Workbook

Sheet Histórico y Rendimiento
A1: DIRECCIÓN DE OPERACIONES Y MAQUINARIA PESADA
A2: REPORTE HISTÓRICO CONSOLIDADO DE RENDIMIENTO DE MAQUINARIA — CARRETERA LIBRE MÉXICO-TOLUCA
A3: Corte Oficial: Semanas 24 a 37 | Peso Volumétrico Asfalto: 1,742 kg/m³ (1.742 Ton/m³)
C5: PESO VOLUMÉTRICO ASFALTO (Ton/m³): | F5: 1.742
A8: No. | B8: Económico | C8: Equipo / Maquinaria | D8: No. Serie | E8: Operador Registrado | F8: Concepto / Trabajo | G8: Viajes Acumulados | H8: Volumen Total (m³) | I8: Toneladas Totales (Ton) | J8: Diésel Acumulado (L) | K8: Rendimiento Real (L/Ton) | L8: Rendimiento Real (L/m³) | M8: Estatus Operativo
A9: 1 | B9: PRR-01 | C9: PERFILADORA WIRTGEN W200i | D9: 14200089 | E9: JAVIER PAREDES CORTE | F9: Fresado de Pavimento | G9: 1138 | H9: 15603 | I9: 27180.426 | J9: ='Semana 24'!I9+'Semana 25'!I9+'Semana 26'!I9+'Semana 27'!I9+'Semana 28'!I9+'Semana 29'!I9+'Semana 30'!I9+'Semana 31'!I9+'Semana 32'!I9+'Semana 33'!I9+'Semana 34'!I9+'Semana 35'!I9+'Semana 36'!I9+'Semana 37'!I9 | K9: =IF(I9>0, J9/I9, 0) | L9: =IF(H9>0, J9/H9, 0) | M9: ÓPTIMO / OPERATIVO
A10: 2 | B10: VG-01 | C10: PAVIMENTADORA VÖGELE SUPER 1800-3i | D10: 14821687 | E10: ERWIN CUTEÑO HERNANDEZ | F10: Tendido de Mezcla Asfáltica | G10: 638 | H10: 8968 | I10: 15622.256 | J10: ='Semana 24'!I10+'Semana 25'!I10+'Semana 26'!I10+'Semana 27'!I10+'Semana 28'!I10+'Semana 29'!I10+'Semana 30'!I10+'Semana 31'!I10+'Semana 32'!I10+'Semana 33'!I10+'Semana 34'!I10+'Semana 35'!I10+'Semana 36'!I10+'Semana 37'!I10 | K10: =IF(I10>0, J10/I10, 0) | L10: =IF(H10>0, J10/H10, 0) | M10: ÓPTIMO / OPERATIVO
A11: 3 | B11: DR-01 | C11: COMPACTADOR TÁNDEM HAMM-HD120 VV | D11: H1840093 | E11: JOEL ALBERTO RIVERA RIVAS | F11: Compactación Tándem Primaria | G11: 638 | H11: 8968 | I11: 15622.256 | J11: ='Semana 24'!I11+'Semana 25'!I11+'Semana 26'!I11+'Semana 27'!I11+'Semana 28'!I11+'Semana 29'!I11+'Semana 30'!I11+'Semana 31'!I11+'Semana 32'!I11+'Semana 33'!I11+'Semana 34'!I11+'Semana 35'!I11+'Semana 36'!I11+'Semana 37'!I11 | K11: =IF(I11>0, J11/I11, 0) | L11: =IF(H11>0, J11/H11, 0) | M11: ÓPTIMO / OPERATIVO
A12: 4 | B12: DR-02 | C12: COMPACTADOR TÁNDEM HAMM-HD140 | D12: H1840234 | E12: ALEXIS RENDON DOMINGUEZ | F12: Compactación Tándem Pesada | G12: 638 | H12: 8968 | I12: 15622.256 | J12: ='Semana 24'!I12+'Semana 25'!I12+'Semana 26'!I12+'Semana 27'!I12+'Semana 28'!I12+'Semana 29'!I12+'Semana 30'!I12+'Semana 31'!I12+'Semana 32'!I12+'Semana 33'!I12+'Semana 34'!I12+'Semana 35'!I12+'Semana 36'!I12+'Semana 37'!I12 | K12: =IF(I12>0, J12/I12, 0) | L12: =IF(H12>0, J12/H12, 0) | M12: ÓPTIMO / OPERATIVO
A13: 5 | B13: NM-01 | C13: COMPACTADOR NEUMÁTICO DYNAPAC CP271 | D13: CP271-980 | E13: JOSE CARLOS ROMERO TELLEZ | F13: Compactación Neumática / Sellado | G13: 638 | H13: 8968 | I13: 15622.256 | J13: ='Semana 24'!I13+'Semana 25'!I13+'Semana 26'!I13+'Semana 27'!I13+'Semana 28'!I13+'Semana 29'!I13+'Semana 30'!I13+'Semana 31'!I13+'Semana 32'!I13+'Semana 33'!I13+'Semana 34'!I13+'Semana 35'!I13+'Semana 36'!I13+'Semana 37'!I13 | K13: =IF(I13>0, J13/I13, 0) | L13: =IF(H13>0, J13/H13, 0) | M13: ÓPTIMO / OPERATIVO
A14: 6 | B14: NM-09 | C14: COMPACTADOR NEUMÁTICO HAMM 208 | D14: HM-208-114 | E14: NOLVIN DE JESUS PEREZ GOMEZ | F14: Compactación Neumática / Acabado | G14: 638 | H14: 8968 | I14: 15622.256 | J14: ='Semana 24'!I14+'Semana 25'!I14+'Semana 26'!I14+'Semana 27'!I14+'Semana 28'!I14+'Semana 29'!I14+'Semana 30'!I14+'Semana 31'!I14+'Semana 32'!I14+'Semana 33'!I14+'Semana 34'!I14+'Semana 35'!I14+'Semana 36'!I14+'Semana 37'!I14 | K14: =IF(I14>0, J14/I14, 0) | L14: =IF(H14>0, J14/H14, 0) | M14: ÓPTIMO / OPERATIVO
A15: 7 | B15: BR-01 | C15: BARREDORA INDUSTRIAL BROCE BROOM-350 | D15: 51300000-4794 | E15: EDGAR ROSALES MARTINEZ | F15: Limpieza y Barrido Previo | G15: 638 | H15: 8968 | I15: 15622.256 | J15: ='Semana 24'!I15+'Semana 25'!I15+'Semana 26'!I15+'Semana 27'!I15+'Semana 28'!I15+'Semana 29'!I15+'Semana 30'!I15+'Semana 31'!I15+'Semana 32'!I15+'Semana 33'!I15+'Semana 34'!I15+'Semana 35'!I15+'Semana 36'!I15+'Semana 37'!I15 | K15: =IF(I15>0, J15/I15, 0) | L15: =IF(H15>0, J15/H15, 0) | M15: ÓPTIMO / OPERATIVO
A16: 8 | B16: RT-05 | C16: RETROEXCAVADORA JOHN DEERE 310SK | D16: 1T0310SKAEE262172 | E16: ADOLFO NAVA LOPEZ | F16: Carga Fresado y Derrumbes | G16: 1138 | H16: 15603 | I16: 27180.426 | J16: ='Semana 24'!I16+'Semana 25'!I16+'Semana 26'!I16+'Semana 27'!I16+'Semana 28'!I16+'Semana 29'!I16+'Semana 30'!I16+'Semana 31'!I16+'Semana 32'!I16+'Semana 33'!I16+'Semana 34'!I16+'Semana 35'!I16+'Semana 36'!I16+'Semana 37'!I16 | K16: =IF(I16>0, J16/I16, 0) | L16: =IF(H16>0, J16/H16, 0) | M16: ÓPTIMO / OPERATIVO
A17: 9 | B17: PT-01 | C17: PETROLIZADORA INTERNATIONAL / FORD F800 | D17: 3HTMMAAR830567 | E17: ELTHON EDUARDO MARTINEZ GOMORA | F17: Riego de Liga / Emulsión | G17: 638 | H17: 8968 | I17: 15622.256 | J17: ='Semana 24'!I17+'Semana 25'!I17+'Semana 26'!I17+'Semana 27'!I17+'Semana 28'!I17+'Semana 29'!I17+'Semana 30'!I17+'Semana 31'!I17+'Semana 32'!I17+'Semana 33'!I17+'Semana 34'!I17+'Semana 35'!I17+'Semana 36'!I17+'Semana 37'!I17 | K17: =IF(I17>0, J17/I17, 0) | L17: =IF(H17>0, J17/H17, 0) | M17: ÓPTIMO / OPERATIVO
A18: 10 | B18: CPR-01 | C18: COMPRESOR DE AIRE INGERSOLL RAND IR185 | D18: PHD25B330551 | E18: CUADRILLA DE LIMPIEZA | F18: Sopleteado de Juntas | G18: 0 | H18: 0 | I18: 0 | J18: ='Semana 24'!I18+'Semana 25'!I18+'Semana 26'!I18+'Semana 27'!I18+'Semana 28'!I18+'Semana 29'!I18+'Semana 30'!I18+'Semana 31'!I18+'Semana 32'!I18+'Semana 33'!I18+'Semana 34'!I18+'Semana 35'!I18+'Semana 36'!I18+'Semana 37'!I18 | K18: 0 | L18: 0 | M18: SIN REGISTRO
A19: 11 | B19: PP-01 | C19: CAMIÓN IMPACTO / PIPA DE AGUA FORD | D19: 1FDYR80U0GVA15942 | E19: CUADRILLA DE AGUA | F19: Enfriamiento Rodillos / Riego | G19: 0 | H19: 0 | I19: 0 | J19: ='Semana 24'!I19+'Semana 25'!I19+'Semana 26'!I19+'Semana 27'!I19+'Semana 28'!I19+'Semana 29'!I19+'Semana 30'!I19+'Semana 31'!I19+'Semana 32'!I19+'Semana 33'!I19+'Semana 34'!I19+'Semana 35'!I19+'Semana 36'!I19+'Semana 37'!I19 | K19: 0 | L19: 0 | M19: ÓPTIMO / OPERATIVO
A20: 12 | B20: TL-01 | C20: TORRE DE LUZ MAXILIGHT 4X1000W | D20: MX-4000-22 | E20: CUADRILLA NOCTURNA | F20: Iluminación Nocturna | G20: 0 | H20: 0 | I20: 0 | J20: ='Semana 24'!I20+'Semana 25'!I20+'Semana 26'!I20+'Semana 27'!I20+'Semana 28'!I20+'Semana 29'!I20+'Semana 30'!I20+'Semana 31'!I20+'Semana 32'!I20+'Semana 33'!I20+'Semana 34'!I20+'Semana 35'!I20+'Semana 36'!I20+'Semana 37'!I20 | K20: 0 | L20: 0 | M20: ÓPTIMO / OPERATIVO
A21: 13 | B21: APOYO | C21: EQUIPOS DE APOYO / BIDONES / AJUSTES | D21: S/N | E21: Personal de Apoyo Obra | F21: Excavadora 320, Motoconformadora, Bidones | G21: 0 | H21: 0 | I21: 0 | J21: 4677.66 | K21: 0 | L21: 0 | M21: APOYOS PUNTUALES
A22: TOTAL CONSOLIDADO OBRA MÉXICO-TOLUCA (SEM 24 A 34) | G22: =1138+638 | H22: =15603+8968 | I22: =27180.426+15622.256 | J22: =SUM(J9:J21) | K22: =IF(I22>0, J22/I22, 0) | L22: =IF(H22>0, J22/H22, 0) | M22: CIERRE GENERAL

Sheet Análisis y Gráficas
A1: DASHBOARD INTEGRAL DE RENDIMIENTO DE MAQUINARIA Y ANÁLISIS ESTADÍSTICO DE OBRA
A2: CARRETERA LIBRE MÉXICO-TOLUCA | CORTE OFICIAL SEMANAS 24 A 37 | DATOS DE FRESADO Y CARPETA CONSOLIDADOS
A4: DIÉSEL TOTAL OBRA | C4: VOLUMEN TOTAL OBRA | E4: FRESADO TOTAL | G4: CARPETA TOTAL | I4: RENDIMIENTO GLOBAL | K4: RENDIMIENTO DIARIO PROM
A5: 35837 | C5: 29940 | E5: 17696 | G5: 21329.048 | I5: 1.197 | K5: 1.205
A7: 1. ANÁLISIS ESTADÍSTICO DESCRIPTIVO DE PRODUCCIÓN Y CONSUMO SEMANAL (N = 14 SEMANAS)
A8: Indicador Operativo | B8: Unidad | C8: Media (μ) | D8: Mediana | E8: Desv. Est (σ) | F8: Coef. Var (CV%) | G8: Mínimo | H8: Máximo | I8: Rango IQR | J8: Asimetría | K8: Rend. Base | L8: Desviación | M8: Diagnóstico Operativo
A9: Fresado Semanal | B9: m³ | C9: 1264 | D9: 1319.5 | E9: 607.1 | F9: 48.0% | G9: 42 | H9: 2023 | I9: 504 | J9: -0.99 | K9: - | L9: - | M9: Moderada dispersión por transición de frentes
A10: Carpeta Semanal (Volumen) | B10: m³ | C10: 874.57 | D10: 908.5 | E10: 226.5 | F10: 25.9% | G10: 490 | H10: 1204 | I10: 283.25 | J10: -0.35 | K10: - | L10: - | M10: Alta regularidad de suministro en obra
A11: Carpeta Semanal (Peso) | B11: Ton | C11: 1523.5 | D11: 1582.61 | E11: 394.56 | F11: 25.9% | G11: 853.58 | H11: 2097.37 | I11: 493.42 | J11: -0.35 | K11: - | L11: - | M11: Distribución casi simétrica / Estable
A12: Diésel Semanal Obra | B12: Litros | C12: 2559.79 | D12: 2776 | E12: 864.73 | F12: 33.8% | G12: 693 | H12: 3727 | I12: 651 | J12: -1.09 | K12: - | L12: - | M12: Alineado a semanas con doble frente
A13: Rend. Pavimentadora (VG-01) | B13: L/Ton | C13: 0.332 | D13: 0.349 | E13: 0.106 | F13: 31.9% | G13: 0.143 | H13: 0.552 | I13: 0.108 | J13: 0.28 | K13: 0.35 | L13: -3.8% | M13: ÓPTIMO: Muy cercano a estándar de catálogo
A14: Rend. Perfiladora (PRR-01) | B14: L/m³ | C14: 1.577 | D14: 0.712 | E14: 2.991 | F14: 189.7% | G14: 0.121 | H14: 11.905 | I14: 0.575 | J14: 3.48 | K14: 3.2 | L14: -73.5% | M14: EFICIENTE: Sesgado por ralentí en Sem 36
A15: Rendimiento Global Obra | B15: L/m³ | C15: 1.25 | D15: 1.365 | E15: 0.459 | F15: 36.7% | G15: 0.401 | H15: 2.044 | I15: 0.603 | J15: -0.37 | K15: - | L15: - | M15: Consistente: 1.20 L de diésel por m³ producido
A17: 2. RENDIMIENTO POR MÁQUINA: REAL VS. ESPERADO (BASE) Y DESVIACIONES GLOBALES
A18: No. | B18: Económico | C18: Equipo / Maquinaria | D18: Concepto Operativo | E18: Volumen / Ton | F18: Diésel Real (L) | G18: Rend. Real | H18: Rend. Base | I18: Unidad | J18: Desviación (%) | K18: Delta Diésel (L) | L18: Horas Est (h) | M18: Estatus Operativo
A19: 1 | B19: PRR-01 | C19: PERFILADORA WIRTGEN W200i | D19: Fresado de Pavimento | E19: 17696 | F19: 15024 | G19: 0.849 | H19: 3.2 | I19: L/m³ | J19: -0.735 | K19: -41603.2 | L19: 223.6 | M19: DENTRO DE RENDIMIENTO BASE
A20: 2 | B20: VG-01 | C20: PAVIMENTADORA VÖGELE SUPER 1800-3i | D20: Tendido de Mezcla Asfáltica | E20: 21329.048 | F20: 7184 | G20: 0.337 | H20: 0.35 | I20: L/Ton | J20: -0.038 | K20: -281.2 | L20: 442.4 | M20: DENTRO DE RENDIMIENTO BASE
A21: 3 | B21: DR-01 | C21: COMPACTADOR TÁNDEM HAMM-HD120 VV | D21: Compactación Tándem Primaria | E21: 21329.048 | F21: 1696 | G21: 0.08 | H21: 0.3 | I21: L/Ton | J21: -0.735 | K21: -4702.7 | L21: 118.6 | M21: DENTRO DE RENDIMIENTO BASE
A22: 4 | B22: DR-02 | C22: COMPACTADOR TÁNDEM HAMM-HD140 | D22: Compactación Tándem Pesada | E22: 21329.048 | F22: 1414 | G22: 0.066 | H22: 0.3 | I22: L/Ton | J22: -0.779 | K22: -4984.7 | L22: 98.9 | M22: DENTRO DE RENDIMIENTO BASE
A23: 5 | B23: NM-01 | C23: COMPACTADOR NEUMÁTICO DYNAPAC CP271 | D23: Compactación Neumática / Sellado | E23: 21329.048 | F23: 1822 | G23: 0.085 | H23: 0.25 | I23: L/Ton | J23: -0.658 | K23: -3510.3 | L23: 159.3 | M23: DENTRO DE RENDIMIENTO BASE
A24: 6 | B24: NM-09 | C24: COMPACTADOR NEUMÁTICO HAMM 208 | D24: Compactación Neumática / Acabado | E24: 21329.048 | F24: 1133 | G24: 0.053 | H24: 0.24 | I24: L/Ton | J24: -0.779 | K24: -3986 | L24: 103.4 | M24: DENTRO DE RENDIMIENTO BASE
A25: 7 | B25: BR-01 | C25: BARREDORA INDUSTRIAL BROCE BROOM-350 | D25: Limpieza y Barrido Previo | E25: 21329.048 | F25: 1200 | G25: 0.056 | H25: 0.05 | I25: L/Ton | J25: 0.125 | K25: 133.5 | L25: 134.2 | M25: EXCEDE RENDIMIENTO BASE (+12.5%)
A26: 8 | B26: RT-05 | C26: RETROEXCAVADORA JOHN DEERE 310SK | D26: Carga Fresado y Derrumbes | E26: 17696 | F26: 4318 | G26: 0.244 | H26: 0.26 | I26: L/m³ | J26: -0.062 | K26: -283 | L26: 580.4 | M26: DENTRO DE RENDIMIENTO BASE
A27: 9 | B27: PT-01 | C27: PETROLIZADORA INTERNATIONAL / FORD F800 | D27: Riego de Liga / Emulsión | E27: 21329.048 | F27: 1878 | G27: 0.088 | H27: 0.12 | I27: L/Ton | J27: -0.266 | K27: -681.5 | L27: 147.2 | M27: DENTRO DE RENDIMIENTO BASE
A28: 10 | B28: CPR-01 | C28: COMPRESOR DE AIRE INGERSOLL RAND IR185 | D28: Sopleteado de Juntas | E28: 21329.048 | F28: 0 | G28: 0 | H28: 0.08 | I28: L/Ton | J28: -1 | K28: -1706.3 | L28: 0 | M28: SIN CONSUMO (Inactiva)
A29: 11 | B29: PP-01 | C29: CAMIÓN IMPACTO / PIPA DE AGUA FORD | D29: Enfriamiento Rodillos / Riego | E29: 21329.048 | F29: 50 | G29: 0.002 | H29: 0.06 | I29: L/Ton | J29: -0.961 | K29: -1229.7 | L29: 16.5 | M29: APOYO PUNTUAL
A30: 12 | B30: TL-01 | C30: TORRE DE LUZ MAXILIGHT 4X1000W | D30: Iluminación Nocturna | E30: 21329.048 | F30: 118 | G30: 0.006 | H30: 0.04 | I30: L/Ton | J30: -0.862 | K30: -735.2 | L30: 49 | M30: APOYO NOCTURNO
A31: TOTAL FLOTA / CONSOLIDADO OBRA | E31: 29940 | F31: 35837 | G31: 1.197 | H31: - | I31: L/m³ | J31: - | K31: -63110.8 | L31: 1988.4 | M31: EFICIENCIA GLOBAL CONTROLADA
A34: 3. EVOLUCIÓN SEMANAL DEL RENDIMIENTO POR ACTIVIDAD Y OBRA (SEMANAS 24 A 37)
A35: Semana | B35: Periodo Oficial | C35: Fresado (m³) | D35: Carpeta (Ton) | E35: Diésel Sem (L) | F35: Rend. Fresa Real | G35: Base Fresa | H35: Rend. Carpeta Real | I35: Base Carpeta | J35: Rend. Tren Rodillos | K35: Base Tren | L35: Rend. Global Obra | M35: Promedio Obra
A36: Semana 24 | B36: 08/Jun - 13/Jun/2026 | C36: 1190 | D36: 952.874 | E36: 1093 | F36: 0.653 | G36: 3.2 | H36: 0.143 | I36: 0.35 | J36: 0 | K36: 0.3 | L36: 0.629 | M36: 1.197
A37: Semana 25 | B37: 15/Jun - 20/Jun/2026 | C37: 994 | D37: 1672.32 | E37: 2748 | F37: 1.207 | G37: 3.2 | H37: 0.335 | I37: 0.35 | J37: 0.257 | K37: 0.3 | L37: 1.406 | M37: 1.197
A38: Semana 26 | B38: 22/Jun - 27/Jun/2026 | C38: 1029 | D38: 1015.586 | E38: 2804 | F38: 1.354 | G38: 3.2 | H38: 0.317 | I38: 0.35 | J38: 0.621 | K38: 0.3 | L38: 1.739 | M38: 1.197
A39: Semana 27 | B39: 29/Jun - 04/Jul/2026 | C39: 1470 | D39: 1492.894 | E39: 3727 | F39: 1.193 | G39: 3.2 | H39: 0.401 | I39: 0.35 | J39: 0.366 | K39: 0.3 | L39: 1.602 | M39: 1.197
A40: Semana 28 | B40: 06/Jul - 11/Jul/2026 | C40: 1239 | D40: 853.58 | E40: 693 | F40: 0.121 | G40: 3.2 | H40: 0.187 | I40: 0.35 | J40: 0.232 | K40: 0.3 | L40: 0.401 | M40: 1.197
A41: Semana 29 | B41: 13/Jul - 18/Jul/2026 | C41: 1351 | D41: 1414.504 | E41: 3380 | F41: 1.458 | G41: 3.2 | H41: 0.375 | I41: 0.35 | J41: 0.028 | K41: 0.3 | L41: 1.563 | M41: 1.197
A42: Semana 30 | B42: 20/Jul - 25/Jul/2026 | C42: 1904 | D42: 1804.712 | E42: 2663 | F42: 0.63 | G42: 3.2 | H42: 0.194 | I42: 0.35 | J42: 0.391 | K42: 0.3 | L42: 0.906 | M42: 1.197
A43: Semana 31 | B43: 27/Jul - 01/Ago/2026 | C43: 1288 | D43: 1743.742 | E43: 3100 | F43: 0.932 | G43: 3.2 | H43: 0.316 | I43: 0.35 | J43: 0.325 | K43: 0.3 | L43: 1.354 | M43: 1.197
A44: Semana 32 | B44: 03/Ago - 08/Ago/2026 | C44: 1547 | D44: 1999.816 | E44: 2593 | F44: 0.621 | G44: 3.2 | H44: 0.363 | I44: 0.35 | J44: 0.2 | K44: 0.3 | L44: 0.962 | M44: 1.197
A45: Semana 33 | B45: 10/Ago - 15/Ago/2026 | C45: 1582 | D45: 1268.176 | E45: 3180 | F45: 0.771 | G45: 3.2 | H45: 0.552 | I45: 0.35 | J45: 0.299 | K45: 0.3 | L45: 1.377 | M45: 1.197
...

Sheet Conciliación y Auditoría
A1: INFORME DE AUDITORÍA Y CONCILIACIÓN TRIANGULADA: FACTURAS VS. CARGAS EN DB VS. BITÁCORA DE CAMPO
A2: OBRA: CARRETERA MÉXICO - TOLUCA | PROVEEDOR FISCAL: DERIVADOS DE PETRÓLEO CASTILLA | PERIODO AUDITADO: SEMANAS 24 A 37
B4: TOTAL DIÉSEL FACTURADO | D4: TOTAL CARGAS EN DB | F4: BITÁCORA MAQUINARIA | H4: DESVIACIÓN FACTURADO VS OBRA | J4: RENDIMIENTO OPERATIVO (OBRA) | L4: RENDIMIENTO FACTURADO
B5: 41,020.11 L ($1,107,547.97 MXN (74 facturas)) | D5: 40,724.66 L (99.28% de match con facturas) | F5: 36,067.00 L (Consumo reportado en 12 máquinas) | H5: +4,953.11 L (+13.73% sobreconsumo facturado) | J5: 1.205 L/m³ (Eficiencia directa en maquinaria) | L5: 1.370 L/m³ (Impacto financiero (+0.165 L/m³))
A7: TABLA 1: CONCILIACIÓN TRIANGULADA SEMANAL (BITÁCORA DE CAMPO VS. CARGAS EN DB VS. FACTURAS PAGADAS)
A8: Semana | B8: Vol. Fresado (m³) | C8: Vol. Carpeta (m³) | D8: Vol. Total (m³) | E8: Diésel Bitácora (L) | F8: Cargas DB (L) | G8: Diff DB vs Bit (L) | H8: Diésel Facturado (L) | I8: Importe Facturado (MXN) | J8: Diff Fact vs Bit (L) | K8: % Desv. Fact/Bit | L8: Rend. Bitácora (L/m³) | M8: Rend. Facturado (L/m³)
A9: Semana 24 | B9: 1737 | C9: 0 | D9: 1737 | E9: 1285 | F9: 1485 | G9: 200 | H9: 0 | I9: 0 | J9: -1285 | K9: -1 | L9: 0.74 | M9: 0
A10: Semana 25 | B10: 994 | C10: 960 | D10: 1954 | E10: 2576 | F10: 2828 | G10: 252 | H10: 2410 | I10: 65070.37 | J10: -166 | K10: -0.064 | L10: 1.318 | M10: 1.233
A11: Semana 26 | B11: 980 | C11: 632 | D11: 1612 | E11: 2804 | F11: 2517 | G11: -287 | H11: 2530 | I11: 68310.31 | J11: -274 | K11: -0.098 | L11: 1.739 | M11: 1.569
A12: Semana 27 | B12: 1029 | C12: 1298 | D12: 2327 | E12: 3727 | F12: 4876 | G12: 1149 | H12: 4895 | I12: 132165.61 | J12: 1168 | K12: 0.313 | L12: 1.602 | M12: 2.104
A13: Semana 28 | B13: 1729 | C13: 0 | D13: 1729 | E13: 753 | F13: 2521 | G13: 1768 | H13: 2500 | I13: 67500.48 | J13: 1747 | K13: 2.32 | L13: 0.436 | M13: 1.446
A14: Semana 29 | B14: 1267 | C14: 896 | D14: 2163 | E14: 3480 | F14: 3705.77 | G14: 225.77 | H14: 3714.77 | I14: 100299.09 | J14: 234.77 | K14: 0.067 | L14: 1.609 | M14: 1.717
A15: Semana 30 | B15: 1848 | C15: 1092 | D15: 2940 | E15: 2713 | F15: 3652.18 | G15: 939.18 | H15: 3640.18 | I15: 98285.37 | J15: 927.18 | K15: 0.342 | L15: 0.923 | M15: 1.238
A16: Semana 31 | B16: 1400 | C16: 889 | D16: 2289 | E16: 3100 | F16: 3103.71 | G16: 3.71 | H16: 4160.16 | I16: 112324.58 | J16: 1060.16 | K16: 0.342 | L16: 1.354 | M16: 1.817
A17: Semana 32 | B17: 1603 | C17: 1092 | D17: 2695 | E17: 2593 | F17: 2931 | G17: 338 | H17: 2910 | I17: 78570.36 | J17: 317 | K17: 0.122 | L17: 0.962 | M17: 1.08
A18: Semana 33 | B18: 1050 | C18: 1260 | D18: 2310 | E18: 3180 | F18: 3180 | G18: 0 | H18: 3420 | I18: 92340.41 | J18: 240 | K18: 0.075 | L18: 1.377 | M18: 1.481
A19: Semana 34 | B19: 1638 | C19: 1177 | D19: 2815 | E19: 2916 | F19: 2775 | G19: -141 | H19: 2780 | I19: 75060.3 | J19: -136 | K19: -0.047 | L19: 1.036 | M19: 0.988
A20: Semana 35 | B20: 42 | C20: 994 | D20: 1036 | E20: 1599 | F20: 1679 | G20: 80 | H20: 2140 | I20: 57780.35 | J20: 541 | K20: 0.338 | L20: 1.543 | M20: 2.066
... A22: Semana 37 | B22: 1974 | C22: 1204 | D22: 3178 | E22: 2980 | F22: 2980 | G22: 0 | H22: 2980 | I22: 80460.33 | J22: 0 | K22: 0 | L22: 0.938 | M22: 0.938
A23: TOTALES / PROMEDIOS | B23: =SUM(B9:B22) | C23: =SUM(C9:C22) | D23: =SUM(D9:D22) | E23: =SUM(E9:E22) | F23: =SUM(F9:F22) | G23: =SUM(G9:G22) | H23: =SUM(H9:H22) | I23: =SUM(I9:I22) | J23: =SUM(J9:J22) | K23: =(H23-E23)/E23 | L23: =E23/D23 | M23: =H23/D23
A25: TABLA 2: RESUMEN DE PROVEEDORES FISCALES DE COMBUSTIBLE EN OBRA MÉXICO - TOLUCA
A26: Proveedor | B26: Punto de Entrega | C26: Facturas | D26: Litros Facturados | E26: Importe Total (MXN) | F26: Precio Prom. (MXN/L) | G26: % Part.
A27: DERIVADOS DE PETROLEO CASTILLA | B27: Obra México - Toluca (Marimba M-01) | C27: 74 | D27: 41330.11 | E27: 1115918 | F27: 27 | G27: 0.973
A28: ESTADO DE CUENTA / VALES | B28: Cargas de Emergencia Toluca | C28: 2 | D28: 1140 | E28: 30780.1 | F28: 27 | G28: 0.027
A29: TOTAL FACTURADO PROVEEDORES | B29: CONSOLIDADO FISCAL | C29: =SUM(C27:C28) | D29: =SUM(D27:D28) | E29: =SUM(E27:E28) | F29: =E29/D29 | G29: =SUM(G27:G28)
A31: TABLA 3: ANÁLISIS FORENSE DE LAS CAUSAS DE LA DESVIACIÓN FACTURADO VS. BITÁCORA
A32: Concepto / Causa de la Desviación | B32: Volumen (L) | C32: Costo (MXN) | D32: % de Desv. | E32: Impacto Operativo y Diagnóstico
A33: 1. Equipos de Apoyo y Rentados (Fuera de plantilla 12 equipos) | B33: 3255.45 | C33: 87897.15 | D33: 0.657 | E33: Motoconformadoras, excavadoras 320D/330 en banco, pipas y barredoras auxiliares cargadas por la marimba pero no consideradas en la plantilla de 12 equipos titulares.
A34: 2. Ajustes de Conciliación en Marimba (Stock remanente / AJU-01) | B34: 1147.66 | C34: 30986.82 | D34: 0.232 | E34: Litros facturados en bloque que quedaron como stock en la marimba M-01 durante semanas de paro o jornada reducida (destaca Sem 28 con +1,548 L en ajustes).
A35: 3. Desfases de Corte de Facturación (Sem 24 a Sem 25) | B35: 550 | C35: 14850 | D35: 0.111 | E35: El diésel de la primera semana de obra (Semana 24) se consumió en campo antes de emitir las facturas A10052 y A10058 el 15-16 de junio.
A36: TOTAL DESVIACIÓN EXPLICADA | B36: =SUM(B33:B35) | C36: =SUM(C33:C35) | D36: =SUM(D33:D35) | E36: 100% de la brecha auditada entre facturación y bitácora de campo

Sheet Semana 24
A1: CONTROL SEMANAL DE RENDIMIENTO DE MAQUINARIA (SEMANA 24)
A2: OBRA: CARRETERA LIBRE MÉXICO-TOLUCA | PERIODO: 08/Jun/2026 - 13/Jun/2026
A4: 1. PARÁMETROS: | B4: PESO VOLUMÉTRICO ASFALTO (Ton/m³): | E4: 1.742
A5: 2. FRESADO SEMANAL: | B5: Viajes de Fresado: | C5: 85 | D5: Volumen Fresado (m³): | E5: 1190
A6: 3. CARPETA SEMANAL: | B6: Viajes de Mezcla: | C6: 37 | D6: Volumen Carpeta (m³): | E6: 547 | F6: Toneladas Carpeta (Ton): | G6: =E6*$E$4
A8: No. | B8: Económico | C8: Equipo / Maquinaria | D8: Operador Asignado | E8: Concepto de Trabajo | F8: Viajes Asignados | G8: Volumen (m³) | H8: Toneladas (Ton) | I8: Diésel Surtido (L) | J8: Rendimiento Real (L/Ton) | K8: Rendimiento Real (L/m³) | L8: Rend. Base (L/h) | M8: Horas Est. Operación | N8: Estatus Operativo
A9: 1 | B9: PRR-01 | C9: PERFILADORA WIRTGEN W200i | D9: JAVIER PAREDES CORTE | E9: Fresado de Pavimento | F9: =$C$5 | G9: =$E$5 | H9: - | I9: 777 | J9: - | K9: =IF(G9>0, I9/G9, 0) | L9: 67.2 | M9: =IF(L9>0, I9/L9, 0) | N9: =IF(I9=0, "SIN CONSUMO (Inactiva)", IF(A9=1, IF(K9<=0.85, "DENTRO DE RENDIMIENTO BASE", "EXCEDE RENDIMIENTO BASE"), IF(A9=2, IF(J9<=0.38, "DENTRO DE RENDIMIENTO BASE", "EXCEDE RENDIMIENTO BASE"), IF(OR(A9=3,A9=4,A9=5,A9=6), IF(J9<=0.08, "DENTRO DE RENDIMIENTO BASE", "EXCEDE RENDIMIENTO BASE"), IF(A9=7, IF(J9<=0.07, "DENTRO DE RENDIMIENTO BASE", "EXCEDE RENDIMIENTO BASE"), IF(A9=8, IF(K9<=0.22, "DENTRO DE RENDIMIENTO BASE", "EXCEDE RENDIMIENTO BASE"), IF(A9=9, IF(J9<=0.075, "DENTRO DE RENDIMIENTO BASE", "EXCEDE RENDIMIENTO BASE"), "APOYO PUNTUAL")))))))
A10: 2 | B10: VG-01 | C10: PAVIMENTADORA VÖGELE SUPER 1800-3i | D10: ERWIN CUTEÑO HERNANDEZ | E10: Tendido de Mezcla Asfáltica | F10: =$C$6 | G10: =$E$6 | H10: =G10*$E$4 | I10: 136 | J10: =IF(H10>0, I10/H10, 0) | K10: =IF(G10>0, I10/G10, 0) | L10: 16.24 | M10: =IF(L10>0, I10/L10, 0) | N10: =IF(I10=0, "SIN CONSUMO (Inactiva)", IF(A10=1, IF(K10<=0.85, "DENTRO DE RENDIMIENTO BASE", "EXCEDE RENDIMIENTO BASE"), IF(A10=2, IF(J10<=0.38, "DENTRO DE RENDIMIENTO BASE", "EXCEDE RENDIMIENTO BASE"), IF(OR(A10=3,A10=4,A10=5,A10=6), IF(J10<=0.08, "DENTRO DE RENDIMIENTO BASE", "EXCEDE RENDIMIENTO BASE"), IF(A10=7, IF(J10<=0.07, "DENTRO DE RENDIMIENTO BASE", "EXCEDE RENDIMIENTO BASE"), IF(A10=8, IF(K10<=0.22, "DENTRO DE RENDIMIENTO BASE", "EXCEDE RENDIMIENTO BASE"), IF(A10=9, IF(J10<=0.075, "DENTRO DE RENDIMIENTO BASE", "EXCEDE RENDIMIENTO BASE"), "APOYO PUNTUAL")))))))
A11: 3 | B11: DR-01 | C11: COMPACTADOR TÁNDEM HAMM-HD120 VV | D11: JOEL ALBERTO RIVERA RIVAS | E11: Compactación Tándem Primaria | F11: =$C$6 | G11: =$E$6 | H11: =G11*$E$4 | I11: 0 | J11: =IF(H11>0, I11/H11, 0) | K11: =IF(G11>0, I11/G11, 0) | L11: 14.3 | M11: =IF(L11>0, I11/L11, 0) | N11: =IF(I11=0, "SIN CONSUMO (Inactiva)", IF(A11=1, IF(K11<=0.85, "DENTRO DE RENDIMIENTO BASE", "EXCEDE RENDIMIENTO BASE"), IF(A11=2, IF(J11<=0.38, "DENTRO DE RENDIMIENTO BASE", "EXCEDE RENDIMIENTO BASE"), IF(OR(A11=3,A11=4,A11=5,A11=6), IF(J11<=0.08, "DENTRO DE RENDIMIENTO BASE", "EXCEDE RENDIMIENTO BASE"), IF(A11=7, IF(J11<=0.07, "DENTRO DE RENDIMIENTO BASE", "EXCEDE RENDIMIENTO BASE"), IF(A11=8, IF(K11<=0.22, "DENTRO DE RENDIMIENTO BASE", "EXCEDE RENDIMIENTO BASE"), IF(A11=9, IF(J11<=0.075, "DENTRO DE RENDIMIENTO BASE", "EXCEDE RENDIMIENTO BASE"), "APOYO PUNTUAL")))))))
A12: 4 | B12: DR-02 | C12: COMPACTADOR TÁNDEM HAMM-HD140 | D12: ALEXIS RENDON DOMINGUEZ | E12: Compactación Tándem Pesada | F12: =$C$6 | G12: =$E$6 | H12: =G12*$E$4 | I12: 0 | J12: =IF(H12>0, I12/H12, 0) | K12: =IF(G12>0, I12/G12, 0) | L12: 14.3 | M12: =IF(L12>0, I12/L12, 0) | N12: =IF(I12=0, "SIN CONSUMO (Inactiva)", IF(A12=1, IF(K12<=0.85, "DENTRO DE RENDIMIENTO BASE", "EXCEDE RENDIMIENTO BASE"), IF(A12=2, IF(J12<=0.38, "DENTRO DE RENDIMIENTO BASE", "EXCEDE RENDIMIENTO BASE"), IF(OR(A12=3,A12=4,A12=5,A12=6), IF(J12<=0.08, "DENTRO DE RENDIMIENTO BASE", "EXCEDE RENDIMIENTO BASE"), IF(A12=7, IF(J12<=0.07, "DENTRO DE RENDIMIENTO BASE", "EXCEDE RENDIMIENTO BASE"), IF(A12=8, IF(K12<=0.22, "DENTRO DE RENDIMIENTO BASE", "EXCEDE RENDIMIENTO BASE"), IF(A12=9, IF(J12<=0.075, "DENTRO DE RENDIMIENTO BASE", "EXCEDE RENDIMIENTO BASE"), "APOYO PUNTUAL")))))))
A13: 5 | B13: NM-01 | C13: COMPACTADOR NEUMÁTICO DYNAPAC CP271 | D13: JOSE CARLOS ROMERO TELLEZ | E13: Compactación Neumática / Sellado | F13: =$C$6 | G13: =$E$6 | H13: =G13*$E$4 | I13: 0 | J13: =IF(H13>0, I13/H13, 0) | K13: =IF(G13>0, I13/G13, 0) | L13: 11.44 | M13: =IF(L13>0, I13/L13, 0) | N13: =IF(I13=0, "SIN CONSUMO (Inactiva)", IF(A13=1, IF(K13<=0.85, "DENTRO DE RENDIMIENTO BASE", "EXCEDE RENDIMIENTO BASE"), IF(A13=2, IF(J13<=0.38, "DENTRO DE RENDIMIENTO BASE", "EXCEDE RENDIMIENTO BASE"), IF(OR(A13=3,A13=4,A13=5,A13=6), IF(J13<=0.08, "DENTRO DE RENDIMIENTO BASE", "EXCEDE RENDIMIENTO BASE"), IF(A13=7, IF(J13<=0.07, "DENTRO DE RENDIMIENTO BASE", "EXCEDE RENDIMIENTO BASE"), IF(A13=8, IF(K13<=0.22, "DENTRO DE RENDIMIENTO BASE", "EXCEDE RENDIMIENTO BASE"), IF(A13=9, IF(J13<=0.075, "DENTRO DE RENDIMIENTO BASE", "EXCEDE RENDIMIENTO BASE"), "APOYO PUNTUAL")))))))
A14: 6 | B14: NM-09 | C14: COMPACTADOR NEUMÁTICO HAMM 208 | D14: NOLVIN DE JESUS PEREZ GOMEZ | E14: Compactación Neumática / Acabado | F14: =$C$6 | G14: =$E$6 | H14: =G14*$E$4 | I14: 0 | J14: =IF(H14>0, I14/H14, 0) | K14: =IF(G14>0, I14/G14, 0) | L14: 10.96 | M14: =IF(L14>0, I14/L14, 0) | N14: =IF(I14=0, "SIN CONSUMO (Inactiva)", IF(A14=1, IF(K14<=0.85, "DENTRO DE RENDIMIENTO BASE", "EXCEDE RENDIMIENTO BASE"), IF(A14=2, IF(J14<=0.38, "DENTRO DE RENDIMIENTO BASE", "EXCEDE RENDIMIENTO BASE"), IF(OR(A14=3,A14=4,A14=5,A14=6), IF(J14<=0.08, "DENTRO DE RENDIMIENTO BASE", "EXCEDE RENDIMIENTO BASE"), IF(A14=7, IF(J14<=0.07, "DENTRO DE RENDIMIENTO BASE", "EXCEDE RENDIMIENTO BASE"), IF(A14=8, IF(K14<=0.22, "DENTRO DE RENDIMIENTO BASE", "EXCEDE RENDIMIENTO BASE"), IF(A14=9, IF(J14<=0.075, "DENTRO DE RENDIMIENTO BASE", "EXCEDE RENDIMIENTO BASE"), "APOYO PUNTUAL")))))))
A15: 7 | B15: BR-01 | C15: BARREDORA INDUSTRIAL BROCE BROOM-350 | D15: EDGAR ROSALES MARTINEZ | E15: Limpieza y Barrido Previo | F15: =$C$6 | G15: =$E$6 | H15: =G15*$E$4 | I15: 60 | J15: =IF(H15>0, I15/H15, 0) | K15: =IF(G15>0, I15/G15, 0) | L15: 8.94 | M15: =IF(L15>0, I15/L15, 0) | N15: =IF(I15=0, "SIN CONSUMO (Inactiva)", IF(A15=1, IF(K15<=0.85, "DENTRO DE RENDIMIENTO BASE", "EXCEDE RENDIMIENTO BASE"), IF(A15=2, IF(J15<=0.38, "DENTRO DE RENDIMIENTO BASE", "EXCEDE RENDIMIENTO BASE"), IF(OR(A15=3,A15=4,A15=5,A15=6), IF(J15<=0.08, "DENTRO DE RENDIMIENTO BASE", "EXCEDE RENDIMIENTO BASE"), IF(A15=7, IF(J15<=0.07, "DENTRO DE RENDIMIENTO BASE", "EXCEDE RENDIMIENTO BASE"), IF(A15=8, IF(K15<=0.22, "DENTRO DE RENDIMIENTO BASE", "EXCEDE RENDIMIENTO BASE"), IF(A15=9, IF(J15<=0.075, "DENTRO DE RENDIMIENTO BASE", "EXCEDE RENDIMIENTO BASE"), "APOYO PUNTUAL")))))))
A16: 8 | B16: RT-05 | C16: RETROEXCAVADORA JOHN DEERE 310SK | D16: ADOLFO NAVA LOPEZ | E16: Carga Fresado y Derrumbes | F16: =$C$5 | G16: =$E$5 | H16: - | I16: 80 | J16: - | K16: =IF(G16>0, I16/G16, 0) | L16: 7.44 | M16: =IF(L16>0, I16/L16, 0) | N16: =IF(I16=0, "SIN CONSUMO (Inactiva)", IF(A16=1, IF(K16<=0.85, "DENTRO DE RENDIMIENTO BASE", "EXCEDE RENDIMIENTO BASE"), IF(A16=2, IF(J16<=0.38, "DENTRO DE RENDIMIENTO BASE", "EXCEDE RENDIMIENTO BASE"), IF(OR(A16=3,A16=4,A16=5,A16=6), IF(J16<=0.08, "DENTRO DE RENDIMIENTO BASE", "EXCEDE RENDIMIENTO BASE"), IF(A16=7, IF(J16<=0.07, "DENTRO DE RENDIMIENTO BASE", "EXCEDE RENDIMIENTO BASE"), IF(A16=8, IF(K16<=0.22, "DENTRO DE RENDIMIENTO BASE", "EXCEDE RENDIMIENTO BASE"), IF(A16=9, IF(J16<=0.075, "DENTRO DE RENDIMIENTO BASE", "EXCEDE RENDIMIENTO BASE"), "APOYO PUNTUAL")))))))
A17: 9 | B17: PT-01 | C17: PETROLIZADORA INTERNATIONAL / FORD F800 | D17: ELTHON EDUARDO MARTINEZ GOMORA | E17: Riego de Liga / Emulsión | F17: =$C$6 | G17: =$E$6 | H17: =G17*$E$4 | I17: 0 | J17: =IF(H17>0, I17/H17, 0) | K17: =IF(G17>0, I17/G17, 0) | L17: 12.76 | M17: =IF(L17>0, I17/L17, 0) | N17: =IF(I17=0, "SIN CONSUMO (Inactiva)", IF(A17=1, IF(K17<=0.85, "DENTRO DE RENDIMIENTO BASE", "EXCEDE RENDIMIENTO BASE"), IF(A17=2, IF(J17<=0.38, "DENTRO DE RENDIMIENTO BASE", "EXCEDE RENDIMIENTO BASE"), IF(OR(A17=3,A17=4,A17=5,A17=6), IF(J17<=0.08, "DENTRO DE RENDIMIENTO BASE", "EXCEDE RENDIMIENTO BASE"), IF(A17=7, IF(J17<=0.07, "DENTRO DE RENDIMIENTO BASE", "EXCEDE RENDIMIENTO BASE"), IF(A17=8, IF(K17<=0.22, "DENTRO DE RENDIMIENTO BASE", "EXCEDE RENDIMIENTO BASE"), IF(A17=9, IF(J17<=0.075, "DENTRO DE RENDIMIENTO BASE", "EXCEDE RENDIMIENTO BASE"), "APOYO PUNTUAL")))))))
A18: 10 | B18: CPR-01 | C18: COMPRESOR DE AIRE INGERSOLL RAND IR185 | D18: CUADRILLA DE LIMPIEZA | E18: Sopleteado de Juntas | F18: 0 | G18: 0 | H18: 0 | I18: 0 | J18: 0 | K18: 0 | L18: 9.97 | M18: =IF(L18>0, I18/L18, 0) | N18: =IF(I18=0, "SIN CONSUMO (Inactiva)", IF(A18=1, IF(K18<=0.85, "DENTRO DE RENDIMIENTO BASE", "EXCEDE RENDIMIENTO BASE"), IF(A18=2, IF(J18<=0.38, "DENTRO DE RENDIMIENTO BASE", "EXCEDE RENDIMIENTO BASE"), IF(OR(A18=3,A18=4,A18=5,A18=6), IF(J18<=0.08, "DENTRO DE RENDIMIENTO BASE", "EXCEDE RENDIMIENTO BASE"), IF(A18=7, IF(J18<=0.07, "DENTRO DE RENDIMIENTO BASE", "EXCEDE RENDIMIENTO BASE"), IF(A18=8, IF(K18<=0.22, "DENTRO DE RENDIMIENTO BASE", "EXCEDE RENDIMIENTO BASE"), IF(A18=9, IF(J18<=0.075, "DENTRO DE RENDIMIENTO BASE", "EXCEDE RENDIMIENTO BASE"), "APOYO PUNTUAL")))))))
A19: 11 | B19: PP-01 | C19: CAMIÓN IMPACTO / PIPA DE AGUA FORD | D19: CUADRILLA DE AGUA | E19: Enfriamiento Rodillos / Riego | F19: 0 | G19: 0 | H19: 0 | I19: 0 | J19: 0 | K19: 0 | L19: 3.03 | M19: =IF(L19>0, I19/L19, 0) | N19: =IF(I19=0, "SIN CONSUMO (Inactiva)", IF(A19=1, IF(K19<=0.85, "DENTRO DE RENDIMIENTO BASE", "EXCEDE RENDIMIENTO BASE"), IF(A19=2, IF(J19<=0.38, "DENTRO DE RENDIMIENTO BASE", "EXCEDE RENDIMIENTO BASE"), IF(OR(A19=3,A19=4,A19=5,A19=6), IF(J19<=0.08, "DENTRO DE RENDIMIENTO BASE", "EXCEDE RENDIMIENTO BASE"), IF(A19=7, IF(J19<=0.07, "DENTRO DE RENDIMIENTO BASE", "EXCEDE RENDIMIENTO BASE"), IF(A19=8, IF(K19<=0.22, "DENTRO DE RENDIMIENTO BASE", "EXCEDE RENDIMIENTO BASE"), IF(A19=9, IF(J19<=0.075, "DENTRO DE RENDIMIENTO BASE", "EXCEDE RENDIMIENTO BASE"), "APOYO PUNTUAL")))))))
A20: 12 | B20: TL-01 | C20: TORRE DE LUZ MAXILIGHT 4X1000W | D20: CUADRILLA NOCTURNA | E20: Iluminación Nocturna | F20: 0 | G20: 0 | H20: 0 | I20: 40 | J20: 0 | K20: 0 | L20: 2.41 | M20: =IF(L20>0, I20/L20, 0) | N20: =IF(I20=0, "SIN CONSUMO (Inactiva)", IF(A20=1, IF(K20<=0.85, "DENTRO DE RENDIMIENTO BASE", "EXCEDE RENDIMIENTO BASE"), IF(A20=2, IF(J20<=0.38, "DENTRO DE RENDIMIENTO BASE", "EXCEDE RENDIMIENTO BASE"), IF(OR(A20=3,A20=4,A20=5,A20=6), IF(J20<=0.08, "DENTRO DE RENDIMIENTO BASE", "EXCEDE RENDIMIENTO BASE"), IF(A20=7, IF(J20<=0.07, "DENTRO DE RENDIMIENTO BASE", "EXCEDE RENDIMIENTO BASE"), IF(A20=8, IF(K20<=0.22, "DENTRO DE RENDIMIENTO BASE", "EXCEDE RENDIMIENTO BASE"), IF(A20=9, IF(J20<=0.075, "DENTRO DE RENDIMIENTO BASE", "EXCEDE RENDIMIENTO BASE"), "APOYO PUNTUAL")))))))
A21: TOTAL SEMANA 24 (OBRA CARRETERA MÉXICO-TOLUCA) | F21: =C5+C6 | G21: =E5+E6 | H21: =G6 | I21: =SUM(I9:I20) | J21: =IF(H21>0, I21/H21, 0) | K21: =IF(G21>0, I21/G21, 0) | L21: — | M21: =SUM(M9:M20) | N21: SEMANA REGISTRADA
A24: DESGLOSE DIARIO DE COMBUSTIBLE, VOLUMEN, TONELAJE Y RENDIMIENTO — SEMANA 24
A25: DATOS DEL EQUIPO | F25: LUNES | J25: MARTES | N25: MIÉRCOLES | R25: JUEVES | V25: VIERNES | Z25: SÁBADO | AD25: TOTAL SEMANAL
A26: No. | B26: Económico | C26: Equipo / Maquinaria | D26: Operador Asignado | E26: Concepto de Trabajo | F26: Diésel (L) | G26: Volumen (m³) | H26: Toneladas (Ton) | I26: Rendimiento Real | J26: Diésel (L) | K26: Volumen (m³) | L26: Toneladas (Ton) | M26: Rendimiento Real | N26: Diésel (L) | O26: Volumen (m³) | P26: Toneladas (Ton) | Q26: Rendimiento Real | R26: Diésel (L) | S26: Volumen (m³) | T26: Toneladas (Ton) | U26: Rendimiento Real | V26: Diésel (L) | W26: Volumen (m³) | X26: Toneladas (Ton) | Y26: Rendimiento Real | Z26: Diésel (L) | AA26: Volumen (m³) | AB26: Toneladas (Ton) | AC26: Rendimiento Real | AD26: Total Diésel (L) | AE26: Total Vol (m³) | AF26: Total Ton (Ton) | AG26: Rend. Promedio
A27: 1 | B27: PRR-01 | C27: PERFILADORA WIRTGEN W200i | D27: JAVIER PAREDES CORTE | E27: Fresado de Pavimento | F27: 277 | G27: 98 | H27: =G27*$E$4 | I27: =IF(G27>0, F27/G27, 0) | J27: 0 | K27: 294 | L27: =K27*$E$4 | M27: =IF(K27>0, J27/K27, 0) | N27: 250 | O27: 378 | P27: 392 | Q27: =IF(O27>0, N27/O27, 0) | R27: 0 | S27: 0 | T27: =S27*$E$4 | U27: =IF(S27>0, R27/S27, 0) | V27: 250 | W27: 406 | X27: =W27*$E$4 | Y27: =IF(W27>0, V27/W27, 0) | Z27: 0 | AA27: 0 | AB27: =AA27*$E$4 | AC27: =IF(AA27>0, Z27/AA27, 0) | AD27: =F27+J27+N27+R27+V27+Z27 | AE27: =G27+K27+O27+S27+W27+AA27 | AF27: =H27+L27+P27+T27+X27+AB27 | AG27: =IF(AE27>0, AD27/AE27, 0)
A28: 2 | B28: VG-01 | C28: PAVIMENTADORA VÖGELE SUPER 1800-3i | D28: ERWIN CUTEÑO HERNANDEZ | E28: Tendido de Mezcla Asfáltica | F28: 0 | G28: 90 | H28: =G28*$E$4 | I28: =IF(H28>0, F28/H28, 0) | J28: 0 | K28: 0 | L28: =K28*$E$4 | M28: =IF(L28>0, J28/L28, 0) | N28: 0 | O28: 0 | P28: =O28*$E$4 | Q28: =IF(P28>0, N28/P28, 0) | R28: 136 | S28: 120 | T28: =S28*$E$4 | U28: =IF(T28>0, R28/T28, 0) | V28: 0 | W28: 272 | X28: =W28*$E$4 | Y28: =IF(X28>0, V28/X28, 0) | Z28: 0 | AA28: 90 | AB28: =AA28*$E$4 | AC28: =IF(AB28>0, Z28/AB28, 0) | AD28: =F28+J28+N28+R28+V28+Z28 | AE28: =G28+K28+O28+S28+W28+AA28 | AF28: =H28+L28+P28+T28+X28+AB28 | AG28: =IF(AF28>0, AD28/AF28, 0)
A29: 3 | B29: DR-01 | C29: COMPACTADOR TÁNDEM HAMM-HD120 VV | D29: JOEL ALBERTO RIVERA RIVAS | E29: Compactación Tándem Primaria | F29: 32 | G29: 90 | H29: =G29*$E$4 | I29: =IF(H29>0, F29/H29, 0) | J29: 0 | K29: 0 | L29: =K29*$E$4 | M29: =IF(L29>0, J29/L29, 0) | N29: 0 | O29: 0 | P29: =O29*$E$4 | Q29: =IF(P29>0, N29/P29, 0) | R29: 30 | S29: 120 | T29: =S29*$E$4 | U29: =IF(T29>0, R29/T29, 0) | V29: 40 | W29: 272 | X29: =W29*$E$4 | Y29: =IF(X29>0, V29/X29, 0) | Z29: 0 | AA29: 90 | AB29: =AA29*$E$4 | AC29: =IF(AB29>0, Z29/AB29, 0) | AD29: =F29+J29+N29+R29+V29+Z29 | AE29: =G29+K29+O29+S29+W29+AA29 | AF29: =H29+L29+P29+T29+X29+AB29 | AG29: =IF(AF29>0, AD29/AF29, 0)
A30: 4 | B30: DR-02 | C30: COMPACTADOR TÁNDEM HAMM-HD140 | D30: ALEXIS RENDON DOMINGUEZ | E30: Compactación Tándem Pesada | F30: 0 | G30: 90 | H30: =G30*$E$4 | I30: =IF(H30>0, F30/H30, 0) | J30: 0 | K30: 0 | L30: =K30*$E$4 | M30: =IF(L30>0, J30/L30, 0) | N30: 0 | O30: 0 | P30: =O30*$E$4 | Q30: =IF(P30>0, N30/P30, 0) | R30: 0 | S30: 120 | T30: =S30*$E$4 | U30: =IF(T30>0, R30/T30, 0) | V30: 0 | W30: 272 | X30: =W30*$E$4 | Y30: =IF(X30>0, V30/X30, 0) | Z30: 0 | AA30: 90 | AB30: =AA30*$E$4 | AC30: =IF(AB30>0, Z30/AB30, 0) | AD30: =F30+J30+N30+R30+V30+Z30 | AE30: =G30+K30+O30+S30+W30+AA30 | AF30: =H30+L30+P30+T30+X30+AB30 | AG30: =IF(AF30>0, AD30/AF30, 0)
A31: 5 | B31: NM-01 | C31: COMPACTADOR NEUMÁTICO DYNAPAC CP271 | D31: JOSE CARLOS ROMERO TELLEZ | E31: Compactación Neumática / Sellado | F31: 30 | G31: 90 | H31: =G31*$E$4 | I31: =IF(H31>0, F31/H31, 0) | J31: 0 | K31: 0 | L31: =K31*$E$4 | M31: =IF(L31>0, J31/L31, 0) | N31: 0 | O31: 0 | P31: =O31*$E$4 | Q31: =IF(P31>0, N31/P31, 0) | R31: 30 | S31: 120 | T31: =S31*$E$4 | U31: =IF(T31>0, R31/T31, 0) | V31: 30 | W31: 272 | X31: =W31*$E$4 | Y31: =IF(X31>0, V31/X31, 0) | Z31: 0 | AA31: 90 | AB31: =AA31*$E$4 | AC31: =IF(AB31>0, Z31/AB31, 0) | AD31: =F31+J31+N31+R31+V31+Z31 | AE31: =G31+K31+O31+S31+W31+AA31 | AF31: =H31+L31+P31+T31+X31+AB31 | AG31: =IF(AF31>0, AD31/AF31, 0)
A32: 6 | B32: NM-09 | C32: COMPACTADOR NEUMÁTICO HAMM 208 | D32: NOLVIN DE JESUS PEREZ GOMEZ | E32: Compactación Neumática / Acabado | F32: 0 | G32: 90 | H32: =G32*$E$4 | I32: =IF(H32>0, F32/H32, 0) | J32: 0 | K32: 0 | L32: =K32*$E$4 | M32: =IF(L32>0, J32/L32, 0) | N32: 0 | O32: 0 | P32: =O32*$E$4 | Q32: =IF(P32>0, N32/P32, 0) | R32: 0 | S32: 120 | T32: =S32*$E$4 | U32: =IF(T32>0, R32/T32, 0) | V32: 0 | W32: 272 | X32: =W32*$E$4 | Y32: =IF(X32>0, V32/X32, 0) | Z32: 0 | AA32: 90 | AB32: =AA32*$E$4 | AC32: =IF(AB32>0, Z32/AB32, 0) | AD32: =F32+J32+N32+R32+V32+Z32 | AE32: =G32+K32+O32+S32+W32+AA32 | AF32: =H32+L32+P32+T32+X32+AB32 | AG32: =IF(AF32>0, AD32/AF32, 0)
A33: 7 | B33: BR-01 | C33: BARREDORA INDUSTRIAL BROCE BROOM-350 | D33: EDGAR ROSALES MARTINEZ | E33: Limpieza y Barrido Previo | F33: 0 | G33: 90 | H33: =G33*$E$4 | I33: =IF(H33>0, F33/H33, 0) | J33: 0 | K33: 0 | L33: =K33*$E$4 | M33: =IF(L33>0, J33/L33, 0) | N33: 20 | O33: 0 | P33: =O33*$E$4 | Q33: =IF(P33>0, N33/P33, 0) | R33: 20 | S33: 120 | T33: =S33*$E$4 | U33: =IF(T33>0, R33/T33, 0) | V33: 20 | W33: 272 | X33: =W33*$E$4 | Y33: =IF(X33>0, V33/X33, 0) | Z33: 0 | AA33: 90 | AB33: =AA33*$E$4 | AC33: =IF(AB33>0, Z33/AB33, 0) | AD33: =F33+J33+N33+R33+V33+Z33 | AE33: =G33+K33+O33+S33+W33+AA33 | AF33: =H33+L33+P33+T33+X33+AB33 | AG33: =IF(AF33>0, AD33/AF33, 0)
A34: 8 | B34: RT-05 | C34: RETROEXCAVADORA JOHN DEERE 310SK | D34: ADOLFO NAVA LOPEZ | E34: Carga Fresado y Derrumbes | F34: 30 | G34: 98 | H34: =G34*$E$4 | I34: =IF(G34>0, F34/G34, 0) | J34: 0 | K34: 294 | L34: =K34*$E$4 | M34: =IF(K34>0, J34/K34, 0) | N34: 30 | O34: 378 | P34: 392 | Q34: =IF(O34>0, N34/O34, 0) | R34: 20 | S34: 0 | T34: =S34*$E$4 | U34: =IF(S34>0, R34/S34, 0) | V34: 0 | W34: 406 | X34: =W34*$E$4 | Y34: =IF(W34>0, V34/W34, 0) | Z34: 0 | AA34: 0 | AB34: =AA34*$E$4 | AC34: =IF(AA34>0, Z34/AA34, 0) | AD34: =F34+J34+N34+R34+V34+Z34 | AE34: =G34+K34+O34+S34+W34+AA34 | AF34: =H34+L34+P34+T34+X34+AB34 | AG34: =IF(AE34>0, AD34/AE34, 0)
A35: 9 | B35: PT-01 | C35: PETROLIZADORA INTERNATIONAL / FORD F800 | D35: ELTHON EDUARDO MARTINEZ GOMORA | E35: Riego de Liga / Emulsión | F35: 0 | G35: 90 | H35: =G35*$E$4 | I35: =IF(H35>0, F35/H35, 0) | J35: 0 | K35: 0 | L35: =K35*$E$4 | M35: =IF(L35>0, J35/L35, 0) | N35: 0 | O35: 0 | P35: =O35*$E$4 | Q35: =IF(P35>0, N35/P35, 0) | R35: 0 | S35: 120 | T35: =S35*$E$4 | U35: =IF(T35>0, R35/T35, 0) | V35: 0 | W35: 272 | X35: =W35*$E$4 | Y35: =IF(X35>0, V35/X35, 0) | Z35: 0 | AA35: 90 | AB35: =AA35*$E$4 | AC35: =IF(AB35>0, Z35/AB35, 0) | AD35: =F35+J35+N35+R35+V35+Z35 | AE35: =G35+K35+O35+S35+W35+AA35 | AF35: =H35+L35+P35+T35+X35+AB35 | AG35: =IF(AF35>0, AD35/AF35, 0)
A36: 10 | B36: CPR-01 | C36: COMPRESOR DE AIRE INGERSOLL RAND IR185 | D36: CUADRILLA DE LIMPIEZA | E36: Sopleteado de Juntas | F36: 0 | G36: 0 | H36: =G36*$E$4 | I36: 0 | J36: 0 | K36: 0 | L36: =K36*$E$4 | M36: 0 | N36: 0 | O36: 0 | P36: =O36*$E$4 | Q36: 0 | R36: 0 | S36: 0 | T36: =S36*$E$4 | U36: 0 | V36: 0 | W36: 0 | X36: =W36*$E$4 | Y36: 0 | Z36: 0 | AA36: 0 | AB36: =AA36*$E$4 | AC36: 0 | AD36: =F36+J36+N36+R36+V36+Z36 | AE36: =G36+K36+O36+S36+W36+AA36 | AF36: =H36+L36+P36+T36+X36+AB36 | AG36: 0
A37: 11 | B37: PP-01 | C37: CAMIÓN IMPACTO / PIPA DE AGUA FORD | D37: CUADRILLA DE AGUA | E37: Enfriamiento Rodillos / Riego | F37: 0 | G37: 0 | H37: =G37*$E$4 | I37: 0 | J37: 0 | K37: 0 | L37: =K37*$E$4 | M37: 0 | N37: 0 | O37: 0 | P37: =O37*$E$4 | Q37: 0 | R37: 0 | S37: 0 | T37: =S37*$E$4 | U37: 0 | V37: 0 | W37: 0 | X37: =W37*$E$4 | Y37: 0 | Z37: 0 | AA37: 0 | AB37: =AA37*$E$4 | AC37: 0 | AD37: =F37+J37+N37+R37+V37+Z37 | AE37: =G37+K37+O37+S37+W37+AA37 | AF37: =H37+L37+P37+T37+X37+AB37 | AG37: 0
A38: 12 | B38: TL-01 | C38: TORRE DE LUZ MAXILIGHT 4X1000W | D38: CUADRILLA NOCTURNA | E38: Iluminación Nocturna | F38: 0 | G38: 0 | H38: =G38*$E$4 | I38: 0 | J38: 0 | K38: 0 | L38: =K38*$E$4 | M38: 0 | N38: 0 | O38: 0 | P38: =O38*$E$4 | Q38: 0 | R38: 20 | S38: 0 | T38: =S38*$E$4 | U38: 0 | V38: 20 | W38: 0 | X38: =W38*$E$4 | Y38: 0 | Z38: 0 | AA38: 0 | AB38: =AA38*$E$4 | AC38: 0 | AD38: =F38+J38+N38+R38+V38+Z38 | AE38: =G38+K38+O38+S38+W38+AA38 | AF38: =H38+L38+P38+T38+X38+AB38 | AG38: 0
A39: TOTAL DIARIO CONSOLIDADO (OBRA MÉXICO-TOLUCA) | F39: =SUM(F27:F38) | G39: =MAX(G27:G38) | H39: =G39*$E$4 | I39: =IF(H39>0, F39/H39, 0) | J39: =SUM(J27:J38) | K39: =MAX(K27:K38) | L39: =K39*$E$4 | M39: =IF(L39>0, J39/L39, 0) | N39: =SUM(N27:N38) | O39: =MAX(O27:O38) | P39: =O39*$E$4 | Q39: =IF(P39>0, N39/P39, 0) | R39: =SUM(R27:R38) | S39: =MAX(S27:S38) | T39: =S39*$E$4 | U39: =IF(T39>0, R39/T39, 0) | V39: =SUM(V27:V38) | W39: =MAX(W27:W38) | X39: =W39*$E$4 | Y39: =IF(X39>0, V39/X39, 0) | Z39: =SUM(Z27:Z38) | AA39: =MAX(AA27:AA38) | AB39: =AA39*$E$4 | AC39: =IF(AB39>0, Z39/AB39, 0) | AD39: =SUM(AD27:AD38) | AE39: =SUM(AE27:AE38) | AF39: =SUM(AF27:AF38) | AG39: =IF(AF39>0, AD39/AF39, 0)
A41: NOTA TÉCNICA Y CRITERIOS DE CONTROL DE RENDIMIENTO — OBRA MÉXICO-TOLUCA: 1. Peso Volumétrico Oficial del Asfalto: 1.742 Ton/m³ (Toneladas = m³ Carpeta × 1.742). 2. Rendimiento Base (L/h): Consumo nominal de fabricante ajustado con 1.2% anual de desgaste por antigüedad al 2026. 3. Rendimiento Real: Diésel Surtido / Toneladas Tendidas (L/Ton) o Diésel Surtido / Volumen Fresado (L/m³). 4. Estatus Operativo: DENTRO DE RENDIMIENTO BASE (Verde) / EXCEDE RENDIMIENTO BASE (Rojo) / SIN CONSUMO (Gris).

Sheet Semana 25
A1: CONTROL SEMANAL DE RENDIMIENTO DE MAQUINARIA (SEMANA 25)
A2: OBRA: CARRETERA LIBRE MÉXICO-TOLUCA | PERIODO: 15/Jun/2026 - 20/Jun/2026
A4: 1. PARÁMETROS: | B4: PESO VOLUMÉTRICO ASFALTO (Ton/m³): | E4: 1.742
A5: 2. FRESADO SEMANAL: | B5: Viajes de Fresado: | C5: 71 | D5: Volumen Fresado (m³): | E5: 994
A6: 3. CARPETA SEMANAL: | B6: Viajes de Mezcla: | C6: 69 | D6: Volumen Carpeta (m³): | E6: 960 | F6: Toneladas Carpeta (Ton): | G6: =E6*$E$4
A8: No. | B8: Económico | C8: Equipo / Maquinaria | D8: Operador Asignado | E8: Concepto de Trabajo | F8: Viajes Asignados | G8: Volumen (m³) | H8: Toneladas (Ton) | I8: Diésel Surtido (L) | J8: Rendimiento Real (L/Ton) | K8: Rendimiento Real (L/m³) | L8: Rend. Base (L/h) | M8: Horas Est. Operación | N8: Estatus Operativo
A9: 1 | B9: PRR-01 | C9: PERFILADORA WIRTGEN W200i | D9: JAVIER PAREDES CORTE | E9: Fresado de Pavimento | F9: =$C$5 | G9: =$E$5 | H9: - | I9: 1200 | J9: - | K9: =IF(G9>0, I9/G9, 0) | L9: 67.2 | M9: =IF(L9>0, I9/L9, 0) | N9: =IF(I9=0, "SIN CONSUMO (Inactiva)", IF(A9=1, IF(K9<=0.85, "DENTRO DE RENDIMIENTO BASE", "EXCEDE RENDIMIENTO BASE"), IF(A9=2, IF(J9<=0.38, "DENTRO DE RENDIMIENTO BASE", "EXCEDE RENDIMIENTO BASE"), IF(OR(A9=3,A9=4,A9=5,A9=6), IF(J9<=0.08, "DENTRO DE RENDIMIENTO BASE", "EXCEDE RENDIMIENTO BASE"), IF(A9=7, IF(J9<=0.07, "DENTRO DE RENDIMIENTO BASE", "EXCEDE RENDIMIENTO BASE"), IF(A9=8, IF(K9<=0.22, "DENTRO DE RENDIMIENTO BASE", "EXCEDE RENDIMIENTO BASE"), IF(A9=9, IF(J9<=0.075, "DENTRO DE RENDIMIENTO BASE", "EXCEDE RENDIMIENTO BASE"), "APOYO PUNTUAL")))))))
A10: 2 | B10: VG-01 | C10: PAVIMENTADORA VÖGELE SUPER 1800-3i | D10: ERWIN CUTEÑO HERNANDEZ | E10: Tendido de Mezcla Asfáltica | F10: =$C$6 | G10: =$E$6 | H10: =G10*$E$4 | I10: 561 | J10: =IF(H10>0, I10/H10, 0) | K10: =IF(G10>0, I10/G10, 0) | L10: 16.24 | M10: =IF(L10>0, I10/L10, 0) | N10: =IF(I10=0, "SIN CONSUMO (Inactiva)", IF(A10=1, IF(K10<=0.85, "DENTRO DE RENDIMIENTO BASE", "EXCEDE RENDIMIENTO BASE"), IF(A10=2, IF(J10<=0.38, "DENTRO DE RENDIMIENTO BASE", "EXCEDE RENDIMIENTO BASE"), IF(OR(A10=3,A10=4,A10=5,A10=6), IF(J10<=0.08, "DENTRO DE RENDIMIENTO BASE", "EXCEDE RENDIMIENTO BASE"), IF(A10=7, IF(J10<=0.07, "DENTRO DE RENDIMIENTO BASE", "EXCEDE RENDIMIENTO BASE"), IF(A10=8, IF(K10<=0.22, "DENTRO DE RENDIMIENTO BASE", "EXCEDE RENDIMIENTO BASE"), IF(A10=9, IF(J10<=0.075, "DENTRO DE RENDIMIENTO BASE", "EXCEDE RENDIMIENTO BASE"), "APOYO PUNTUAL")))))))
A11: 3 | B11: DR-01 | C11: COMPACTADOR TÁNDEM HAMM-HD120 VV | D11: JOEL ALBERTO RIVERA RIVAS | E11: Compactación Tándem Primaria | F11: =$C$6 | G11: =$E$6 | H11: =G11*$E$4 | I11: 172 | J11: =IF(H11>0, I11/H11, 0) | K11: =IF(G11>0, I11/G11, 0) | L11: 14.3 | M11: =IF(L11>0, I11/L11, 0) | N11: =IF(I11=0, "SIN CONSUMO (Inactiva)", IF(A11=1, IF(K11<=0.85, "DENTRO DE RENDIMIENTO BASE", "EXCEDE RENDIMIENTO BASE"), IF(A11=2, IF(J11<=0.38, "DENTRO DE RENDIMIENTO BASE", "EXCEDE RENDIMIENTO BASE"), IF(OR(A11=3,A11=4,A11=5,A11=6), IF(J11<=0.08, "DENTRO DE RENDIMIENTO BASE", "EXCEDE RENDIMIENTO BASE"), IF(A11=7, IF(J11<=0.07, "DENTRO DE RENDIMIENTO BASE", "EXCEDE RENDIMIENTO BASE"), IF(A11=8, IF(K11<=0.22, "DENTRO DE RENDIMIENTO BASE", "EXCEDE RENDIMIENTO BASE"), IF(A11=9, IF(J11<=0.075, "DENTRO DE RENDIMIENTO BASE", "EXCEDE RENDIMIENTO BASE"), "APOYO PUNTUAL")))))))
A12: 4 | B12: DR-02 | C12: COMPACTADOR TÁNDEM HAMM-HD140 | D12: ALEXIS RENDON DOMINGUEZ | E12: Compactación Tándem Pesada | F12: =$C$6 | G12: =$E$6 | H12: =G12*$E$4 | I12: 33 | J12: =IF(H12>0, I12/H12, 0) | K12: =IF(G12>0, I12/G12, 0) | L12: 14.3 | M12: =IF(L12>0, I12/L12, 0) | N12: =IF(I12=0, "SIN CONSUMO (Inactiva)", IF(A12=1, IF(K12<=0.85, "DENTRO DE RENDIMIENTO BASE", "EXCEDE RENDIMIENTO BASE"), IF(A12=2, IF(J12<=0.38, "DENTRO DE RENDIMIENTO BASE", "EXCEDE RENDIMIENTO BASE"), IF(OR(A12=3,A12=4,A12=5,A12=6), IF(J12<=0.08, "DENTRO DE RENDIMIENTO BASE", "EXCEDE RENDIMIENTO BASE"), IF(A12=7, IF(J12<=0.07, "DENTRO DE RENDIMIENTO BASE", "EXCEDE RENDIMIENTO BASE"), IF(A12=8, IF(K12<=0.22, "DENTRO DE RENDIMIENTO BASE", "EXCEDE RENDIMIENTO BASE"), IF(A12=9, IF(J12<=0.075, "DENTRO DE RENDIMIENTO BASE", "EXCEDE RENDIMIENTO BASE"), "APOYO PUNTUAL")))))))
A13: 5 | B13: NM-01 | C13: COMPACTADOR NEUMÁTICO DYNAPAC CP271 | D13: JOSE CARLOS ROMERO TELLEZ | E13: Compactación Neumática / Sellado | F13: =$C$6 | G13: =$E$6 | H13: =G13*$E$4 | I13: 224 | J13: =IF(H13>0, I13/H13, 0) | K13: =IF(G13>0, I13/G13, 0) | L13: 11.44 | M13: =IF(L13>0, I13/L13, 0) | N13: =IF(I13=0, "SIN CONSUMO (Inactiva)", IF(A13=1, IF(K13<=0.85, "DENTRO DE RENDIMIENTO BASE", "EXCEDE RENDIMIENTO BASE"), IF(A13=2, IF(J13<=0.38, "DENTRO DE RENDIMIENTO BASE", "EXCEDE RENDIMIENTO BASE"), IF(OR(A13=3,A13=4,A13=5,A13=6), IF(J13<=0.08, "DENTRO DE RENDIMIENTO BASE", "EXCEDE RENDIMIENTO BASE"), IF(A13=7, IF(J13<=0.07, "DENTRO DE RENDIMIENTO BASE", "EXCEDE RENDIMIENTO BASE"), IF(A13=8, IF(K13<=0.22, "DENTRO DE RENDIMIENTO BASE", "EXCEDE RENDIMIENTO BASE"), IF(A13=9, IF(J13<=0.075, "DENTRO DE RENDIMIENTO BASE", "EXCEDE RENDIMIENTO BASE"), "APOYO PUNTUAL")))))))
A14: 6 | B14: NM-09 | C14: COMPACTADOR NEUMÁTICO HAMM 208 | D14: NOLVIN DE JESUS PEREZ GOMEZ | E14: Compactación Neumática / Acabado | F14: =$C$6 | G14: =$E$6 | H14: =G14*$E$4 | I14: 0 | J14: =IF(H14>0, I14/H14, 0) | K14: =IF(G14>0, I14/G14, 0) | L14: 10.96 | M14: =IF(L14>0, I14/L14, 0) | N14: =IF(I14=0, "SIN CONSUMO (Inactiva)", IF(A14=1, IF(K14<=0.85, "DENTRO DE RENDIMIENTO BASE", "EXCEDE RENDIMIENTO BASE"), IF(A14=2, IF(J14<=0.38, "DENTRO DE RENDIMIENTO BASE", "EXCEDE RENDIMIENTO BASE"), IF(OR(A14=3,A14=4,A14=5,A14=6), IF(J14<=0.08, "DENTRO DE RENDIMIENTO BASE", "EXCEDE RENDIMIENTO BASE"), IF(A14=7, IF(J14<=0.07, "DENTRO DE RENDIMIENTO BASE", "EXCEDE RENDIMIENTO BASE"), IF(A14=8, IF(K14<=0.22, "DENTRO DE RENDIMIENTO BASE", "EXCEDE RENDIMIENTO BASE"), IF(A14=9, IF(J14<=0.075, "DENTRO DE RENDIMIENTO BASE", "EXCEDE RENDIMIENTO BASE"), "APOYO PUNTUAL")))))))
A15: 7 | B15: BR-01 | C15: BARREDORA INDUSTRIAL BROCE BROOM-350 | D15: EDGAR ROSALES MARTINEZ | E15: Limpieza y Barrido Previo | F15: =$C$6 | G15: =$E$6 | H15: =G15*$E$4 | I15: 88 | J15: =IF(H15>0, I15/H15, 0) | K15: =IF(G15>0, I15/G15, 0) | L15: 8.94 | M15: =IF(L15>0, I15/L15, 0) | N15: =IF(I15=0, "SIN CONSUMO (Inactiva)", IF(A15=1, IF(K15<=0.85, "DENTRO DE RENDIMIENTO BASE", "EXCEDE RENDIMIENTO BASE"), IF(A15=2, IF(J15<=0.38, "DENTRO DE RENDIMIENTO BASE", "EXCEDE RENDIMIENTO BASE"), IF(OR(A15=3,A15=4,A15=5,A15=6), IF(J15<=0.08, "DENTRO DE RENDIMIENTO BASE", "EXCEDE RENDIMIENTO BASE"), IF(A15=7, IF(J15<=0.07, "DENTRO DE RENDIMIENTO BASE", "EXCEDE RENDIMIENTO BASE"), IF(A15=8, IF(K15<=0.22, "DENTRO DE RENDIMIENTO BASE", "EXCEDE RENDIMIENTO BASE"), IF(A15=9, IF(J15<=0.075, "DENTRO DE RENDIMIENTO BASE", "EXCEDE RENDIMIENTO BASE"), "APOYO PUNTUAL")))))))
A16: 8 | B16: RT-05 | C16: RETROEXCAVADORA JOHN DEERE 310SK | D16: ADOLFO NAVA LOPEZ | E16: Carga Fresado y Derrumbes | F16: =$C$5 | G16: =$E$5 | H16: - | I16: 320 | J16: - | K16: =IF(G16>0, I16/G16, 0) | L16: 7.44 | M16: =IF(L16>0, I16/L16, 0) | N16: =IF(I16=0, "SIN CONSUMO (Inactiva)", IF(A16=1, IF(K16<=0.85, "DENTRO DE RENDIMIENTO BASE", "EXCEDE RENDIMIENTO BASE"), IF(A16=2, IF(J16<=0.38, "DENTRO DE RENDIMIENTO BASE", "EXCEDE RENDIMIENTO BASE"), IF(OR(A16=3,A16=4,A16=5,A16=6), IF(J16<=0.08, "DENTRO DE RENDIMIENTO BASE", "EXCEDE RENDIMIENTO BASE"), IF(A16=7, IF(J16<=0.07, "DENTRO DE RENDIMIENTO BASE", "EXCEDE RENDIMIENTO BASE"), IF(A16=8, IF(K16<=0.22, "DENTRO DE RENDIMIENTO BASE", "EXCEDE RENDIMIENTO BASE"), IF(A16=9, IF(J16<=0.075, "DENTRO DE RENDIMIENTO BASE", "EXCEDE RENDIMIENTO BASE"), "APOYO PUNTUAL")))))))
A17: 9 | B17: PT-01 | C17: PETROLIZADORA INTERNATIONAL / FORD F800 | D17: ELTHON EDUARDO MARTINEZ GOMORA | E17: Riego de Liga / Emulsión | F17: =$C$6 | G17: =$E$6 | H17: =G17*$E$4 | I17: 150 | J17: =IF(H17>0, I17/H17, 0) | K17: =IF(G17>0, I17/G17, 0) | L17: 12.76 | M17: =IF(L17>0, I17/L17, 0) | N17: =IF(I17=0, "SIN CONSUMO (Inactiva)", IF(A17=1, IF(K17<=0.85, "DENTRO DE RENDIMIENTO BASE", "EXCEDE RENDIMIENTO BASE"), IF(A17=2, IF(J17<=0.38, "DENTRO DE RENDIMIENTO BASE", "EXCEDE RENDIMIENTO BASE"), IF(OR(A17=3,A17=4,A17=5,A17=6), IF(J17<=0.08, "DENTRO DE RENDIMIENTO BASE", "EXCEDE RENDIMIENTO BASE"), IF(A17=7, IF(J17<=0.07, "DENTRO DE RENDIMIENTO BASE", "EXCEDE RENDIMIENTO BASE"), IF(A17=8, IF(K17<=0.22, "DENTRO DE RENDIMIENTO BASE", "EXCEDE RENDIMIENTO BASE"), IF(A17=9, IF(J17<=0.075, "DENTRO DE RENDIMIENTO BASE", "EXCEDE RENDIMIENTO BASE"), "APOYO PUNTUAL")))))))
A18: 10 | B18: CPR-01 | C18: COMPRESOR DE AIRE INGERSOLL RAND IR185 | D18: CUADRILLA DE LIMPIEZA | E18: Sopleteado de Juntas | F18: 0 | G18: 0 | H18: 0 | I18: 0 | J18: 0 | K18: 0 | L18: 9.97 | M18: =IF(L18>0, I18/L18, 0) | N18: =IF(I18=0, "SIN CONSUMO (Inactiva)", IF(A18=1, IF(K18<=0.85, "DENTRO DE RENDIMIENTO BASE", "EXCEDE RENDIMIENTO BASE"), IF(A18=2, IF(J18<=0.38, "DENTRO DE RENDIMIENTO BASE", "EXCEDE RENDIMIENTO BASE"), IF(OR(A18=3,A18=4,A18=5,A18=6), IF(J18<=0.08, "DENTRO DE RENDIMIENTO BASE", "EXCEDE RENDIMIENTO BASE"), IF(A18=7, IF(J18<=0.07, "DENTRO DE RENDIMIENTO BASE", "EXCEDE RENDIMIENTO BASE"), IF(A18=8, IF(K18<=0.22, "DENTRO DE RENDIMIENTO BASE", "EXCEDE RENDIMIENTO BASE"), IF(A18=9, IF(J18<=0.075, "DENTRO DE RENDIMIENTO BASE", "EXCEDE RENDIMIENTO BASE"), "APOYO PUNTUAL")))))))
A19: 11 | B19: PP-01 | C19: CAMIÓN IMPACTO / PIPA DE AGUA FORD | D19: CUADRILLA DE AGUA | E19: Enfriamiento Rodillos / Riego | F19: 0 | G19: 0 | H19: 0 | I19: 0 | J19: 0 | K19: 0 | L19: 3.03 | M19: =IF(L19>0, I19/L19, 0) | N19: =IF(I19=0, "SIN CONSUMO (Inactiva)", IF(A19=1, IF(K19<=0.85, "DENTRO DE RENDIMIENTO BASE", "EXCEDE RENDIMIENTO BASE"), IF(A19=2, IF(J19<=0.38, "DENTRO DE RENDIMIENTO BASE", "EXCEDE RENDIMIENTO BASE"), IF(OR(A19=3,A19=4,A19=5,A19=6), IF(J19<=0.08, "DENTRO DE RENDIMIENTO BASE", "EXCEDE RENDIMIENTO BASE"), IF(A19=7, IF(J19<=0.07, "DENTRO DE RENDIMIENTO BASE", "EXCEDE RENDIMIENTO BASE"), IF(A19=8, IF(K19<=0.22, "DENTRO DE RENDIMIENTO BASE", "EXCEDE RENDIMIENTO BASE"), IF(A19=9, IF(J19<=0.075, "DENTRO DE RENDIMIENTO BASE", "EXCEDE RENDIMIENTO BASE"), "APOYO PUNTUAL")))))))
A20: 12 | B20: TL-01 | C20: TORRE DE LUZ MAXILIGHT 4X1000W | D20: CUADRILLA NOCTURNA | E20: Iluminación Nocturna | F20: 0 | G20: 0 | H20: 0 | I20: 0 | J20: 0 | K20: 0 | L20: 2.41 | M20: =IF(L20>0, I20/L20, 0) | N20: =IF(I20=0, "SIN CONSUMO (Inactiva)", IF(A20=1, IF(K20<=0.85, "DENTRO DE RENDIMIENTO BASE", "EXCEDE RENDIMIENTO BASE"), IF(A20=2, IF(J20<=0.38, "DENTRO DE RENDIMIENTO BASE", "EXCEDE RENDIMIENTO BASE"), IF(OR(A20=3,A20=4,A20=5,A20=6), IF(J20<=0.08, "DENTRO DE RENDIMIENTO BASE", "EXCEDE RENDIMIENTO BASE"), IF(A20=7, IF(J20<=0.07, "DENTRO DE RENDIMIENTO BASE", "EXCEDE RENDIMIENTO BASE"), IF(A20=8, IF(K20<=0.22, "DENTRO DE RENDIMIENTO BASE", "EXCEDE RENDIMIENTO BASE"), IF(A20=9, IF(J20<=0.075, "DENTRO DE RENDIMIENTO BASE", "EXCEDE RENDIMIENTO BASE"), "APOYO PUNTUAL")))))))
A21: TOTAL SEMANA 25 (OBRA CARRETERA MÉXICO-TOLUCA) | F21: =C5+C6 | G21: =E5+E6 | H21: =G6 | I21: =SUM(I9:I20) | J21: =IF(H21>0, I21/H21, 0) | K21: =IF(G21>0, I21/G21, 0) | L21: — | M21: =SUM(M9:M20) | N21: SEMANA REGISTRADA
A24: DESGLOSE DIARIO DE COMBUSTIBLE, VOLUMEN, TONELAJE Y RENDIMIENTO — SEMANA 25
A25: DATOS DEL EQUIPO | F25: LUNES | J25: MARTES | N25: MIÉRCOLES | R25: JUEVES | V25: VIERNES | Z25: SÁBADO | AD25: TOTAL SEMANAL
A26: No. | B26: Económico | C26: Equipo / Maquinaria | D26: Operador Asignado | E26: Concepto de Trabajo | F26: Diésel (L) | G26: Volumen (m³) | H26: Toneladas (Ton) | I26: Rendimiento Real | J26: Diésel (L) | K26: Volumen (m³) | L26: Toneladas (Ton) | M26: Rendimiento Real | N26: Diésel (L) | O26: Volumen (m³) | P26: Toneladas (Ton) | Q26: Rendimiento Real | R26: Diésel (L) | S26: Volumen (m³) | T26: Toneladas (Ton) | U26: Rendimiento Real | V26: Diésel (L) | W26: Volumen (m³) | X26: Toneladas (Ton) | Y26: Rendimiento Real | Z26: Diésel (L) | AA26: Volumen (m³) | AB26: Toneladas (Ton) | AC26: Rendimiento Real | AD26: Total Diésel (L) | AE26: Total Vol (m³) | AF26: Total Ton (Ton) | AG26: Rend. Promedio
A27: 1 | B27: PRR-01 | C27: PERFILADORA WIRTGEN W200i | D27: JAVIER PAREDES CORTE | E27: Fresado de Pavimento | F27: 400 | G27: 238 | H27: =G27*$E$4 | I27: =IF(G27>0, F27/G27, 0) | J27: 400 | K27: 210 | L27: =K27*$E$4 | M27: =IF(K27>0, J27/K27, 0) | N27: 200 | O27: 280 | P27: =O27*$E$4 | Q27: =IF(O27>0, N27/O27, 0) | R27: 200 | S27: 266 | T27: =S27*$E$4 | U27: =IF(S27>0, R27/S27, 0) | V27: 0 | W27: 0 | X27: =W27*$E$4 | Y27: =IF(W27>0, V27/W27, 0) | Z27: 0 | AA27: 0 | AB27: =AA27*$E$4 | AC27: =IF(AA27>0, Z27/AA27, 0) | AD27: =F27+J27+N27+R27+V27+Z27 | AE27: =G27+K27+O27+S27+W27+AA27 | AF27: =H27+L27+P27+T27+X27+AB27 | AG27: =IF(AE27>0, AD27/AE27, 0)
A28: 2 | B28: VG-01 | C28: PAVIMENTADORA VÖGELE SUPER 1800-3i | D28: ERWIN CUTEÑO HERNANDEZ | E28: Tendido de Mezcla Asfáltica | F28: 99 | G28: 162 | H28: =G28*$E$4 | I28: =IF(H28>0, F28/H28, 0) | J28: 107 | K28: 238 | L28: =K28*$E$4 | M28: =IF(L28>0, J28/L28, 0) | N28: 120 | O28: 168 | P28: =O28*$E$4 | Q28: =IF(P28>0, N28/P28, 0) | R28: 115 | S28: 196 | T28: =S28*$E$4 | U28: =IF(T28>0, R28/T28, 0) | V28: 120 | W28: 196 | X28: =W28*$E$4 | Y28: =IF(X28>0, V28/X28, 0) | Z28: 0 | AA28: 0 | AB28: =AA28*$E$4 | AC28: =IF(AB28>0, Z28/AB28, 0) | AD28: =F28+J28+N28+R28+V28+Z28 | AE28: =G28+K28+O28+S28+W28+AA28 | AF28: =H28+L28+P28+T28+X28+AB28 | AG28: =IF(AF28>0, AD28/AF28, 0)
A29: 3 | B29: DR-01 | C29: COMPACTADOR TÁNDEM HAMM-HD120 VV | D29: JOEL ALBERTO RIVERA RIVAS | E29: Compactación Tándem Primaria | F29: 0 | G29: 162 | H29: =G29*$E$4 | I29: =IF(H29>0, F29/H29, 0) | J29: 0 | K29: 238 | L29: =K29*$E$4 | M29: =IF(L29>0, J29/L29, 0) | N29: 0 | O29: 168 | P29: =O29*$E$4 | Q29: =IF(P29>0, N29/P29, 0) | R29: 0 | S29: 196 | T29: =S29*$E$4 | U29: =IF(T29>0, R29/T29, 0) | V29: 0 | W29: 196 | X29: =W29*$E$4 | Y29: =IF(X29>0, V29/X29, 0) | Z29: 0 | AA29: 0 | AB29: =AA29*$E$4 | AC29: =IF(AB29>0, Z29/AB29, 0) | AD29: =F29+J29+N29+R29+V29+Z29 | AE29: =G29+K29+O29+S29+W29+AA29 | AF29: =H29+L29+P29+T29+X29+AB29 | AG29: =IF(AF29>0, AD29/AF29, 0)
A30: 4 | B30: DR-02 | C30: COMPACTADOR TÁNDEM HAMM-HD140 | D30: ALEXIS RENDON DOMINGUEZ | E30: Compactación Tándem Pesada | F30: 33 | G30: 162 | H30: =G30*$E$4 | I30: =IF(H30>0, F30/H30, 0) | J30: 0 | K30: 238 | L30: =K30*$E$4 | M30: =IF(L30>0, J30/L30, 0) | N30: 0 | O30: 168 | P30: =O30*$E$4 | Q30: =IF(P30>0, N30/P30, 0) | R30: 0 | S30: 196 | T30: =S30*$E$4 | U30: =IF(T30>0, R30/T30, 0) | V30: 0 | W30: 196 | X30: =W30*$E$4 | Y30: =IF(X30>0, V30/X30, 0) | Z30: 0 | AA30: 0 | AB30: =AA30*$E$4 | AC30: =IF(AB30>0, Z30/AB30, 0) | AD30: =F30+J30+N30+R30+V30+Z30 | AE30: =G30+K30+O30+S30+W30+AA30 | AF30: =H30+L30+P30+T30+X30+AB30 | AG30: =IF(AF30>0, AD30/AF30, 0)
A31: 5 | B31: NM-01 | C31: COMPACTADOR NEUMÁTICO DYNAPAC CP271 | D31: JOSE CARLOS ROMERO TELLEZ | E31: Compactación Neumática / Sellado | F31: 50 | G31: 162 | H31: =G31*$E$4 | I31: =IF(H31>0, F31/H31, 0) | J31: 30 | K31: 238 | L31: =K31*$E$4 | M31: =IF(L31>0, J31/L31, 0) | N31: 30 | O31: 168 | P31: =O31*$E$4 | Q31: =IF(P31>0, N31/P31, 0) | R31: 30 | S31: 196 | T31: =S31*$E$4 | U31: =IF(T31>0, R31/T31, 0) | V31: 84 | W31: 196 | X31: =W31*$E$4 | Y31: =IF(X31>0, V31/X31, 0) | Z31: 0 | AA31: 0 | AB31: =AA31*$E$4 | AC31: =IF(AB31>0, Z31/AB31, 0) | AD31: =F31+J31+N31+R31+V31+Z31 | AE31: =G31+K31+O31+S31+W31+AA31 | AF31: =H31+L31+P31+T31+X31+AB31 | AG31: =IF(AF31>0, AD31/AF31, 0)
A32: 6 | B32: NM-09 | C32: COMPACTADOR NEUMÁTICO HAMM 208 | D32: NOLVIN DE JESUS PEREZ GOMEZ | E32: Compactación Neumática / Acabado | F32: 0 | G32: 162 | H32: =G32*$E$4 | I32: =IF(H32>0, F32/H32, 0) | J32: 0 | K32: 238 | L32: =K32*$E$4 | M32: =IF(L32>0, J32/L32, 0) | N32: 0 | O32: 168 | P32: =O32*$E$4 | Q32: =IF(P32>0, N32/P32, 0) | R32: 0 | S32: 196 | T32: =S32*$E$4 | U32: =IF(T32>0, R32/T32, 0) | V32: 0 | W32: 196 | X32: =W32*$E$4 | Y32: =IF(X32>0, V32/X32, 0) | Z32: 0 | AA32: 0 | AB32: =AA32*$E$4 | AC32: =IF(AB32>0, Z32/AB32, 0) | AD32: =F32+J32+N32+R32+V32+Z32 | AE32: =G32+K32+O32+S32+W32+AA32 | AF32: =H32+L32+P32+T32+X32+AB32 | AG32: =IF(AF32>0, AD32/AF32, 0)
A33: 7 | B33: BR-01 | C33: BARREDORA INDUSTRIAL BROCE BROOM-350 | D33: EDGAR ROSALES MARTINEZ | E33: Limpieza y Barrido Previo | F33: 0 | G33: 162 | H33: =G33*$E$4 | I33: =IF(H33>0, F33/H33, 0) | J33: 30 | K33: 238 | L33: =K33*$E$4 | M33: =IF(L33>0, J33/L33, 0) | N33: 28 | O33: 168 | P33: =O33*$E$4 | Q33: =IF(P33>0, N33/P33, 0) | R33: 0 | S33: 196 | T33: =S33*$E$4 | U33: =IF(T33>0, R33/T33, 0) | V33: 30 | W33: 196 | X33: =W33*$E$4 | Y33: =IF(X33>0, V33/X33, 0) | Z33: 0 | AA33: 0 | AB33: =AA33*$E$4 | AC33: =IF(AB33>0, Z33/AB33, 0) | AD33: =F33+J33+N33+R33+V33+Z33 | AE33: =G33+K33+O33+S33+W33+AA33 | AF33: =H33+L33+P33+T33+X33+AB33 | AG33: =IF(AF33>0, AD33/AF33, 0)
A34: 8 | B34: RT-05 | C34: RETROEXCAVADORA JOHN DEERE 310SK | D34: ADOLFO NAVA LOPEZ | E34: Carga Fresado y Derrumbes | F34: 40 | G34: 238 | H34: =G34*$E$4 | I34: =IF(G34>0, F34/G34, 0) | J34: 40 | K34: 210 | L34: =K34*$E$4 | M34: =IF(K34>0, J34/K34, 0) | N34: 60 | O34: 280 | P34: =O34*$E$4 | Q34: =IF(O34>0, N34/O34, 0) | R34: 30 | S34: 266 | T34: =S34*$E$4 | U34: =IF(S34>0, R34/S34, 0) | V34: 150 | W34: 0 | X34: =W34*$E$4 | Y34: =IF(W34>0, V34/W34, 0) | Z34: 0 | AA34: 0 | AB34: =AA34*$E$4 | AC34: =IF(AA34>0, Z34/AA34, 0) | AD34: =F34+J34+N34+R34+V34+Z34 | AE34: =G34+K34+O34+S34+W34+AA34 | AF34: =H34+L34+P34+T34+X34+AB34 | AG34: =IF(AE34>0, AD34/AE34, 0)
A35: 9 | B35: PT-01 | C35: PETROLIZADORA INTERNATIONAL / FORD F800 | D35: ELTHON EDUARDO MARTINEZ GOMORA | E35: Riego de Liga / Emulsión | F35: 50 | G35: 162 | H35: =G35*$E$4 | I35: =IF(H35>0, F35/H35, 0) | J35: 50 | K35: 238 | L35: =K35*$E$4 | M35: =IF(L35>0, J35/L35, 0) | N35: 0 | O35: 168 | P35: =O35*$E$4 | Q35: =IF(P35>0, N35/P35, 0) | R35: 50 | S35: 196 | T35: =S35*$E$4 | U35: =IF(T35>0, R35/T35, 0) | V35: 0 | W35: 196 | X35: =W35*$E$4 | Y35: =IF(X35>0, V35/X35, 0) | Z35: 0 | AA35: 0 | AB35: =AA35*$E$4 | AC35: =IF(AB35>0, Z35/AB35, 0) | AD35: =F35+J35+N35+R35+V35+Z35 | AE35: =G35+K35+O35+S35+W35+AA35 | AF35: =H35+L35+P35+T35+X35+AB35 | AG35: =IF(AF35>0, AD35/AF35, 0)
A36: 10 | B36: CPR-01 | C36: COMPRESOR DE AIRE INGERSOLL RAND IR185 | D36: CUADRILLA DE LIMPIEZA | E36: Sopleteado de Juntas | F36: 0 | G36: 0 | H36: =G36*$E$4 | I36: 0 | J36: 0 | K36: 0 | L36: =K36*$E$4 | M36: 0 | N36: 0 | O36: 0 | P36: =O36*$E$4 | Q36: 0 | R36: 0 | S36: 0 | T36: =S36*$E$4 | U36: 0 | V36: 0 | W36: 0 | X36: =W36*$E$4 | Y36: 0 | Z36: 0 | AA36: 0 | AB36: =AA36*$E$4 | AC36: 0 | AD36: =F36+J36+N36+R36+V36+Z36 | AE36: =G36+K36+O36+S36+W36+AA36 | AF36: =H36+L36+P36+T36+X36+AB36 | AG36: 0
A37: 11 | B37: PP-01 | C37: CAMIÓN IMPACTO / PIPA DE AGUA FORD | D37: CUADRILLA DE AGUA | E37: Enfriamiento Rodillos / Riego | F37: 0 | G37: 0 | H37: =G37*$E$4 | I37: 0 | J37: 0 | K37: 0 | L37: =K37*$E$4 | M37: 0 | N37: 0 | O37: 0 | P37: =O37*$E$4 | Q37: 0 | R37: 0 | S37: 0 | T37: =S37*$E$4 | U37: 0 | V37: 0 | W37: 0 | X37: =W37*$E$4 | Y37: 0 | Z37: 0 | AA37: 0 | AB37: =AA37*$E$4 | AC37: 0 | AD37: =F37+J37+N37+R37+V37+Z37 | AE37: =G37+K37+O37+S37+W37+AA37 | AF37: =H37+L37+P37+T37+X37+AB37 | AG37: 0
