Workbook

Sheet Histórico y Rendimiento
A1: CONTROL SEMANAL DE RENDIMIENTO DE MAQUINARIA — ACUMULADO HISTÓRICO
A2: OBRA: LERMA - TRES MARÍAS | CONSOLIDADO OPERATIVO (SEMANAS 24 A 37)
A8: No. | B8: Económico | C8: Descripción de Maquinaria | D8: Operador Asignado | E8: Concepto de Trabajo | F8: Diésel Acumulado (L) | G8: Fresado m³ Total | H8: Carpeta Ton Total | I8: Rend Prom (L/Ton) | J8: Rend Prom (L/m³) | K8: Horas Est Totales
A9: 1 | B9: PR-01 | C9: PERFILADORA RODATEC RX600-4-4008 / RX600E | D9: JAVIER PAREDES CORTE | E9: Fresado de Pavimento | F9: ='Semana 24'!I9+'Semana 25'!I9+'Semana 26'!I9+'Semana 27'!I9+'Semana 28'!I9+'Semana 29'!I9+'Semana 30'!I9+'Semana 31'!I9+'Semana 32'!I9+'Semana 37'!I9 | G9: ='Semana 24'!G9+'Semana 25'!G9+'Semana 26'!G9+'Semana 27'!G9+'Semana 28'!G9+'Semana 29'!G9+'Semana 30'!G9+'Semana 31'!G9+'Semana 32'!G9+'Semana 37'!G9 | H9: ='Semana 24'!H9+'Semana 25'!H9+'Semana 26'!H9+'Semana 27'!H9+'Semana 28'!H9+'Semana 29'!H9+'Semana 30'!H9+'Semana 31'!H9+'Semana 32'!H9+'Semana 37'!H9 | I9: =IF(H9>0, F9/H9, 0) | J9: =IF(G9>0, F9/G9, 0) | K9: =IF(67.2>0, F9/67.2, 0)
A10: 2 | B10: VG-03 | C10: PAVIMENTADORA VÖGELE SJ 1800-3 / 1800-3i | D10: ERWIN CUTEÑO HERNANDEZ | E10: Tendido de Mezcla Asfáltica | F10: ='Semana 24'!I10+'Semana 25'!I10+'Semana 26'!I10+'Semana 27'!I10+'Semana 28'!I10+'Semana 29'!I10+'Semana 30'!I10+'Semana 31'!I10+'Semana 32'!I10+'Semana 37'!I10 | G10: ='Semana 24'!G10+'Semana 25'!G10+'Semana 26'!G10+'Semana 27'!G10+'Semana 28'!G10+'Semana 29'!G10+'Semana 30'!G10+'Semana 31'!G10+'Semana 32'!G10+'Semana 37'!G10 | H10: ='Semana 24'!H10+'Semana 25'!H10+'Semana 26'!H10+'Semana 27'!H10+'Semana 28'!H10+'Semana 29'!H10+'Semana 30'!H10+'Semana 31'!H10+'Semana 32'!H10+'Semana 37'!H10 | I10: =IF(H10>0, F10/H10, 0) | J10: =IF(G10>0, F10/G10, 0) | K10: =IF(16.24>0, F10/16.24, 0)
A11: 3 | B11: TD-01 | C11: COMPACTADOR TÁNDEM CATERPILLAR CB54 | D11: JOEL ALBERTO RIVERA RIVAS | E11: Compactación Tándem Primaria | F11: ='Semana 24'!I11+'Semana 25'!I11+'Semana 26'!I11+'Semana 27'!I11+'Semana 28'!I11+'Semana 29'!I11+'Semana 30'!I11+'Semana 31'!I11+'Semana 32'!I11+'Semana 37'!I11 | G11: ='Semana 24'!G11+'Semana 25'!G11+'Semana 26'!G11+'Semana 27'!G11+'Semana 28'!G11+'Semana 29'!G11+'Semana 30'!G11+'Semana 31'!G11+'Semana 32'!G11+'Semana 37'!G11 | H11: ='Semana 24'!H11+'Semana 25'!H11+'Semana 26'!H11+'Semana 27'!H11+'Semana 28'!H11+'Semana 29'!H11+'Semana 30'!H11+'Semana 31'!H11+'Semana 32'!H11+'Semana 37'!H11 | I11: =IF(H11>0, F11/H11, 0) | J11: =IF(G11>0, F11/G11, 0) | K11: =IF(14.3>0, F11/14.3, 0)
A12: 4 | B12: VC-01 | C12: VIBROCOMPACTADOR CATERPILLAR CB66B | D12: ALEXIS RENDON DOMINGUEZ | E12: Compactación Tándem Pesada / Acabado | F12: ='Semana 24'!I12+'Semana 25'!I12+'Semana 26'!I12+'Semana 27'!I12+'Semana 28'!I12+'Semana 29'!I12+'Semana 30'!I12+'Semana 31'!I12+'Semana 32'!I12+'Semana 37'!I12 | G12: ='Semana 24'!G12+'Semana 25'!G12+'Semana 26'!G12+'Semana 27'!G12+'Semana 28'!G12+'Semana 29'!G12+'Semana 30'!G12+'Semana 31'!G12+'Semana 32'!G12+'Semana 37'!G12 | H12: ='Semana 24'!H12+'Semana 25'!H12+'Semana 26'!H12+'Semana 27'!H12+'Semana 28'!H12+'Semana 29'!H12+'Semana 30'!H12+'Semana 31'!H12+'Semana 32'!H12+'Semana 37'!H12 | I12: =IF(H12>0, F12/H12, 0) | J12: =IF(G12>0, F12/G12, 0) | K12: =IF(14.3>0, F12/14.3, 0)
A13: 5 | B13: NM-02 | C13: COMPACTADOR NEUMÁTICO VOLVO PT-240R | D13: JOSE CARLOS ROMERO TELLEZ | E13: Compactación Neumática / Sellado | F13: ='Semana 24'!I13+'Semana 25'!I13+'Semana 26'!I13+'Semana 27'!I13+'Semana 28'!I13+'Semana 29'!I13+'Semana 30'!I13+'Semana 31'!I13+'Semana 32'!I13+'Semana 37'!I13 | G13: ='Semana 24'!G13+'Semana 25'!G13+'Semana 26'!G13+'Semana 27'!G13+'Semana 28'!G13+'Semana 29'!G13+'Semana 30'!G13+'Semana 31'!G13+'Semana 32'!G13+'Semana 37'!G13 | H13: ='Semana 24'!H13+'Semana 25'!H13+'Semana 26'!H13+'Semana 27'!H13+'Semana 28'!H13+'Semana 29'!H13+'Semana 30'!H13+'Semana 31'!H13+'Semana 32'!H13+'Semana 37'!H13 | I13: =IF(H13>0, F13/H13, 0) | J13: =IF(G13>0, F13/G13, 0) | K13: =IF(11.44>0, F13/11.44, 0)
A14: 6 | B14: NM-08 | C14: COMPACTADOR NEUMÁTICO PF-300B | D14: NOLVIN DE JESUS PEREZ GOMEZ | E14: Compactación Neumática / Acabado | F14: ='Semana 24'!I14+'Semana 25'!I14+'Semana 26'!I14+'Semana 27'!I14+'Semana 28'!I14+'Semana 29'!I14+'Semana 30'!I14+'Semana 31'!I14+'Semana 32'!I14+'Semana 37'!I14 | G14: ='Semana 24'!G14+'Semana 25'!G14+'Semana 26'!G14+'Semana 27'!G14+'Semana 28'!G14+'Semana 29'!G14+'Semana 30'!G14+'Semana 31'!G14+'Semana 32'!G14+'Semana 37'!G14 | H14: ='Semana 24'!H14+'Semana 25'!H14+'Semana 26'!H14+'Semana 27'!H14+'Semana 28'!H14+'Semana 29'!H14+'Semana 30'!H14+'Semana 31'!H14+'Semana 32'!H14+'Semana 37'!H14 | I14: =IF(H14>0, F14/H14, 0) | J14: =IF(G14>0, F14/G14, 0) | K14: =IF(10.96>0, F14/10.96, 0)
A15: 7 | B15: BR-02 | C15: BARREDORA INDUSTRIAL LAYMOR SM400 | D15: EDGAR ROSALES MARTINEZ | E15: Limpieza y Barrido Previo | F15: ='Semana 24'!I15+'Semana 25'!I15+'Semana 26'!I15+'Semana 27'!I15+'Semana 28'!I15+'Semana 29'!I15+'Semana 30'!I15+'Semana 31'!I15+'Semana 32'!I15+'Semana 37'!I15 | G15: ='Semana 24'!G15+'Semana 25'!G15+'Semana 26'!G15+'Semana 27'!G15+'Semana 28'!G15+'Semana 29'!G15+'Semana 30'!G15+'Semana 31'!G15+'Semana 32'!G15+'Semana 37'!G15 | H15: ='Semana 24'!H15+'Semana 25'!H15+'Semana 26'!H15+'Semana 27'!H15+'Semana 28'!H15+'Semana 29'!H15+'Semana 30'!H15+'Semana 31'!H15+'Semana 32'!H15+'Semana 37'!H15 | I15: =IF(H15>0, F15/H15, 0) | J15: =IF(G15>0, F15/G15, 0) | K15: =IF(8.94>0, F15/8.94, 0)
A16: 8 | B16: BR-05 | C16: BARREDORA BROCE BROOM KR350 / RJ350 | D16: CUADRILLA DE BARRIDO | E16: Barrido de Calzada y Apoyo | F16: ='Semana 24'!I16+'Semana 25'!I16+'Semana 26'!I16+'Semana 27'!I16+'Semana 28'!I16+'Semana 29'!I16+'Semana 30'!I16+'Semana 31'!I16+'Semana 32'!I16+'Semana 37'!I16 | G16: ='Semana 24'!G16+'Semana 25'!G16+'Semana 26'!G16+'Semana 27'!G16+'Semana 28'!G16+'Semana 29'!G16+'Semana 30'!G16+'Semana 31'!G16+'Semana 32'!G16+'Semana 37'!G16 | H16: ='Semana 24'!H16+'Semana 25'!H16+'Semana 26'!H16+'Semana 27'!H16+'Semana 28'!H16+'Semana 29'!H16+'Semana 30'!H16+'Semana 31'!H16+'Semana 32'!H16+'Semana 37'!H16 | I16: =IF(H16>0, F16/H16, 0) | J16: =IF(G16>0, F16/G16, 0) | K16: =IF(8.94>0, F16/8.94, 0)
A17: 9 | B17: RT-02 | C17: RETROEXCAVADORA JOHN DEERE 310K / CASE 580N | D17: ADOLFO NAVA LOPEZ | E17: Carga Fresado y Derrumbes | F17: ='Semana 24'!I17+'Semana 25'!I17+'Semana 26'!I17+'Semana 27'!I17+'Semana 28'!I17+'Semana 29'!I17+'Semana 30'!I17+'Semana 31'!I17+'Semana 32'!I17+'Semana 37'!I17 | G17: ='Semana 24'!G17+'Semana 25'!G17+'Semana 26'!G17+'Semana 27'!G17+'Semana 28'!G17+'Semana 29'!G17+'Semana 30'!G17+'Semana 31'!G17+'Semana 32'!G17+'Semana 37'!G17 | H17: ='Semana 24'!H17+'Semana 25'!H17+'Semana 26'!H17+'Semana 27'!H17+'Semana 28'!H17+'Semana 29'!H17+'Semana 30'!H17+'Semana 31'!H17+'Semana 32'!H17+'Semana 37'!H17 | I17: =IF(H17>0, F17/H17, 0) | J17: =IF(G17>0, F17/G17, 0) | K17: =IF(7.44>0, F17/7.44, 0)
A18: 10 | B18: PT-01 | C18: PETROLIZADORA FORD F800 (IMPACTO 04) | D18: ELTHON EDUARDO MARTINEZ GOMORA | E18: Riego de Liga / Emulsión Asfáltica | F18: ='Semana 24'!I18+'Semana 25'!I18+'Semana 26'!I18+'Semana 27'!I18+'Semana 28'!I18+'Semana 29'!I18+'Semana 30'!I18+'Semana 31'!I18+'Semana 32'!I18+'Semana 37'!I18 | G18: ='Semana 24'!G18+'Semana 25'!G18+'Semana 26'!G18+'Semana 27'!G18+'Semana 28'!G18+'Semana 29'!G18+'Semana 30'!G18+'Semana 31'!G18+'Semana 32'!G18+'Semana 37'!G18 | H18: ='Semana 24'!H18+'Semana 25'!H18+'Semana 26'!H18+'Semana 27'!H18+'Semana 28'!H18+'Semana 29'!H18+'Semana 30'!H18+'Semana 31'!H18+'Semana 32'!H18+'Semana 37'!H18 | I18: =IF(H18>0, F18/H18, 0) | J18: =IF(G18>0, F18/G18, 0) | K18: =IF(12.76>0, F18/12.76, 0)
A19: 11 | B19: CPR-01 | C19: COMPRESOR SULLIVAN PALATEK D2010 | D19: CUADRILLA DE SOPLETEADO | E19: Sopleteado de Superficie y Juntas | F19: ='Semana 24'!I19+'Semana 25'!I19+'Semana 26'!I19+'Semana 27'!I19+'Semana 28'!I19+'Semana 29'!I19+'Semana 30'!I19+'Semana 31'!I19+'Semana 32'!I19+'Semana 37'!I19 | G19: ='Semana 24'!G19+'Semana 25'!G19+'Semana 26'!G19+'Semana 27'!G19+'Semana 28'!G19+'Semana 29'!G19+'Semana 30'!G19+'Semana 31'!G19+'Semana 32'!G19+'Semana 37'!G19 | H19: ='Semana 24'!H19+'Semana 25'!H19+'Semana 26'!H19+'Semana 27'!H19+'Semana 28'!H19+'Semana 29'!H19+'Semana 30'!H19+'Semana 31'!H19+'Semana 32'!H19+'Semana 37'!H19 | I19: =IF(H19>0, F19/H19, 0) | J19: =IF(G19>0, F19/G19, 0) | K19: =IF(9.97>0, F19/9.97, 0)
A20: 12 | B20: PP-01 | C20: PIPA DE AGUA (IMPACTO 01) FORD | D20: ALAN ALEXIS GUTIERREZ FLORES | E20: Enfriamiento Rodillos / Riego | F20: ='Semana 24'!I20+'Semana 25'!I20+'Semana 26'!I20+'Semana 27'!I20+'Semana 28'!I20+'Semana 29'!I20+'Semana 30'!I20+'Semana 31'!I20+'Semana 32'!I20+'Semana 37'!I20 | G20: ='Semana 24'!G20+'Semana 25'!G20+'Semana 26'!G20+'Semana 27'!G20+'Semana 28'!G20+'Semana 29'!G20+'Semana 30'!G20+'Semana 31'!G20+'Semana 32'!G20+'Semana 37'!G20 | H20: ='Semana 24'!H20+'Semana 25'!H20+'Semana 26'!H20+'Semana 27'!H20+'Semana 28'!H20+'Semana 29'!H20+'Semana 30'!H20+'Semana 31'!H20+'Semana 32'!H20+'Semana 37'!H20 | I20: =IF(H20>0, F20/H20, 0) | J20: =IF(G20>0, F20/G20, 0) | K20: =IF(3.03>0, F20/3.03, 0)
A21: 13 | B21: CI-02 | C21: CAMIÓN DE IMPACTO FORD 4300 (ATENUADOR TMA) | D21: CUADRILLA DE SEGURIDAD VIAL | E21: Protección Vial / Atenuador Móvil | F21: ='Semana 24'!I21+'Semana 25'!I21+'Semana 26'!I21+'Semana 27'!I21+'Semana 28'!I21+'Semana 29'!I21+'Semana 30'!I21+'Semana 31'!I21+'Semana 32'!I21+'Semana 37'!I21 | G21: ='Semana 24'!G21+'Semana 25'!G21+'Semana 26'!G21+'Semana 27'!G21+'Semana 28'!G21+'Semana 29'!G21+'Semana 30'!G21+'Semana 31'!G21+'Semana 32'!G21+'Semana 37'!G21 | H21: ='Semana 24'!H21+'Semana 25'!H21+'Semana 26'!H21+'Semana 27'!H21+'Semana 28'!H21+'Semana 29'!H21+'Semana 30'!H21+'Semana 31'!H21+'Semana 32'!H21+'Semana 37'!H21 | I21: =IF(H21>0, F21/H21, 0) | J21: =IF(G21>0, F21/G21, 0) | K21: =IF(8.5>0, F21/8.5, 0)
A22: 14 | B22: TL-01 | C22: TORRE DE LUCES MAXILIGHT / APOYO NOCTURNO | D22: CUADRILLA NOCTURNA | E22: Iluminación Nocturna / Cuadrilla | F22: ='Semana 24'!I22+'Semana 25'!I22+'Semana 26'!I22+'Semana 27'!I22+'Semana 28'!I22+'Semana 29'!I22+'Semana 30'!I22+'Semana 31'!I22+'Semana 32'!I22+'Semana 37'!I22 | G22: ='Semana 24'!G22+'Semana 25'!G22+'Semana 26'!G22+'Semana 27'!G22+'Semana 28'!G22+'Semana 29'!G22+'Semana 30'!G22+'Semana 31'!G22+'Semana 32'!G22+'Semana 37'!G22 | H22: ='Semana 24'!H22+'Semana 25'!H22+'Semana 26'!H22+'Semana 27'!H22+'Semana 28'!H22+'Semana 29'!H22+'Semana 30'!H22+'Semana 31'!H22+'Semana 32'!H22+'Semana 37'!H22 | I22: =IF(H22>0, F22/H22, 0) | J22: =IF(G22>0, F22/G22, 0) | K22: =IF(2.41>0, F22/2.41, 0)
A23: TOTAL ACUMULADO HISTÓRICO (OBRA LERMA - TRES MARÍAS) | F23: =SUM(F9:F22) | G23: =SUM(G9:G22) | H23: =SUM(H9:H22) | I23: =IF(H23>0, F23/H23, 0) | J23: =IF(G23>0, F23/G23, 0) | K23: =SUM(K9:K22)

Sheet Semana 24
A1: CONTROL SEMANAL DE RENDIMIENTO DE MAQUINARIA (SEMANA 24)
A2: OBRA: LERMA - TRES MARÍAS | PERIODO: 08/Jun/2026 - 13/Jun/2026
D4: PESO VOLUMÉTRICO ASFALTO: | E4: 1.742
B5: VIAJES FRESADO: | C5: 0 | D5: VOLUMEN FRESADO (m³): | E5: 0
B6: VIAJES CARPETA: | C6: 0 | D6: VOLUMEN CARPETA (m³): | E6: 0 | F6: TONELADAS CARPETA: | G6: =E6*$E$4
A8: No. | B8: Económico | C8: Descripción de Maquinaria | D8: Operador Asignado | E8: Concepto de Trabajo | F8: Unidad Medida | G8: Volumen m³ | H8: Volumen Ton | I8: Diésel Surtido (L) | J8: Rendimiento Real (L/Ton) | K8: Rendimiento Real (L/m³) | L8: Rendimiento Base (L/h) | M8: Horas Estimadas (h) | N8: Estatus Operativo
A9: 1 | B9: PR-01 | C9: PERFILADORA RODATEC RX600-4-4008 / RX600E | D9: JAVIER PAREDES CORTE | E9: Fresado de Pavimento | F9: m³ | G9: =E5 | H9: 0 | I9: =AD28 | J9: 0 | K9: =IF(G9>0, I9/G9, 0) | L9: 67.2 | M9: =IF(L9>0, I9/L9, 0) | N9: =IF(I9=0, "SIN CONSUMO (Inactiva)", IF(AND(G9>0, K9<=1.3*3.2), "DENTRO DE RENDIMIENTO BASE", IF(G9>0, "EXCEDE RENDIMIENTO BASE", "OPERACIÓN SIN VOLUMEN")))
A10: 2 | B10: VG-03 | C10: PAVIMENTADORA VÖGELE SJ 1800-3 / 1800-3i | D10: ERWIN CUTEÑO HERNANDEZ | E10: Tendido de Mezcla Asfáltica | F10: Ton | G10: 0 | H10: =G6 | I10: =AD29 | J10: =IF(H10>0, I10/H10, 0) | K10: =IF($E$6>0, I10/$E$6, 0) | L10: 16.24 | M10: =IF(L10>0, I10/L10, 0) | N10: =IF(I10=0, "SIN CONSUMO (Inactiva)", IF(AND(H10>0, J10<=1.2*0.35), "DENTRO DE RENDIMIENTO BASE", IF(H10>0, "EXCEDE RENDIMIENTO BASE", "OPERACIÓN SIN VOLUMEN")))
A11: 3 | B11: TD-01 | C11: COMPACTADOR TÁNDEM CATERPILLAR CB54 | D11: JOEL ALBERTO RIVERA RIVAS | E11: Compactación Tándem Primaria | F11: Ton | G11: 0 | H11: =G6 | I11: =AD30 | J11: =IF(H11>0, I11/H11, 0) | K11: =IF($E$6>0, I11/$E$6, 0) | L11: 14.3 | M11: =IF(L11>0, I11/L11, 0) | N11: =IF(I11=0, "SIN CONSUMO (Inactiva)", IF(AND(H11>0, J11<=1.2*0.3), "DENTRO DE RENDIMIENTO BASE", IF(H11>0, "EXCEDE RENDIMIENTO BASE", "OPERACIÓN SIN VOLUMEN")))
A12: 4 | B12: VC-01 | C12: VIBROCOMPACTADOR CATERPILLAR CB66B | D12: ALEXIS RENDON DOMINGUEZ | E12: Compactación Tándem Pesada / Acabado | F12: Ton | G12: 0 | H12: =G6 | I12: =AD31 | J12: =IF(H12>0, I12/H12, 0) | K12: =IF($E$6>0, I12/$E$6, 0) | L12: 14.3 | M12: =IF(L12>0, I12/L12, 0) | N12: =IF(I12=0, "SIN CONSUMO (Inactiva)", IF(AND(H12>0, J12<=1.2*0.3), "DENTRO DE RENDIMIENTO BASE", IF(H12>0, "EXCEDE RENDIMIENTO BASE", "OPERACIÓN SIN VOLUMEN")))
A13: 5 | B13: NM-02 | C13: COMPACTADOR NEUMÁTICO VOLVO PT-240R | D13: JOSE CARLOS ROMERO TELLEZ | E13: Compactación Neumática / Sellado | F13: Ton | G13: 0 | H13: =G6 | I13: =AD32 | J13: =IF(H13>0, I13/H13, 0) | K13: =IF($E$6>0, I13/$E$6, 0) | L13: 11.44 | M13: =IF(L13>0, I13/L13, 0) | N13: =IF(I13=0, "SIN CONSUMO (Inactiva)", IF(AND(H13>0, J13<=1.2*0.25), "DENTRO DE RENDIMIENTO BASE", IF(H13>0, "EXCEDE RENDIMIENTO BASE", "OPERACIÓN SIN VOLUMEN")))
A14: 6 | B14: NM-08 | C14: COMPACTADOR NEUMÁTICO PF-300B | D14: NOLVIN DE JESUS PEREZ GOMEZ | E14: Compactación Neumática / Acabado | F14: Ton | G14: 0 | H14: =G6 | I14: =AD33 | J14: =IF(H14>0, I14/H14, 0) | K14: =IF($E$6>0, I14/$E$6, 0) | L14: 10.96 | M14: =IF(L14>0, I14/L14, 0) | N14: =IF(I14=0, "SIN CONSUMO (Inactiva)", IF(AND(H14>0, J14<=1.2*0.24), "DENTRO DE RENDIMIENTO BASE", IF(H14>0, "EXCEDE RENDIMIENTO BASE", "OPERACIÓN SIN VOLUMEN")))
A15: 7 | B15: BR-02 | C15: BARREDORA INDUSTRIAL LAYMOR SM400 | D15: EDGAR ROSALES MARTINEZ | E15: Limpieza y Barrido Previo | F15: m² | G15: 0 | H15: =G6 | I15: =AD34 | J15: =IF(H15>0, I15/H15, 0) | K15: 0 | L15: 8.94 | M15: =IF(L15>0, I15/L15, 0) | N15: =IF(I15=0, "SIN CONSUMO (Inactiva)", IF(AND(H15>0, J15<=1.2*0.05), "DENTRO DE RENDIMIENTO BASE", IF(H15>0, "EXCEDE RENDIMIENTO BASE", "OPERACIÓN SIN VOLUMEN")))
A16: 8 | B16: BR-05 | C16: BARREDORA BROCE BROOM KR350 / RJ350 | D16: CUADRILLA DE BARRIDO | E16: Barrido de Calzada y Apoyo | F16: m² | G16: 0 | H16: =G6 | I16: =AD35 | J16: =IF(H16>0, I16/H16, 0) | K16: 0 | L16: 8.94 | M16: =IF(L16>0, I16/L16, 0) | N16: =IF(I16=0, "SIN CONSUMO (Inactiva)", IF(AND(H16>0, J16<=1.2*0.05), "DENTRO DE RENDIMIENTO BASE", IF(H16>0, "EXCEDE RENDIMIENTO BASE", "OPERACIÓN SIN VOLUMEN")))
A17: 9 | B17: RT-02 | C17: RETROEXCAVADORA JOHN DEERE 310K / CASE 580N | D17: ADOLFO NAVA LOPEZ | E17: Carga Fresado y Derrumbes | F17: m³ | G17: 0 | H17: =G6 | I17: =AD36 | J17: =IF(H17>0, I17/H17, 0) | K17: 0 | L17: 7.44 | M17: =IF(L17>0, I17/L17, 0) | N17: =IF(I17=0, "SIN CONSUMO (Inactiva)", IF(AND(H17>0, J17<=1.2*0.15), "DENTRO DE RENDIMIENTO BASE", IF(H17>0, "EXCEDE RENDIMIENTO BASE", "OPERACIÓN SIN VOLUMEN")))
A18: 10 | B18: PT-01 | C18: PETROLIZADORA FORD F800 (IMPACTO 04) | D18: ELTHON EDUARDO MARTINEZ GOMORA | E18: Riego de Liga / Emulsión Asfáltica | F18: L-Emul | G18: 0 | H18: =G6 | I18: =AD37 | J18: =IF(H18>0, I18/H18, 0) | K18: 0 | L18: 12.76 | M18: =IF(L18>0, I18/L18, 0) | N18: =IF(I18=0, "SIN CONSUMO (Inactiva)", IF(AND(H18>0, J18<=1.2*0.12), "DENTRO DE RENDIMIENTO BASE", IF(H18>0, "EXCEDE RENDIMIENTO BASE", "OPERACIÓN SIN VOLUMEN")))
A19: 11 | B19: CPR-01 | C19: COMPRESOR SULLIVAN PALATEK D2010 | D19: CUADRILLA DE SOPLETEADO | E19: Sopleteado de Superficie y Juntas | F19: Horas | G19: 0 | H19: =G6 | I19: =AD38 | J19: =IF(H19>0, I19/H19, 0) | K19: 0 | L19: 9.97 | M19: =IF(L19>0, I19/L19, 0) | N19: =IF(I19=0, "SIN CONSUMO (Inactiva)", IF(AND(H19>0, J19<=1.2*0.08), "DENTRO DE RENDIMIENTO BASE", IF(H19>0, "EXCEDE RENDIMIENTO BASE", "OPERACIÓN SIN VOLUMEN")))
A20: 12 | B20: PP-01 | C20: PIPA DE AGUA (IMPACTO 01) FORD | D20: ALAN ALEXIS GUTIERREZ FLORES | E20: Enfriamiento Rodillos / Riego | F20: m³-Agua | G20: 0 | H20: =G6 | I20: =AD39 | J20: =IF(H20>0, I20/H20, 0) | K20: 0 | L20: 3.03 | M20: =IF(L20>0, I20/L20, 0) | N20: =IF(I20=0, "SIN CONSUMO (Inactiva)", IF(AND(H20>0, J20<=1.2*0.06), "DENTRO DE RENDIMIENTO BASE", IF(H20>0, "EXCEDE RENDIMIENTO BASE", "OPERACIÓN SIN VOLUMEN")))
A21: 13 | B21: CI-02 | C21: CAMIÓN DE IMPACTO FORD 4300 (ATENUADOR TMA) | D21: CUADRILLA DE SEGURIDAD VIAL | E21: Protección Vial / Atenuador Móvil | F21: Horas | G21: 0 | H21: =G6 | I21: =AD40 | J21: =IF(H21>0, I21/H21, 0) | K21: 0 | L21: 8.5 | M21: =IF(L21>0, I21/L21, 0) | N21: =IF(I21=0, "SIN CONSUMO (Inactiva)", IF(AND(H21>0, J21<=1.2*0.1), "DENTRO DE RENDIMIENTO BASE", IF(H21>0, "EXCEDE RENDIMIENTO BASE", "OPERACIÓN SIN VOLUMEN")))
A22: 14 | B22: TL-01 | C22: TORRE DE LUCES MAXILIGHT / APOYO NOCTURNO | D22: CUADRILLA NOCTURNA | E22: Iluminación Nocturna / Cuadrilla | F22: Horas | G22: 0 | H22: =G6 | I22: =AD41 | J22: =IF(H22>0, I22/H22, 0) | K22: 0 | L22: 2.41 | M22: =IF(L22>0, I22/L22, 0) | N22: =IF(I22=0, "SIN CONSUMO (Inactiva)", IF(AND(H22>0, J22<=1.2*0.04), "DENTRO DE RENDIMIENTO BASE", IF(H22>0, "EXCEDE RENDIMIENTO BASE", "OPERACIÓN SIN VOLUMEN")))
A23: TOTAL SEMANAL (OBRA LERMA - TRES MARÍAS) | G23: =SUM(G9:G22) | H23: =SUM(H9:H22) | I23: =SUM(I9:I22) | J23: =IF(H23>0, I23/H23, 0) | K23: =IF(G23>0, I23/G23, 0) | M23: =SUM(M9:M22) | N23: CONSOLIDADO SEMANAL
A25: DESGLOSE DIARIO DE COMBUSTIBLE, VOLUMEN, TONELAJE Y RENDIMIENTO — SEMANA 24
A26: DATOS DEL EQUIPO | F26: LUNES | J26: MARTES | N26: MIÉRCOLES | R26: JUEVES | V26: VIERNES | Z26: SÁBADO | AD26: TOTAL SEMANAL
A27: No. | B27: Económico | C27: Descripción de Maquinaria | D27: Operador Asignado | E27: Concepto de Trabajo | F27: Litros | G27: Vol m³ | H27: Horas Est | I27: Rend L/m³ | J27: Litros | K27: Vol m³ | L27: Horas Est | M27: Rend L/m³ | N27: Litros | O27: Vol m³ | P27: Horas Est | Q27: Rend L/m³ | R27: Litros | S27: Vol m³ | T27: Horas Est | U27: Rend L/m³ | V27: Litros | W27: Vol m³ | X27: Horas Est | Y27: Rend L/m³ | Z27: Litros | AA27: Vol m³ | AB27: Horas Est | AC27: Rend L/m³ | AD27: Diésel Surtido (L) | AE27: Vol m³ Total | AF27: Horas Est Total | AG27: Rend Prom (L/m³)
A28: 1 | B28: PR-01 | C28: PERFILADORA RODATEC RX600-4-4008 / RX600E | D28: JAVIER PAREDES CORTE | E28: Fresado de Pavimento | F28: 0 | G28: 0 | H28: =IF(L9>0, F28/L9, 0) | I28: =IF(G28>0, F28/G28, 0) | J28: 0 | K28: 0 | L28: =IF(L9>0, J28/L9, 0) | M28: =IF(K28>0, J28/K28, 0) | N28: 0 | O28: 0 | P28: =IF(L9>0, N28/L9, 0) | Q28: =IF(O28>0, N28/O28, 0) | R28: 0 | S28: 0 | T28: =IF(L9>0, R28/L9, 0) | U28: =IF(S28>0, R28/S28, 0) | V28: 0 | W28: 0 | X28: =IF(L9>0, V28/L9, 0) | Y28: =IF(W28>0, V28/W28, 0) | Z28: 0 | AA28: 0 | AB28: =IF(L9>0, Z28/L9, 0) | AC28: =IF(AA28>0, Z28/AA28, 0) | AD28: =F28+J28+N28+R28+V28+Z28 | AE28: =G28+K28+O28+S28+W28+AA28 | AF28: =H28+L28+P28+T28+X28+AB28 | AG28: =IF(AE28>0, AD28/AE28, 0)
A29: 2 | B29: VG-03 | C29: PAVIMENTADORA VÖGELE SJ 1800-3 / 1800-3i | D29: ERWIN CUTEÑO HERNANDEZ | E29: Tendido de Mezcla Asfáltica | F29: 97 | G29: 0 | H29: =IF(L10>0, F29/L10, 0) | I29: =IF(G29>0, F29/G29, 0) | J29: 0 | K29: 0 | L29: =IF(L10>0, J29/L10, 0) | M29: =IF(K29>0, J29/K29, 0) | N29: 0 | O29: 0 | P29: =IF(L10>0, N29/L10, 0) | Q29: =IF(O29>0, N29/O29, 0) | R29: 185 | S29: 0 | T29: =IF(L10>0, R29/L10, 0) | U29: =IF(S29>0, R29/S29, 0) | V29: 0 | W29: 0 | X29: =IF(L10>0, V29/L10, 0) | Y29: =IF(W29>0, V29/W29, 0) | Z29: 0 | AA29: 0 | AB29: =IF(L10>0, Z29/L10, 0) | AC29: =IF(AA29>0, Z29/AA29, 0) | AD29: =F29+J29+N29+R29+V29+Z29 | AE29: =G29+K29+O29+S29+W29+AA29 | AF29: =H29+L29+P29+T29+X29+AB29 | AG29: =IF(AE29>0, AD29/AE29, 0)
A30: 3 | B30: TD-01 | C30: COMPACTADOR TÁNDEM CATERPILLAR CB54 | D30: JOEL ALBERTO RIVERA RIVAS | E30: Compactación Tándem Primaria | F30: 0 | G30: 0 | H30: =IF(L11>0, F30/L11, 0) | I30: =IF(G30>0, F30/G30, 0) | J30: 0 | K30: 0 | L30: =IF(L11>0, J30/L11, 0) | M30: =IF(K30>0, J30/K30, 0) | N30: 0 | O30: 0 | P30: =IF(L11>0, N30/L11, 0) | Q30: =IF(O30>0, N30/O30, 0) | R30: 0 | S30: 0 | T30: =IF(L11>0, R30/L11, 0) | U30: =IF(S30>0, R30/S30, 0) | V30: 0 | W30: 0 | X30: =IF(L11>0, V30/L11, 0) | Y30: =IF(W30>0, V30/W30, 0) | Z30: 0 | AA30: 0 | AB30: =IF(L11>0, Z30/L11, 0) | AC30: =IF(AA30>0, Z30/AA30, 0) | AD30: =F30+J30+N30+R30+V30+Z30 | AE30: =G30+K30+O30+S30+W30+AA30 | AF30: =H30+L30+P30+T30+X30+AB30 | AG30: =IF(AE30>0, AD30/AE30, 0)
A31: 4 | B31: VC-01 | C31: VIBROCOMPACTADOR CATERPILLAR CB66B | D31: ALEXIS RENDON DOMINGUEZ | E31: Compactación Tándem Pesada / Acabado | F31: 0 | G31: 0 | H31: =IF(L12>0, F31/L12, 0) | I31: =IF(G31>0, F31/G31, 0) | J31: 50 | K31: 0 | L31: =IF(L12>0, J31/L12, 0) | M31: =IF(K31>0, J31/K31, 0) | N31: 0 | O31: 0 | P31: =IF(L12>0, N31/L12, 0) | Q31: =IF(O31>0, N31/O31, 0) | R31: 90 | S31: 0 | T31: =IF(L12>0, R31/L12, 0) | U31: =IF(S31>0, R31/S31, 0) | V31: 0 | W31: 0 | X31: =IF(L12>0, V31/L12, 0) | Y31: =IF(W31>0, V31/W31, 0) | Z31: 0 | AA31: 0 | AB31: =IF(L12>0, Z31/L12, 0) | AC31: =IF(AA31>0, Z31/AA31, 0) | AD31: =F31+J31+N31+R31+V31+Z31 | AE31: =G31+K31+O31+S31+W31+AA31 | AF31: =H31+L31+P31+T31+X31+AB31 | AG31: =IF(AE31>0, AD31/AE31, 0)
A32: 5 | B32: NM-02 | C32: COMPACTADOR NEUMÁTICO VOLVO PT-240R | D32: JOSE CARLOS ROMERO TELLEZ | E32: Compactación Neumática / Sellado | F32: 0 | G32: 0 | H32: =IF(L13>0, F32/L13, 0) | I32: =IF(G32>0, F32/G32, 0) | J32: 0 | K32: 0 | L32: =IF(L13>0, J32/L13, 0) | M32: =IF(K32>0, J32/K32, 0) | N32: 0 | O32: 0 | P32: =IF(L13>0, N32/L13, 0) | Q32: =IF(O32>0, N32/O32, 0) | R32: 40 | S32: 0 | T32: =IF(L13>0, R32/L13, 0) | U32: =IF(S32>0, R32/S32, 0) | V32: 0 | W32: 0 | X32: =IF(L13>0, V32/L13, 0) | Y32: =IF(W32>0, V32/W32, 0) | Z32: 0 | AA32: 0 | AB32: =IF(L13>0, Z32/L13, 0) | AC32: =IF(AA32>0, Z32/AA32, 0) | AD32: =F32+J32+N32+R32+V32+Z32 | AE32: =G32+K32+O32+S32+W32+AA32 | AF32: =H32+L32+P32+T32+X32+AB32 | AG32: =IF(AE32>0, AD32/AE32, 0)
A33: 6 | B33: NM-08 | C33: COMPACTADOR NEUMÁTICO PF-300B | D33: NOLVIN DE JESUS PEREZ GOMEZ | E33: Compactación Neumática / Acabado | F33: 0 | G33: 0 | H33: =IF(L14>0, F33/L14, 0) | I33: =IF(G33>0, F33/G33, 0) | J33: 0 | K33: 0 | L33: =IF(L14>0, J33/L14, 0) | M33: =IF(K33>0, J33/K33, 0) | N33: 0 | O33: 0 | P33: =IF(L14>0, N33/L14, 0) | Q33: =IF(O33>0, N33/O33, 0) | R33: 0 | S33: 0 | T33: =IF(L14>0, R33/L14, 0) | U33: =IF(S33>0, R33/S33, 0) | V33: 0 | W33: 0 | X33: =IF(L14>0, V33/L14, 0) | Y33: =IF(W33>0, V33/W33, 0) | Z33: 0 | AA33: 0 | AB33: =IF(L14>0, Z33/L14, 0) | AC33: =IF(AA33>0, Z33/AA33, 0) | AD33: =F33+J33+N33+R33+V33+Z33 | AE33: =G33+K33+O33+S33+W33+AA33 | AF33: =H33+L33+P33+T33+X33+AB33 | AG33: =IF(AE33>0, AD33/AE33, 0)
A34: 7 | B34: BR-02 | C34: BARREDORA INDUSTRIAL LAYMOR SM400 | D34: EDGAR ROSALES MARTINEZ | E34: Limpieza y Barrido Previo | F34: 0 | G34: 0 | H34: =IF(L15>0, F34/L15, 0) | I34: =IF(G34>0, F34/G34, 0) | J34: 0 | K34: 0 | L34: =IF(L15>0, J34/L15, 0) | M34: =IF(K34>0, J34/K34, 0) | N34: 0 | O34: 0 | P34: =IF(L15>0, N34/L15, 0) | Q34: =IF(O34>0, N34/O34, 0) | R34: 0 | S34: 0 | T34: =IF(L15>0, R34/L15, 0) | U34: =IF(S34>0, R34/S34, 0) | V34: 0 | W34: 0 | X34: =IF(L15>0, V34/L15, 0) | Y34: =IF(W34>0, V34/W34, 0) | Z34: 0 | AA34: 0 | AB34: =IF(L15>0, Z34/L15, 0) | AC34: =IF(AA34>0, Z34/AA34, 0) | AD34: =F34+J34+N34+R34+V34+Z34 | AE34: =G34+K34+O34+S34+W34+AA34 | AF34: =H34+L34+P34+T34+X34+AB34 | AG34: =IF(AE34>0, AD34/AE34, 0)
A35: 8 | B35: BR-05 | C35: BARREDORA BROCE BROOM KR350 / RJ350 | D35: CUADRILLA DE BARRIDO | E35: Barrido de Calzada y Apoyo | F35: 0 | G35: 0 | H35: =IF(L16>0, F35/L16, 0) | I35: =IF(G35>0, F35/G35, 0) | J35: 0 | K35: 0 | L35: =IF(L16>0, J35/L16, 0) | M35: =IF(K35>0, J35/K35, 0) | N35: 0 | O35: 0 | P35: =IF(L16>0, N35/L16, 0) | Q35: =IF(O35>0, N35/O35, 0) | R35: 0 | S35: 0 | T35: =IF(L16>0, R35/L16, 0) | U35: =IF(S35>0, R35/S35, 0) | V35: 0 | W35: 0 | X35: =IF(L16>0, V35/L16, 0) | Y35: =IF(W35>0, V35/W35, 0) | Z35: 0 | AA35: 0 | AB35: =IF(L16>0, Z35/L16, 0) | AC35: =IF(AA35>0, Z35/AA35, 0) | AD35: =F35+J35+N35+R35+V35+Z35 | AE35: =G35+K35+O35+S35+W35+AA35 | AF35: =H35+L35+P35+T35+X35+AB35 | AG35: =IF(AE35>0, AD35/AE35, 0)
A36: 9 | B36: RT-02 | C36: RETROEXCAVADORA JOHN DEERE 310K / CASE 580N | D36: ADOLFO NAVA LOPEZ | E36: Carga Fresado y Derrumbes | F36: 0 | G36: 0 | H36: =IF(L17>0, F36/L17, 0) | I36: =IF(G36>0, F36/G36, 0) | J36: 70 | K36: 0 | L36: =IF(L17>0, J36/L17, 0) | M36: =IF(K36>0, J36/K36, 0) | N36: 0 | O36: 0 | P36: =IF(L17>0, N36/L17, 0) | Q36: =IF(O36>0, N36/O36, 0) | R36: 70 | S36: 0 | T36: =IF(L17>0, R36/L17, 0) | U36: =IF(S36>0, R36/S36, 0) | V36: 0 | W36: 0 | X36: =IF(L17>0, V36/L17, 0) | Y36: =IF(W36>0, V36/W36, 0) | Z36: 0 | AA36: 0 | AB36: =IF(L17>0, Z36/L17, 0) | AC36: =IF(AA36>0, Z36/AA36, 0) | AD36: =F36+J36+N36+R36+V36+Z36 | AE36: =G36+K36+O36+S36+W36+AA36 | AF36: =H36+L36+P36+T36+X36+AB36 | AG36: =IF(AE36>0, AD36/AE36, 0)
A37: 10 | B37: PT-01 | C37: PETROLIZADORA FORD F800 (IMPACTO 04) | D37: ELTHON EDUARDO MARTINEZ GOMORA | E37: Riego de Liga / Emulsión Asfáltica | F37: 0 | G37: 0 | H37: =IF(L18>0, F37/L18, 0) | I37: =IF(G37>0, F37/G37, 0) | J37: 60 | K37: 0 | L37: =IF(L18>0, J37/L18, 0) | M37: =IF(K37>0, J37/K37, 0) | N37: 0 | O37: 0 | P37: =IF(L18>0, N37/L18, 0) | Q37: =IF(O37>0, N37/O37, 0) | R37: 80 | S37: 0 | T37: =IF(L18>0, R37/L18, 0) | U37: =IF(S37>0, R37/S37, 0) | V37: 0 | W37: 0 | X37: =IF(L18>0, V37/L18, 0) | Y37: =IF(W37>0, V37/W37, 0) | Z37: 0 | AA37: 0 | AB37: =IF(L18>0, Z37/L18, 0) | AC37: =IF(AA37>0, Z37/AA37, 0) | AD37: =F37+J37+N37+R37+V37+Z37 | AE37: =G37+K37+O37+S37+W37+AA37 | AF37: =H37+L37+P37+T37+X37+AB37 | AG37: =IF(AE37>0, AD37/AE37, 0)
A38: 11 | B38: CPR-01 | C38: COMPRESOR SULLIVAN PALATEK D2010 | D38: CUADRILLA DE SOPLETEADO | E38: Sopleteado de Superficie y Juntas | F38: 0 | G38: 0 | H38: =IF(L19>0, F38/L19, 0) | I38: =IF(G38>0, F38/G38, 0) | J38: 0 | K38: 0 | L38: =IF(L19>0, J38/L19, 0) | M38: =IF(K38>0, J38/K38, 0) | N38: 0 | O38: 0 | P38: =IF(L19>0, N38/L19, 0) | Q38: =IF(O38>0, N38/O38, 0) | R38: 50 | S38: 0 | T38: =IF(L19>0, R38/L19, 0) | U38: =IF(S38>0, R38/S38, 0) | V38: 0 | W38: 0 | X38: =IF(L19>0, V38/L19, 0) | Y38: =IF(W38>0, V38/W38, 0) | Z38: 0 | AA38: 0 | AB38: =IF(L19>0, Z38/L19, 0) | AC38: =IF(AA38>0, Z38/AA38, 0) | AD38: =F38+J38+N38+R38+V38+Z38 | AE38: =G38+K38+O38+S38+W38+AA38 | AF38: =H38+L38+P38+T38+X38+AB38 | AG38: =IF(AE38>0, AD38/AE38, 0)
A39: 12 | B39: PP-01 | C39: PIPA DE AGUA (IMPACTO 01) FORD | D39: ALAN ALEXIS GUTIERREZ FLORES | E39: Enfriamiento Rodillos / Riego | F39: 0 | G39: 0 | H39: =IF(L20>0, F39/L20, 0) | I39: =IF(G39>0, F39/G39, 0) | J39: 0 | K39: 0 | L39: =IF(L20>0, J39/L20, 0) | M39: =IF(K39>0, J39/K39, 0) | N39: 0 | O39: 0 | P39: =IF(L20>0, N39/L20, 0) | Q39: =IF(O39>0, N39/O39, 0) | R39: 0 | S39: 0 | T39: =IF(L20>0, R39/L20, 0) | U39: =IF(S39>0, R39/S39, 0) | V39: 0 | W39: 0 | X39: =IF(L20>0, V39/L20, 0) | Y39: =IF(W39>0, V39/W39, 0) | Z39: 0 | AA39: 0 | AB39: =IF(L20>0, Z39/L20, 0) | AC39: =IF(AA39>0, Z39/AA39, 0) | AD39: =F39+J39+N39+R39+V39+Z39 | AE39: =G39+K39+O39+S39+W39+AA39 | AF39: =H39+L39+P39+T39+X39+AB39 | AG39: =IF(AE39>0, AD39/AE39, 0)
... A41: 14 | B41: TL-01 | C41: TORRE DE LUCES MAXILIGHT / APOYO NOCTURNO | D41: CUADRILLA NOCTURNA | E41: Iluminación Nocturna / Cuadrilla | F41: 0 | G41: 0 | H41: =IF(L22>0, F41/L22, 0) | I41: =IF(G41>0, F41/G41, 0) | J41: 0 | K41: 0 | L41: =IF(L22>0, J41/L22, 0) | M41: =IF(K41>0, J41/K41, 0) | N41: 0 | O41: 0 | P41: =IF(L22>0, N41/L22, 0) | Q41: =IF(O41>0, N41/O41, 0) | R41: 0 | S41: 0 | T41: =IF(L22>0, R41/L22, 0) | U41: =IF(S41>0, R41/S41, 0) | V41: 0 | W41: 0 | X41: =IF(L22>0, V41/L22, 0) | Y41: =IF(W41>0, V41/W41, 0) | Z41: 0 | AA41: 0 | AB41: =IF(L22>0, Z41/L22, 0) | AC41: =IF(AA41>0, Z41/AA41, 0) | AD41: =F41+J41+N41+R41+V41+Z41 | AE41: =G41+K41+O41+S41+W41+AA41 | AF41: =H41+L41+P41+T41+X41+AB41 | AG41: =IF(AE41>0, AD41/AE41, 0)
A42: TOTAL DIARIO CONSOLIDADO (OBRA LERMA - TRES MARÍAS) | F42: =SUM(F28:F41) | G42: =SUM(G28:G41) | H42: =SUM(H28:H41) | I42: =IF(G42>0, F42/G42, 0) | J42: =SUM(J28:J41) | K42: =SUM(K28:K41) | L42: =SUM(L28:L41) | M42: =IF(K42>0, J42/K42, 0) | N42: =SUM(N28:N41) | O42: =SUM(O28:O41) | P42: =SUM(P28:P41) | Q42: =IF(O42>0, N42/O42, 0) | R42: =SUM(R28:R41) | S42: =SUM(S28:S41) | T42: =SUM(T28:T41) | U42: =IF(S42>0, R42/S42, 0) | V42: =SUM(V28:V41) | W42: =SUM(W28:W41) | X42: =SUM(X28:X41) | Y42: =IF(W42>0, V42/W42, 0) | Z42: =SUM(Z28:Z41) | AA42: =SUM(AA28:AA41) | AB42: =SUM(AB28:AB41) | AC42: =IF(AA42>0, Z42/AA42, 0) | AD42: =SUM(AD28:AD41) | AE42: =SUM(AE28:AE41) | AF42: =SUM(AF28:AF41) | AG42: =IF(AE42>0, AD42/AE42, 0)

Sheet Semana 25
A1: CONTROL SEMANAL DE RENDIMIENTO DE MAQUINARIA (SEMANA 25)
A2: OBRA: LERMA - TRES MARÍAS | PERIODO: 15/Jun/2026 - 20/Jun/2026
D4: PESO VOLUMÉTRICO ASFALTO: | E4: 1.742
B5: VIAJES FRESADO: | C5: 0 | D5: VOLUMEN FRESADO (m³): | E5: 0
B6: VIAJES CARPETA: | C6: 0 | D6: VOLUMEN CARPETA (m³): | E6: 0 | F6: TONELADAS CARPETA: | G6: =E6*$E$4
A8: No. | B8: Económico | C8: Descripción de Maquinaria | D8: Operador Asignado | E8: Concepto de Trabajo | F8: Unidad Medida | G8: Volumen m³ | H8: Volumen Ton | I8: Diésel Surtido (L) | J8: Rendimiento Real (L/Ton) | K8: Rendimiento Real (L/m³) | L8: Rendimiento Base (L/h) | M8: Horas Estimadas (h) | N8: Estatus Operativo
A9: 1 | B9: PR-01 | C9: PERFILADORA RODATEC RX600-4-4008 / RX600E | D9: JAVIER PAREDES CORTE | E9: Fresado de Pavimento | F9: m³ | G9: =E5 | H9: 0 | I9: =AD28 | J9: 0 | K9: =IF(G9>0, I9/G9, 0) | L9: 67.2 | M9: =IF(L9>0, I9/L9, 0) | N9: =IF(I9=0, "SIN CONSUMO (Inactiva)", IF(AND(G9>0, K9<=1.3*3.2), "DENTRO DE RENDIMIENTO BASE", IF(G9>0, "EXCEDE RENDIMIENTO BASE", "OPERACIÓN SIN VOLUMEN")))
A10: 2 | B10: VG-03 | C10: PAVIMENTADORA VÖGELE SJ 1800-3 / 1800-3i | D10: ERWIN CUTEÑO HERNANDEZ | E10: Tendido de Mezcla Asfáltica | F10: Ton | G10: 0 | H10: =G6 | I10: =AD29 | J10: =IF(H10>0, I10/H10, 0) | K10: =IF($E$6>0, I10/$E$6, 0) | L10: 16.24 | M10: =IF(L10>0, I10/L10, 0) | N10: =IF(I10=0, "SIN CONSUMO (Inactiva)", IF(AND(H10>0, J10<=1.2*0.35), "DENTRO DE RENDIMIENTO BASE", IF(H10>0, "EXCEDE RENDIMIENTO BASE", "OPERACIÓN SIN VOLUMEN")))
A11: 3 | B11: TD-01 | C11: COMPACTADOR TÁNDEM CATERPILLAR CB54 | D11: JOEL ALBERTO RIVERA RIVAS | E11: Compactación Tándem Primaria | F11: Ton | G11: 0 | H11: =G6 | I11: =AD30 | J11: =IF(H11>0, I11/H11, 0) | K11: =IF($E$6>0, I11/$E$6, 0) | L11: 14.3 | M11: =IF(L11>0, I11/L11, 0) | N11: =IF(I11=0, "SIN CONSUMO (Inactiva)", IF(AND(H11>0, J11<=1.2*0.3), "DENTRO DE RENDIMIENTO BASE", IF(H11>0, "EXCEDE RENDIMIENTO BASE", "OPERACIÓN SIN VOLUMEN")))
A12: 4 | B12: VC-01 | C12: VIBROCOMPACTADOR CATERPILLAR CB66B | D12: ALEXIS RENDON DOMINGUEZ | E12: Compactación Tándem Pesada / Acabado | F12: Ton | G12: 0 | H12: =G6 | I12: =AD31 | J12: =IF(H12>0, I12/H12, 0) | K12: =IF($E$6>0, I12/$E$6, 0) | L12: 14.3 | M12: =IF(L12>0, I12/L12, 0) | N12: =IF(I12=0, "SIN CONSUMO (Inactiva)", IF(AND(H12>0, J12<=1.2*0.3), "DENTRO DE RENDIMIENTO BASE", IF(H12>0, "EXCEDE RENDIMIENTO BASE", "OPERACIÓN SIN VOLUMEN")))
A13: 5 | B13: NM-02 | C13: COMPACTADOR NEUMÁTICO VOLVO PT-240R | D13: JOSE CARLOS ROMERO TELLEZ | E13: Compactación Neumática / Sellado | F13: Ton | G13: 0 | H13: =G6 | I13: =AD32 | J13: =IF(H13>0, I13/H13, 0) | K13: =IF($E$6>0, I13/$E$6, 0) | L13: 11.44 | M13: =IF(L13>0, I13/L13, 0) | N13: =IF(I13=0, "SIN CONSUMO (Inactiva)", IF(AND(H13>0, J13<=1.2*0.25), "DENTRO DE RENDIMIENTO BASE", IF(H13>0, "EXCEDE RENDIMIENTO BASE", "OPERACIÓN SIN VOLUMEN")))
A14: 6 | B14: NM-08 | C14: COMPACTADOR NEUMÁTICO PF-300B | D14: NOLVIN DE JESUS PEREZ GOMEZ | E14: Compactación Neumática / Acabado | F14: Ton | G14: 0 | H14: =G6 | I14: =AD33 | J14: =IF(H14>0, I14/H14, 0) | K14: =IF($E$6>0, I14/$E$6, 0) | L14: 10.96 | M14: =IF(L14>0, I14/L14, 0) | N14: =IF(I14=0, "SIN CONSUMO (Inactiva)", IF(AND(H14>0, J14<=1.2*0.24), "DENTRO DE RENDIMIENTO BASE", IF(H14>0, "EXCEDE RENDIMIENTO BASE", "OPERACIÓN SIN VOLUMEN")))
A15: 7 | B15: BR-02 | C15: BARREDORA INDUSTRIAL LAYMOR SM400 | D15: EDGAR ROSALES MARTINEZ | E15: Limpieza y Barrido Previo | F15: m² | G15: 0 | H15: =G6 | I15: =AD34 | J15: =IF(H15>0, I15/H15, 0) | K15: 0 | L15: 8.94 | M15: =IF(L15>0, I15/L15, 0) | N15: =IF(I15=0, "SIN CONSUMO (Inactiva)", IF(AND(H15>0, J15<=1.2*0.05), "DENTRO DE RENDIMIENTO BASE", IF(H15>0, "EXCEDE RENDIMIENTO BASE", "OPERACIÓN SIN VOLUMEN")))
A16: 8 | B16: BR-05 | C16: BARREDORA BROCE BROOM KR350 / RJ350 | D16: CUADRILLA DE BARRIDO | E16: Barrido de Calzada y Apoyo | F16: m² | G16: 0 | H16: =G6 | I16: =AD35 | J16: =IF(H16>0, I16/H16, 0) | K16: 0 | L16: 8.94 | M16: =IF(L16>0, I16/L16, 0) | N16: =IF(I16=0, "SIN CONSUMO (Inactiva)", IF(AND(H16>0, J16<=1.2*0.05), "DENTRO DE RENDIMIENTO BASE", IF(H16>0, "EXCEDE RENDIMIENTO BASE", "OPERACIÓN SIN VOLUMEN")))
A17: 9 | B17: RT-02 | C17: RETROEXCAVADORA JOHN DEERE 310K / CASE 580N | D17: ADOLFO NAVA LOPEZ | E17: Carga Fresado y Derrumbes | F17: m³ | G17: 0 | H17: =G6 | I17: =AD36 | J17: =IF(H17>0, I17/H17, 0) | K17: 0 | L17: 7.44 | M17: =IF(L17>0, I17/L17, 0) | N17: =IF(I17=0, "SIN CONSUMO (Inactiva)", IF(AND(H17>0, J17<=1.2*0.15), "DENTRO DE RENDIMIENTO BASE", IF(H17>0, "EXCEDE RENDIMIENTO BASE", "OPERACIÓN SIN VOLUMEN")))
A18: 10 | B18: PT-01 | C18: PETROLIZADORA FORD F800 (IMPACTO 04) | D18: ELTHON EDUARDO MARTINEZ GOMORA | E18: Riego de Liga / Emulsión Asfáltica | F18: L-Emul | G18: 0 | H18: =G6 | I18: =AD37 | J18: =IF(H18>0, I18/H18, 0) | K18: 0 | L18: 12.76 | M18: =IF(L18>0, I18/L18, 0) | N18: =IF(I18=0, "SIN CONSUMO (Inactiva)", IF(AND(H18>0, J18<=1.2*0.12), "DENTRO DE RENDIMIENTO BASE", IF(H18>0, "EXCEDE RENDIMIENTO BASE", "OPERACIÓN SIN VOLUMEN")))
A19: 11 | B19: CPR-01 | C19: COMPRESOR SULLIVAN PALATEK D2010 | D19: CUADRILLA DE SOPLETEADO | E19: Sopleteado de Superficie y Juntas | F19: Horas | G19: 0 | H19: =G6 | I19: =AD38 | J19: =IF(H19>0, I19/H19, 0) | K19: 0 | L19: 9.97 | M19: =IF(L19>0, I19/L19, 0) | N19: =IF(I19=0, "SIN CONSUMO (Inactiva)", IF(AND(H19>0, J19<=1.2*0.08), "DENTRO DE RENDIMIENTO BASE", IF(H19>0, "EXCEDE RENDIMIENTO BASE", "OPERACIÓN SIN VOLUMEN")))
A20: 12 | B20: PP-01 | C20: PIPA DE AGUA (IMPACTO 01) FORD | D20: ALAN ALEXIS GUTIERREZ FLORES | E20: Enfriamiento Rodillos / Riego | F20: m³-Agua | G20: 0 | H20: =G6 | I20: =AD39 | J20: =IF(H20>0, I20/H20, 0) | K20: 0 | L20: 3.03 | M20: =IF(L20>0, I20/L20, 0) | N20: =IF(I20=0, "SIN CONSUMO (Inactiva)", IF(AND(H20>0, J20<=1.2*0.06), "DENTRO DE RENDIMIENTO BASE", IF(H20>0, "EXCEDE RENDIMIENTO BASE", "OPERACIÓN SIN VOLUMEN")))
A21: 13 | B21: CI-02 | C21: CAMIÓN DE IMPACTO FORD 4300 (ATENUADOR TMA) | D21: CUADRILLA DE SEGURIDAD VIAL | E21: Protección Vial / Atenuador Móvil | F21: Horas | G21: 0 | H21: =G6 | I21: =AD40 | J21: =IF(H21>0, I21/H21, 0) | K21: 0 | L21: 8.5 | M21: =IF(L21>0, I21/L21, 0) | N21: =IF(I21=0, "SIN CONSUMO (Inactiva)", IF(AND(H21>0, J21<=1.2*0.1), "DENTRO DE RENDIMIENTO BASE", IF(H21>0, "EXCEDE RENDIMIENTO BASE", "OPERACIÓN SIN VOLUMEN")))
A22: 14 | B22: TL-01 | C22: TORRE DE LUCES MAXILIGHT / APOYO NOCTURNO | D22: CUADRILLA NOCTURNA | E22: Iluminación Nocturna / Cuadrilla | F22: Horas | G22: 0 | H22: =G6 | I22: =AD41 | J22: =IF(H22>0, I22/H22, 0) | K22: 0 | L22: 2.41 | M22: =IF(L22>0, I22/L22, 0) | N22: =IF(I22=0, "SIN CONSUMO (Inactiva)", IF(AND(H22>0, J22<=1.2*0.04), "DENTRO DE RENDIMIENTO BASE", IF(H22>0, "EXCEDE RENDIMIENTO BASE", "OPERACIÓN SIN VOLUMEN")))
A23: TOTAL SEMANAL (OBRA LERMA - TRES MARÍAS) | G23: =SUM(G9:G22) | H23: =SUM(H9:H22) | I23: =SUM(I9:I22) | J23: =IF(H23>0, I23/H23, 0) | K23: =IF(G23>0, I23/G23, 0) | M23: =SUM(M9:M22) | N23: CONSOLIDADO SEMANAL
A25: DESGLOSE DIARIO DE COMBUSTIBLE, VOLUMEN, TONELAJE Y RENDIMIENTO — SEMANA 25
A26: DATOS DEL EQUIPO | F26: LUNES | J26: MARTES | N26: MIÉRCOLES | R26: JUEVES | V26: VIERNES | Z26: SÁBADO | AD26: TOTAL SEMANAL
A27: No. | B27: Económico | C27: Descripción de Maquinaria | D27: Operador Asignado | E27: Concepto de Trabajo | F27: Litros | G27: Vol m³ | H27: Horas Est | I27: Rend L/m³ | J27: Litros | K27: Vol m³ | L27: Horas Est | M27: Rend L/m³ | N27: Litros | O27: Vol m³ | P27: Horas Est | Q27: Rend L/m³ | R27: Litros | S27: Vol m³ | T27: Horas Est | U27: Rend L/m³ | V27: Litros | W27: Vol m³ | X27: Horas Est | Y27: Rend L/m³ | Z27: Litros | AA27: Vol m³ | AB27: Horas Est | AC27: Rend L/m³ | AD27: Diésel Surtido (L) | AE27: Vol m³ Total | AF27: Horas Est Total | AG27: Rend Prom (L/m³)
A28: 1 | B28: PR-01 | C28: PERFILADORA RODATEC RX600-4-4008 / RX600E | D28: JAVIER PAREDES CORTE | E28: Fresado de Pavimento | F28: 0 | G28: 0 | H28: =IF(L9>0, F28/L9, 0) | I28: =IF(G28>0, F28/G28, 0) | J28: 350 | K28: 0 | L28: =IF(L9>0, J28/L9, 0) | M28: =IF(K28>0, J28/K28, 0) | N28: 0 | O28: 0 | P28: =IF(L9>0, N28/L9, 0) | Q28: =IF(O28>0, N28/O28, 0) | R28: 0 | S28: 0 | T28: =IF(L9>0, R28/L9, 0) | U28: =IF(S28>0, R28/S28, 0) | V28: 0 | W28: 0 | X28: =IF(L9>0, V28/L9, 0) | Y28: =IF(W28>0, V28/W28, 0) | Z28: 0 | AA28: 0 | AB28: =IF(L9>0, Z28/L9, 0) | AC28: =IF(AA28>0, Z28/AA28, 0) | AD28: =F28+J28+N28+R28+V28+Z28 | AE28: =G28+K28+O28+S28+W28+AA28 | AF28: =H28+L28+P28+T28+X28+AB28 | AG28: =IF(AE28>0, AD28/AE28, 0)
A29: 2 | B29: VG-03 | C29: PAVIMENTADORA VÖGELE SJ 1800-3 / 1800-3i | D29: ERWIN CUTEÑO HERNANDEZ | E29: Tendido de Mezcla Asfáltica | F29: 73 | G29: 0 | H29: =IF(L10>0, F29/L10, 0) | I29: =IF(G29>0, F29/G29, 0) | J29: 165 | K29: 0 | L29: =IF(L10>0, J29/L10, 0) | M29: =IF(K29>0, J29/K29, 0) | N29: 0 | O29: 0 | P29: =IF(L10>0, N29/L10, 0) | Q29: =IF(O29>0, N29/O29, 0) | R29: 0 | S29: 0 | T29: =IF(L10>0, R29/L10, 0) | U29: =IF(S29>0, R29/S29, 0) | V29: 160 | W29: 0 | X29: =IF(L10>0, V29/L10, 0) | Y29: =IF(W29>0, V29/W29, 0) | Z29: 0 | AA29: 0 | AB29: =IF(L10>0, Z29/L10, 0) | AC29: =IF(AA29>0, Z29/AA29, 0) | AD29: =F29+J29+N29+R29+V29+Z29 | AE29: =G29+K29+O29+S29+W29+AA29 | AF29: =H29+L29+P29+T29+X29+AB29 | AG29: =IF(AE29>0, AD29/AE29, 0)
A30: 3 | B30: TD-01 | C30: COMPACTADOR TÁNDEM CATERPILLAR CB54 | D30: JOEL ALBERTO RIVERA RIVAS | E30: Compactación Tándem Primaria | F30: 24 | G30: 0 | H30: =IF(L11>0, F30/L11, 0) | I30: =IF(G30>0, F30/G30, 0) | J30: 0 | K30: 0 | L30: =IF(L11>0, J30/L11, 0) | M30: =IF(K30>0, J30/K30, 0) | N30: 0 | O30: 0 | P30: =IF(L11>0, N30/L11, 0) | Q30: =IF(O30>0, N30/O30, 0) | R30: 0 | S30: 0 | T30: =IF(L11>0, R30/L11, 0) | U30: =IF(S30>0, R30/S30, 0) | V30: 50 | W30: 0 | X30: =IF(L11>0, V30/L11, 0) | Y30: =IF(W30>0, V30/W30, 0) | Z30: 0 | AA30: 0 | AB30: =IF(L11>0, Z30/L11, 0) | AC30: =IF(AA30>0, Z30/AA30, 0) | AD30: =F30+J30+N30+R30+V30+Z30 | AE30: =G30+K30+O30+S30+W30+AA30 | AF30: =H30+L30+P30+T30+X30+AB30 | AG30: =IF(AE30>0, AD30/AE30, 0)
A31: 4 | B31: VC-01 | C31: VIBROCOMPACTADOR CATERPILLAR CB66B | D31: ALEXIS RENDON DOMINGUEZ | E31: Compactación Tándem Pesada / Acabado | F31: 0 | G31: 0 | H31: =IF(L12>0, F31/L12, 0) | I31: =IF(G31>0, F31/G31, 0) | J31: 0 | K31: 0 | L31: =IF(L12>0, J31/L12, 0) | M31: =IF(K31>0, J31/K31, 0) | N31: 0 | O31: 0 | P31: =IF(L12>0, N31/L12, 0) | Q31: =IF(O31>0, N31/O31, 0) | R31: 0 | S31: 0 | T31: =IF(L12>0, R31/L12, 0) | U31: =IF(S31>0, R31/S31, 0) | V31: 0 | W31: 0 | X31: =IF(L12>0, V31/L12, 0) | Y31: =IF(W31>0, V31/W31, 0) | Z31: 0 | AA31: 0 | AB31: =IF(L12>0, Z31/L12, 0) | AC31: =IF(AA31>0, Z31/AA31, 0) | AD31: =F31+J31+N31+R31+V31+Z31 | AE31: =G31+K31+O31+S31+W31+AA31 | AF31: =H31+L31+P31+T31+X31+AB31 | AG31: =IF(AE31>0, AD31/AE31, 0)
A32: 5 | B32: NM-02 | C32: COMPACTADOR NEUMÁTICO VOLVO PT-240R | D32: JOSE CARLOS ROMERO TELLEZ | E32: Compactación Neumática / Sellado | F32: 0 | G32: 0 | H32: =IF(L13>0, F32/L13, 0) | I32: =IF(G32>0, F32/G32, 0) | J32: 0 | K32: 0 | L32: =IF(L13>0, J32/L13, 0) | M32: =IF(K32>0, J32/K32, 0) | N32: 0 | O32: 0 | P32: =IF(L13>0, N32/L13, 0) | Q32: =IF(O32>0, N32/O32, 0) | R32: 0 | S32: 0 | T32: =IF(L13>0, R32/L13, 0) | U32: =IF(S32>0, R32/S32, 0) | V32: 30 | W32: 0 | X32: =IF(L13>0, V32/L13, 0) | Y32: =IF(W32>0, V32/W32, 0) | Z32: 0 | AA32: 0 | AB32: =IF(L13>0, Z32/L13, 0) | AC32: =IF(AA32>0, Z32/AA32, 0) | AD32: =F32+J32+N32+R32+V32+Z32 | AE32: =G32+K32+O32+S32+W32+AA32 | AF32: =H32+L32+P32+T32+X32+AB32 | AG32: =IF(AE32>0, AD32/AE32, 0)
A33: 6 | B33: NM-08 | C33: COMPACTADOR NEUMÁTICO PF-300B | D33: NOLVIN DE JESUS PEREZ GOMEZ | E33: Compactación Neumática / Acabado | F33: 0 | G33: 0 | H33: =IF(L14>0, F33/L14, 0) | I33: =IF(G33>0, F33/G33, 0) | J33: 0 | K33: 0 | L33: =IF(L14>0, J33/L14, 0) | M33: =IF(K33>0, J33/K33, 0) | N33: 0 | O33: 0 | P33: =IF(L14>0, N33/L14, 0) | Q33: =IF(O33>0, N33/O33, 0) | R33: 0 | S33: 0 | T33: =IF(L14>0, R33/L14, 0) | U33: =IF(S33>0, R33/S33, 0) | V33: 0 | W33: 0 | X33: =IF(L14>0, V33/L14, 0) | Y33: =IF(W33>0, V33/W33, 0) | Z33: 0 | AA33: 0 | AB33: =IF(L14>0, Z33/L14, 0) | AC33: =IF(AA33>0, Z33/AA33, 0) | AD33: =F33+J33+N33+R33+V33+Z33 | AE33: =G33+K33+O33+S33+W33+AA33 | AF33: =H33+L33+P33+T33+X33+AB33 | AG33: =IF(AE33>0, AD33/AE33, 0)
A34: 7 | B34: BR-02 | C34: BARREDORA INDUSTRIAL LAYMOR SM400 | D34: EDGAR ROSALES MARTINEZ | E34: Limpieza y Barrido Previo | F34: 52 | G34: 0 | H34: =IF(L15>0, F34/L15, 0) | I34: =IF(G34>0, F34/G34, 0) | J34: 0 | K34: 0 | L34: =IF(L15>0, J34/L15, 0) | M34: =IF(K34>0, J34/K34, 0) | N34: 0 | O34: 0 | P34: =IF(L15>0, N34/L15, 0) | Q34: =IF(O34>0, N34/O34, 0) | R34: 0 | S34: 0 | T34: =IF(L15>0, R34/L15, 0) | U34: =IF(S34>0, R34/S34, 0) | V34: 43 | W34: 0 | X34: =IF(L15>0, V34/L15, 0) | Y34: =IF(W34>0, V34/W34, 0) | Z34: 0 | AA34: 0 | AB34: =IF(L15>0, Z34/L15, 0) | AC34: =IF(AA34>0, Z34/AA34, 0) | AD34: =F34+J34+N34+R34+V34+Z34 | AE34: =G34+K34+O34+S34+W34+AA34 | AF34: =H34+L34+P34+T34+X34+AB34 | AG34: =IF(AE34>0, AD34/AE34, 0)
A35: 8 | B35: BR-05 | C35: BARREDORA BROCE BROOM KR350 / RJ350 | D35: CUADRILLA DE BARRIDO | E35: Barrido de Calzada y Apoyo | F35: 0 | G35: 0 | H35: =IF(L16>0, F35/L16, 0) | I35: =IF(G35>0, F35/G35, 0) | J35: 0 | K35: 0 | L35: =IF(L16>0, J35/L16, 0) | M35: =IF(K35>0, J35/K35, 0) | N35: 0 | O35: 0 | P35: =IF(L16>0, N35/L16, 0) | Q35: =IF(O35>0, N35/O35, 0) | R35: 0 | S35: 0 | T35: =IF(L16>0, R35/L16, 0) | U35: =IF(S35>0, R35/S35, 0) | V35: 0 | W35: 0 | X35: =IF(L16>0, V35/L16, 0) | Y35: =IF(W35>0, V35/W35, 0) | Z35: 0 | AA35: 0 | AB35: =IF(L16>0, Z35/L16, 0) | AC35: =IF(AA35>0, Z35/AA35, 0) | AD35: =F35+J35+N35+R35+V35+Z35 | AE35: =G35+K35+O35+S35+W35+AA35 | AF35: =H35+L35+P35+T35+X35+AB35 | AG35: =IF(AE35>0, AD35/AE35, 0)
A36: 9 | B36: RT-02 | C36: RETROEXCAVADORA JOHN DEERE 310K / CASE 580N | D36: ADOLFO NAVA LOPEZ | E36: Carga Fresado y Derrumbes | F36: 55 | G36: 0 | H36: =IF(L17>0, F36/L17, 0) | I36: =IF(G36>0, F36/G36, 0) | J36: 0 | K36: 0 | L36: =IF(L17>0, J36/L17, 0) | M36: =IF(K36>0, J36/K36, 0) | N36: 0 | O36: 0 | P36: =IF(L17>0, N36/L17, 0) | Q36: =IF(O36>0, N36/O36, 0) | R36: 0 | S36: 0 | T36: =IF(L17>0, R36/L17, 0) | U36: =IF(S36>0, R36/S36, 0) | V36: 80 | W36: 0 | X36: =IF(L17>0, V36/L17, 0) | Y36: =IF(W36>0, V36/W36, 0) | Z36: 0 | AA36: 0 | AB36: =IF(L17>0, Z36/L17, 0) | AC36: =IF(AA36>0, Z36/AA36, 0) | AD36: =F36+J36+N36+R36+V36+Z36 | AE36: =G36+K36+O36+S36+W36+AA36 | AF36: =H36+L36+P36+T36+X36+AB36 | AG36: =IF(AE36>0, AD36/AE36, 0)
A37: 10 | B37: PT-01 | C37: PETROLIZADORA FORD F800 (IMPACTO 04) | D37: ELTHON EDUARDO MARTINEZ GOMORA | E37: Riego de Liga / Emulsión Asfáltica | F37: 60 | G37: 0 | H37: =IF(L18>0, F37/L18, 0) | I37: =IF(G37>0, F37/G37, 0) | J37: 0 | K37: 0 | L37: =IF(L18>0, J37/L18, 0) | M37: =IF(K37>0, J37/K37, 0) | N37: 0 | O37: 0 | P37: =IF(L18>0, N37/L18, 0) | Q37: =IF(O37>0, N37/O37, 0) | R37: 0 | S37: 0 | T37: =IF(L18>0, R37/L18, 0) | U37: =IF(S37>0, R37/S37, 0) | V37: 40 | W37: 0 | X37: =IF(L18>0, V37/L18, 0) | Y37: =IF(W37>0, V37/W37, 0) | Z37: 0 | AA37: 0 | AB37: =IF(L18>0, Z37/L18, 0) | AC37: =IF(AA37>0, Z37/AA37, 0) | AD37: =F37+J37+N37+R37+V37+Z37 | AE37: =G37+K37+O37+S37+W37+AA37 | AF37: =H37+L37+P37+T37+X37+AB37 | AG37: =IF(AE37>0, AD37/AE37, 0)
A38: 11 | B38: CPR-01 | C38: COMPRESOR SULLIVAN PALATEK D2010 | D38: CUADRILLA DE SOPLETEADO | E38: Sopleteado de Superficie y Juntas | F38: 0 | G38: 0 | H38: =IF(L19>0, F38/L19, 0) | I38: =IF(G38>0, F38/G38, 0) | J38: 0 | K38: 0 | L38: =IF(L19>0, J38/L19, 0) | M38: =IF(K38>0, J38/K38, 0) | N38: 0 | O38: 0 | P38: =IF(L19>0, N38/L19, 0) | Q38: =IF(O38>0, N38/O38, 0) | R38: 0 | S38: 0 | T38: =IF(L19>0, R38/L19, 0) | U38: =IF(S38>0, R38/S38, 0) | V38: 0 | W38: 0 | X38: =IF(L19>0, V38/L19, 0) | Y38: =IF(W38>0, V38/W38, 0) | Z38: 0 | AA38: 0 | AB38: =IF(L19>0, Z38/L19, 0) | AC38: =IF(AA38>0, Z38/AA38, 0) | AD38: =F38+J38+N38+R38+V38+Z38 | AE38: =G38+K38+O38+S38+W38+AA38 | AF38: =H38+L38+P38+T38+X38+AB38 | AG38: =IF(AE38>0, AD38/AE38, 0)
A39: 12 | B39: PP-01 | C39: PIPA DE AGUA (IMPACTO 01) FORD | D39: ALAN ALEXIS GUTIERREZ FLORES | E39: Enfriamiento Rodillos / Riego | F39: 0 | G39: 0 | H39: =IF(L20>0, F39/L20, 0) | I39: =IF(G39>0, F39/G39, 0) | J39: 100 | K39: 0 | L39: =IF(L20>0, J39/L20, 0) | M39: =IF(K39>0, J39/K39, 0) | N39: 0 | O39: 0 | P39: =IF(L20>0, N39/L20, 0) | Q39: =IF(O39>0, N39/O39, 0) | R39: 0 | S39: 0 | T39: =IF(L20>0, R39/L20, 0) | U39: =IF(S39>0, R39/S39, 0) | V39: 50 | W39: 0 | X39: =IF(L20>0, V39/L20, 0) | Y39: =IF(W39>0, V39/W39, 0) | Z39: 0 | AA39: 0 | AB39: =IF(L20>0, Z39/L20, 0) | AC39: =IF(AA39>0, Z39/AA39, 0) | AD39: =F39+J39+N39+R39+V39+Z39 | AE39: =G39+K39+O39+S39+W39+AA39 | AF39: =H39+L39+P39+T39+X39+AB39 | AG39: =IF(AE39>0, AD39/AE39, 0)
... A41: 14 | B41: TL-01 | C41: TORRE DE LUCES MAXILIGHT / APOYO NOCTURNO | D41: CUADRILLA NOCTURNA | E41: Iluminación Nocturna / Cuadrilla | F41: 25 | G41: 0 | H41: =IF(L22>0, F41/L22, 0) | I41: =IF(G41>0, F41/G41, 0) | J41: 0 | K41: 0 | L41: =IF(L22>0, J41/L22, 0) | M41: =IF(K41>0, J41/K41, 0) | N41: 0 | O41: 0 | P41: =IF(L22>0, N41/L22, 0) | Q41: =IF(O41>0, N41/O41, 0) | R41: 0 | S41: 0 | T41: =IF(L22>0, R41/L22, 0) | U41: =IF(S41>0, R41/S41, 0) | V41: 0 | W41: 0 | X41: =IF(L22>0, V41/L22, 0) | Y41: =IF(W41>0, V41/W41, 0) | Z41: 0 | AA41: 0 | AB41: =IF(L22>0, Z41/L22, 0) | AC41: =IF(AA41>0, Z41/AA41, 0) | AD41: =F41+J41+N41+R41+V41+Z41 | AE41: =G41+K41+O41+S41+W41+AA41 | AF41: =H41+L41+P41+T41+X41+AB41 | AG41: =IF(AE41>0, AD41/AE41, 0)
A42: TOTAL DIARIO CONSOLIDADO (OBRA LERMA - TRES MARÍAS) | F42: =SUM(F28:F41) | G42: =SUM(G28:G41) | H42: =SUM(H28:H41) | I42: =IF(G42>0, F42/G42, 0) | J42: =SUM(J28:J41) | K42: =SUM(K28:K41) | L42: =SUM(L28:L41) | M42: =IF(K42>0, J42/K42, 0) | N42: =SUM(N28:N41) | O42: =SUM(O28:O41) | P42: =SUM(P28:P41) | Q42: =IF(O42>0, N42/O42, 0) | R42: =SUM(R28:R41) | S42: =SUM(S28:S41) | T42: =SUM(T28:T41) | U42: =IF(S42>0, R42/S42, 0) | V42: =SUM(V28:V41) | W42: =SUM(W28:W41) | X42: =SUM(X28:X41) | Y42: =IF(W42>0, V42/W42, 0) | Z42: =SUM(Z28:Z41) | AA42: =SUM(AA28:AA41) | AB42: =SUM(AB28:AB41) | AC42: =IF(AA42>0, Z42/AA42, 0) | AD42: =SUM(AD28:AD41) | AE42: =SUM(AE28:AE41) | AF42: =SUM(AF28:AF41) | AG42: =IF(AE42>0, AD42/AE42, 0)

Sheet Semana 26
A1: CONTROL SEMANAL DE RENDIMIENTO DE MAQUINARIA (SEMANA 26)
A2: OBRA: LERMA - TRES MARÍAS | PERIODO: 22/Jun/2026 - 27/Jun/2026
D4: PESO VOLUMÉTRICO ASFALTO: | E4: 1.742
B5: VIAJES FRESADO: | C5: 0 | D5: VOLUMEN FRESADO (m³): | E5: 0
B6: VIAJES CARPETA: | C6: 0 | D6: VOLUMEN CARPETA (m³): | E6: 0 | F6: TONELADAS CARPETA: | G6: =E6*$E$4
A8: No. | B8: Económico | C8: Descripción de Maquinaria | D8: Operador Asignado | E8: Concepto de Trabajo | F8: Unidad Medida | G8: Volumen m³ | H8: Volumen Ton | I8: Diésel Surtido (L) | J8: Rendimiento Real (L/Ton) | K8: Rendimiento Real (L/m³) | L8: Rendimiento Base (L/h) | M8: Horas Estimadas (h) | N8: Estatus Operativo
A9: 1 | B9: PR-01 | C9: PERFILADORA RODATEC RX600-4-4008 / RX600E | D9: JAVIER PAREDES CORTE | E9: Fresado de Pavimento | F9: m³ | G9: =E5 | H9: 0 | I9: =AD28 | J9: 0 | K9: =IF(G9>0, I9/G9, 0) | L9: 67.2 | M9: =IF(L9>0, I9/L9, 0) | N9: =IF(I9=0, "SIN CONSUMO (Inactiva)", IF(AND(G9>0, K9<=1.3*3.2), "DENTRO DE RENDIMIENTO BASE", IF(G9>0, "EXCEDE RENDIMIENTO BASE", "OPERACIÓN SIN VOLUMEN")))
A10: 2 | B10: VG-03 | C10: PAVIMENTADORA VÖGELE SJ 1800-3 / 1800-3i | D10: ERWIN CUTEÑO HERNANDEZ | E10: Tendido de Mezcla Asfáltica | F10: Ton | G10: 0 | H10: =G6 | I10: =AD29 | J10: =IF(H10>0, I10/H10, 0) | K10: =IF($E$6>0, I10/$E$6, 0) | L10: 16.24 | M10: =IF(L10>0, I10/L10, 0) | N10: =IF(I10=0, "SIN CONSUMO (Inactiva)", IF(AND(H10>0, J10<=1.2*0.35), "DENTRO DE RENDIMIENTO BASE", IF(H10>0, "EXCEDE RENDIMIENTO BASE", "OPERACIÓN SIN VOLUMEN")))
A11: 3 | B11: TD-01 | C11: COMPACTADOR TÁNDEM CATERPILLAR CB54 | D11: JOEL ALBERTO RIVERA RIVAS | E11: Compactación Tándem Primaria | F11: Ton | G11: 0 | H11: =G6 | I11: =AD30 | J11: =IF(H11>0, I11/H11, 0) | K11: =IF($E$6>0, I11/$E$6, 0) | L11: 14.3 | M11: =IF(L11>0, I11/L11, 0) | N11: =IF(I11=0, "SIN CONSUMO (Inactiva)", IF(AND(H11>0, J11<=1.2*0.3), "DENTRO DE RENDIMIENTO BASE", IF(H11>0, "EXCEDE RENDIMIENTO BASE", "OPERACIÓN SIN VOLUMEN")))
A12: 4 | B12: VC-01 | C12: VIBROCOMPACTADOR CATERPILLAR CB66B | D12: ALEXIS RENDON DOMINGUEZ | E12: Compactación Tándem Pesada / Acabado | F12: Ton | G12: 0 | H12: =G6 | I12: =AD31 | J12: =IF(H12>0, I12/H12, 0) | K12: =IF($E$6>0, I12/$E$6, 0) | L12: 14.3 | M12: =IF(L12>0, I12/L12, 0) | N12: =IF(I12=0, "SIN CONSUMO (Inactiva)", IF(AND(H12>0, J12<=1.2*0.3), "DENTRO DE RENDIMIENTO BASE", IF(H12>0, "EXCEDE RENDIMIENTO BASE", "OPERACIÓN SIN VOLUMEN")))
A13: 5 | B13: NM-02 | C13: COMPACTADOR NEUMÁTICO VOLVO PT-240R | D13: JOSE CARLOS ROMERO TELLEZ | E13: Compactación Neumática / Sellado | F13: Ton | G13: 0 | H13: =G6 | I13: =AD32 | J13: =IF(H13>0, I13/H13, 0) | K13: =IF($E$6>0, I13/$E$6, 0) | L13: 11.44 | M13: =IF(L13>0, I13/L13, 0) | N13: =IF(I13=0, "SIN CONSUMO (Inactiva)", IF(AND(H13>0, J13<=1.2*0.25), "DENTRO DE RENDIMIENTO BASE", IF(H13>0, "EXCEDE RENDIMIENTO BASE", "OPERACIÓN SIN VOLUMEN")))
A14: 6 | B14: NM-08 | C14: COMPACTADOR NEUMÁTICO PF-300B | D14: NOLVIN DE JESUS PEREZ GOMEZ | E14: Compactación Neumática / Acabado | F14: Ton | G14: 0 | H14: =G6 | I14: =AD33 | J14: =IF(H14>0, I14/H14, 0) | K14: =IF($E$6>0, I14/$E$6, 0) | L14: 10.96 | M14: =IF(L14>0, I14/L14, 0) | N14: =IF(I14=0, "SIN CONSUMO (Inactiva)", IF(AND(H14>0, J14<=1.2*0.24), "DENTRO DE RENDIMIENTO BASE", IF(H14>0, "EXCEDE RENDIMIENTO BASE", "OPERACIÓN SIN VOLUMEN")))
A15: 7 | B15: BR-02 | C15: BARREDORA INDUSTRIAL LAYMOR SM400 | D15: EDGAR ROSALES MARTINEZ | E15: Limpieza y Barrido Previo | F15: m² | G15: 0 | H15: =G6 | I15: =AD34 | J15: =IF(H15>0, I15/H15, 0) | K15: 0 | L15: 8.94 | M15: =IF(L15>0, I15/L15, 0) | N15: =IF(I15=0, "SIN CONSUMO (Inactiva)", IF(AND(H15>0, J15<=1.2*0.05), "DENTRO DE RENDIMIENTO BASE", IF(H15>0, "EXCEDE RENDIMIENTO BASE", "OPERACIÓN SIN VOLUMEN")))
A16: 8 | B16: BR-05 | C16: BARREDORA BROCE BROOM KR350 / RJ350 | D16: CUADRILLA DE BARRIDO | E16: Barrido de Calzada y Apoyo | F16: m² | G16: 0 | H16: =G6 | I16: =AD35 | J16: =IF(H16>0, I16/H16, 0) | K16: 0 | L16: 8.94 | M16: =IF(L16>0, I16/L16, 0) | N16: =IF(I16=0, "SIN CONSUMO (Inactiva)", IF(AND(H16>0, J16<=1.2*0.05), "DENTRO DE RENDIMIENTO BASE", IF(H16>0, "EXCEDE RENDIMIENTO BASE", "OPERACIÓN SIN VOLUMEN")))
A17: 9 | B17: RT-02 | C17: RETROEXCAVADORA JOHN DEERE 310K / CASE 580N | D17: ADOLFO NAVA LOPEZ | E17: Carga Fresado y Derrumbes | F17: m³ | G17: 0 | H17: =G6 | I17: =AD36 | J17: =IF(H17>0, I17/H17, 0) | K17: 0 | L17: 7.44 | M17: =IF(L17>0, I17/L17, 0) | N17: =IF(I17=0, "SIN CONSUMO (Inactiva)", IF(AND(H17>0, J17<=1.2*0.15), "DENTRO DE RENDIMIENTO BASE", IF(H17>0, "EXCEDE RENDIMIENTO BASE", "OPERACIÓN SIN VOLUMEN")))
A18: 10 | B18: PT-01 | C18: PETROLIZADORA FORD F800 (IMPACTO 04) | D18: ELTHON EDUARDO MARTINEZ GOMORA | E18: Riego de Liga / Emulsión Asfáltica | F18: L-Emul | G18: 0 | H18: =G6 | I18: =AD37 | J18: =IF(H18>0, I18/H18, 0) | K18: 0 | L18: 12.76 | M18: =IF(L18>0, I18/L18, 0) | N18: =IF(I18=0, "SIN CONSUMO (Inactiva)", IF(AND(H18>0, J18<=1.2*0.12), "DENTRO DE RENDIMIENTO BASE", IF(H18>0, "EXCEDE RENDIMIENTO BASE", "OPERACIÓN SIN VOLUMEN")))
A19: 11 | B19: CPR-01 | C19: COMPRESOR SULLIVAN PALATEK D2010 | D19: CUADRILLA DE SOPLETEADO | E19: Sopleteado de Superficie y Juntas | F19: Horas | G19: 0 | H19: =G6 | I19: =AD38 | J19: =IF(H19>0, I19/H19, 0) | K19: 0 | L19: 9.97 | M19: =IF(L19>0, I19/L19, 0) | N19: =IF(I19=0, "SIN CONSUMO (Inactiva)", IF(AND(H19>0, J19<=1.2*0.08), "DENTRO DE RENDIMIENTO BASE", IF(H19>0, "EXCEDE RENDIMIENTO BASE", "OPERACIÓN SIN VOLUMEN")))
A20: 12 | B20: PP-01 | C20: PIPA DE AGUA (IMPACTO 01) FORD | D20: ALAN ALEXIS GUTIERREZ FLORES | E20: Enfriamiento Rodillos / Riego | F20: m³-Agua | G20: 0 | H20: =G6 | I20: =AD39 | J20: =IF(H20>0, I20/H20, 0) | K20: 0 | L20: 3.03 | M20: =IF(L20>0, I20/L20, 0) | N20: =IF(I20=0, "SIN CONSUMO (Inactiva)", IF(AND(H20>0, J20<=1.2*0.06), "DENTRO DE RENDIMIENTO BASE", IF(H20>0, "EXCEDE RENDIMIENTO BASE", "OPERACIÓN SIN VOLUMEN")))
A21: 13 | B21: CI-02 | C21: CAMIÓN DE IMPACTO FORD 4300 (ATENUADOR TMA) | D21: CUADRILLA DE SEGURIDAD VIAL | E21: Protección Vial / Atenuador Móvil | F21: Horas | G21: 0 | H21: =G6 | I21: =AD40 | J21: =IF(H21>0, I21/H21, 0) | K21: 0 | L21: 8.5 | M21: =IF(L21>0, I21/L21, 0) | N21: =IF(I21=0, "SIN CONSUMO (Inactiva)", IF(AND(H21>0, J21<=1.2*0.1), "DENTRO DE RENDIMIENTO BASE", IF(H21>0, "EXCEDE RENDIMIENTO BASE", "OPERACIÓN SIN VOLUMEN")))
A22: 14 | B22: TL-01 | C22: TORRE DE LUCES MAXILIGHT / APOYO NOCTURNO | D22: CUADRILLA NOCTURNA | E22: Iluminación Nocturna / Cuadrilla | F22: Horas | G22: 0 | H22: =G6 | I22: =AD41 | J22: =IF(H22>0, I22/H22, 0) | K22: 0 | L22: 2.41 | M22: =IF(L22>0, I22/L22, 0) | N22: =IF(I22=0, "SIN CONSUMO (Inactiva)", IF(AND(H22>0, J22<=1.2*0.04), "DENTRO DE RENDIMIENTO BASE", IF(H22>0, "EXCEDE RENDIMIENTO BASE", "OPERACIÓN SIN VOLUMEN")))
A23: TOTAL SEMANAL (OBRA LERMA - TRES MARÍAS) | G23: =SUM(G9:G22) | H23: =SUM(H9:H22) | I23: =SUM(I9:I22) | J23: =IF(H23>0, I23/H23, 0) | K23: =IF(G23>0, I23/G23, 0) | M23: =SUM(M9:M22) | N23: CONSOLIDADO SEMANAL
A25: DESGLOSE DIARIO DE COMBUSTIBLE, VOLUMEN, TONELAJE Y RENDIMIENTO — SEMANA 26
A26: DATOS DEL EQUIPO | F26: LUNES | J26: MARTES | N26: MIÉRCOLES | R26: JUEVES | V26: VIERNES | Z26: SÁBADO | AD26: TOTAL SEMANAL
A27: No. | B27: Económico | C27: Descripción de Maquinaria | D27: Operador Asignado | E27: Concepto de Trabajo | F27: Litros | G27: Vol m³ | H27: Horas Est | I27: Rend L/m³ | J27: Litros | K27: Vol m³ | L27: Horas Est | M27: Rend L/m³ | N27: Litros | O27: Vol m³ | P27: Horas Est | Q27: Rend L/m³ | R27: Litros | S27: Vol m³ | T27: Horas Est | U27: Rend L/m³ | V27: Litros | W27: Vol m³ | X27: Horas Est | Y27: Rend L/m³ | Z27: Litros | AA27: Vol m³ | AB27: Horas Est | AC27: Rend L/m³ | AD27: Diésel Surtido (L) | AE27: Vol m³ Total | AF27: Horas Est Total | AG27: Rend Prom (L/m³)
A28: 1 | B28: PR-01 | C28: PERFILADORA RODATEC RX600-4-4008 / RX600E | D28: JAVIER PAREDES CORTE | E28: Fresado de Pavimento | F28: 0 | G28: 0 | H28: =IF(L9>0, F28/L9, 0) | I28: =IF(G28>0, F28/G28, 0) | J28: 0 | K28: 0 | L28: =IF(L9>0, J28/L9, 0) | M28: =IF(K28>0, J28/K28, 0) | N28: 0 | O28: 0 | P28: =IF(L9>0, N28/L9, 0) | Q28: =IF(O28>0, N28/O28, 0) | R28: 140 | S28: 0 | T28: =IF(L9>0, R28/L9, 0) | U28: =IF(S28>0, R28/S28, 0) | V28: 0 | W28: 0 | X28: =IF(L9>0, V28/L9, 0) | Y28: =IF(W28>0, V28/W28, 0) | Z28: 0 | AA28: 0 | AB28: =IF(L9>0, Z28/L9, 0) | AC28: =IF(AA28>0, Z28/AA28, 0) | AD28: =F28+J28+N28+R28+V28+Z28 | AE28: =G28+K28+O28+S28+W28+AA28 | AF28: =H28+L28+P28+T28+X28+AB28 | AG28: =IF(AE28>0, AD28/AE28, 0)
A29: 2 | B29: VG-03 | C29: PAVIMENTADORA VÖGELE SJ 1800-3 / 1800-3i | D29: ERWIN CUTEÑO HERNANDEZ | E29: Tendido de Mezcla Asfáltica | F29: 162 | G29: 0 | H29: =IF(L10>0, F29/L10, 0) | I29: =IF(G29>0, F29/G29, 0) | J29: 0 | K29: 0 | L29: =IF(L10>0, J29/L10, 0) | M29: =IF(K29>0, J29/K29, 0) | N29: 0 | O29: 0 | P29: =IF(L10>0, N29/L10, 0) | Q29: =IF(O29>0, N29/O29, 0) | R29: 177 | S29: 0 | T29: =IF(L10>0, R29/L10, 0) | U29: =IF(S29>0, R29/S29, 0) | V29: 0 | W29: 0 | X29: =IF(L10>0, V29/L10, 0) | Y29: =IF(W29>0, V29/W29, 0) | Z29: 0 | AA29: 0 | AB29: =IF(L10>0, Z29/L10, 0) | AC29: =IF(AA29>0, Z29/AA29, 0) | AD29: =F29+J29+N29+R29+V29+Z29 | AE29: =G29+K29+O29+S29+W29+AA29 | AF29: =H29+L29+P29+T29+X29+AB29 | AG29: =IF(AE29>0, AD29/AE29, 0)
A30: 3 | B30: TD-01 | C30: COMPACTADOR TÁNDEM CATERPILLAR CB54 | D30: JOEL ALBERTO RIVERA RIVAS | E30: Compactación Tándem Primaria | F30: 50 | G30: 0 | H30: =IF(L11>0, F30/L11, 0) | I30: =IF(G30>0, F30/G30, 0) | J30: 0 | K30: 0 | L30: =IF(L11>0, J30/L11, 0) | M30: =IF(K30>0, J30/K30, 0) | N30: 0 | O30: 0 | P30: =IF(L11>0, N30/L11, 0) | Q30: =IF(O30>0, N30/O30, 0) | R30: 0 | S30: 0 | T30: =IF(L11>0, R30/L11, 0) | U30: =IF(S30>0, R30/S30, 0) | V30: 0 | W30: 0 | X30: =IF(L11>0, V30/L11, 0) | Y30: =IF(W30>0, V30/W30, 0) | Z30: 0 | AA30: 0 | AB30: =IF(L11>0, Z30/L11, 0) | AC30: =IF(AA30>0, Z30/AA30, 0) | AD30: =F30+J30+N30+R30+V30+Z30 | AE30: =G30+K30+O30+S30+W30+AA30 | AF30: =H30+L30+P30+T30+X30+AB30 | AG30: =IF(AE30>0, AD30/AE30, 0)
A31: 4 | B31: VC-01 | C31: VIBROCOMPACTADOR CATERPILLAR CB66B | D31: ALEXIS RENDON DOMINGUEZ | E31: Compactación Tándem Pesada / Acabado | F31: 0 | G31: 0 | H31: =IF(L12>0, F31/L12, 0) | I31: =IF(G31>0, F31/G31, 0) | J31: 0 | K31: 0 | L31: =IF(L12>0, J31/L12, 0) | M31: =IF(K31>0, J31/K31, 0) | N31: 0 | O31: 0 | P31: =IF(L12>0, N31/L12, 0) | Q31: =IF(O31>0, N31/O31, 0) | R31: 0 | S31: 0 | T31: =IF(L12>0, R31/L12, 0) | U31: =IF(S31>0, R31/S31, 0) | V31: 0 | W31: 0 | X31: =IF(L12>0, V31/L12, 0) | Y31: =IF(W31>0, V31/W31, 0) | Z31: 0 | AA31: 0 | AB31: =IF(L12>0, Z31/L12, 0) | AC31: =IF(AA31>0, Z31/AA31, 0) | AD31: =F31+J31+N31+R31+V31+Z31 | AE31: =G31+K31+O31+S31+W31+AA31 | AF31: =H31+L31+P31+T31+X31+AB31 | AG31: =IF(AE31>0, AD31/AE31, 0)
A32: 5 | B32: NM-02 | C32: COMPACTADOR NEUMÁTICO VOLVO PT-240R | D32: JOSE CARLOS ROMERO TELLEZ | E32: Compactación Neumática / Sellado | F32: 100 | G32: 0 | H32: =IF(L13>0, F32/L13, 0) | I32: =IF(G32>0, F32/G32, 0) | J32: 0 | K32: 0 | L32: =IF(L13>0, J32/L13, 0) | M32: =IF(K32>0, J32/K32, 0) | N32: 0 | O32: 0 | P32: =IF(L13>0, N32/L13, 0) | Q32: =IF(O32>0, N32/O32, 0) | R32: 0 | S32: 0 | T32: =IF(L13>0, R32/L13, 0) | U32: =IF(S32>0, R32/S32, 0) | V32: 0 | W32: 0 | X32: =IF(L13>0, V32/L13, 0) | Y32: =IF(W32>0, V32/W32, 0) | Z32: 0 | AA32: 0 | AB32: =IF(L13>0, Z32/L13, 0) | AC32: =IF(AA32>0, Z32/AA32, 0) | AD32: =F32+J32+N32+R32+V32+Z32 | AE32: =G32+K32+O32+S32+W32+AA32 | AF32: =H32+L32+P32+T32+X32+AB32 | AG32: =IF(AE32>0, AD32/AE32, 0)
A33: 6 | B33: NM-08 | C33: COMPACTADOR NEUMÁTICO PF-300B | D33: NOLVIN DE JESUS PEREZ GOMEZ | E33: Compactación Neumática / Acabado | F33: 0 | G33: 0 | H33: =IF(L14>0, F33/L14, 0) | I33: =IF(G33>0, F33/G33, 0) | J33: 0 | K33: 0 | L33: =IF(L14>0, J33/L14, 0) | M33: =IF(K33>0, J33/K33, 0) | N33: 0 | O33: 0 | P33: =IF(L14>0, N33/L14, 0) | Q33: =IF(O33>0, N33/O33, 0) | R33: 0 | S33: 0 | T33: =IF(L14>0, R33/L14, 0) | U33: =IF(S33>0, R33/S33, 0) | V33: 0 | W33: 0 | X33: =IF(L14>0, V33/L14, 0) | Y33: =IF(W33>0, V33/W33, 0) | Z33: 0 | AA33: 0 | AB33: =IF(L14>0, Z33/L14, 0) | AC33: =IF(AA33>0, Z33/AA33, 0) | AD33: =F33+J33+N33+R33+V33+Z33 | AE33: =G33+K33+O33+S33+W33+AA33 | AF33: =H33+L33+P33+T33+X33+AB33 | AG33: =IF(AE33>0, AD33/AE33, 0)
A34: 7 | B34: BR-02 | C34: BARREDORA INDUSTRIAL LAYMOR SM400 | D34: EDGAR ROSALES MARTINEZ | E34: Limpieza y Barrido Previo | F34: 0 | G34: 0 | H34: =IF(L15>0, F34/L15, 0) | I34: =IF(G34>0, F34/G34, 0) | J34: 0 | K34: 0 | L34: =IF(L15>0, J34/L15, 0) | M34: =IF(K34>0, J34/K34, 0) | N34: 0 | O34: 0 | P34: =IF(L15>0, N34/L15, 0) | Q34: =IF(O34>0, N34/O34, 0) | R34: 50 | S34: 0 | T34: =IF(L15>0, R34/L15, 0) | U34: =IF(S34>0, R34/S34, 0) | V34: 0 | W34: 0 | X34: =IF(L15>0, V34/L15, 0) | Y34: =IF(W34>0, V34/W34, 0) | Z34: 0 | AA34: 0 | AB34: =IF(L15>0, Z34/L15, 0) | AC34: =IF(AA34>0, Z34/AA34, 0) | AD34: =F34+J34+N34+R34+V34+Z34 | AE34: =G34+K34+O34+S34+W34+AA34 | AF34: =H34+L34+P34+T34+X34+AB34 | AG34: =IF(AE34>0, AD34/AE34, 0)
