Workbook

Sheet Carga_Camiones
A1: GC-MAT-001 | BITÁCORA DE CARGA DE CAMIONES (PLANTA / TRANSPORTE)
A2: Responsable: | D2: Semana: | G2: Fecha entrega: | K2: Plantas Origen: | L2: Toluca / Huixquilucan
A4: Fecha | B4: Folio Remisión (JDJ) | C4: Folio Báscula | D4: Planta Origen | E4: Obra Destino | F4: Material | G4: Placas del Vehículo | H4: Tipo de Vehículo | I4: Capacidad (m³) | J4: Operador | K4: Peso Bruto (kg) | L4: Peso Tara (kg) | M4: Peso Neto (kg) | N4: Hora de Salida | O4: Temperatura (°C) | P4: Odómetro / Kilometraje | Q4: Despachador | R4: Observaciones
A5: 2026-06-08 | B5: 5632 | C5: 56140 | D5: Toluca | E5: Chamapa - Lecheria | F5: Carpeta Densa | G5: 98-BM-8P | H5: Torton | I5: 14 | J5: Bernabé Gutierrez | K5: 36120 | L5: 11290 | M5: =K5-L5 -> 24830 | N5: 11:58 PM | O5: 185 | P5: km 61290 + 6442 | Q5: c1ll0ll1 CM | R5: cpo 1 carril unico
A6: 2026-06-15 | B6: 86.0 | C6: 56140.0 | D6: Toluca | E6: Lerma - Toluca | F6: Mezcla Preparada Caliente N.3 | G6: 464AJ2 | H6: Torton | I6: 14 | J6: Carlos Valdes | K6: 36120 | L6: 11290 | M6: =K6-L6 -> 24830 | N6: 12:44 | O6: 172 | P6: km 61290 + 6442 | Q6: c1ll0ll1 CM | R6: cpo 1 carril unico
M7: =K7-L7 -> 0
M8: =K8-L8 -> 0
M9: =K9-L9 -> 0
M10: =K10-L10 -> 0
M11: =K11-L11 -> 0
M12: =K12-L12 -> 0
M13: =K13-L13 -> 0
M14: =K14-L14 -> 0
M15: =K15-L15 -> 0
M16: =K16-L16 -> 0
M17: =K17-L17 -> 0
M18: =K18-L18 -> 0
... M105: =K105-L105 -> 0

Sheet Cotejo_Mezcla
A1: GC-MAT-002 | CONCILIACIÓN Y COTEJO DE MEZCLA (PLANTA VS REMISIÓN OBRA)
A2: Encargado: | D2: Periodo: | G2: Obra Destino: | H2: Todas
A4: Fecha Planta | B4: Folio Remisión Planta | C4: Planta Origen | D4: Peso Neto Planta (kg) | E4: Hora Salida Planta | F4: Temp Planta (°C) | G4: Folio Nota Trujano (Obra) | H4: Obra Destino | I4: Sindicato | J4: Material Recibido | K4: Placas Vehículo | L4: Capacidad (m³) | M4: Operador | N4: Hora Llegada Obra | O4: Temp Obra (°C) | P4: Encargado de Obra | Q4: Checador | R4: Pérdida Temp (°C) | S4: Estatus Entrega | T4: Observaciones
A5: 46181 | B5: =Carga_Camiones!B5 -> 5632 | C5: Planta Huixquilucan | D5: 0 | E5: =Carga_Camiones!N5 -> 11:58 PM | F5: 175 | G5: 5632 | H5: Chamapa - Lecheria | I5: Cusum Huixquiluca | J5: Protocolo | K5: 98-BM-8P | L5: 14 | M5: Bernabé Gutierrez | N5: 0.055555556 | O5: 0 | P5: Francisco Javier | Q5: Yahir Barreda | R5: =F5-O5 -> 175 | S5: =IF(G5="","Pendiente",IF(K5=Carga_Camiones!G5,"OK","Diferencia Placa")) -> OK | T5: Carga nocturna conciliada con firma de checador
A6: 46182 | B6: 5633 | C6: Planta Huixquilucan | D6: 0 | E6: 0.015972222 | F6: 175 | G6: 5633 | H6: Chamapa - Lecheria | I6: Cusum Huixquiluca | J6: Protocolo | K6: 119-AJ-3 | L6: 14 | M6: Bernabe Chaves | N6: 0.059027778 | O6: 0 | P6: Francisco Javier | Q6: Yahir Barreda | R6: =IF(O6="","",F6-O6) -> 175 | S6: =IF(G6="","Pendiente",IF(K6=Carga_Camiones!G6,"OK","Diferencia Placa")) -> Diferencia Placa | T6: Entregado a tiempo, sin novedades
A7: 46182 | B7: 5634 | C7: Planta Huixquilucan | D7: =Carga_Camiones!M7 -> 0 | E7: 0.040277778 | F7: 175 | G7: 5634 | H7: Chamapa - Lecheria | I7: Cusum Huixquiluca | J7: Protocolo | K7: ND-5931-C | L7: 14 | M7: Ivsn Mulato | N7: 0.072916667 | O7: 0 | P7: Francisco Javier | Q7: Yahir Barreda | R7: =IF(O7="","",F7-O7) -> 175 | S7: =IF(G7="","Pendiente",IF(K7=Carga_Camiones!G7,"OK","Diferencia Placa")) -> Diferencia Placa
A8: 46182 | B8: 5635 | C8: Planta Huixquilucan | D8: =Carga_Camiones!M8 -> 0 | E8: =Carga_Camiones!N8 -> 0 | F8: 175 | G8: 5635 | H8: Chamapa - Lecheria | I8: Cusum Huixquiluca | J8: Protocolo | K8: 94-AC-5F | L8: 14 | M8: Hugo Gutierrez | O8: 0 | P8: Francisco Javier | Q8: Yahir Barreda | R8: =IF(O8="","",F8-O8) -> 175 | S8: =IF(G8="","Pendiente",IF(K8=Carga_Camiones!G8,"OK","Diferencia Placa")) -> Diferencia Placa
A9: 46182 | B9: 5636 | C9: Planta Huixquilucan | D9: =Carga_Camiones!M9 -> 0 | E9: 0.39861111 | F9: 175 | G9: 5636 | H9: Chamapa - Lecheria | I9: Cusum Huixquiluca | J9: Protocolo | K9: 73-DG-IU | L9: 14 | M9: Edwin | O9: 0 | P9: Francisco Javier | Q9: Yahir Barreda | R9: =IF(O9="","",F9-O9) -> 175 | S9: =IF(G9="","Pendiente",IF(K9=Carga_Camiones!G9,"OK","Diferencia Placa")) -> Diferencia Placa
A10: 46182 | B10: 5637 | C10: Planta Huixquilucan | D10: =Carga_Camiones!M10 -> 0 | E10: 0.088194444 | F10: 175 | G10: 5637 | H10: Chamapa - Lecheria | I10: Cusum Huixquiluca | J10: Protocolo | K10: LC-45-753 | L10: 14 | M10: Cesar Granados | O10: 0 | P10: Francisco Javier | Q10: Yahir Barreda | R10: =IF(O10="","",F10-O10) -> 175 | S10: =IF(G10="","Pendiente",IF(K10=Carga_Camiones!G10,"OK","Diferencia Placa")) -> Diferencia Placa
A11: 46182 | B11: 5638 | C11: Planta Huixquilucan | D11: =Carga_Camiones!M11 -> 0 | E11: 0.10625 | F11: 175 | G11: 5638 | H11: Chamapa - Lecheria | I11: Cusum Huixquiluca | J11: Protocolo | K11: 02-BG-FT | L11: 14 | M11: Cesar Gutierrez | O11: 0 | P11: Francisco Javier | Q11: Yahir Barreda | R11: =IF(O11="","",F11-O11) -> 175 | S11: =IF(G11="","Pendiente",IF(K11=Carga_Camiones!G11,"OK","Diferencia Placa")) -> Diferencia Placa
A12: 46182 | B12: 5639 | C12: Planta Huixquilucan | D12: =Carga_Camiones!M12 -> 0 | E12: 0.125 | F12: 175 | G12: 5639 | H12: Chamapa - Lecheria | I12: Cusum Huixquiluca | J12: Protocolo | K12: 43-BD-6C | L12: 14 | M12: Victor Gutierrez | O12: 0 | P12: Francisco Javier | Q12: Yahir Barreda | R12: =IF(O12="","",F12-O12) -> 175 | S12: =IF(G12="","Pendiente",IF(K12=Carga_Camiones!G12,"OK","Diferencia Placa")) -> Diferencia Placa
A13: 46182 | B13: 5640 | C13: Planta Huixquilucan | D13: =Carga_Camiones!M13 -> 0 | E13: 0.13888889 | F13: 175 | G13: 5640 | H13: Chamapa - Lecheria | I13: Cusum Huixquiluca | J13: Protocolo | K13: 487-AP-2 | L13: 14 | M13: Ivan Gutierrez | O13: 0 | P13: Francisco Javier | Q13: Yahir Barreda | R13: =IF(O13="","",F13-O13) -> 175 | S13: =IF(G13="","Pendiente",IF(K13=Carga_Camiones!G13,"OK","Diferencia Placa")) -> Diferencia Placa
A14: 46182 | B14: 5641 | C14: Planta Huixquilucan | D14: =Carga_Camiones!M14 -> 0 | E14: 0.15347222 | F14: 175 | G14: 5641 | H14: Chamapa - Lecheria | I14: Cusum Huixquiluca | J14: Protocolo | K14: 98-CM-8P | L14: 14 | M14: Bernaba Gutierrez | O14: 0 | P14: Francisco Javier | Q14: Yahir Barreda | R14: =IF(O14="","",F14-O14) -> 175 | S14: =IF(G14="","Pendiente",IF(K14=Carga_Camiones!G14,"OK","Diferencia Placa")) -> Diferencia Placa
A15: 46182 | B15: 5642 | C15: Planta Huixquilucan | D15: =Carga_Camiones!M15 -> 0 | E15: 0.16875 | F15: 175 | G15: 5642 | H15: Chamapa - Lecheria | I15: Cusum Huixquiluca | J15: Protocolo | K15: LG-01-321 | L15: 14 | M15: Julio | O15: 0 | P15: Francisco Javier | Q15: Yahir Barreda | R15: =IF(O15="","",F15-O15) -> 175 | S15: =IF(G15="","Pendiente",IF(K15=Carga_Camiones!G15,"OK","Diferencia Placa")) -> Diferencia Placa
A16: 46182 | B16: 5643 | C16: Planta Huixquilucan | D16: =Carga_Camiones!M16 -> 0 | E16: 0.18402778 | F16: 175 | G16: 5643 | H16: Chamapa - Lecheria | I16: Cusum Huixquiluca | J16: Protocolo | K16: NS-1640-C | L16: 14 | M16: Orlando Gutierrez | O16: 0 | P16: Francisco Javier | Q16: Yahir Barreda | R16: =IF(O16="","",F16-O16) -> 175 | S16: =IF(G16="","Pendiente",IF(K16=Carga_Camiones!G16,"OK","Diferencia Placa")) -> Diferencia Placa
A17: 46182 | B17: 5644 | C17: Planta Huixquilucan | D17: =Carga_Camiones!M17 -> 0 | E17: 0.19791667 | F17: 175 | G17: 5644 | H17: Chamapa - Lecheria | I17: Cusum Huixquiluca | J17: Protocolo | K17: 17-AN-4C | L17: 14 | M17: Erick Gutierrez | O17: 0 | P17: Francisco Javier | Q17: Yahir Barreda | R17: =IF(O17="","",F17-O17) -> 175 | S17: =IF(G17="","Pendiente",IF(K17=Carga_Camiones!G17,"OK","Diferencia Placa")) -> Diferencia Placa
A18: 46182 | B18: 5645 | C18: Planta Huixquilucan | D18: =Carga_Camiones!M18 -> 0 | E18: 0.2125 | F18: 175 | G18: 5645 | H18: Chamapa - Lecheria | I18: Cusum Huixquiluca | J18: Protocolo | K18: LF-41-892 | L18: 14 | M18: Lucio Bustamante | O18: 0 | P18: Francisco Javier | Q18: Yahir Barreda | R18: =IF(O18="","",F18-O18) -> 175 | S18: =IF(G18="","Pendiente",IF(K18=Carga_Camiones!G18,"OK","Diferencia Placa")) -> Diferencia Placa
A19: 46182 | B19: 5646 | C19: Planta Huixquilucan | D19: =Carga_Camiones!M19 -> 0 | E19: 0.22777778 | F19: 175 | G19: 5646 | H19: Chamapa - Lecheria | I19: Cusum Huixquiluca | J19: Protocolo | K19: 43-BD-6C | L19: 14 | M19: Victor Gonzalez | O19: 0 | P19: Francisco Javier | Q19: Yahir Barreda | R19: =IF(O19="","",F19-O19) -> 175 | S19: =IF(G19="","Pendiente",IF(K19=Carga_Camiones!G19,"OK","Diferencia Placa")) -> Diferencia Placa
A20: 46185 | B20: 5680 | C20: Planta Huixquilucan | D20: =Carga_Camiones!M20 -> 0 | E20: =Carga_Camiones!N20 -> 0 | F20: 175 | G20: 5680 | H20: México-Toluca | I20: Cusum Huixquiluca | J20: Marshall | K20: LD58235 | L20: 14 | M20: Cortes Guadarrama | O20: 0 | P20: Francisco Javier | Q20: Yahir Barreda | R20: =IF(O20="","",F20-O20) -> 175 | S20: =IF(G20="","Pendiente",IF(K20=Carga_Camiones!G20,"OK","Diferencia Placa")) -> Diferencia Placa
A21: 46185 | B21: 5681 | C21: Planta Huixquilucan | D21: =Carga_Camiones!M21 -> 0 | E21: =Carga_Camiones!N21 -> 0 | F21: 175 | G21: 5681 | H21: México-Toluca | I21: Cusum Huixquiluca | J21: Marshall | K21: 22BC9R | L21: 14 | M21: David | O21: 0 | P21: Francisco Javier | Q21: Yahir Barreda | R21: =IF(O21="","",F21-O21) -> 175 | S21: =IF(G21="","Pendiente",IF(K21=Carga_Camiones!G21,"OK","Diferencia Placa")) -> Diferencia Placa
A22: 46185 | B22: 5686 | C22: Planta Huixquilucan | D22: =Carga_Camiones!M22 -> 0 | E22: 0.55486111 | F22: 175 | G22: 5686 | H22: México-Toluca | I22: Cusum Huixquiluca | J22: Marshall | K22: MY7967B | L22: 14 | M22: Enrique Torres | N22: 0.60416667 | O22: 0 | P22: Francisco Javier | Q22: Yahir Barreda | R22: =IF(O22="","",F22-O22) -> 175 | S22: =IF(G22="","Pendiente",IF(K22=Carga_Camiones!G22,"OK","Diferencia Placa")) -> Diferencia Placa
A23: 46185 | B23: 5685 | C23: Planta Huixquilucan | D23: =Carga_Camiones!M23 -> 0 | E23: 0.53888889 | F23: 175 | G23: 5685 | H23: México-Toluca | I23: Cusum Huixquiluca | J23: Marshall | K23: NR.0950-C | L23: 14 | M23: Alejandro Flores | N23: 0.625 | O23: 0 | P23: Francisco Javier | Q23: Yahir Barreda | R23: =IF(O23="","",F23-O23) -> 175 | S23: =IF(G23="","Pendiente",IF(K23=Carga_Camiones!G23,"OK","Diferencia Placa")) -> Diferencia Placa
A24: 46185 | B24: 5687 | C24: Planta Huixquilucan | D24: =Carga_Camiones!M24 -> 0 | E24: 0.56944444 | F24: 175 | G24: 5687 | H24: México-Toluca | I24: Cusum Huixquiluca | J24: Marshall | K24: NB1255P | L24: 14 | M24: Santos Sotero | N24: 0.64583333 | O24: 0 | P24: Francisco Javier | Q24: Yahir Barreda | R24: =IF(O24="","",F24-O24) -> 175 | S24: =IF(G24="","Pendiente",IF(K24=Carga_Camiones!G24,"OK","Diferencia Placa")) -> Diferencia Placa
A25: 46185 | B25: 5688 | C25: Planta Huixquilucan | D25: =Carga_Camiones!M25 -> 0 | E25: 0.58541667 | F25: 175 | G25: 5688 | H25: México-Toluca | I25: Cusum Huixquiluca | J25: Marshall | K25: MY7967B | L25: 14 | M25: Jorge Garcia | N25: 0.66875 | O25: 0 | P25: Francisco Javier | Q25: Yahir Barreda | R25: =IF(O25="","",F25-O25) -> 175 | S25: =IF(G25="","Pendiente",IF(K25=Carga_Camiones!G25,"OK","Diferencia Placa")) -> Diferencia Placa
A26: 46185 | B26: 5684 | C26: Planta Huixquilucan | D26: =Carga_Camiones!M26 -> 0 | E26: 0.52222222 | F26: 175 | G26: 5684 | H26: México-Toluca | I26: Cusum Huixquiluca | J26: Marshall | K26: 11D-57-440 | L26: 14 | M26: Ramiro Hernandez | N26: 0.70972222 | O26: 0 | P26: Francisco Javier | Q26: Yahir Barreda | R26: =IF(O26="","",F26-O26) -> 175 | S26: =IF(G26="","Pendiente",IF(K26=Carga_Camiones!G26,"OK","Diferencia Placa")) -> Diferencia Placa
A27: 46185 | B27: 5683 | C27: Planta Huixquilucan | D27: =Carga_Camiones!M27 -> 0 | E27: 0.50694444 | F27: 175 | G27: 5683 | H27: México-Toluca | I27: Cusum Huixquiluca | J27: Marshall | K27: 11C-4281-J | L27: 14 | N27: 0.71527778 | O27: 0 | P27: Francisco Javier | Q27: Yahir Barreda | R27: =IF(O27="","",F27-O27) -> 175 | S27: =IF(G27="","Pendiente",IF(K27=Carga_Camiones!G27,"OK","Diferencia Placa")) -> Diferencia Placa
A28: 46183 | B28: 55537 | C28: Planta Toluca | D28: 23960 | E28: 0.51388889 | F28: 175 | G28: 42 | H28: Lerma - Tres Marías | J28: Mezcla Preparada Caliente N.3 | K28: 52BM3K | L28: 14 | M28: Mauricio Hernandez | N28: 0.55555556 | O28: 0 | P28: Apolinar | Q28: Citlalli C.M | R28: =IF(O28="","",F28-O28) -> 175 | S28: =IF(G28="","Pendiente",IF(K28=Carga_Camiones!G28,"OK","Diferencia Placa")) -> Diferencia Placa
A29: 46183 | B29: =Carga_Camiones!B29 -> 0 | D29: =Carga_Camiones!M29 -> 0 | E29: =Carga_Camiones!N29 -> 0 | F29: =Carga_Camiones!O29 -> 0 | R29: =IF(O29="","",F29-O29) | S29: =IF(G29="","Pendiente",IF(K29=Carga_Camiones!G29,"OK","Diferencia Placa")) -> Pendiente
A30: 46172 | B30: 4971 | C30: Planta Huixquilucan | D30: =Carga_Camiones!M30 -> 0 | E30: =Carga_Camiones!N30 -> 0 | F30: =Carga_Camiones!O30 -> 0 | G30: 4971 | H30: Kartodromo | I30: Cusum Huixquilucan | J30: Base Hidraulica | K30: 119AJ3 | L30: 14 | M30: Bernabe Gutierrez | R30: =IF(O30="","",F30-O30) | S30: =IF(G30="","Pendiente",IF(K30=Carga_Camiones!G30,"OK","Diferencia Placa")) -> Diferencia Placa
A31: 46172 | B31: 4973 | C31: Planta Huixquilucan | D31: =Carga_Camiones!M31 -> 0 | E31: =Carga_Camiones!N31 -> 0 | F31: =Carga_Camiones!O31 -> 0 | G31: 4973 | H31: Kartodromo | I31: Cusum Huixquilucan | J31: Base Hidraulica | K31: 119AJ3 | L31: 14 | M31: Bernabe Gutierrez | R31: =IF(O31="","",F31-O31) | S31: =IF(G31="","Pendiente",IF(K31=Carga_Camiones!G31,"OK","Diferencia Placa")) -> Diferencia Placa
A32: 46172 | B32: 4974 | C32: Planta Huixquilucan | D32: =Carga_Camiones!M32 -> 0 | E32: =Carga_Camiones!N32 -> 0 | F32: =Carga_Camiones!O32 -> 0 | G32: 4974 | H32: Kartodromo | I32: Cusum Huixquilucan | J32: Base Hidraulica | K32: 119AJ3 | L32: 14 | M32: | | R32: =IF(O32="","",F32-O32) | S32: =IF(G32="","Pendiente",IF(K32=Carga_Camiones!G32,"OK","Diferencia Placa")) -> Diferencia Placa
A33: 46174 | B33: 4975 | C33: Planta Huixquilucan | D33: =Carga_Camiones!M33 -> 0 | E33: =Carga_Camiones!N33 -> 0 | F33: =Carga_Camiones!O33 -> 0 | G33: 4975 | H33: Kartodromo | I33: Cusum Huixquilucan | J33: sma | K33: 02BG7J | L33: 15 | M33: Cesar gutierrez | N33: 0.34930556 | R33: =IF(O33="","",F33-O33) | S33: =IF(G33="","Pendiente",IF(K33=Carga_Camiones!G33,"OK","Diferencia Placa")) -> Diferencia Placa
A34: 46174 | B34: 4976 | C34: Planta Huixquilucan | D34: =Carga_Camiones!M34 -> 0 | E34: =Carga_Camiones!N34 -> 0 | F34: =Carga_Camiones!O34 -> 0 | G34: 4976 | H34: Kartodromo | I34: Cusum Huixquilucan | J34: sma | K34: 70BH10 | L34: 15 | M34: Isac Lopez | N34: 0.36319444 | R34: =IF(O34="","",F34-O34) | S34: =IF(G34="","Pendiente",IF(K34=Carga_Camiones!G34,"OK","Diferencia Placa")) -> Diferencia Placa
A35: 46174 | B35: 4977 | C35: Planta Huixquilucan | D35: =Carga_Camiones!M35 -> 0 | E35: =Carga_Camiones!N35 -> 0 | F35: =Carga_Camiones!O35 -> 0 | G35: 4977 | H35: Kartodromo | I35: Cusum Huixquilucan | J35: sma | K35: 98BM8p | L35: 15 | M35: Bernabe Gutierrez | N35: 0.37708333 | R35: =IF(O35="","",F35-O35) | S35: =IF(G35="","Pendiente",IF(K35=Carga_Camiones!G35,"OK","Diferencia Placa")) -> Diferencia Placa
A36: 46174 | B36: 4978 | C36: Planta Huixquilucan | D36: =Carga_Camiones!M36 -> 0 | E36: =Carga_Camiones!N36 -> 0 | F36: =Carga_Camiones!O36 -> 0 | G36: 4978 | H36: Kartodromo | I36: Cusum Huixquilucan | J36: sma | K36: NV17287 | L36: 15 | M36: Eduardo Gonzalez | N36: 0.39027778 | R36: =IF(O36="","",F36-O36) | S36: =IF(G36="","Pendiente",IF(K36=Carga_Camiones!G36,"OK","Diferencia Placa")) -> Diferencia Placa
A37: 46175 | B37: 4996 | C37: Planta Huixquilucan | D37: =Carga_Camiones!M37 -> 0 | E37: =Carga_Camiones!N37 -> 0 | F37: =Carga_Camiones!O37 -> 0 | G37: 4996 | H37: Kartodromo | I37: Cusum Huixquilucan | J37: sma | K37: 98BM8P | L37: 15 | M37: Bernabe Gutierrez | N37: 0.48611111 | R37: =IF(O37="","",F37-O37) | S37: =IF(G37="","Pendiente",IF(K37=Carga_Camiones!G37,"OK","Diferencia Placa")) -> Diferencia Placa
A38: 46175 | B38: 4997 | C38: Planta Huixquilucan | D38: =Carga_Camiones!M38 -> 0 | E38: =Carga_Camiones!N38 -> 0 | F38: =Carga_Camiones!O38 -> 0 | G38: 4997 | H38: Kartodromo | I38: Cusum Huixquilucan | J38: sma | K38: HF50814 | L38: 7 | M38: Jose Angel | N38: 0.49305556 | R38: =IF(O38="","",F38-O38) | S38: =IF(G38="","Pendiente",IF(K38=Carga_Camiones!G38,"OK","Diferencia Placa")) -> Diferencia Placa
A39: 46175 | B39: 4998 | C39: Planta Huixquilucan | D39: =Carga_Camiones!M39 -> 0 | E39: =Carga_Camiones!N39 -> 0 | F39: =Carga_Camiones!O39 -> 0 | G39: 49998 | H39: Kartodromo | I39: Cusum Huixquilucan | J39: sma | K39: LC45753 | L39: 15 | M39: Cesar Granados | N39: 0.50555556 | R39: =IF(O39="","",F39-O39) | S39: =IF(G39="","Pendiente",IF(K39=Carga_Camiones!G39,"OK","Diferencia Placa")) -> Diferencia Placa
A40: 46175 | B40: 4999 | C40: Planta Huixquilucan | D40: =Carga_Camiones!M40 -> 0 | E40: =Carga_Camiones!N40 -> 0 | F40: =Carga_Camiones!O40 -> 0 | G40: 4999 | H40: Kartodromo | I40: Cusum Huixquilucan | J40: sma | K40: 73BGLU | L40: 15 | M40: Ricardo Pedrazo | N40: 0.51805556 | R40: =IF(O40="","",F40-O40) | S40: =IF(G40="","Pendiente",IF(K40=Carga_Camiones!G40,"OK","Diferencia Placa")) -> Diferencia Placa
A41: 46175 | B41: 5000 | C41: Planta Huixquilucan | D41: =Carga_Camiones!M41 -> 0 | E41: =Carga_Camiones!N41 -> 0 | F41: =Carga_Camiones!O41 -> 0 | G41: 5000 | H41: Kartodromo | I41: Cusum Huixquilucan | J41: sma | K41: 17AN4C | L41: 15 | M41: Erick Gutierrez | N41: 0.53194444 | R41: =IF(O41="","",F41-O41) | S41: =IF(G41="","Pendiente",IF(K41=Carga_Camiones!G41,"OK","Diferencia Placa")) -> Diferencia Placa
...

Sheet Control_Fresado
A1: GC-MAT-003 | CONTROL DE RETORNO Y REGISTRO DE FRESADO DE OBRA (POR CAPACIDAD)
A2: Responsable: | E2: Obra Origen: | F2: Todas | H2: Fecha Reporte:
A4: Fecha | B4: No. | C4: Folio Nota (Trujano) | D4: Obra Origen | E4: Sindicato | F4: Material | G4: Placas del Vehículo | H4: Capacidad (m³) | I4: Operador | J4: Hora de Salida | K4: Hora de Llegada | L4: Encargado de Obra | M4: Checador | N4: Destino (Planta/Acopio) | O4: Observaciones
A5: 2026-06-08 | B5: 1 | C5: 5872 | D5: Chamapa-Lechería | E5: cosum | F5: FRESADO | G5: NS-1640-C | H5: 14 | I5: Orlando Gutierrez | J5: 10:53 pm | K5: 10:46 pm | L5: Ing. Javier Perez | M5: Yahir Barreda | N5: Planta Huixquilucan | O5: Viaje nocturno reportado por checador
A6: 2026-06-08 | B6: 2 | C6: 5872 | D6: Chamapa-Lechería | E6: cosum | F6: FRESADO | G6: NS-1640-C | H6: 14 | I6: Orlando Gutierrez | J6: 22:53:00 | K6: 22:46:00 | L6: Francisco Javier | M6: Yahir Barreda | N6: Planta Huixquilucan | O6: Viaje nocturno reportado por checador
A7: 2026-06-08 | B7: 3 | C7: 5873 | D7: Chamapa-Lechería | E7: cosum | F7: FRESADO | G7: LG-01-321 | H7: 14 | I7: Julio Resendiz | J7: 23:14:00 | K7: 23:07:00 | L7: Francisco Javier | M7: Yahir Barreda | N7: Planta Huixquilucan
A8: 2026-06-08 | B8: 4 | C8: 5874 | D8: Chamapa-Lechería | E8: cosum | F8: FRESADO | G8: LF-41-892 | H8: 14 | I8: Lucio Gustamante | J8: 23:21:00 | K8: 23:15:00 | L8: Francisco Javier | M8: Yahir Barreda | N8: Planta Huixquilucan
A9: 2026-06-08 | B9: 5 | C9: 5875 | D9: Chamapa-Lechería | E9: cosum | F9: FRESADO | G9: 17-AN4C | H9: 14 | I9: Erick Gutierrez | J9: 23:28:00 | K9: 23:22:00 | L9: Francisco Javier | M9: Yahir Barreda | N9: Planta Huixquilucan
A10: 2026-06-08 | B10: 6 | C10: 5876 | D10: Chamapa-Lechería | E10: cosum | F10: FRESADO | G10: NS-1640-C | H10: 14 | I10: Orlando Gutierrez | J10: 23:47:00 | K10: 23:39:00 | L10: Francisco Javier | M10: Yahir Barreda | N10: Planta Huixquilucan
A11: 2026-06-08 | B11: 7 | C11: 5877 | D11: Chamapa-Lechería | E11: cosum | F11: FRESADO | G11: LG-01-321 | H11: 14 | I11: Julio Resendiz | J11: 23:56:00 | K11: 23:48:00 | L11: Francisco Javier | M11: Yahir Barreda | N11: Planta Huixquilucan
A12: 2026-06-08 | B12: 8 | C12: 5878 | D12: Chamapa-Lechería | E12: cosum | F12: FRESADO | G12: LF-41-892 | H12: 14 | I12: Lucio Gustamante | J12: 00:02:00 | K12: 23:56:00 | L12: Francisco Javier | M12: Yahir Barreda | N12: Planta Huixquilucan
A13: 2026-06-08 | B13: 9 | C13: 5879 | D13: Chamapa-Lechería | E13: cosum | F13: FRESADO | G13: 17-AN4C | H13: 14 | I13: Erick Gutierrez | J13: 00:11:00 | K13: 00:02:00 | L13: Francisco Javier | M13: Yahir Barreda | N13: Planta Huixquilucan
A14: 2026-06-08 | B14: 10 | C14: 5880 | D14: Chamapa-Lechería | E14: cosum | F14: FRESADO | G14: NS-1640-C | H14: 14 | I14: Orlando Gutierrez | J14: 00:21:00 | K14: 00:13:00 | L14: Francisco Javier | M14: Yahir Barreda | N14: Planta Huixquilucan
A15: 2026-06-08 | B15: 11 | C15: 5881 | D15: Chamapa-Lechería | E15: cosum | F15: FRESADO | G15: LG-01-321 | H15: 14 | I15: Julio Resendiz | J15: 00:26:00 | K15: 00:21:00 | L15: Francisco Javier | M15: Yahir Barreda | N15: Planta Huixquilucan
A16: 2026-06-08 | B16: 12 | C16: 5882 | D16: Chamapa-Lechería | E16: cosum | F16: FRESADO | G16: LF-41-892 | H16: 14 | I16: Lucio Gustamante | J16: 00:33:00 | K16: 00:27:00 | L16: Francisco Javier | M16: Yahir Barreda | N16: Planta Huixquilucan
A17: 2026-06-08 | B17: 13 | C17: 5883 | D17: Chamapa-Lechería | E17: cosum | F17: FRESADO | G17: 17-AN4C | H17: 14 | I17: Erick Gutierrez | J17: 00:41:00 | K17: 00:35:00 | L17: Francisco Javier | M17: Yahir Barreda | N17: Planta Huixquilucan
A18: 2026-06-08 | B18: 14 | C18: 5884 | D18: Chamapa-Lechería | E18: cosum | F18: FRESADO | G18: NS-1640-C | H18: 14 | I18: Orlando Gutierrez | J18: 00:59:00 | K18: 00:44:00 | L18: Francisco Javier | M18: Yahir Barreda | N18: Planta Huixquilucan
... A23: 2026-06-08 | B23: 19 | C23: 5889 | D23: Chamapa-Lechería | E23: cosum | F23: FRESADO | G23: LF-41-892 | H23: 14 | I23: Lucio Gustamante | J23: 01:46:00 | K23: 01:41:00 | L23: Francisco Javier | M23: Yahir Barreda | N23: Planta Huixquilucan
A24: 46182 | B24: 20 | C24: 5894 | D24: Chamapa-Lechería | E24: cosum | F24: FRESADO | G24: NS-1640-C | H24: 14 | I24: Orlando Gutierrez | J24: 0.91805556 | K24: 0.91319444 | L24: Francisco Javier | M24: Yahir Barreda | N24: Planta Huixquilucan
A25: 46182 | B25: 21 | C25: 5895 | D25: Chamapa-Lechería | E25: cosum | F25: FRESADO | G25: LG-01-321 | H25: 14 | I25: Julio Resendiz | J25: 0.92430556 | K25: 0.91875 | L25: Francisco Javier | M25: Yahir Barreda | N25: Planta Huixquilucan
A26: 46182 | B26: 22 | C26: 5896 | D26: Chamapa-Lechería | E26: cosum | F26: FRESADO | G26: 43-BD-6E | H26: 14 | I26: Victor Gonzalez | J26: 0.92847222 | K26: 0.925 | L26: Francisco Javier | M26: Yahir Barreda | N26: Planta Huixquilucan
A27: 46182 | B27: 23 | C27: 5898 | D27: Chamapa-Lechería | E27: cosum | F27: FRESADO | G27: 120-AJ-3 | H27: 14 | I27: Cesar Gutierrez | J27: 0.93402778 | K27: 0.92916667 | L27: Francisco Javier | M27: Yahir Barreda | N27: Planta Huixquilucan
A28: 46182 | B28: 24 | C28: 5899 | D28: Chamapa-Lechería | E28: cosum | F28: FRESADO | G28: NS-1640-C | H28: 14 | I28: Orlando Gutierrez | J28: 0.94236111 | K28: 0.93819444 | L28: Francisco Javier | M28: Yahir Barreda | N28: Planta Huixquilucan
A29: 46182 | B29: 25 | C29: 5900 | D29: Chamapa-Lechería | E29: cosum | F29: FRESADO | G29: LG-01-321 | H29: 14 | I29: Julio Resendiz | J29: 0.94930556 | K29: 0.94513889 | L29: Francisco Javier | M29: Yahir Barreda | N29: Planta Huixquilucan
A30: 46182 | B30: 26 | C30: 501 | D30: Chamapa-Lechería | E30: cosum | F30: FRESADO | G30: 120-AJ-3 | H30: 14 | I30: Cesar Gutierrez | J30: 0.95347222 | K30: 0.95 | L30: Francisco Javier | M30: Yahir Barreda | N30: Planta Huixquilucan
A31: 46182 | B31: 27 | C31: 502 | D31: Chamapa-Lechería | E31: cosum | F31: FRESADO | G31: 43-BD-6E | H31: 14 | I31: Victor Gonzalez | J31: 0.95763889 | K31: 0.95416667 | L31: Francisco Javier | M31: Yahir Barreda | N31: Planta Huixquilucan
A32: 46182 | B32: 28 | C32: 503 | D32: Chamapa-Lechería | E32: cosum | F32: FRESADO | G32: NS-1640-C | H32: 14 | I32: Orlando Gutierrez | J32: 0.96319444 | K32: 0.95902778 | L32: Francisco Javier | M32: Yahir Barreda | N32: Planta Huixquilucan
A33: 46182 | B33: 29 | C33: 504 | D33: Chamapa-Lechería | E33: cosum | F33: FRESADO | G33: LG-01-321 | H33: 14 | I33: Julio Resendiz | J33: 0.97152778 | K33: 0.96805556 | L33: Francisco Javier | M33: Yahir Barreda | N33: Planta Huixquilucan
A34: 46182 | B34: 30 | C34: 505 | D34: Chamapa-Lechería | E34: cosum | F34: FRESADO | G34: 120-AJ-3 | H34: 14 | I34: Cesar Gutierrez | J34: 0.97847222 | K34: 0.97222222 | L34: Francisco Javier | M34: Yahir Barreda | N34: Planta Huixquilucan
A35: 46182 | B35: 31 | C35: 506 | D35: Chamapa-Lechería | E35: cosum | F35: FRESADO | G35: 43-BD-6E | H35: 14 | I35: Victor Gonzalez | J35: 0.98472222 | K35: 0.97916667 | L35: Francisco Javier | M35: Yahir Barreda | N35: Planta Huixquilucan
... A41: 46182 | B41: 37 | C41: 513 | D41: Chamapa-Lechería | E41: cosum | F41: FRESADO | G41: LG-01-321 | H41: 14 | I41: Julio Resendiz | J41: 0.053472222 | K41: 0.041666667 | L41: Francisco Javier | M41: Yahir Barreda | N41: Planta Huixquilucan
A42: 46182 | B42: 38 | C42: 514 | D42: Chamapa-Lechería | E42: cosum | F42: FRESADO | G42: 120-AJ-3 | H42: 14 | I42: Cesar Gutierrez | J42: 0.0625 | K42: 0.054166667 | L42: Francisco Javier | M42: Yahir Barreda | N42: Planta Huixquilucan | O42: Viaje en Falso
A43: 46183 | B43: 39 | C43: 5438 | D43: Lerma - Tres Marías | E43: Emulsiones y Asfaltos Jorge | F43: FRESADO | G43: 74-BK-2U | H43: 14 | I43: Eduardo Castillo | J43: 0.3625 | K43: 0.33333333 | L43: Apolinar | M43: Citlalli I.M.
A44: 46183 | B44: 40 | C44: 5439 | D44: Lerma - Tres Marías | E44: Emulsiones y Asfaltos Jorge | F44: FRESADO | G44: HB-4926-H | H44: 14 | I44: Cirino Garcia | K44: 0.33333333 | L44: Apolinar | M44: Citlalli I.M.
A45: 46183 | B45: 41 | C45: 5440 | D45: Lerma - Tres Marías | E45: Emulsiones y Asfaltos Jorge | F45: FRESADO | G45: NT-2314-C | H45: 14 | I45: Geovani Contreras | J45: 0.38888889 | K45: 0.375 | L45: Apolinar | M45: Citlalli I.M.
A46: 46183 | B46: 42 | C46: 5441 | D46: Lerma - Tres Marías | E46: Emulsiones y Asfaltos Jorge | F46: FRESADO | G46: NH-8962-O | H46: 14 | I46: Alexis Malvaes | K46: 0.33333333 | L46: Apolinar | M46: Citlalli I.M.
A47: 46183 | B47: 43 | C47: 5442 | D47: Lerma - Tres Marías | E47: Emulsiones y Asfaltos Jorge | F47: FRESADO | G47: 74-BK-2U | H47: 14 | I47: Eduardo Castillo | K47: 0.33333333 | L47: Apolinar | M47: Citlalli I.M.
A48: 46183 | B48: 44 | C48: 5443 | D48: Lerma - Tres Marías | E48: Emulsiones y Asfaltos Jorge | F48: FRESADO | G48: HB-4926-H | H48: 14 | I48: Cirino Garcia | K48: 0.33333333 | L48: Apolinar | M48: Citlalli I.M.
A49: 46183 | B49: 45 | C49: 5444 | D49: Lerma - Tres Marías | E49: Emulsiones y Asfaltos Jorge | F49: FRESADO | G49: NT-2314-C | H49: 14 | I49: Geovani Contreras | K49: 0.33333333 | L49: Apolinar | M49: Citlalli I.M.
A50: 46183 | B50: 46 | C50: 5445 | D50: Lerma - Tres Marías | E50: Emulsiones y Asfaltos Jorge | F50: FRESADO | G50: NH-8962-O | H50: 14 | I50: Alexis Malvaes | K50: 0.33333333 | L50: Apolinar | M50: Citlalli I.M.
...

Sheet Catalogos
A1: CATÁLOGOS OFICIALES - CONTROL DE MATERIALES, MEZCLA Y FRESADO
A3: Código Obra | B3: Nombre de Obra | C3: Ingeniero Responsable | E3: Código Planta | F3: Planta Origen | H3: Código Material | I3: Descripción del Material | K3: Código Planta | L3: Sindicato
A4: MT | B4: México-Toluca | C4: Samuel Ortega | E4: TOL | F4: Planta Toluca | H4: MC3 | I4: Mezcla Preparada Caliente N.3 | K4: CHUI | L4: Cusum Huixquilucan
A5: L3M | B5: Lerma - Tres Marías | C5: Apolinar | E5: HUI | F5: Planta Huixquilucan | H5: MA | I5: Mezcla Asfáltica | K5: CTOL | L5: Cusum Toluca
A6: LT | B6: Lerma - Toluca | C6: Carlos Valdes | H6: FR | I6: Fresado | L6: Emulsiones y Asfaltos Jorge
A7: CL | B7: Chamapa-Lechería | C7: Francisco Javier | H7: ASF | I7: Asfalto
A8: BT | B8: Bacheo Toluca | C8: Diego Carreola | H8: CD | I8: Carpeta Densa
B9: Kartodromo | I9: Protocolo
I10: Marshall
I11: Base Hidraulica
I12: sma
A29: Cosum toluca | B29: mezcla asfaltica | C29: 3350

Sheet Instrucciones
A1: PROCEDIMIENTO OPERATIVO - CONTROL DE MATERIALES
A3: Paso | B3: Responsable | C3: Descripción de la Actividad
A4: 1 | B4: Operador de Camión | C4: Al cargar mezcla en planta, solicita ticket de báscula y remisión JDJ Asfaltos. Reporta por WhatsApp con foto.
A5: 2 | B5: Despachador / Capturista | C5: Registra la mezcla cargada en la pestaña 'Carga_Camiones'. Los pesos Bruto y Tara se ingresan y el Peso Neto se calcula solo.
A6: 3 | B6: Residente de Obra / Checador | C6: Al recibir el camión de mezcla en la obra, llena la nota rosa de 'Grupo Trujano' anotando la hora de llegada, temperatura de la mezcla al tirar, placas, operador y firmas.
A7: 4 | B7: Despachador / Capturista | C7: Coteja lo enviado de planta vs lo recibido en obra en 'Cotejo_Mezcla'. La hoja cruzará automáticamente las placas y calculará la pérdida de temperatura de trayecto.
A8: 5 | B8: Checador / Residente | C8: Al cargar y despachar fresado (asfalto molido) desde la obra, llena la nota de 'Grupo Trujano' con la capacidad del camión (m³), placas, horas y firmas.
A9: 6 | B9: Despachador / Capturista | C9: Registra las salidas de fresado en la pestaña 'Control_Fresado'. No requiere pesos de báscula; el control de volumen se realiza mediante la capacidad del camión en m³ y los viajes completados.
