Workbook

Sheet Resumen_Saldos_Semanales
A1: GRUPO TRUJANO — CONTROL DE SALDOS Y SOLICITUDES DE DIÉSEL
A2: SEGUIMIENTO EN TIEMPO REAL: LÍMITE SEMANAL AUTORIZADO VS. CONSUMO / SOLICITADO
B4: AUTORIZADO TOTAL | C4: TOTAL SOLICITADO | D4: SALDO DISPONIBLE | E4: % EJECUTADO GLOBAL
B5: =SUM(C9:C21) -> 31200 | C5: =SUM(D9:D21) -> 3786 | D5: =SUM(E9:E21) -> 27414 | E5: =IF(B5>0, C5/B5, 0) -> 0.12134615
A8: Obra / Frente de Trabajo | B8: Responsable de Obra | C8: Límite Autorizado (Lts) | D8: Litros Solicitados (Lts) | E8: Saldo Disponible (Lts) | F8: % Utilizado | G8: Estatus / Alerta
A9: México - Toluca | B9: Francisco Javier | C9: 5000 | D9: 2836 | E9: =C9-D9 -> 2164 | F9: =IF(C9>0, D9/C9, 0) -> 0.5672 | G9: =IF(E9<0, "⚠️ EXCEDIDO", IF(F9>=0.8, "⚡ POR AGOTAR", "✅ DISPONIBLE")) -> ✅ DISPONIBLE
A10: Lerma - Tres Marías | B10: Apolinar | C10: 3500 | D10: =SUMIFS(Captura_Solicitudes!E:E, Captura_Solicitudes!C:C, A10) -> 0 | E10: =C10-D10 -> 3500 | F10: =IF(C10>0, D10/C10, 0) -> 0 | G10: =IF(E10<0, "⚠️ EXCEDIDO", IF(F10>=0.8, "⚡ POR AGOTAR", "✅ DISPONIBLE")) -> ✅ DISPONIBLE
A11: Chamapa - Lechería | B11: Sin responsable | C11: 2500 | D11: =SUMIFS(Captura_Solicitudes!E:E, Captura_Solicitudes!C:C, A11) -> 0 | E11: =C11-D11 -> 2500 | F11: =IF(C11>0, D11/C11, 0) -> 0 | G11: =IF(E11<0, "⚠️ EXCEDIDO", IF(F11>=0.8, "⚡ POR AGOTAR", "✅ DISPONIBLE")) -> ✅ DISPONIBLE
A12: Bacheo Toluca | B12: Diego Carreola | C12: 2000 | D12: =SUMIFS(Captura_Solicitudes!E:E, Captura_Solicitudes!C:C, A12) -> 0 | E12: =C12-D12 -> 2000 | F12: =IF(C12>0, D12/C12, 0) -> 0 | G12: =IF(E12<0, "⚠️ EXCEDIDO", IF(F12>=0.8, "⚡ POR AGOTAR", "✅ DISPONIBLE")) -> ✅ DISPONIBLE
A13: Planta Huixquilucan | B13: Luis | C13: 4000 | D13: =SUMIFS(Captura_Solicitudes!E:E, Captura_Solicitudes!C:C, A13) -> 0 | E13: =C13-D13 -> 4000 | F13: =IF(C13>0, D13/C13, 0) -> 0 | G13: =IF(E13<0, "⚠️ EXCEDIDO", IF(F13>=0.8, "⚡ POR AGOTAR", "✅ DISPONIBLE")) -> ✅ DISPONIBLE
A14: Planta Pegaso | B14: Jack | C14: 3000 | D14: =SUMIFS(Captura_Solicitudes!E:E, Captura_Solicitudes!C:C, A14) -> 0 | E14: =C14-D14 -> 3000 | F14: =IF(C14>0, D14/C14, 0) -> 0 | G14: =IF(E14<0, "⚠️ EXCEDIDO", IF(F14>=0.8, "⚡ POR AGOTAR", "✅ DISPONIBLE")) -> ✅ DISPONIBLE
A15: Desasolve | B15: Diego Carreola | C15: 1200 | D15: =SUMIFS(Captura_Solicitudes!E:E, Captura_Solicitudes!C:C, A15) -> 950 | E15: =C15-D15 -> 250 | F15: =IF(C15>0, D15/C15, 0) -> 0.79166667 | G15: =IF(E15<0, "⚠️ EXCEDIDO", IF(F15>=0.8, "⚡ POR AGOTAR", "✅ DISPONIBLE")) -> ✅ DISPONIBLE
A16: Providencia | B16: Samuel | C16: 1500 | D16: =SUMIFS(Captura_Solicitudes!E:E, Captura_Solicitudes!C:C, A16) -> 0 | E16: =C16-D16 -> 1500 | F16: =IF(C16>0, D16/C16, 0) -> 0 | G16: =IF(E16<0, "⚠️ EXCEDIDO", IF(F16>=0.8, "⚡ POR AGOTAR", "✅ DISPONIBLE")) -> ✅ DISPONIBLE
A17: Alfredo del Mazo | B17: Variable | C17: 2500 | D17: =SUMIFS(Captura_Solicitudes!E:E, Captura_Solicitudes!C:C, A17) -> 0 | E17: =C17-D17 -> 2500 | F17: =IF(C17>0, D17/C17, 0) -> 0 | G17: =IF(E17<0, "⚠️ EXCEDIDO", IF(F17>=0.8, "⚡ POR AGOTAR", "✅ DISPONIBLE")) -> ✅ DISPONIBLE
A18: Colegio Militar | B18: Apolinar | C18: 1500 | D18: =SUMIFS(Captura_Solicitudes!E:E, Captura_Solicitudes!C:C, A18) -> 0 | E18: =C18-D18 -> 1500 | F18: =IF(C18>0, D18/C18, 0) -> 0 | G18: =IF(E18<0, "⚠️ EXCEDIDO", IF(F18>=0.8, "⚡ POR AGOTAR", "✅ DISPONIBLE")) -> ✅ DISPONIBLE
A19: Explanada Damián Carmona | B19: Sin responsable | C19: 1500 | D19: =SUMIFS(Captura_Solicitudes!E:E, Captura_Solicitudes!C:C, A19) -> 0 | E19: =C19-D19 -> 1500 | F19: =IF(C19>0, D19/C19, 0) -> 0 | G19: =IF(E19<0, "⚠️ EXCEDIDO", IF(F19>=0.8, "⚡ POR AGOTAR", "✅ DISPONIBLE")) -> ✅ DISPONIBLE
A20: Calle Revolución y Calle Lerdo | B20: Sin responsable | C20: 1000 | D20: =SUMIFS(Captura_Solicitudes!E:E, Captura_Solicitudes!C:C, A20) -> 0 | E20: =C20-D20 -> 1000 | F20: =IF(C20>0, D20/C20, 0) -> 0 | G20: =IF(E20<0, "⚠️ EXCEDIDO", IF(F20>=0.8, "⚡ POR AGOTAR", "✅ DISPONIBLE")) -> ✅ DISPONIBLE
A21: Constitución | B21: Sin responsable | C21: 2000 | D21: =SUMIFS(Captura_Solicitudes!E:E, Captura_Solicitudes!C:C, A21) -> 0 | E21: =C21-D21 -> 2000 | F21: =IF(C21>0, D21/C21, 0) -> 0 | G21: =IF(E21<0, "⚠️ EXCEDIDO", IF(F21>=0.8, "⚡ POR AGOTAR", "✅ DISPONIBLE")) -> ✅ DISPONIBLE
A22: TOTAL GENERAL | C22: =SUM(C9:C21) -> 31200 | D22: =SUM(D9:D21) -> 3786 | E22: =SUM(E9:E21) -> 27414 | F22: =IF(C22>0, D22/C22, 0) -> 0.12134615

Sheet Catalogos
A1: LISTA DE OBRAS | B1: RESPONSABLE DEFAULT
A2: México - Toluca | B2: Francisco Javier
A3: Lerma - Tres Marías | B3: Apolinar
A4: Chamapa - Lechería | B4: Sin responsable
A5: Bacheo Toluca | B5: Diego Carreola
A6: Planta Huixquilucan | B6: Luis
A7: Planta Pegaso | B7: Jack
A8: Desasolve | B8: Diego Carreola
A9: Providencia | B9: Samuel
A10: Alfredo del Mazo | B10: Variable
A11: Colegio Militar | B11: Apolinar
D101: PCW G3-G1 | E101: RAM-700 PCW G3-G1
D102: PCW9238 | E102: Vehiculo PCW9238
D103: PCW9391 | E103: Vehiculo PCW9391
D104: PEG-01 | E104: Pickup Pegaso 1
D105: PEG-02 | E105: Pickup Pegaso 2
D106: PER-200 | E106: Perfiladora Wirtgen W-200
D107: PET-02 | E107: Petrolizadora
D108: PL-01 | E108: PAYLOADER
D109: PL-02 | E109: Payloder 644k
D110: PL-03 | E110: Payloder 930K
D111: PP-01 | E111: PIPA DE AGUA (IMPACTO 01) FORD None
D112: PR-01 | E112: PERFILADORA RODATEC RX600-4-4008
... D136: VOG-03 | E136: Pavimentadora Vögele-03

Sheet Captura_Solicitudes
A1: GRUPO TRUJANO — PROYECTO FÉNIX
A2: MÓDULO DE CAPTURA DIARIA DE SOLICITUDES DE DIÉSEL PARA OBRAS
A4: Folio Solicitud | B4: Fecha | C4: Obra / Frente Destino | D4: Responsable Obra | E4: Litros Solicitados | F4: Uso / Actividad | G4: Estatus | H4: Observaciones
A5: =IF(C5<>"", "SOL-2026-" & TEXT(13-4, "000"), "") -> SOL-2026-009 | B5: 46223 | C5: México - Toluca | D5: =VLOOKUP(C5,Catalogos!$A$2:$B$11,2,FALSE) -> Francisco Javier | E5: 500 | G5: Aprobado
A6: =IF(C6<>"", "SOL-2026-" & TEXT(14-4, "000"), "") -> SOL-2026-010 | B6: 2026-07-24 | C6: Desasolve | D6: =VLOOKUP(C6,Catalogos!$A$2:$B$11,2,FALSE) -> Diego Carreola | E6: 950 | G6: Pendiente
A7: =IF(C7<>"", "SOL-2026-" & TEXT(15-4, "000"), "") | B7: 2026-07-24 | D7: =VLOOKUP(C7,Catalogos!$A$2:$B$11,2,FALSE) -> #N/A | G7: Pendiente
A8: =IF(C8<>"", "SOL-2026-" & TEXT(16-4, "000"), "") | B8: 2026-07-24 | D8: =VLOOKUP(C8,Catalogos!$A$2:$B$11,2,FALSE) -> #N/A | G8: Pendiente
A9: =IF(C9<>"", "SOL-2026-" & TEXT(17-4, "000"), "") | B9: 2026-07-24 | D9: =VLOOKUP(C9,Catalogos!$A$2:$B$11,2,FALSE) -> #N/A | G9: Pendiente
A10: =IF(C10<>"", "SOL-2026-" & TEXT(18-4, "000"), "") | B10: 2026-07-24 | D10: =VLOOKUP(C10,Catalogos!$A$2:$B$11,2,FALSE) -> #N/A | G10: Pendiente
A11: =IF(C11<>"", "SOL-2026-" & TEXT(19-4, "000"), "") | B11: 2026-07-24 | D11: =VLOOKUP(C11,Catalogos!$A$2:$B$11,2,FALSE) -> #N/A | G11: Pendiente
A12: =IF(C12<>"", "SOL-2026-" & TEXT(20-4, "000"), "") | B12: 2026-07-24 | D12: =VLOOKUP(C12,Catalogos!$A$2:$B$11,2,FALSE) -> #N/A | G12: Pendiente
A13: =IF(C13<>"", "SOL-2026-" & TEXT(21-4, "000"), "") | B13: 2026-07-24 | D13: =VLOOKUP(C13,Catalogos!$A$2:$B$11,2,FALSE) -> #N/A | G13: Pendiente
A14: =IF(C14<>"", "SOL-2026-" & TEXT(22-4, "000"), "") | B14: 2026-07-24 | D14: =VLOOKUP(C14,Catalogos!$A$2:$B$11,2,FALSE) -> #N/A | G14: Pendiente
A15: =IF(C15<>"", "SOL-2026-" & TEXT(23-4, "000"), "") | B15: 2026-07-24 | D15: =VLOOKUP(C15,Catalogos!$A$2:$B$11,2,FALSE) -> #N/A | G15: Pendiente
A16: =IF(C16<>"", "SOL-2026-" & TEXT(24-4, "000"), "") | B16: 2026-07-24 | D16: =VLOOKUP(C16,Catalogos!$A$2:$B$11,2,FALSE) -> #N/A | G16: Pendiente
A17: =IF(C17<>"", "SOL-2026-" & TEXT(25-4, "000"), "") | B17: 2026-07-24 | D17: =VLOOKUP(C17,Catalogos!$A$2:$B$11,2,FALSE) -> #N/A | G17: Pendiente
A18: =IF(C18<>"", "SOL-2026-" & TEXT(26-4, "000"), "") | B18: 2026-07-24 | D18: =VLOOKUP(C18,Catalogos!$A$2:$B$11,2,FALSE) -> #N/A | G18: Pendiente
A19: =IF(C19<>"", "SOL-2026-" & TEXT(27-4, "000"), "") | B19: 2026-07-24 | D19: =VLOOKUP(C19,Catalogos!$A$2:$B$11,2,FALSE) -> #N/A | G19: Pendiente
A20: =IF(C20<>"", "SOL-2026-" & TEXT(28-4, "000"), "") | B20: 2026-07-24 | D20: =VLOOKUP(C20,Catalogos!$A$2:$B$11,2,FALSE) -> #N/A | G20: Pendiente
A21: =IF(C21<>"", "SOL-2026-" & TEXT(29-4, "000"), "") | B21: 2026-07-24 | D21: =VLOOKUP(C21,Catalogos!$A$2:$B$11,2,FALSE) -> #N/A | G21: Pendiente
A22: =IF(C22<>"", "SOL-2026-" & TEXT(30-4, "000"), "") | B22: 2026-07-24 | D22: =VLOOKUP(C22,Catalogos!$A$2:$B$11,2,FALSE) -> #N/A | G22: Pendiente
A23: =IF(C23<>"", "SOL-2026-" & TEXT(31-4, "000"), "") | B23: 2026-07-24 | D23: =VLOOKUP(C23,Catalogos!$A$2:$B$11,2,FALSE) -> #N/A | G23: Pendiente
A24: =IF(C24<>"", "SOL-2026-" & TEXT(32-4, "000"), "") | B24: 2026-07-24 | D24: =VLOOKUP(C24,Catalogos!$A$2:$B$11,2,FALSE) -> #N/A | G24: Pendiente
A25: =IF(C25<>"", "SOL-2026-" & TEXT(33-4, "000"), "") | B25: 2026-07-24 | D25: =VLOOKUP(C25,Catalogos!$A$2:$B$11,2,FALSE) -> #N/A | G25: Pendiente
A26: =IF(C26<>"", "SOL-2026-" & TEXT(34-4, "000"), "") | B26: 2026-07-24 | D26: =VLOOKUP(C26,Catalogos!$A$2:$B$11,2,FALSE) -> #N/A | G26: Pendiente
A27: =IF(C27<>"", "SOL-2026-" & TEXT(35-4, "000"), "") | B27: 2026-07-24 | D27: =VLOOKUP(C27,Catalogos!$A$2:$B$11,2,FALSE) -> #N/A | G27: Pendiente
A28: =IF(C28<>"", "SOL-2026-" & TEXT(36-4, "000"), "") | B28: 2026-07-24 | D28: =VLOOKUP(C28,Catalogos!$A$2:$B$11,2,FALSE) -> #N/A | G28: Pendiente
A29: =IF(C29<>"", "SOL-2026-" & TEXT(37-4, "000"), "") | B29: 2026-07-24 | D29: =VLOOKUP(C29,Catalogos!$A$2:$B$11,2,FALSE) -> #N/A | G29: Pendiente
A30: =IF(C30<>"", "SOL-2026-" & TEXT(38-4, "000"), "") | B30: 2026-07-24 | D30: =VLOOKUP(C30,Catalogos!$A$2:$B$11,2,FALSE) -> #N/A | G30: Pendiente
A31: =IF(C31<>"", "SOL-2026-" & TEXT(39-4, "000"), "") | B31: 2026-07-24 | D31: =VLOOKUP(C31,Catalogos!$A$2:$B$11,2,FALSE) -> #N/A | G31: Pendiente
A32: =IF(C32<>"", "SOL-2026-" & TEXT(40-4, "000"), "") | B32: 2026-07-24 | D32: =VLOOKUP(C32,Catalogos!$A$2:$B$11,2,FALSE) -> #N/A | G32: Pendiente
A33: =IF(C33<>"", "SOL-2026-" & TEXT(41-4, "000"), "") | B33: 2026-07-24 | D33: =VLOOKUP(C33,Catalogos!$A$2:$B$11,2,FALSE) -> #N/A | G33: Pendiente
A34: =IF(C34<>"", "SOL-2026-" & TEXT(42-4, "000"), "") | B34: 2026-07-24 | D34: =VLOOKUP(C34,Catalogos!$A$2:$B$11,2,FALSE) -> #N/A | G34: Pendiente
A35: =IF(C35<>"", "SOL-2026-" & TEXT(43-4, "000"), "") | B35: 2026-07-24 | D35: =VLOOKUP(C35,Catalogos!$A$2:$B$11,2,FALSE) -> #N/A | G35: Pendiente
A36: =IF(C36<>"", "SOL-2026-" & TEXT(44-4, "000"), "") | B36: 2026-07-24 | D36: =VLOOKUP(C36,Catalogos!$A$2:$B$11,2,FALSE) -> #N/A | G36: Pendiente
A37: =IF(C37<>"", "SOL-2026-" & TEXT(45-4, "000"), "") | B37: 2026-07-24 | D37: =VLOOKUP(C37,Catalogos!$A$2:$B$11,2,FALSE) -> #N/A | G37: Pendiente
A38: =IF(C38<>"", "SOL-2026-" & TEXT(46-4, "000"), "") | B38: 2026-07-24 | D38: =VLOOKUP(C38,Catalogos!$A$2:$B$11,2,FALSE) -> #N/A | G38: Pendiente
A39: =IF(C39<>"", "SOL-2026-" & TEXT(47-4, "000"), "") | B39: 2026-07-24 | D39: =VLOOKUP(C39,Catalogos!$A$2:$B$11,2,FALSE) -> #N/A | G39: Pendiente
A40: =IF(C40<>"", "SOL-2026-" & TEXT(48-4, "000"), "") | B40: 2026-07-24 | D40: =VLOOKUP(C40,Catalogos!$A$2:$B$11,2,FALSE) -> #N/A | G40: Pendiente
A41: =IF(C41<>"", "SOL-2026-" & TEXT(49-4, "000"), "") | B41: 2026-07-24 | D41: =VLOOKUP(C41,Catalogos!$A$2:$B$11,2,FALSE) -> #N/A | G41: Pendiente
...
