Workbook

Sheet Dashboard
A1: DASHBOARD EJECUTIVO DE CONTROL DE COMBUSTIBLE | GRUPO TRUJANO
A3: FILTROS DEL DASHBOARD (Celdas en amarillo editables en Excel)
B4: Obra Seleccionada: | C4: México-Toluca | E4: =IF(I28=0, "🟢 TODO COINCIDE (0 L)", "🔴 DISCREPANCIA: " & I28 & " L")
B5: Fecha Inicio (Lunes): | C5: 46195
B6: Fecha Fin (Rango): | C6: 46202
B7: Precio Diésel ($/L): | C7: 27
B8: Período Resumen: | C8: Semana Seleccionada
A10: COMPARATIVA: SOLICITADO (PETICIONES) VS ENTREGADO EN OBRA
A11: Día | B11: Fecha | C11: Lts Solicitados | D11: Lts Recibidos Obra | E11: Dif. Litros (Obra-Sol) | F11: Costo Solicitado | G11: Costo Real Obra | H11: Dif. Costo (Real-Sol)
A12: Lunes | B12: =C$5 | C12: =IF(C$4="Todas", SUMIFS(Solicitudes!F:F, Solicitudes!C:C, B12), SUMIFS(Solicitudes!F:F, Solicitudes!B:B, C$4, Solicitudes!C:C, B12)) | D12: =IF(C$4="Jalisco", SUMIFS(Captura_Jalisco!G:G, Captura_Jalisco!A:A, B12, Captura_Jalisco!B:B, "Salida"), IF(C$4="Todas", SUMIFS(Captura_Obra!F:F, Captura_Obra!A:A, B12) + SUMIFS(Captura_Jalisco!G:G, Captura_Jalisco!A:A, B12, Captura_Jalisco!B:B, "Salida"), SUMIFS(Captura_Obra!F:F, Captura_Obra!B:B, C$4, Captura_Obra!A:A, B12))) | E12: =D12-C12 | F12: =C12*C$7 | G12: =D12*C$7 | H12: =G12-F12
A13: Martes | B13: =B12+1 | C13: =IF(C$4="Todas", SUMIFS(Solicitudes!F:F, Solicitudes!C:C, B13), SUMIFS(Solicitudes!F:F, Solicitudes!B:B, C$4, Solicitudes!C:C, B13)) | D13: =IF(C$4="Jalisco", SUMIFS(Captura_Jalisco!G:G, Captura_Jalisco!A:A, B13, Captura_Jalisco!B:B, "Salida"), IF(C$4="Todas", SUMIFS(Captura_Obra!F:F, Captura_Obra!A:A, B13) + SUMIFS(Captura_Jalisco!G:G, Captura_Jalisco!A:A, B13, Captura_Jalisco!B:B, "Salida"), SUMIFS(Captura_Obra!F:F, Captura_Obra!B:B, C$4, Captura_Obra!A:A, B13))) | E13: =D13-C13 | F13: =C13*C$7 | G13: =D13*C$7 | H13: =G13-F13
A14: Miércoles | B14: =B13+1 | C14: =IF(C$4="Todas", SUMIFS(Solicitudes!F:F, Solicitudes!C:C, B14), SUMIFS(Solicitudes!F:F, Solicitudes!B:B, C$4, Solicitudes!C:C, B14)) | D14: =IF(C$4="Jalisco", SUMIFS(Captura_Jalisco!G:G, Captura_Jalisco!A:A, B14, Captura_Jalisco!B:B, "Salida"), IF(C$4="Todas", SUMIFS(Captura_Obra!F:F, Captura_Obra!A:A, B14) + SUMIFS(Captura_Jalisco!G:G, Captura_Jalisco!A:A, B14, Captura_Jalisco!B:B, "Salida"), SUMIFS(Captura_Obra!F:F, Captura_Obra!B:B, C$4, Captura_Obra!A:A, B14))) | E14: =D14-C14 | F14: =C14*C$7 | G14: =D14*C$7 | H14: =G14-F14
A15: Jueves | B15: =B14+1 | C15: =IF(C$4="Todas", SUMIFS(Solicitudes!F:F, Solicitudes!C:C, B15), SUMIFS(Solicitudes!F:F, Solicitudes!B:B, C$4, Solicitudes!C:C, B15)) | D15: =IF(C$4="Jalisco", SUMIFS(Captura_Jalisco!G:G, Captura_Jalisco!A:A, B15, Captura_Jalisco!B:B, "Salida"), IF(C$4="Todas", SUMIFS(Captura_Obra!F:F, Captura_Obra!A:A, B15) + SUMIFS(Captura_Jalisco!G:G, Captura_Jalisco!A:A, B15, Captura_Jalisco!B:B, "Salida"), SUMIFS(Captura_Obra!F:F, Captura_Obra!B:B, C$4, Captura_Obra!A:A, B15))) | E15: =D15-C15 | F15: =C15*C$7 | G15: =D15*C$7 | H15: =G15-F15
A16: Viernes | B16: =B15+1 | C16: =IF(C$4="Todas", SUMIFS(Solicitudes!F:F, Solicitudes!C:C, B16), SUMIFS(Solicitudes!F:F, Solicitudes!B:B, C$4, Solicitudes!C:C, B16)) | D16: =IF(C$4="Jalisco", SUMIFS(Captura_Jalisco!G:G, Captura_Jalisco!A:A, B16, Captura_Jalisco!B:B, "Salida"), IF(C$4="Todas", SUMIFS(Captura_Obra!F:F, Captura_Obra!A:A, B16) + SUMIFS(Captura_Jalisco!G:G, Captura_Jalisco!A:A, B16, Captura_Jalisco!B:B, "Salida"), SUMIFS(Captura_Obra!F:F, Captura_Obra!B:B, C$4, Captura_Obra!A:A, B16))) | E16: =D16-C16 | F16: =C16*C$7 | G16: =D16*C$7 | H16: =G16-F16
A17: Sábado | B17: =B16+1 | C17: =IF(C$4="Todas", SUMIFS(Solicitudes!F:F, Solicitudes!C:C, B17), SUMIFS(Solicitudes!F:F, Solicitudes!B:B, C$4, Solicitudes!C:C, B17)) | D17: =IF(C$4="Jalisco", SUMIFS(Captura_Jalisco!G:G, Captura_Jalisco!A:A, B17, Captura_Jalisco!B:B, "Salida"), IF(C$4="Todas", SUMIFS(Captura_Obra!F:F, Captura_Obra!A:A, B17) + SUMIFS(Captura_Jalisco!G:G, Captura_Jalisco!A:A, B17, Captura_Jalisco!B:B, "Salida"), SUMIFS(Captura_Obra!F:F, Captura_Obra!B:B, C$4, Captura_Obra!A:A, B17))) | E17: =D17-C17 | F17: =C17*C$7 | G17: =D17*C$7 | H17: =G17-F17
A18: TOTAL SEMANAL | C18: =SUM(C12:C17) | D18: =SUM(D12:D17) | E18: =SUM(E12:E17) | F18: =SUM(F12:F17) | G18: =SUM(G12:G17) | H18: =SUM(H12:H17)
A20: CONCILIACIÓN FÍSICA Y DISCREPANCIAS (OBRA VS MARIMBA Y PEGASO)
A21: Día | B21: Fecha | C21: Obra Recibió (M) | D21: Marimba Despachó | E21: Dif. Marimba | F21: Obra Recibió (P) | G21: Pegaso Despachó | H21: Dif. Pegaso | I21: Dif. Total (L) | J21: Observaciones / Justificación
A22: Lunes | B22: =B12 | C22: =IF(C$4="Todas", SUMIFS(Captura_Obra!F:F, Captura_Obra!A:A, B22, Captura_Obra!C:C, "Marimba M-01"), SUMIFS(Captura_Obra!F:F, Captura_Obra!B:B, C$4, Captura_Obra!A:A, B22, Captura_Obra!C:C, "Marimba M-01")) | D22: =IF(C$4="Todas", SUMIFS(Captura_Marimba_M01!G:G, Captura_Marimba_M01!A:A, B22, Captura_Marimba_M01!B:B, "Salida"), SUMIFS(Captura_Marimba_M01!G:G, Captura_Marimba_M01!C:C, C$4, Captura_Marimba_M01!A:A, B22, Captura_Marimba_M01!B:B, "Salida")) | E22: =C22-D22 | F22: =IF(C$4="Todas", SUMIFS(Captura_Obra!F:F, Captura_Obra!A:A, B22, Captura_Obra!C:C, "Pegaso Directo"), SUMIFS(Captura_Obra!F:F, Captura_Obra!B:B, C$4, Captura_Obra!A:A, B22, Captura_Obra!C:C, "Pegaso Directo")) | G22: =IF(C$4="Todas", SUMIFS(Captura_Pegaso!H:H, Captura_Pegaso!A:A, B22, Captura_Pegaso!B:B, "Salida"), SUMIFS(Captura_Pegaso!H:H, Captura_Pegaso!D:D, C$4, Captura_Pegaso!A:A, B22, Captura_Pegaso!B:B, "Salida")) | H22: =F22-G22 | I22: =E22+H22
A23: Martes | B23: =B13 | C23: =IF(C$4="Todas", SUMIFS(Captura_Obra!F:F, Captura_Obra!A:A, B23, Captura_Obra!C:C, "Marimba M-01"), SUMIFS(Captura_Obra!F:F, Captura_Obra!B:B, C$4, Captura_Obra!A:A, B23, Captura_Obra!C:C, "Marimba M-01")) | D23: =IF(C$4="Todas", SUMIFS(Captura_Marimba_M01!G:G, Captura_Marimba_M01!A:A, B23, Captura_Marimba_M01!B:B, "Salida"), SUMIFS(Captura_Marimba_M01!G:G, Captura_Marimba_M01!C:C, C$4, Captura_Marimba_M01!A:A, B23, Captura_Marimba_M01!B:B, "Salida")) | E23: =C23-D23 | F23: =IF(C$4="Todas", SUMIFS(Captura_Obra!F:F, Captura_Obra!A:A, B23, Captura_Obra!C:C, "Pegaso Directo"), SUMIFS(Captura_Obra!F:F, Captura_Obra!B:B, C$4, Captura_Obra!A:A, B23, Captura_Obra!C:C, "Pegaso Directo")) | G23: =IF(C$4="Todas", SUMIFS(Captura_Pegaso!H:H, Captura_Pegaso!A:A, B23, Captura_Pegaso!B:B, "Salida"), SUMIFS(Captura_Pegaso!H:H, Captura_Pegaso!D:D, C$4, Captura_Pegaso!A:A, B23, Captura_Pegaso!B:B, "Salida")) | H23: =F23-G23 | I23: =E23+H23
A24: Miércoles | B24: =B14 | C24: =IF(C$4="Todas", SUMIFS(Captura_Obra!F:F, Captura_Obra!A:A, B24, Captura_Obra!C:C, "Marimba M-01"), SUMIFS(Captura_Obra!F:F, Captura_Obra!B:B, C$4, Captura_Obra!A:A, B24, Captura_Obra!C:C, "Marimba M-01")) | D24: =IF(C$4="Todas", SUMIFS(Captura_Marimba_M01!G:G, Captura_Marimba_M01!A:A, B24, Captura_Marimba_M01!B:B, "Salida"), SUMIFS(Captura_Marimba_M01!G:G, Captura_Marimba_M01!C:C, C$4, Captura_Marimba_M01!A:A, B24, Captura_Marimba_M01!B:B, "Salida")) | E24: =C24-D24 | F24: =IF(C$4="Todas", SUMIFS(Captura_Obra!F:F, Captura_Obra!A:A, B24, Captura_Obra!C:C, "Pegaso Directo"), SUMIFS(Captura_Obra!F:F, Captura_Obra!B:B, C$4, Captura_Obra!A:A, B24, Captura_Obra!C:C, "Pegaso Directo")) | G24: =IF(C$4="Todas", SUMIFS(Captura_Pegaso!H:H, Captura_Pegaso!A:A, B24, Captura_Pegaso!B:B, "Salida"), SUMIFS(Captura_Pegaso!H:H, Captura_Pegaso!D:D, C$4, Captura_Pegaso!A:A, B24, Captura_Pegaso!B:B, "Salida")) | H24: =F24-G24 | I24: =E24+H24
A25: Jueves | B25: =B15 | C25: =IF(C$4="Todas", SUMIFS(Captura_Obra!F:F, Captura_Obra!A:A, B25, Captura_Obra!C:C, "Marimba M-01"), SUMIFS(Captura_Obra!F:F, Captura_Obra!B:B, C$4, Captura_Obra!A:A, B25, Captura_Obra!C:C, "Marimba M-01")) | D25: =IF(C$4="Todas", SUMIFS(Captura_Marimba_M01!G:G, Captura_Marimba_M01!A:A, B25, Captura_Marimba_M01!B:B, "Salida"), SUMIFS(Captura_Marimba_M01!G:G, Captura_Marimba_M01!C:C, C$4, Captura_Marimba_M01!A:A, B25, Captura_Marimba_M01!B:B, "Salida")) | E25: =C25-D25 | F25: =IF(C$4="Todas", SUMIFS(Captura_Obra!F:F, Captura_Obra!A:A, B25, Captura_Obra!C:C, "Pegaso Directo"), SUMIFS(Captura_Obra!F:F, Captura_Obra!B:B, C$4, Captura_Obra!A:A, B25, Captura_Obra!C:C, "Pegaso Directo")) | G25: =IF(C$4="Todas", SUMIFS(Captura_Pegaso!H:H, Captura_Pegaso!A:A, B25, Captura_Pegaso!B:B, "Salida"), SUMIFS(Captura_Pegaso!H:H, Captura_Pegaso!D:D, C$4, Captura_Pegaso!A:A, B25, Captura_Pegaso!B:B, "Salida")) | H25: =F25-G25 | I25: =E25+H25
A26: Viernes | B26: =B16 | C26: =IF(C$4="Todas", SUMIFS(Captura_Obra!F:F, Captura_Obra!A:A, B26, Captura_Obra!C:C, "Marimba M-01"), SUMIFS(Captura_Obra!F:F, Captura_Obra!B:B, C$4, Captura_Obra!A:A, B26, Captura_Obra!C:C, "Marimba M-01")) | D26: =IF(C$4="Todas", SUMIFS(Captura_Marimba_M01!G:G, Captura_Marimba_M01!A:A, B26, Captura_Marimba_M01!B:B, "Salida"), SUMIFS(Captura_Marimba_M01!G:G, Captura_Marimba_M01!C:C, C$4, Captura_Marimba_M01!A:A, B26, Captura_Marimba_M01!B:B, "Salida")) | E26: =C26-D26 | F26: =IF(C$4="Todas", SUMIFS(Captura_Obra!F:F, Captura_Obra!A:A, B26, Captura_Obra!C:C, "Pegaso Directo"), SUMIFS(Captura_Obra!F:F, Captura_Obra!B:B, C$4, Captura_Obra!A:A, B26, Captura_Obra!C:C, "Pegaso Directo")) | G26: =IF(C$4="Todas", SUMIFS(Captura_Pegaso!H:H, Captura_Pegaso!A:A, B26, Captura_Pegaso!B:B, "Salida"), SUMIFS(Captura_Pegaso!H:H, Captura_Pegaso!D:D, C$4, Captura_Pegaso!A:A, B26, Captura_Pegaso!B:B, "Salida")) | H26: =F26-G26 | I26: =E26+H26
A27: Sábado | B27: =B17 | C27: =IF(C$4="Todas", SUMIFS(Captura_Obra!F:F, Captura_Obra!A:A, B27, Captura_Obra!C:C, "Marimba M-01"), SUMIFS(Captura_Obra!F:F, Captura_Obra!B:B, C$4, Captura_Obra!A:A, B27, Captura_Obra!C:C, "Marimba M-01")) | D27: =IF(C$4="Todas", SUMIFS(Captura_Marimba_M01!G:G, Captura_Marimba_M01!A:A, B27, Captura_Marimba_M01!B:B, "Salida"), SUMIFS(Captura_Marimba_M01!G:G, Captura_Marimba_M01!C:C, C$4, Captura_Marimba_M01!A:A, B27, Captura_Marimba_M01!B:B, "Salida")) | E27: =C27-D27 | F27: =IF(C$4="Todas", SUMIFS(Captura_Obra!F:F, Captura_Obra!A:A, B27, Captura_Obra!C:C, "Pegaso Directo"), SUMIFS(Captura_Obra!F:F, Captura_Obra!B:B, C$4, Captura_Obra!A:A, B27, Captura_Obra!C:C, "Pegaso Directo")) | G27: =IF(C$4="Todas", SUMIFS(Captura_Pegaso!H:H, Captura_Pegaso!A:A, B27, Captura_Pegaso!B:B, "Salida"), SUMIFS(Captura_Pegaso!H:H, Captura_Pegaso!D:D, C$4, Captura_Pegaso!A:A, B27, Captura_Pegaso!B:B, "Salida")) | H27: =F27-G27 | I27: =E27+H27
A28: TOTAL CONCILIADO | C28: =SUM(C22:C27) | D28: =SUM(D22:D27) | E28: =SUM(E22:E27) | F28: =SUM(F22:F27) | G28: =SUM(G22:G27) | H28: =SUM(H22:H27) | I28: =SUM(I22:I27)
Q30: ="SOLICITUDES DE DISEL DIARIAS Y SEMANALES POR OBRA (SEMANA " & YEAR(C5) & "-" & TEXT(MONTH(C5),"00") & "-" & TEXT(DAY(C5),"00") & ")"
A31: RESUMEN ACUMULADO POR OBRA / PERÍODO SELECCIONADO | Q31: Obra | R31: Solicitante | S31: Lunes | U31: Martes | W31: Miércoles | Y31: Jueves | AA31: Viernes | AC31: Sábado | AE31: Total Semanal Solicitado | AF31: Total Seamanal Autorizado
A32: Obra | B32: Total Litros Suministrados | C32: Costo Total Acumulado | S32: Solicitado | T32: Autorizado | U32: Solicitado | V32: Autorizado | W32: Solicitado | X32: Autorizado | Y32: Solicitado | Z32: Autorizado | AA32: Solicitado | AB32: Autorizado | AC32: Solicitado | AD32: Autorizado
A33: México-Toluca | B33: =IF(C$8="Acumulado Histórico", SUMIFS(Captura_Obra!F:F, Captura_Obra!B:B, A33), IF(C$8="Rango de Fechas", SUMIFS(Captura_Obra!F:F, Captura_Obra!B:B, A33, Captura_Obra!A:A, ">="&C$5, Captura_Obra!A:A, "<="&(C$6+5)), SUMIFS(Captura_Obra!F:F, Captura_Obra!B:B, A33, Captura_Obra!A:A, ">="&C$5, Captura_Obra!A:A, "<="&(C$5+5)))) | C33: =B33*C$7 | P33: m | Q33: =A33 | R33: =VLOOKUP(Q33,Catalogos!$B$4:$C$18,2,FALSE) | S33: =SUMIFS(Solicitudes!$F:$F, Solicitudes!$B:$B, $Q33, Solicitudes!$C:$C, $B$12) | T33: 550 | U33: =SUMIFS(Solicitudes!$F:$F, Solicitudes!$B:$B, $Q33, Solicitudes!$C:$C, $B$13) | V33: 550 | W33: =SUMIFS(Solicitudes!$F:$F, Solicitudes!$B:$B, $Q33, Solicitudes!$C:$C, $B$14) | X33: 550 | Y33: =SUMIFS(Solicitudes!$F:$F, Solicitudes!$B:$B, $Q33, Solicitudes!$C:$C, $B$15) | Z33: 550 | AA33: =SUMIFS(Solicitudes!$F:$F, Solicitudes!$B:$B, $Q33, Solicitudes!$C:$C, $B$16) | AB33: 550 | AC33: =SUMIFS(Solicitudes!$F:$F, Solicitudes!$B:$B, $Q33, Solicitudes!$C:$C, $B$17) | AD33: 0 | AE33: =SUM(S33,U33,W33,Y33,AA33,AC33,) | AF33: =SUM(T33,V33,X33,Z33,AB33,AD33)
A34: Lerma - Tres Marías | B34: =IF(C$8="Acumulado Histórico", SUMIFS(Captura_Obra!F:F, Captura_Obra!B:B, A34), IF(C$8="Rango de Fechas", SUMIFS(Captura_Obra!F:F, Captura_Obra!B:B, A34, Captura_Obra!A:A, ">="&C$5, Captura_Obra!A:A, "<="&(C$6+5)), SUMIFS(Captura_Obra!F:F, Captura_Obra!B:B, A34, Captura_Obra!A:A, ">="&C$5, Captura_Obra!A:A, "<="&(C$5+5)))) | C34: =B34*C$7 | P34: p | Q34: =A34 | R34: =VLOOKUP(Q34,Catalogos!$B$4:$C$18,2,FALSE) | S34: =SUMIFS(Solicitudes!$F:$F, Solicitudes!$B:$B, $Q34, Solicitudes!$C:$C, $B$12) | T34: 400 | U34: =SUMIFS(Solicitudes!$F:$F, Solicitudes!$B:$B, $Q34, Solicitudes!$C:$C, $B$13) | V34: 400 | W34: =SUMIFS(Solicitudes!$F:$F, Solicitudes!$B:$B, $Q34, Solicitudes!$C:$C, $B$14) | X34: 400 | Y34: =SUMIFS(Solicitudes!$F:$F, Solicitudes!$B:$B, $Q34, Solicitudes!$C:$C, $B$15) | Z34: 400 | AA34: =SUMIFS(Solicitudes!$F:$F, Solicitudes!$B:$B, $Q34, Solicitudes!$C:$C, $B$16) | AB34: 400 | AC34: =SUMIFS(Solicitudes!$F:$F, Solicitudes!$B:$B, $Q34, Solicitudes!$C:$C, $B$17) | AD34: =SUMIFS(Solicitudes!$F:$F, Solicitudes!$B:$B, $Q34, Solicitudes!$C:$C, ($B$17+1)) | AE34: =SUM(S34,U34,W34,Y34,AA34,AC34,) | AF34: =SUM(T34,V34,X34,Z34,AB34,AD34)
A35: Chamapa-Lechería | B35: =IF(C$8="Acumulado Histórico", SUMIFS(Captura_Obra!F:F, Captura_Obra!B:B, A35), IF(C$8="Rango de Fechas", SUMIFS(Captura_Obra!F:F, Captura_Obra!B:B, A35, Captura_Obra!A:A, ">="&C$5, Captura_Obra!A:A, "<="&(C$6+5)), SUMIFS(Captura_Obra!F:F, Captura_Obra!B:B, A35, Captura_Obra!A:A, ">="&C$5, Captura_Obra!A:A, "<="&(C$5+5)))) | C35: =B35*C$7 | P35: p | Q35: =A36 | R35: =VLOOKUP(Q35,Catalogos!$B$4:$C$18,2,FALSE) | S35: =SUMIFS(Solicitudes!$F:$F, Solicitudes!$B:$B, $Q35, Solicitudes!$C:$C, $B$12) | T35: 100 | U35: =SUMIFS(Solicitudes!$F:$F, Solicitudes!$B:$B, $Q35, Solicitudes!$C:$C, $B$13) | V35: 100 | W35: =SUMIFS(Solicitudes!$F:$F, Solicitudes!$B:$B, $Q35, Solicitudes!$C:$C, $B$14) | X35: 100 | Y35: =SUMIFS(Solicitudes!$F:$F, Solicitudes!$B:$B, $Q35, Solicitudes!$C:$C, $B$15) | Z35: 100 | AA35: =SUMIFS(Solicitudes!$F:$F, Solicitudes!$B:$B, $Q35, Solicitudes!$C:$C, $B$16) | AB35: 100 | AC35: =SUMIFS(Solicitudes!$F:$F, Solicitudes!$B:$B, $Q35, Solicitudes!$C:$C, $B$17) | AD35: =SUMIFS(Solicitudes!$F:$F, Solicitudes!$B:$B, $Q35, Solicitudes!$C:$C, ($B$17+1)) | AE35: =SUM(S35,U35,W35,Y35,AA35,AC35,) | AF35: =SUM(T35,V35,X35,Z35,AB35,AD35)
A36: Bacheo Toluca | B36: =IF(C$8="Acumulado Histórico", SUMIFS(Captura_Obra!F:F, Captura_Obra!B:B, A36), IF(C$8="Rango de Fechas", SUMIFS(Captura_Obra!F:F, Captura_Obra!B:B, A36, Captura_Obra!A:A, ">="&C$5, Captura_Obra!A:A, "<="&(C$6+5)), SUMIFS(Captura_Obra!F:F, Captura_Obra!B:B, A36, Captura_Obra!A:A, ">="&C$5, Captura_Obra!A:A, "<="&(C$5+5)))) | C36: =B36*C$7 | P36: p | Q36: =A37 | R36: =VLOOKUP(Q36,Catalogos!$B$4:$C$18,2,FALSE) | S36: =SUMIFS(Solicitudes!$F:$F, Solicitudes!$B:$B, $Q36, Solicitudes!$C:$C, $B$12) | T36: 0 | U36: =SUMIFS(Solicitudes!$F:$F, Solicitudes!$B:$B, $Q36, Solicitudes!$C:$C, $B$13) | V36: 300 | W36: =SUMIFS(Solicitudes!$F:$F, Solicitudes!$B:$B, $Q36, Solicitudes!$C:$C, $B$14) | X36: 1000 | Y36: =SUMIFS(Solicitudes!$F:$F, Solicitudes!$B:$B, $Q36, Solicitudes!$C:$C, $B$15) | Z36: 300 | AA36: =SUMIFS(Solicitudes!$F:$F, Solicitudes!$B:$B, $Q36, Solicitudes!$C:$C, $B$16) | AB36: 0 | AC36: =SUMIFS(Solicitudes!$F:$F, Solicitudes!$B:$B, $Q36, Solicitudes!$C:$C, $B$17) | AD36: =SUMIFS(Solicitudes!$F:$F, Solicitudes!$B:$B, $Q36, Solicitudes!$C:$C, ($B$17+1)) | AE36: =SUM(S36,U36,W36,Y36,AA36,AC36,) | AF36: =SUM(T36,V36,X36,Z36,AB36,AD36)
A37: Planta Asfalto Pegaso | B37: =IF(C$8="Acumulado Histórico", SUMIFS(Captura_Obra!F:F, Captura_Obra!B:B, A37), IF(C$8="Rango de Fechas", SUMIFS(Captura_Obra!F:F, Captura_Obra!B:B, A37, Captura_Obra!A:A, ">="&C$5, Captura_Obra!A:A, "<="&(C$6+5)), SUMIFS(Captura_Obra!F:F, Captura_Obra!B:B, A37, Captura_Obra!A:A, ">="&C$5, Captura_Obra!A:A, "<="&(C$5+5)))) | C37: =B37*C$7 | P37: h | Q37: =A38 | R37: =VLOOKUP(Q37,Catalogos!$B$4:$C$18,2,FALSE) | S37: =SUMIFS(Solicitudes!$F:$F, Solicitudes!$B:$B, $Q37, Solicitudes!$C:$C, $B$12) | T37: 500 | U37: =SUMIFS(Solicitudes!$F:$F, Solicitudes!$B:$B, $Q37, Solicitudes!$C:$C, $B$13) | V37: 500 | W37: =SUMIFS(Solicitudes!$F:$F, Solicitudes!$B:$B, $Q37, Solicitudes!$C:$C, $B$14) | X37: 500 | Y37: =SUMIFS(Solicitudes!$F:$F, Solicitudes!$B:$B, $Q37, Solicitudes!$C:$C, $B$15) | Z37: 500 | AA37: =SUMIFS(Solicitudes!$F:$F, Solicitudes!$B:$B, $Q37, Solicitudes!$C:$C, $B$16) | AB37: 500 | AC37: =SUMIFS(Solicitudes!$F:$F, Solicitudes!$B:$B, $Q37, Solicitudes!$C:$C, $B$17) | AD37: =SUMIFS(Solicitudes!$F:$F, Solicitudes!$B:$B, $Q37, Solicitudes!$C:$C, ($B$17+1)) | AE37: =SUM(S37,U37,W37,Y37,AA37,AC37,) | AF37: =SUM(T37,V37,X37,Z37,AB37,AD37)
A38: Planta Asflato Huixquilucan | B38: =IF(C$8="Acumulado Histórico", SUMIFS(Captura_Obra!F:F, Captura_Obra!B:B, A38), IF(C$8="Rango de Fechas", SUMIFS(Captura_Obra!F:F, Captura_Obra!B:B, A38, Captura_Obra!A:A, ">="&C$5, Captura_Obra!A:A, "<="&(C$6+5)), SUMIFS(Captura_Obra!F:F, Captura_Obra!B:B, A38, Captura_Obra!A:A, ">="&C$5, Captura_Obra!A:A, "<="&(C$5+5)))) | C38: =B38*C$7 | Q38: =A41 | S38: =SUM(S33:S37) | T38: =SUM(T33:T37) | U38: =SUM(U33:U37) | V38: =SUM(V33:V37) | W38: =SUM(W33:W37) | X38: =SUM(X33:X37) | Y38: =SUM(Y33:Y37) | Z38: =SUM(Z33:Z37) | ... AE38: =SUM(AE33:AE37) | AF38: =SUM(T38,V38,X38,Z38,AB38,AD38)
A39: Dragones | B39: =IF(C$8="Acumulado Histórico", SUMIFS(Captura_Obra!F:F, Captura_Obra!B:B, A39), IF(C$8="Rango de Fechas", SUMIFS(Captura_Obra!F:F, Captura_Obra!B:B, A39, Captura_Obra!A:A, ">="&C$5, Captura_Obra!A:A, "<="&(C$6+5)), SUMIFS(Captura_Obra!F:F, Captura_Obra!B:B, A39, Captura_Obra!A:A, ">="&C$5, Captura_Obra!A:A, "<="&(C$5+5)))) | C39: =B39*C$7
A40: Jalisco | B40: =IF(C$8="Acumulado Histórico", SUMIFS(Captura_Jalisco!G:G, Captura_Jalisco!B:B, "Salida"), IF(C$8="Rango de Fechas", SUMIFS(Captura_Jalisco!G:G, Captura_Jalisco!B:B, "Salida", Captura_Jalisco!A:A, ">="&C$5, Captura_Jalisco!A:A, "<="&(C$6+5)), SUMIFS(Captura_Jalisco!G:G, Captura_Jalisco!B:B, "Salida", Captura_Jalisco!A:A, ">="&C$5, Captura_Jalisco!A:A, "<="&(C$5+5)))) | C40: =B40*C$7
A41: TOTAL GENERAL | B41: =SUM(B33:B40) | C41: =SUM(C33:C40)
A43: RESUMEN DE CONSUMO SEMANAL POR OBRA (DETALLE HISTÓRICO POR SEMANA)
B44: Obra (Tabla Semanal): | C44: Jalisco
B45: Precio Diésel ($/L): | C45: 27
...

Sheet Conciliacion_Auditoria
A1: AUDITORÍA DE CONCILIACIÓN (CRUCE TRANSACCIONAL)
A3: Origen | B3: Folio Suministro (Pipa) | C3: Folio Recepción (Obra) | D3: Estatus | E3: Fecha | F3: Obra | G3: Máquina / Destino | H3: Lts Entregados | I3: Lts Recibidos | J3: Diferencia Lts | K3: Estatus
A4: =IF(Captura_Pegaso!A5="", "", "Pegaso") | B4: =IF(Captura_Pegaso!A5="", "", Captura_Pegaso!N5) | C4: =IF(Captura_Pegaso!A5="", "", IFERROR(LOOKUP(2, 1/((Captura_Obra!$A$5:$A$1000=E4)*(Captura_Obra!$B$5:$B$1000=F4)*(Captura_Obra!$D$5:$D$1000=G4)), Captura_Obra!$N$5:$N$1000), "No Reportado")) | D4: =IF(Captura_Pegaso!A5="", "", IF(J4=0, "✅ Cuadrado", IF(I4=0, "❌ Falta en Obra", "⚠️ Dif"))) | E4: =IF(Captura_Pegaso!A5="", "", Captura_Pegaso!A5) | F4: =IF(Captura_Pegaso!A5="", "", Captura_Pegaso!D5) | G4: =IF(Captura_Pegaso!A5="", "", Captura_Pegaso!E5) | H4: =IF(Captura_Pegaso!A5="", "", Captura_Pegaso!H5) | I4: =IF(Captura_Pegaso!A5="", "", SUMIFS(Captura_Obra!$F:$F, Captura_Obra!$A:$A, E4, Captura_Obra!$B:$B, F4, Captura_Obra!$D:$D, G4)) | J4: =IF(Captura_Pegaso!A5="", "", H4 - I4)
A5: =IF(Captura_Pegaso!A6="", "", "Pegaso") | B5: =IF(Captura_Pegaso!A6="", "", Captura_Pegaso!N6) | C5: =IF(Captura_Pegaso!A6="", "", IFERROR(LOOKUP(2, 1/((Captura_Obra!$A$5:$A$1000=E5)*(Captura_Obra!$B$5:$B$1000=F5)*(Captura_Obra!$D$5:$D$1000=G5)), Captura_Obra!$N$5:$N$1000), "No Reportado")) | D5: =IF(Captura_Pegaso!A6="", "", IF(J5=0, "✅ Cuadrado", IF(I5=0, "❌ Falta en Obra", "⚠️ Dif"))) | E5: =IF(Captura_Pegaso!A6="", "", Captura_Pegaso!A6) | F5: =IF(Captura_Pegaso!A6="", "", Captura_Pegaso!D6) | G5: =IF(Captura_Pegaso!A6="", "", Captura_Pegaso!E6) | H5: =IF(Captura_Pegaso!A6="", "", Captura_Pegaso!H6) | I5: =IF(Captura_Pegaso!A6="", "", SUMIFS(Captura_Obra!$F:$F, Captura_Obra!$A:$A, E5, Captura_Obra!$B:$B, F5, Captura_Obra!$D:$D, G5)) | J5: =IF(Captura_Pegaso!A6="", "", H5 - I5)
A6: =IF(Captura_Pegaso!A7="", "", "Pegaso") | B6: =IF(Captura_Pegaso!A7="", "", Captura_Pegaso!N7) | C6: =IF(Captura_Pegaso!A7="", "", IFERROR(LOOKUP(2, 1/((Captura_Obra!$A$5:$A$1000=E6)*(Captura_Obra!$B$5:$B$1000=F6)*(Captura_Obra!$D$5:$D$1000=G6)), Captura_Obra!$N$5:$N$1000), "No Reportado")) | D6: =IF(Captura_Pegaso!A7="", "", IF(J6=0, "✅ Cuadrado", IF(I6=0, "❌ Falta en Obra", "⚠️ Dif"))) | E6: =IF(Captura_Pegaso!A7="", "", Captura_Pegaso!A7) | F6: =IF(Captura_Pegaso!A7="", "", Captura_Pegaso!D7) | G6: =IF(Captura_Pegaso!A7="", "", Captura_Pegaso!E7) | H6: =IF(Captura_Pegaso!A7="", "", Captura_Pegaso!H7) | I6: =IF(Captura_Pegaso!A7="", "", SUMIFS(Captura_Obra!$F:$F, Captura_Obra!$A:$A, E6, Captura_Obra!$B:$B, F6, Captura_Obra!$D:$D, G6)) | J6: =IF(Captura_Pegaso!A7="", "", H6 - I6)
A7: =IF(Captura_Pegaso!A8="", "", "Pegaso") | B7: =IF(Captura_Pegaso!A8="", "", Captura_Pegaso!N8) | C7: =IF(Captura_Pegaso!A8="", "", IFERROR(LOOKUP(2, 1/((Captura_Obra!$A$5:$A$1000=E7)*(Captura_Obra!$B$5:$B$1000=F7)*(Captura_Obra!$D$5:$D$1000=G7)), Captura_Obra!$N$5:$N$1000), "No Reportado")) | D7: =IF(Captura_Pegaso!A8="", "", IF(J7=0, "✅ Cuadrado", IF(I7=0, "❌ Falta en Obra", "⚠️ Dif"))) | E7: =IF(Captura_Pegaso!A8="", "", Captura_Pegaso!A8) | F7: =IF(Captura_Pegaso!A8="", "", Captura_Pegaso!D8) | G7: =IF(Captura_Pegaso!A8="", "", Captura_Pegaso!E8) | H7: =IF(Captura_Pegaso!A8="", "", Captura_Pegaso!H8) | I7: =IF(Captura_Pegaso!A8="", "", SUMIFS(Captura_Obra!$F:$F, Captura_Obra!$A:$A, E7, Captura_Obra!$B:$B, F7, Captura_Obra!$D:$D, G7)) | J7: =IF(Captura_Pegaso!A8="", "", H7 - I7)
A8: =IF(Captura_Pegaso!A9="", "", "Pegaso") | B8: =IF(Captura_Pegaso!A9="", "", Captura_Pegaso!N9) | C8: =IF(Captura_Pegaso!A9="", "", IFERROR(LOOKUP(2, 1/((Captura_Obra!$A$5:$A$1000=E8)*(Captura_Obra!$B$5:$B$1000=F8)*(Captura_Obra!$D$5:$D$1000=G8)), Captura_Obra!$N$5:$N$1000), "No Reportado")) | D8: =IF(Captura_Pegaso!A9="", "", IF(J8=0, "✅ Cuadrado", IF(I8=0, "❌ Falta en Obra", "⚠️ Dif"))) | E8: =IF(Captura_Pegaso!A9="", "", Captura_Pegaso!A9) | F8: =IF(Captura_Pegaso!A9="", "", Captura_Pegaso!D9) | G8: =IF(Captura_Pegaso!A9="", "", Captura_Pegaso!E9) | H8: =IF(Captura_Pegaso!A9="", "", Captura_Pegaso!H9) | I8: =IF(Captura_Pegaso!A9="", "", SUMIFS(Captura_Obra!$F:$F, Captura_Obra!$A:$A, E8, Captura_Obra!$B:$B, F8, Captura_Obra!$D:$D, G8)) | J8: =IF(Captura_Pegaso!A9="", "", H8 - I8)
A9: =IF(Captura_Pegaso!A10="", "", "Pegaso") | B9: =IF(Captura_Pegaso!A10="", "", Captura_Pegaso!N10) | C9: =IF(Captura_Pegaso!A10="", "", IFERROR(LOOKUP(2, 1/((Captura_Obra!$A$5:$A$1000=E9)*(Captura_Obra!$B$5:$B$1000=F9)*(Captura_Obra!$D$5:$D$1000=G9)), Captura_Obra!$N$5:$N$1000), "No Reportado")) | D9: =IF(Captura_Pegaso!A10="", "", IF(J9=0, "✅ Cuadrado", IF(I9=0, "❌ Falta en Obra", "⚠️ Dif"))) | E9: =IF(Captura_Pegaso!A10="", "", Captura_Pegaso!A10) | F9: =IF(Captura_Pegaso!A10="", "", Captura_Pegaso!D10) | G9: =IF(Captura_Pegaso!A10="", "", Captura_Pegaso!E10) | H9: =IF(Captura_Pegaso!A10="", "", Captura_Pegaso!H10) | I9: =IF(Captura_Pegaso!A10="", "", SUMIFS(Captura_Obra!$F:$F, Captura_Obra!$A:$A, E9, Captura_Obra!$B:$B, F9, Captura_Obra!$D:$D, G9)) | J9: =IF(Captura_Pegaso!A10="", "", H9 - I9)
A10: =IF(Captura_Pegaso!A11="", "", "Pegaso") | B10: =IF(Captura_Pegaso!A11="", "", Captura_Pegaso!N11) | C10: =IF(Captura_Pegaso!A11="", "", IFERROR(LOOKUP(2, 1/((Captura_Obra!$A$5:$A$1000=E10)*(Captura_Obra!$B$5:$B$1000=F10)*(Captura_Obra!$D$5:$D$1000=G10)), Captura_Obra!$N$5:$N$1000), "No Reportado")) | D10: =IF(Captura_Pegaso!A11="", "", IF(J10=0, "✅ Cuadrado", IF(I10=0, "❌ Falta en Obra", "⚠️ Dif"))) | E10: =IF(Captura_Pegaso!A11="", "", Captura_Pegaso!A11) | F10: =IF(Captura_Pegaso!A11="", "", Captura_Pegaso!D11) | G10: =IF(Captura_Pegaso!A11="", "", Captura_Pegaso!E11) | H10: =IF(Captura_Pegaso!A11="", "", Captura_Pegaso!H11) | I10: =IF(Captura_Pegaso!A11="", "", SUMIFS(Captura_Obra!$F:$F, Captura_Obra!$A:$A, E10, Captura_Obra!$B:$B, F10, Captura_Obra!$D:$D, G10)) | J10: =IF(Captura_Pegaso!A11="", "", H10 - I10)
A11: =IF(Captura_Pegaso!A12="", "", "Pegaso") | B11: =IF(Captura_Pegaso!A12="", "", Captura_Pegaso!N12) | C11: =IF(Captura_Pegaso!A12="", "", IFERROR(LOOKUP(2, 1/((Captura_Obra!$A$5:$A$1000=E11)*(Captura_Obra!$B$5:$B$1000=F11)*(Captura_Obra!$D$5:$D$1000=G11)), Captura_Obra!$N$5:$N$1000), "No Reportado")) | D11: =IF(Captura_Pegaso!A12="", "", IF(J11=0, "✅ Cuadrado", IF(I11=0, "❌ Falta en Obra", "⚠️ Dif"))) | E11: =IF(Captura_Pegaso!A12="", "", Captura_Pegaso!A12) | F11: =IF(Captura_Pegaso!A12="", "", Captura_Pegaso!D12) | G11: =IF(Captura_Pegaso!A12="", "", Captura_Pegaso!E12) | H11: =IF(Captura_Pegaso!A12="", "", Captura_Pegaso!H12) | I11: =IF(Captura_Pegaso!A12="", "", SUMIFS(Captura_Obra!$F:$F, Captura_Obra!$A:$A, E11, Captura_Obra!$B:$B, F11, Captura_Obra!$D:$D, G11)) | J11: =IF(Captura_Pegaso!A12="", "", H11 - I11)
A12: =IF(Captura_Pegaso!A13="", "", "Pegaso") | B12: =IF(Captura_Pegaso!A13="", "", Captura_Pegaso!N13) | C12: =IF(Captura_Pegaso!A13="", "", IFERROR(LOOKUP(2, 1/((Captura_Obra!$A$5:$A$1000=E12)*(Captura_Obra!$B$5:$B$1000=F12)*(Captura_Obra!$D$5:$D$1000=G12)), Captura_Obra!$N$5:$N$1000), "No Reportado")) | D12: =IF(Captura_Pegaso!A13="", "", IF(J12=0, "✅ Cuadrado", IF(I12=0, "❌ Falta en Obra", "⚠️ Dif"))) | E12: =IF(Captura_Pegaso!A13="", "", Captura_Pegaso!A13) | F12: =IF(Captura_Pegaso!A13="", "", Captura_Pegaso!D13) | G12: =IF(Captura_Pegaso!A13="", "", Captura_Pegaso!E13) | H12: =IF(Captura_Pegaso!A13="", "", Captura_Pegaso!H13) | I12: =IF(Captura_Pegaso!A13="", "", SUMIFS(Captura_Obra!$F:$F, Captura_Obra!$A:$A, E12, Captura_Obra!$B:$B, F12, Captura_Obra!$D:$D, G12)) | J12: =IF(Captura_Pegaso!A13="", "", H12 - I12)
A13: =IF(Captura_Pegaso!A14="", "", "Pegaso") | B13: =IF(Captura_Pegaso!A14="", "", Captura_Pegaso!N14) | C13: =IF(Captura_Pegaso!A14="", "", IFERROR(LOOKUP(2, 1/((Captura_Obra!$A$5:$A$1000=E13)*(Captura_Obra!$B$5:$B$1000=F13)*(Captura_Obra!$D$5:$D$1000=G13)), Captura_Obra!$N$5:$N$1000), "No Reportado")) | D13: =IF(Captura_Pegaso!A14="", "", IF(J13=0, "✅ Cuadrado", IF(I13=0, "❌ Falta en Obra", "⚠️ Dif"))) | E13: =IF(Captura_Pegaso!A14="", "", Captura_Pegaso!A14) | F13: =IF(Captura_Pegaso!A14="", "", Captura_Pegaso!D14) | G13: =IF(Captura_Pegaso!A14="", "", Captura_Pegaso!E14) | H13: =IF(Captura_Pegaso!A14="", "", Captura_Pegaso!H14) | I13: =IF(Captura_Pegaso!A14="", "", SUMIFS(Captura_Obra!$F:$F, Captura_Obra!$A:$A, E13, Captura_Obra!$B:$B, F13, Captura_Obra!$D:$D, G13)) | J13: =IF(Captura_Pegaso!A14="", "", H13 - I13)
A14: =IF(Captura_Pegaso!A15="", "", "Pegaso") | B14: =IF(Captura_Pegaso!A15="", "", Captura_Pegaso!N15) | C14: =IF(Captura_Pegaso!A15="", "", IFERROR(LOOKUP(2, 1/((Captura_Obra!$A$5:$A$1000=E14)*(Captura_Obra!$B$5:$B$1000=F14)*(Captura_Obra!$D$5:$D$1000=G14)), Captura_Obra!$N$5:$N$1000), "No Reportado")) | D14: =IF(Captura_Pegaso!A15="", "", IF(J14=0, "✅ Cuadrado", IF(I14=0, "❌ Falta en Obra", "⚠️ Dif"))) | E14: =IF(Captura_Pegaso!A15="", "", Captura_Pegaso!A15) | F14: =IF(Captura_Pegaso!A15="", "", Captura_Pegaso!D15) | G14: =IF(Captura_Pegaso!A15="", "", Captura_Pegaso!E15) | H14: =IF(Captura_Pegaso!A15="", "", Captura_Pegaso!H15) | I14: =IF(Captura_Pegaso!A15="", "", SUMIFS(Captura_Obra!$F:$F, Captura_Obra!$A:$A, E14, Captura_Obra!$B:$B, F14, Captura_Obra!$D:$D, G14)) | J14: =IF(Captura_Pegaso!A15="", "", H14 - I14)
A15: =IF(Captura_Pegaso!A16="", "", "Pegaso") | B15: =IF(Captura_Pegaso!A16="", "", Captura_Pegaso!N16) | C15: =IF(Captura_Pegaso!A16="", "", IFERROR(LOOKUP(2, 1/((Captura_Obra!$A$5:$A$1000=E15)*(Captura_Obra!$B$5:$B$1000=F15)*(Captura_Obra!$D$5:$D$1000=G15)), Captura_Obra!$N$5:$N$1000), "No Reportado")) | D15: =IF(Captura_Pegaso!A16="", "", IF(J15=0, "✅ Cuadrado", IF(I15=0, "❌ Falta en Obra", "⚠️ Dif"))) | E15: =IF(Captura_Pegaso!A16="", "", Captura_Pegaso!A16) | F15: =IF(Captura_Pegaso!A16="", "", Captura_Pegaso!D16) | G15: =IF(Captura_Pegaso!A16="", "", Captura_Pegaso!E16) | H15: =IF(Captura_Pegaso!A16="", "", Captura_Pegaso!H16) | I15: =IF(Captura_Pegaso!A16="", "", SUMIFS(Captura_Obra!$F:$F, Captura_Obra!$A:$A, E15, Captura_Obra!$B:$B, F15, Captura_Obra!$D:$D, G15)) | J15: =IF(Captura_Pegaso!A16="", "", H15 - I15)
... A150: =IF(Captura_Pegaso!A151="", "", "Pegaso") | B150: =IF(Captura_Pegaso!A151="", "", Captura_Pegaso!N151) | C150: =IF(Captura_Pegaso!A151="", "", IFERROR(LOOKUP(2, 1/((Captura_Obra!$A$5:$A$1000=E150)*(Captura_Obra!$B$5:$B$1000=F150)*(Captura_Obra!$D$5:$D$1000=G150)), Captura_Obra!$N$5:$N$1000), "No Reportado")) | D150: =IF(Captura_Pegaso!A151="", "", IF(J150=0, "✅ Cuadrado", IF(I150=0, "❌ Falta en Obra", "⚠️ Dif"))) | E150: =IF(Captura_Pegaso!A151="", "", Captura_Pegaso!A151) | F150: =IF(Captura_Pegaso!A151="", "", Captura_Pegaso!D151) | G150: =IF(Captura_Pegaso!A151="", "", Captura_Pegaso!E151) | H150: =IF(Captura_Pegaso!A151="", "", Captura_Pegaso!H151) | I150: =IF(Captura_Pegaso!A151="", "", SUMIFS(Captura_Obra!$F:$F, Captura_Obra!$A:$A, E150, Captura_Obra!$B:$B, F150, Captura_Obra!$D:$D, G150)) | J150: =IF(Captura_Pegaso!A151="", "", H150 - I150)
A151: =IF(Captura_Marimba_M01!A5="", "", "Marimba") | B151: =IF(Captura_Marimba_M01!A5="", "", Captura_Marimba_M01!N5) | C151: =IF(Captura_Marimba_M01!A5="", "", IFERROR(LOOKUP(2, 1/((Captura_Obra!$A$5:$A$1000=E151)*(Captura_Obra!$B$5:$B$1000=F151)*(Captura_Obra!$D$5:$D$1000=G151)), Captura_Obra!$N$5:$N$1000), "No Reportado")) | D151: =IF(Captura_Marimba_M01!A5="", "", IF(J151=0, "✅ Cuadrado", IF(I151=0, "❌ Falta en Obra", "⚠️ Dif"))) | E151: =IF(Captura_Marimba_M01!A5="", "", Captura_Marimba_M01!A5) | F151: =IF(Captura_Marimba_M01!A5="", "", Captura_Marimba_M01!C5) | G151: =IF(Captura_Marimba_M01!A5="", "", Captura_Marimba_M01!D5) | H151: =IF(Captura_Marimba_M01!A5="", "", Captura_Marimba_M01!G5) | I151: =IF(Captura_Marimba_M01!A5="", "", SUMIFS(Captura_Obra!$F:$F, Captura_Obra!$A:$A, E151, Captura_Obra!$B:$B, F151, Captura_Obra!$D:$D, G151)) | J151: =IF(Captura_Marimba_M01!A5="", "", H151 - I151)
A152: =IF(Captura_Marimba_M01!A6="", "", "Marimba") | B152: =IF(Captura_Marimba_M01!A6="", "", Captura_Marimba_M01!N6) | C152: =IF(Captura_Marimba_M01!A6="", "", IFERROR(LOOKUP(2, 1/((Captura_Obra!$A$5:$A$1000=E152)*(Captura_Obra!$B$5:$B$1000=F152)*(Captura_Obra!$D$5:$D$1000=G152)), Captura_Obra!$N$5:$N$1000), "No Reportado")) | D152: =IF(Captura_Marimba_M01!A6="", "", IF(J152=0, "✅ Cuadrado", IF(I152=0, "❌ Falta en Obra", "⚠️ Dif"))) | E152: =IF(Captura_Marimba_M01!A6="", "", Captura_Marimba_M01!A6) | F152: =IF(Captura_Marimba_M01!A6="", "", Captura_Marimba_M01!C6) | G152: =IF(Captura_Marimba_M01!A6="", "", Captura_Marimba_M01!D6) | H152: =IF(Captura_Marimba_M01!A6="", "", Captura_Marimba_M01!G6) | I152: =IF(Captura_Marimba_M01!A6="", "", SUMIFS(Captura_Obra!$F:$F, Captura_Obra!$A:$A, E152, Captura_Obra!$B:$B, F152, Captura_Obra!$D:$D, G152)) | J152: =IF(Captura_Marimba_M01!A6="", "", H152 - I152)
A153: =IF(Captura_Marimba_M01!A7="", "", "Marimba") | B153: =IF(Captura_Marimba_M01!A7="", "", Captura_Marimba_M01!N7) | C153: =IF(Captura_Marimba_M01!A7="", "", IFERROR(LOOKUP(2, 1/((Captura_Obra!$A$5:$A$1000=E153)*(Captura_Obra!$B$5:$B$1000=F153)*(Captura_Obra!$D$5:$D$1000=G153)), Captura_Obra!$N$5:$N$1000), "No Reportado")) | D153: =IF(Captura_Marimba_M01!A7="", "", IF(J153=0, "✅ Cuadrado", IF(I153=0, "❌ Falta en Obra", "⚠️ Dif"))) | E153: =IF(Captura_Marimba_M01!A7="", "", Captura_Marimba_M01!A7) | F153: =IF(Captura_Marimba_M01!A7="", "", Captura_Marimba_M01!C7) | G153: =IF(Captura_Marimba_M01!A7="", "", Captura_Marimba_M01!D7) | H153: =IF(Captura_Marimba_M01!A7="", "", Captura_Marimba_M01!G7) | I153: =IF(Captura_Marimba_M01!A7="", "", SUMIFS(Captura_Obra!$F:$F, Captura_Obra!$A:$A, E153, Captura_Obra!$B:$B, F153, Captura_Obra!$D:$D, G153)) | J153: =IF(Captura_Marimba_M01!A7="", "", H153 - I153)
A154: =IF(Captura_Marimba_M01!A8="", "", "Marimba") | B154: =IF(Captura_Marimba_M01!A8="", "", Captura_Marimba_M01!N8) | C154: =IF(Captura_Marimba_M01!A8="", "", IFERROR(LOOKUP(2, 1/((Captura_Obra!$A$5:$A$1000=E154)*(Captura_Obra!$B$5:$B$1000=F154)*(Captura_Obra!$D$5:$D$1000=G154)), Captura_Obra!$N$5:$N$1000), "No Reportado")) | D154: =IF(Captura_Marimba_M01!A8="", "", IF(J154=0, "✅ Cuadrado", IF(I154=0, "❌ Falta en Obra", "⚠️ Dif"))) | E154: =IF(Captura_Marimba_M01!A8="", "", Captura_Marimba_M01!A8) | F154: =IF(Captura_Marimba_M01!A8="", "", Captura_Marimba_M01!C8) | G154: =IF(Captura_Marimba_M01!A8="", "", Captura_Marimba_M01!D8) | H154: =IF(Captura_Marimba_M01!A8="", "", Captura_Marimba_M01!G8) | I154: =IF(Captura_Marimba_M01!A8="", "", SUMIFS(Captura_Obra!$F:$F, Captura_Obra!$A:$A, E154, Captura_Obra!$B:$B, F154, Captura_Obra!$D:$D, G154)) | J154: =IF(Captura_Marimba_M01!A8="", "", H154 - I154)
A155: =IF(Captura_Marimba_M01!A9="", "", "Marimba") | B155: =IF(Captura_Marimba_M01!A9="", "", Captura_Marimba_M01!N9) | C155: =IF(Captura_Marimba_M01!A9="", "", IFERROR(LOOKUP(2, 1/((Captura_Obra!$A$5:$A$1000=E155)*(Captura_Obra!$B$5:$B$1000=F155)*(Captura_Obra!$D$5:$D$1000=G155)), Captura_Obra!$N$5:$N$1000), "No Reportado")) | D155: =IF(Captura_Marimba_M01!A9="", "", IF(J155=0, "✅ Cuadrado", IF(I155=0, "❌ Falta en Obra", "⚠️ Dif"))) | E155: =IF(Captura_Marimba_M01!A9="", "", Captura_Marimba_M01!A9) | F155: =IF(Captura_Marimba_M01!A9="", "", Captura_Marimba_M01!C9) | G155: =IF(Captura_Marimba_M01!A9="", "", Captura_Marimba_M01!D9) | H155: =IF(Captura_Marimba_M01!A9="", "", Captura_Marimba_M01!G9) | I155: =IF(Captura_Marimba_M01!A9="", "", SUMIFS(Captura_Obra!$F:$F, Captura_Obra!$A:$A, E155, Captura_Obra!$B:$B, F155, Captura_Obra!$D:$D, G155)) | J155: =IF(Captura_Marimba_M01!A9="", "", H155 - I155)
A156: =IF(Captura_Marimba_M01!A10="", "", "Marimba") | B156: =IF(Captura_Marimba_M01!A10="", "", Captura_Marimba_M01!N10) | C156: =IF(Captura_Marimba_M01!A10="", "", IFERROR(LOOKUP(2, 1/((Captura_Obra!$A$5:$A$1000=E156)*(Captura_Obra!$B$5:$B$1000=F156)*(Captura_Obra!$D$5:$D$1000=G156)), Captura_Obra!$N$5:$N$1000), "No Reportado")) | D156: =IF(Captura_Marimba_M01!A10="", "", IF(J156=0, "✅ Cuadrado", IF(I156=0, "❌ Falta en Obra", "⚠️ Dif"))) | E156: =IF(Captura_Marimba_M01!A10="", "", Captura_Marimba_M01!A10) | F156: =IF(Captura_Marimba_M01!A10="", "", Captura_Marimba_M01!C10) | G156: =IF(Captura_Marimba_M01!A10="", "", Captura_Marimba_M01!D10) | H156: =IF(Captura_Marimba_M01!A10="", "", Captura_Marimba_M01!G10) | I156: =IF(Captura_Marimba_M01!A10="", "", SUMIFS(Captura_Obra!$F:$F, Captura_Obra!$A:$A, E156, Captura_Obra!$B:$B, F156, Captura_Obra!$D:$D, G156)) | J156: =IF(Captura_Marimba_M01!A10="", "", H156 - I156)
A157: =IF(Captura_Marimba_M01!A11="", "", "Marimba") | B157: =IF(Captura_Marimba_M01!A11="", "", Captura_Marimba_M01!N11) | C157: =IF(Captura_Marimba_M01!A11="", "", IFERROR(LOOKUP(2, 1/((Captura_Obra!$A$5:$A$1000=E157)*(Captura_Obra!$B$5:$B$1000=F157)*(Captura_Obra!$D$5:$D$1000=G157)), Captura_Obra!$N$5:$N$1000), "No Reportado")) | D157: =IF(Captura_Marimba_M01!A11="", "", IF(J157=0, "✅ Cuadrado", IF(I157=0, "❌ Falta en Obra", "⚠️ Dif"))) | E157: =IF(Captura_Marimba_M01!A11="", "", Captura_Marimba_M01!A11) | F157: =IF(Captura_Marimba_M01!A11="", "", Captura_Marimba_M01!C11) | G157: =IF(Captura_Marimba_M01!A11="", "", Captura_Marimba_M01!D11) | H157: =IF(Captura_Marimba_M01!A11="", "", Captura_Marimba_M01!G11) | I157: =IF(Captura_Marimba_M01!A11="", "", SUMIFS(Captura_Obra!$F:$F, Captura_Obra!$A:$A, E157, Captura_Obra!$B:$B, F157, Captura_Obra!$D:$D, G157)) | J157: =IF(Captura_Marimba_M01!A11="", "", H157 - I157)
A158: =IF(Captura_Marimba_M01!A12="", "", "Marimba") | B158: =IF(Captura_Marimba_M01!A12="", "", Captura_Marimba_M01!N12) | C158: =IF(Captura_Marimba_M01!A12="", "", IFERROR(LOOKUP(2, 1/((Captura_Obra!$A$5:$A$1000=E158)*(Captura_Obra!$B$5:$B$1000=F158)*(Captura_Obra!$D$5:$D$1000=G158)), Captura_Obra!$N$5:$N$1000), "No Reportado")) | D158: =IF(Captura_Marimba_M01!A12="", "", IF(J158=0, "✅ Cuadrado", IF(I158=0, "❌ Falta en Obra", "⚠️ Dif"))) | E158: =IF(Captura_Marimba_M01!A12="", "", Captura_Marimba_M01!A12) | F158: =IF(Captura_Marimba_M01!A12="", "", Captura_Marimba_M01!C12) | G158: =IF(Captura_Marimba_M01!A12="", "", Captura_Marimba_M01!D12) | H158: =IF(Captura_Marimba_M01!A12="", "", Captura_Marimba_M01!G12) | I158: =IF(Captura_Marimba_M01!A12="", "", SUMIFS(Captura_Obra!$F:$F, Captura_Obra!$A:$A, E158, Captura_Obra!$B:$B, F158, Captura_Obra!$D:$D, G158)) | J158: =IF(Captura_Marimba_M01!A12="", "", H158 - I158)
A159: =IF(Captura_Marimba_M01!A13="", "", "Marimba") | B159: =IF(Captura_Marimba_M01!A13="", "", Captura_Marimba_M01!N13) | C159: =IF(Captura_Marimba_M01!A13="", "", IFERROR(LOOKUP(2, 1/((Captura_Obra!$A$5:$A$1000=E159)*(Captura_Obra!$B$5:$B$1000=F159)*(Captura_Obra!$D$5:$D$1000=G159)), Captura_Obra!$N$5:$N$1000), "No Reportado")) | D159: =IF(Captura_Marimba_M01!A13="", "", IF(J159=0, "✅ Cuadrado", IF(I159=0, "❌ Falta en Obra", "⚠️ Dif"))) | E159: =IF(Captura_Marimba_M01!A13="", "", Captura_Marimba_M01!A13) | F159: =IF(Captura_Marimba_M01!A13="", "", Captura_Marimba_M01!C13) | G159: =IF(Captura_Marimba_M01!A13="", "", Captura_Marimba_M01!D13) | H159: =IF(Captura_Marimba_M01!A13="", "", Captura_Marimba_M01!G13) | I159: =IF(Captura_Marimba_M01!A13="", "", SUMIFS(Captura_Obra!$F:$F, Captura_Obra!$A:$A, E159, Captura_Obra!$B:$B, F159, Captura_Obra!$D:$D, G159)) | J159: =IF(Captura_Marimba_M01!A13="", "", H159 - I159)
A160: =IF(Captura_Marimba_M01!A14="", "", "Marimba") | B160: =IF(Captura_Marimba_M01!A14="", "", Captura_Marimba_M01!N14) | C160: =IF(Captura_Marimba_M01!A14="", "", IFERROR(LOOKUP(2, 1/((Captura_Obra!$A$5:$A$1000=E160)*(Captura_Obra!$B$5:$B$1000=F160)*(Captura_Obra!$D$5:$D$1000=G160)), Captura_Obra!$N$5:$N$1000), "No Reportado")) | D160: =IF(Captura_Marimba_M01!A14="", "", IF(J160=0, "✅ Cuadrado", IF(I160=0, "❌ Falta en Obra", "⚠️ Dif"))) | E160: =IF(Captura_Marimba_M01!A14="", "", Captura_Marimba_M01!A14) | F160: =IF(Captura_Marimba_M01!A14="", "", Captura_Marimba_M01!C14) | G160: =IF(Captura_Marimba_M01!A14="", "", Captura_Marimba_M01!D14) | H160: =IF(Captura_Marimba_M01!A14="", "", Captura_Marimba_M01!G14) | I160: =IF(Captura_Marimba_M01!A14="", "", SUMIFS(Captura_Obra!$F:$F, Captura_Obra!$A:$A, E160, Captura_Obra!$B:$B, F160, Captura_Obra!$D:$D, G160)) | J160: =IF(Captura_Marimba_M01!A14="", "", H160 - I160)
A161: =IF(Captura_Marimba_M01!A15="", "", "Marimba") | B161: =IF(Captura_Marimba_M01!A15="", "", Captura_Marimba_M01!N15) | C161: =IF(Captura_Marimba_M01!A15="", "", IFERROR(LOOKUP(2, 1/((Captura_Obra!$A$5:$A$1000=E161)*(Captura_Obra!$B$5:$B$1000=F161)*(Captura_Obra!$D$5:$D$1000=G161)), Captura_Obra!$N$5:$N$1000), "No Reportado")) | D161: =IF(Captura_Marimba_M01!A15="", "", IF(J161=0, "✅ Cuadrado", IF(I161=0, "❌ Falta en Obra", "⚠️ Dif"))) | E161: =IF(Captura_Marimba_M01!A15="", "", Captura_Marimba_M01!A15) | F161: =IF(Captura_Marimba_M01!A15="", "", Captura_Marimba_M01!C15) | G161: =IF(Captura_Marimba_M01!A15="", "", Captura_Marimba_M01!D15) | H161: =IF(Captura_Marimba_M01!A15="", "", Captura_Marimba_M01!G15) | I161: =IF(Captura_Marimba_M01!A15="", "", SUMIFS(Captura_Obra!$F:$F, Captura_Obra!$A:$A, E161, Captura_Obra!$B:$B, F161, Captura_Obra!$D:$D, G161)) | J161: =IF(Captura_Marimba_M01!A15="", "", H161 - I161)
A162: =IF(Captura_Marimba_M01!A16="", "", "Marimba") | B162: =IF(Captura_Marimba_M01!A16="", "", Captura_Marimba_M01!N16) | C162: =IF(Captura_Marimba_M01!A16="", "", IFERROR(LOOKUP(2, 1/((Captura_Obra!$A$5:$A$1000=E162)*(Captura_Obra!$B$5:$B$1000=F162)*(Captura_Obra!$D$5:$D$1000=G162)), Captura_Obra!$N$5:$N$1000), "No Reportado")) | D162: =IF(Captura_Marimba_M01!A16="", "", IF(J162=0, "✅ Cuadrado", IF(I162=0, "❌ Falta en Obra", "⚠️ Dif"))) | E162: =IF(Captura_Marimba_M01!A16="", "", Captura_Marimba_M01!A16) | F162: =IF(Captura_Marimba_M01!A16="", "", Captura_Marimba_M01!C16) | G162: =IF(Captura_Marimba_M01!A16="", "", Captura_Marimba_M01!D16) | H162: =IF(Captura_Marimba_M01!A16="", "", Captura_Marimba_M01!G16) | I162: =IF(Captura_Marimba_M01!A16="", "", SUMIFS(Captura_Obra!$F:$F, Captura_Obra!$A:$A, E162, Captura_Obra!$B:$B, F162, Captura_Obra!$D:$D, G162)) | J162: =IF(Captura_Marimba_M01!A16="", "", H162 - I162)
... A300: =IF(Captura_Marimba_M01!A154="", "", "Marimba") | B300: =IF(Captura_Marimba_M01!A154="", "", Captura_Marimba_M01!N154) | C300: =IF(Captura_Marimba_M01!A154="", "", IFERROR(LOOKUP(2, 1/((Captura_Obra!$A$5:$A$1000=E300)*(Captura_Obra!$B$5:$B$1000=F300)*(Captura_Obra!$D$5:$D$1000=G300)), Captura_Obra!$N$5:$N$1000), "No Reportado")) | D300: =IF(Captura_Marimba_M01!A154="", "", IF(J300=0, "✅ Cuadrado", IF(I300=0, "❌ Falta en Obra", "⚠️ Dif"))) | E300: =IF(Captura_Marimba_M01!A154="", "", Captura_Marimba_M01!A154) | F300: =IF(Captura_Marimba_M01!A154="", "", Captura_Marimba_M01!C154) | G300: =IF(Captura_Marimba_M01!A154="", "", Captura_Marimba_M01!D154) | H300: =IF(Captura_Marimba_M01!A154="", "", Captura_Marimba_M01!G154) | I300: =IF(Captura_Marimba_M01!A154="", "", SUMIFS(Captura_Obra!$F:$F, Captura_Obra!$A:$A, E300, Captura_Obra!$B:$B, F300, Captura_Obra!$D:$D, G300)) | J300: =IF(Captura_Marimba_M01!A154="", "", H300 - I300)
A301: =IF(OR(Captura_Obra!A5="", (SUMIFS(Captura_Pegaso!$H:$H, Captura_Pegaso!$A:$A, Captura_Obra!A5, Captura_Pegaso!$D:$D, Captura_Obra!B5, Captura_Pegaso!$E:$E, Captura_Obra!D5) + SUMIFS(Captura_Marimba_M01!$G:$G, Captura_Marimba_M01!$A:$A, Captura_Obra!A5, Captura_Marimba_M01!$C:$C, Captura_Obra!B5, Captura_Marimba_M01!$D:$D, Captura_Obra!D5))>0), "", "Huérfano Obra") | B301: =IF(OR(Captura_Obra!A5="", (SUMIFS(Captura_Pegaso!$H:$H, Captura_Pegaso!$A:$A, Captura_Obra!A5, Captura_Pegaso!$D:$D, Captura_Obra!B5, Captura_Pegaso!$E:$E, Captura_Obra!D5) + SUMIFS(Captura_Marimba_M01!$G:$G, Captura_Marimba_M01!$A:$A, Captura_Obra!A5, Captura_Marimba_M01!$C:$C, Captura_Obra!B5, Captura_Marimba_M01!$D:$D, Captura_Obra!D5))>0), "", "No Reportado") | C301: =IF(OR(Captura_Obra!A5="", (SUMIFS(Captura_Pegaso!$H:$H, Captura_Pegaso!$A:$A, Captura_Obra!A5, Captura_Pegaso!$D:$D, Captura_Obra!B5, Captura_Pegaso!$E:$E, Captura_Obra!D5) + SUMIFS(Captura_Marimba_M01!$G:$G, Captura_Marimba_M01!$A:$A, Captura_Obra!A5, Captura_Marimba_M01!$C:$C, Captura_Obra!B5, Captura_Marimba_M01!$D:$D, Captura_Obra!D5))>0), "", Captura_Obra!N5) | D301: =IF(OR(Captura_Obra!A5="", (SUMIFS(Captura_Pegaso!$H:$H, Captura_Pegaso!$A:$A, Captura_Obra!A5, Captura_Pegaso!$D:$D, Captura_Obra!B5, Captura_Pegaso!$E:$E, Captura_Obra!D5) + SUMIFS(Captura_Marimba_M01!$G:$G, Captura_Marimba_M01!$A:$A, Captura_Obra!A5, Captura_Marimba_M01!$C:$C, Captura_Obra!B5, Captura_Marimba_M01!$D:$D, Captura_Obra!D5))>0), "", "❌ Falta en Pipa") | E301: =IF(OR(Captura_Obra!A5="", (SUMIFS(Captura_Pegaso!$H:$H, Captura_Pegaso!$A:$A, Captura_Obra!A5, Captura_Pegaso!$D:$D, Captura_Obra!B5, Captura_Pegaso!$E:$E, Captura_Obra!D5) + SUMIFS(Captura_Marimba_M01!$G:$G, Captura_Marimba_M01!$A:$A, Captura_Obra!A5, Captura_Marimba_M01!$C:$C, Captura_Obra!B5, Captura_Marimba_M01!$D:$D, Captura_Obra!D5))>0), "", Captura_Obra!A5) | F301: =IF(OR(Captura_Obra!A5="", (SUMIFS(Captura_Pegaso!$H:$H, Captura_Pegaso!$A:$A, Captura_Obra!A5, Captura_Pegaso!$D:$D, Captura_Obra!B5, Captura_Pegaso!$E:$E, Captura_Obra!D5) + SUMIFS(Captura_Marimba_M01!$G:$G, Captura_Marimba_M01!$A:$A, Captura_Obra!A5, Captura_Marimba_M01!$C:$C, Captura_Obra!B5, Captura_Marimba_M01!$D:$D, Captura_Obra!D5))>0), "", Captura_Obra!B5) | G301: =IF(OR(Captura_Obra!A5="", (SUMIFS(Captura_Pegaso!$H:$H, Captura_Pegaso!$A:$A, Captura_Obra!A5, Captura_Pegaso!$D:$D, Captura_Obra!B5, Captura_Pegaso!$E:$E, Captura_Obra!D5) + SUMIFS(Captura_Marimba_M01!$G:$G, Captura_Marimba_M01!$A:$A, Captura_Obra!A5, Captura_Marimba_M01!$C:$C, Captura_Obra!B5, Captura_Marimba_M01!$D:$D, Captura_Obra!D5))>0), "", Captura_Obra!D5) | H301: =IF(OR(Captura_Obra!A5="", (SUMIFS(Captura_Pegaso!$H:$H, Captura_Pegaso!$A:$A, Captura_Obra!A5, Captura_Pegaso!$D:$D, Captura_Obra!B5, Captura_Pegaso!$E:$E, Captura_Obra!D5) + SUMIFS(Captura_Marimba_M01!$G:$G, Captura_Marimba_M01!$A:$A, Captura_Obra!A5, Captura_Marimba_M01!$C:$C, Captura_Obra!B5, Captura_Marimba_M01!$D:$D, Captura_Obra!D5))>0), "", 0) | I301: =IF(OR(Captura_Obra!A5="", (SUMIFS(Captura_Pegaso!$H:$H, Captura_Pegaso!$A:$A, Captura_Obra!A5, Captura_Pegaso!$D:$D, Captura_Obra!B5, Captura_Pegaso!$E:$E, Captura_Obra!D5) + SUMIFS(Captura_Marimba_M01!$G:$G, Captura_Marimba_M01!$A:$A, Captura_Obra!A5, Captura_Marimba_M01!$C:$C, Captura_Obra!B5, Captura_Marimba_M01!$D:$D, Captura_Obra!D5))>0), "", Captura_Obra!F5) | J301: =IF(OR(Captura_Obra!A5="", (SUMIFS(Captura_Pegaso!$H:$H, Captura_Pegaso!$A:$A, Captura_Obra!A5, Captura_Pegaso!$D:$D, Captura_Obra!B5, Captura_Pegaso!$E:$E, Captura_Obra!D5) + SUMIFS(Captura_Marimba_M01!$G:$G, Captura_Marimba_M01!$A:$A, Captura_Obra!A5, Captura_Marimba_M01!$C:$C, Captura_Obra!B5, Captura_Marimba_M01!$D:$D, Captura_Obra!D5))>0), "", H301 - I301)
A302: =IF(OR(Captura_Obra!A6="", (SUMIFS(Captura_Pegaso!$H:$H, Captura_Pegaso!$A:$A, Captura_Obra!A6, Captura_Pegaso!$D:$D, Captura_Obra!B6, Captura_Pegaso!$E:$E, Captura_Obra!D6) + SUMIFS(Captura_Marimba_M01!$G:$G, Captura_Marimba_M01!$A:$A, Captura_Obra!A6, Captura_Marimba_M01!$C:$C, Captura_Obra!B6, Captura_Marimba_M01!$D:$D, Captura_Obra!D6))>0), "", "Huérfano Obra") | B302: =IF(OR(Captura_Obra!A6="", (SUMIFS(Captura_Pegaso!$H:$H, Captura_Pegaso!$A:$A, Captura_Obra!A6, Captura_Pegaso!$D:$D, Captura_Obra!B6, Captura_Pegaso!$E:$E, Captura_Obra!D6) + SUMIFS(Captura_Marimba_M01!$G:$G, Captura_Marimba_M01!$A:$A, Captura_Obra!A6, Captura_Marimba_M01!$C:$C, Captura_Obra!B6, Captura_Marimba_M01!$D:$D, Captura_Obra!D6))>0), "", "No Reportado") | C302: =IF(OR(Captura_Obra!A6="", (SUMIFS(Captura_Pegaso!$H:$H, Captura_Pegaso!$A:$A, Captura_Obra!A6, Captura_Pegaso!$D:$D, Captura_Obra!B6, Captura_Pegaso!$E:$E, Captura_Obra!D6) + SUMIFS(Captura_Marimba_M01!$G:$G, Captura_Marimba_M01!$A:$A, Captura_Obra!A6, Captura_Marimba_M01!$C:$C, Captura_Obra!B6, Captura_Marimba_M01!$D:$D, Captura_Obra!D6))>0), "", Captura_Obra!N6) | D302: =IF(OR(Captura_Obra!A6="", (SUMIFS(Captura_Pegaso!$H:$H, Captura_Pegaso!$A:$A, Captura_Obra!A6, Captura_Pegaso!$D:$D, Captura_Obra!B6, Captura_Pegaso!$E:$E, Captura_Obra!D6) + SUMIFS(Captura_Marimba_M01!$G:$G, Captura_Marimba_M01!$A:$A, Captura_Obra!A6, Captura_Marimba_M01!$C:$C, Captura_Obra!B6, Captura_Marimba_M01!$D:$D, Captura_Obra!D6))>0), "", "❌ Falta en Pipa") | E302: =IF(OR(Captura_Obra!A6="", (SUMIFS(Captura_Pegaso!$H:$H, Captura_Pegaso!$A:$A, Captura_Obra!A6, Captura_Pegaso!$D:$D, Captura_Obra!B6, Captura_Pegaso!$E:$E, Captura_Obra!D6) + SUMIFS(Captura_Marimba_M01!$G:$G, Captura_Marimba_M01!$A:$A, Captura_Obra!A6, Captura_Marimba_M01!$C:$C, Captura_Obra!B6, Captura_Marimba_M01!$D:$D, Captura_Obra!D6))>0), "", Captura_Obra!A6) | F302: =IF(OR(Captura_Obra!A6="", (SUMIFS(Captura_Pegaso!$H:$H, Captura_Pegaso!$A:$A, Captura_Obra!A6, Captura_Pegaso!$D:$D, Captura_Obra!B6, Captura_Pegaso!$E:$E, Captura_Obra!D6) + SUMIFS(Captura_Marimba_M01!$G:$G, Captura_Marimba_M01!$A:$A, Captura_Obra!A6, Captura_Marimba_M01!$C:$C, Captura_Obra!B6, Captura_Marimba_M01!$D:$D, Captura_Obra!D6))>0), "", Captura_Obra!B6) | G302: =IF(OR(Captura_Obra!A6="", (SUMIFS(Captura_Pegaso!$H:$H, Captura_Pegaso!$A:$A, Captura_Obra!A6, Captura_Pegaso!$D:$D, Captura_Obra!B6, Captura_Pegaso!$E:$E, Captura_Obra!D6) + SUMIFS(Captura_Marimba_M01!$G:$G, Captura_Marimba_M01!$A:$A, Captura_Obra!A6, Captura_Marimba_M01!$C:$C, Captura_Obra!B6, Captura_Marimba_M01!$D:$D, Captura_Obra!D6))>0), "", Captura_Obra!D6) | H302: =IF(OR(Captura_Obra!A6="", (SUMIFS(Captura_Pegaso!$H:$H, Captura_Pegaso!$A:$A, Captura_Obra!A6, Captura_Pegaso!$D:$D, Captura_Obra!B6, Captura_Pegaso!$E:$E, Captura_Obra!D6) + SUMIFS(Captura_Marimba_M01!$G:$G, Captura_Marimba_M01!$A:$A, Captura_Obra!A6, Captura_Marimba_M01!$C:$C, Captura_Obra!B6, Captura_Marimba_M01!$D:$D, Captura_Obra!D6))>0), "", 0) | I302: =IF(OR(Captura_Obra!A6="", (SUMIFS(Captura_Pegaso!$H:$H, Captura_Pegaso!$A:$A, Captura_Obra!A6, Captura_Pegaso!$D:$D, Captura_Obra!B6, Captura_Pegaso!$E:$E, Captura_Obra!D6) + SUMIFS(Captura_Marimba_M01!$G:$G, Captura_Marimba_M01!$A:$A, Captura_Obra!A6, Captura_Marimba_M01!$C:$C, Captura_Obra!B6, Captura_Marimba_M01!$D:$D, Captura_Obra!D6))>0), "", Captura_Obra!F6) | J302: =IF(OR(Captura_Obra!A6="", (SUMIFS(Captura_Pegaso!$H:$H, Captura_Pegaso!$A:$A, Captura_Obra!A6, Captura_Pegaso!$D:$D, Captura_Obra!B6, Captura_Pegaso!$E:$E, Captura_Obra!D6) + SUMIFS(Captura_Marimba_M01!$G:$G, Captura_Marimba_M01!$A:$A, Captura_Obra!A6, Captura_Marimba_M01!$C:$C, Captura_Obra!B6, Captura_Marimba_M01!$D:$D, Captura_Obra!D6))>0), "", H302 - I302)
A303: =IF(OR(Captura_Obra!A7="", (SUMIFS(Captura_Pegaso!$H:$H, Captura_Pegaso!$A:$A, Captura_Obra!A7, Captura_Pegaso!$D:$D, Captura_Obra!B7, Captura_Pegaso!$E:$E, Captura_Obra!D7) + SUMIFS(Captura_Marimba_M01!$G:$G, Captura_Marimba_M01!$A:$A, Captura_Obra!A7, Captura_Marimba_M01!$C:$C, Captura_Obra!B7, Captura_Marimba_M01!$D:$D, Captura_Obra!D7))>0), "", "Huérfano Obra") | B303: =IF(OR(Captura_Obra!A7="", (SUMIFS(Captura_Pegaso!$H:$H, Captura_Pegaso!$A:$A, Captura_Obra!A7, Captura_Pegaso!$D:$D, Captura_Obra!B7, Captura_Pegaso!$E:$E, Captura_Obra!D7) + SUMIFS(Captura_Marimba_M01!$G:$G, Captura_Marimba_M01!$A:$A, Captura_Obra!A7, Captura_Marimba_M01!$C:$C, Captura_Obra!B7, Captura_Marimba_M01!$D:$D, Captura_Obra!D7))>0), "", "No Reportado") | C303: =IF(OR(Captura_Obra!A7="", (SUMIFS(Captura_Pegaso!$H:$H, Captura_Pegaso!$A:$A, Captura_Obra!A7, Captura_Pegaso!$D:$D, Captura_Obra!B7, Captura_Pegaso!$E:$E, Captura_Obra!D7) + SUMIFS(Captura_Marimba_M01!$G:$G, Captura_Marimba_M01!$A:$A, Captura_Obra!A7, Captura_Marimba_M01!$C:$C, Captura_Obra!B7, Captura_Marimba_M01!$D:$D, Captura_Obra!D7))>0), "", Captura_Obra!N7) | D303: =IF(OR(Captura_Obra!A7="", (SUMIFS(Captura_Pegaso!$H:$H, Captura_Pegaso!$A:$A, Captura_Obra!A7, Captura_Pegaso!$D:$D, Captura_Obra!B7, Captura_Pegaso!$E:$E, Captura_Obra!D7) + SUMIFS(Captura_Marimba_M01!$G:$G, Captura_Marimba_M01!$A:$A, Captura_Obra!A7, Captura_Marimba_M01!$C:$C, Captura_Obra!B7, Captura_Marimba_M01!$D:$D, Captura_Obra!D7))>0), "", "❌ Falta en Pipa") | E303: =IF(OR(Captura_Obra!A7="", (SUMIFS(Captura_Pegaso!$H:$H, Captura_Pegaso!$A:$A, Captura_Obra!A7, Captura_Pegaso!$D:$D, Captura_Obra!B7, Captura_Pegaso!$E:$E, Captura_Obra!D7) + SUMIFS(Captura_Marimba_M01!$G:$G, Captura_Marimba_M01!$A:$A, Captura_Obra!A7, Captura_Marimba_M01!$C:$C, Captura_Obra!B7, Captura_Marimba_M01!$D:$D, Captura_Obra!D7))>0), "", Captura_Obra!A7) | F303: =IF(OR(Captura_Obra!A7="", (SUMIFS(Captura_Pegaso!$H:$H, Captura_Pegaso!$A:$A, Captura_Obra!A7, Captura_Pegaso!$D:$D, Captura_Obra!B7, Captura_Pegaso!$E:$E, Captura_Obra!D7) + SUMIFS(Captura_Marimba_M01!$G:$G, Captura_Marimba_M01!$A:$A, Captura_Obra!A7, Captura_Marimba_M01!$C:$C, Captura_Obra!B7, Captura_Marimba_M01!$D:$D, Captura_Obra!D7))>0), "", Captura_Obra!B7) | G303: =IF(OR(Captura_Obra!A7="", (SUMIFS(Captura_Pegaso!$H:$H, Captura_Pegaso!$A:$A, Captura_Obra!A7, Captura_Pegaso!$D:$D, Captura_Obra!B7, Captura_Pegaso!$E:$E, Captura_Obra!D7) + SUMIFS(Captura_Marimba_M01!$G:$G, Captura_Marimba_M01!$A:$A, Captura_Obra!A7, Captura_Marimba_M01!$C:$C, Captura_Obra!B7, Captura_Marimba_M01!$D:$D, Captura_Obra!D7))>0), "", Captura_Obra!D7) | H303: =IF(OR(Captura_Obra!A7="", (SUMIFS(Captura_Pegaso!$H:$H, Captura_Pegaso!$A:$A, Captura_Obra!A7, Captura_Pegaso!$D:$D, Captura_Obra!B7, Captura_Pegaso!$E:$E, Captura_Obra!D7) + SUMIFS(Captura_Marimba_M01!$G:$G, Captura_Marimba_M01!$A:$A, Captura_Obra!A7, Captura_Marimba_M01!$C:$C, Captura_Obra!B7, Captura_Marimba_M01!$D:$D, Captura_Obra!D7))>0), "", 0) | I303: =IF(OR(Captura_Obra!A7="", (SUMIFS(Captura_Pegaso!$H:$H, Captura_Pegaso!$A:$A, Captura_Obra!A7, Captura_Pegaso!$D:$D, Captura_Obra!B7, Captura_Pegaso!$E:$E, Captura_Obra!D7) + SUMIFS(Captura_Marimba_M01!$G:$G, Captura_Marimba_M01!$A:$A, Captura_Obra!A7, Captura_Marimba_M01!$C:$C, Captura_Obra!B7, Captura_Marimba_M01!$D:$D, Captura_Obra!D7))>0), "", Captura_Obra!F7) | J303: =IF(OR(Captura_Obra!A7="", (SUMIFS(Captura_Pegaso!$H:$H, Captura_Pegaso!$A:$A, Captura_Obra!A7, Captura_Pegaso!$D:$D, Captura_Obra!B7, Captura_Pegaso!$E:$E, Captura_Obra!D7) + SUMIFS(Captura_Marimba_M01!$G:$G, Captura_Marimba_M01!$A:$A, Captura_Obra!A7, Captura_Marimba_M01!$C:$C, Captura_Obra!B7, Captura_Marimba_M01!$D:$D, Captura_Obra!D7))>0), "", H303 - I303)
A304: =IF(OR(Captura_Obra!A8="", (SUMIFS(Captura_Pegaso!$H:$H, Captura_Pegaso!$A:$A, Captura_Obra!A8, Captura_Pegaso!$D:$D, Captura_Obra!B8, Captura_Pegaso!$E:$E, Captura_Obra!D8) + SUMIFS(Captura_Marimba_M01!$G:$G, Captura_Marimba_M01!$A:$A, Captura_Obra!A8, Captura_Marimba_M01!$C:$C, Captura_Obra!B8, Captura_Marimba_M01!$D:$D, Captura_Obra!D8))>0), "", "Huérfano Obra") | B304: =IF(OR(Captura_Obra!A8="", (SUMIFS(Captura_Pegaso!$H:$H, Captura_Pegaso!$A:$A, Captura_Obra!A8, Captura_Pegaso!$D:$D, Captura_Obra!B8, Captura_Pegaso!$E:$E, Captura_Obra!D8) + SUMIFS(Captura_Marimba_M01!$G:$G, Captura_Marimba_M01!$A:$A, Captura_Obra!A8, Captura_Marimba_M01!$C:$C, Captura_Obra!B8, Captura_Marimba_M01!$D:$D, Captura_Obra!D8))>0), "", "No Reportado") | C304: =IF(OR(Captura_Obra!A8="", (SUMIFS(Captura_Pegaso!$H:$H, Captura_Pegaso!$A:$A, Captura_Obra!A8, Captura_Pegaso!$D:$D, Captura_Obra!B8, Captura_Pegaso!$E:$E, Captura_Obra!D8) + SUMIFS(Captura_Marimba_M01!$G:$G, Captura_Marimba_M01!$A:$A, Captura_Obra!A8, Captura_Marimba_M01!$C:$C, Captura_Obra!B8, Captura_Marimba_M01!$D:$D, Captura_Obra!D8))>0), "", Captura_Obra!N8) | D304: =IF(OR(Captura_Obra!A8="", (SUMIFS(Captura_Pegaso!$H:$H, Captura_Pegaso!$A:$A, Captura_Obra!A8, Captura_Pegaso!$D:$D, Captura_Obra!B8, Captura_Pegaso!$E:$E, Captura_Obra!D8) + SUMIFS(Captura_Marimba_M01!$G:$G, Captura_Marimba_M01!$A:$A, Captura_Obra!A8, Captura_Marimba_M01!$C:$C, Captura_Obra!B8, Captura_Marimba_M01!$D:$D, Captura_Obra!D8))>0), "", "❌ Falta en Pipa") | E304: =IF(OR(Captura_Obra!A8="", (SUMIFS(Captura_Pegaso!$H:$H, Captura_Pegaso!$A:$A, Captura_Obra!A8, Captura_Pegaso!$D:$D, Captura_Obra!B8, Captura_Pegaso!$E:$E, Captura_Obra!D8) + SUMIFS(Captura_Marimba_M01!$G:$G, Captura_Marimba_M01!$A:$A, Captura_Obra!A8, Captura_Marimba_M01!$C:$C, Captura_Obra!B8, Captura_Marimba_M01!$D:$D, Captura_Obra!D8))>0), "", Captura_Obra!A8) | F304: =IF(OR(Captura_Obra!A8="", (SUMIFS(Captura_Pegaso!$H:$H, Captura_Pegaso!$A:$A, Captura_Obra!A8, Captura_Pegaso!$D:$D, Captura_Obra!B8, Captura_Pegaso!$E:$E, Captura_Obra!D8) + SUMIFS(Captura_Marimba_M01!$G:$G, Captura_Marimba_M01!$A:$A, Captura_Obra!A8, Captura_Marimba_M01!$C:$C, Captura_Obra!B8, Captura_Marimba_M01!$D:$D, Captura_Obra!D8))>0), "", Captura_Obra!B8) | G304: =IF(OR(Captura_Obra!A8="", (SUMIFS(Captura_Pegaso!$H:$H, Captura_Pegaso!$A:$A, Captura_Obra!A8, Captura_Pegaso!$D:$D, Captura_Obra!B8, Captura_Pegaso!$E:$E, Captura_Obra!D8) + SUMIFS(Captura_Marimba_M01!$G:$G, Captura_Marimba_M01!$A:$A, Captura_Obra!A8, Captura_Marimba_M01!$C:$C, Captura_Obra!B8, Captura_Marimba_M01!$D:$D, Captura_Obra!D8))>0), "", Captura_Obra!D8) | H304: =IF(OR(Captura_Obra!A8="", (SUMIFS(Captura_Pegaso!$H:$H, Captura_Pegaso!$A:$A, Captura_Obra!A8, Captura_Pegaso!$D:$D, Captura_Obra!B8, Captura_Pegaso!$E:$E, Captura_Obra!D8) + SUMIFS(Captura_Marimba_M01!$G:$G, Captura_Marimba_M01!$A:$A, Captura_Obra!A8, Captura_Marimba_M01!$C:$C, Captura_Obra!B8, Captura_Marimba_M01!$D:$D, Captura_Obra!D8))>0), "", 0) | I304: =IF(OR(Captura_Obra!A8="", (SUMIFS(Captura_Pegaso!$H:$H, Captura_Pegaso!$A:$A, Captura_Obra!A8, Captura_Pegaso!$D:$D, Captura_Obra!B8, Captura_Pegaso!$E:$E, Captura_Obra!D8) + SUMIFS(Captura_Marimba_M01!$G:$G, Captura_Marimba_M01!$A:$A, Captura_Obra!A8, Captura_Marimba_M01!$C:$C, Captura_Obra!B8, Captura_Marimba_M01!$D:$D, Captura_Obra!D8))>0), "", Captura_Obra!F8) | J304: =IF(OR(Captura_Obra!A8="", (SUMIFS(Captura_Pegaso!$H:$H, Captura_Pegaso!$A:$A, Captura_Obra!A8, Captura_Pegaso!$D:$D, Captura_Obra!B8, Captura_Pegaso!$E:$E, Captura_Obra!D8) + SUMIFS(Captura_Marimba_M01!$G:$G, Captura_Marimba_M01!$A:$A, Captura_Obra!A8, Captura_Marimba_M01!$C:$C, Captura_Obra!B8, Captura_Marimba_M01!$D:$D, Captura_Obra!D8))>0), "", H304 - I304)
