Workbook

Sheet Dashboard
A1: DASHBOARD EJECUTIVO DE CONTROL DE COMBUSTIBLE | GRUPO TRUJANO
A3: FILTROS DEL DASHBOARD (Celdas en amarillo editables en Excel) | E3: ESTADO DE LA CONCILIACIÓN SEMANAL
B4: Obra Seleccionada: | C4: Lerma - Tres Marías | E4: =IF(I28=0, "🟢 TODO COINCIDE (0 L)", "🔴 DISCREPANCIA: " & I28 & " L")
B5: Fecha Inicio (Lunes): | C5: 46188
B6: Fecha Fin (Rango): | C6: 46188
B7: Precio Diésel ($/L): | C7: 28.3
B8: Período Resumen: | C8: Semana Seleccionada
A10: COMPARATIVA: SOLICITADO (PETICIONES) VS ENTREGADO EN OBRA
A11: Día | B11: Fecha | C11: Lts Solicitados | D11: Lts Recibidos Obra | E11: Dif. Litros (Obra-Sol) | F11: Costo Solicitado | G11: Costo Real Obra | H11: Dif. Costo (Real-Sol)
A12: Lunes | B12: =C$5 | C12: =IF(C$4="Todas", SUMIFS(Solicitudes!F:F, Solicitudes!C:C, B12), SUMIFS(Solicitudes!F:F, Solicitudes!B:B, C$4, Solicitudes!C:C, B12)) | D12: =IF(C$4="Jalisco", SUMIFS(Captura_Jalisco!G:G, Captura_Jalisco!A:A, B12, Captura_Jalisco!B:B, "Salida"), IF(C$4="Todas", SUMIFS(Captura_Obra!F:F, Captura_Obra!A:A, B12) + SUMIFS(Captura_Jalisco!G:G, Captura_Jalisco!A:A, B12, Captura_Jalisco!B:B, "Salida"), SUMIFS(Captura_Obra!F:F, Captura_Obra!B:B, C$4, Captura_Obra!A:A, B12))) | E12: =D12-C12 | F12: =C12*C$7 | G12: =D12*C$7 | H12: =G12-F12
A13: Martes | B13: =B12+1 | C13: =IF(C$4="Todas", SUMIFS(Solicitudes!F:F, Solicitudes!C:C, B13), SUMIFS(Solicitudes!F:F, Solicitudes!B:B, C$4, Solicitudes!C:C, B13)) | D13: =IF(C$4="Jalisco", SUMIFS(Captura_Jalisco!G:G, Captura_Jalisco!A:A, B13, Captura_Jalisco!B:B, "Salida"), IF(C$4="Todas", SUMIFS(Captura_Obra!F:F, Captura_Obra!A:A, B13) + SUMIFS(Captura_Jalisco!G:G, Captura_Jalisco!A:A, B13, Captura_Jalisco!B:B, "Salida"), SUMIFS(Captura_Obra!F:F, Captura_Obra!B:B, C$4, Captura_Obra!A:A, B13))) | E13: =D13-C13 | F13: =C13*C$7 | G13: =D13*C$7 | H13: =G13-F13
A14: Miércoles | B14: =B13+1 | C14: =IF(C$4="Todas", SUMIFS(Solicitudes!F:F, Solicitudes!C:C, B14), SUMIFS(Solicitudes!F:F, Solicitudes!B:B, C$4, Solicitudes!C:C, B14)) | D14: =IF(C$4="Jalisco", SUMIFS(Captura_Jalisco!G:G, Captura_Jalisco!A:A, B14, Captura_Jalisco!B:B, "Salida"), IF(C$4="Todas", SUMIFS(Captura_Obra!F:F, Captura_Obra!A:A, B14) + SUMIFS(Captura_Jalisco!G:G, Captura_Jalisco!A:A, B14, Captura_Jalisco!B:B, "Salida"), SUMIFS(Captura_Obra!F:F, Captura_Obra!B:B, C$4, Captura_Obra!A:A, B14))) | E14: =D14-C14 | F14: =C14*C$7 | G14: =D14*C$7 | H14: =G14-F14
A15: Jueves | B15: =B14+1 | C15: =IF(C$4="Todas", SUMIFS(Solicitudes!F:F, Solicitudes!C:C, B15), SUMIFS(Solicitudes!F:F, Solicitudes!B:B, C$4, Solicitudes!C:C, B15)) | D15: =IF(C$4="Jalisco", SUMIFS(Captura_Jalisco!G:G, Captura_Jalisco!A:A, B15, Captura_Jalisco!B:B, "Salida"), IF(C$4="Todas", SUMIFS(Captura_Obra!F:F, Captura_Obra!A:A, B15) + SUMIFS(Captura_Jalisco!G:G, Captura_Jalisco!A:A, B15, Captura_Jalisco!B:B, "Salida"), SUMIFS(Captura_Obra!F:F, Captura_Obra!B:B, C$4, Captura_Obra!A:A, B15))) | E15: =D15-C15 | F15: =C15*C$7 | G15: =D15*C$7 | H15: =G15-F15
A16: Viernes | B16: =B15+1 | C16: =IF(C$4="Todas", SUMIFS(Solicitudes!F:F, Solicitudes!C:C, B16), SUMIFS(Solicitudes!F:F, Solicitudes!B:B, C$4, Solicitudes!C:C, B16)) | D16: =IF(C$4="Jalisco", SUMIFS(Captura_Jalisco!G:G, Captura_Jalisco!A:A, B16, Captura_Jalisco!B:B, "Salida"), IF(C$4="Todas", SUMIFS(Captura_Obra!F:F, Captura_Obra!A:A, B16) + SUMIFS(Captura_Jalisco!G:G, Captura_Jalisco!A:A, B16, Captura_Jalisco!B:B, "Salida"), SUMIFS(Captura_Obra!F:F, Captura_Obra!B:B, C$4, Captura_Obra!A:A, B16))) | E16: =D16-C16 | F16: =C16*C$7 | G16: =D16*C$7 | H16: =G16-F16
A17: Sábado | B17: =B16+1 | C17: =IF(C$4="Todas", SUMIFS(Solicitudes!F:F, Solicitudes!C:C, B17), SUMIFS(Solicitudes!F:F, Solicitudes!B:B, C$4, Solicitudes!C:C, B17)) | D17: =IF(C$4="Jalisco", SUMIFS(Captura_Jalisco!G:G, Captura_Jalisco!A:A, B17, Captura_Jalisco!B:B, "Salida"), IF(C$4="Todas", SUMIFS(Captura_Obra!F:F, Captura_Obra!A:A, B17) + SUMIFS(Captura_Jalisco!G:G, Captura_Jalisco!A:A, B17, Captura_Jalisco!B:B, "Salida"), SUMIFS(Captura_Obra!F:F, Captura_Obra!B:B, C$4, Captura_Obra!A:A, B17))) | E17: =D17-C17 | F17: =C17*C$7 | G17: =D17*C$7 | H17: =G17-F17
A18: TOTAL SEMANAL | C18: =SUM(C12:C17) | D18: =SUM(D12:D17) | E18: =SUM(E12:E17) | F18: =SUM(F12:F17) | G18: =SUM(G12:G17) | H18: =SUM(H12:H17)
A20: CONCILIACIÓN FÍSICA Y DISCREPANCIAS (OBRA VS MARIMBA Y PEGASO)
A21: Día | B21: Fecha | C21: Obra Recibió (M) | D21: Marimba Despachó | E21: Dif. Marimba | F21: Obra Recibió (P) | G21: Pegaso Despachó | H21: Dif. Pegaso | I21: Dif. Total (L) | J21: Observaciones / Justificación
A22: Lunes | B22: =B12 | C22: =IF(C$4="Todas", SUMIFS(Captura_Obra!F:F, Captura_Obra!A:A, B22, Captura_Obra!C:C, "Marimba M-01"), SUMIFS(Captura_Obra!F:F, Captura_Obra!B:B, C$4, Captura_Obra!A:A, B22, Captura_Obra!C:C, "Marimba M-01")) | D22: =IF(C$4="Todas", SUMIFS(Captura_Marimba_M01!G:G, Captura_Marimba_M01!A:A, B22, Captura_Marimba_M01!B:B, "Salida"), SUMIFS(Captura_Marimba_M01!G:G, Captura_Marimba_M01!C:C, C$4, Captura_Marimba_M01!A:A, B22, Captura_Marimba_M01!B:B, "Salida")) | E22: =C22-D22 | F22: =IF(C$4="Todas", SUMIFS(Captura_Obra!F:F, Captura_Obra!A:A, B22, Captura_Obra!C:C, "Pegaso Directo"), SUMIFS(Captura_Obra!F:F, Captura_Obra!B:B, C$4, Captura_Obra!A:A, B22, Captura_Obra!C:C, "Pegaso Directo")) | G22: =IF(C$4="Todas", SUMIFS(Captura_Pegaso!H:H, Captura_Pegaso!A:A, B22, Captura_Pegaso!B:B, "Salida"), SUMIFS(Captura_Pegaso!H:H, Captura_Pegaso!D:D, C$4, Captura_Pegaso!A:A, B22, Captura_Pegaso!B:B, "Salida")) | H22: =F22-G22 | I22: =E22+H22
A23: Martes | B23: =B13 | C23: =IF(C$4="Todas", SUMIFS(Captura_Obra!F:F, Captura_Obra!A:A, B23, Captura_Obra!C:C, "Marimba M-01"), SUMIFS(Captura_Obra!F:F, Captura_Obra!B:B, C$4, Captura_Obra!A:A, B23, Captura_Obra!C:C, "Marimba M-01")) | D23: =IF(C$4="Todas", SUMIFS(Captura_Marimba_M01!G:G, Captura_Marimba_M01!A:A, B23, Captura_Marimba_M01!B:B, "Salida"), SUMIFS(Captura_Marimba_M01!G:G, Captura_Marimba_M01!C:C, C$4, Captura_Marimba_M01!A:A, B23, Captura_Marimba_M01!B:B, "Salida")) | E23: =C23-D23 | F23: =IF(C$4="Todas", SUMIFS(Captura_Obra!F:F, Captura_Obra!A:A, B23, Captura_Obra!C:C, "Pegaso Directo"), SUMIFS(Captura_Obra!F:F, Captura_Obra!B:B, C$4, Captura_Obra!A:A, B23, Captura_Obra!C:C, "Pegaso Directo")) | G23: =IF(C$4="Todas", SUMIFS(Captura_Pegaso!H:H, Captura_Pegaso!A:A, B23, Captura_Pegaso!B:B, "Salida"), SUMIFS(Captura_Pegaso!H:H, Captura_Pegaso!D:D, C$4, Captura_Pegaso!A:A, B23, Captura_Pegaso!B:B, "Salida")) | H23: =F23-G23 | I23: =E23+H23
A24: Miércoles | B24: =B14 | C24: =IF(C$4="Todas", SUMIFS(Captura_Obra!F:F, Captura_Obra!A:A, B24, Captura_Obra!C:C, "Marimba M-01"), SUMIFS(Captura_Obra!F:F, Captura_Obra!B:B, C$4, Captura_Obra!A:A, B24, Captura_Obra!C:C, "Marimba M-01")) | D24: =IF(C$4="Todas", SUMIFS(Captura_Marimba_M01!G:G, Captura_Marimba_M01!A:A, B24, Captura_Marimba_M01!B:B, "Salida"), SUMIFS(Captura_Marimba_M01!G:G, Captura_Marimba_M01!C:C, C$4, Captura_Marimba_M01!A:A, B24, Captura_Marimba_M01!B:B, "Salida")) | E24: =C24-D24 | F24: =IF(C$4="Todas", SUMIFS(Captura_Obra!F:F, Captura_Obra!A:A, B24, Captura_Obra!C:C, "Pegaso Directo"), SUMIFS(Captura_Obra!F:F, Captura_Obra!B:B, C$4, Captura_Obra!A:A, B24, Captura_Obra!C:C, "Pegaso Directo")) | G24: =IF(C$4="Todas", SUMIFS(Captura_Pegaso!H:H, Captura_Pegaso!A:A, B24, Captura_Pegaso!B:B, "Salida"), SUMIFS(Captura_Pegaso!H:H, Captura_Pegaso!D:D, C$4, Captura_Pegaso!A:A, B24, Captura_Pegaso!B:B, "Salida")) | H24: =F24-G24 | I24: =E24+H24
A25: Jueves | B25: =B15 | C25: =IF(C$4="Todas", SUMIFS(Captura_Obra!F:F, Captura_Obra!A:A, B25, Captura_Obra!C:C, "Marimba M-01"), SUMIFS(Captura_Obra!F:F, Captura_Obra!B:B, C$4, Captura_Obra!A:A, B25, Captura_Obra!C:C, "Marimba M-01")) | D25: =IF(C$4="Todas", SUMIFS(Captura_Marimba_M01!G:G, Captura_Marimba_M01!A:A, B25, Captura_Marimba_M01!B:B, "Salida"), SUMIFS(Captura_Marimba_M01!G:G, Captura_Marimba_M01!C:C, C$4, Captura_Marimba_M01!A:A, B25, Captura_Marimba_M01!B:B, "Salida")) | E25: =C25-D25 | F25: =IF(C$4="Todas", SUMIFS(Captura_Obra!F:F, Captura_Obra!A:A, B25, Captura_Obra!C:C, "Pegaso Directo"), SUMIFS(Captura_Obra!F:F, Captura_Obra!B:B, C$4, Captura_Obra!A:A, B25, Captura_Obra!C:C, "Pegaso Directo")) | G25: =IF(C$4="Todas", SUMIFS(Captura_Pegaso!H:H, Captura_Pegaso!A:A, B25, Captura_Pegaso!B:B, "Salida"), SUMIFS(Captura_Pegaso!H:H, Captura_Pegaso!D:D, C$4, Captura_Pegaso!A:A, B25, Captura_Pegaso!B:B, "Salida")) | H25: =F25-G25 | I25: =E25+H25
A26: Viernes | B26: =B16 | C26: =IF(C$4="Todas", SUMIFS(Captura_Obra!F:F, Captura_Obra!A:A, B26, Captura_Obra!C:C, "Marimba M-01"), SUMIFS(Captura_Obra!F:F, Captura_Obra!B:B, C$4, Captura_Obra!A:A, B26, Captura_Obra!C:C, "Marimba M-01")) | D26: =IF(C$4="Todas", SUMIFS(Captura_Marimba_M01!G:G, Captura_Marimba_M01!A:A, B26, Captura_Marimba_M01!B:B, "Salida"), SUMIFS(Captura_Marimba_M01!G:G, Captura_Marimba_M01!C:C, C$4, Captura_Marimba_M01!A:A, B26, Captura_Marimba_M01!B:B, "Salida")) | E26: =C26-D26 | F26: =IF(C$4="Todas", SUMIFS(Captura_Obra!F:F, Captura_Obra!A:A, B26, Captura_Obra!C:C, "Pegaso Directo"), SUMIFS(Captura_Obra!F:F, Captura_Obra!B:B, C$4, Captura_Obra!A:A, B26, Captura_Obra!C:C, "Pegaso Directo")) | G26: =IF(C$4="Todas", SUMIFS(Captura_Pegaso!H:H, Captura_Pegaso!A:A, B26, Captura_Pegaso!B:B, "Salida"), SUMIFS(Captura_Pegaso!H:H, Captura_Pegaso!D:D, C$4, Captura_Pegaso!A:A, B26, Captura_Pegaso!B:B, "Salida")) | H26: =F26-G26 | I26: =E26+H26
A27: Sábado | B27: =B17 | C27: =IF(C$4="Todas", SUMIFS(Captura_Obra!F:F, Captura_Obra!A:A, B27, Captura_Obra!C:C, "Marimba M-01"), SUMIFS(Captura_Obra!F:F, Captura_Obra!B:B, C$4, Captura_Obra!A:A, B27, Captura_Obra!C:C, "Marimba M-01")) | D27: =IF(C$4="Todas", SUMIFS(Captura_Marimba_M01!G:G, Captura_Marimba_M01!A:A, B27, Captura_Marimba_M01!B:B, "Salida"), SUMIFS(Captura_Marimba_M01!G:G, Captura_Marimba_M01!C:C, C$4, Captura_Marimba_M01!A:A, B27, Captura_Marimba_M01!B:B, "Salida")) | E27: =C27-D27 | F27: =IF(C$4="Todas", SUMIFS(Captura_Obra!F:F, Captura_Obra!A:A, B27, Captura_Obra!C:C, "Pegaso Directo"), SUMIFS(Captura_Obra!F:F, Captura_Obra!B:B, C$4, Captura_Obra!A:A, B27, Captura_Obra!C:C, "Pegaso Directo")) | G27: =IF(C$4="Todas", SUMIFS(Captura_Pegaso!H:H, Captura_Pegaso!A:A, B27, Captura_Pegaso!B:B, "Salida"), SUMIFS(Captura_Pegaso!H:H, Captura_Pegaso!D:D, C$4, Captura_Pegaso!A:A, B27, Captura_Pegaso!B:B, "Salida")) | H27: =F27-G27 | I27: =E27+H27
A28: TOTAL CONCILIADO | C28: =SUM(C22:C27) | D28: =SUM(D22:D27) | E28: =SUM(E22:E27) | F28: =SUM(F22:F27) | G28: =SUM(G22:G27) | H28: =SUM(H22:H27) | I28: =SUM(I22:I27)
Q30: ="SOLICITUDES DE DISEL DIARIAS Y SEMANALES POR OBRA (SEMANA " & YEAR(C5) & "-" & TEXT(MONTH(C5),"00") & "-" & TEXT(DAY(C5),"00") & ")"
A31: RESUMEN ACUMULADO POR OBRA / PERÍODO SELECCIONADO | Q31: Obra | R31: Solicitante | S31: Lunes | U31: Martes | W31: Miércoles | Y31: Jueves | AA31: Viernes | AC31: Sábado | AE31: Total Semanal Solicitado | AF31: Total Seamanal Autorizado
A32: Obra | B32: Total Litros Suministrados | C32: Costo Total Acumulado | S32: Solicitado | T32: Autorizado | U32: Solicitado | V32: Autorizado | W32: Solicitado | X32: Autorizado | Y32: Solicitado | Z32: Autorizado | AA32: Solicitado | AB32: Autorizado | AC32: Solicitado | AD32: Autorizado
A33: México-Toluca | B33: =IF(C$8="Acumulado Histórico", SUMIFS(Captura_Obra!F:F, Captura_Obra!B:B, A33), IF(C$8="Rango de Fechas", SUMIFS(Captura_Obra!F:F, Captura_Obra!B:B, A33, Captura_Obra!A:A, ">="&C$5, Captura_Obra!A:A, "<="&(C$6+5)), SUMIFS(Captura_Obra!F:F, Captura_Obra!B:B, A33, Captura_Obra!A:A, ">="&C$5, Captura_Obra!A:A, "<="&(C$5+5)))) | C33: =B33*C$7 | P33: m | Q33: =A33 | R33: =VLOOKUP(Q33,Catalogos!$B$4:$C$18,2,FALSE) | S33: =SUMIFS(Solicitudes!$F:$F, Solicitudes!$B:$B, $Q33, Solicitudes!$C:$C, $B$12) | T33: 550 | U33: =SUMIFS(Solicitudes!$F:$F, Solicitudes!$B:$B, $Q33, Solicitudes!$C:$C, $B$13) | V33: 550 | W33: =SUMIFS(Solicitudes!$F:$F, Solicitudes!$B:$B, $Q33, Solicitudes!$C:$C, $B$14) | X33: 550 | Y33: =SUMIFS(Solicitudes!$F:$F, Solicitudes!$B:$B, $Q33, Solicitudes!$C:$C, $B$15) | Z33: 550 | AA33: =SUMIFS(Solicitudes!$F:$F, Solicitudes!$B:$B, $Q33, Solicitudes!$C:$C, $B$16) | AB33: 550 | AC33: =SUMIFS(Solicitudes!$F:$F, Solicitudes!$B:$B, $Q33, Solicitudes!$C:$C, $B$17) | AD33: 0 | AE33: =SUM(S33,U33,W33,Y33,AA33,AC33,) | AF33: =SUM(T33,V33,X33,Z33,AB33,AD33)
A34: Lerma - Tres Marías | B34: =IF(C$8="Acumulado Histórico", SUMIFS(Captura_Obra!F:F, Captura_Obra!B:B, A34), IF(C$8="Rango de Fechas", SUMIFS(Captura_Obra!F:F, Captura_Obra!B:B, A34, Captura_Obra!A:A, ">="&C$5, Captura_Obra!A:A, "<="&(C$6+5)), SUMIFS(Captura_Obra!F:F, Captura_Obra!B:B, A34, Captura_Obra!A:A, ">="&C$5, Captura_Obra!A:A, "<="&(C$5+5)))) | C34: =B34*C$7 | P34: p | Q34: =A34 | R34: =VLOOKUP(Q34,Catalogos!$B$4:$C$18,2,FALSE) | S34: =SUMIFS(Solicitudes!$F:$F, Solicitudes!$B:$B, $Q34, Solicitudes!$C:$C, $B$12) | T34: 400 | U34: =SUMIFS(Solicitudes!$F:$F, Solicitudes!$B:$B, $Q34, Solicitudes!$C:$C, $B$13) | V34: 400 | W34: =SUMIFS(Solicitudes!$F:$F, Solicitudes!$B:$B, $Q34, Solicitudes!$C:$C, $B$14) | X34: 400 | Y34: =SUMIFS(Solicitudes!$F:$F, Solicitudes!$B:$B, $Q34, Solicitudes!$C:$C, $B$15) | Z34: 400 | AA34: =SUMIFS(Solicitudes!$F:$F, Solicitudes!$B:$B, $Q34, Solicitudes!$C:$C, $B$16) | AB34: 400 | AC34: =SUMIFS(Solicitudes!$F:$F, Solicitudes!$B:$B, $Q34, Solicitudes!$C:$C, $B$17) | AD34: =SUMIFS(Solicitudes!$F:$F, Solicitudes!$B:$B, $Q34, Solicitudes!$C:$C, ($B$17+1)) | AE34: =SUM(S34,U34,W34,Y34,AA34,AC34,) | AF34: =SUM(T34,V34,X34,Z34,AB34,AD34)
A35: Chamapa-Lechería | B35: =IF(C$8="Acumulado Histórico", SUMIFS(Captura_Obra!F:F, Captura_Obra!B:B, A35), IF(C$8="Rango de Fechas", SUMIFS(Captura_Obra!F:F, Captura_Obra!B:B, A35, Captura_Obra!A:A, ">="&C$5, Captura_Obra!A:A, "<="&(C$6+5)), SUMIFS(Captura_Obra!F:F, Captura_Obra!B:B, A35, Captura_Obra!A:A, ">="&C$5, Captura_Obra!A:A, "<="&(C$5+5)))) | C35: =B35*C$7 | P35: p | Q35: =A36 | R35: =VLOOKUP(Q35,Catalogos!$B$4:$C$18,2,FALSE) | S35: =SUMIFS(Solicitudes!$F:$F, Solicitudes!$B:$B, $Q35, Solicitudes!$C:$C, $B$12) | T35: 100 | U35: =SUMIFS(Solicitudes!$F:$F, Solicitudes!$B:$B, $Q35, Solicitudes!$C:$C, $B$13) | V35: 100 | W35: =SUMIFS(Solicitudes!$F:$F, Solicitudes!$B:$B, $Q35, Solicitudes!$C:$C, $B$14) | X35: 100 | Y35: =SUMIFS(Solicitudes!$F:$F, Solicitudes!$B:$B, $Q35, Solicitudes!$C:$C, $B$15) | Z35: 100 | AA35: =SUMIFS(Solicitudes!$F:$F, Solicitudes!$B:$B, $Q35, Solicitudes!$C:$C, $B$16) | AB35: 100 | AC35: =SUMIFS(Solicitudes!$F:$F, Solicitudes!$B:$B, $Q35, Solicitudes!$C:$C, $B$17) | AD35: =SUMIFS(Solicitudes!$F:$F, Solicitudes!$B:$B, $Q35, Solicitudes!$C:$C, ($B$17+1)) | AE35: =SUM(S35,U35,W35,Y35,AA35,AC35,) | AF35: =SUM(T35,V35,X35,Z35,AB35,AD35)
A36: Bacheo Toluca | B36: =IF(C$8="Acumulado Histórico", SUMIFS(Captura_Obra!F:F, Captura_Obra!B:B, A36), IF(C$8="Rango de Fechas", SUMIFS(Captura_Obra!F:F, Captura_Obra!B:B, A36, Captura_Obra!A:A, ">="&C$5, Captura_Obra!A:A, "<="&(C$6+5)), SUMIFS(Captura_Obra!F:F, Captura_Obra!B:B, A36, Captura_Obra!A:A, ">="&C$5, Captura_Obra!A:A, "<="&(C$5+5)))) | C36: =B36*C$7 | P36: p | Q36: =A37 | R36: =VLOOKUP(Q36,Catalogos!$B$4:$C$18,2,FALSE) | S36: =SUMIFS(Solicitudes!$F:$F, Solicitudes!$B:$B, $Q36, Solicitudes!$C:$C, $B$12) | T36: 0 | U36: =SUMIFS(Solicitudes!$F:$F, Solicitudes!$B:$B, $Q36, Solicitudes!$C:$C, $B$13) | V36: 300 | W36: =SUMIFS(Solicitudes!$F:$F, Solicitudes!$B:$B, $Q36, Solicitudes!$C:$C, $B$14) | X36: 1000 | Y36: =SUMIFS(Solicitudes!$F:$F, Solicitudes!$B:$B, $Q36, Solicitudes!$C:$C, $B$15) | Z36: 300 | AA36: =SUMIFS(Solicitudes!$F:$F, Solicitudes!$B:$B, $Q36, Solicitudes!$C:$C, $B$16) | AB36: 0 | AC36: =SUMIFS(Solicitudes!$F:$F, Solicitudes!$B:$B, $Q36, Solicitudes!$C:$C, $B$17) | AD36: =SUMIFS(Solicitudes!$F:$F, Solicitudes!$B:$B, $Q36, Solicitudes!$C:$C, ($B$17+1)) | AE36: =SUM(S36,U36,W36,Y36,AA36,AC36,) | AF36: =SUM(T36,V36,X36,Z36,AB36,AD36)
A37: Planta Asfalto Pegaso | B37: =IF(C$8="Acumulado Histórico", SUMIFS(Captura_Obra!F:F, Captura_Obra!B:B, A37), IF(C$8="Rango de Fechas", SUMIFS(Captura_Obra!F:F, Captura_Obra!B:B, A37, Captura_Obra!A:A, ">="&C$5, Captura_Obra!A:A, "<="&(C$6+5)), SUMIFS(Captura_Obra!F:F, Captura_Obra!B:B, A37, Captura_Obra!A:A, ">="&C$5, Captura_Obra!A:A, "<="&(C$5+5)))) | C37: =B37*C$7 | P37: h | Q37: =A38 | R37: =VLOOKUP(Q37,Catalogos!$B$4:$C$18,2,FALSE) | S37: =SUMIFS(Solicitudes!$F:$F, Solicitudes!$B:$B, $Q37, Solicitudes!$C:$C, $B$12) | T37: 500 | U37: =SUMIFS(Solicitudes!$F:$F, Solicitudes!$B:$B, $Q37, Solicitudes!$C:$C, $B$13) | V37: 500 | W37: =SUMIFS(Solicitudes!$F:$F, Solicitudes!$B:$B, $Q37, Solicitudes!$C:$C, $B$14) | X37: 500 | Y37: =SUMIFS(Solicitudes!$F:$F, Solicitudes!$B:$B, $Q37, Solicitudes!$C:$C, $B$15) | Z37: 500 | AA37: =SUMIFS(Solicitudes!$F:$F, Solicitudes!$B:$B, $Q37, Solicitudes!$C:$C, $B$16) | AB37: 500 | AC37: =SUMIFS(Solicitudes!$F:$F, Solicitudes!$B:$B, $Q37, Solicitudes!$C:$C, $B$17) | AD37: =SUMIFS(Solicitudes!$F:$F, Solicitudes!$B:$B, $Q37, Solicitudes!$C:$C, ($B$17+1)) | AE37: =SUM(S37,U37,W37,Y37,AA37,AC37,) | AF37: =SUM(T37,V37,X37,Z37,AB37,AD37)
A38: Planta Asflato Huixquilucan | B38: =IF(C$8="Acumulado Histórico", SUMIFS(Captura_Obra!F:F, Captura_Obra!B:B, A38), IF(C$8="Rango de Fechas", SUMIFS(Captura_Obra!F:F, Captura_Obra!B:B, A38, Captura_Obra!A:A, ">="&C$5, Captura_Obra!A:A, "<="&(C$6+5)), SUMIFS(Captura_Obra!F:F, Captura_Obra!B:B, A38, Captura_Obra!A:A, ">="&C$5, Captura_Obra!A:A, "<="&(C$5+5)))) | C38: =B38*C$7 | Q38: =A41 | S38: =SUM(S33:S37) | T38: =SUM(T33:T37) | U38: =SUM(U33:U37) | V38: =SUM(V33:V37) | W38: =SUM(W33:W37) | X38: =SUM(X33:X37) | Y38: =SUM(Y33:Y37) | Z38: =SUM(Z33:Z37) | ... AE38: =SUM(AE33:AE37) | AF38: =SUM(T38,V38,X38,Z38,AB38,AD38)
A39: Dragones | B39: =IF(C$8="Acumulado Histórico", SUMIFS(Captura_Obra!F:F, Captura_Obra!B:B, A39), IF(C$8="Rango de Fechas", SUMIFS(Captura_Obra!F:F, Captura_Obra!B:B, A39, Captura_Obra!A:A, ">="&C$5, Captura_Obra!A:A, "<="&(C$6+5)), SUMIFS(Captura_Obra!F:F, Captura_Obra!B:B, A39, Captura_Obra!A:A, ">="&C$5, Captura_Obra!A:A, "<="&(C$5+5)))) | C39: =B39*C$7
A40: Jalisco | B40: =IF(C$8="Acumulado Histórico", SUMIFS(Captura_Jalisco!G:G, Captura_Jalisco!B:B, "Salida"), IF(C$8="Rango de Fechas", SUMIFS(Captura_Jalisco!G:G, Captura_Jalisco!B:B, "Salida", Captura_Jalisco!A:A, ">="&C$5, Captura_Jalisco!A:A, "<="&(C$6+5)), SUMIFS(Captura_Jalisco!G:G, Captura_Jalisco!B:B, "Salida", Captura_Jalisco!A:A, ">="&C$5, Captura_Jalisco!A:A, "<="&(C$5+5)))) | C40: =B40*C$7
A41: TOTAL GENERAL | B41: =SUM(B33:B40) | C41: =SUM(C33:C40)
A43: RESUMEN DE CONSUMO SEMANAL POR OBRA (DETALLE HISTÓRICO POR SEMANA)
B44: Obra (Tabla Semanal): | C44: Todas
B45: Precio Diésel ($/L): | C45: 27
...

Sheet Dashboard_Ejecutivo
B2: Peticiones por Día y Obra | G2: Salidas Marimba por Día y Obra | L2: Salidas Pegaso a Obra | Q2: Consumo Total en Obra | V2: Resumen Semanal por Obra
B4: Fecha | C4: Obra | D4: Litros Solicitados | E4: Costo Estimado ($) | G4: Fecha | H4: Obra | I4: Salida (L) | J4: Costo Surtido ($) | L4: Fecha | M4: Obra | N4: Salida (L) | O4: Costo Surtido ($) | Q4: Fecha | R4: Obra | S4: Litros Recibidos | T4: Costo Surtido ($) | V4: Obra | W4: Litros Recibidos | X4: Costo Surtido ($)
B5: 2026-06-07 | C5: Lerma - Tres Marías | D5: 160 | E5: 4528 | G5: 2026-06-08 | H5: Chamapa-Lechería | I5: 455 | J5: 12876.5 | L5: 2026-06-08 | M5: Bacheo Toluca | N5: 180 | O5: 5094 | Q5: 2026-06-08 | R5: Bacheo Toluca | S5: 100 | T5: 2830 | V5: Bacheo Toluca | W5: 200 | X5: 5660
B6: 2026-06-07 | C6: México-Toluca | D6: 640 | E6: 18112 | G6: 2026-06-08 | H6: Lerma - Tres Marías | I6: 97 | J6: 2745.1 | L6: 2026-06-08 | M6: Planta Asfalto Pegaso | N6: 409 | O6: 11574.7 | Q6: 2026-06-08 | R6: Chamapa-Lechería | S6: 455 | T6: 12876.5 | V6: Chamapa-Lechería | W6: 1693 | X6: 47911.9
B7: 2026-06-08 | C7: Bacheo Toluca | D7: 100 | E7: 2830 | G7: 2026-06-08 | H7: México-Toluca | I7: 369 | J7: 10442.7 | L7: 2026-06-09 | M7: Lerma - Tres Marías | N7: 180 | O7: 5094 | Q7: 2026-06-08 | R7: Lerma - Tres Marías | S7: 97 | T7: 2745.1 | V7: Lerma - Tres Marías | W7: 872 | X7: 24677.6
B8: 2026-06-08 | C8: Chamapa-Lechería | D8: 990 | E8: 28017 | G8: 2026-06-09 | H8: Chamapa-Lechería | I8: 736 | J8: 20828.8 | L8: 2026-06-10 | M8: Bacheo Toluca | N8: 100 | O8: 2830 | Q8: 2026-06-08 | R8: México-Toluca | S8: 369 | T8: 10442.7 | V8: México-Toluca | W8: 1285 | X8: 36365.5
B9: 2026-06-09 | C9: Bacheo Toluca | D9: 100 | E9: 2830 | G9: 2026-06-10 | H9: México-Toluca | I9: 300 | J9: 8490 | L9: 2026-06-11 | M9: Lerma - Tres Marías | N9: 595 | O9: 16838.5 | Q9: 2026-06-08 | R9: Planta Asfalto Pegaso | S9: 409 | T9: 11574.7 | V9: Planta Asfalto Pegaso | W9: 647 | X9: 18310.1
B10: 2026-06-09 | C10: Chamapa-Lechería | D10: 790 | E10: 22357 | G10: 2026-06-11 | H10: México-Toluca | I10: 256 | J10: 7244.8 | L10: 2026-06-11 | M10: Planta Asfalto Pegaso | N10: 238 | O10: 6735.4 | Q10: 2026-06-09 | R10: Chamapa-Lechería | S10: 736 | T10: 20828.8 | X10: =SUM(X5:X9)
B11: 2026-06-09 | C11: Lerma - Tres Marías | D11: 210 | E11: 5943 | G11: 2026-06-12 | H11: Chamapa-Lechería | I11: 502 | J11: 14206.6 | L11: 2026-06-12 | M11: Bacheo Toluca | N11: 70 | O11: 1981 | Q11: 2026-06-09 | R11: Lerma - Tres Marías | S11: 180 | T11: 5094
B12: 2026-06-10 | C12: México-Toluca | D12: 320 | E12: 9056 | G12: 2026-06-12 | H12: México-Toluca | I12: 360 | J12: 10188 | Q12: 2026-06-10 | R12: Bacheo Toluca | S12: 100 | T12: 2830
B13: 2026-06-11 | C13: Bacheo Toluca | D13: 70 | E13: 1981 | Q13: 2026-06-10 | R13: México-Toluca | S13: 300 | T13: 8490
B14: 2026-06-11 | C14: Lerma - Tres Marías | D14: 460 | E14: 13018 | Q14: 2026-06-11 | R14: Lerma - Tres Marías | S14: 595 | T14: 16838.5
B15: 2026-06-12 | C15: Chamapa-Lechería | D15: 620 | E15: 17546 | Q15: 2026-06-11 | R15: México-Toluca | S15: 256 | T15: 7244.8
B16: 2026-06-12 | C16: México-Toluca | D16: 540 | E16: 15282 | Q16: 2026-06-11 | R16: Planta Asfalto Pegaso | S16: 238 | T16: 6735.4
Q17: 2026-06-12 | R17: Chamapa-Lechería | S17: 502 | T17: 14206.6
Q18: 2026-06-12 | R18: México-Toluca | S18: 360 | T18: 10188
B35: Costos por Día (Petición vs Surtido) | G35: Costos por Obra (Petición vs Surtido) | L35: Totales Generales por Día | Q35: Totales Generales por Obra | V35: Reporte de Discrepancias (Faltantes/Sobrantes)
B37: Fecha | C37: Costo Solicitado ($) | D37: Costo Surtido ($) | G37: Obra | H37: Costo Solicitado ($) | I37: Costo Surtido ($) | L37: Fecha | M37: Litros Totales | N37: Costo Total ($) | Q37: Obra | R37: Litros Totales | S37: Costo Total ($) | V37: Fecha | W37: Obra | X37: Litros Surtidos | Y37: Litros Recibidos | Z37: Discrepancia (L)
B38: 2026-06-07 | C38: 22640 | D38: 0 | G38: Bacheo Toluca | H38: 7641 | I38: 9905 | L38: 2026-06-08 | M38: 1510 | N38: 42733 | Q38: Bacheo Toluca | R38: 350 | S38: 9905 | V38: 2026-06-08 | W38: Bacheo Toluca | X38: 180 | Y38: 100 | Z38: 80
B39: 2026-06-08 | C39: 30847 | D39: 42733 | G39: Chamapa-Lechería | H39: 67920 | I39: 47911.9 | L39: 2026-06-09 | M39: 916 | N39: 25922.8 | Q39: Chamapa-Lechería | R39: 1693 | S39: 47911.9 | V39: 2026-06-12 | W39: Bacheo Toluca | X39: 70 | Y39: 0 | Z39: 70
B40: 2026-06-09 | C40: 31130 | D40: 25922.8 | G40: Lerma - Tres Marías | H40: 23489 | I40: 24677.6 | L40: 2026-06-10 | M40: 400 | N40: 11320 | Q40: Lerma - Tres Marías | R40: 872 | S40: 24677.6
B41: 2026-06-10 | C41: 9056 | D41: 11320 | G41: México-Toluca | H41: 42450 | I41: 36365.5 | L41: 2026-06-11 | M41: 1089 | N41: 30818.7 | Q41: México-Toluca | R41: 1285 | S41: 36365.5
B42: 2026-06-11 | C42: 14999 | D42: 30818.7 | G42: Planta Asfalto Pegaso | H42: 0 | I42: 18310.1 | L42: 2026-06-12 | M42: 932 | N42: 26375.6 | Q42: Planta Asfalto Pegaso | R42: 647 | S42: 18310.1
B43: 2026-06-12 | C43: 32828 | D43: 26375.6

Sheet Captura_Pegaso
A1: GC-COMB-001 | BITÁCORA DE INVENTARIO PEGASO
A2: Responsable: | C2: Semana: | F2: Fecha entrega: | H2: Tanque: | I2: Pegaso | J2: Costo por litro base:
A3: Folio Ticket | B3: Fecha | C3: Hora | D3: Origen | E3: Destino | F3: Obra Asignada | G3: Litros | H3: Costo/L
F200: =VLOOKUP(TablaPegaso[[#This Row],[Equipo]],Catalogos!$I$4:$J$34,2,FALSE)
F201: =VLOOKUP(TablaPegaso[[#This Row],[Equipo]],Catalogos!$I$4:$J$34,2,FALSE)
F202: =VLOOKUP(TablaPegaso[[#This Row],[Equipo]],Catalogos!$I$4:$J$34,2,FALSE)
F203: =VLOOKUP(TablaPegaso[[#This Row],[Equipo]],Catalogos!$I$4:$J$34,2,FALSE)
F204: =VLOOKUP(TablaPegaso[[#This Row],[Equipo]],Catalogos!$I$4:$J$34,2,FALSE)
F205: =VLOOKUP(TablaPegaso[[#This Row],[Equipo]],Catalogos!$I$4:$J$34,2,FALSE)
F206: =VLOOKUP(TablaPegaso[[#This Row],[Equipo]],Catalogos!$I$4:$J$34,2,FALSE)

Sheet Captura_Marimba_M01
A1: GC-COMB-002 | BITÁCORA DE SUMINISTRO DE MARIMBA M-01
A2: Operador: | C2: Semana: | E2: Fecha entrega: | G2: Marimba: | H2: M-01 | I2: Costo/L base:
A3: Folio Ticket | B3: Fecha | C3: Hora | D3: Origen | E3: Destino | F3: Obra Asignada | G3: Litros | H3: Costo/L
N43: =SUM(G5:G48)
E200: =VLOOKUP(TablaMarimba[[#This Row],[Equipo]],Catalogos!$I$4:$J$35,2,FALSE) | I200: 28.3
E201: =VLOOKUP(TablaMarimba[[#This Row],[Equipo]],Catalogos!$I$4:$J$35,2,FALSE) | I201: 28.3
E202: =VLOOKUP(TablaMarimba[[#This Row],[Equipo]],Catalogos!$I$4:$J$35,2,FALSE) | I202: 28.3
E203: =VLOOKUP(TablaMarimba[[#This Row],[Equipo]],Catalogos!$I$4:$J$35,2,FALSE) | I203: 28.3
E204: =VLOOKUP(TablaMarimba[[#This Row],[Equipo]],Catalogos!$I$4:$J$35,2,FALSE) | I204: 28.3
E205: =VLOOKUP(TablaMarimba[[#This Row],[Equipo]],Catalogos!$I$4:$J$35,2,FALSE) | I205: 28.3
E206: =VLOOKUP(TablaMarimba[[#This Row],[Equipo]],Catalogos!$I$4:$J$35,2,FALSE) | I206: 28.3

Sheet Captura_Jalisco
A1: GC-COMB-002 | BITÁCORA DE SUMINISTRO DE JALISCO
A2: Operador: | C2: Semana: | E2: Fecha entrega: | G2: Marimba: | H2: M-01 | I2: Costo/L base:
A3: Folio Ticket | B3: Fecha | C3: Hora | D3: Origen | E3: Destino | F3: Obra Asignada | G3: Litros | H3: Costo/L
M4: Ajuste | N4: Gasolina | O4: Firma/Validación | P4: Observaciones
M5: 0
M10: 25056
M22: 31320 | N22: 3000
N25: 1556
N33: 3700
R43: =SUM(G5:G48)
E200: =VLOOKUP(TablaMarimba6[[#This Row],[Equipo]],Catalogos!$I$4:$J$35,2,FALSE) | I200: 28.3 | L200: =(TablaMarimba6[[#This Row],[Saldo inicial(vales)]]-TablaMarimba6[[#This Row],[Importe]])
E201: =VLOOKUP(TablaMarimba6[[#This Row],[Equipo]],Catalogos!$I$4:$J$35,2,FALSE) | I201: 28.3 | L201: =(TablaMarimba6[[#This Row],[Saldo inicial(vales)]]-TablaMarimba6[[#This Row],[Importe]])
E202: =VLOOKUP(TablaMarimba6[[#This Row],[Equipo]],Catalogos!$I$4:$J$35,2,FALSE) | I202: 28.3 | L202: =(TablaMarimba6[[#This Row],[Saldo inicial(vales)]]-TablaMarimba6[[#This Row],[Importe]])
E203: =VLOOKUP(TablaMarimba6[[#This Row],[Equipo]],Catalogos!$I$4:$J$35,2,FALSE) | I203: 28.3 | L203: =(TablaMarimba6[[#This Row],[Saldo inicial(vales)]]-TablaMarimba6[[#This Row],[Importe]])
E204: =VLOOKUP(TablaMarimba6[[#This Row],[Equipo]],Catalogos!$I$4:$J$35,2,FALSE) | I204: 28.3 | J204: =IFERROR((F204+G204)*I204,0) | L204: =(TablaMarimba6[[#This Row],[Saldo inicial(vales)]]-TablaMarimba6[[#This Row],[Importe]])
E205: =VLOOKUP(TablaMarimba6[[#This Row],[Equipo]],Catalogos!$I$4:$J$35,2,FALSE) | I205: 28.3 | J205: =IFERROR((F205+G205)*I205,0) | L205: =(TablaMarimba6[[#This Row],[Saldo inicial(vales)]]-TablaMarimba6[[#This Row],[Importe]])
E206: =VLOOKUP(TablaMarimba6[[#This Row],[Equipo]],Catalogos!$I$4:$J$35,2,FALSE) | I206: 28.3 | J206: =IFERROR((F206+G206)*I206,0) | L206: =(TablaMarimba6[[#This Row],[Saldo inicial(vales)]]-TablaMarimba6[[#This Row],[Importe]])

Sheet Captura_Obra
A1: GC-COMB-003 | BITÁCORA DE CONTROL DE COMBUSTIBLE DE OBRA
A2: Ingeniero: | C2: Semana: | E2: Fecha entrega: | G2: Obra: | I2: Costo/L base:
A3: Folio Ticket | B3: Fecha | C3: Hora | D3: Origen | E3: Destino | F3: Obra Asignada | G3: Litros | H3: Costo/L
M14: =SUM(F5:F64)
E200: =VLOOKUP(TablaObra[[#This Row],[Equipo]],Catalogos!$I$4:$J$46,2,FALSE)
E201: =VLOOKUP(TablaObra[[#This Row],[Equipo]],Catalogos!$I$4:$J$46,2,FALSE)
E202: =VLOOKUP(TablaObra[[#This Row],[Equipo]],Catalogos!$I$4:$J$46,2,FALSE)
E203: =VLOOKUP(TablaObra[[#This Row],[Equipo]],Catalogos!$I$4:$J$46,2,FALSE)
E204: =VLOOKUP(TablaObra[[#This Row],[Equipo]],Catalogos!$I$4:$J$46,2,FALSE)
E205: =VLOOKUP(TablaObra[[#This Row],[Equipo]],Catalogos!$I$4:$J$46,2,FALSE)
E206: =VLOOKUP(TablaObra[[#This Row],[Equipo]],Catalogos!$I$4:$J$46,2,FALSE)
E207: =VLOOKUP(TablaObra[[#This Row],[Equipo]],Catalogos!$I$4:$J$46,2,FALSE)
E208: =VLOOKUP(TablaObra[[#This Row],[Equipo]],Catalogos!$I$4:$J$46,2,FALSE)
E209: =VLOOKUP(TablaObra[[#This Row],[Equipo]],Catalogos!$I$4:$J$46,2,FALSE)
E210: =VLOOKUP(TablaObra[[#This Row],[Equipo]],Catalogos!$I$4:$J$46,2,FALSE)
E211: =VLOOKUP(TablaObra[[#This Row],[Equipo]],Catalogos!$I$4:$J$46,2,FALSE)
... E260: =VLOOKUP(TablaObra[[#This Row],[Equipo]],Catalogos!$I$4:$J$46,2,FALSE)
E261: =VLOOKUP(TablaObra[[#This Row],[Equipo]],Catalogos!$I$4:$J$46,2,FALSE) | H261: =IFERROR(F261*G261,0)
E262: =VLOOKUP(TablaObra[[#This Row],[Equipo]],Catalogos!$I$4:$J$46,2,FALSE) | H262: =IFERROR(F262*G262,0)
E263: =VLOOKUP(TablaObra[[#This Row],[Equipo]],Catalogos!$I$4:$J$46,2,FALSE) | H263: =IFERROR(F263*G263,0)
E264: =VLOOKUP(TablaObra[[#This Row],[Equipo]],Catalogos!$I$4:$J$46,2,FALSE) | H264: =IFERROR(F264*G264,0)
E265: =VLOOKUP(TablaObra[[#This Row],[Equipo]],Catalogos!$I$4:$J$46,2,FALSE) | H265: =IFERROR(F265*G265,0)
E266: =VLOOKUP(TablaObra[[#This Row],[Equipo]],Catalogos!$I$4:$J$46,2,FALSE) | H266: =IFERROR(F266*G266,0)
E267: =VLOOKUP(TablaObra[[#This Row],[Equipo]],Catalogos!$I$4:$J$46,2,FALSE) | H267: =IFERROR(F267*G267,0)
E268: =VLOOKUP(TablaObra[[#This Row],[Equipo]],Catalogos!$I$4:$J$46,2,FALSE) | H268: =IFERROR(F268*G268,0)
E269: =VLOOKUP(TablaObra[[#This Row],[Equipo]],Catalogos!$I$4:$J$46,2,FALSE) | H269: =IFERROR(F269*G269,0)
E270: =VLOOKUP(TablaObra[[#This Row],[Equipo]],Catalogos!$I$4:$J$46,2,FALSE) | H270: =IFERROR(F270*G270,0)
E271: =VLOOKUP(TablaObra[[#This Row],[Equipo]],Catalogos!$I$4:$J$46,2,FALSE) | H271: =IFERROR(F271*G271,0)
E272: =VLOOKUP(TablaObra[[#This Row],[Equipo]],Catalogos!$I$4:$J$46,2,FALSE) | H272: =IFERROR(F272*G272,0)
... E304: =VLOOKUP(TablaObra[[#This Row],[Equipo]],Catalogos!$I$4:$J$46,2,FALSE) | H304: =IFERROR(F304*G304,0)

Sheet Solicitudes
A1: GC-COMB-003 | BITÁCORA DE SOLICITUDES DE COMBUSTIBLE DE OBRA
A2: Ingeniero: | C2: Semana: | E2: Fecha entrega: | G2: Obra: | I2: Costo/L base:
A4: Fecha de Solicitud | B4: Obra | C4: Fecha de Trabajo | D4: Equipo | E4: Económico | F4: Litros Solicitados | G4: Costo/L | H4: Importe | I4: Solicitante | J4: Incidencia | K4: Observaciones
A5: 46180 | B5: México-Toluca | C5: 46181 | D5: Vogel | E5: =VLOOKUP(TablaObra5[[#This Row],[Equipo]],Catalogos!$I$4:$J$64,2,FALSE) | F5: 200 | G5: 28.3 | H5: =IFERROR(F5*G5,0) | I5: =VLOOKUP(TablaObra5[[#This Row],[Obra]],Catalogos!$B$3:$C$10,2,FALSE)
A6: 46180 | B6: México-Toluca | C6: 46181 | D6: Perfiladora | E6: =VLOOKUP(TablaObra5[[#This Row],[Equipo]],Catalogos!$I$4:$J$64,2,FALSE) | F6: 300 | G6: 28.3 | H6: =IFERROR(F6*G6,0) | I6: =VLOOKUP(TablaObra5[[#This Row],[Obra]],Catalogos!$B$3:$C$10,2,FALSE)
A7: 46180 | B7: México-Toluca | C7: 46181 | D7: Retroexcavadora | E7: =VLOOKUP(TablaObra5[[#This Row],[Equipo]],Catalogos!$I$4:$J$64,2,FALSE) | F7: 30 | G7: 28.3 | H7: =IFERROR(F7*G7,0) | I7: =VLOOKUP(TablaObra5[[#This Row],[Obra]],Catalogos!$B$3:$C$10,2,FALSE)
A8: 46180 | B8: México-Toluca | C8: 46181 | D8: Barredora | E8: =VLOOKUP(TablaObra5[[#This Row],[Equipo]],Catalogos!$I$4:$J$64,2,FALSE) | F8: 20 | G8: 28.3 | H8: =IFERROR(F8*G8,0) | I8: =VLOOKUP(TablaObra5[[#This Row],[Obra]],Catalogos!$B$3:$C$10,2,FALSE)
A9: 46180 | B9: México-Toluca | C9: 46181 | D9: Neuomatico | E9: =VLOOKUP(TablaObra5[[#This Row],[Equipo]],Catalogos!$I$4:$J$64,2,FALSE) | F9: 30 | G9: 28.3 | H9: =IFERROR(F9*G9,0) | I9: =VLOOKUP(TablaObra5[[#This Row],[Obra]],Catalogos!$B$3:$C$10,2,FALSE)
A10: 46180 | B10: México-Toluca | C10: 46181 | D10: Compactador | E10: =VLOOKUP(TablaObra5[[#This Row],[Equipo]],Catalogos!$I$4:$J$64,2,FALSE) | F10: 30 | G10: 28.3 | H10: =IFERROR(F10*G10,0) | I10: =VLOOKUP(TablaObra5[[#This Row],[Obra]],Catalogos!$B$3:$C$10,2,FALSE)
A11: 46180 | B11: México-Toluca | C11: 46181 | D11: Limpieza | E11: =VLOOKUP(TablaObra5[[#This Row],[Equipo]],Catalogos!$I$4:$J$64,2,FALSE) | F11: 30 | G11: 28.3 | H11: =IFERROR(F11*G11,0) | I11: =VLOOKUP(TablaObra5[[#This Row],[Obra]],Catalogos!$B$3:$C$10,2,FALSE)
A12: 46180 | B12: Lerma - Tres Marías | C12: 46181 | D12: Retroexcavadora | E12: =VLOOKUP(TablaObra5[[#This Row],[Equipo]],Catalogos!$I$4:$J$64,2,FALSE) | F12: 50 | G12: 28.3 | H12: =IFERROR(F12*G12,0) | I12: =VLOOKUP(TablaObra5[[#This Row],[Obra]],Catalogos!$B$3:$C$10,2,FALSE)
A13: 46180 | B13: Lerma - Tres Marías | C13: 46181 | D13: Neuomatico | E13: =VLOOKUP(TablaObra5[[#This Row],[Equipo]],Catalogos!$I$4:$J$64,2,FALSE) | F13: 50 | G13: 28.3 | H13: =IFERROR(F13*G13,0) | I13: =VLOOKUP(TablaObra5[[#This Row],[Obra]],Catalogos!$B$3:$C$10,2,FALSE)
A14: 46180 | B14: Lerma - Tres Marías | C14: 46181 | D14: Petrolizadora | E14: =VLOOKUP(TablaObra5[[#This Row],[Equipo]],Catalogos!$I$4:$J$64,2,FALSE) | F14: 60 | G14: 28.3 | H14: =IFERROR(F14*G14,0) | I14: =VLOOKUP(TablaObra5[[#This Row],[Obra]],Catalogos!$B$3:$C$10,2,FALSE)
A15: 46181 | B15: Bacheo Toluca | D15: Retroexcavadora | E15: =VLOOKUP(TablaObra5[[#This Row],[Equipo]],Catalogos!$I$4:$J$64,2,FALSE) | F15: 100 | G15: 28.3 | H15: =IFERROR(F15*G15,0) | I15: =VLOOKUP(TablaObra5[[#This Row],[Obra]],Catalogos!$B$3:$C$10,2,FALSE)
A16: 46181 | B16: Chamapa-Lechería | C16: 46181 | D16: Perfiladora Wirgent | E16: =VLOOKUP(TablaObra5[[#This Row],[Equipo]],Catalogos!$I$4:$J$64,2,FALSE) | F16: 250 | G16: 28.3 | H16: =IFERROR(F16*G16,0) | I16: =VLOOKUP(TablaObra5[[#This Row],[Obra]],Catalogos!$B$3:$C$10,2,FALSE)
A17: 46181 | B17: Chamapa-Lechería | C17: 46181 | D17: Perfiladora Cat-PM | E17: =VLOOKUP(TablaObra5[[#This Row],[Equipo]],Catalogos!$I$4:$J$64,2,FALSE) | F17: 150 | G17: 28.3 | H17: =IFERROR(F17*G17,0) | I17: =VLOOKUP(TablaObra5[[#This Row],[Obra]],Catalogos!$B$3:$C$10,2,FALSE)
A18: 46181 | B18: Chamapa-Lechería | C18: 46181 | D18: Barredora Broce | E18: =VLOOKUP(TablaObra5[[#This Row],[Equipo]],Catalogos!$I$4:$J$64,2,FALSE) | F18: 40 | G18: 28.3 | H18: =IFERROR(F18*G18,0) | I18: =VLOOKUP(TablaObra5[[#This Row],[Obra]],Catalogos!$B$3:$C$10,2,FALSE)
A19: 46181 | B19: Chamapa-Lechería | C19: 46181 | D19: Retroexcavadora Jonh Deere | E19: =VLOOKUP(TablaObra5[[#This Row],[Equipo]],Catalogos!$I$4:$J$64,2,FALSE) | F19: 60 | G19: 28.3 | H19: =IFERROR(F19*G19,0) | I19: =VLOOKUP(TablaObra5[[#This Row],[Obra]],Catalogos!$B$3:$C$10,2,FALSE)
A20: 46181 | B20: Chamapa-Lechería | C20: 46181 | D20: Buggy Trasnfer | E20: =VLOOKUP(TablaObra5[[#This Row],[Equipo]],Catalogos!$I$4:$J$64,2,FALSE) | F20: 100 | G20: 28.3 | H20: =IFERROR(F20*G20,0) | I20: =VLOOKUP(TablaObra5[[#This Row],[Obra]],Catalogos!$B$3:$C$10,2,FALSE)
A21: 46181 | B21: Chamapa-Lechería | C21: 46181 | D21: Vogele Guion | E21: =VLOOKUP(TablaObra5[[#This Row],[Equipo]],Catalogos!$I$4:$J$64,2,FALSE) | F21: 100 | G21: 28.3 | H21: =IFERROR(F21*G21,0) | I21: =VLOOKUP(TablaObra5[[#This Row],[Obra]],Catalogos!$B$3:$C$10,2,FALSE)
A22: 46181 | B22: Chamapa-Lechería | C22: 46181 | D22: Limpieza | E22: =VLOOKUP(TablaObra5[[#This Row],[Equipo]],Catalogos!$I$4:$J$64,2,FALSE) | F22: 20 | G22: 28.3 | H22: =IFERROR(F22*G22,0) | I22: =VLOOKUP(TablaObra5[[#This Row],[Obra]],Catalogos!$B$3:$C$10,2,FALSE)
A23: 46181 | B23: Chamapa-Lechería | C23: 46181 | D23: Tandem Hamm | E23: =VLOOKUP(TablaObra5[[#This Row],[Equipo]],Catalogos!$I$4:$J$64,2,FALSE) | F23: 50 | G23: 28.3 | H23: =IFERROR(F23*G23,0) | I23: =VLOOKUP(TablaObra5[[#This Row],[Obra]],Catalogos!$B$3:$C$10,2,FALSE)
A24: 46181 | B24: Chamapa-Lechería | C24: 46181 | D24: Neuomatico Dynapac | E24: =VLOOKUP(TablaObra5[[#This Row],[Equipo]],Catalogos!$I$4:$J$64,2,FALSE) | F24: 50 | G24: 28.3 | H24: =IFERROR(F24*G24,0) | I24: =VLOOKUP(TablaObra5[[#This Row],[Obra]],Catalogos!$B$3:$C$10,2,FALSE)
A25: 46181 | B25: Chamapa-Lechería | C25: 46181 | D25: Petrolizadora Elton | E25: =VLOOKUP(TablaObra5[[#This Row],[Equipo]],Catalogos!$I$4:$J$64,2,FALSE) | F25: 50 | G25: 28.3 | H25: =IFERROR(F25*G25,0) | I25: =VLOOKUP(TablaObra5[[#This Row],[Obra]],Catalogos!$B$3:$C$10,2,FALSE)
A26: 46181 | B26: Chamapa-Lechería | C26: 46181 | D26: Camion de Impacto | E26: =VLOOKUP(TablaObra5[[#This Row],[Equipo]],Catalogos!$I$4:$J$64,2,FALSE) | F26: 20 | G26: 28.3 | H26: =IFERROR(F26*G26,0) | I26: =VLOOKUP(TablaObra5[[#This Row],[Obra]],Catalogos!$B$3:$C$10,2,FALSE)
A27: 46181 | B27: Chamapa-Lechería | C27: 46181 | D27: Maxilihgs | E27: =VLOOKUP(TablaObra5[[#This Row],[Equipo]],Catalogos!$I$4:$J$64,2,FALSE) | F27: 50 | G27: 28.3 | H27: =IFERROR(F27*G27,0) | I27: =VLOOKUP(TablaObra5[[#This Row],[Obra]],Catalogos!$B$3:$C$10,2,FALSE)
... A40: 46182 | B40: Chamapa-Lechería | C40: 46182 | D40: Compresor | E40: =VLOOKUP(TablaObra5[[#This Row],[Equipo]],Catalogos!$I$4:$J$64,2,FALSE) | F40: 30 | G40: 28.3 | H40: =IFERROR(F40*G40,0) | I40: =VLOOKUP(TablaObra5[[#This Row],[Obra]],Catalogos!$B$3:$C$10,2,FALSE)
A41: 46182 | B41: Lerma - Tres Marías | C41: 46182 | D41: Retroexcavadora | E41: =VLOOKUP(TablaObra5[[#This Row],[Equipo]],Catalogos!$I$4:$J$64,2,FALSE) | F41: 50 | G41: 28.3 | H41: =IFERROR(F41*G41,0) | I41: =VLOOKUP(TablaObra5[[#This Row],[Obra]],Catalogos!$B$3:$C$10,2,FALSE) | K41: Segunda solicitud, el dia 7/06/2026, no se relizo la carga
A42: 46182 | B42: Lerma - Tres Marías | C42: 46182 | D42: Neuomatico | E42: =VLOOKUP(TablaObra5[[#This Row],[Equipo]],Catalogos!$I$4:$J$64,2,FALSE) | F42: 50 | G42: 28.3 | H42: =IFERROR(F42*G42,0) | I42: =VLOOKUP(TablaObra5[[#This Row],[Obra]],Catalogos!$B$3:$C$10,2,FALSE)
A43: 46182 | B43: Lerma - Tres Marías | C43: 46182 | D43: Petrolizadora | E43: =VLOOKUP(TablaObra5[[#This Row],[Equipo]],Catalogos!$I$4:$J$64,2,FALSE) | F43: 60 | G43: 28.3 | H43: =IFERROR(F43*G43,0) | I43: =VLOOKUP(TablaObra5[[#This Row],[Obra]],Catalogos!$B$3:$C$10,2,FALSE)
A44: 46182 | B44: Lerma - Tres Marías | C44: 46182 | D44: Doble Rodillo | E44: =VLOOKUP(TablaObra5[[#This Row],[Equipo]],Catalogos!$I$4:$J$64,2,FALSE) | F44: 50 | G44: 28.3 | H44: =IFERROR(F44*G44,0) | I44: =VLOOKUP(TablaObra5[[#This Row],[Obra]],Catalogos!$B$3:$C$10,2,FALSE)
A45: 46182 | B45: Bacheo Toluca | D45: Retroexcavadora | E45: =VLOOKUP(TablaObra5[[#This Row],[Equipo]],Catalogos!$I$4:$J$64,2,FALSE) | F45: 100 | G45: 28.3 | H45: =IFERROR(F45*G45,0) | I45: =VLOOKUP(TablaObra5[[#This Row],[Obra]],Catalogos!$B$3:$C$10,2,FALSE)
A46: 46183 | B46: México-Toluca | C46: 46183 | D46: Perfiladora | E46: =VLOOKUP(TablaObra5[[#This Row],[Equipo]],Catalogos!$I$4:$J$64,2,FALSE) | F46: 250 | G46: 28.3 | H46: =IFERROR(F46*G46,0) | I46: =VLOOKUP(TablaObra5[[#This Row],[Obra]],Catalogos!$B$3:$C$10,2,FALSE)
A47: 46183 | B47: México-Toluca | C47: 46183 | D47: Retroexcavadora | E47: =VLOOKUP(TablaObra5[[#This Row],[Equipo]],Catalogos!$I$4:$J$64,2,FALSE) | F47: 30 | G47: 28.3 | H47: =IFERROR(F47*G47,0) | I47: =VLOOKUP(TablaObra5[[#This Row],[Obra]],Catalogos!$B$3:$C$10,2,FALSE)
A48: 46183 | B48: México-Toluca | C48: 46183 | D48: Barredora | E48: =VLOOKUP(TablaObra5[[#This Row],[Equipo]],Catalogos!$I$4:$J$64,2,FALSE) | F48: 20 | G48: 28.3 | H48: =IFERROR(F48*G48,0) | I48: =VLOOKUP(TablaObra5[[#This Row],[Obra]],Catalogos!$B$3:$C$10,2,FALSE)
A49: 46183 | B49: México-Toluca | C49: 46183 | D49: Maxilihgs | E49: =VLOOKUP(TablaObra5[[#This Row],[Equipo]],Catalogos!$I$4:$J$64,2,FALSE) | F49: 20 | G49: 28.3 | H49: =IFERROR(F49*G49,0) | I49: =VLOOKUP(TablaObra5[[#This Row],[Obra]],Catalogos!$B$3:$C$10,2,FALSE)
A50: 46184 | B50: Lerma - Tres Marías | C50: 46184 | D50: Petrolizadora | E50: =VLOOKUP(TablaObra5[[#This Row],[Equipo]],Catalogos!$I$4:$J$64,2,FALSE) | F50: 80 | G50: 28.3 | H50: =IFERROR(F50*G50,0) | I50: =VLOOKUP(TablaObra5[[#This Row],[Obra]],Catalogos!$B$3:$C$10,2,FALSE)
A51: 46184 | B51: Lerma - Tres Marías | C51: 46184 | D51: Camion de Impacto | E51: =VLOOKUP(TablaObra5[[#This Row],[Equipo]],Catalogos!$I$4:$J$64,2,FALSE) | F51: 80 | G51: 28.3 | H51: =IFERROR(F51*G51,0) | I51: =VLOOKUP(TablaObra5[[#This Row],[Obra]],Catalogos!$B$3:$C$10,2,FALSE)
A52: 46184 | B52: Lerma - Tres Marías | C52: 46184 | D52: Retroexcavadora | E52: =VLOOKUP(TablaObra5[[#This Row],[Equipo]],Catalogos!$I$4:$J$64,2,FALSE) | F52: 70 | G52: 28.3 | H52: =IFERROR(F52*G52,0) | I52: =VLOOKUP(TablaObra5[[#This Row],[Obra]],Catalogos!$B$3:$C$10,2,FALSE)
A53: 46184 | B53: Lerma - Tres Marías | C53: 46184 | D53: Doble Rodillo | E53: =VLOOKUP(TablaObra5[[#This Row],[Equipo]],Catalogos!$I$4:$J$64,2,FALSE) | F53: 40 | G53: 28.3 | H53: =IFERROR(F53*G53,0) | I53: =VLOOKUP(TablaObra5[[#This Row],[Obra]],Catalogos!$B$3:$C$10,2,FALSE)
...

Sheet Conciliacion
B2: CONCILIACIÓN SEMANAL: DESPACHADO VS RECIBIDO
B3: SEMANA: | C3: =Dashboard!C5
B5: Obra | C5: Despachado por Marimba (Lts) | D5: Despachado por Pegaso (Lts) | E5: Total Despachado (Lts) | F5: Recibido en Obra (Lts) | G5: Diferencia / Desvío (Lts)
B6: =IF(ROWS($6:6)<=MAX(Catalogos!$R$4:$R$11), IFERROR(INDEX(Catalogos!$B$4:$B$11, MATCH(ROWS($6:6), Catalogos!$R$4:$R$11, 0)), ""), IF(ROWS($6:6)=MAX(Catalogos!$R$4:$R$11)+1, "TOTAL GENERAL", "")) | C6: =IF(ROWS($6:6)<=MAX(Catalogos!$R$4:$R$11), SUMIFS(Captura_Marimba_M01!$G:$G, Captura_Marimba_M01!$C:$C, $B6, Captura_Marimba_M01!$A:$A, ">=" & $C$3, Captura_Marimba_M01!$A:$A, "<=" & ($C$3+6)), IF(ROWS($6:6)=MAX(Catalogos!$R$4:$R$11)+1, SUMIFS(Captura_Marimba_M01!$G:$G, Captura_Marimba_M01!$A:$A, ">=" & $C$3, Captura_Marimba_M01!$A:$A, "<=" & ($C$3+6)), "")) | D6: =IF(ROWS($6:6)<=MAX(Catalogos!$R$4:$R$11), SUMIFS(Captura_Pegaso!$H:$H, Captura_Pegaso!$D:$D, $B6, Captura_Pegaso!$A:$A, ">=" & $C$3, Captura_Pegaso!$A:$A, "<=" & ($C$3+6)), IF(ROWS($6:6)=MAX(Catalogos!$R$4:$R$11)+1, SUMIFS(Captura_Pegaso!$H:$H, Captura_Pegaso!$A:$A, ">=" & $C$3, Captura_Pegaso!$A:$A, "<=" & ($C$3+6)), "")) | E6: =IF(ROWS($6:6)<=MAX(Catalogos!$R$4:$R$11)+1, C6+D6, "") | F6: =IF(ROWS($6:6)<=MAX(Catalogos!$R$4:$R$11), SUMIFS(Captura_Obra!$F:$F, Captura_Obra!$B:$B, $B6, Captura_Obra!$A:$A, ">=" & $C$3, Captura_Obra!$A:$A, "<=" & ($C$3+6)), IF(ROWS($6:6)=MAX(Catalogos!$R$4:$R$11)+1, SUMIFS(Captura_Obra!$F:$F, Captura_Obra!$A:$A, ">=" & $C$3, Captura_Obra!$A:$A, "<=" & ($C$3+6)), "")) | G6: =IF(ROWS($6:6)<=MAX(Catalogos!$R$4:$R$11)+1, E6-F6, "")
B7: =IF(ROWS($6:7)<=MAX(Catalogos!$R$4:$R$11), IFERROR(INDEX(Catalogos!$B$4:$B$11, MATCH(ROWS($6:7), Catalogos!$R$4:$R$11, 0)), ""), IF(ROWS($6:7)=MAX(Catalogos!$R$4:$R$11)+1, "TOTAL GENERAL", "")) | C7: =IF(ROWS($6:7)<=MAX(Catalogos!$R$4:$R$11), SUMIFS(Captura_Marimba_M01!$G:$G, Captura_Marimba_M01!$C:$C, $B7, Captura_Marimba_M01!$A:$A, ">=" & $C$3, Captura_Marimba_M01!$A:$A, "<=" & ($C$3+6)), IF(ROWS($6:7)=MAX(Catalogos!$R$4:$R$11)+1, SUMIFS(Captura_Marimba_M01!$G:$G, Captura_Marimba_M01!$A:$A, ">=" & $C$3, Captura_Marimba_M01!$A:$A, "<=" & ($C$3+6)), "")) | D7: =IF(ROWS($6:7)<=MAX(Catalogos!$R$4:$R$11), SUMIFS(Captura_Pegaso!$H:$H, Captura_Pegaso!$D:$D, $B7, Captura_Pegaso!$A:$A, ">=" & $C$3, Captura_Pegaso!$A:$A, "<=" & ($C$3+6)), IF(ROWS($6:7)=MAX(Catalogos!$R$4:$R$11)+1, SUMIFS(Captura_Pegaso!$H:$H, Captura_Pegaso!$A:$A, ">=" & $C$3, Captura_Pegaso!$A:$A, "<=" & ($C$3+6)), "")) | E7: =IF(ROWS($6:7)<=MAX(Catalogos!$R$4:$R$11)+1, C7+D7, "") | F7: =IF(ROWS($6:7)<=MAX(Catalogos!$R$4:$R$11), SUMIFS(Captura_Obra!$F:$F, Captura_Obra!$B:$B, $B7, Captura_Obra!$A:$A, ">=" & $C$3, Captura_Obra!$A:$A, "<=" & ($C$3+6)), IF(ROWS($6:7)=MAX(Catalogos!$R$4:$R$11)+1, SUMIFS(Captura_Obra!$F:$F, Captura_Obra!$A:$A, ">=" & $C$3, Captura_Obra!$A:$A, "<=" & ($C$3+6)), "")) | G7: =IF(ROWS($6:7)<=MAX(Catalogos!$R$4:$R$11)+1, E7-F7, "")
B8: =IF(ROWS($6:8)<=MAX(Catalogos!$R$4:$R$11), IFERROR(INDEX(Catalogos!$B$4:$B$11, MATCH(ROWS($6:8), Catalogos!$R$4:$R$11, 0)), ""), IF(ROWS($6:8)=MAX(Catalogos!$R$4:$R$11)+1, "TOTAL GENERAL", "")) | C8: =IF(ROWS($6:8)<=MAX(Catalogos!$R$4:$R$11), SUMIFS(Captura_Marimba_M01!$G:$G, Captura_Marimba_M01!$C:$C, $B8, Captura_Marimba_M01!$A:$A, ">=" & $C$3, Captura_Marimba_M01!$A:$A, "<=" & ($C$3+6)), IF(ROWS($6:8)=MAX(Catalogos!$R$4:$R$11)+1, SUMIFS(Captura_Marimba_M01!$G:$G, Captura_Marimba_M01!$A:$A, ">=" & $C$3, Captura_Marimba_M01!$A:$A, "<=" & ($C$3+6)), "")) | D8: =IF(ROWS($6:8)<=MAX(Catalogos!$R$4:$R$11), SUMIFS(Captura_Pegaso!$H:$H, Captura_Pegaso!$D:$D, $B8, Captura_Pegaso!$A:$A, ">=" & $C$3, Captura_Pegaso!$A:$A, "<=" & ($C$3+6)), IF(ROWS($6:8)=MAX(Catalogos!$R$4:$R$11)+1, SUMIFS(Captura_Pegaso!$H:$H, Captura_Pegaso!$A:$A, ">=" & $C$3, Captura_Pegaso!$A:$A, "<=" & ($C$3+6)), "")) | E8: =IF(ROWS($6:8)<=MAX(Catalogos!$R$4:$R$11)+1, C8+D8, "") | F8: =IF(ROWS($6:8)<=MAX(Catalogos!$R$4:$R$11), SUMIFS(Captura_Obra!$F:$F, Captura_Obra!$B:$B, $B8, Captura_Obra!$A:$A, ">=" & $C$3, Captura_Obra!$A:$A, "<=" & ($C$3+6)), IF(ROWS($6:8)=MAX(Catalogos!$R$4:$R$11)+1, SUMIFS(Captura_Obra!$F:$F, Captura_Obra!$A:$A, ">=" & $C$3, Captura_Obra!$A:$A, "<=" & ($C$3+6)), "")) | G8: =IF(ROWS($6:8)<=MAX(Catalogos!$R$4:$R$11)+1, E8-F8, "")
B9: =IF(ROWS($6:9)<=MAX(Catalogos!$R$4:$R$11), IFERROR(INDEX(Catalogos!$B$4:$B$11, MATCH(ROWS($6:9), Catalogos!$R$4:$R$11, 0)), ""), IF(ROWS($6:9)=MAX(Catalogos!$R$4:$R$11)+1, "TOTAL GENERAL", "")) | C9: =IF(ROWS($6:9)<=MAX(Catalogos!$R$4:$R$11), SUMIFS(Captura_Marimba_M01!$G:$G, Captura_Marimba_M01!$C:$C, $B9, Captura_Marimba_M01!$A:$A, ">=" & $C$3, Captura_Marimba_M01!$A:$A, "<=" & ($C$3+6)), IF(ROWS($6:9)=MAX(Catalogos!$R$4:$R$11)+1, SUMIFS(Captura_Marimba_M01!$G:$G, Captura_Marimba_M01!$A:$A, ">=" & $C$3, Captura_Marimba_M01!$A:$A, "<=" & ($C$3+6)), "")) | D9: =IF(ROWS($6:9)<=MAX(Catalogos!$R$4:$R$11), SUMIFS(Captura_Pegaso!$H:$H, Captura_Pegaso!$D:$D, $B9, Captura_Pegaso!$A:$A, ">=" & $C$3, Captura_Pegaso!$A:$A, "<=" & ($C$3+6)), IF(ROWS($6:9)=MAX(Catalogos!$R$4:$R$11)+1, SUMIFS(Captura_Pegaso!$H:$H, Captura_Pegaso!$A:$A, ">=" & $C$3, Captura_Pegaso!$A:$A, "<=" & ($C$3+6)), "")) | E9: =IF(ROWS($6:9)<=MAX(Catalogos!$R$4:$R$11)+1, C9+D9, "") | F9: =IF(ROWS($6:9)<=MAX(Catalogos!$R$4:$R$11), SUMIFS(Captura_Obra!$F:$F, Captura_Obra!$B:$B, $B9, Captura_Obra!$A:$A, ">=" & $C$3, Captura_Obra!$A:$A, "<=" & ($C$3+6)), IF(ROWS($6:9)=MAX(Catalogos!$R$4:$R$11)+1, SUMIFS(Captura_Obra!$F:$F, Captura_Obra!$A:$A, ">=" & $C$3, Captura_Obra!$A:$A, "<=" & ($C$3+6)), "")) | G9: =IF(ROWS($6:9)<=MAX(Catalogos!$R$4:$R$11)+1, E9-F9, "")
B10: =IF(ROWS($6:10)<=MAX(Catalogos!$R$4:$R$11), IFERROR(INDEX(Catalogos!$B$4:$B$11, MATCH(ROWS($6:10), Catalogos!$R$4:$R$11, 0)), ""), IF(ROWS($6:10)=MAX(Catalogos!$R$4:$R$11)+1, "TOTAL GENERAL", "")) | C10: =IF(ROWS($6:10)<=MAX(Catalogos!$R$4:$R$11), SUMIFS(Captura_Marimba_M01!$G:$G, Captura_Marimba_M01!$C:$C, $B10, Captura_Marimba_M01!$A:$A, ">=" & $C$3, Captura_Marimba_M01!$A:$A, "<=" & ($C$3+6)), IF(ROWS($6:10)=MAX(Catalogos!$R$4:$R$11)+1, SUMIFS(Captura_Marimba_M01!$G:$G, Captura_Marimba_M01!$A:$A, ">=" & $C$3, Captura_Marimba_M01!$A:$A, "<=" & ($C$3+6)), "")) | D10: =IF(ROWS($6:10)<=MAX(Catalogos!$R$4:$R$11), SUMIFS(Captura_Pegaso!$H:$H, Captura_Pegaso!$D:$D, $B10, Captura_Pegaso!$A:$A, ">=" & $C$3, Captura_Pegaso!$A:$A, "<=" & ($C$3+6)), IF(ROWS($6:10)=MAX(Catalogos!$R$4:$R$11)+1, SUMIFS(Captura_Pegaso!$H:$H, Captura_Pegaso!$A:$A, ">=" & $C$3, Captura_Pegaso!$A:$A, "<=" & ($C$3+6)), "")) | E10: =IF(ROWS($6:10)<=MAX(Catalogos!$R$4:$R$11)+1, C10+D10, "") | F10: =IF(ROWS($6:10)<=MAX(Catalogos!$R$4:$R$11), SUMIFS(Captura_Obra!$F:$F, Captura_Obra!$B:$B, $B10, Captura_Obra!$A:$A, ">=" & $C$3, Captura_Obra!$A:$A, "<=" & ($C$3+6)), IF(ROWS($6:10)=MAX(Catalogos!$R$4:$R$11)+1, SUMIFS(Captura_Obra!$F:$F, Captura_Obra!$A:$A, ">=" & $C$3, Captura_Obra!$A:$A, "<=" & ($C$3+6)), "")) | G10: =IF(ROWS($6:10)<=MAX(Catalogos!$R$4:$R$11)+1, E10-F10, "")
B11: =IF(ROWS($6:11)<=MAX(Catalogos!$R$4:$R$11), IFERROR(INDEX(Catalogos!$B$4:$B$11, MATCH(ROWS($6:11), Catalogos!$R$4:$R$11, 0)), ""), IF(ROWS($6:11)=MAX(Catalogos!$R$4:$R$11)+1, "TOTAL GENERAL", "")) | C11: =IF(ROWS($6:11)<=MAX(Catalogos!$R$4:$R$11), SUMIFS(Captura_Marimba_M01!$G:$G, Captura_Marimba_M01!$C:$C, $B11, Captura_Marimba_M01!$A:$A, ">=" & $C$3, Captura_Marimba_M01!$A:$A, "<=" & ($C$3+6)), IF(ROWS($6:11)=MAX(Catalogos!$R$4:$R$11)+1, SUMIFS(Captura_Marimba_M01!$G:$G, Captura_Marimba_M01!$A:$A, ">=" & $C$3, Captura_Marimba_M01!$A:$A, "<=" & ($C$3+6)), "")) | D11: =IF(ROWS($6:11)<=MAX(Catalogos!$R$4:$R$11), SUMIFS(Captura_Pegaso!$H:$H, Captura_Pegaso!$D:$D, $B11, Captura_Pegaso!$A:$A, ">=" & $C$3, Captura_Pegaso!$A:$A, "<=" & ($C$3+6)), IF(ROWS($6:11)=MAX(Catalogos!$R$4:$R$11)+1, SUMIFS(Captura_Pegaso!$H:$H, Captura_Pegaso!$A:$A, ">=" & $C$3, Captura_Pegaso!$A:$A, "<=" & ($C$3+6)), "")) | E11: =IF(ROWS($6:11)<=MAX(Catalogos!$R$4:$R$11)+1, C11+D11, "") | F11: =IF(ROWS($6:11)<=MAX(Catalogos!$R$4:$R$11), SUMIFS(Captura_Obra!$F:$F, Captura_Obra!$B:$B, $B11, Captura_Obra!$A:$A, ">=" & $C$3, Captura_Obra!$A:$A, "<=" & ($C$3+6)), IF(ROWS($6:11)=MAX(Catalogos!$R$4:$R$11)+1, SUMIFS(Captura_Obra!$F:$F, Captura_Obra!$A:$A, ">=" & $C$3, Captura_Obra!$A:$A, "<=" & ($C$3+6)), "")) | G11: =IF(ROWS($6:11)<=MAX(Catalogos!$R$4:$R$11)+1, E11-F11, "")
B12: =IF(ROWS($6:12)<=MAX(Catalogos!$R$4:$R$11), IFERROR(INDEX(Catalogos!$B$4:$B$11, MATCH(ROWS($6:12), Catalogos!$R$4:$R$11, 0)), ""), IF(ROWS($6:12)=MAX(Catalogos!$R$4:$R$11)+1, "TOTAL GENERAL", "")) | C12: =IF(ROWS($6:12)<=MAX(Catalogos!$R$4:$R$11), SUMIFS(Captura_Marimba_M01!$G:$G, Captura_Marimba_M01!$C:$C, $B12, Captura_Marimba_M01!$A:$A, ">=" & $C$3, Captura_Marimba_M01!$A:$A, "<=" & ($C$3+6)), IF(ROWS($6:12)=MAX(Catalogos!$R$4:$R$11)+1, SUMIFS(Captura_Marimba_M01!$G:$G, Captura_Marimba_M01!$A:$A, ">=" & $C$3, Captura_Marimba_M01!$A:$A, "<=" & ($C$3+6)), "")) | D12: =IF(ROWS($6:12)<=MAX(Catalogos!$R$4:$R$11), SUMIFS(Captura_Pegaso!$H:$H, Captura_Pegaso!$D:$D, $B12, Captura_Pegaso!$A:$A, ">=" & $C$3, Captura_Pegaso!$A:$A, "<=" & ($C$3+6)), IF(ROWS($6:12)=MAX(Catalogos!$R$4:$R$11)+1, SUMIFS(Captura_Pegaso!$H:$H, Captura_Pegaso!$A:$A, ">=" & $C$3, Captura_Pegaso!$A:$A, "<=" & ($C$3+6)), "")) | E12: =IF(ROWS($6:12)<=MAX(Catalogos!$R$4:$R$11)+1, C12+D12, "") | F12: =IF(ROWS($6:12)<=MAX(Catalogos!$R$4:$R$11), SUMIFS(Captura_Obra!$F:$F, Captura_Obra!$B:$B, $B12, Captura_Obra!$A:$A, ">=" & $C$3, Captura_Obra!$A:$A, "<=" & ($C$3+6)), IF(ROWS($6:12)=MAX(Catalogos!$R$4:$R$11)+1, SUMIFS(Captura_Obra!$F:$F, Captura_Obra!$A:$A, ">=" & $C$3, Captura_Obra!$A:$A, "<=" & ($C$3+6)), "")) | G12: =IF(ROWS($6:12)<=MAX(Catalogos!$R$4:$R$11)+1, E12-F12, "")
B13: =IF(ROWS($6:13)<=MAX(Catalogos!$R$4:$R$11), IFERROR(INDEX(Catalogos!$B$4:$B$11, MATCH(ROWS($6:13), Catalogos!$R$4:$R$11, 0)), ""), IF(ROWS($6:13)=MAX(Catalogos!$R$4:$R$11)+1, "TOTAL GENERAL", "")) | C13: =IF(ROWS($6:13)<=MAX(Catalogos!$R$4:$R$11), SUMIFS(Captura_Marimba_M01!$G:$G, Captura_Marimba_M01!$C:$C, $B13, Captura_Marimba_M01!$A:$A, ">=" & $C$3, Captura_Marimba_M01!$A:$A, "<=" & ($C$3+6)), IF(ROWS($6:13)=MAX(Catalogos!$R$4:$R$11)+1, SUMIFS(Captura_Marimba_M01!$G:$G, Captura_Marimba_M01!$A:$A, ">=" & $C$3, Captura_Marimba_M01!$A:$A, "<=" & ($C$3+6)), "")) | D13: =IF(ROWS($6:13)<=MAX(Catalogos!$R$4:$R$11), SUMIFS(Captura_Pegaso!$H:$H, Captura_Pegaso!$D:$D, $B13, Captura_Pegaso!$A:$A, ">=" & $C$3, Captura_Pegaso!$A:$A, "<=" & ($C$3+6)), IF(ROWS($6:13)=MAX(Catalogos!$R$4:$R$11)+1, SUMIFS(Captura_Pegaso!$H:$H, Captura_Pegaso!$A:$A, ">=" & $C$3, Captura_Pegaso!$A:$A, "<=" & ($C$3+6)), "")) | E13: =IF(ROWS($6:13)<=MAX(Catalogos!$R$4:$R$11)+1, C13+D13, "") | F13: =IF(ROWS($6:13)<=MAX(Catalogos!$R$4:$R$11), SUMIFS(Captura_Obra!$F:$F, Captura_Obra!$B:$B, $B13, Captura_Obra!$A:$A, ">=" & $C$3, Captura_Obra!$A:$A, "<=" & ($C$3+6)), IF(ROWS($6:13)=MAX(Catalogos!$R$4:$R$11)+1, SUMIFS(Captura_Obra!$F:$F, Captura_Obra!$A:$A, ">=" & $C$3, Captura_Obra!$A:$A, "<=" & ($C$3+6)), "")) | G13: =IF(ROWS($6:13)<=MAX(Catalogos!$R$4:$R$11)+1, E13-F13, "")
B14: =IF(ROWS($6:14)<=MAX(Catalogos!$R$4:$R$11), IFERROR(INDEX(Catalogos!$B$4:$B$11, MATCH(ROWS($6:14), Catalogos!$R$4:$R$11, 0)), ""), IF(ROWS($6:14)=MAX(Catalogos!$R$4:$R$11)+1, "TOTAL GENERAL", "")) | C14: =IF(ROWS($6:14)<=MAX(Catalogos!$R$4:$R$11), SUMIFS(Captura_Marimba_M01!$G:$G, Captura_Marimba_M01!$C:$C, $B14, Captura_Marimba_M01!$A:$A, ">=" & $C$3, Captura_Marimba_M01!$A:$A, "<=" & ($C$3+6)), IF(ROWS($6:14)=MAX(Catalogos!$R$4:$R$11)+1, SUMIFS(Captura_Marimba_M01!$G:$G, Captura_Marimba_M01!$A:$A, ">=" & $C$3, Captura_Marimba_M01!$A:$A, "<=" & ($C$3+6)), "")) | D14: =IF(ROWS($6:14)<=MAX(Catalogos!$R$4:$R$11), SUMIFS(Captura_Pegaso!$H:$H, Captura_Pegaso!$D:$D, $B14, Captura_Pegaso!$A:$A, ">=" & $C$3, Captura_Pegaso!$A:$A, "<=" & ($C$3+6)), IF(ROWS($6:14)=MAX(Catalogos!$R$4:$R$11)+1, SUMIFS(Captura_Pegaso!$H:$H, Captura_Pegaso!$A:$A, ">=" & $C$3, Captura_Pegaso!$A:$A, "<=" & ($C$3+6)), "")) | E14: =IF(ROWS($6:14)<=MAX(Catalogos!$R$4:$R$11)+1, C14+D14, "") | F14: =IF(ROWS($6:14)<=MAX(Catalogos!$R$4:$R$11), SUMIFS(Captura_Obra!$F:$F, Captura_Obra!$B:$B, $B14, Captura_Obra!$A:$A, ">=" & $C$3, Captura_Obra!$A:$A, "<=" & ($C$3+6)), IF(ROWS($6:14)=MAX(Catalogos!$R$4:$R$11)+1, SUMIFS(Captura_Obra!$F:$F, Captura_Obra!$A:$A, ">=" & $C$3, Captura_Obra!$A:$A, "<=" & ($C$3+6)), "")) | G14: =IF(ROWS($6:14)<=MAX(Catalogos!$R$4:$R$11)+1, E14-F14, "")
B18: CONCILIACIÓN DIARIA POR OBRA: DESPACHADO VS RECIBIDO
B19: SEMANA: | C19: =$C$3
B20: OBRA: | C20: Lerma - Tres Marías
B22: Día de la Semana | C22: Despachado por Marimba (Lts) | D22: Despachado por Pegaso (Lts) | E22: Total Despachado (Lts) | F22: Recibido en Obra (Lts) | G22: Diferencia / Desvío (Lts)
B23: =$C$19 | C23: =IF(OR($C$19="", $C$20=""), "", SUMIFS(Captura_Marimba_M01!$G:$G, Captura_Marimba_M01!$C:$C, $C$20, Captura_Marimba_M01!$A:$A, $B23)) | D23: =IF(OR($C$19="", $C$20=""), "", SUMIFS(Captura_Pegaso!$H:$H, Captura_Pegaso!$D:$D, $C$20, Captura_Pegaso!$A:$A, $B23)) | E23: =IF(OR($C$19="", $C$20=""), "", C23+D23) | F23: =IF(OR($C$19="", $C$20=""), "", SUMIFS(Captura_Obra!$F:$F, Captura_Obra!$B:$B, $C$20, Captura_Obra!$A:$A, $B23)) | G23: =IF(OR($C$19="", $C$20=""), "", E23-F23)
B24: =B23+1 | C24: =IF(OR($C$19="", $C$20=""), "", SUMIFS(Captura_Marimba_M01!$G:$G, Captura_Marimba_M01!$C:$C, $C$20, Captura_Marimba_M01!$A:$A, $B24)) | D24: =IF(OR($C$19="", $C$20=""), "", SUMIFS(Captura_Pegaso!$H:$H, Captura_Pegaso!$D:$D, $C$20, Captura_Pegaso!$A:$A, $B24)) | E24: =IF(OR($C$19="", $C$20=""), "", C24+D24) | F24: =IF(OR($C$19="", $C$20=""), "", SUMIFS(Captura_Obra!$F:$F, Captura_Obra!$B:$B, $C$20, Captura_Obra!$A:$A, $B24)) | G24: =IF(OR($C$19="", $C$20=""), "", E24-F24)
B25: =B24+1 | C25: =IF(OR($C$19="", $C$20=""), "", SUMIFS(Captura_Marimba_M01!$G:$G, Captura_Marimba_M01!$C:$C, $C$20, Captura_Marimba_M01!$A:$A, $B25)) | D25: =IF(OR($C$19="", $C$20=""), "", SUMIFS(Captura_Pegaso!$H:$H, Captura_Pegaso!$D:$D, $C$20, Captura_Pegaso!$A:$A, $B25)) | E25: =IF(OR($C$19="", $C$20=""), "", C25+D25) | F25: =IF(OR($C$19="", $C$20=""), "", SUMIFS(Captura_Obra!$F:$F, Captura_Obra!$B:$B, $C$20, Captura_Obra!$A:$A, $B25)) | G25: =IF(OR($C$19="", $C$20=""), "", E25-F25)
B26: =B25+1 | C26: =IF(OR($C$19="", $C$20=""), "", SUMIFS(Captura_Marimba_M01!$G:$G, Captura_Marimba_M01!$C:$C, $C$20, Captura_Marimba_M01!$A:$A, $B26)) | D26: =IF(OR($C$19="", $C$20=""), "", SUMIFS(Captura_Pegaso!$H:$H, Captura_Pegaso!$D:$D, $C$20, Captura_Pegaso!$A:$A, $B26)) | E26: =IF(OR($C$19="", $C$20=""), "", C26+D26) | F26: =IF(OR($C$19="", $C$20=""), "", SUMIFS(Captura_Obra!$F:$F, Captura_Obra!$B:$B, $C$20, Captura_Obra!$A:$A, $B26)) | G26: =IF(OR($C$19="", $C$20=""), "", E26-F26)
B27: =B26+1 | C27: =IF(OR($C$19="", $C$20=""), "", SUMIFS(Captura_Marimba_M01!$G:$G, Captura_Marimba_M01!$C:$C, $C$20, Captura_Marimba_M01!$A:$A, $B27)) | D27: =IF(OR($C$19="", $C$20=""), "", SUMIFS(Captura_Pegaso!$H:$H, Captura_Pegaso!$D:$D, $C$20, Captura_Pegaso!$A:$A, $B27)) | E27: =IF(OR($C$19="", $C$20=""), "", C27+D27) | F27: =IF(OR($C$19="", $C$20=""), "", SUMIFS(Captura_Obra!$F:$F, Captura_Obra!$B:$B, $C$20, Captura_Obra!$A:$A, $B27)) | G27: =IF(OR($C$19="", $C$20=""), "", E27-F27)
B28: =B27+1 | C28: =IF(OR($C$19="", $C$20=""), "", SUMIFS(Captura_Marimba_M01!$G:$G, Captura_Marimba_M01!$C:$C, $C$20, Captura_Marimba_M01!$A:$A, $B28)) | D28: =IF(OR($C$19="", $C$20=""), "", SUMIFS(Captura_Pegaso!$H:$H, Captura_Pegaso!$D:$D, $C$20, Captura_Pegaso!$A:$A, $B28)) | E28: =IF(OR($C$19="", $C$20=""), "", C28+D28) | F28: =IF(OR($C$19="", $C$20=""), "", SUMIFS(Captura_Obra!$F:$F, Captura_Obra!$B:$B, $C$20, Captura_Obra!$A:$A, $B28)) | G28: =IF(OR($C$19="", $C$20=""), "", E28-F28)
B29: =B28+1 | C29: =IF(OR($C$19="", $C$20=""), "", SUMIFS(Captura_Marimba_M01!$G:$G, Captura_Marimba_M01!$C:$C, $C$20, Captura_Marimba_M01!$A:$A, $B29)) | D29: =IF(OR($C$19="", $C$20=""), "", SUMIFS(Captura_Pegaso!$H:$H, Captura_Pegaso!$D:$D, $C$20, Captura_Pegaso!$A:$A, $B29)) | E29: =IF(OR($C$19="", $C$20=""), "", C29+D29) | F29: =IF(OR($C$19="", $C$20=""), "", SUMIFS(Captura_Obra!$F:$F, Captura_Obra!$B:$B, $C$20, Captura_Obra!$A:$A, $B29)) | G29: =IF(OR($C$19="", $C$20=""), "", E29-F29)
B30: TOTAL GENERAL | C30: =IF(OR($C$19="", $C$20=""), "", SUM(C23:C29)) | D30: =IF(OR($C$19="", $C$20=""), "", SUM(D23:D29)) | E30: =IF(OR($C$19="", $C$20=""), "", SUM(E23:E29)) | F30: =IF(OR($C$19="", $C$20=""), "", SUM(F23:F29)) | G30: =IF(OR($C$19="", $C$20=""), "", SUM(G23:G29))

Sheet Catalogos
A1: CATÁLOGOS OFICIALES - CONTROL DE COMBUSTIBLE
K2: Obras Dropdown | L2: Semanas Dropdown | U2: ASIGNACIÓN DE MAQUINARIA A OBRAS Y OPERADORES
A3: Código Obra | B3: Obra | C3: Ingeniero | E3: Código | F3: Fuente / Origen | I3: Tipo de Equipo | J3: Económico | M3: Total Lts (Semana Dashboard) | N3: 0 | Q3: Total Lts (Conciliacion) | R3: 0 | U3: No. Económico | V3: Tipo de Equipo | W3: Obra Asignada | X3: Operador Asignado
A4: MT | B4: México-Toluca | C4: Francisco Javier | E4: GAS | F4: Gasolinera Huixquilucan | I4: RETROEXCAVADORA CASE 580 N | J4: RT-01 | K4: México-Toluca | L4: 46167 | M4: =SUMIFS(Solicitudes!$F:$F, Solicitudes!$B:$B, $B4, Solicitudes!$C:$C, ">=" & Dashboard!$C$55, Solicitudes!$C:$C, "<=" & (Dashboard!$C$55+6)) + IF($B4="Jalisco", SUMIFS(Captura_Jalisco!$G:$G, Captura_Jalisco!$A:$A, ">=" & Dashboard!$C$55, Captura_Jalisco!$A:$A, "<=" & (Dashboard!$C$55+6), Captura_Jalisco!$B:$B, "Salida"), SUMIFS(Captura_Obra!$F:$F, Captura_Obra!$B:$B, $B4, Captura_Obra!$A:$A, ">=" & Dashboard!$C$55, Captura_Obra!$A:$A, "<=" & (Dashboard!$C$55+6))) | N4: =IF(M4>0, MAX($N$3:N3)+1, "") | Q4: =SUMIFS(Captura_Pegaso!$H:$H, Captura_Pegaso!$D:$D, $B4, Captura_Pegaso!$A:$A, ">=" & Conciliacion!$C$3, Captura_Pegaso!$A:$A, "<=" & (Conciliacion!$C$3+6)) + SUMIFS(Captura_Marimba_M01!$G:$G, Captura_Marimba_M01!$C:$C, $B4, Captura_Marimba_M01!$A:$A, ">=" & Conciliacion!$C$3, Captura_Marimba_M01!$A:$A, "<=" & (Conciliacion!$C$3+6)) + SUMIFS(Captura_Obra!$F:$F, Captura_Obra!$B:$B, $B4, Captura_Obra!$A:$A, ">=" & Conciliacion!$C$3, Captura_Obra!$A:$A, "<=" & (Conciliacion!$C$3+6)) | R4: =IF(Q4>0, MAX($R$3:R3)+1, "") | U4: RT-03 | V4: RETROEXCAVADORA CASE 580 N
