Workbook

Sheet Dashboard
A1: DASHBOARD EJECUTIVO DE CONTROL DE COMBUSTIBLE | GRUPO TRUJANO
A3: FILTROS DEL DASHBOARD (Celdas en amarillo editables en Excel)
B4: Obra Seleccionada: | C4: México-Toluca
B5: Fecha Inicio (Lunes): | C5: 46181
B6: Precio Diésel ($/L): | C6: 28.3
A8: COMPARATIVA: SOLICITADO (PETICIONES) VS ENTREGADO EN OBRA
A9: Día | B9: Fecha | C9: Lts Solicitados | D9: Lts Recibidos Obra | E9: Dif. Litros (Obra-Sol) | F9: Costo Solicitado | G9: Costo Real Obra | H9: Dif. Costo (Real-Sol)
A10: Lunes | B10: =C$5 | C10: =IF(C$4="Todas", SUMIFS(Solicitudes!F:F, Solicitudes!C:C, B10), SUMIFS(Solicitudes!F:F, Solicitudes!B:B, C$4, Solicitudes!C:C, B10)) | D10: =IF(C$4="Todas", SUMIFS(Captura_Obra!F:F, Captura_Obra!A:A, B10), SUMIFS(Captura_Obra!F:F, Captura_Obra!B:B, C$4, Captura_Obra!A:A, B10)) | E10: =D10-C10 | F10: =C10*C$6 | G10: =D10*C$6 | H10: =G10-F10
A11: Martes | B11: =B10+1 | C11: =IF(C$4="Todas", SUMIFS(Solicitudes!F:F, Solicitudes!C:C, B11), SUMIFS(Solicitudes!F:F, Solicitudes!B:B, C$4, Solicitudes!C:C, B11)) | D11: =IF(C$4="Todas", SUMIFS(Captura_Obra!F:F, Captura_Obra!A:A, B11), SUMIFS(Captura_Obra!F:F, Captura_Obra!B:B, C$4, Captura_Obra!A:A, B11)) | E11: =D11-C11 | F11: =C11*C$6 | G11: =D11*C$6 | H11: =G11-F11
A12: Miércoles | B12: =B11+1 | C12: =IF(C$4="Todas", SUMIFS(Solicitudes!F:F, Solicitudes!C:C, B12), SUMIFS(Solicitudes!F:F, Solicitudes!B:B, C$4, Solicitudes!C:C, B12)) | D12: =IF(C$4="Todas", SUMIFS(Captura_Obra!F:F, Captura_Obra!A:A, B12), SUMIFS(Captura_Obra!F:F, Captura_Obra!B:B, C$4, Captura_Obra!A:A, B12)) | E12: =D12-C12 | F12: =C12*C$6 | G12: =D12*C$6 | H12: =G12-F12
A13: Jueves | B13: =B12+1 | C13: =IF(C$4="Todas", SUMIFS(Solicitudes!F:F, Solicitudes!C:C, B13), SUMIFS(Solicitudes!F:F, Solicitudes!B:B, C$4, Solicitudes!C:C, B13)) | D13: =IF(C$4="Todas", SUMIFS(Captura_Obra!F:F, Captura_Obra!A:A, B13), SUMIFS(Captura_Obra!F:F, Captura_Obra!B:B, C$4, Captura_Obra!A:A, B13)) | E13: =D13-C13 | F13: =C13*C$6 | G13: =D13*C$6 | H13: =G13-F13
A14: Viernes | B14: =B13+1 | C14: =IF(C$4="Todas", SUMIFS(Solicitudes!F:F, Solicitudes!C:C, B14), SUMIFS(Solicitudes!F:F, Solicitudes!B:B, C$4, Solicitudes!C:C, B14)) | D14: =IF(C$4="Todas", SUMIFS(Captura_Obra!F:F, Captura_Obra!A:A, B14), SUMIFS(Captura_Obra!F:F, Captura_Obra!B:B, C$4, Captura_Obra!A:A, B14)) | E14: =D14-C14 | F14: =C14*C$6 | G14: =D14*C$6 | H14: =G14-F14
A15: Sábado | B15: =B14+1 | C15: =IF(C$4="Todas", SUMIFS(Solicitudes!F:F, Solicitudes!C:C, B15), SUMIFS(Solicitudes!F:F, Solicitudes!B:B, C$4, Solicitudes!C:C, B15)) | D15: =IF(C$4="Todas", SUMIFS(Captura_Obra!F:F, Captura_Obra!A:A, B15), SUMIFS(Captura_Obra!F:F, Captura_Obra!B:B, C$4, Captura_Obra!A:A, B15)) | E15: =D15-C15 | F15: =C15*C$6 | G15: =D15*C$6 | H15: =G15-F15
A16: TOTAL SEMANAL | C16: =SUM(C10:C15) | D16: =SUM(D10:D15) | E16: =SUM(E10:E15) | F16: =SUM(F10:F15) | G16: =SUM(G10:G15) | H16: =SUM(H10:H15)
A19: CONCILIACIÓN FÍSICA Y DISCREPANCIAS (OBRA VS MARIMBA Y PEGASO)
A20: Día | B20: Fecha | C20: Obra Recibió (M) | D20: Marimba Despachó | E20: Dif. Marimba | F20: Obra Recibió (P) | G20: Pegaso Despachó | H20: Dif. Pegaso | I20: Dif. Total (L)
A21: Lunes | B21: =B10 | C21: =IF(C$4="Todas", SUMIFS(Captura_Obra!F:F, Captura_Obra!A:A, B21, Captura_Obra!C:C, "Marimba M-01"), SUMIFS(Captura_Obra!F:F, Captura_Obra!B:B, C$4, Captura_Obra!A:A, B21, Captura_Obra!C:C, "Marimba M-01")) | D21: =IF(C$4="Todas", SUMIFS(Captura_Marimba_M01!G:G, Captura_Marimba_M01!A:A, B21, Captura_Marimba_M01!B:B, "Salida a Obra"), SUMIFS(Captura_Marimba_M01!G:G, Captura_Marimba_M01!C:C, C$4, Captura_Marimba_M01!A:A, B21, Captura_Marimba_M01!B:B, "Salida a Obra")) | E21: =C21-D21 | F21: =IF(C$4="Todas", SUMIFS(Captura_Obra!F:F, Captura_Obra!A:A, B21, Captura_Obra!C:C, "Pegaso Directo"), SUMIFS(Captura_Obra!F:F, Captura_Obra!B:B, C$4, Captura_Obra!A:A, B21, Captura_Obra!C:C, "Pegaso Directo")) | G21: =IF(C$4="Todas", SUMIFS(Captura_Pegaso!H:H, Captura_Pegaso!A:A, B21, Captura_Pegaso!B:B, "Salida Directa Máquina"), SUMIFS(Captura_Pegaso!H:H, Captura_Pegaso!D:D, C$4, Captura_Pegaso!A:A, B21, Captura_Pegaso!B:B, "Salida Directa Máquina")) | H21: =F21-G21 | I21: =E21+H21
A22: Martes | B22: =B11 | C22: =IF(C$4="Todas", SUMIFS(Captura_Obra!F:F, Captura_Obra!A:A, B22, Captura_Obra!C:C, "Marimba M-01"), SUMIFS(Captura_Obra!F:F, Captura_Obra!B:B, C$4, Captura_Obra!A:A, B22, Captura_Obra!C:C, "Marimba M-01")) | D22: =IF(C$4="Todas", SUMIFS(Captura_Marimba_M01!G:G, Captura_Marimba_M01!A:A, B22, Captura_Marimba_M01!B:B, "Salida a Obra"), SUMIFS(Captura_Marimba_M01!G:G, Captura_Marimba_M01!C:C, C$4, Captura_Marimba_M01!A:A, B22, Captura_Marimba_M01!B:B, "Salida a Obra")) | E22: =C22-D22 | F22: =IF(C$4="Todas", SUMIFS(Captura_Obra!F:F, Captura_Obra!A:A, B22, Captura_Obra!C:C, "Pegaso Directo"), SUMIFS(Captura_Obra!F:F, Captura_Obra!B:B, C$4, Captura_Obra!A:A, B22, Captura_Obra!C:C, "Pegaso Directo")) | G22: =IF(C$4="Todas", SUMIFS(Captura_Pegaso!H:H, Captura_Pegaso!A:A, B22, Captura_Pegaso!B:B, "Salida Directa Máquina"), SUMIFS(Captura_Pegaso!H:H, Captura_Pegaso!D:D, C$4, Captura_Pegaso!A:A, B22, Captura_Pegaso!B:B, "Salida Directa Máquina")) | H22: =F22-G22 | I22: =E22+H22
A23: Miércoles | B23: =B12 | C23: =IF(C$4="Todas", SUMIFS(Captura_Obra!F:F, Captura_Obra!A:A, B23, Captura_Obra!C:C, "Marimba M-01"), SUMIFS(Captura_Obra!F:F, Captura_Obra!B:B, C$4, Captura_Obra!A:A, B23, Captura_Obra!C:C, "Marimba M-01")) | D23: =IF(C$4="Todas", SUMIFS(Captura_Marimba_M01!G:G, Captura_Marimba_M01!A:A, B23, Captura_Marimba_M01!B:B, "Salida a Obra"), SUMIFS(Captura_Marimba_M01!G:G, Captura_Marimba_M01!C:C, C$4, Captura_Marimba_M01!A:A, B23, Captura_Marimba_M01!B:B, "Salida a Obra")) | E23: =C23-D23 | F23: =IF(C$4="Todas", SUMIFS(Captura_Obra!F:F, Captura_Obra!A:A, B23, Captura_Obra!C:C, "Pegaso Directo"), SUMIFS(Captura_Obra!F:F, Captura_Obra!B:B, C$4, Captura_Obra!A:A, B23, Captura_Obra!C:C, "Pegaso Directo")) | G23: =IF(C$4="Todas", SUMIFS(Captura_Pegaso!H:H, Captura_Pegaso!A:A, B23, Captura_Pegaso!B:B, "Salida Directa Máquina"), SUMIFS(Captura_Pegaso!H:H, Captura_Pegaso!D:D, C$4, Captura_Pegaso!A:A, B23, Captura_Pegaso!B:B, "Salida Directa Máquina")) | H23: =F23-G23 | I23: =E23+H23
A24: Jueves | B24: =B13 | C24: =IF(C$4="Todas", SUMIFS(Captura_Obra!F:F, Captura_Obra!A:A, B24, Captura_Obra!C:C, "Marimba M-01"), SUMIFS(Captura_Obra!F:F, Captura_Obra!B:B, C$4, Captura_Obra!A:A, B24, Captura_Obra!C:C, "Marimba M-01")) | D24: =IF(C$4="Todas", SUMIFS(Captura_Marimba_M01!G:G, Captura_Marimba_M01!A:A, B24, Captura_Marimba_M01!B:B, "Salida a Obra"), SUMIFS(Captura_Marimba_M01!G:G, Captura_Marimba_M01!C:C, C$4, Captura_Marimba_M01!A:A, B24, Captura_Marimba_M01!B:B, "Salida a Obra")) | E24: =C24-D24 | F24: =IF(C$4="Todas", SUMIFS(Captura_Obra!F:F, Captura_Obra!A:A, B24, Captura_Obra!C:C, "Pegaso Directo"), SUMIFS(Captura_Obra!F:F, Captura_Obra!B:B, C$4, Captura_Obra!A:A, B24, Captura_Obra!C:C, "Pegaso Directo")) | G24: =IF(C$4="Todas", SUMIFS(Captura_Pegaso!H:H, Captura_Pegaso!A:A, B24, Captura_Pegaso!B:B, "Salida Directa Máquina"), SUMIFS(Captura_Pegaso!H:H, Captura_Pegaso!D:D, C$4, Captura_Pegaso!A:A, B24, Captura_Pegaso!B:B, "Salida Directa Máquina")) | H24: =F24-G24 | I24: =E24+H24
A25: Viernes | B25: =B14 | C25: =IF(C$4="Todas", SUMIFS(Captura_Obra!F:F, Captura_Obra!A:A, B25, Captura_Obra!C:C, "Marimba M-01"), SUMIFS(Captura_Obra!F:F, Captura_Obra!B:B, C$4, Captura_Obra!A:A, B25, Captura_Obra!C:C, "Marimba M-01")) | D25: =IF(C$4="Todas", SUMIFS(Captura_Marimba_M01!G:G, Captura_Marimba_M01!A:A, B25, Captura_Marimba_M01!B:B, "Salida a Obra"), SUMIFS(Captura_Marimba_M01!G:G, Captura_Marimba_M01!C:C, C$4, Captura_Marimba_M01!A:A, B25, Captura_Marimba_M01!B:B, "Salida a Obra")) | E25: =C25-D25 | F25: =IF(C$4="Todas", SUMIFS(Captura_Obra!F:F, Captura_Obra!A:A, B25, Captura_Obra!C:C, "Pegaso Directo"), SUMIFS(Captura_Obra!F:F, Captura_Obra!B:B, C$4, Captura_Obra!A:A, B25, Captura_Obra!C:C, "Pegaso Directo")) | G25: =IF(C$4="Todas", SUMIFS(Captura_Pegaso!H:H, Captura_Pegaso!A:A, B25, Captura_Pegaso!B:B, "Salida Directa Máquina"), SUMIFS(Captura_Pegaso!H:H, Captura_Pegaso!D:D, C$4, Captura_Pegaso!A:A, B25, Captura_Pegaso!B:B, "Salida Directa Máquina")) | H25: =F25-G25 | I25: =E25+H25
A26: Sábado | B26: =B15 | C26: =IF(C$4="Todas", SUMIFS(Captura_Obra!F:F, Captura_Obra!A:A, B26, Captura_Obra!C:C, "Marimba M-01"), SUMIFS(Captura_Obra!F:F, Captura_Obra!B:B, C$4, Captura_Obra!A:A, B26, Captura_Obra!C:C, "Marimba M-01")) | D26: =IF(C$4="Todas", SUMIFS(Captura_Marimba_M01!G:G, Captura_Marimba_M01!A:A, B26, Captura_Marimba_M01!B:B, "Salida a Obra"), SUMIFS(Captura_Marimba_M01!G:G, Captura_Marimba_M01!C:C, C$4, Captura_Marimba_M01!A:A, B26, Captura_Marimba_M01!B:B, "Salida a Obra")) | E26: =C26-D26 | F26: =IF(C$4="Todas", SUMIFS(Captura_Obra!F:F, Captura_Obra!A:A, B26, Captura_Obra!C:C, "Pegaso Directo"), SUMIFS(Captura_Obra!F:F, Captura_Obra!B:B, C$4, Captura_Obra!A:A, B26, Captura_Obra!C:C, "Pegaso Directo")) | G26: =IF(C$4="Todas", SUMIFS(Captura_Pegaso!H:H, Captura_Pegaso!A:A, B26, Captura_Pegaso!B:B, "Salida Directa Máquina"), SUMIFS(Captura_Pegaso!H:H, Captura_Pegaso!D:D, C$4, Captura_Pegaso!A:A, B26, Captura_Pegaso!B:B, "Salida Directa Máquina")) | H26: =F26-G26 | I26: =E26+H26
A27: TOTAL SEMANAL | C27: =SUM(C21:C26) | D27: =SUM(D21:D26) | E27: =SUM(E21:E26) | F27: =SUM(F21:F26) | G27: =SUM(G21:G26) | H27: =SUM(H21:H26) | I27: =SUM(I21:I26)

Sheet Dashboard_Ejecutivo
B2: Peticiones por Día y Obra | G2: Salidas Marimba por Día y Obra | L2: Salidas Pegaso a Obra | Q2: Consumo Total en Obra | V2: Resumen Semanal por Obra
B4: Fecha | C4: Obra | D4: Litros Solicitados | E4: Costo Estimado ($) | G4: Fecha | H4: Obra | I4: Salida (L) | J4: Costo Surtido ($) | L4: Fecha | M4: Obra | N4: Salida (L) | O4: Costo Surtido ($) | Q4: Fecha | R4: Obra | S4: Litros Recibidos | T4: Costo Surtido ($) | V4: Obra | W4: Litros Recibidos | X4: Costo Surtido ($)
B5: 2026-06-07 | C5: Lerma - Tres Marías | D5: 160 | E5: 4528 | G5: 2026-06-08 | H5: Chamapa-Lechería | I5: 455 | J5: 12876.5 | L5: 2026-06-08 | M5: Bacheo Toluca | N5: 180 | O5: 5094 | Q5: 2026-06-08 | R5: Bacheo Toluca | S5: 100 | T5: 2830 | V5: Bacheo Toluca | W5: 200 | X5: 5660
B6: 2026-06-07 | C6: México-Toluca | D6: 640 | E6: 18112 | G6: 2026-06-08 | H6: Lerma - Tres Marías | I6: 97 | J6: 2745.1 | L6: 2026-06-08 | M6: Planta Asfalto Pegaso | N6: 409 | O6: 11574.7 | Q6: 2026-06-08 | R6: Chamapa-Lechería | S6: 455 | T6: 12876.5 | V6: Chamapa-Lechería | W6: 1693 | X6: 47911.9
B7: 2026-06-08 | C7: Bacheo Toluca | D7: 100 | E7: 2830 | G7: 2026-06-08 | H7: México-Toluca | I7: 369 | J7: 10442.7 | L7: 2026-06-09 | M7: Lerma - Tres Marías | N7: 180 | O7: 5094 | Q7: 2026-06-08 | R7: Lerma - Tres Marías | S7: 97 | T7: 2745.1 | V7: Lerma - Tres Marías | W7: 872 | X7: 24677.6
B8: 2026-06-08 | C8: Chamapa-Lechería | D8: 990 | E8: 28017 | G8: 2026-06-09 | H8: Chamapa-Lechería | I8: 736 | J8: 20828.8 | L8: 2026-06-10 | M8: Bacheo Toluca | N8: 100 | O8: 2830 | Q8: 2026-06-08 | R8: México-Toluca | S8: 369 | T8: 10442.7 | V8: México-Toluca | W8: 1285 | X8: 36365.5
B9: 2026-06-09 | C9: Bacheo Toluca | D9: 100 | E9: 2830 | G9: 2026-06-10 | H9: México-Toluca | I9: 300 | J9: 8490 | L9: 2026-06-11 | M9: Lerma - Tres Marías | N9: 595 | O9: 16838.5 | Q9: 2026-06-08 | R9: Planta Asfalto Pegaso | S9: 409 | T9: 11574.7 | V9: Planta Asfalto Pegaso | W9: 647 | X9: 18310.1
B10: 2026-06-09 | C10: Chamapa-Lechería | D10: 790 | E10: 22357 | G10: 2026-06-11 | H10: México-Toluca | I10: 256 | J10: 7244.8 | L10: 2026-06-11 | M10: Planta Asfalto Pegaso | N10: 238 | O10: 6735.4 | Q10: 2026-06-09 | R10: Chamapa-Lechería | S10: 736 | T10: 20828.8 | X10: =SUM(X5:X9)
B11: 2026-06-09 | C11: Lerma - Tres Marías | D11: 210 | E11: 5943 | G11: 2026-06-12 | H11: Chamapa-Lechería | I11: 502 | J11: 14206.6 | L11: 2026-06-12 | M11: Bacheo Toluca | N11: 70 | O11: 1981 | Q11: 2026-06-09 | R11: Lerma - Tres Marías | S11: 180 | T11: 5094
B12: 2026-06-10 | C12: México-Toluca | D12: 320 | E12: 9056 | G12: 2026-06-12 | H12: México-Toluca | I12: 360 | J12: 10188 | Q12: 2026-06-10 | R12: Bacheo Toluca | S12: 100 | T12: 2830
B13: 2026-06-11 | C13: Bacheo Toluca | D13: 70 | E13: 1981 | Q13: 2026-06-10 | R13: México-Toluca | S13: 300 | T13: 8490
B14: 2026-06-11 | C14: Lerma - Tres Marías | D14: 460 | E14: 13018 | Q14: 2026-06-11 | R14: Lerma - Tres Marías | S14: 595 | T14: 16838.5
B15: 2026-06-12 | C15: Chamapa-Lechería | D15: 620 | E15: 17546 | Q15: 2026-06-11 | R15: México-Toluca | S15: 256 | T15: 7244.8
B16: 2026-06-12 | C16: México-Toluca | D16: 540 | E16: 15282 | Q16: 2026-06-11 | R16: Planta Asfalto Pegaso | S16: 238 | T16: 6735.4
Q17: 2026-06-12 | R17: Chamapa-Lechería | S17: 502 | T17: 14206.6
Q18: 2026-06-12 | R18: México-Toluca | S18: 360 | T18: 10188
B35: Costos por Día (Petición vs Surtido) | G35: Costos por Obra (Petición vs Surtido) | L35: Totales Generales por Día | Q35: Totales Generales por Obra | V35: Reporte de Discrepancias (Faltantes/Sobrantes)
B37: Fecha | C37: Costo Solicitado ($) | D37: Costo Surtido ($) | G37: Obra | H37: Costo Solicitado ($) | I37: Costo Surtido ($) | L37: Fecha | M37: Litros Totales | N37: Costo Total ($) | Q37: Obra | R37: Litros Totales | S37: Costo Total ($) | V37: Fecha | W37: Obra | X37: Litros Surtidos | Y37: Litros Recibidos | Z37: Discrepancia (L)
B38: 2026-06-07 | C38: 22640 | D38: 0 | G38: Bacheo Toluca | H38: 7641 | I38: 9905 | L38: 2026-06-08 | M38: 1510 | N38: 42733 | Q38: Bacheo Toluca | R38: 350 | S38: 9905 | V38: 2026-06-08 | W38: Bacheo Toluca | X38: 180 | Y38: 100 | Z38: 80
B39: 2026-06-08 | C39: 30847 | D39: 42733 | G39: Chamapa-Lechería | H39: 67920 | I39: 47911.9 | L39: 2026-06-09 | M39: 916 | N39: 25922.8 | Q39: Chamapa-Lechería | R39: 1693 | S39: 47911.9 | V39: 2026-06-12 | W39: Bacheo Toluca | X39: 70 | Y39: 0 | Z39: 70
B40: 2026-06-09 | C40: 31130 | D40: 25922.8 | G40: Lerma - Tres Marías | H40: 23489 | I40: 24677.6 | L40: 2026-06-10 | M40: 400 | N40: 11320 | Q40: Lerma - Tres Marías | R40: 872 | S40: 24677.6
B41: 2026-06-10 | C41: 9056 | D41: 11320 | G41: México-Toluca | H41: 42450 | I41: 36365.5 | L41: 2026-06-11 | M41: 1089 | N41: 30818.7 | Q41: México-Toluca | R41: 1285 | S41: 36365.5
B42: 2026-06-11 | C42: 14999 | D42: 30818.7 | G42: Planta Asfalto Pegaso | H42: 0 | I42: 18310.1 | L42: 2026-06-12 | M42: 932 | N42: 26375.6 | Q42: Planta Asfalto Pegaso | R42: 647 | S42: 18310.1
B43: 2026-06-12 | C43: 32828 | D43: 26375.6

Sheet Captura_Pegaso
A1: GC-COMB-001 | BITÁCORA DE INVENTARIO PEGASO
A2: Responsable: | C2: Semana: | F2: Fecha entrega: | H2: Tanque: | I2: Pegaso | J2: Costo por litro base:
A4: Fecha | B4: Tipo Movimiento | C4: Origen/Destino | D4: Obra | E4: Equipo | F4: Economico | G4: Entrada (L) | H4: Salida (L) | I4: Existencia Teórica | J4: Costo/L | K4: Importe | L4: Observaciones
A5: 46181 | B5: Salida Directa Máquina | C5: Otro | D5: Bacheo Toluca | E5: Bidones | F5: =VLOOKUP(TablaPegaso[[#This Row],[Equipo]],Catalogos!$I$4:$J$34,2,FALSE) | H5: 100 | I5: =IF(ROW()=5,G5-H5,I4+G5-H5) | J5: 28.3 | K5: =IFERROR((G5+H5)*J5,0)
A6: 46181 | B6: Salida Directa Máquina | C6: Planta Asfalto Pegaso | D6: Planta Asfalto Pegaso | E6: Bidones | F6: =VLOOKUP(TablaPegaso[[#This Row],[Equipo]],Catalogos!$I$4:$J$34,2,FALSE) | H6: 200 | I6: =IF(ROW()=5,G6-H6,I5+G6-H6) | J6: 28.3 | K6: =IFERROR((G6+H6)*J6,0)
A7: 46181 | B7: Salida Directa Máquina | C7: Planta Asfaltos | D7: Planta Asfalto Pegaso | E7: Bidones | F7: =VLOOKUP(TablaPegaso[[#This Row],[Equipo]],Catalogos!$I$4:$J$34,2,FALSE) | H7: 209 | I7: =IF(ROW()=5,G7-H7,I6+G7-H7) | J7: 28.3 | K7: =IFERROR((G7+H7)*J7,0)
A8: 46181 | B8: Entrada | F8: =VLOOKUP(TablaPegaso[[#This Row],[Equipo]],Catalogos!$I$4:$J$34,2,FALSE) | G8: 2800 | I8: =IF(ROW()=5,G8-H8,I7+G8-H8) | J8: 28.3 | K8: =IFERROR((G8+H8)*J8,0)
A9: 46181 | B9: Salida Directa Máquina | C9: Carga directa | D9: Bacheo Toluca | E9: Bidones | F9: =VLOOKUP(TablaPegaso[[#This Row],[Equipo]],Catalogos!$I$4:$J$34,2,FALSE) | H9: 80 | I9: =IF(ROW()=5,G9-H9,I8+G9-H9) | J9: 28.3 | K9: =IFERROR((G9+H9)*J9,0)
A10: 46182 | B10: Salida Directa Máquina | C10: Carga directa | D10: Lerma - Tres Marías | E10: Retroexcavadora | F10: =VLOOKUP(TablaPegaso[[#This Row],[Equipo]],Catalogos!$I$4:$J$34,2,FALSE) | H10: 70 | I10: =IF(ROW()=5,G10-H10,I9+G10-H10) | J10: 28.3 | K10: =IFERROR((G10+H10)*J10,0)
A11: 46182 | B11: Salida Directa Máquina | C11: Carga directa | D11: Lerma - Tres Marías | E11: Doble Rodillo | F11: =VLOOKUP(TablaPegaso[[#This Row],[Equipo]],Catalogos!$I$4:$J$34,2,FALSE) | H11: 50 | I11: =IF(ROW()=5,G11-H11,I10+G11-H11) | J11: 28.3 | K11: =IFERROR((G11+H11)*J11,0)
A12: 46182 | B12: Salida Directa Máquina | C12: Carga directa | D12: Lerma - Tres Marías | E12: Petrolizadora | F12: =VLOOKUP(TablaPegaso[[#This Row],[Equipo]],Catalogos!$I$4:$J$34,2,FALSE) | H12: 60 | I12: =IF(ROW()=5,G12-H12,I11+G12-H12) | J12: 28.3 | K12: =IFERROR((G12+H12)*J12,0)
A13: 46183 | B13: Salida Directa Máquina | C13: Otro | D13: Bacheo Toluca | E13: Bidones | F13: =VLOOKUP(TablaPegaso[[#This Row],[Equipo]],Catalogos!$I$4:$J$34,2,FALSE) | H13: 100 | I13: =IF(ROW()=5,G13-H13,I12+G13-H13) | J13: 28.3 | K13: =IFERROR((G13+H13)*J13,0)
A14: 46184 | B14: Salida Directa Máquina | C14: Planta Asfalto Pegaso | D14: Planta Asfalto Pegaso | E14: PayLoder | F14: =VLOOKUP(TablaPegaso[[#This Row],[Equipo]],Catalogos!$I$4:$J$34,2,FALSE) | H14: 238 | I14: =IF(ROW()=5,G14-H14,I13+G14-H14) | J14: 28.3 | K14: =IFERROR((G14+H14)*J14,0)
A15: 46184 | B15: Salida Directa Máquina | C15: Carga directa | D15: Lerma - Tres Marías | E15: Petrolizadora | F15: =VLOOKUP(TablaPegaso[[#This Row],[Equipo]],Catalogos!$I$4:$J$34,2,FALSE) | H15: 80 | I15: =IF(ROW()=5,G15-H15,I14+G15-H15) | J15: 28.3 | K15: =IFERROR((G15+H15)*J15,0)
A16: 46184 | B16: Salida Directa Máquina | C16: Carga directa | D16: Lerma - Tres Marías | E16: Compresor | F16: =VLOOKUP(TablaPegaso[[#This Row],[Equipo]],Catalogos!$I$4:$J$34,2,FALSE) | H16: 50 | I16: =IF(ROW()=5,G16-H16,I15+G16-H16) | J16: 28.3 | K16: =IFERROR((G16+H16)*J16,0)
A17: 46184 | B17: Salida Directa Máquina | C17: Carga directa | D17: Lerma - Tres Marías | E17: Retroexcavadora | F17: =VLOOKUP(TablaPegaso[[#This Row],[Equipo]],Catalogos!$I$4:$J$34,2,FALSE) | H17: 70 | I17: =IF(ROW()=5,G17-H17,I16+G17-H17) | J17: 28.3 | K17: =IFERROR((G17+H17)*J17,0)
A18: 46184 | B18: Salida Directa Máquina | C18: Carga directa | D18: Lerma - Tres Marías | E18: Camion de Impacto | F18: =VLOOKUP(TablaPegaso[[#This Row],[Equipo]],Catalogos!$I$4:$J$34,2,FALSE) | H18: 80 | I18: =IF(ROW()=5,G18-H18,I17+G18-H18) | J18: 28.3 | K18: =IFERROR((G18+H18)*J18,0)
A19: 46184 | B19: Salida Directa Máquina | C19: Carga directa | D19: Lerma - Tres Marías | E19: Vogel | F19: =VLOOKUP(TablaPegaso[[#This Row],[Equipo]],Catalogos!$I$4:$J$34,2,FALSE) | H19: 185 | I19: =IF(ROW()=5,G19-H19,I18+G19-H19) | J19: 28.3 | K19: =IFERROR((G19+H19)*J19,0)
A20: 46184 | B20: Salida Directa Máquina | C20: Carga directa | D20: Lerma - Tres Marías | E20: Doble Rodillo | F20: =VLOOKUP(TablaPegaso[[#This Row],[Equipo]],Catalogos!$I$4:$J$34,2,FALSE) | H20: 50 | I20: =IF(ROW()=5,G20-H20,I19+G20-H20) | J20: 28.3 | K20: =IFERROR((G20+H20)*J20,0)
... A23: 46185 | B23: Salida Directa Máquina | C23: Carga directa | D23: Bacheo Toluca | E23: Barredora Broce | F23: =VLOOKUP(TablaPegaso[[#This Row],[Equipo]],Catalogos!$I$4:$J$34,2,FALSE) | H23: 70 | I23: =IF(ROW()=5,G23-H23,I22+G23-H23) | J23: 28.3 | K23: =IFERROR((G23+H23)*J23,0)
F24: =VLOOKUP(TablaPegaso[[#This Row],[Equipo]],Catalogos!$I$4:$J$34,2,FALSE) | I24: =IF(ROW()=5,G24-H24,I23+G24-H24) | K24: =IFERROR((G24+H24)*J24,0)
F25: =VLOOKUP(TablaPegaso[[#This Row],[Equipo]],Catalogos!$I$4:$J$34,2,FALSE) | I25: =IF(ROW()=5,G25-H25,I24+G25-H25) | K25: =IFERROR((G25+H25)*J25,0)
F26: =VLOOKUP(TablaPegaso[[#This Row],[Equipo]],Catalogos!$I$4:$J$34,2,FALSE) | I26: =IF(ROW()=5,G26-H26,I25+G26-H26) | K26: =IFERROR((G26+H26)*J26,0)
F27: =VLOOKUP(TablaPegaso[[#This Row],[Equipo]],Catalogos!$I$4:$J$34,2,FALSE) | I27: =IF(ROW()=5,G27-H27,I26+G27-H27) | K27: =IFERROR((G27+H27)*J27,0)
F28: =VLOOKUP(TablaPegaso[[#This Row],[Equipo]],Catalogos!$I$4:$J$34,2,FALSE) | I28: =IF(ROW()=5,G28-H28,I27+G28-H28) | K28: =IFERROR((G28+H28)*J28,0)
F29: =VLOOKUP(TablaPegaso[[#This Row],[Equipo]],Catalogos!$I$4:$J$34,2,FALSE) | I29: =IF(ROW()=5,G29-H29,I28+G29-H29) | K29: =IFERROR((G29+H29)*J29,0)
F30: =VLOOKUP(TablaPegaso[[#This Row],[Equipo]],Catalogos!$I$4:$J$34,2,FALSE) | I30: =IF(ROW()=5,G30-H30,I29+G30-H30) | K30: =IFERROR((G30+H30)*J30,0)
F31: =VLOOKUP(TablaPegaso[[#This Row],[Equipo]],Catalogos!$I$4:$J$34,2,FALSE) | I31: =IF(ROW()=5,G31-H31,I30+G31-H31) | K31: =IFERROR((G31+H31)*J31,0)
F32: =VLOOKUP(TablaPegaso[[#This Row],[Equipo]],Catalogos!$I$4:$J$34,2,FALSE) | I32: =IF(ROW()=5,G32-H32,I31+G32-H32) | K32: =IFERROR((G32+H32)*J32,0)
F33: =VLOOKUP(TablaPegaso[[#This Row],[Equipo]],Catalogos!$I$4:$J$34,2,FALSE) | I33: =IF(ROW()=5,G33-H33,I32+G33-H33) | K33: =IFERROR((G33+H33)*J33,0)
F34: =VLOOKUP(TablaPegaso[[#This Row],[Equipo]],Catalogos!$I$4:$J$34,2,FALSE) | I34: =IF(ROW()=5,G34-H34,I33+G34-H34) | K34: =IFERROR((G34+H34)*J34,0)
F35: =VLOOKUP(TablaPegaso[[#This Row],[Equipo]],Catalogos!$I$4:$J$34,2,FALSE) | I35: =IF(ROW()=5,G35-H35,I34+G35-H35) | K35: =IFERROR((G35+H35)*J35,0)
... F206: =VLOOKUP(TablaPegaso[[#This Row],[Equipo]],Catalogos!$I$4:$J$34,2,FALSE) | I206: =IF(ROW()=5,G206-H206,I205+G206-H206) | K206: =IFERROR((G206+H206)*J206,0)

Sheet Captura_Marimba_M01
A1: GC-COMB-002 | BITÁCORA DE SUMINISTRO DE MARIMBA M-01
A2: Operador: | C2: Semana: | E2: Fecha entrega: | G2: Marimba: | H2: M-01 | I2: Costo/L base:
A4: Fecha | B4: Movimiento | C4: Origen/Obra | D4: Equipo | E4: Económico | F4: Entrada (L) | G4: Salida (L) | H4: Existencia Teórica | I4: Costo/L | J4: Importe | K4: Firma/Validación | L4: Observaciones
A5: 46181 | B5: Salida a Obra | C5: México-Toluca | D5: Neuomatico | E5: =VLOOKUP(TablaMarimba[[#This Row],[Equipo]],Catalogos!$I$4:$J$34,2,FALSE) | F5: 0 | G5: 30 | H5: =IF(ROW()=5,F5-G5,H4+F5-G5) | I5: 28.3 | J5: =IFERROR((F5+G5)*I5,0)
A6: 46181 | B6: Salida a Obra | C6: México-Toluca | D6: Compactador | E6: =VLOOKUP(TablaMarimba[[#This Row],[Equipo]],Catalogos!$I$4:$J$34,2,FALSE) | G6: 32 | H6: =IF(ROW()=5,F6-G6,H5+F6-G6) | I6: 28.3 | J6: =IFERROR((F6+G6)*I6,0)
A7: 46181 | B7: Salida a Obra | C7: México-Toluca | D7: Perfiladora | E7: =VLOOKUP(TablaMarimba[[#This Row],[Equipo]],Catalogos!$I$4:$J$34,2,FALSE) | G7: 277 | H7: =IF(ROW()=5,F7-G7,H6+F7-G7) | I7: 28.3 | J7: =IFERROR((F7+G7)*I7,0)
A8: 46181 | B8: Salida a Obra | C8: México-Toluca | D8: Retroexcavadora | E8: =VLOOKUP(TablaMarimba[[#This Row],[Equipo]],Catalogos!$I$4:$J$34,2,FALSE) | G8: 30 | H8: =IF(ROW()=5,F8-G8,H7+F8-G8) | I8: 28.3 | J8: =IFERROR((F8+G8)*I8,0)
A9: 46181 | B9: Salida a Obra | C9: Lerma - Tres Marías | D9: Vogel | E9: =VLOOKUP(TablaMarimba[[#This Row],[Equipo]],Catalogos!$I$4:$J$34,2,FALSE) | G9: 97 | H9: =IF(ROW()=5,F9-G9,H8+F9-G9) | I9: 28.3 | J9: =IFERROR((F9+G9)*I9,0)
A10: 46181 | B10: Salida a Obra | C10: Chamapa-Lechería | D10: Perfiladora Wirgent | E10: =VLOOKUP(TablaMarimba[[#This Row],[Equipo]],Catalogos!$I$4:$J$34,2,FALSE) | G10: 198 | H10: =IF(ROW()=5,F10-G10,H9+F10-G10) | I10: 28.3 | J10: =IFERROR((F10+G10)*I10,0)
A11: 46181 | B11: Salida a Obra | C11: Chamapa-Lechería | D11: Maxilihgs | E11: =VLOOKUP(TablaMarimba[[#This Row],[Equipo]],Catalogos!$I$4:$J$34,2,FALSE) | G11: 10 | H11: =IF(ROW()=5,F11-G11,H10+F11-G11) | I11: 28.3 | J11: =IFERROR((F11+G11)*I11,0)
A12: 46181 | B12: Salida a Obra | C12: Chamapa-Lechería | D12: Neuomatico Dynapac | E12: =VLOOKUP(TablaMarimba[[#This Row],[Equipo]],Catalogos!$I$4:$J$34,2,FALSE) | G12: 27 | H12: =IF(ROW()=5,F12-G12,H11+F12-G12) | I12: 28.3 | J12: =IFERROR((F12+G12)*I12,0)
A13: 46181 | B13: Salida a Obra | C13: Chamapa-Lechería | D13: Compresor | E13: =VLOOKUP(TablaMarimba[[#This Row],[Equipo]],Catalogos!$I$4:$J$34,2,FALSE) | G13: 30 | H13: =IF(ROW()=5,F13-G13,H12+F13-G13) | I13: 28.3 | J13: =IFERROR((F13+G13)*I13,0)
A14: 46181 | B14: Salida a Obra | C14: Chamapa-Lechería | D14: Retroexcavadora Jonh Deere | E14: =VLOOKUP(TablaMarimba[[#This Row],[Equipo]],Catalogos!$I$4:$J$34,2,FALSE) | G14: 40 | H14: =IF(ROW()=5,F14-G14,H13+F14-G14) | I14: 28.3 | J14: =IFERROR((F14+G14)*I14,0)
A15: 46181 | B15: Salida a Obra | C15: Chamapa-Lechería | D15: Vogele Guion | E15: =VLOOKUP(TablaMarimba[[#This Row],[Equipo]],Catalogos!$I$4:$J$34,2,FALSE) | G15: 120 | H15: =IF(ROW()=5,F15-G15,H14+F15-G15) | I15: 28.3 | J15: =IFERROR((F15+G15)*I15,0)
A16: 46181 | B16: Salida a Obra | C16: Chamapa-Lechería | D16: Petrolizadora Elton | E16: =VLOOKUP(TablaMarimba[[#This Row],[Equipo]],Catalogos!$I$4:$J$34,2,FALSE) | G16: 30 | H16: =IF(ROW()=5,F16-G16,H15+F16-G16) | I16: 28.3 | J16: =IFERROR((F16+G16)*I16,0)
A17: 46182 | B17: Salida a Obra | C17: Chamapa-Lechería | D17: Barredora Broce | E17: =VLOOKUP(TablaMarimba[[#This Row],[Equipo]],Catalogos!$I$4:$J$34,2,FALSE) | G17: 30 | H17: =IF(ROW()=5,F17-G17,H16+F17-G17) | I17: 28.3 | J17: =IFERROR((F17+G17)*I17,0)
... A42: 46185 | B42: Salida a Obra | C42: Chamapa-Lechería | D42: Petrolizadora Elton | E42: =VLOOKUP(TablaMarimba[[#This Row],[Equipo]],Catalogos!$I$4:$J$34,2,FALSE) | G42: 40 | H42: =IF(ROW()=5,F42-G42,H41+F42-G42) | I42: 28.3 | J42: =IFERROR((F42+G42)*I42,0)
A43: 46185 | B43: Salida a Obra | C43: Chamapa-Lechería | D43: Perfiladora Wirgent | E43: =VLOOKUP(TablaMarimba[[#This Row],[Equipo]],Catalogos!$I$4:$J$34,2,FALSE) | G43: 200 | H43: =IF(ROW()=5,F43-G43,H42+F43-G43) | I43: 28.3 | J43: =IFERROR((F43+G43)*I43,0) | N43: =SUM(G5:G48)
A44: 46185 | B44: Salida a Obra | C44: México-Toluca | D44: Barredora | E44: =VLOOKUP(TablaMarimba[[#This Row],[Equipo]],Catalogos!$I$4:$J$34,2,FALSE) | G44: 20 | H44: =IF(ROW()=5,F44-G44,H43+F44-G44) | I44: 28.3 | J44: =IFERROR((F44+G44)*I44,0)
A45: 46185 | B45: Salida a Obra | C45: México-Toluca | D45: Neuomatico | E45: =VLOOKUP(TablaMarimba[[#This Row],[Equipo]],Catalogos!$I$4:$J$34,2,FALSE) | G45: 30 | H45: =IF(ROW()=5,F45-G45,H44+F45-G45) | I45: 28.3 | J45: =IFERROR((F45+G45)*I45,0)
A46: 46185 | B46: Salida a Obra | C46: México-Toluca | D46: Maxilihgs | E46: =VLOOKUP(TablaMarimba[[#This Row],[Equipo]],Catalogos!$I$4:$J$34,2,FALSE) | G46: 20 | H46: =IF(ROW()=5,F46-G46,H45+F46-G46) | I46: 28.3 | J46: =IFERROR((F46+G46)*I46,0)
A47: 46185 | B47: Salida a Obra | C47: México-Toluca | D47: Compactador | E47: =VLOOKUP(TablaMarimba[[#This Row],[Equipo]],Catalogos!$I$4:$J$34,2,FALSE) | G47: 40 | H47: =IF(ROW()=5,F47-G47,H46+F47-G47) | I47: 28.3 | J47: =IFERROR((F47+G47)*I47,0)
A48: 46185 | B48: Salida a Obra | C48: México-Toluca | D48: Perfiladora | E48: =VLOOKUP(TablaMarimba[[#This Row],[Equipo]],Catalogos!$I$4:$J$34,2,FALSE) | G48: 250 | H48: =IF(ROW()=5,F48-G48,H47+F48-G48) | I48: 28.3 | J48: =IFERROR((F48+G48)*I48,0)
E49: =VLOOKUP(TablaMarimba[[#This Row],[Equipo]],Catalogos!$I$4:$J$34,2,FALSE) | H49: =IF(ROW()=5,F49-G49,H48+F49-G49) | I49: 28.3 | J49: =IFERROR((F49+G49)*I49,0)
E50: =VLOOKUP(TablaMarimba[[#This Row],[Equipo]],Catalogos!$I$4:$J$34,2,FALSE) | H50: =IF(ROW()=5,F50-G50,H49+F50-G50) | I50: 28.3 | J50: =IFERROR((F50+G50)*I50,0)
E51: =VLOOKUP(TablaMarimba[[#This Row],[Equipo]],Catalogos!$I$4:$J$34,2,FALSE) | H51: =IF(ROW()=5,F51-G51,H50+F51-G51) | I51: 28.3 | J51: =IFERROR((F51+G51)*I51,0)
E52: =VLOOKUP(TablaMarimba[[#This Row],[Equipo]],Catalogos!$I$4:$J$34,2,FALSE) | H52: =IF(ROW()=5,F52-G52,H51+F52-G52) | I52: 28.3 | J52: =IFERROR((F52+G52)*I52,0)
E53: =VLOOKUP(TablaMarimba[[#This Row],[Equipo]],Catalogos!$I$4:$J$34,2,FALSE) | H53: =IF(ROW()=5,F53-G53,H52+F53-G53) | I53: 28.3 | J53: =IFERROR((F53+G53)*I53,0)
E54: =VLOOKUP(TablaMarimba[[#This Row],[Equipo]],Catalogos!$I$4:$J$34,2,FALSE) | H54: =IF(ROW()=5,F54-G54,H53+F54-G54) | I54: 28.3 | J54: =IFERROR((F54+G54)*I54,0)
E55: =VLOOKUP(TablaMarimba[[#This Row],[Equipo]],Catalogos!$I$4:$J$34,2,FALSE) | H55: =IF(ROW()=5,F55-G55,H54+F55-G55) | I55: 28.3 | J55: =IFERROR((F55+G55)*I55,0)
E56: =VLOOKUP(TablaMarimba[[#This Row],[Equipo]],Catalogos!$I$4:$J$34,2,FALSE) | H56: =IF(ROW()=5,F56-G56,H55+F56-G56) | I56: 28.3 | J56: =IFERROR((F56+G56)*I56,0)
E57: =VLOOKUP(TablaMarimba[[#This Row],[Equipo]],Catalogos!$I$4:$J$34,2,FALSE) | H57: =IF(ROW()=5,F57-G57,H56+F57-G57) | I57: 28.3 | J57: =IFERROR((F57+G57)*I57,0)
E58: =VLOOKUP(TablaMarimba[[#This Row],[Equipo]],Catalogos!$I$4:$J$34,2,FALSE) | H58: =IF(ROW()=5,F58-G58,H57+F58-G58) | I58: 28.3 | J58: =IFERROR((F58+G58)*I58,0)
E59: =VLOOKUP(TablaMarimba[[#This Row],[Equipo]],Catalogos!$I$4:$J$34,2,FALSE) | H59: =IF(ROW()=5,F59-G59,H58+F59-G59) | I59: 28.3 | J59: =IFERROR((F59+G59)*I59,0)
E60: =VLOOKUP(TablaMarimba[[#This Row],[Equipo]],Catalogos!$I$4:$J$34,2,FALSE) | H60: =IF(ROW()=5,F60-G60,H59+F60-G60) | I60: 28.3 | J60: =IFERROR((F60+G60)*I60,0)
... E204: =VLOOKUP(TablaMarimba[[#This Row],[Equipo]],Catalogos!$I$4:$J$34,2,FALSE) | H204: =IF(ROW()=5,F204-G204,H203+F204-G204) | I204: 28.3 | J204: =IFERROR((F204+G204)*I204,0)

Sheet Solicitudes
A1: GC-COMB-003 | BITÁCORA DE SOLICITUDES DE COMBUSTIBLE DE OBRA
A2: Ingeniero: | C2: Semana: | E2: Fecha entrega: | G2: Obra: | I2: Costo/L base:
A4: Fecha de Solicitud | B4: Obra | C4: Fecha de Trabajo | D4: Equipo | E4: Económico | F4: Litros Solicitados | G4: Costo/L | H4: Importe | I4: Solicitante | J4: Incidencia | K4: Observaciones
A5: 46180 | B5: México-Toluca | C5: 46181 | D5: Vogel | E5: =VLOOKUP(TablaObra5[[#This Row],[Equipo]],Catalogos!$I$3:$J$34,2,FALSE) | F5: 200 | G5: 28.3 | H5: =IFERROR(F5*G5,0) | I5: =VLOOKUP(TablaObra5[[#This Row],[Obra]],Catalogos!$B$3:$C$8,2,FALSE)
A6: 46180 | B6: México-Toluca | C6: 46181 | D6: Perfiladora | E6: =VLOOKUP(TablaObra5[[#This Row],[Equipo]],Catalogos!$I$3:$J$34,2,FALSE) | F6: 300 | G6: 28.3 | H6: =IFERROR(F6*G6,0) | I6: =VLOOKUP(TablaObra5[[#This Row],[Obra]],Catalogos!$B$3:$C$8,2,FALSE)
A7: 46180 | B7: México-Toluca | C7: 46181 | D7: Retroexcavadora | E7: =VLOOKUP(TablaObra5[[#This Row],[Equipo]],Catalogos!$I$3:$J$34,2,FALSE) | F7: 30 | G7: 28.3 | H7: =IFERROR(F7*G7,0) | I7: =VLOOKUP(TablaObra5[[#This Row],[Obra]],Catalogos!$B$3:$C$8,2,FALSE)
A8: 46180 | B8: México-Toluca | C8: 46181 | D8: Barredora | E8: =VLOOKUP(TablaObra5[[#This Row],[Equipo]],Catalogos!$I$3:$J$34,2,FALSE) | F8: 20 | G8: 28.3 | H8: =IFERROR(F8*G8,0) | I8: =VLOOKUP(TablaObra5[[#This Row],[Obra]],Catalogos!$B$3:$C$8,2,FALSE)
A9: 46180 | B9: México-Toluca | C9: 46181 | D9: Neuomatico | E9: =VLOOKUP(TablaObra5[[#This Row],[Equipo]],Catalogos!$I$3:$J$34,2,FALSE) | F9: 30 | G9: 28.3 | H9: =IFERROR(F9*G9,0) | I9: =VLOOKUP(TablaObra5[[#This Row],[Obra]],Catalogos!$B$3:$C$8,2,FALSE)
A10: 46180 | B10: México-Toluca | C10: 46181 | D10: Compactador | E10: =VLOOKUP(TablaObra5[[#This Row],[Equipo]],Catalogos!$I$3:$J$34,2,FALSE) | F10: 30 | G10: 28.3 | H10: =IFERROR(F10*G10,0) | I10: =VLOOKUP(TablaObra5[[#This Row],[Obra]],Catalogos!$B$3:$C$8,2,FALSE)
A11: 46180 | B11: México-Toluca | C11: 46181 | D11: Limpieza | E11: =VLOOKUP(TablaObra5[[#This Row],[Equipo]],Catalogos!$I$3:$J$34,2,FALSE) | F11: 30 | G11: 28.3 | H11: =IFERROR(F11*G11,0) | I11: =VLOOKUP(TablaObra5[[#This Row],[Obra]],Catalogos!$B$3:$C$8,2,FALSE)
A12: 46180 | B12: Lerma - Tres Marías | C12: 46181 | D12: Retroexcavadora | E12: =VLOOKUP(TablaObra5[[#This Row],[Equipo]],Catalogos!$I$3:$J$34,2,FALSE) | F12: 50 | G12: 28.3 | H12: =IFERROR(F12*G12,0) | I12: =VLOOKUP(TablaObra5[[#This Row],[Obra]],Catalogos!$B$3:$C$8,2,FALSE)
A13: 46180 | B13: Lerma - Tres Marías | C13: 46181 | D13: Neuomatico | E13: =VLOOKUP(TablaObra5[[#This Row],[Equipo]],Catalogos!$I$3:$J$34,2,FALSE) | F13: 50 | G13: 28.3 | H13: =IFERROR(F13*G13,0) | I13: =VLOOKUP(TablaObra5[[#This Row],[Obra]],Catalogos!$B$3:$C$8,2,FALSE)
A14: 46180 | B14: Lerma - Tres Marías | C14: 46181 | D14: Petrolizadora | E14: =VLOOKUP(TablaObra5[[#This Row],[Equipo]],Catalogos!$I$3:$J$34,2,FALSE) | F14: 60 | G14: 28.3 | H14: =IFERROR(F14*G14,0) | I14: =VLOOKUP(TablaObra5[[#This Row],[Obra]],Catalogos!$B$3:$C$8,2,FALSE)
A15: 46181 | B15: Bacheo Toluca | D15: Retroexcavadora | E15: =VLOOKUP(TablaObra5[[#This Row],[Equipo]],Catalogos!$I$3:$J$34,2,FALSE) | F15: 100 | G15: 28.3 | H15: =IFERROR(F15*G15,0) | I15: =VLOOKUP(TablaObra5[[#This Row],[Obra]],Catalogos!$B$3:$C$8,2,FALSE)
A16: 46181 | B16: Chamapa-Lechería | C16: 46181 | D16: Perfiladora Wirgent | E16: =VLOOKUP(TablaObra5[[#This Row],[Equipo]],Catalogos!$I$3:$J$34,2,FALSE) | F16: 250 | G16: 28.3 | H16: =IFERROR(F16*G16,0) | I16: =VLOOKUP(TablaObra5[[#This Row],[Obra]],Catalogos!$B$3:$C$8,2,FALSE)
A17: 46181 | B17: Chamapa-Lechería | C17: 46181 | D17: Perfiladora Cat-PM | E17: =VLOOKUP(TablaObra5[[#This Row],[Equipo]],Catalogos!$I$3:$J$34,2,FALSE) | F17: 150 | G17: 28.3 | H17: =IFERROR(F17*G17,0) | I17: =VLOOKUP(TablaObra5[[#This Row],[Obra]],Catalogos!$B$3:$C$8,2,FALSE)
A18: 46181 | B18: Chamapa-Lechería | C18: 46181 | D18: Barredora Broce | E18: =VLOOKUP(TablaObra5[[#This Row],[Equipo]],Catalogos!$I$3:$J$34,2,FALSE) | F18: 40 | G18: 28.3 | H18: =IFERROR(F18*G18,0) | I18: =VLOOKUP(TablaObra5[[#This Row],[Obra]],Catalogos!$B$3:$C$8,2,FALSE)
A19: 46181 | B19: Chamapa-Lechería | C19: 46181 | D19: Retroexcavadora Jonh Deere | E19: =VLOOKUP(TablaObra5[[#This Row],[Equipo]],Catalogos!$I$3:$J$34,2,FALSE) | F19: 60 | G19: 28.3 | H19: =IFERROR(F19*G19,0) | I19: =VLOOKUP(TablaObra5[[#This Row],[Obra]],Catalogos!$B$3:$C$8,2,FALSE)
A20: 46181 | B20: Chamapa-Lechería | C20: 46181 | D20: Buggy Trasnfer | E20: =VLOOKUP(TablaObra5[[#This Row],[Equipo]],Catalogos!$I$3:$J$34,2,FALSE) | F20: 100 | G20: 28.3 | H20: =IFERROR(F20*G20,0) | I20: =VLOOKUP(TablaObra5[[#This Row],[Obra]],Catalogos!$B$3:$C$8,2,FALSE)
A21: 46181 | B21: Chamapa-Lechería | C21: 46181 | D21: Vogele Guion | E21: =VLOOKUP(TablaObra5[[#This Row],[Equipo]],Catalogos!$I$3:$J$34,2,FALSE) | F21: 100 | G21: 28.3 | H21: =IFERROR(F21*G21,0) | I21: =VLOOKUP(TablaObra5[[#This Row],[Obra]],Catalogos!$B$3:$C$8,2,FALSE)
A22: 46181 | B22: Chamapa-Lechería | C22: 46181 | D22: Limpieza | E22: =VLOOKUP(TablaObra5[[#This Row],[Equipo]],Catalogos!$I$3:$J$34,2,FALSE) | F22: 20 | G22: 28.3 | H22: =IFERROR(F22*G22,0) | I22: =VLOOKUP(TablaObra5[[#This Row],[Obra]],Catalogos!$B$3:$C$8,2,FALSE)
A23: 46181 | B23: Chamapa-Lechería | C23: 46181 | D23: Tandem Hamm | E23: =VLOOKUP(TablaObra5[[#This Row],[Equipo]],Catalogos!$I$3:$J$34,2,FALSE) | F23: 50 | G23: 28.3 | H23: =IFERROR(F23*G23,0) | I23: =VLOOKUP(TablaObra5[[#This Row],[Obra]],Catalogos!$B$3:$C$8,2,FALSE)
A24: 46181 | B24: Chamapa-Lechería | C24: 46181 | D24: Neuomatico Dynapac | E24: =VLOOKUP(TablaObra5[[#This Row],[Equipo]],Catalogos!$I$3:$J$34,2,FALSE) | F24: 50 | G24: 28.3 | H24: =IFERROR(F24*G24,0) | I24: =VLOOKUP(TablaObra5[[#This Row],[Obra]],Catalogos!$B$3:$C$8,2,FALSE)
A25: 46181 | B25: Chamapa-Lechería | C25: 46181 | D25: Petrolizadora Elton | E25: =VLOOKUP(TablaObra5[[#This Row],[Equipo]],Catalogos!$I$3:$J$34,2,FALSE) | F25: 50 | G25: 28.3 | H25: =IFERROR(F25*G25,0) | I25: =VLOOKUP(TablaObra5[[#This Row],[Obra]],Catalogos!$B$3:$C$8,2,FALSE)
A26: 46181 | B26: Chamapa-Lechería | C26: 46181 | D26: Camion de Impacto | E26: =VLOOKUP(TablaObra5[[#This Row],[Equipo]],Catalogos!$I$3:$J$34,2,FALSE) | F26: 20 | G26: 28.3 | H26: =IFERROR(F26*G26,0) | I26: =VLOOKUP(TablaObra5[[#This Row],[Obra]],Catalogos!$B$3:$C$8,2,FALSE)
A27: 46181 | B27: Chamapa-Lechería | C27: 46181 | D27: Maxilihgs | E27: =VLOOKUP(TablaObra5[[#This Row],[Equipo]],Catalogos!$I$3:$J$34,2,FALSE) | F27: 50 | G27: 28.3 | H27: =IFERROR(F27*G27,0) | I27: =VLOOKUP(TablaObra5[[#This Row],[Obra]],Catalogos!$B$3:$C$8,2,FALSE)
... A40: 46182 | B40: Chamapa-Lechería | C40: 46182 | D40: Compresor | E40: =VLOOKUP(TablaObra5[[#This Row],[Equipo]],Catalogos!$I$3:$J$34,2,FALSE) | F40: 30 | G40: 28.3 | H40: =IFERROR(F40*G40,0) | I40: =VLOOKUP(TablaObra5[[#This Row],[Obra]],Catalogos!$B$3:$C$8,2,FALSE)
A41: 46182 | B41: Lerma - Tres Marías | C41: 46182 | D41: Retroexcavadora | E41: =VLOOKUP(TablaObra5[[#This Row],[Equipo]],Catalogos!$I$3:$J$34,2,FALSE) | F41: 50 | G41: 28.3 | H41: =IFERROR(F41*G41,0) | I41: =VLOOKUP(TablaObra5[[#This Row],[Obra]],Catalogos!$B$3:$C$8,2,FALSE) | K41: Segunda solicitud, el dia 7/06/2026, no se relizo la carga
A42: 46182 | B42: Lerma - Tres Marías | C42: 46182 | D42: Neuomatico | E42: =VLOOKUP(TablaObra5[[#This Row],[Equipo]],Catalogos!$I$3:$J$34,2,FALSE) | F42: 50 | G42: 28.3 | H42: =IFERROR(F42*G42,0) | I42: =VLOOKUP(TablaObra5[[#This Row],[Obra]],Catalogos!$B$3:$C$8,2,FALSE)
A43: 46182 | B43: Lerma - Tres Marías | C43: 46182 | D43: Petrolizadora | E43: =VLOOKUP(TablaObra5[[#This Row],[Equipo]],Catalogos!$I$3:$J$34,2,FALSE) | F43: 60 | G43: 28.3 | H43: =IFERROR(F43*G43,0) | I43: =VLOOKUP(TablaObra5[[#This Row],[Obra]],Catalogos!$B$3:$C$8,2,FALSE)
A44: 46182 | B44: Lerma - Tres Marías | C44: 46182 | D44: Doble Rodillo | E44: =VLOOKUP(TablaObra5[[#This Row],[Equipo]],Catalogos!$I$3:$J$34,2,FALSE) | F44: 50 | G44: 28.3 | H44: =IFERROR(F44*G44,0) | I44: =VLOOKUP(TablaObra5[[#This Row],[Obra]],Catalogos!$B$3:$C$8,2,FALSE)
A45: 46182 | B45: Bacheo Toluca | D45: Retroexcavadora | E45: =VLOOKUP(TablaObra5[[#This Row],[Equipo]],Catalogos!$I$3:$J$34,2,FALSE) | F45: 100 | G45: 28.3 | H45: =IFERROR(F45*G45,0) | I45: =VLOOKUP(TablaObra5[[#This Row],[Obra]],Catalogos!$B$3:$C$8,2,FALSE)
A46: 46183 | B46: México-Toluca | C46: 46183 | D46: Perfiladora | E46: =VLOOKUP(TablaObra5[[#This Row],[Equipo]],Catalogos!$I$3:$J$34,2,FALSE) | F46: 250 | G46: 28.3 | H46: =IFERROR(F46*G46,0) | I46: =VLOOKUP(TablaObra5[[#This Row],[Obra]],Catalogos!$B$3:$C$8,2,FALSE)
A47: 46183 | B47: México-Toluca | C47: 46183 | D47: Retroexcavadora | E47: =VLOOKUP(TablaObra5[[#This Row],[Equipo]],Catalogos!$I$3:$J$34,2,FALSE) | F47: 30 | G47: 28.3 | H47: =IFERROR(F47*G47,0) | I47: =VLOOKUP(TablaObra5[[#This Row],[Obra]],Catalogos!$B$3:$C$8,2,FALSE)
A48: 46183 | B48: México-Toluca | C48: 46183 | D48: Barredora | E48: =VLOOKUP(TablaObra5[[#This Row],[Equipo]],Catalogos!$I$3:$J$34,2,FALSE) | F48: 20 | G48: 28.3 | H48: =IFERROR(F48*G48,0) | I48: =VLOOKUP(TablaObra5[[#This Row],[Obra]],Catalogos!$B$3:$C$8,2,FALSE)
A49: 46183 | B49: México-Toluca | C49: 46183 | D49: Maxilihgs | E49: =VLOOKUP(TablaObra5[[#This Row],[Equipo]],Catalogos!$I$3:$J$34,2,FALSE) | F49: 20 | G49: 28.3 | H49: =IFERROR(F49*G49,0) | I49: =VLOOKUP(TablaObra5[[#This Row],[Obra]],Catalogos!$B$3:$C$8,2,FALSE)
A50: 46184 | B50: Lerma - Tres Marías | C50: 46184 | D50: Petrolizadora | E50: =VLOOKUP(TablaObra5[[#This Row],[Equipo]],Catalogos!$I$3:$J$34,2,FALSE) | F50: 80 | G50: 28.3 | H50: =IFERROR(F50*G50,0) | I50: =VLOOKUP(TablaObra5[[#This Row],[Obra]],Catalogos!$B$3:$C$8,2,FALSE)
A51: 46184 | B51: Lerma - Tres Marías | C51: 46184 | D51: Camion de Impacto | E51: =VLOOKUP(TablaObra5[[#This Row],[Equipo]],Catalogos!$I$3:$J$34,2,FALSE) | F51: 80 | G51: 28.3 | H51: =IFERROR(F51*G51,0) | I51: =VLOOKUP(TablaObra5[[#This Row],[Obra]],Catalogos!$B$3:$C$8,2,FALSE)
A52: 46184 | B52: Lerma - Tres Marías | C52: 46184 | D52: Retroexcavadora | E52: =VLOOKUP(TablaObra5[[#This Row],[Equipo]],Catalogos!$I$3:$J$34,2,FALSE) | F52: 70 | G52: 28.3 | H52: =IFERROR(F52*G52,0) | I52: =VLOOKUP(TablaObra5[[#This Row],[Obra]],Catalogos!$B$3:$C$8,2,FALSE)
A53: 46184 | B53: Lerma - Tres Marías | C53: 46184 | D53: Doble Rodillo | E53: =VLOOKUP(TablaObra5[[#This Row],[Equipo]],Catalogos!$I$3:$J$34,2,FALSE) | F53: 40 | G53: 28.3 | H53: =IFERROR(F53*G53,0) | I53: =VLOOKUP(TablaObra5[[#This Row],[Obra]],Catalogos!$B$3:$C$8,2,FALSE)
...

Sheet Captura_Obra
A1: GC-COMB-003 | BITÁCORA DE CONTROL DE COMBUSTIBLE DE OBRA
A2: Ingeniero: | C2: Semana: | E2: Fecha entrega: | G2: Obra: | I2: Costo/L base:
A4: Fecha | B4: Obra | C4: Fuente | D4: Equipo | E4: Económico | F4: Litros Recibidos | G4: Costo/L | H4: Importe | I4: Actividad Ejecutada | J4: Incidencia | K4: Observaciones
A5: 46181 | B5: México-Toluca | C5: Marimba M-01 | D5: Neuomatico | E5: =VLOOKUP(TablaObra[[#This Row],[Equipo]],Catalogos!I$4:J$34,2,FALSE) | F5: 30 | G5: 28.3 | H5: =IFERROR(F5*G5,0)
A6: 46181 | B6: México-Toluca | C6: Marimba M-01 | D6: Compactador | E6: =VLOOKUP(TablaObra[[#This Row],[Equipo]],Catalogos!I$4:J$34,2,FALSE) | F6: 32 | G6: 28.3 | H6: =IFERROR(F6*G6,0)
A7: 46181 | B7: México-Toluca | C7: Marimba M-01 | D7: Perfiladora | E7: =VLOOKUP(TablaObra[[#This Row],[Equipo]],Catalogos!I$4:J$34,2,FALSE) | F7: 277 | G7: 28.3 | H7: =IFERROR(F7*G7,0)
A8: 46181 | B8: México-Toluca | C8: Marimba M-01 | D8: Retroexcavadora | E8: =VLOOKUP(TablaObra[[#This Row],[Equipo]],Catalogos!I$4:J$34,2,FALSE) | F8: 30 | G8: 28.3 | H8: =IFERROR(F8*G8,0)
A9: 46181 | B9: Lerma - Tres Marías | C9: Marimba M-01 | D9: Vogel | E9: =VLOOKUP(TablaObra[[#This Row],[Equipo]],Catalogos!I$4:J$34,2,FALSE) | F9: 97 | G9: 28.3 | H9: =IFERROR(F9*G9,0)
A10: 46181 | B10: Chamapa-Lechería | C10: Marimba M-01 | D10: Perfiladora Wirgent | E10: =VLOOKUP(TablaObra[[#This Row],[Equipo]],Catalogos!I$4:J$34,2,FALSE) | F10: 198 | G10: 28.3 | H10: =IFERROR(F10*G10,0)
A11: 46181 | B11: Chamapa-Lechería | C11: Marimba M-01 | D11: Maxilihgs | E11: =VLOOKUP(TablaObra[[#This Row],[Equipo]],Catalogos!I$4:J$34,2,FALSE) | F11: 10 | G11: 28.3 | H11: =IFERROR(F11*G11,0)
A12: 46181 | B12: Chamapa-Lechería | C12: Marimba M-01 | D12: Neuomatico Dynapac | E12: =VLOOKUP(TablaObra[[#This Row],[Equipo]],Catalogos!I$4:J$34,2,FALSE) | F12: 27 | G12: 28.3 | H12: =IFERROR(F12*G12,0)
A13: 46181 | B13: Chamapa-Lechería | C13: Marimba M-01 | D13: Compresor | E13: =VLOOKUP(TablaObra[[#This Row],[Equipo]],Catalogos!I$4:J$34,2,FALSE) | F13: 30 | G13: 28.3 | H13: =IFERROR(F13*G13,0)
A14: 46181 | B14: Chamapa-Lechería | C14: Marimba M-01 | D14: Retroexcavadora Jonh Deere | E14: =VLOOKUP(TablaObra[[#This Row],[Equipo]],Catalogos!I$4:J$34,2,FALSE) | F14: 40 | G14: 28.3 | H14: =IFERROR(F14*G14,0) | M14: =SUM(F5:F64)
A15: 46181 | B15: Chamapa-Lechería | C15: Marimba M-01 | D15: Vogele Guion | E15: =VLOOKUP(TablaObra[[#This Row],[Equipo]],Catalogos!I$4:J$34,2,FALSE) | F15: 120 | G15: 28.3 | H15: =IFERROR(F15*G15,0)
A16: 46181 | B16: Chamapa-Lechería | C16: Marimba M-01 | D16: Petrolizadora Elton | E16: =VLOOKUP(TablaObra[[#This Row],[Equipo]],Catalogos!I$4:J$34,2,FALSE) | F16: 30 | G16: 28.3 | H16: =IFERROR(F16*G16,0)
A17: 46181 | B17: Bacheo Toluca | C17: Pegaso Directo | D17: Bidones | E17: =VLOOKUP(TablaObra[[#This Row],[Equipo]],Catalogos!I$4:J$34,2,FALSE) | F17: 100 | G17: 28.3 | H17: =IFERROR(F17*G17,0)
A18: 46181 | B18: Planta Asfalto Pegaso | C18: Pegaso Directo | D18: Bidones | E18: =VLOOKUP(TablaObra[[#This Row],[Equipo]],Catalogos!I$4:J$34,2,FALSE) | F18: 200 | G18: 28.3 | H18: =IFERROR(F18*G18,0)
A19: 46181 | B19: Planta Asfalto Pegaso | C19: Pegaso Directo | D19: Bidones | E19: =VLOOKUP(TablaObra[[#This Row],[Equipo]],Catalogos!I$4:J$34,2,FALSE) | F19: 209 | G19: 28.3 | H19: =IFERROR(F19*G19,0)
A20: 46182 | B20: Chamapa-Lechería | C20: Marimba M-01 | D20: Barredora Broce | E20: =VLOOKUP(TablaObra[[#This Row],[Equipo]],Catalogos!I$4:J$34,2,FALSE) | F20: 30 | G20: 28.3 | H20: =IFERROR(F20*G20,0)
A21: 46182 | B21: Chamapa-Lechería | C21: Marimba M-01 | D21: Buggy Trasnfer | E21: =VLOOKUP(TablaObra[[#This Row],[Equipo]],Catalogos!I$4:J$34,2,FALSE) | F21: 100 | G21: 28.3 | H21: =IFERROR(F21*G21,0)
A22: 46182 | B22: Chamapa-Lechería | C22: Marimba M-01 | D22: Tandem Hamm | E22: =VLOOKUP(TablaObra[[#This Row],[Equipo]],Catalogos!I$4:J$34,2,FALSE) | F22: 30 | G22: 28.3 | H22: =IFERROR(F22*G22,0)
A23: 46182 | B23: Chamapa-Lechería | C23: Marimba M-01 | D23: Perfiladora Wirgent | E23: =VLOOKUP(TablaObra[[#This Row],[Equipo]],Catalogos!I$4:J$34,2,FALSE) | F23: 150 | G23: 28.3 | H23: =IFERROR(F23*G23,0)
A24: 46182 | B24: Chamapa-Lechería | C24: Marimba M-01 | D24: Petrolizadora Elton | E24: =VLOOKUP(TablaObra[[#This Row],[Equipo]],Catalogos!I$4:J$34,2,FALSE) | F24: 50 | G24: 28.3 | H24: =IFERROR(F24*G24,0)
A25: 46182 | B25: Chamapa-Lechería | C25: Marimba M-01 | D25: Vogele Guion | E25: =VLOOKUP(TablaObra[[#This Row],[Equipo]],Catalogos!I$4:J$34,2,FALSE) | F25: 136 | G25: 28.3 | H25: =IFERROR(F25*G25,0)
A26: 46182 | B26: Chamapa-Lechería | C26: Marimba M-01 | D26: Tandem Hamm | E26: =VLOOKUP(TablaObra[[#This Row],[Equipo]],Catalogos!I$4:J$34,2,FALSE) | F26: 30 | G26: 28.3 | H26: =IFERROR(F26*G26,0)
... A37: 46183 | B37: Bacheo Toluca | C37: Pegaso Directo | D37: Bidones | E37: =VLOOKUP(TablaObra[[#This Row],[Equipo]],Catalogos!I$4:J$34,2,FALSE) | F37: 100 | G37: 28.3 | H37: =IFERROR(F37*G37,0)
A38: 46184 | B38: México-Toluca | C38: Marimba M-01 | D38: Compactador | E38: =VLOOKUP(TablaObra[[#This Row],[Equipo]],Catalogos!I$4:J$34,2,FALSE) | F38: 30 | G38: 28.3 | H38: =IFERROR(F38*G38,0) | K38: Cuerpo a (Pausada)
A39: 46184 | B39: México-Toluca | C39: Marimba M-01 | D39: Neuomatico | E39: =VLOOKUP(TablaObra[[#This Row],[Equipo]],Catalogos!I$4:J$34,2,FALSE) | F39: 30 | G39: 28.3 | H39: =IFERROR(F39*G39,0) | K39: Cuerpo a (Pausada)
A40: 46184 | B40: México-Toluca | C40: Marimba M-01 | D40: Vogel | E40: =VLOOKUP(TablaObra[[#This Row],[Equipo]],Catalogos!I$4:J$34,2,FALSE) | F40: 136 | G40: 28.3 | H40: =IFERROR(F40*G40,0) | K40: Cuerpo a (Pausada)
A41: 46184 | B41: México-Toluca | C41: Marimba M-01 | D41: Barredora | E41: =VLOOKUP(TablaObra[[#This Row],[Equipo]],Catalogos!I$4:J$34,2,FALSE) | F41: 20 | G41: 28.3 | H41: =IFERROR(F41*G41,0) | K41: Cuerpo a (Pausada)
A42: 46184 | B42: México-Toluca | C42: Marimba M-01 | D42: Retroexcavadora | E42: =VLOOKUP(TablaObra[[#This Row],[Equipo]],Catalogos!I$4:J$34,2,FALSE) | F42: 20 | G42: 28.3 | H42: =IFERROR(F42*G42,0) | K42: Cuerpo a (Pausada)
A43: 46184 | B43: México-Toluca | C43: Marimba M-01 | D43: Maxilihgs | E43: =VLOOKUP(TablaObra[[#This Row],[Equipo]],Catalogos!I$4:J$34,2,FALSE) | F43: 20 | G43: 28.3 | H43: =IFERROR(F43*G43,0) | K43: Cuerpo a (Pausada)
A44: 46184 | B44: Planta Asfalto Pegaso | C44: Pegaso Directo | D44: PayLoder | E44: =VLOOKUP(TablaObra[[#This Row],[Equipo]],Catalogos!I$4:J$34,2,FALSE) | F44: 238 | G44: 28.3 | H44: =IFERROR(F44*G44,0)
A45: 46184 | B45: Lerma - Tres Marías | C45: Pegaso Directo | D45: Petrolizadora | E45: =VLOOKUP(TablaObra[[#This Row],[Equipo]],Catalogos!I$4:J$34,2,FALSE) | F45: 80 | G45: 28.3 | H45: =IFERROR(F45*G45,0)
A46: 46184 | B46: Lerma - Tres Marías | C46: Pegaso Directo | D46: Compresor | E46: =VLOOKUP(TablaObra[[#This Row],[Equipo]],Catalogos!I$4:J$34,2,FALSE) | F46: 50 | G46: 28.3 | H46: =IFERROR(F46*G46,0)
A47: 46184 | B47: Lerma - Tres Marías | C47: Pegaso Directo | D47: Retroexcavadora | E47: =VLOOKUP(TablaObra[[#This Row],[Equipo]],Catalogos!I$4:J$34,2,FALSE) | F47: 70 | G47: 28.3 | H47: =IFERROR(F47*G47,0)
A48: 46184 | B48: Lerma - Tres Marías | C48: Pegaso Directo | D48: Camion de Impacto | E48: =VLOOKUP(TablaObra[[#This Row],[Equipo]],Catalogos!I$4:J$34,2,FALSE) | F48: 80 | G48: 28.3 | H48: =IFERROR(F48*G48,0)
A49: 46184 | B49: Lerma - Tres Marías | C49: Pegaso Directo | D49: Vogel | E49: =VLOOKUP(TablaObra[[#This Row],[Equipo]],Catalogos!I$4:J$34,2,FALSE) | F49: 185 | G49: 28.3 | H49: =IFERROR(F49*G49,0)
A50: 46184 | B50: Lerma - Tres Marías | C50: Pegaso Directo | D50: Doble Rodillo | E50: =VLOOKUP(TablaObra[[#This Row],[Equipo]],Catalogos!I$4:J$34,2,FALSE) | F50: 50 | G50: 28.3 | H50: =IFERROR(F50*G50,0)
A51: 46184 | B51: Lerma - Tres Marías | C51: Pegaso Directo | D51: Doble Rodillo | E51: =VLOOKUP(TablaObra[[#This Row],[Equipo]],Catalogos!I$4:J$34,2,FALSE) | F51: 40 | G51: 28.3 | H51: =IFERROR(F51*G51,0)
...

Sheet Conciliacion
A1: CONCILIACIÓN SEMANAL / MENSUAL
A3: Concepto | B3: Litros
A4: Entradas a Pegaso | B4: =SUM(Captura_Pegaso!G5:G206)
A5: Salidas Pegaso a Marimba | B5: =SUMIF(Captura_Pegaso!B5:B206,"Salida a Marimba",Captura_Pegaso!H5:H206)
A6: Salidas Pegaso directo a Máquinas | B6: =SUMIF(Captura_Pegaso!B5:B206,"Salida Directa Máquina",Captura_Pegaso!H5:H206)
A7: Entradas registradas en Marimba | B7: =SUMIF(Captura_Marimba_M01!B5:B204,"Entrada desde Pegaso",Captura_Marimba_M01!F5:F204)
A8: Salidas Marimba a Obra | B8: =SUMIF(Captura_Marimba_M01!B5:B204,"Salida a Obra",Captura_Marimba_M01!G5:G204)
A9: Litros reconocidos por Obras | B9: =SUM(Captura_Obra!F5:F304)
A10: Diferencia Pegaso vs Marimba | B10: =B5-B7
A11: Diferencia Marimba vs Obra | B11: =B8-(B9-B6)
A12: Diferencia Total a Revisar | B12: =B10+B11
A14: Obra | B14: Litros Recibidos | C14: Costo | D14: % Consumo
A15: México-Toluca | B15: =SUMIF(Captura_Obra!B:B,A15,Captura_Obra!F:F) | C15: =SUMIF(Captura_Obra!B:B,A15,Captura_Obra!H:H) | D15: =IFERROR(B15/$B$21,0)
A16: Lerma - Tres Marías | B16: =SUMIF(Captura_Obra!B:B,A16,Captura_Obra!F:F) | C16: =SUMIF(Captura_Obra!B:B,A16,Captura_Obra!H:H) | D16: =IFERROR(B16/$B$21,0)
A17: Chamapa-Lechería | B17: =SUMIF(Captura_Obra!B:B,A17,Captura_Obra!F:F) | C17: =SUMIF(Captura_Obra!B:B,A17,Captura_Obra!H:H) | D17: =IFERROR(B17/$B$21,0)
A18: Bacheo Toluca | B18: =SUMIF(Captura_Obra!B:B,A18,Captura_Obra!F:F) | C18: =SUMIF(Captura_Obra!B:B,A18,Captura_Obra!H:H) | D18: =IFERROR(B18/$B$21,0)
A19: Planta Asfalto Pegaso | B19: =SUMIF(Captura_Obra!B:B,A19,Captura_Obra!F:F) | C19: =SUMIF(Captura_Obra!B:B,A19,Captura_Obra!H:H) | D19: =IFERROR(B19/$B$21,0)
A20: Planta Asflato Huixquilucan | B20: =SUMIF(Captura_Obra!B:B,A20,Captura_Obra!F:F) | C20: =SUMIF(Captura_Obra!B:B,A20,Captura_Obra!H:H) | D20: =IFERROR(B20/$B$21,0)
A21: TOTAL | B21: =SUM(B15:B20) | C21: =SUM(C15:C20) | D21: =SUM(D15:D20)
A23: Validación Corporativa
A24: Revisó Gobierno Corporativo | C24: Fecha | E24: Estatus | G24: Observaciones
E25: □ Correcto □ Observado □ Pendiente
A26: Firma

Sheet Catalogos
A1: CATÁLOGOS OFICIALES - CONTROL DE COMBUSTIBLE
K2: Obras Dropdown | L2: Semanas Dropdown
A3: Código Obra | B3: Obra | C3: Ingeniero | E3: Código | F3: Fuente / Origen | I3: Tipo de Equipo | J3: Económico
A4: MT | B4: México-Toluca | C4: Samuel Ortega | E4: GAS | F4: Gasolinera Huixquilucan | I4: Fresadora | J4: FR-01 | K4: México-Toluca | L4: 46181
A5: L3M | B5: Lerma - Tres Marías | C5: Apolinar | E5: PEG | F5: Tanque Pegaso | I5: Compactador | J5: CP-01 | K5: Lerma - Tres Marías | L5: 46188
A6: NP | B6: No aplica | E6: PAP | F6: Planta Asfalto Pegaso | I6: Excavadora | J6: EX-01 | K6: Chamapa-Lechería | L6: 46195
A7: CL | B7: Chamapa-Lechería | C7: Francisco Javier | E7: M01 | F7: Marimba M-01 | I7: Retroexcavadora | J7: RT-01 | K7: Bacheo Toluca | L7: 46202
A8: BT | B8: Bacheo Toluca | C8: Diego Carreola | E8: DIR | F8: Carga directa | I8: Motoconformadora | J8: MG-01 | K8: Todas | L8: 46209
A9: PAP | B9: Planta Asfalto Pegaso | E9: PAH | F9: Planta Asfaltos | I9: Petrolizadora | J9: PT-01 | L9: 46216
A10: PAH | B10: Planta Asflato Huixquilucan | E10: Otr | F10: Otro | I10: Pipa | J10: PP-01 | L10: 46223
I11: Camión | J11: CM-01 | L11: 46230
I12: Perfiladora Wirgent | J12: PR-02 | L12: 46237
I13: Perfiladora Cat-PM | J13: PR-03 | L13: 46244
I14: Barredora Broce | J14: BR-02 | L14: 46251
I15: Retroexcavadora Jonh Deere | J15: RT-02 | L15: 46258
I16: Buggy Trasnfer | J16: BG-01 | L16: 46265
I17: Cargador | J17: CR-01 | L17: 46272
I18: Vogel | J18: VG-01 | L18: 46279
I19: Perfiladora | J19: PR-01 | L19: 46286
I20: Barredora | J20: BR-01 | L20: 46293
I21: Neuomatico | J21: NM-01 | L21: 46300
I22: Vogele Guion | J22: VG-02 | L22: 46307
... I33: PayLoder | J33: PL-01 | L33: 46384
I34: Otro | J34: OT-01

Sheet Formatos_Fisicos
A1: FORMATOS FÍSICOS PARA IMPRESIÓN Y FIRMA
A3: GC-COMB-001 BITÁCORA PEGASO
A4: Semana: | B4: Responsable: | C4: Existencia Inicial: | D4: Existencia Final Física: | E4: Fecha Entrega: | F4: Firma:
A6: Fecha | B6: Movimiento | C6: Origen/Destino | D6: Obra | E6: Equipo/Económico | F6: Entrada (L) | G6: Salida (L) | H6: Operador (firma) | I6: Ingeniero Responsable
A16: GC-COMB-002 BITÁCORA MARIMBA M-01
A17: Semana: | B17: Operador: | C17: Inventario Inicial: | D17: Inventario Final: | E17: Fecha Entrega: | F17: Firma:
A19: Fecha | B19: Movimiento | C19: Obra | D19: Equipo | E19: Económico | F19: Entrada (L) | G19: Salida (L) | H19: Observaciones
A29: GC-COMB-003 BITÁCORA DE OBRA
A30: Semana: | B30: Obra: | C30: Ingeniero: | D30: Fecha Entrega: | E30: Firma:
A32: Fecha | B32: Fuente | C32: Equipo | D32: Económico | E32: Litros Recibidos | F32: Actividad | G32: Incidencia | H32: Observaciones

Sheet Instrucciones
A1: PROCEDIMIENTO OPERATIVO GC-COMB-01
A3: 1 | B3: Gasolinera → Pegaso | C3: Vigilante registra entrada en GC-COMB-001 con factura/remisión y litros recibidos.
A4: 2 | B4: Pegaso → Marimba M-01 | C4: Vigilante registra salida en GC-COMB-001. Operador de Marimba registra entrada en GC-COMB-002.
A5: 3 | B5: Pegaso → Máquina | C5: Vigilante registra salida directa en GC-COMB-001. Ingeniero registra recepción en GC-COMB-003.
A6: 4 | B6: Marimba → Obras/Máquinas | C6: Operador registra cada suministro en GC-COMB-002. Ingeniero reconoce litros por obra en GC-COMB-003.
A7: 5 | B7: Obras actuales | C7: México-Toluca, Lerma - Tres Marías y Chamapa-Lechería.
A8: 6 | B8: Horómetro | C8: No es obligatorio porque no funciona en la mayoría de equipos. El control principal será por litros, obra, equipo, actividad e incidencia.
A9: 7 | B9: Costo | C9: Capturar costo/litro en cada registro para obtener costo por obra y costo total semanal.
A10: 8 | B10: Cierre semanal | C10: Todos entregan bitácoras físicas firmadas. Gobierno Corporativo captura y revisa conciliación.
A11: 9 | B11: Alertas | C11: Si la diferencia total es distinta de cero, revisar Pegaso vs Marimba y Marimba/Pegaso vs Obra.
A12: 10 | B12: Reunión lunes | C12: Usar Dashboard para mostrar consumo, costo y diferencias al Ing. Pepe.
A14: Responsables | C14: Vigilante Pegaso = inventario / Operador Marimba = distribución / Ingeniero = validación de obra / Gobierno Corporativo = conciliación y pago.
A16: Documentación soporte | C16: Factura, remisión, bitácoras físicas firmadas, evidencias de incidencias cuando existan.
A18: Nota | C18: Este archivo no usa macros. Funciona con fórmulas, catálogos y validaciones para evitar dependencia de VBA.
