Workbook

Sheet Formato Obra
B4: GC-COMB-003: BITÁCORA SEMANAL DE CONTROL DE COMBUSTIBLE EN OBRA
B6: Semana No.: | C6: 25 | E6: Obra / Centro de Trabajo: | H6: Planta Asfalto Pegaso
B7: Dia del: | D7: al: | F7: Ingeniero Responsable: | H7: Janeth
B10: 1. COMBUSTIBLE RECIBIDO DURANTE LA SEMANA
B11: FECHA (DÍA) | D11: FUENTE (PEGASO / MARIMBA) | H11: LITROS RECIBIDOS
B12: LUNES | D12: Gasolinera Huixquilucan
B13: MARTES
B14: MIERCOLES
B15: JUEVES
B16: VIERNES
B17: SÁBADO
B18: DOMINGO
B19: TOTAL RECIBIDO EN LA SEMANA: | E19: =SUM(E12:E18) -> 0
B29: 2. REGISTRO TRANSACCIONAL DE COMBUSTIBLE (NUEVO MODELO)
B30: Folio Ticket | D30: Fecha (DD/MM) | E30: Hora (HH:MM) | F30: Origen (Suministro) | H30: Destino ( Maquinaria) | J30: Economico | K30: Litros | L30: Operador/Firma | V30: TOT HORAS
B31: =IF(H31="","", IFERROR(VLOOKUP($H$6, Catalogos!$H$2:$I$20, 2, FALSE), "FOL") & IF($C$6="","", "-" & $C$6) & "-" & TEXT(ROW(A1),"000")) | J31: =VLOOKUP(H31,Catalogos!$D$2:$G$33,2,FALSE) -> #N/A | L31: =VLOOKUP(H31,Catalogos!$D$2:$G$33,4,FALSE) -> #N/A
B32: =IF(H32="","", IFERROR(VLOOKUP($H$6, Catalogos!$H$2:$I$20, 2, FALSE), "FOL") & IF($C$6="","", "-" & $C$6) & "-" & TEXT(ROW(A2),"000")) | J32: =VLOOKUP(H32,Catalogos!$D$2:$G$33,2,FALSE) -> #N/A | L32: =VLOOKUP(H32,Catalogos!$D$2:$G$33,4,FALSE) -> #N/A
B33: =IF(H33="","", IFERROR(VLOOKUP($H$6, Catalogos!$H$2:$I$20, 2, FALSE), "FOL") & IF($C$6="","", "-" & $C$6) & "-" & TEXT(ROW(A3),"000")) | J33: =VLOOKUP(H33,Catalogos!$D$2:$G$33,2,FALSE) -> #N/A | L33: =VLOOKUP(H33,Catalogos!$D$2:$G$33,4,FALSE) -> #N/A
B34: =IF(H34="","", IFERROR(VLOOKUP($H$6, Catalogos!$H$2:$I$20, 2, FALSE), "FOL") & IF($C$6="","", "-" & $C$6) & "-" & TEXT(ROW(A4),"000")) | J34: =VLOOKUP(H34,Catalogos!$D$2:$G$33,2,FALSE) -> #N/A | L34: =VLOOKUP(H34,Catalogos!$D$2:$G$33,4,FALSE) -> #N/A
B35: =IF(H35="","", IFERROR(VLOOKUP($H$6, Catalogos!$H$2:$I$20, 2, FALSE), "FOL") & IF($C$6="","", "-" & $C$6) & "-" & TEXT(ROW(A5),"000")) | J35: =VLOOKUP(H35,Catalogos!$D$2:$G$33,2,FALSE) -> #N/A | L35: =VLOOKUP(H35,Catalogos!$D$2:$G$33,4,FALSE) -> #N/A
B36: =IF(H36="","", IFERROR(VLOOKUP($H$6, Catalogos!$H$2:$I$20, 2, FALSE), "FOL") & IF($C$6="","", "-" & $C$6) & "-" & TEXT(ROW(A6),"000")) | J36: =VLOOKUP(H36,Catalogos!$D$2:$G$33,2,FALSE) -> #N/A | L36: =VLOOKUP(H36,Catalogos!$D$2:$G$33,4,FALSE) -> #N/A
B37: =IF(H37="","", IFERROR(VLOOKUP($H$6, Catalogos!$H$2:$I$20, 2, FALSE), "FOL") & IF($C$6="","", "-" & $C$6) & "-" & TEXT(ROW(A7),"000")) | J37: =VLOOKUP(H37,Catalogos!$D$2:$G$33,2,FALSE) -> #N/A | L37: =VLOOKUP(H37,Catalogos!$D$2:$G$33,4,FALSE) -> #N/A
B38: =IF(H38="","", IFERROR(VLOOKUP($H$6, Catalogos!$H$2:$I$20, 2, FALSE), "FOL") & IF($C$6="","", "-" & $C$6) & "-" & TEXT(ROW(A8),"000")) | J38: =VLOOKUP(H38,Catalogos!$D$2:$G$33,2,FALSE) -> #N/A | L38: =VLOOKUP(H38,Catalogos!$D$2:$G$33,4,FALSE) -> #N/A
B39: =IF(H39="","", IFERROR(VLOOKUP($H$6, Catalogos!$H$2:$I$20, 2, FALSE), "FOL") & IF($C$6="","", "-" & $C$6) & "-" & TEXT(ROW(A9),"000")) | J39: =VLOOKUP(H39,Catalogos!$D$2:$G$33,2,FALSE) -> #N/A | L39: =VLOOKUP(H39,Catalogos!$D$2:$G$33,4,FALSE) -> #N/A
B40: =IF(H40="","", IFERROR(VLOOKUP($H$6, Catalogos!$H$2:$I$20, 2, FALSE), "FOL") & IF($C$6="","", "-" & $C$6) & "-" & TEXT(ROW(A10),"000")) | J40: =VLOOKUP(H40,Catalogos!$D$2:$G$33,2,FALSE) -> #N/A | L40: =VLOOKUP(H40,Catalogos!$D$2:$G$33,4,FALSE) -> #N/A
B41: =IF(H41="","", IFERROR(VLOOKUP($H$6, Catalogos!$H$2:$I$20, 2, FALSE), "FOL") & IF($C$6="","", "-" & $C$6) & "-" & TEXT(ROW(A11),"000")) | J41: =VLOOKUP(H41,Catalogos!$D$2:$G$33,2,FALSE) -> #N/A | L41: =VLOOKUP(H41,Catalogos!$D$2:$G$33,4,FALSE) -> #N/A
B42: =IF(H42="","", IFERROR(VLOOKUP($H$6, Catalogos!$H$2:$I$20, 2, FALSE), "FOL") & IF($C$6="","", "-" & $C$6) & "-" & TEXT(ROW(A12),"000")) | J42: =VLOOKUP(H42,Catalogos!$D$2:$G$33,2,FALSE) -> #N/A | L42: =VLOOKUP(H42,Catalogos!$D$2:$G$33,4,FALSE) -> #N/A
... B100: =IF(H100="","", IFERROR(VLOOKUP($H$6, Catalogos!$H$2:$I$20, 2, FALSE), "FOL") & IF($C$6="","", "-" & $C$6) & "-" & TEXT(ROW(A70),"000")) | J100: =VLOOKUP(H100,Catalogos!$D$2:$G$33,2,FALSE) -> #N/A | L100: =VLOOKUP(H100,Catalogos!$D$2:$G$33,4,FALSE) -> #N/A
B107: 3.TRABAJO POR HORA DE MAQUINARIA
B108: MAQUINARIA | D108: LUN | E108: MAR | F108: MIE | G108: JUE | H108: VIE | I108: SAB | J108: TOTAL DE HORAS
B109: 1.
B110: 2.
B111: 3.
B112: 4.
B113: 5.
B114: 6.
B115: 7.
B116: 8.
B117: 9.
B118: 10.
...

Sheet Catalogos
A1: Obras | B1: Ingeniero | C1: Origen | D1: Tipo de Equipo | E1: No. Económico | F1: Obra Asignada | G1: Operador Asignado | H1: Obra | I1: Iniciales
A2: México-Toluca | B2: Francisco Javier | C2: Gasolinera Huixquilucan | D2: RETROEXCAVADORA CASE 580 N | E2: RT-03 | H2: Lerma - Tres Marías | I2: LT
A3: Lerma - Tres Marías | B3: Apolinar | C3: Tanque Pegaso | D3: PAVIMENTADORA VOGELE 1800-3 i | E3: VG-01 | F3: México-Toluca | G3: Gerardo Ezequiel Piña Fernández | H3: México-Toluca | I3: MT
A4: No aplica | B4: Diego Carreola | C4: Planta Asfalto Pegaso | D4: PAVIMENTADORA VOGELE 1800-2 SJ | E4: VG-02 | H4: Chamapa-Lechería | I4: CL
A5: Chamapa-Lechería | B5: Janeth | C5: Marimba M-01 | D5: PAVIMENTADORA VOGELE SJ 1800-3 | E5: VG-03 | F5: Lerma - Tres Marías | G5: Jose de Jesus Eusebio Martinez | H5: Bacheo Toluca | I5: BT
A6: Bacheo Toluca | B6: Luis | C6: Carga directa | D6: PERFILADORA RODATEC RX600-4-4008 | E6: PR-01 | H6: Planta Asfalto Pegaso | I6: PAP
A7: Planta Asfalto Pegaso | C7: Planta Asfaltos | D7: PERFILADORA RODATEC RX600E | E7: PR-02 | F7: Lerma - Tres Marías | G7: Alan Alexis Gutierrez Flores | H7: Dragones | I7: DR
A8: Planta Asflato Huixquilucan | C8: Entrada | D8: BARREDORA BROCE RJ350 | E8: BR-01 | F8: México-Toluca | G8: Edgar Rosales Martinez
A9: Dragones | C9: Salida | D9: BARREDORA LAYMOR SM400 | E9: BR-02
A10: Jalisco | D10: BARREDORA SUPERIOR BROOM DT80J | E10: BR-03
D11: BARREDORA LAYMOR SM400 | E11: BR-04 | F11: Lerma - Tres Marías | G11: Fernando Angeles Reyes
D12: DOBLE RODILLO/VIBROCOMPACTADOR DE RODILLOS HAMM 120HD VV | E12: DR-01 | F12: México-Toluca | G12: POR ASIGNAR
D13: DOBLE RODILLO/VIBROCOMPACTADOR DE RODILLOS HAMM 140HD | E13: DR-02 | F13: México-Toluca | G13: Julián Piña Hernández
D14: TANDEM DOBLE RODILLO / VIBROCOMPACTOR RODILLO CAT CB54 | E14: TD-01
D15: VIBROCOMPACTADOR CATERPILLAR CB66B | E15: VC-01 | F15: Lerma - Tres Marías | G15: Jose Manuel Reyes Flores
D16: NEUMATICO / COMPACTADOR DE NEUMATICOS DINAPAC CP271 | E16: NM-01 | F16: Lerma - Tres Marías | G16: Marco Antonio Estrada Arellano
D17: NEUMATICO VOLVO PT-240R | E17: NM-02 | F17: México-Toluca | G17: Luis Fernando Mendiola Vivero
D18: COMPRESOR SULLIVAN PALATEK D2010 | E18: CPR-01 | F18: Lerma - Tres Marías | G18: Eduardo Guadarrama Garcia
D19: COMPRESOR SULLIVAN PALATEK D2010 | E19: CPR-02
D20: RETROEXCAVADORA CASE 420DN | E20: RT-04
D21: BARREDORA BROCE BROOM KR350 | E21: BR-05
D22: RETROEXCAVADORA JHONDEREE 310SK | E22: RT-05 | F22: México-Toluca | G22: Adolfo Nava Lopez
D23: BARREDORA BROCE BROOM KR350 | E23: BR-06
D24: DOBLE RODILLO INGERSOLL RAND DD-108HF | E24: DR-03
D25: TRASFER BUGGI RODATEC | E25: BG-01
D26: IMPACTO FORD 4300 | E26: CI-01
D27: IMPACTO FORD F800 | E27: CI-02 | F27: Lerma - Tres Marías | G27: Marco Antonio Millan Centeno
D28: PETROLIZADORA (IMPACTO 04) FORD F800 | E28: PT-01
D29: PETROLIZADORA INTERNATIONAL | E29: PT-02 | F29: Lerma - Tres Marías | G29: Francisco Gomora Angeles / Elthon Eduardo
D30: PIPA DE AGUA (IMPACTO 01) FORD | E30: PP-01
D31: DOBLE RODILLO RAD ROLLER FILY-325 PRO | E31: DR-04
D32: PERFILADORA WIRGENT-W200i | E32: S/N (WIRGENT) | F32: México-Toluca | G32: Alejandro de Jesus Fuentes Tapia
D33: COMPRESOR INGERSOLL RAND IR185 | E33: S/N (IR185) | F33: México-Toluca | G33: Jose Carlos Romero Tellez
