Workbook

Sheet Resumen_Ejecutivo_Copia
B2: TABLAS DINAMICAS DE COSTOS Y FINANZAS
C5: Etiquetas de columna
C6: 1. Solicitud | E6: 2. Consumo Real | G6: 4. Facturas | I6: Total Cuenta de Costo Total | J6: Total Cuenta de Litros
B7: Etiquetas de fila | C7: Cuenta de Costo Total | D7: Cuenta de Litros | E7: Cuenta de Costo Total | F7: Cuenta de Litros | G7: Cuenta de Costo Total | H7: Cuenta de Litros
B8: 22 | E8: 6 | F8: 6 | I8: 6 | J8: 6
B9: 23 | E9: 12 | F9: 12 | I9: 12 | J9: 12
B10: 24 | C10: 70 | D10: 70 | E10: 107 | F10: 107 | I10: 177 | J10: 177
B11: Bacheo Toluca | C11: 5 | D11: 5 | E11: 2 | F11: 2 | I11: 7 | J11: 7
B12: Chamapa-Lechería | C12: 33 | D12: 33 | E12: 50 | F12: 50 | I12: 83 | J12: 83
B13: Jalisco | E13: 3 | F13: 3 | I13: 3 | J13: 3
B14: Lerma - Tres Marías | C14: 14 | D14: 14 | E14: 13 | F14: 13 | I14: 27 | J14: 27
B15: Maquinaria Pegaso | E15: 3 | F15: 3 | I15: 3 | J15: 3
B16: México-Toluca | C16: 18 | D16: 18 | E16: 36 | F16: 36 | I16: 54 | J16: 54
B17: 25 | C17: 67 | D17: 67 | E17: 109 | F17: 109 | G17: 15 | H17: 15 | I17: 191 | J17: 191
B18: Bacheo Toluca | C18: 9 | D18: 9 | E18: 8 | F18: 8 | I18: 17 | J18: 17
B19: Dragones | E19: 1 | F19: 1 | I19: 1 | J19: 1
B20: Jalisco | E20: 10 | F20: 10 | I20: 10 | J20: 10
B21: Lerma - Tres Marías | C21: 19 | D21: 19 | E21: 18 | F21: 18 | I21: 37 | J21: 37
B22: Maquinaria Pegaso | E22: 3 | F22: 3 | G22: 2 | H22: 2 | I22: 5 | J22: 5
B23: México-Toluca | C23: 39 | D23: 39 | E23: 60 | F23: 60 | G23: 5 | H23: 5 | I23: 104 | J23: 104
B24: Planta Asflato Huixquilucan | E24: 9 | F24: 9 | G24: 4 | H24: 4 | I24: 13 | J24: 13
B25: Transportes Pegaso | G25: 4 | H25: 4 | I25: 4 | J25: 4
B26: 26 | C26: 142 | D26: 142 | E26: 88 | F26: 88 | G26: 12 | H26: 12 | I26: 242 | J26: 242
B27: Bacheo Toluca | C27: 19 | D27: 19 | E27: 11 | F27: 11 | I27: 30 | J27: 30
B28: Dragones | E28: 2 | F28: 2 | I28: 2 | J28: 2
B29: Jalisco | E29: 11 | F29: 11 | I29: 11 | J29: 11
B30: Lerma - Tres Marías | C30: 60 | D30: 60 | E30: 16 | F30: 16 | I30: 76 | J30: 76
B31: Maquinaria Pegaso | E31: 7 | F31: 7 | I31: 7 | J31: 7
B32: México-Toluca | C32: 39 | D32: 39 | E32: 32 | F32: 32 | G32: 9 | H32: 9 | I32: 80 | J32: 80
B33: Planta Asfalto Pegaso | C33: 4 | D33: 4 | I33: 4 | J33: 4
B34: Planta Asflato Huixquilucan | C34: 20 | D34: 20 | E34: 9 | F34: 9 | G34: 1 | H34: 1 | I34: 30 | J34: 30
B35: Transportes Pegaso | G35: 2 | H35: 2 | I35: 2 | J35: 2
B36: 27 | C36: 104 | D36: 104 | E36: 30 | F36: 30 | I36: 134 | J36: 134
B37: Bacheo Toluca | C37: 26 | D37: 26 | E37: 1 | F37: 1 | I37: 27 | J37: 27
B38: Dragones | E38: 1 | F38: 1 | I38: 1 | J38: 1
B39: Lerma - Tres Marías | E39: 8 | F39: 8 | I39: 8 | J39: 8
B40: México-Toluca | C40: 53 | D40: 53 | E40: 11 | F40: 11 | I40: 64 | J40: 64
B41: Planta Asfalto Huixquilucan | C41: 25 | D41: 25 | I41: 25 | J41: 25
B42: Planta Asfalto Pegaso | E42: 2 | F42: 2 | I42: 2 | J42: 2
B43: Planta Asflato Huixquilucan | E43: 4 | F43: 4 | I43: 4 | J43: 4
...

Sheet Dashboard_Copia
B2: TABLAS DINAMICAS DE OPERACION (VOLUMEN)
B5: Cuenta de Lts Operativos | C5: Etiquetas de columna
B6: Etiquetas de fila | C6: 1. Solicitud | D6: 2. Consumo Real | E6: 4. Facturas | F6: Total general
B7: 22 | D7: 6 | F7: 6
B8: Jalisco | D8: 6 | F8: 6
B9: 23 | D9: 12 | F9: 12
B10: Jalisco | D10: 12 | F10: 12
B11: 24 | C11: 70 | D11: 107 | F11: 177
B12: Bacheo Toluca | C12: 5 | D12: 2 | F12: 7
B13: Chamapa-Lechería | C13: 33 | D13: 50 | F13: 83
B14: Jalisco | D14: 3 | F14: 3
B15: Lerma - Tres Marías | C15: 14 | D15: 13 | F15: 27
B16: Maquinaria Pegaso | D16: 3 | F16: 3
B17: México-Toluca | C17: 18 | D17: 36 | F17: 54
B18: 25 | C18: 67 | D18: 109 | E18: 15 | F18: 191
B19: Bacheo Toluca | C19: 9 | D19: 8 | F19: 17
B20: Dragones | D20: 1 | F20: 1
B21: Jalisco | D21: 10 | F21: 10
B22: Lerma - Tres Marías | C22: 19 | D22: 18 | F22: 37
B23: Maquinaria Pegaso | D23: 3 | E23: 2 | F23: 5
B24: México-Toluca | C24: 39 | D24: 60 | E24: 5 | F24: 104
B25: Planta Asflato Huixquilucan | D25: 9 | E25: 4 | F25: 13
B26: Transportes Pegaso | E26: 4 | F26: 4
B27: 26 | C27: 142 | D27: 88 | E27: 12 | F27: 242
B28: Bacheo Toluca | C28: 19 | D28: 11 | F28: 30
B29: Dragones | D29: 2 | F29: 2
B30: Jalisco | D30: 11 | F30: 11
B31: Lerma - Tres Marías | C31: 60 | D31: 16 | F31: 76
B32: Maquinaria Pegaso | D32: 7 | F32: 7
B33: México-Toluca | C33: 39 | D33: 32 | E33: 9 | F33: 80
B34: Planta Asfalto Pegaso | C34: 4 | F34: 4
B35: Planta Asflato Huixquilucan | C35: 20 | D35: 9 | E35: 1 | F35: 30
B36: Transportes Pegaso | E36: 2 | F36: 2
B37: 27 | C37: 104 | D37: 30 | F37: 134
B38: Bacheo Toluca | C38: 26 | D38: 1 | F38: 27
B39: Dragones | D39: 1 | F39: 1
B40: Lerma - Tres Marías | D40: 8 | F40: 8
B41: México-Toluca | C41: 53 | D41: 11 | F41: 64
B42: Planta Asfalto Huixquilucan | C42: 25 | F42: 25
B43: Planta Asfalto Pegaso | D43: 2 | F43: 2
...

Sheet Base_Datos
A1: ID_TICKET | B1: SEMANA | C1: FECHA | D1: OBRA | E1: TIPO_REGISTRO | F1: EQUIPO_CONCEPTO | G1: LITROS | H1: PRECIO_UNITARIO | I1: COSTO_TOTAL | J1: CATEGORIA | K1: OBSERVACIONES
A2: =IF(LEFT(E2,1)="1","SOL",IF(LEFT(E2,1)="2","CO",IF(LEFT(E2,1)="3","ALM",IF(LEFT(E2,1)="4","FAC","TRX")))) & "-" & B2 & "-" & TEXT(COUNTIFS($E$2:$E2,E2,$B$2:$B2,B2),"000") -> SOL-24-001 | B2: 24 | C2: 46181 | D2: México-Toluca | E2: 1. Solicitud | F2: Vogel | G2: 200 | H2: 27 | I2: 5400 | J2: DIESEL | K2: 27
A3: =IF(LEFT(E3,1)="1","SOL",IF(LEFT(E3,1)="2","CO",IF(LEFT(E3,1)="3","ALM",IF(LEFT(E3,1)="4","FAC","TRX")))) & "-" & B3 & "-" & TEXT(COUNTIFS($E$2:$E3,E3,$B$2:$B3,B3),"000") -> SOL-24-002 | B3: 24 | C3: 46181 | D3: México-Toluca | E3: 1. Solicitud | F3: Perfiladora | G3: 300 | H3: 27 | I3: 8100 | J3: DIESEL | K3: 27
A4: =IF(LEFT(E4,1)="1","SOL",IF(LEFT(E4,1)="2","CO",IF(LEFT(E4,1)="3","ALM",IF(LEFT(E4,1)="4","FAC","TRX")))) & "-" & B4 & "-" & TEXT(COUNTIFS($E$2:$E4,E4,$B$2:$B4,B4),"000") -> SOL-24-003 | B4: 24 | C4: 46181 | D4: México-Toluca | E4: 1. Solicitud | F4: Retroexcavadora | G4: 30 | H4: 27 | I4: 810 | J4: DIESEL | K4: 27
A5: =IF(LEFT(E5,1)="1","SOL",IF(LEFT(E5,1)="2","CO",IF(LEFT(E5,1)="3","ALM",IF(LEFT(E5,1)="4","FAC","TRX")))) & "-" & B5 & "-" & TEXT(COUNTIFS($E$2:$E5,E5,$B$2:$B5,B5),"000") -> SOL-24-004 | B5: 24 | C5: 46181 | D5: México-Toluca | E5: 1. Solicitud | F5: Barredora | G5: 20 | H5: 27 | I5: 540 | J5: DIESEL | K5: 27
A6: =IF(LEFT(E6,1)="1","SOL",IF(LEFT(E6,1)="2","CO",IF(LEFT(E6,1)="3","ALM",IF(LEFT(E6,1)="4","FAC","TRX")))) & "-" & B6 & "-" & TEXT(COUNTIFS($E$2:$E6,E6,$B$2:$B6,B6),"000") -> SOL-24-005 | B6: 24 | C6: 46181 | D6: México-Toluca | E6: 1. Solicitud | F6: Neuomatico | G6: 30 | H6: 27 | I6: 810 | J6: DIESEL | K6: 27
A7: =IF(LEFT(E7,1)="1","SOL",IF(LEFT(E7,1)="2","CO",IF(LEFT(E7,1)="3","ALM",IF(LEFT(E7,1)="4","FAC","TRX")))) & "-" & B7 & "-" & TEXT(COUNTIFS($E$2:$E7,E7,$B$2:$B7,B7),"000") -> SOL-24-006 | B7: 24 | C7: 46181 | D7: México-Toluca | E7: 1. Solicitud | F7: Compactador | G7: 30 | H7: 27 | I7: 810 | J7: DIESEL | K7: 27
A8: =IF(LEFT(E8,1)="1","SOL",IF(LEFT(E8,1)="2","CO",IF(LEFT(E8,1)="3","ALM",IF(LEFT(E8,1)="4","FAC","TRX")))) & "-" & B8 & "-" & TEXT(COUNTIFS($E$2:$E8,E8,$B$2:$B8,B8),"000") -> SOL-24-007 | B8: 24 | C8: 46181 | D8: México-Toluca | E8: 1. Solicitud | F8: Limpieza | G8: 30 | H8: 27 | I8: 810 | J8: DIESEL | K8: 27
A9: =IF(LEFT(E9,1)="1","SOL",IF(LEFT(E9,1)="2","CO",IF(LEFT(E9,1)="3","ALM",IF(LEFT(E9,1)="4","FAC","TRX")))) & "-" & B9 & "-" & TEXT(COUNTIFS($E$2:$E9,E9,$B$2:$B9,B9),"000") -> SOL-24-008 | B9: 24 | C9: 46181 | D9: Lerma - Tres Marías | E9: 1. Solicitud | F9: Retroexcavadora | G9: 50 | H9: 27 | I9: 1350 | J9: DIESEL | K9: 27
A10: =IF(LEFT(E10,1)="1","SOL",IF(LEFT(E10,1)="2","CO",IF(LEFT(E10,1)="3","ALM",IF(LEFT(E10,1)="4","FAC","TRX")))) & "-" & B10 & "-" & TEXT(COUNTIFS($E$2:$E10,E10,$B$2:$B10,B10),"000") -> SOL-24-009 | B10: 24 | C10: 46181 | D10: Lerma - Tres Marías | E10: 1. Solicitud | F10: Neuomatico | G10: 50 | H10: 27 | I10: 1350 | J10: DIESEL | K10: 27
A11: =IF(LEFT(E11,1)="1","SOL",IF(LEFT(E11,1)="2","CO",IF(LEFT(E11,1)="3","ALM",IF(LEFT(E11,1)="4","FAC","TRX")))) & "-" & B11 & "-" & TEXT(COUNTIFS($E$2:$E11,E11,$B$2:$B11,B11),"000") -> SOL-24-010 | B11: 24 | C11: 46181 | D11: Lerma - Tres Marías | E11: 1. Solicitud | F11: Petrolizadora | G11: 60 | H11: 27 | I11: 1620 | J11: DIESEL | K11: 27
A12: =IF(LEFT(E12,1)="1","SOL",IF(LEFT(E12,1)="2","CO",IF(LEFT(E12,1)="3","ALM",IF(LEFT(E12,1)="4","FAC","TRX")))) & "-" & B12 & "-" & TEXT(COUNTIFS($E$2:$E12,E12,$B$2:$B12,B12),"000") -> SOL-24-011 | B12: 24 | D12: Bacheo Toluca | E12: 1. Solicitud | F12: Retroexcavadora | G12: 100 | H12: 27 | I12: 2700 | J12: DIESEL | K12: 27
A13: =IF(LEFT(E13,1)="1","SOL",IF(LEFT(E13,1)="2","CO",IF(LEFT(E13,1)="3","ALM",IF(LEFT(E13,1)="4","FAC","TRX")))) & "-" & B13 & "-" & TEXT(COUNTIFS($E$2:$E13,E13,$B$2:$B13,B13),"000") -> SOL-24-012 | B13: 24 | C13: 46181 | D13: Chamapa-Lechería | E13: 1. Solicitud | F13: Perfiladora Wirgent | G13: 250 | H13: 27 | I13: 6750 | J13: DIESEL | K13: 27
A14: =IF(LEFT(E14,1)="1","SOL",IF(LEFT(E14,1)="2","CO",IF(LEFT(E14,1)="3","ALM",IF(LEFT(E14,1)="4","FAC","TRX")))) & "-" & B14 & "-" & TEXT(COUNTIFS($E$2:$E14,E14,$B$2:$B14,B14),"000") -> SOL-24-013 | B14: 24 | C14: 46181 | D14: Chamapa-Lechería | E14: 1. Solicitud | F14: Perfiladora Cat-PM | G14: 150 | H14: 27 | I14: 4050 | J14: DIESEL | K14: 27
A15: =IF(LEFT(E15,1)="1","SOL",IF(LEFT(E15,1)="2","CO",IF(LEFT(E15,1)="3","ALM",IF(LEFT(E15,1)="4","FAC","TRX")))) & "-" & B15 & "-" & TEXT(COUNTIFS($E$2:$E15,E15,$B$2:$B15,B15),"000") -> SOL-24-014 | B15: 24 | C15: 46181 | D15: Chamapa-Lechería | E15: 1. Solicitud | F15: Barredora Broce | G15: 40 | H15: 27 | I15: 1080 | J15: DIESEL | K15: 27
A16: =IF(LEFT(E16,1)="1","SOL",IF(LEFT(E16,1)="2","CO",IF(LEFT(E16,1)="3","ALM",IF(LEFT(E16,1)="4","FAC","TRX")))) & "-" & B16 & "-" & TEXT(COUNTIFS($E$2:$E16,E16,$B$2:$B16,B16),"000") -> SOL-24-015 | B16: 24 | C16: 46181 | D16: Chamapa-Lechería | E16: 1. Solicitud | F16: Retroexcavadora Jonh Deere | G16: 60 | H16: 27 | I16: 1620 | J16: DIESEL | K16: 27
A17: =IF(LEFT(E17,1)="1","SOL",IF(LEFT(E17,1)="2","CO",IF(LEFT(E17,1)="3","ALM",IF(LEFT(E17,1)="4","FAC","TRX")))) & "-" & B17 & "-" & TEXT(COUNTIFS($E$2:$E17,E17,$B$2:$B17,B17),"000") -> SOL-24-016 | B17: 24 | C17: 46181 | D17: Chamapa-Lechería | E17: 1. Solicitud | F17: Buggy Trasnfer | G17: 100 | H17: 27 | I17: 2700 | J17: DIESEL | K17: 27
A18: =IF(LEFT(E18,1)="1","SOL",IF(LEFT(E18,1)="2","CO",IF(LEFT(E18,1)="3","ALM",IF(LEFT(E18,1)="4","FAC","TRX")))) & "-" & B18 & "-" & TEXT(COUNTIFS($E$2:$E18,E18,$B$2:$B18,B18),"000") -> SOL-24-017 | B18: 24 | C18: 46181 | D18: Chamapa-Lechería | E18: 1. Solicitud | F18: Vogele Guion | G18: 100 | H18: 27 | I18: 2700 | J18: DIESEL | K18: 27
A19: =IF(LEFT(E19,1)="1","SOL",IF(LEFT(E19,1)="2","CO",IF(LEFT(E19,1)="3","ALM",IF(LEFT(E19,1)="4","FAC","TRX")))) & "-" & B19 & "-" & TEXT(COUNTIFS($E$2:$E19,E19,$B$2:$B19,B19),"000") -> SOL-24-018 | B19: 24 | C19: 46181 | D19: Chamapa-Lechería | E19: 1. Solicitud | F19: Limpieza | G19: 20 | H19: 27 | I19: 540 | J19: DIESEL | K19: 27
A20: =IF(LEFT(E20,1)="1","SOL",IF(LEFT(E20,1)="2","CO",IF(LEFT(E20,1)="3","ALM",IF(LEFT(E20,1)="4","FAC","TRX")))) & "-" & B20 & "-" & TEXT(COUNTIFS($E$2:$E20,E20,$B$2:$B20,B20),"000") -> SOL-24-019 | B20: 24 | C20: 46181 | D20: Chamapa-Lechería | E20: 1. Solicitud | F20: Tandem Hamm | G20: 50 | H20: 27 | I20: 1350 | J20: DIESEL | K20: 27
A21: =IF(LEFT(E21,1)="1","SOL",IF(LEFT(E21,1)="2","CO",IF(LEFT(E21,1)="3","ALM",IF(LEFT(E21,1)="4","FAC","TRX")))) & "-" & B21 & "-" & TEXT(COUNTIFS($E$2:$E21,E21,$B$2:$B21,B21),"000") -> SOL-24-020 | B21: 24 | C21: 46181 | D21: Chamapa-Lechería | E21: 1. Solicitud | F21: Neuomatico Dynapac | G21: 50 | H21: 27 | I21: 1350 | J21: DIESEL | K21: 27
A22: =IF(LEFT(E22,1)="1","SOL",IF(LEFT(E22,1)="2","CO",IF(LEFT(E22,1)="3","ALM",IF(LEFT(E22,1)="4","FAC","TRX")))) & "-" & B22 & "-" & TEXT(COUNTIFS($E$2:$E22,E22,$B$2:$B22,B22),"000") -> SOL-24-021 | B22: 24 | C22: 46181 | D22: Chamapa-Lechería | E22: 1. Solicitud | F22: Petrolizadora Elton | G22: 50 | H22: 27 | I22: 1350 | J22: DIESEL | K22: 27
A23: =IF(LEFT(E23,1)="1","SOL",IF(LEFT(E23,1)="2","CO",IF(LEFT(E23,1)="3","ALM",IF(LEFT(E23,1)="4","FAC","TRX")))) & "-" & B23 & "-" & TEXT(COUNTIFS($E$2:$E23,E23,$B$2:$B23,B23),"000") -> SOL-24-022 | B23: 24 | C23: 46181 | D23: Chamapa-Lechería | E23: 1. Solicitud | F23: Camion de Impacto | G23: 20 | H23: 27 | I23: 540 | J23: DIESEL | K23: 27
A24: =IF(LEFT(E24,1)="1","SOL",IF(LEFT(E24,1)="2","CO",IF(LEFT(E24,1)="3","ALM",IF(LEFT(E24,1)="4","FAC","TRX")))) & "-" & B24 & "-" & TEXT(COUNTIFS($E$2:$E24,E24,$B$2:$B24,B24),"000") -> SOL-24-023 | B24: 24 | C24: 46181 | D24: Chamapa-Lechería | E24: 1. Solicitud | F24: Maxilihgs | G24: 50 | H24: 27 | I24: 1350 | J24: DIESEL | K24: 27
... A41: =IF(LEFT(E41,1)="1","SOL",IF(LEFT(E41,1)="2","CO",IF(LEFT(E41,1)="3","ALM",IF(LEFT(E41,1)="4","FAC","TRX")))) & "-" & B41 & "-" & TEXT(COUNTIFS($E$2:$E41,E41,$B$2:$B41,B41),"000") -> SOL-24-040 | B41: 24 | C41: 46182 | D41: Lerma - Tres Marías | E41: 1. Solicitud | F41: Doble Rodillo | G41: 50 | H41: 27 | I41: 1350 | J41: DIESEL | K41: 27
A42: =IF(LEFT(E42,1)="1","SOL",IF(LEFT(E42,1)="2","CO",IF(LEFT(E42,1)="3","ALM",IF(LEFT(E42,1)="4","FAC","TRX")))) & "-" & B42 & "-" & TEXT(COUNTIFS($E$2:$E42,E42,$B$2:$B42,B42),"000") -> SOL-24-041 | B42: 24 | D42: Bacheo Toluca | E42: 1. Solicitud | F42: Retroexcavadora | G42: 100 | H42: 27 | I42: 2700 | J42: DIESEL | K42: 27
A43: =IF(LEFT(E43,1)="1","SOL",IF(LEFT(E43,1)="2","CO",IF(LEFT(E43,1)="3","ALM",IF(LEFT(E43,1)="4","FAC","TRX")))) & "-" & B43 & "-" & TEXT(COUNTIFS($E$2:$E43,E43,$B$2:$B43,B43),"000") -> SOL-24-042 | B43: 24 | C43: 46183 | D43: México-Toluca | E43: 1. Solicitud | F43: Perfiladora | G43: 250 | H43: 27 | I43: 6750 | J43: DIESEL | K43: 27
A44: =IF(LEFT(E44,1)="1","SOL",IF(LEFT(E44,1)="2","CO",IF(LEFT(E44,1)="3","ALM",IF(LEFT(E44,1)="4","FAC","TRX")))) & "-" & B44 & "-" & TEXT(COUNTIFS($E$2:$E44,E44,$B$2:$B44,B44),"000") -> SOL-24-043 | B44: 24 | C44: 46183 | D44: México-Toluca | E44: 1. Solicitud | F44: Retroexcavadora | G44: 30 | H44: 27 | I44: 810 | J44: DIESEL | K44: 27
A45: =IF(LEFT(E45,1)="1","SOL",IF(LEFT(E45,1)="2","CO",IF(LEFT(E45,1)="3","ALM",IF(LEFT(E45,1)="4","FAC","TRX")))) & "-" & B45 & "-" & TEXT(COUNTIFS($E$2:$E45,E45,$B$2:$B45,B45),"000") -> SOL-24-044 | B45: 24 | C45: 46183 | D45: México-Toluca | E45: 1. Solicitud | F45: Barredora | G45: 20 | H45: 27 | I45: 540 | J45: DIESEL | K45: 27
A46: =IF(LEFT(E46,1)="1","SOL",IF(LEFT(E46,1)="2","CO",IF(LEFT(E46,1)="3","ALM",IF(LEFT(E46,1)="4","FAC","TRX")))) & "-" & B46 & "-" & TEXT(COUNTIFS($E$2:$E46,E46,$B$2:$B46,B46),"000") -> SOL-24-045 | B46: 24 | C46: 46183 | D46: México-Toluca | E46: 1. Solicitud | F46: Maxilihgs | G46: 20 | H46: 27 | I46: 540 | J46: DIESEL | K46: 27
A47: =IF(LEFT(E47,1)="1","SOL",IF(LEFT(E47,1)="2","CO",IF(LEFT(E47,1)="3","ALM",IF(LEFT(E47,1)="4","FAC","TRX")))) & "-" & B47 & "-" & TEXT(COUNTIFS($E$2:$E47,E47,$B$2:$B47,B47),"000") -> SOL-24-046 | B47: 24 | C47: 46184 | D47: Lerma - Tres Marías | E47: 1. Solicitud | F47: Petrolizadora | G47: 80 | H47: 27 | I47: 2160 | J47: DIESEL | K47: 27
A48: =IF(LEFT(E48,1)="1","SOL",IF(LEFT(E48,1)="2","CO",IF(LEFT(E48,1)="3","ALM",IF(LEFT(E48,1)="4","FAC","TRX")))) & "-" & B48 & "-" & TEXT(COUNTIFS($E$2:$E48,E48,$B$2:$B48,B48),"000") -> SOL-24-047 | B48: 24 | C48: 46184 | D48: Lerma - Tres Marías | E48: 1. Solicitud | F48: Camion de Impacto | G48: 80 | H48: 27 | I48: 2160 | J48: DIESEL | K48: 27
A49: =IF(LEFT(E49,1)="1","SOL",IF(LEFT(E49,1)="2","CO",IF(LEFT(E49,1)="3","ALM",IF(LEFT(E49,1)="4","FAC","TRX")))) & "-" & B49 & "-" & TEXT(COUNTIFS($E$2:$E49,E49,$B$2:$B49,B49),"000") -> SOL-24-048 | B49: 24 | C49: 46184 | D49: Lerma - Tres Marías | E49: 1. Solicitud | F49: Retroexcavadora | G49: 70 | H49: 27 | I49: 1890 | J49: DIESEL | K49: 27
A50: =IF(LEFT(E50,1)="1","SOL",IF(LEFT(E50,1)="2","CO",IF(LEFT(E50,1)="3","ALM",IF(LEFT(E50,1)="4","FAC","TRX")))) & "-" & B50 & "-" & TEXT(COUNTIFS($E$2:$E50,E50,$B$2:$B50,B50),"000") -> SOL-24-049 | B50: 24 | C50: 46184 | D50: Lerma - Tres Marías | E50: 1. Solicitud | F50: Doble Rodillo | G50: 40 | H50: 27 | I50: 1080 | J50: DIESEL | K50: 27
A51: =IF(LEFT(E51,1)="1","SOL",IF(LEFT(E51,1)="2","CO",IF(LEFT(E51,1)="3","ALM",IF(LEFT(E51,1)="4","FAC","TRX")))) & "-" & B51 & "-" & TEXT(COUNTIFS($E$2:$E51,E51,$B$2:$B51,B51),"000") -> SOL-24-050 | B51: 24 | C51: 46184 | D51: Lerma - Tres Marías | E51: 1. Solicitud | F51: Vogel | G51: 150 | H51: 27 | I51: 4050 | J51: DIESEL | K51: 27
A52: =IF(LEFT(E52,1)="1","SOL",IF(LEFT(E52,1)="2","CO",IF(LEFT(E52,1)="3","ALM",IF(LEFT(E52,1)="4","FAC","TRX")))) & "-" & B52 & "-" & TEXT(COUNTIFS($E$2:$E52,E52,$B$2:$B52,B52),"000") -> SOL-24-051 | B52: 24 | C52: 46184 | D52: Lerma - Tres Marías | E52: 1. Solicitud | F52: Limpieza | G52: 30 | H52: 27 | I52: 810 | J52: DIESEL | K52: 27
A53: =IF(LEFT(E53,1)="1","SOL",IF(LEFT(E53,1)="2","CO",IF(LEFT(E53,1)="3","ALM",IF(LEFT(E53,1)="4","FAC","TRX")))) & "-" & B53 & "-" & TEXT(COUNTIFS($E$2:$E53,E53,$B$2:$B53,B53),"000") -> SOL-24-052 | B53: 24 | C53: 46184 | D53: Lerma - Tres Marías | E53: 1. Solicitud | F53: Rastrillador | G53: 10 | H53: 27 | I53: 270 | J53: DIESEL | K53: 27
A54: =IF(LEFT(E54,1)="1","SOL",IF(LEFT(E54,1)="2","CO",IF(LEFT(E54,1)="3","ALM",IF(LEFT(E54,1)="4","FAC","TRX")))) & "-" & B54 & "-" & TEXT(COUNTIFS($E$2:$E54,E54,$B$2:$B54,B54),"000") -> SOL-24-053 | B54: 24 | D54: Bacheo Toluca | E54: 1. Solicitud | F54: Retroexcavadora | G54: 50 | H54: 27 | I54: 1350 | J54: DIESEL | K54: 27
A55: =IF(LEFT(E55,1)="1","SOL",IF(LEFT(E55,1)="2","CO",IF(LEFT(E55,1)="3","ALM",IF(LEFT(E55,1)="4","FAC","TRX")))) & "-" & B55 & "-" & TEXT(COUNTIFS($E$2:$E55,E55,$B$2:$B55,B55),"000") -> SOL-24-054 | B55: 24 | D55: Bacheo Toluca | E55: 1. Solicitud | F55: Otro | G55: 10 | H55: 27 | I55: 270 | J55: DIESEL | K55: 27
A56: =IF(LEFT(E56,1)="1","SOL",IF(LEFT(E56,1)="2","CO",IF(LEFT(E56,1)="3","ALM",IF(LEFT(E56,1)="4","FAC","TRX")))) & "-" & B56 & "-" & TEXT(COUNTIFS($E$2:$E56,E56,$B$2:$B56,B56),"000") -> SOL-24-055 | B56: 24 | D56: Bacheo Toluca | E56: 1. Solicitud | F56: Limpieza | G56: 10 | H56: 27 | I56: 270 | J56: DIESEL | K56: 27
...

Sheet Dashboard
A1: DASHBOARD EJECUTIVO DE CONTROL DE COMBUSTIBLE | GRUPO TRUJANO
A3: FILTROS DEL DASHBOARD (Celdas en amarillo editables en Excel) | E3: ESTADO DE LA CONCILIACIÓN SEMANAL
B4: Obra Seleccionada: | C4: México-Toluca | E4: =IF(I28=0, "🟢 TODO COINCIDE (0 L)", "🔴 DISCREPANCIA: " & I28 & " L") -> 🔴 DISCREPANCIA: 2159 L
B5: Fecha Inicio (Lunes): | C5: 46195
B6: Fecha Fin (Rango): | C6: 46202
B7: Precio Diésel ($/L): | C7: 27
B8: Período Resumen: | C8: Semana Seleccionada
A10: COMPARATIVA: SOLICITADO (PETICIONES) VS ENTREGADO EN OBRA
A11: Día | B11: Fecha | C11: Lts Solicitados | D11: Lts Recibidos Obra | E11: Dif. Litros (Obra-Sol) | F11: Costo Solicitado | G11: Costo Real Obra | H11: Dif. Costo (Real-Sol)
A12: Lunes | B12: =C$5 -> 46195 | C12: =IF(C$4="Todas", SUMIFS(Solicitudes!F:F, Solicitudes!C:C, B12), SUMIFS(Solicitudes!F:F, Solicitudes!B:B, C$4, Solicitudes!C:C, B12)) -> 660 | D12: =IF(C$4="Jalisco", SUMIFS(Captura_Jalisco!G:G, Captura_Jalisco!A:A, B12, Captura_Jalisco!B:B, "Salida"), IF(C$4="Todas", SUMIFS(Captura_Obra!F:F, Captura_Obra!A:A, B12) + SUMIFS(Captura_Jalisco!G:G, Captura_Jalisco!A:A, B12, Captura_Jalisco!B:B, "Salida"), SUMIFS(Captura_Obra!F:F, Captura_Obra!B:B, C$4, Captura_Obra!A:A, B12))) -> 766 | E12: =D12-C12 -> 106 | F12: =C12*C$7 -> 17820 | G12: =D12*C$7 -> 20682 | H12: =G12-F12 -> 2862
A13: Martes | B13: =B12+1 -> 46196 | C13: =IF(C$4="Todas", SUMIFS(Solicitudes!F:F, Solicitudes!C:C, B13), SUMIFS(Solicitudes!F:F, Solicitudes!B:B, C$4, Solicitudes!C:C, B13)) -> 380 | D13: =IF(C$4="Jalisco", SUMIFS(Captura_Jalisco!G:G, Captura_Jalisco!A:A, B13, Captura_Jalisco!B:B, "Salida"), IF(C$4="Todas", SUMIFS(Captura_Obra!F:F, Captura_Obra!A:A, B13) + SUMIFS(Captura_Jalisco!G:G, Captura_Jalisco!A:A, B13, Captura_Jalisco!B:B, "Salida"), SUMIFS(Captura_Obra!F:F, Captura_Obra!B:B, C$4, Captura_Obra!A:A, B13))) -> 102 | E13: =D13-C13 -> -278 | F13: =C13*C$7 -> 10260 | G13: =D13*C$7 -> 2754 | H13: =G13-F13 -> -7506
A14: Miércoles | B14: =B13+1 -> 46197 | C14: =IF(C$4="Todas", SUMIFS(Solicitudes!F:F, Solicitudes!C:C, B14), SUMIFS(Solicitudes!F:F, Solicitudes!B:B, C$4, Solicitudes!C:C, B14)) -> 620 | D14: =IF(C$4="Jalisco", SUMIFS(Captura_Jalisco!G:G, Captura_Jalisco!A:A, B14, Captura_Jalisco!B:B, "Salida"), IF(C$4="Todas", SUMIFS(Captura_Obra!F:F, Captura_Obra!A:A, B14) + SUMIFS(Captura_Jalisco!G:G, Captura_Jalisco!A:A, B14, Captura_Jalisco!B:B, "Salida"), SUMIFS(Captura_Obra!F:F, Captura_Obra!B:B, C$4, Captura_Obra!A:A, B14))) -> 471 | E14: =D14-C14 -> -149 | F14: =C14*C$7 -> 16740 | G14: =D14*C$7 -> 12717 | H14: =G14-F14 -> -4023
A15: Jueves | B15: =B14+1 -> 46198 | C15: =IF(C$4="Todas", SUMIFS(Solicitudes!F:F, Solicitudes!C:C, B15), SUMIFS(Solicitudes!F:F, Solicitudes!B:B, C$4, Solicitudes!C:C, B15)) -> 620 | D15: =IF(C$4="Jalisco", SUMIFS(Captura_Jalisco!G:G, Captura_Jalisco!A:A, B15, Captura_Jalisco!B:B, "Salida"), IF(C$4="Todas", SUMIFS(Captura_Obra!F:F, Captura_Obra!A:A, B15) + SUMIFS(Captura_Jalisco!G:G, Captura_Jalisco!A:A, B15, Captura_Jalisco!B:B, "Salida"), SUMIFS(Captura_Obra!F:F, Captura_Obra!B:B, C$4, Captura_Obra!A:A, B15))) -> 150 | E15: =D15-C15 -> -470 | F15: =C15*C$7 -> 16740 | G15: =D15*C$7 -> 4050 | H15: =G15-F15 -> -12690
A16: Viernes | B16: =B15+1 -> 46199 | C16: =IF(C$4="Todas", SUMIFS(Solicitudes!F:F, Solicitudes!C:C, B16), SUMIFS(Solicitudes!F:F, Solicitudes!B:B, C$4, Solicitudes!C:C, B16)) -> 620 | D16: =IF(C$4="Jalisco", SUMIFS(Captura_Jalisco!G:G, Captura_Jalisco!A:A, B16, Captura_Jalisco!B:B, "Salida"), IF(C$4="Todas", SUMIFS(Captura_Obra!F:F, Captura_Obra!A:A, B16) + SUMIFS(Captura_Jalisco!G:G, Captura_Jalisco!A:A, B16, Captura_Jalisco!B:B, "Salida"), SUMIFS(Captura_Obra!F:F, Captura_Obra!B:B, C$4, Captura_Obra!A:A, B16))) -> 807 | E16: =D16-C16 -> 187 | F16: =C16*C$7 -> 16740 | G16: =D16*C$7 -> 21789 | H16: =G16-F16 -> 5049
A17: Sábado | B17: =B16+1 -> 46200 | C17: =IF(C$4="Todas", SUMIFS(Solicitudes!F:F, Solicitudes!C:C, B17), SUMIFS(Solicitudes!F:F, Solicitudes!B:B, C$4, Solicitudes!C:C, B17)) -> 0 | D17: =IF(C$4="Jalisco", SUMIFS(Captura_Jalisco!G:G, Captura_Jalisco!A:A, B17, Captura_Jalisco!B:B, "Salida"), IF(C$4="Todas", SUMIFS(Captura_Obra!F:F, Captura_Obra!A:A, B17) + SUMIFS(Captura_Jalisco!G:G, Captura_Jalisco!A:A, B17, Captura_Jalisco!B:B, "Salida"), SUMIFS(Captura_Obra!F:F, Captura_Obra!B:B, C$4, Captura_Obra!A:A, B17))) -> 192 | E17: =D17-C17 -> 192 | F17: =C17*C$7 -> 0 | G17: =D17*C$7 -> 5184 | H17: =G17-F17 -> 5184
A18: TOTAL SEMANAL | C18: =SUM(C12:C17) -> 2900 | D18: =SUM(D12:D17) -> 2488 | E18: =SUM(E12:E17) -> -412 | F18: =SUM(F12:F17) -> 78300 | G18: =SUM(G12:G17) -> 67176 | H18: =SUM(H12:H17) -> -11124
A20: CONCILIACIÓN FÍSICA Y DISCREPANCIAS (OBRA VS MARIMBA Y PEGASO)
A21: Día | B21: Fecha | C21: Obra Recibió (M) | D21: Marimba Despachó | E21: Dif. Marimba | F21: Obra Recibió (P) | G21: Pegaso Despachó | H21: Dif. Pegaso | I21: Dif. Total (L) | J21: Observaciones / Justificación
A22: Lunes | B22: =B12 -> 46195 | C22: =IF(C$4="Todas", SUMIFS(Captura_Obra!F:F, Captura_Obra!A:A, B22, Captura_Obra!C:C, "Marimba M-01"), SUMIFS(Captura_Obra!F:F, Captura_Obra!B:B, C$4, Captura_Obra!A:A, B22, Captura_Obra!C:C, "Marimba M-01")) -> 766 | D22: =IF(C$4="Todas", SUMIFS(Captura_Marimba_M01!G:G, Captura_Marimba_M01!A:A, B22, Captura_Marimba_M01!B:B, "Salida"), SUMIFS(Captura_Marimba_M01!G:G, Captura_Marimba_M01!C:C, C$4, Captura_Marimba_M01!A:A, B22, Captura_Marimba_M01!B:B, "Salida")) -> 0 | E22: =C22-D22 -> 766 | F22: =IF(C$4="Todas", SUMIFS(Captura_Obra!F:F, Captura_Obra!A:A, B22, Captura_Obra!C:C, "Pegaso Directo"), SUMIFS(Captura_Obra!F:F, Captura_Obra!B:B, C$4, Captura_Obra!A:A, B22, Captura_Obra!C:C, "Pegaso Directo")) -> 0 | G22: =IF(C$4="Todas", SUMIFS(Captura_Pegaso!H:H, Captura_Pegaso!A:A, B22, Captura_Pegaso!B:B, "Salida"), SUMIFS(Captura_Pegaso!H:H, Captura_Pegaso!D:D, C$4, Captura_Pegaso!A:A, B22, Captura_Pegaso!B:B, "Salida")) -> 0 | H22: =F22-G22 -> 0 | I22: =E22+H22 -> 766
A23: Martes | B23: =B13 -> 46196 | C23: =IF(C$4="Todas", SUMIFS(Captura_Obra!F:F, Captura_Obra!A:A, B23, Captura_Obra!C:C, "Marimba M-01"), SUMIFS(Captura_Obra!F:F, Captura_Obra!B:B, C$4, Captura_Obra!A:A, B23, Captura_Obra!C:C, "Marimba M-01")) -> 102 | D23: =IF(C$4="Todas", SUMIFS(Captura_Marimba_M01!G:G, Captura_Marimba_M01!A:A, B23, Captura_Marimba_M01!B:B, "Salida"), SUMIFS(Captura_Marimba_M01!G:G, Captura_Marimba_M01!C:C, C$4, Captura_Marimba_M01!A:A, B23, Captura_Marimba_M01!B:B, "Salida")) -> 0 | E23: =C23-D23 -> 102 | F23: =IF(C$4="Todas", SUMIFS(Captura_Obra!F:F, Captura_Obra!A:A, B23, Captura_Obra!C:C, "Pegaso Directo"), SUMIFS(Captura_Obra!F:F, Captura_Obra!B:B, C$4, Captura_Obra!A:A, B23, Captura_Obra!C:C, "Pegaso Directo")) -> 0 | G23: =IF(C$4="Todas", SUMIFS(Captura_Pegaso!H:H, Captura_Pegaso!A:A, B23, Captura_Pegaso!B:B, "Salida"), SUMIFS(Captura_Pegaso!H:H, Captura_Pegaso!D:D, C$4, Captura_Pegaso!A:A, B23, Captura_Pegaso!B:B, "Salida")) -> 0 | H23: =F23-G23 -> 0 | I23: =E23+H23 -> 102
A24: Miércoles | B24: =B14 -> 46197 | C24: =IF(C$4="Todas", SUMIFS(Captura_Obra!F:F, Captura_Obra!A:A, B24, Captura_Obra!C:C, "Marimba M-01"), SUMIFS(Captura_Obra!F:F, Captura_Obra!B:B, C$4, Captura_Obra!A:A, B24, Captura_Obra!C:C, "Marimba M-01")) -> 471 | D24: =IF(C$4="Todas", SUMIFS(Captura_Marimba_M01!G:G, Captura_Marimba_M01!A:A, B24, Captura_Marimba_M01!B:B, "Salida"), SUMIFS(Captura_Marimba_M01!G:G, Captura_Marimba_M01!C:C, C$4, Captura_Marimba_M01!A:A, B24, Captura_Marimba_M01!B:B, "Salida")) -> 0 | E24: =C24-D24 -> 471 | F24: =IF(C$4="Todas", SUMIFS(Captura_Obra!F:F, Captura_Obra!A:A, B24, Captura_Obra!C:C, "Pegaso Directo"), SUMIFS(Captura_Obra!F:F, Captura_Obra!B:B, C$4, Captura_Obra!A:A, B24, Captura_Obra!C:C, "Pegaso Directo")) -> 0 | G24: =IF(C$4="Todas", SUMIFS(Captura_Pegaso!H:H, Captura_Pegaso!A:A, B24, Captura_Pegaso!B:B, "Salida"), SUMIFS(Captura_Pegaso!H:H, Captura_Pegaso!D:D, C$4, Captura_Pegaso!A:A, B24, Captura_Pegaso!B:B, "Salida")) -> 0 | H24: =F24-G24 -> 0 | I24: =E24+H24 -> 471
A25: Jueves | B25: =B15 -> 46198 | C25: =IF(C$4="Todas", SUMIFS(Captura_Obra!F:F, Captura_Obra!A:A, B25, Captura_Obra!C:C, "Marimba M-01"), SUMIFS(Captura_Obra!F:F, Captura_Obra!B:B, C$4, Captura_Obra!A:A, B25, Captura_Obra!C:C, "Marimba M-01")) -> 150 | D25: =IF(C$4="Todas", SUMIFS(Captura_Marimba_M01!G:G, Captura_Marimba_M01!A:A, B25, Captura_Marimba_M01!B:B, "Salida"), SUMIFS(Captura_Marimba_M01!G:G, Captura_Marimba_M01!C:C, C$4, Captura_Marimba_M01!A:A, B25, Captura_Marimba_M01!B:B, "Salida")) -> 0 | E25: =C25-D25 -> 150 | F25: =IF(C$4="Todas", SUMIFS(Captura_Obra!F:F, Captura_Obra!A:A, B25, Captura_Obra!C:C, "Pegaso Directo"), SUMIFS(Captura_Obra!F:F, Captura_Obra!B:B, C$4, Captura_Obra!A:A, B25, Captura_Obra!C:C, "Pegaso Directo")) -> 0 | G25: =IF(C$4="Todas", SUMIFS(Captura_Pegaso!H:H, Captura_Pegaso!A:A, B25, Captura_Pegaso!B:B, "Salida"), SUMIFS(Captura_Pegaso!H:H, Captura_Pegaso!D:D, C$4, Captura_Pegaso!A:A, B25, Captura_Pegaso!B:B, "Salida")) -> 0 | H25: =F25-G25 -> 0 | I25: =E25+H25 -> 150
A26: Viernes | B26: =B16 -> 46199 | C26: =IF(C$4="Todas", SUMIFS(Captura_Obra!F:F, Captura_Obra!A:A, B26, Captura_Obra!C:C, "Marimba M-01"), SUMIFS(Captura_Obra!F:F, Captura_Obra!B:B, C$4, Captura_Obra!A:A, B26, Captura_Obra!C:C, "Marimba M-01")) -> 478 | D26: =IF(C$4="Todas", SUMIFS(Captura_Marimba_M01!G:G, Captura_Marimba_M01!A:A, B26, Captura_Marimba_M01!B:B, "Salida"), SUMIFS(Captura_Marimba_M01!G:G, Captura_Marimba_M01!C:C, C$4, Captura_Marimba_M01!A:A, B26, Captura_Marimba_M01!B:B, "Salida")) -> 0 | E26: =C26-D26 -> 478 | F26: =IF(C$4="Todas", SUMIFS(Captura_Obra!F:F, Captura_Obra!A:A, B26, Captura_Obra!C:C, "Pegaso Directo"), SUMIFS(Captura_Obra!F:F, Captura_Obra!B:B, C$4, Captura_Obra!A:A, B26, Captura_Obra!C:C, "Pegaso Directo")) -> 0 | G26: =IF(C$4="Todas", SUMIFS(Captura_Pegaso!H:H, Captura_Pegaso!A:A, B26, Captura_Pegaso!B:B, "Salida"), SUMIFS(Captura_Pegaso!H:H, Captura_Pegaso!D:D, C$4, Captura_Pegaso!A:A, B26, Captura_Pegaso!B:B, "Salida")) -> 0 | H26: =F26-G26 -> 0 | I26: =E26+H26 -> 478
A27: Sábado | B27: =B17 -> 46200 | C27: =IF(C$4="Todas", SUMIFS(Captura_Obra!F:F, Captura_Obra!A:A, B27, Captura_Obra!C:C, "Marimba M-01"), SUMIFS(Captura_Obra!F:F, Captura_Obra!B:B, C$4, Captura_Obra!A:A, B27, Captura_Obra!C:C, "Marimba M-01")) -> 192 | D27: =IF(C$4="Todas", SUMIFS(Captura_Marimba_M01!G:G, Captura_Marimba_M01!A:A, B27, Captura_Marimba_M01!B:B, "Salida"), SUMIFS(Captura_Marimba_M01!G:G, Captura_Marimba_M01!C:C, C$4, Captura_Marimba_M01!A:A, B27, Captura_Marimba_M01!B:B, "Salida")) -> 0 | E27: =C27-D27 -> 192 | F27: =IF(C$4="Todas", SUMIFS(Captura_Obra!F:F, Captura_Obra!A:A, B27, Captura_Obra!C:C, "Pegaso Directo"), SUMIFS(Captura_Obra!F:F, Captura_Obra!B:B, C$4, Captura_Obra!A:A, B27, Captura_Obra!C:C, "Pegaso Directo")) -> 0 | G27: =IF(C$4="Todas", SUMIFS(Captura_Pegaso!H:H, Captura_Pegaso!A:A, B27, Captura_Pegaso!B:B, "Salida"), SUMIFS(Captura_Pegaso!H:H, Captura_Pegaso!D:D, C$4, Captura_Pegaso!A:A, B27, Captura_Pegaso!B:B, "Salida")) -> 0 | H27: =F27-G27 -> 0 | I27: =E27+H27 -> 192
A28: TOTAL CONCILIADO | C28: =SUM(C22:C27) -> 2159 | D28: =SUM(D22:D27) -> 0 | E28: =SUM(E22:E27) -> 2159 | F28: =SUM(F22:F27) -> 0 | G28: =SUM(G22:G27) -> 0 | H28: =SUM(H22:H27) -> 0 | I28: =SUM(I22:I27) -> 2159
Q30: ="SOLICITUDES DE DISEL DIARIAS Y SEMANALES POR OBRA (SEMANA " & YEAR(C5) & "-" & TEXT(MONTH(C5),"00") & "-" & TEXT(DAY(C5),"00") & ")" -> SOLICITUDES DE DISEL DIARIAS Y SEMANALES POR OBRA (SEMANA 2026-06-22)
A31: RESUMEN ACUMULADO POR OBRA / PERÍODO SELECCIONADO | Q31: Obra | R31: Solicitante | S31: Lunes | U31: Martes | W31: Miércoles | Y31: Jueves | AA31: Viernes | AC31: Sábado | AE31: Total Semanal Solicitado | AF31: Total Seamanal Autorizado
A32: Obra | B32: Total Litros Suministrados | C32: Costo Total Acumulado | S32: Solicitado | T32: Autorizado | U32: Solicitado | V32: Autorizado | W32: Solicitado | X32: Autorizado | Y32: Solicitado | Z32: Autorizado | AA32: Solicitado | AB32: Autorizado | AC32: Solicitado | AD32: Autorizado
A33: México-Toluca | B33: =IF(C$8="Acumulado Histórico", SUMIFS(Captura_Obra!F:F, Captura_Obra!B:B, A33), IF(C$8="Rango de Fechas", SUMIFS(Captura_Obra!F:F, Captura_Obra!B:B, A33, Captura_Obra!A:A, ">="&C$5, Captura_Obra!A:A, "<="&(C$6+5)), SUMIFS(Captura_Obra!F:F, Captura_Obra!B:B, A33, Captura_Obra!A:A, ">="&C$5, Captura_Obra!A:A, "<="&(C$5+5)))) -> 2488 | C33: =B33*C$7 -> 67176 | P33: m | Q33: =A33 -> México-Toluca | R33: =VLOOKUP(Q33,Catalogos!$B$4:$C$18,2,FALSE) -> Francisco Javier | S33: =SUMIFS(Solicitudes!$F:$F, Solicitudes!$B:$B, $Q33, Solicitudes!$C:$C, $B$12) -> 660 | T33: 550 | U33: =SUMIFS(Solicitudes!$F:$F, Solicitudes!$B:$B, $Q33, Solicitudes!$C:$C, $B$13) -> 380 | V33: 550 | W33: =SUMIFS(Solicitudes!$F:$F, Solicitudes!$B:$B, $Q33, Solicitudes!$C:$C, $B$14) -> 620 | X33: 550 | Y33: =SUMIFS(Solicitudes!$F:$F, Solicitudes!$B:$B, $Q33, Solicitudes!$C:$C, $B$15) -> 620 | Z33: 550 | AA33: =SUMIFS(Solicitudes!$F:$F, Solicitudes!$B:$B, $Q33, Solicitudes!$C:$C, $B$16) -> 620 | AB33: 550 | AC33: =SUMIFS(Solicitudes!$F:$F, Solicitudes!$B:$B, $Q33, Solicitudes!$C:$C, $B$17) -> 0 | AD33: 0 | AE33: =SUM(S33,U33,W33,Y33,AA33,AC33,) -> 2900 | AF33: =SUM(T33,V33,X33,Z33,AB33,AD33) -> 2750
A34: Lerma - Tres Marías | B34: =IF(C$8="Acumulado Histórico", SUMIFS(Captura_Obra!F:F, Captura_Obra!B:B, A34), IF(C$8="Rango de Fechas", SUMIFS(Captura_Obra!F:F, Captura_Obra!B:B, A34, Captura_Obra!A:A, ">="&C$5, Captura_Obra!A:A, "<="&(C$6+5)), SUMIFS(Captura_Obra!F:F, Captura_Obra!B:B, A34, Captura_Obra!A:A, ">="&C$5, Captura_Obra!A:A, "<="&(C$5+5)))) -> 1279 | C34: =B34*C$7 -> 34533 | P34: p | Q34: =A34 -> Lerma - Tres Marías | R34: =VLOOKUP(Q34,Catalogos!$B$4:$C$18,2,FALSE) -> Apolinar | S34: =SUMIFS(Solicitudes!$F:$F, Solicitudes!$B:$B, $Q34, Solicitudes!$C:$C, $B$12) -> 608 | T34: 400 | U34: =SUMIFS(Solicitudes!$F:$F, Solicitudes!$B:$B, $Q34, Solicitudes!$C:$C, $B$13) -> 608 | V34: 400 | W34: =SUMIFS(Solicitudes!$F:$F, Solicitudes!$B:$B, $Q34, Solicitudes!$C:$C, $B$14) -> 608 | X34: 400 | Y34: =SUMIFS(Solicitudes!$F:$F, Solicitudes!$B:$B, $Q34, Solicitudes!$C:$C, $B$15) -> 608 | Z34: 400 | AA34: =SUMIFS(Solicitudes!$F:$F, Solicitudes!$B:$B, $Q34, Solicitudes!$C:$C, $B$16) -> 608 | AB34: 400 | AC34: =SUMIFS(Solicitudes!$F:$F, Solicitudes!$B:$B, $Q34, Solicitudes!$C:$C, $B$17) -> 0 | AD34: =SUMIFS(Solicitudes!$F:$F, Solicitudes!$B:$B, $Q34, Solicitudes!$C:$C, ($B$17+1)) -> 0 | AE34: =SUM(S34,U34,W34,Y34,AA34,AC34,) -> 3040 | AF34: =SUM(T34,V34,X34,Z34,AB34,AD34) -> 2000
A35: Chamapa-Lechería | B35: =IF(C$8="Acumulado Histórico", SUMIFS(Captura_Obra!F:F, Captura_Obra!B:B, A35), IF(C$8="Rango de Fechas", SUMIFS(Captura_Obra!F:F, Captura_Obra!B:B, A35, Captura_Obra!A:A, ">="&C$5, Captura_Obra!A:A, "<="&(C$6+5)), SUMIFS(Captura_Obra!F:F, Captura_Obra!B:B, A35, Captura_Obra!A:A, ">="&C$5, Captura_Obra!A:A, "<="&(C$5+5)))) -> 0 | C35: =B35*C$7 -> 0 | P35: p | Q35: =A36 -> Bacheo Toluca | R35: =VLOOKUP(Q35,Catalogos!$B$4:$C$18,2,FALSE) -> Diego Carreola | S35: =SUMIFS(Solicitudes!$F:$F, Solicitudes!$B:$B, $Q35, Solicitudes!$C:$C, $B$12) -> 118 | T35: 100 | U35: =SUMIFS(Solicitudes!$F:$F, Solicitudes!$B:$B, $Q35, Solicitudes!$C:$C, $B$13) -> 105 | V35: 100 | W35: =SUMIFS(Solicitudes!$F:$F, Solicitudes!$B:$B, $Q35, Solicitudes!$C:$C, $B$14) -> 108 | X35: 100 | Y35: =SUMIFS(Solicitudes!$F:$F, Solicitudes!$B:$B, $Q35, Solicitudes!$C:$C, $B$15) -> 125 | Z35: 100 | AA35: =SUMIFS(Solicitudes!$F:$F, Solicitudes!$B:$B, $Q35, Solicitudes!$C:$C, $B$16) -> 118 | AB35: 100 | AC35: =SUMIFS(Solicitudes!$F:$F, Solicitudes!$B:$B, $Q35, Solicitudes!$C:$C, $B$17) -> 0 | AD35: =SUMIFS(Solicitudes!$F:$F, Solicitudes!$B:$B, $Q35, Solicitudes!$C:$C, ($B$17+1)) -> 0 | AE35: =SUM(S35,U35,W35,Y35,AA35,AC35,) -> 574 | AF35: =SUM(T35,V35,X35,Z35,AB35,AD35) -> 500
A36: Bacheo Toluca | B36: =IF(C$8="Acumulado Histórico", SUMIFS(Captura_Obra!F:F, Captura_Obra!B:B, A36), IF(C$8="Rango de Fechas", SUMIFS(Captura_Obra!F:F, Captura_Obra!B:B, A36, Captura_Obra!A:A, ">="&C$5, Captura_Obra!A:A, "<="&(C$6+5)), SUMIFS(Captura_Obra!F:F, Captura_Obra!B:B, A36, Captura_Obra!A:A, ">="&C$5, Captura_Obra!A:A, "<="&(C$5+5)))) -> 1554 | C36: =B36*C$7 -> 41958 | P36: p | Q36: =A37 -> Planta Asfalto Pegaso | R36: =VLOOKUP(Q36,Catalogos!$B$4:$C$18,2,FALSE) -> Janeth | S36: =SUMIFS(Solicitudes!$F:$F, Solicitudes!$B:$B, $Q36, Solicitudes!$C:$C, $B$12) -> 0 | T36: 0 | U36: =SUMIFS(Solicitudes!$F:$F, Solicitudes!$B:$B, $Q36, Solicitudes!$C:$C, $B$13) -> 300 | V36: 300 | W36: =SUMIFS(Solicitudes!$F:$F, Solicitudes!$B:$B, $Q36, Solicitudes!$C:$C, $B$14) -> 1000 | X36: 1000 | Y36: =SUMIFS(Solicitudes!$F:$F, Solicitudes!$B:$B, $Q36, Solicitudes!$C:$C, $B$15) -> 300 | Z36: 300 | AA36: =SUMIFS(Solicitudes!$F:$F, Solicitudes!$B:$B, $Q36, Solicitudes!$C:$C, $B$16) -> 0 | AB36: 0 | AC36: =SUMIFS(Solicitudes!$F:$F, Solicitudes!$B:$B, $Q36, Solicitudes!$C:$C, $B$17) -> 0 | AD36: =SUMIFS(Solicitudes!$F:$F, Solicitudes!$B:$B, $Q36, Solicitudes!$C:$C, ($B$17+1)) -> 0 | AE36: =SUM(S36,U36,W36,Y36,AA36,AC36,) -> 1600 | AF36: =SUM(T36,V36,X36,Z36,AB36,AD36) -> 1600
A37: Planta Asfalto Pegaso | B37: =IF(C$8="Acumulado Histórico", SUMIFS(Captura_Obra!F:F, Captura_Obra!B:B, A37), IF(C$8="Rango de Fechas", SUMIFS(Captura_Obra!F:F, Captura_Obra!B:B, A37, Captura_Obra!A:A, ">="&C$5, Captura_Obra!A:A, "<="&(C$6+5)), SUMIFS(Captura_Obra!F:F, Captura_Obra!B:B, A37, Captura_Obra!A:A, ">="&C$5, Captura_Obra!A:A, "<="&(C$5+5)))) -> 0 | C37: =B37*C$7 -> 0 | P37: h | Q37: =A38 -> Planta Asflato Huixquilucan | R37: =VLOOKUP(Q37,Catalogos!$B$4:$C$18,2,FALSE) -> Luis | S37: =SUMIFS(Solicitudes!$F:$F, Solicitudes!$B:$B, $Q37, Solicitudes!$C:$C, $B$12) -> 600 | T37: 500 | U37: =SUMIFS(Solicitudes!$F:$F, Solicitudes!$B:$B, $Q37, Solicitudes!$C:$C, $B$13) -> 400 | V37: 500 | W37: =SUMIFS(Solicitudes!$F:$F, Solicitudes!$B:$B, $Q37, Solicitudes!$C:$C, $B$14) -> 500 | X37: 500 | Y37: =SUMIFS(Solicitudes!$F:$F, Solicitudes!$B:$B, $Q37, Solicitudes!$C:$C, $B$15) -> 500 | Z37: 500 | AA37: =SUMIFS(Solicitudes!$F:$F, Solicitudes!$B:$B, $Q37, Solicitudes!$C:$C, $B$16) -> 500 | AB37: 500 | AC37: =SUMIFS(Solicitudes!$F:$F, Solicitudes!$B:$B, $Q37, Solicitudes!$C:$C, $B$17) -> 100 | AD37: =SUMIFS(Solicitudes!$F:$F, Solicitudes!$B:$B, $Q37, Solicitudes!$C:$C, ($B$17+1)) -> 0 | AE37: =SUM(S37,U37,W37,Y37,AA37,AC37,) -> 2600 | AF37: =SUM(T37,V37,X37,Z37,AB37,AD37) -> 2500
A38: Planta Asflato Huixquilucan | B38: =IF(C$8="Acumulado Histórico", SUMIFS(Captura_Obra!F:F, Captura_Obra!B:B, A38), IF(C$8="Rango de Fechas", SUMIFS(Captura_Obra!F:F, Captura_Obra!B:B, A38, Captura_Obra!A:A, ">="&C$5, Captura_Obra!A:A, "<="&(C$6+5)), SUMIFS(Captura_Obra!F:F, Captura_Obra!B:B, A38, Captura_Obra!A:A, ">="&C$5, Captura_Obra!A:A, "<="&(C$5+5)))) -> 1050 | C38: =B38*C$7 -> 28350 | Q38: =A41 -> TOTAL GENERAL | S38: =SUM(S33:S37) -> 1986 | T38: =SUM(T33:T37) -> 1550 | U38: =SUM(U33:U37) -> 1793 | V38: =SUM(V33:V37) -> 1850 | W38: =SUM(W33:W37) -> 2836 | X38: =SUM(X33:X37) -> 2550 | Y38: =SUM(Y33:Y37) -> 2153 | Z38: =SUM(Z33:Z37) -> 1850 | ... AE38: =SUM(AE33:AE37) -> 10714 | AF38: =SUM(T38,V38,X38,Z38,AB38,AD38) -> 9350
A39: Dragones | B39: =IF(C$8="Acumulado Histórico", SUMIFS(Captura_Obra!F:F, Captura_Obra!B:B, A39), IF(C$8="Rango de Fechas", SUMIFS(Captura_Obra!F:F, Captura_Obra!B:B, A39, Captura_Obra!A:A, ">="&C$5, Captura_Obra!A:A, "<="&(C$6+5)), SUMIFS(Captura_Obra!F:F, Captura_Obra!B:B, A39, Captura_Obra!A:A, ">="&C$5, Captura_Obra!A:A, "<="&(C$5+5)))) -> 102 | C39: =B39*C$7 -> 2754
A40: Jalisco | B40: =IF(C$8="Acumulado Histórico", SUMIFS(Captura_Jalisco!G:G, Captura_Jalisco!B:B, "Salida"), IF(C$8="Rango de Fechas", SUMIFS(Captura_Jalisco!G:G, Captura_Jalisco!B:B, "Salida", Captura_Jalisco!A:A, ">="&C$5, Captura_Jalisco!A:A, "<="&(C$6+5)), SUMIFS(Captura_Jalisco!G:G, Captura_Jalisco!B:B, "Salida", Captura_Jalisco!A:A, ">="&C$5, Captura_Jalisco!A:A, "<="&(C$5+5)))) -> 1338 | C40: =B40*C$7 -> 36126
A41: TOTAL GENERAL | B41: =SUM(B33:B40) -> 7811 | C41: =SUM(C33:C40) -> 210897
A43: RESUMEN DE CONSUMO SEMANAL POR OBRA (DETALLE HISTÓRICO POR SEMANA)
B44: Obra (Tabla Semanal): | C44: Jalisco
B45: Precio Diésel ($/L): | C45: 27
...

Sheet Conciliacion_Auditoria
A1: AUDITORÍA DE CONCILIACIÓN (CRUCE TRANSACCIONAL)
A3: Origen | B3: Folio Suministro (Pipa) | C3: Folio Recepción (Obra) | D3: Estatus | E3: Fecha | F3: Obra | G3: Máquina / Destino | H3: Lts Entregados | I3: Lts Recibidos | J3: Diferencia Lts | K3: Estatus
A4: =IF(Captura_Pegaso!A5="", "", "Pegaso") -> Pegaso | B4: =IF(Captura_Pegaso!A5="", "", Captura_Pegaso!N5) -> CP-BT-24-001 | C4: =IF(Captura_Pegaso!A5="", "", IFERROR(LOOKUP(2, 1/((Captura_Obra!$A$5:$A$1000=E4)*(Captura_Obra!$B$5:$B$1000=F4)*(Captura_Obra!$D$5:$D$1000=G4)), Captura_Obra!$N$5:$N$1000), "No Reportado")) -> CO-BT-24-013 | D4: =IF(Captura_Pegaso!A5="", "", IF(J4=0, "✅ Cuadrado", IF(I4=0, "❌ Falta en Obra", "⚠️ Dif"))) -> ✅ Cuadrado | E4: =IF(Captura_Pegaso!A5="", "", Captura_Pegaso!A5) -> 46181 | F4: =IF(Captura_Pegaso!A5="", "", Captura_Pegaso!D5) -> Bacheo Toluca | G4: =IF(Captura_Pegaso!A5="", "", Captura_Pegaso!E5) -> Bidones | H4: =IF(Captura_Pegaso!A5="", "", Captura_Pegaso!H5) -> 100 | I4: =IF(Captura_Pegaso!A5="", "", SUMIFS(Captura_Obra!$F:$F, Captura_Obra!$A:$A, E4, Captura_Obra!$B:$B, F4, Captura_Obra!$D:$D, G4)) -> 100 | J4: =IF(Captura_Pegaso!A5="", "", H4 - I4) -> 0
A5: =IF(Captura_Pegaso!A6="", "", "Pegaso") -> Pegaso | B5: =IF(Captura_Pegaso!A6="", "", Captura_Pegaso!N6) -> CP-PAP-24-002 | C5: =IF(Captura_Pegaso!A6="", "", IFERROR(LOOKUP(2, 1/((Captura_Obra!$A$5:$A$1000=E5)*(Captura_Obra!$B$5:$B$1000=F5)*(Captura_Obra!$D$5:$D$1000=G5)), Captura_Obra!$N$5:$N$1000), "No Reportado")) -> No Reportado | D5: =IF(Captura_Pegaso!A6="", "", IF(J5=0, "✅ Cuadrado", IF(I5=0, "❌ Falta en Obra", "⚠️ Dif"))) -> ❌ Falta en Obra | E5: =IF(Captura_Pegaso!A6="", "", Captura_Pegaso!A6) -> 46181 | F5: =IF(Captura_Pegaso!A6="", "", Captura_Pegaso!D6) -> Planta Asfalto Pegaso | G5: =IF(Captura_Pegaso!A6="", "", Captura_Pegaso!E6) -> Bidones | H5: =IF(Captura_Pegaso!A6="", "", Captura_Pegaso!H6) -> 200 | I5: =IF(Captura_Pegaso!A6="", "", SUMIFS(Captura_Obra!$F:$F, Captura_Obra!$A:$A, E5, Captura_Obra!$B:$B, F5, Captura_Obra!$D:$D, G5)) -> 0 | J5: =IF(Captura_Pegaso!A6="", "", H5 - I5) -> 200
A6: =IF(Captura_Pegaso!A7="", "", "Pegaso") -> Pegaso | B6: =IF(Captura_Pegaso!A7="", "", Captura_Pegaso!N7) -> CP-PAP-24-003 | C6: =IF(Captura_Pegaso!A7="", "", IFERROR(LOOKUP(2, 1/((Captura_Obra!$A$5:$A$1000=E6)*(Captura_Obra!$B$5:$B$1000=F6)*(Captura_Obra!$D$5:$D$1000=G6)), Captura_Obra!$N$5:$N$1000), "No Reportado")) -> No Reportado | D6: =IF(Captura_Pegaso!A7="", "", IF(J6=0, "✅ Cuadrado", IF(I6=0, "❌ Falta en Obra", "⚠️ Dif"))) -> ❌ Falta en Obra | E6: =IF(Captura_Pegaso!A7="", "", Captura_Pegaso!A7) -> 46181 | F6: =IF(Captura_Pegaso!A7="", "", Captura_Pegaso!D7) -> Planta Asfalto Pegaso | G6: =IF(Captura_Pegaso!A7="", "", Captura_Pegaso!E7) -> Bidones | H6: =IF(Captura_Pegaso!A7="", "", Captura_Pegaso!H7) -> 209 | I6: =IF(Captura_Pegaso!A7="", "", SUMIFS(Captura_Obra!$F:$F, Captura_Obra!$A:$A, E6, Captura_Obra!$B:$B, F6, Captura_Obra!$D:$D, G6)) -> 0 | J6: =IF(Captura_Pegaso!A7="", "", H6 - I6) -> 209
A7: =IF(Captura_Pegaso!A8="", "", "Pegaso") -> Pegaso | B7: =IF(Captura_Pegaso!A8="", "", Captura_Pegaso!N8) -> CP-FOL-24-004 | C7: =IF(Captura_Pegaso!A8="", "", IFERROR(LOOKUP(2, 1/((Captura_Obra!$A$5:$A$1000=E7)*(Captura_Obra!$B$5:$B$1000=F7)*(Captura_Obra!$D$5:$D$1000=G7)), Captura_Obra!$N$5:$N$1000), "No Reportado")) -> No Reportado | D7: =IF(Captura_Pegaso!A8="", "", IF(J7=0, "✅ Cuadrado", IF(I7=0, "❌ Falta en Obra", "⚠️ Dif"))) -> ✅ Cuadrado | E7: =IF(Captura_Pegaso!A8="", "", Captura_Pegaso!A8) -> 46181 | F7: =IF(Captura_Pegaso!A8="", "", Captura_Pegaso!D8) -> 0 | G7: =IF(Captura_Pegaso!A8="", "", Captura_Pegaso!E8) -> 0 | H7: =IF(Captura_Pegaso!A8="", "", Captura_Pegaso!H8) -> 0 | I7: =IF(Captura_Pegaso!A8="", "", SUMIFS(Captura_Obra!$F:$F, Captura_Obra!$A:$A, E7, Captura_Obra!$B:$B, F7, Captura_Obra!$D:$D, G7)) -> 0 | J7: =IF(Captura_Pegaso!A8="", "", H7 - I7) -> 0
A8: =IF(Captura_Pegaso!A9="", "", "Pegaso") -> Pegaso | B8: =IF(Captura_Pegaso!A9="", "", Captura_Pegaso!N9) -> CP-BT-24-005 | C8: =IF(Captura_Pegaso!A9="", "", IFERROR(LOOKUP(2, 1/((Captura_Obra!$A$5:$A$1000=E8)*(Captura_Obra!$B$5:$B$1000=F8)*(Captura_Obra!$D$5:$D$1000=G8)), Captura_Obra!$N$5:$N$1000), "No Reportado")) -> CO-BT-24-013 | D8: =IF(Captura_Pegaso!A9="", "", IF(J8=0, "✅ Cuadrado", IF(I8=0, "❌ Falta en Obra", "⚠️ Dif"))) -> ⚠️ Dif | E8: =IF(Captura_Pegaso!A9="", "", Captura_Pegaso!A9) -> 46181 | F8: =IF(Captura_Pegaso!A9="", "", Captura_Pegaso!D9) -> Bacheo Toluca | G8: =IF(Captura_Pegaso!A9="", "", Captura_Pegaso!E9) -> Bidones | H8: =IF(Captura_Pegaso!A9="", "", Captura_Pegaso!H9) -> 80 | I8: =IF(Captura_Pegaso!A9="", "", SUMIFS(Captura_Obra!$F:$F, Captura_Obra!$A:$A, E8, Captura_Obra!$B:$B, F8, Captura_Obra!$D:$D, G8)) -> 100 | J8: =IF(Captura_Pegaso!A9="", "", H8 - I8) -> -20
A9: =IF(Captura_Pegaso!A10="", "", "Pegaso") -> Pegaso | B9: =IF(Captura_Pegaso!A10="", "", Captura_Pegaso!N10) -> CP-LT-24-006 | C9: =IF(Captura_Pegaso!A10="", "", IFERROR(LOOKUP(2, 1/((Captura_Obra!$A$5:$A$1000=E9)*(Captura_Obra!$B$5:$B$1000=F9)*(Captura_Obra!$D$5:$D$1000=G9)), Captura_Obra!$N$5:$N$1000), "No Reportado")) -> CO-LT-24-027 | D9: =IF(Captura_Pegaso!A10="", "", IF(J9=0, "✅ Cuadrado", IF(I9=0, "❌ Falta en Obra", "⚠️ Dif"))) -> ✅ Cuadrado | E9: =IF(Captura_Pegaso!A10="", "", Captura_Pegaso!A10) -> 46182 | F9: =IF(Captura_Pegaso!A10="", "", Captura_Pegaso!D10) -> Lerma - Tres Marías | G9: =IF(Captura_Pegaso!A10="", "", Captura_Pegaso!E10) -> Retroexcavadora | H9: =IF(Captura_Pegaso!A10="", "", Captura_Pegaso!H10) -> 70 | I9: =IF(Captura_Pegaso!A10="", "", SUMIFS(Captura_Obra!$F:$F, Captura_Obra!$A:$A, E9, Captura_Obra!$B:$B, F9, Captura_Obra!$D:$D, G9)) -> 70 | J9: =IF(Captura_Pegaso!A10="", "", H9 - I9) -> 0
A10: =IF(Captura_Pegaso!A11="", "", "Pegaso") -> Pegaso | B10: =IF(Captura_Pegaso!A11="", "", Captura_Pegaso!N11) -> CP-LT-24-007 | C10: =IF(Captura_Pegaso!A11="", "", IFERROR(LOOKUP(2, 1/((Captura_Obra!$A$5:$A$1000=E10)*(Captura_Obra!$B$5:$B$1000=F10)*(Captura_Obra!$D$5:$D$1000=G10)), Captura_Obra!$N$5:$N$1000), "No Reportado")) -> CO-LT-24-028 | D10: =IF(Captura_Pegaso!A11="", "", IF(J10=0, "✅ Cuadrado", IF(I10=0, "❌ Falta en Obra", "⚠️ Dif"))) -> ✅ Cuadrado | E10: =IF(Captura_Pegaso!A11="", "", Captura_Pegaso!A11) -> 46182 | F10: =IF(Captura_Pegaso!A11="", "", Captura_Pegaso!D11) -> Lerma - Tres Marías | G10: =IF(Captura_Pegaso!A11="", "", Captura_Pegaso!E11) -> Doble Rodillo | H10: =IF(Captura_Pegaso!A11="", "", Captura_Pegaso!H11) -> 50 | I10: =IF(Captura_Pegaso!A11="", "", SUMIFS(Captura_Obra!$F:$F, Captura_Obra!$A:$A, E10, Captura_Obra!$B:$B, F10, Captura_Obra!$D:$D, G10)) -> 50 | J10: =IF(Captura_Pegaso!A11="", "", H10 - I10) -> 0
A11: =IF(Captura_Pegaso!A12="", "", "Pegaso") -> Pegaso | B11: =IF(Captura_Pegaso!A12="", "", Captura_Pegaso!N12) -> CP-LT-24-008 | C11: =IF(Captura_Pegaso!A12="", "", IFERROR(LOOKUP(2, 1/((Captura_Obra!$A$5:$A$1000=E11)*(Captura_Obra!$B$5:$B$1000=F11)*(Captura_Obra!$D$5:$D$1000=G11)), Captura_Obra!$N$5:$N$1000), "No Reportado")) -> CO-LT-24-029 | D11: =IF(Captura_Pegaso!A12="", "", IF(J11=0, "✅ Cuadrado", IF(I11=0, "❌ Falta en Obra", "⚠️ Dif"))) -> ✅ Cuadrado | E11: =IF(Captura_Pegaso!A12="", "", Captura_Pegaso!A12) -> 46182 | F11: =IF(Captura_Pegaso!A12="", "", Captura_Pegaso!D12) -> Lerma - Tres Marías | G11: =IF(Captura_Pegaso!A12="", "", Captura_Pegaso!E12) -> Petrolizadora | H11: =IF(Captura_Pegaso!A12="", "", Captura_Pegaso!H12) -> 60 | I11: =IF(Captura_Pegaso!A12="", "", SUMIFS(Captura_Obra!$F:$F, Captura_Obra!$A:$A, E11, Captura_Obra!$B:$B, F11, Captura_Obra!$D:$D, G11)) -> 60 | J11: =IF(Captura_Pegaso!A12="", "", H11 - I11) -> 0
A12: =IF(Captura_Pegaso!A13="", "", "Pegaso") -> Pegaso | B12: =IF(Captura_Pegaso!A13="", "", Captura_Pegaso!N13) -> CP-BT-24-009 | C12: =IF(Captura_Pegaso!A13="", "", IFERROR(LOOKUP(2, 1/((Captura_Obra!$A$5:$A$1000=E12)*(Captura_Obra!$B$5:$B$1000=F12)*(Captura_Obra!$D$5:$D$1000=G12)), Captura_Obra!$N$5:$N$1000), "No Reportado")) -> CO-BT-24-033 | D12: =IF(Captura_Pegaso!A13="", "", IF(J12=0, "✅ Cuadrado", IF(I12=0, "❌ Falta en Obra", "⚠️ Dif"))) -> ✅ Cuadrado | E12: =IF(Captura_Pegaso!A13="", "", Captura_Pegaso!A13) -> 46183 | F12: =IF(Captura_Pegaso!A13="", "", Captura_Pegaso!D13) -> Bacheo Toluca | G12: =IF(Captura_Pegaso!A13="", "", Captura_Pegaso!E13) -> Bidones | H12: =IF(Captura_Pegaso!A13="", "", Captura_Pegaso!H13) -> 100 | I12: =IF(Captura_Pegaso!A13="", "", SUMIFS(Captura_Obra!$F:$F, Captura_Obra!$A:$A, E12, Captura_Obra!$B:$B, F12, Captura_Obra!$D:$D, G12)) -> 100 | J12: =IF(Captura_Pegaso!A13="", "", H12 - I12) -> 0
A13: =IF(Captura_Pegaso!A14="", "", "Pegaso") -> Pegaso | B13: =IF(Captura_Pegaso!A14="", "", Captura_Pegaso!N14) -> CP-PAP-24-010 | C13: =IF(Captura_Pegaso!A14="", "", IFERROR(LOOKUP(2, 1/((Captura_Obra!$A$5:$A$1000=E13)*(Captura_Obra!$B$5:$B$1000=F13)*(Captura_Obra!$D$5:$D$1000=G13)), Captura_Obra!$N$5:$N$1000), "No Reportado")) -> No Reportado | D13: =IF(Captura_Pegaso!A14="", "", IF(J13=0, "✅ Cuadrado", IF(I13=0, "❌ Falta en Obra", "⚠️ Dif"))) -> ❌ Falta en Obra | E13: =IF(Captura_Pegaso!A14="", "", Captura_Pegaso!A14) -> 46184 | F13: =IF(Captura_Pegaso!A14="", "", Captura_Pegaso!D14) -> Planta Asfalto Pegaso | G13: =IF(Captura_Pegaso!A14="", "", Captura_Pegaso!E14) -> PayLoder | H13: =IF(Captura_Pegaso!A14="", "", Captura_Pegaso!H14) -> 238 | I13: =IF(Captura_Pegaso!A14="", "", SUMIFS(Captura_Obra!$F:$F, Captura_Obra!$A:$A, E13, Captura_Obra!$B:$B, F13, Captura_Obra!$D:$D, G13)) -> 0 | J13: =IF(Captura_Pegaso!A14="", "", H13 - I13) -> 238
A14: =IF(Captura_Pegaso!A15="", "", "Pegaso") -> Pegaso | B14: =IF(Captura_Pegaso!A15="", "", Captura_Pegaso!N15) -> CP-LT-24-011 | C14: =IF(Captura_Pegaso!A15="", "", IFERROR(LOOKUP(2, 1/((Captura_Obra!$A$5:$A$1000=E14)*(Captura_Obra!$B$5:$B$1000=F14)*(Captura_Obra!$D$5:$D$1000=G14)), Captura_Obra!$N$5:$N$1000), "No Reportado")) -> CO-LT-24-041 | D14: =IF(Captura_Pegaso!A15="", "", IF(J14=0, "✅ Cuadrado", IF(I14=0, "❌ Falta en Obra", "⚠️ Dif"))) -> ✅ Cuadrado | E14: =IF(Captura_Pegaso!A15="", "", Captura_Pegaso!A15) -> 46184 | F14: =IF(Captura_Pegaso!A15="", "", Captura_Pegaso!D15) -> Lerma - Tres Marías | G14: =IF(Captura_Pegaso!A15="", "", Captura_Pegaso!E15) -> Petrolizadora | H14: =IF(Captura_Pegaso!A15="", "", Captura_Pegaso!H15) -> 80 | I14: =IF(Captura_Pegaso!A15="", "", SUMIFS(Captura_Obra!$F:$F, Captura_Obra!$A:$A, E14, Captura_Obra!$B:$B, F14, Captura_Obra!$D:$D, G14)) -> 80 | J14: =IF(Captura_Pegaso!A15="", "", H14 - I14) -> 0
A15: =IF(Captura_Pegaso!A16="", "", "Pegaso") -> Pegaso | B15: =IF(Captura_Pegaso!A16="", "", Captura_Pegaso!N16) -> CP-LT-24-012 | C15: =IF(Captura_Pegaso!A16="", "", IFERROR(LOOKUP(2, 1/((Captura_Obra!$A$5:$A$1000=E15)*(Captura_Obra!$B$5:$B$1000=F15)*(Captura_Obra!$D$5:$D$1000=G15)), Captura_Obra!$N$5:$N$1000), "No Reportado")) -> CO-LT-24-042 | D15: =IF(Captura_Pegaso!A16="", "", IF(J15=0, "✅ Cuadrado", IF(I15=0, "❌ Falta en Obra", "⚠️ Dif"))) -> ✅ Cuadrado | E15: =IF(Captura_Pegaso!A16="", "", Captura_Pegaso!A16) -> 46184 | F15: =IF(Captura_Pegaso!A16="", "", Captura_Pegaso!D16) -> Lerma - Tres Marías | G15: =IF(Captura_Pegaso!A16="", "", Captura_Pegaso!E16) -> Compresor | H15: =IF(Captura_Pegaso!A16="", "", Captura_Pegaso!H16) -> 50 | I15: =IF(Captura_Pegaso!A16="", "", SUMIFS(Captura_Obra!$F:$F, Captura_Obra!$A:$A, E15, Captura_Obra!$B:$B, F15, Captura_Obra!$D:$D, G15)) -> 50 | J15: =IF(Captura_Pegaso!A16="", "", H15 - I15) -> 0
... A150: =IF(Captura_Pegaso!A151="", "", "Pegaso") | B150: =IF(Captura_Pegaso!A151="", "", Captura_Pegaso!N151) | C150: =IF(Captura_Pegaso!A151="", "", IFERROR(LOOKUP(2, 1/((Captura_Obra!$A$5:$A$1000=E150)*(Captura_Obra!$B$5:$B$1000=F150)*(Captura_Obra!$D$5:$D$1000=G150)), Captura_Obra!$N$5:$N$1000), "No Reportado")) | D150: =IF(Captura_Pegaso!A151="", "", IF(J150=0, "✅ Cuadrado", IF(I150=0, "❌ Falta en Obra", "⚠️ Dif"))) | E150: =IF(Captura_Pegaso!A151="", "", Captura_Pegaso!A151) | F150: =IF(Captura_Pegaso!A151="", "", Captura_Pegaso!D151) | G150: =IF(Captura_Pegaso!A151="", "", Captura_Pegaso!E151) | H150: =IF(Captura_Pegaso!A151="", "", Captura_Pegaso!H151) | I150: =IF(Captura_Pegaso!A151="", "", SUMIFS(Captura_Obra!$F:$F, Captura_Obra!$A:$A, E150, Captura_Obra!$B:$B, F150, Captura_Obra!$D:$D, G150)) | J150: =IF(Captura_Pegaso!A151="", "", H150 - I150)
A151: =IF(Captura_Marimba_M01!A5="", "", "Marimba") -> Marimba | B151: =IF(Captura_Marimba_M01!A5="", "", Captura_Marimba_M01!N5) -> CM-MT-24-001 | C151: =IF(Captura_Marimba_M01!A5="", "", IFERROR(LOOKUP(2, 1/((Captura_Obra!$A$5:$A$1000=E151)*(Captura_Obra!$B$5:$B$1000=F151)*(Captura_Obra!$D$5:$D$1000=G151)), Captura_Obra!$N$5:$N$1000), "No Reportado")) -> CO-MT-24-001 | D151: =IF(Captura_Marimba_M01!A5="", "", IF(J151=0, "✅ Cuadrado", IF(I151=0, "❌ Falta en Obra", "⚠️ Dif"))) -> ✅ Cuadrado | E151: =IF(Captura_Marimba_M01!A5="", "", Captura_Marimba_M01!A5) -> 46181 | F151: =IF(Captura_Marimba_M01!A5="", "", Captura_Marimba_M01!C5) -> México-Toluca | G151: =IF(Captura_Marimba_M01!A5="", "", Captura_Marimba_M01!D5) -> Neuomatico | H151: =IF(Captura_Marimba_M01!A5="", "", Captura_Marimba_M01!G5) -> 30 | I151: =IF(Captura_Marimba_M01!A5="", "", SUMIFS(Captura_Obra!$F:$F, Captura_Obra!$A:$A, E151, Captura_Obra!$B:$B, F151, Captura_Obra!$D:$D, G151)) -> 30 | J151: =IF(Captura_Marimba_M01!A5="", "", H151 - I151) -> 0
A152: =IF(Captura_Marimba_M01!A6="", "", "Marimba") -> Marimba | B152: =IF(Captura_Marimba_M01!A6="", "", Captura_Marimba_M01!N6) -> CM-MT-24-002 | C152: =IF(Captura_Marimba_M01!A6="", "", IFERROR(LOOKUP(2, 1/((Captura_Obra!$A$5:$A$1000=E152)*(Captura_Obra!$B$5:$B$1000=F152)*(Captura_Obra!$D$5:$D$1000=G152)), Captura_Obra!$N$5:$N$1000), "No Reportado")) -> CO-MT-24-002 | D152: =IF(Captura_Marimba_M01!A6="", "", IF(J152=0, "✅ Cuadrado", IF(I152=0, "❌ Falta en Obra", "⚠️ Dif"))) -> ✅ Cuadrado | E152: =IF(Captura_Marimba_M01!A6="", "", Captura_Marimba_M01!A6) -> 46181 | F152: =IF(Captura_Marimba_M01!A6="", "", Captura_Marimba_M01!C6) -> México-Toluca | G152: =IF(Captura_Marimba_M01!A6="", "", Captura_Marimba_M01!D6) -> Compactador | H152: =IF(Captura_Marimba_M01!A6="", "", Captura_Marimba_M01!G6) -> 32 | I152: =IF(Captura_Marimba_M01!A6="", "", SUMIFS(Captura_Obra!$F:$F, Captura_Obra!$A:$A, E152, Captura_Obra!$B:$B, F152, Captura_Obra!$D:$D, G152)) -> 32 | J152: =IF(Captura_Marimba_M01!A6="", "", H152 - I152) -> 0
A153: =IF(Captura_Marimba_M01!A7="", "", "Marimba") -> Marimba | B153: =IF(Captura_Marimba_M01!A7="", "", Captura_Marimba_M01!N7) -> CM-MT-24-003 | C153: =IF(Captura_Marimba_M01!A7="", "", IFERROR(LOOKUP(2, 1/((Captura_Obra!$A$5:$A$1000=E153)*(Captura_Obra!$B$5:$B$1000=F153)*(Captura_Obra!$D$5:$D$1000=G153)), Captura_Obra!$N$5:$N$1000), "No Reportado")) -> CO-MT-24-003 | D153: =IF(Captura_Marimba_M01!A7="", "", IF(J153=0, "✅ Cuadrado", IF(I153=0, "❌ Falta en Obra", "⚠️ Dif"))) -> ✅ Cuadrado | E153: =IF(Captura_Marimba_M01!A7="", "", Captura_Marimba_M01!A7) -> 46181 | F153: =IF(Captura_Marimba_M01!A7="", "", Captura_Marimba_M01!C7) -> México-Toluca | G153: =IF(Captura_Marimba_M01!A7="", "", Captura_Marimba_M01!D7) -> Perfiladora | H153: =IF(Captura_Marimba_M01!A7="", "", Captura_Marimba_M01!G7) -> 277 | I153: =IF(Captura_Marimba_M01!A7="", "", SUMIFS(Captura_Obra!$F:$F, Captura_Obra!$A:$A, E153, Captura_Obra!$B:$B, F153, Captura_Obra!$D:$D, G153)) -> 277 | J153: =IF(Captura_Marimba_M01!A7="", "", H153 - I153) -> 0
A154: =IF(Captura_Marimba_M01!A8="", "", "Marimba") -> Marimba | B154: =IF(Captura_Marimba_M01!A8="", "", Captura_Marimba_M01!N8) -> CM-MT-24-004 | C154: =IF(Captura_Marimba_M01!A8="", "", IFERROR(LOOKUP(2, 1/((Captura_Obra!$A$5:$A$1000=E154)*(Captura_Obra!$B$5:$B$1000=F154)*(Captura_Obra!$D$5:$D$1000=G154)), Captura_Obra!$N$5:$N$1000), "No Reportado")) -> CO-MT-24-004 | D154: =IF(Captura_Marimba_M01!A8="", "", IF(J154=0, "✅ Cuadrado", IF(I154=0, "❌ Falta en Obra", "⚠️ Dif"))) -> ✅ Cuadrado | E154: =IF(Captura_Marimba_M01!A8="", "", Captura_Marimba_M01!A8) -> 46181 | F154: =IF(Captura_Marimba_M01!A8="", "", Captura_Marimba_M01!C8) -> México-Toluca | G154: =IF(Captura_Marimba_M01!A8="", "", Captura_Marimba_M01!D8) -> Retroexcavadora | H154: =IF(Captura_Marimba_M01!A8="", "", Captura_Marimba_M01!G8) -> 30 | I154: =IF(Captura_Marimba_M01!A8="", "", SUMIFS(Captura_Obra!$F:$F, Captura_Obra!$A:$A, E154, Captura_Obra!$B:$B, F154, Captura_Obra!$D:$D, G154)) -> 30 | J154: =IF(Captura_Marimba_M01!A8="", "", H154 - I154) -> 0
A155: =IF(Captura_Marimba_M01!A9="", "", "Marimba") -> Marimba | B155: =IF(Captura_Marimba_M01!A9="", "", Captura_Marimba_M01!N9) -> CM-LT-24-005 | C155: =IF(Captura_Marimba_M01!A9="", "", IFERROR(LOOKUP(2, 1/((Captura_Obra!$A$5:$A$1000=E155)*(Captura_Obra!$B$5:$B$1000=F155)*(Captura_Obra!$D$5:$D$1000=G155)), Captura_Obra!$N$5:$N$1000), "No Reportado")) -> CO-LT-24-005 | D155: =IF(Captura_Marimba_M01!A9="", "", IF(J155=0, "✅ Cuadrado", IF(I155=0, "❌ Falta en Obra", "⚠️ Dif"))) -> ✅ Cuadrado | E155: =IF(Captura_Marimba_M01!A9="", "", Captura_Marimba_M01!A9) -> 46181 | F155: =IF(Captura_Marimba_M01!A9="", "", Captura_Marimba_M01!C9) -> Lerma - Tres Marías | G155: =IF(Captura_Marimba_M01!A9="", "", Captura_Marimba_M01!D9) -> Vogel | H155: =IF(Captura_Marimba_M01!A9="", "", Captura_Marimba_M01!G9) -> 97 | I155: =IF(Captura_Marimba_M01!A9="", "", SUMIFS(Captura_Obra!$F:$F, Captura_Obra!$A:$A, E155, Captura_Obra!$B:$B, F155, Captura_Obra!$D:$D, G155)) -> 97 | J155: =IF(Captura_Marimba_M01!A9="", "", H155 - I155) -> 0
A156: =IF(Captura_Marimba_M01!A10="", "", "Marimba") -> Marimba | B156: =IF(Captura_Marimba_M01!A10="", "", Captura_Marimba_M01!N10) -> CM-CL-24-006 | C156: =IF(Captura_Marimba_M01!A10="", "", IFERROR(LOOKUP(2, 1/((Captura_Obra!$A$5:$A$1000=E156)*(Captura_Obra!$B$5:$B$1000=F156)*(Captura_Obra!$D$5:$D$1000=G156)), Captura_Obra!$N$5:$N$1000), "No Reportado")) -> CO-CL-24-006 | D156: =IF(Captura_Marimba_M01!A10="", "", IF(J156=0, "✅ Cuadrado", IF(I156=0, "❌ Falta en Obra", "⚠️ Dif"))) -> ✅ Cuadrado | E156: =IF(Captura_Marimba_M01!A10="", "", Captura_Marimba_M01!A10) -> 46181 | F156: =IF(Captura_Marimba_M01!A10="", "", Captura_Marimba_M01!C10) -> Chamapa-Lechería | G156: =IF(Captura_Marimba_M01!A10="", "", Captura_Marimba_M01!D10) -> Perfiladora Wirgent | H156: =IF(Captura_Marimba_M01!A10="", "", Captura_Marimba_M01!G10) -> 198 | I156: =IF(Captura_Marimba_M01!A10="", "", SUMIFS(Captura_Obra!$F:$F, Captura_Obra!$A:$A, E156, Captura_Obra!$B:$B, F156, Captura_Obra!$D:$D, G156)) -> 198 | J156: =IF(Captura_Marimba_M01!A10="", "", H156 - I156) -> 0
A157: =IF(Captura_Marimba_M01!A11="", "", "Marimba") -> Marimba | B157: =IF(Captura_Marimba_M01!A11="", "", Captura_Marimba_M01!N11) -> CM-CL-24-007 | C157: =IF(Captura_Marimba_M01!A11="", "", IFERROR(LOOKUP(2, 1/((Captura_Obra!$A$5:$A$1000=E157)*(Captura_Obra!$B$5:$B$1000=F157)*(Captura_Obra!$D$5:$D$1000=G157)), Captura_Obra!$N$5:$N$1000), "No Reportado")) -> CO-CL-24-007 | D157: =IF(Captura_Marimba_M01!A11="", "", IF(J157=0, "✅ Cuadrado", IF(I157=0, "❌ Falta en Obra", "⚠️ Dif"))) -> ✅ Cuadrado | E157: =IF(Captura_Marimba_M01!A11="", "", Captura_Marimba_M01!A11) -> 46181 | F157: =IF(Captura_Marimba_M01!A11="", "", Captura_Marimba_M01!C11) -> Chamapa-Lechería | G157: =IF(Captura_Marimba_M01!A11="", "", Captura_Marimba_M01!D11) -> Maxilihgs | H157: =IF(Captura_Marimba_M01!A11="", "", Captura_Marimba_M01!G11) -> 10 | I157: =IF(Captura_Marimba_M01!A11="", "", SUMIFS(Captura_Obra!$F:$F, Captura_Obra!$A:$A, E157, Captura_Obra!$B:$B, F157, Captura_Obra!$D:$D, G157)) -> 10 | J157: =IF(Captura_Marimba_M01!A11="", "", H157 - I157) -> 0
A158: =IF(Captura_Marimba_M01!A12="", "", "Marimba") -> Marimba | B158: =IF(Captura_Marimba_M01!A12="", "", Captura_Marimba_M01!N12) -> CM-CL-24-008 | C158: =IF(Captura_Marimba_M01!A12="", "", IFERROR(LOOKUP(2, 1/((Captura_Obra!$A$5:$A$1000=E158)*(Captura_Obra!$B$5:$B$1000=F158)*(Captura_Obra!$D$5:$D$1000=G158)), Captura_Obra!$N$5:$N$1000), "No Reportado")) -> CO-CL-24-008 | D158: =IF(Captura_Marimba_M01!A12="", "", IF(J158=0, "✅ Cuadrado", IF(I158=0, "❌ Falta en Obra", "⚠️ Dif"))) -> ✅ Cuadrado | E158: =IF(Captura_Marimba_M01!A12="", "", Captura_Marimba_M01!A12) -> 46181 | F158: =IF(Captura_Marimba_M01!A12="", "", Captura_Marimba_M01!C12) -> Chamapa-Lechería | G158: =IF(Captura_Marimba_M01!A12="", "", Captura_Marimba_M01!D12) -> Neuomatico Dynapac | H158: =IF(Captura_Marimba_M01!A12="", "", Captura_Marimba_M01!G12) -> 27 | I158: =IF(Captura_Marimba_M01!A12="", "", SUMIFS(Captura_Obra!$F:$F, Captura_Obra!$A:$A, E158, Captura_Obra!$B:$B, F158, Captura_Obra!$D:$D, G158)) -> 27 | J158: =IF(Captura_Marimba_M01!A12="", "", H158 - I158) -> 0
A159: =IF(Captura_Marimba_M01!A13="", "", "Marimba") -> Marimba | B159: =IF(Captura_Marimba_M01!A13="", "", Captura_Marimba_M01!N13) -> CM-CL-24-009 | C159: =IF(Captura_Marimba_M01!A13="", "", IFERROR(LOOKUP(2, 1/((Captura_Obra!$A$5:$A$1000=E159)*(Captura_Obra!$B$5:$B$1000=F159)*(Captura_Obra!$D$5:$D$1000=G159)), Captura_Obra!$N$5:$N$1000), "No Reportado")) -> CO-CL-24-009 | D159: =IF(Captura_Marimba_M01!A13="", "", IF(J159=0, "✅ Cuadrado", IF(I159=0, "❌ Falta en Obra", "⚠️ Dif"))) -> ✅ Cuadrado | E159: =IF(Captura_Marimba_M01!A13="", "", Captura_Marimba_M01!A13) -> 46181 | F159: =IF(Captura_Marimba_M01!A13="", "", Captura_Marimba_M01!C13) -> Chamapa-Lechería | G159: =IF(Captura_Marimba_M01!A13="", "", Captura_Marimba_M01!D13) -> Compresor | H159: =IF(Captura_Marimba_M01!A13="", "", Captura_Marimba_M01!G13) -> 30 | I159: =IF(Captura_Marimba_M01!A13="", "", SUMIFS(Captura_Obra!$F:$F, Captura_Obra!$A:$A, E159, Captura_Obra!$B:$B, F159, Captura_Obra!$D:$D, G159)) -> 30 | J159: =IF(Captura_Marimba_M01!A13="", "", H159 - I159) -> 0
