Workbook

Sheet Dashboard
A1: DASHBOARD EJECUTIVO DE CONTROL DE COMBUSTIBLE | GRUPO TRUJANO
A3: FILTROS DEL DASHBOARD (Celdas en amarillo editables en Excel)
B4: Obra Seleccionada: | C4: México-Toluca
B5: Fecha Inicio (Lunes): | C5: 46181
B6: Precio Diésel ($/L): | C6: 28.3
A8: COMPARATIVA: SOLICITADO (PETICIONES) VS ENTREGADO EN OBRA
A9: Día | B9: Fecha | C9: Lts Solicitados | D9: Lts Recibidos Obra | E9: Dif. Litros (Obra-Sol) | F9: Costo Solicitado | G9: Costo Real Obra | H9: Dif. Costo (Real-Sol)
A10: Lunes | B10: =C$5 -> 46181 | C10: =IF(C$4="Todas", SUMIFS(Solicitudes!F:F, Solicitudes!C:C, B10), SUMIFS(Solicitudes!F:F, Solicitudes!B:B, C$4, Solicitudes!C:C, B10)) -> 640 | D10: =IF(C$4="Todas", SUMIFS(Captura_Obra!F:F, Captura_Obra!A:A, B10), SUMIFS(Captura_Obra!F:F, Captura_Obra!B:B, C$4, Captura_Obra!A:A, B10)) -> 369 | E10: =D10-C10 -> -271 | F10: =C10*C$6 -> 18112 | G10: =D10*C$6 -> 10442.7 | H10: =G10-F10 -> -7669.3
A11: Martes | B11: =B10+1 -> 46182 | C11: =IF(C$4="Todas", SUMIFS(Solicitudes!F:F, Solicitudes!C:C, B11), SUMIFS(Solicitudes!F:F, Solicitudes!B:B, C$4, Solicitudes!C:C, B11)) -> 0 | D11: =IF(C$4="Todas", SUMIFS(Captura_Obra!F:F, Captura_Obra!A:A, B11), SUMIFS(Captura_Obra!F:F, Captura_Obra!B:B, C$4, Captura_Obra!A:A, B11)) -> 0 | E11: =D11-C11 -> 0 | F11: =C11*C$6 -> 0 | G11: =D11*C$6 -> 0 | H11: =G11-F11 -> 0
A12: Miércoles | B12: =B11+1 -> 46183 | C12: =IF(C$4="Todas", SUMIFS(Solicitudes!F:F, Solicitudes!C:C, B12), SUMIFS(Solicitudes!F:F, Solicitudes!B:B, C$4, Solicitudes!C:C, B12)) -> 320 | D12: =IF(C$4="Todas", SUMIFS(Captura_Obra!F:F, Captura_Obra!A:A, B12), SUMIFS(Captura_Obra!F:F, Captura_Obra!B:B, C$4, Captura_Obra!A:A, B12)) -> 300 | E12: =D12-C12 -> -20 | F12: =C12*C$6 -> 9056 | G12: =D12*C$6 -> 8490 | H12: =G12-F12 -> -566
A13: Jueves | B13: =B12+1 -> 46184 | C13: =IF(C$4="Todas", SUMIFS(Solicitudes!F:F, Solicitudes!C:C, B13), SUMIFS(Solicitudes!F:F, Solicitudes!B:B, C$4, Solicitudes!C:C, B13)) -> 0 | D13: =IF(C$4="Todas", SUMIFS(Captura_Obra!F:F, Captura_Obra!A:A, B13), SUMIFS(Captura_Obra!F:F, Captura_Obra!B:B, C$4, Captura_Obra!A:A, B13)) -> 256 | E13: =D13-C13 -> 256 | F13: =C13*C$6 -> 0 | G13: =D13*C$6 -> 7244.8 | H13: =G13-F13 -> 7244.8
A14: Viernes | B14: =B13+1 -> 46185 | C14: =IF(C$4="Todas", SUMIFS(Solicitudes!F:F, Solicitudes!C:C, B14), SUMIFS(Solicitudes!F:F, Solicitudes!B:B, C$4, Solicitudes!C:C, B14)) -> 540 | D14: =IF(C$4="Todas", SUMIFS(Captura_Obra!F:F, Captura_Obra!A:A, B14), SUMIFS(Captura_Obra!F:F, Captura_Obra!B:B, C$4, Captura_Obra!A:A, B14)) -> 360 | E14: =D14-C14 -> -180 | F14: =C14*C$6 -> 15282 | G14: =D14*C$6 -> 10188 | H14: =G14-F14 -> -5094
A15: Sábado | B15: =B14+1 -> 46186 | C15: =IF(C$4="Todas", SUMIFS(Solicitudes!F:F, Solicitudes!C:C, B15), SUMIFS(Solicitudes!F:F, Solicitudes!B:B, C$4, Solicitudes!C:C, B15)) -> 0 | D15: =IF(C$4="Todas", SUMIFS(Captura_Obra!F:F, Captura_Obra!A:A, B15), SUMIFS(Captura_Obra!F:F, Captura_Obra!B:B, C$4, Captura_Obra!A:A, B15)) -> 0 | E15: =D15-C15 -> 0 | F15: =C15*C$6 -> 0 | G15: =D15*C$6 -> 0 | H15: =G15-F15 -> 0
A16: TOTAL SEMANAL | C16: =SUM(C10:C15) -> 1500 | D16: =SUM(D10:D15) -> 1285 | E16: =SUM(E10:E15) -> -215 | F16: =SUM(F10:F15) -> 42450 | G16: =SUM(G10:G15) -> 36365.5 | H16: =SUM(H10:H15) -> -6084.5
A19: CONCILIACIÓN FÍSICA Y DISCREPANCIAS (OBRA VS MARIMBA Y PEGASO)
A20: Día | B20: Fecha | C20: Obra Recibió (M) | D20: Marimba Despachó | E20: Dif. Marimba | F20: Obra Recibió (P) | G20: Pegaso Despachó | H20: Dif. Pegaso | I20: Dif. Total (L)
A21: Lunes | B21: =B10 -> 46181 | C21: =IF(C$4="Todas", SUMIFS(Captura_Obra!F:F, Captura_Obra!A:A, B21, Captura_Obra!C:C, "Marimba M-01"), SUMIFS(Captura_Obra!F:F, Captura_Obra!B:B, C$4, Captura_Obra!A:A, B21, Captura_Obra!C:C, "Marimba M-01")) -> 369 | D21: =IF(C$4="Todas", SUMIFS(Captura_Marimba_M01!G:G, Captura_Marimba_M01!A:A, B21, Captura_Marimba_M01!B:B, "Salida a Obra"), SUMIFS(Captura_Marimba_M01!G:G, Captura_Marimba_M01!C:C, C$4, Captura_Marimba_M01!A:A, B21, Captura_Marimba_M01!B:B, "Salida a Obra")) -> 369 | E21: =C21-D21 -> 0 | F21: =IF(C$4="Todas", SUMIFS(Captura_Obra!F:F, Captura_Obra!A:A, B21, Captura_Obra!C:C, "Pegaso Directo"), SUMIFS(Captura_Obra!F:F, Captura_Obra!B:B, C$4, Captura_Obra!A:A, B21, Captura_Obra!C:C, "Pegaso Directo")) -> 0 | G21: =IF(C$4="Todas", SUMIFS(Captura_Pegaso!H:H, Captura_Pegaso!A:A, B21, Captura_Pegaso!B:B, "Salida Directa Máquina"), SUMIFS(Captura_Pegaso!H:H, Captura_Pegaso!D:D, C$4, Captura_Pegaso!A:A, B21, Captura_Pegaso!B:B, "Salida Directa Máquina")) -> 0 | H21: =F21-G21 -> 0 | I21: =E21+H21 -> 0
A22: Martes | B22: =B11 -> 46182 | C22: =IF(C$4="Todas", SUMIFS(Captura_Obra!F:F, Captura_Obra!A:A, B22, Captura_Obra!C:C, "Marimba M-01"), SUMIFS(Captura_Obra!F:F, Captura_Obra!B:B, C$4, Captura_Obra!A:A, B22, Captura_Obra!C:C, "Marimba M-01")) -> 0 | D22: =IF(C$4="Todas", SUMIFS(Captura_Marimba_M01!G:G, Captura_Marimba_M01!A:A, B22, Captura_Marimba_M01!B:B, "Salida a Obra"), SUMIFS(Captura_Marimba_M01!G:G, Captura_Marimba_M01!C:C, C$4, Captura_Marimba_M01!A:A, B22, Captura_Marimba_M01!B:B, "Salida a Obra")) -> 0 | E22: =C22-D22 -> 0 | F22: =IF(C$4="Todas", SUMIFS(Captura_Obra!F:F, Captura_Obra!A:A, B22, Captura_Obra!C:C, "Pegaso Directo"), SUMIFS(Captura_Obra!F:F, Captura_Obra!B:B, C$4, Captura_Obra!A:A, B22, Captura_Obra!C:C, "Pegaso Directo")) -> 0 | G22: =IF(C$4="Todas", SUMIFS(Captura_Pegaso!H:H, Captura_Pegaso!A:A, B22, Captura_Pegaso!B:B, "Salida Directa Máquina"), SUMIFS(Captura_Pegaso!H:H, Captura_Pegaso!D:D, C$4, Captura_Pegaso!A:A, B22, Captura_Pegaso!B:B, "Salida Directa Máquina")) -> 0 | H22: =F22-G22 -> 0 | I22: =E22+H22 -> 0
A23: Miércoles | B23: =B12 -> 46183 | C23: =IF(C$4="Todas", SUMIFS(Captura_Obra!F:F, Captura_Obra!A:A, B23, Captura_Obra!C:C, "Marimba M-01"), SUMIFS(Captura_Obra!F:F, Captura_Obra!B:B, C$4, Captura_Obra!A:A, B23, Captura_Obra!C:C, "Marimba M-01")) -> 300 | D23: =IF(C$4="Todas", SUMIFS(Captura_Marimba_M01!G:G, Captura_Marimba_M01!A:A, B23, Captura_Marimba_M01!B:B, "Salida a Obra"), SUMIFS(Captura_Marimba_M01!G:G, Captura_Marimba_M01!C:C, C$4, Captura_Marimba_M01!A:A, B23, Captura_Marimba_M01!B:B, "Salida a Obra")) -> 300 | E23: =C23-D23 -> 0 | F23: =IF(C$4="Todas", SUMIFS(Captura_Obra!F:F, Captura_Obra!A:A, B23, Captura_Obra!C:C, "Pegaso Directo"), SUMIFS(Captura_Obra!F:F, Captura_Obra!B:B, C$4, Captura_Obra!A:A, B23, Captura_Obra!C:C, "Pegaso Directo")) -> 0 | G23: =IF(C$4="Todas", SUMIFS(Captura_Pegaso!H:H, Captura_Pegaso!A:A, B23, Captura_Pegaso!B:B, "Salida Directa Máquina"), SUMIFS(Captura_Pegaso!H:H, Captura_Pegaso!D:D, C$4, Captura_Pegaso!A:A, B23, Captura_Pegaso!B:B, "Salida Directa Máquina")) -> 0 | H23: =F23-G23 -> 0 | I23: =E23+H23 -> 0
A24: Jueves | B24: =B13 -> 46184 | C24: =IF(C$4="Todas", SUMIFS(Captura_Obra!F:F, Captura_Obra!A:A, B24, Captura_Obra!C:C, "Marimba M-01"), SUMIFS(Captura_Obra!F:F, Captura_Obra!B:B, C$4, Captura_Obra!A:A, B24, Captura_Obra!C:C, "Marimba M-01")) -> 256 | D24: =IF(C$4="Todas", SUMIFS(Captura_Marimba_M01!G:G, Captura_Marimba_M01!A:A, B24, Captura_Marimba_M01!B:B, "Salida a Obra"), SUMIFS(Captura_Marimba_M01!G:G, Captura_Marimba_M01!C:C, C$4, Captura_Marimba_M01!A:A, B24, Captura_Marimba_M01!B:B, "Salida a Obra")) -> 256 | E24: =C24-D24 -> 0 | F24: =IF(C$4="Todas", SUMIFS(Captura_Obra!F:F, Captura_Obra!A:A, B24, Captura_Obra!C:C, "Pegaso Directo"), SUMIFS(Captura_Obra!F:F, Captura_Obra!B:B, C$4, Captura_Obra!A:A, B24, Captura_Obra!C:C, "Pegaso Directo")) -> 0 | G24: =IF(C$4="Todas", SUMIFS(Captura_Pegaso!H:H, Captura_Pegaso!A:A, B24, Captura_Pegaso!B:B, "Salida Directa Máquina"), SUMIFS(Captura_Pegaso!H:H, Captura_Pegaso!D:D, C$4, Captura_Pegaso!A:A, B24, Captura_Pegaso!B:B, "Salida Directa Máquina")) -> 0 | H24: =F24-G24 -> 0 | I24: =E24+H24 -> 0
A25: Viernes | B25: =B14 -> 46185 | C25: =IF(C$4="Todas", SUMIFS(Captura_Obra!F:F, Captura_Obra!A:A, B25, Captura_Obra!C:C, "Marimba M-01"), SUMIFS(Captura_Obra!F:F, Captura_Obra!B:B, C$4, Captura_Obra!A:A, B25, Captura_Obra!C:C, "Marimba M-01")) -> 360 | D25: =IF(C$4="Todas", SUMIFS(Captura_Marimba_M01!G:G, Captura_Marimba_M01!A:A, B25, Captura_Marimba_M01!B:B, "Salida a Obra"), SUMIFS(Captura_Marimba_M01!G:G, Captura_Marimba_M01!C:C, C$4, Captura_Marimba_M01!A:A, B25, Captura_Marimba_M01!B:B, "Salida a Obra")) -> 360 | E25: =C25-D25 -> 0 | F25: =IF(C$4="Todas", SUMIFS(Captura_Obra!F:F, Captura_Obra!A:A, B25, Captura_Obra!C:C, "Pegaso Directo"), SUMIFS(Captura_Obra!F:F, Captura_Obra!B:B, C$4, Captura_Obra!A:A, B25, Captura_Obra!C:C, "Pegaso Directo")) -> 0 | G25: =IF(C$4="Todas", SUMIFS(Captura_Pegaso!H:H, Captura_Pegaso!A:A, B25, Captura_Pegaso!B:B, "Salida Directa Máquina"), SUMIFS(Captura_Pegaso!H:H, Captura_Pegaso!D:D, C$4, Captura_Pegaso!A:A, B25, Captura_Pegaso!B:B, "Salida Directa Máquina")) -> 0 | H25: =F25-G25 -> 0 | I25: =E25+H25 -> 0
A26: Sábado | B26: =B15 -> 46186 | C26: =IF(C$4="Todas", SUMIFS(Captura_Obra!F:F, Captura_Obra!A:A, B26, Captura_Obra!C:C, "Marimba M-01"), SUMIFS(Captura_Obra!F:F, Captura_Obra!B:B, C$4, Captura_Obra!A:A, B26, Captura_Obra!C:C, "Marimba M-01")) -> 0 | D26: =IF(C$4="Todas", SUMIFS(Captura_Marimba_M01!G:G, Captura_Marimba_M01!A:A, B26, Captura_Marimba_M01!B:B, "Salida a Obra"), SUMIFS(Captura_Marimba_M01!G:G, Captura_Marimba_M01!C:C, C$4, Captura_Marimba_M01!A:A, B26, Captura_Marimba_M01!B:B, "Salida a Obra")) -> 0 | E26: =C26-D26 -> 0 | F26: =IF(C$4="Todas", SUMIFS(Captura_Obra!F:F, Captura_Obra!A:A, B26, Captura_Obra!C:C, "Pegaso Directo"), SUMIFS(Captura_Obra!F:F, Captura_Obra!B:B, C$4, Captura_Obra!A:A, B26, Captura_Obra!C:C, "Pegaso Directo")) -> 0 | G26: =IF(C$4="Todas", SUMIFS(Captura_Pegaso!H:H, Captura_Pegaso!A:A, B26, Captura_Pegaso!B:B, "Salida Directa Máquina"), SUMIFS(Captura_Pegaso!H:H, Captura_Pegaso!D:D, C$4, Captura_Pegaso!A:A, B26, Captura_Pegaso!B:B, "Salida Directa Máquina")) -> 0 | H26: =F26-G26 -> 0 | I26: =E26+H26 -> 0
A27: TOTAL SEMANAL | C27: =SUM(C21:C26) -> 1285 | D27: =SUM(D21:D26) -> 1285 | E27: =SUM(E21:E26) -> 0 | F27: =SUM(F21:F26) -> 0 | G27: =SUM(G21:G26) -> 0 | H27: =SUM(H21:H26) -> 0 | I27: =SUM(I21:I26) -> 0

Sheet Resumen_Ejecutivo_Copia
B2: TABLAS DINAMICAS DE COSTOS Y FINANZAS
C5: Etiquetas de columna
C6: 1. Solicitud | E6: 2. Consumo Real | G6: 4. Facturas | I6: Total Cuenta de Costo Total | J6: Total Cuenta de Litros
B7: Etiquetas de fila | C7: Cuenta de Costo Total | D7: Cuenta de Litros | E7: Cuenta de Costo Total | F7: Cuenta de Litros | G7: Cuenta de Costo Total | H7: Cuenta de Litros
B8: 22 | E8: 6 | F8: 6 | I8: 6 | J8: 6
B9: 23 | E9: 12 | F9: 12 | I9: 12 | J9: 12
B10: 24 | C10: 70 | D10: 70 | E10: 107 | F10: 107 | I10: 177 | J10: 177
B11: 25 | C11: 67 | D11: 67 | E11: 109 | F11: 109 | G11: 15 | H11: 15 | I11: 191 | J11: 191
B12: Bacheo Toluca | C12: 9 | D12: 9 | E12: 8 | F12: 8 | I12: 17 | J12: 17
B13: Dragones | E13: 1 | F13: 1 | I13: 1 | J13: 1
B14: Jalisco | E14: 10 | F14: 10 | I14: 10 | J14: 10
B15: Lerma - Tres Marías | C15: 19 | D15: 19 | E15: 18 | F15: 18 | I15: 37 | J15: 37
B16: Maquinaria Pegaso | E16: 3 | F16: 3 | G16: 2 | H16: 2 | I16: 5 | J16: 5
B17: México-Toluca | C17: 39 | D17: 39 | E17: 60 | F17: 60 | G17: 5 | H17: 5 | I17: 104 | J17: 104
B18: Planta Asflato Huixquilucan | E18: 9 | F18: 9 | G18: 4 | H18: 4 | I18: 13 | J18: 13
B19: Transportes Pegaso | G19: 4 | H19: 4 | I19: 4 | J19: 4
B20: 26 | C20: 142 | D20: 142 | E20: 88 | F20: 88 | G20: 12 | H20: 12 | I20: 242 | J20: 242
B21: Bacheo Toluca | C21: 19 | D21: 19 | E21: 11 | F21: 11 | I21: 30 | J21: 30
B22: Dragones | E22: 2 | F22: 2 | I22: 2 | J22: 2
B23: Jalisco | E23: 11 | F23: 11 | I23: 11 | J23: 11
B24: Lerma - Tres Marías | C24: 60 | D24: 60 | E24: 16 | F24: 16 | I24: 76 | J24: 76
B25: Maquinaria Pegaso | E25: 7 | F25: 7 | I25: 7 | J25: 7
B26: México-Toluca | C26: 39 | D26: 39 | E26: 32 | F26: 32 | G26: 9 | H26: 9 | I26: 80 | J26: 80
B27: Planta Asfalto Pegaso | C27: 4 | D27: 4 | I27: 4 | J27: 4
B28: Planta Asflato Huixquilucan | C28: 20 | D28: 20 | E28: 9 | F28: 9 | G28: 1 | H28: 1 | I28: 30 | J28: 30
B29: Transportes Pegaso | G29: 2 | H29: 2 | I29: 2 | J29: 2
B30: 27 | C30: 104 | D30: 104 | E30: 30 | F30: 30 | I30: 134 | J30: 134
B31: Bacheo Toluca | C31: 26 | D31: 26 | E31: 1 | F31: 1 | I31: 27 | J31: 27
B32: Dragones | E32: 1 | F32: 1 | I32: 1 | J32: 1
B33: Lerma - Tres Marías | E33: 8 | F33: 8 | I33: 8 | J33: 8
B34: México-Toluca | C34: 53 | D34: 53 | E34: 11 | F34: 11 | I34: 64 | J34: 64
B35: Planta Asfalto Huixquilucan | C35: 25 | D35: 25 | I35: 25 | J35: 25
B36: Planta Asfalto Pegaso | E36: 2 | F36: 2 | I36: 2 | J36: 2
B37: Planta Asflato Huixquilucan | E37: 4 | F37: 4 | I37: 4 | J37: 4
B38: Providencia | E38: 3 | F38: 3 | I38: 3 | J38: 3
B39: Total general | C39: 383 | D39: 383 | E39: 352 | F39: 352 | G39: 27 | H39: 27 | I39: 762 | J39: 762

Sheet Dashboard_Copia
B2: TABLAS DINAMICAS DE OPERACION (VOLUMEN)
B5: Cuenta de Lts Operativos | C5: Etiquetas de columna
B6: Etiquetas de fila | C6: 1. Solicitud | D6: 2. Consumo Real | E6: 4. Facturas | F6: Total general
B7: 22 | D7: 6 | F7: 6
B8: Jalisco | D8: 6 | F8: 6
B9: 23 | D9: 12 | F9: 12
B10: Jalisco | D10: 12 | F10: 12
B11: 24 | C11: 70 | D11: 107 | F11: 177
B12: Bacheo Toluca | C12: 5 | D12: 2 | F12: 7
B13: Chamapa-Lechería | C13: 33 | D13: 50 | F13: 83
B14: Jalisco | D14: 3 | F14: 3
B15: Lerma - Tres Marías | C15: 14 | D15: 13 | F15: 27
B16: Maquinaria Pegaso | D16: 3 | F16: 3
B17: México-Toluca | C17: 18 | D17: 36 | F17: 54
B18: 25 | C18: 67 | D18: 109 | E18: 15 | F18: 191
B19: Bacheo Toluca | C19: 9 | D19: 8 | F19: 17
B20: Dragones | D20: 1 | F20: 1
B21: Jalisco | D21: 10 | F21: 10
B22: Lerma - Tres Marías | C22: 19 | D22: 18 | F22: 37
B23: Maquinaria Pegaso | D23: 3 | E23: 2 | F23: 5
B24: México-Toluca | C24: 39 | D24: 60 | E24: 5 | F24: 104
B25: Planta Asflato Huixquilucan | D25: 9 | E25: 4 | F25: 13
B26: Transportes Pegaso | E26: 4 | F26: 4
B27: 26 | C27: 142 | D27: 88 | E27: 12 | F27: 242
B28: Bacheo Toluca | C28: 19 | D28: 11 | F28: 30
B29: Dragones | D29: 2 | F29: 2
B30: Jalisco | D30: 11 | F30: 11
B31: Lerma - Tres Marías | C31: 60 | D31: 16 | F31: 76
B32: Maquinaria Pegaso | D32: 7 | F32: 7
B33: México-Toluca | C33: 39 | D33: 32 | E33: 9 | F33: 80
B34: Planta Asfalto Pegaso | C34: 4 | F34: 4
B35: Planta Asflato Huixquilucan | C35: 20 | D35: 9 | E35: 1 | F35: 30
B36: Transportes Pegaso | E36: 2 | F36: 2
B37: 27 | C37: 104 | D37: 30 | F37: 134
B38: Bacheo Toluca | C38: 26 | D38: 1 | F38: 27
B39: Dragones | D39: 1 | F39: 1
B40: Lerma - Tres Marías | D40: 8 | F40: 8
B41: México-Toluca | C41: 53 | D41: 11 | F41: 64
B42: Planta Asfalto Huixquilucan | C42: 25 | F42: 25
B43: Planta Asfalto Pegaso | D43: 2 | F43: 2
...

Sheet Base_Datos
A1: ID_TICKET | B1: SEMANA | C1: FECHA | D1: OBRA | E1: TIPO_REGISTRO | F1: EQUIPO_CONCEPTO | G1: LITROS | H1: PRECIO_UNITARIO | I1: COSTO_TOTAL | J1: CATEGORIA | K1: OBSERVACIONES
A2: =IF(LEFT(E2,1)="1","SOL",IF(LEFT(E2,1)="2","CO",IF(LEFT(E2,1)="3","ALM",IF(LEFT(E2,1)="4","FAC","TRX")))) & "-" & B2 & "-" & TEXT(COUNTIFS($E$2:$E2,E2,$B$2:$B2,B2),"000") -> SOL-26-001 | B2: 26 | C2: 38887 | D2: Planta Asflato Huixquilucan | E2: 1. Solicitud | F2: Maxilihgs | G2: 100 | H2: 27 | I2: 2700 | J2: DIESEL | K2: 27
A3: =IF(LEFT(E3,1)="1","SOL",IF(LEFT(E3,1)="2","CO",IF(LEFT(E3,1)="3","ALM",IF(LEFT(E3,1)="4","FAC","TRX")))) & "-" & B3 & "-" & TEXT(COUNTIFS($E$2:$E3,E3,$B$2:$B3,B3),"000") -> SOL-26-002 | B3: 26 | C3: 38887 | D3: Planta Asflato Huixquilucan | E3: 1. Solicitud | F3: Generador | G3: 200 | H3: 27 | I3: 5400 | J3: DIESEL | K3: 27
A4: =IF(LEFT(E4,1)="1","SOL",IF(LEFT(E4,1)="2","CO",IF(LEFT(E4,1)="3","ALM",IF(LEFT(E4,1)="4","FAC","TRX")))) & "-" & B4 & "-" & TEXT(COUNTIFS($E$2:$E4,E4,$B$2:$B4,B4),"000") -> SOL-26-003 | B4: 26 | C4: 38887 | D4: Planta Asflato Huixquilucan | E4: 1. Solicitud | F4: PayLoder | G4: 100 | H4: 27 | I4: 2700 | J4: DIESEL | K4: 27
A5: =IF(LEFT(E5,1)="1","SOL",IF(LEFT(E5,1)="2","CO",IF(LEFT(E5,1)="3","ALM",IF(LEFT(E5,1)="4","FAC","TRX")))) & "-" & B5 & "-" & TEXT(COUNTIFS($E$2:$E5,E5,$B$2:$B5,B5),"000") -> SOL-26-004 | B5: 26 | C5: 38887 | D5: Planta Asflato Huixquilucan | E5: 1. Solicitud | F5: Criba Roja | G5: 100 | H5: 27 | I5: 2700 | J5: DIESEL | K5: 27
A6: =IF(LEFT(E6,1)="1","SOL",IF(LEFT(E6,1)="2","CO",IF(LEFT(E6,1)="3","ALM",IF(LEFT(E6,1)="4","FAC","TRX")))) & "-" & B6 & "-" & TEXT(COUNTIFS($E$2:$E6,E6,$B$2:$B6,B6),"000") -> SOL-26-005 | B6: 26 | C6: 38887 | D6: Lerma - Tres Marías | E6: 1. Solicitud | F6: Retroexcavadora | G6: 80 | H6: 27 | I6: 2160 | J6: DIESEL | K6: 27
A7: =IF(LEFT(E7,1)="1","SOL",IF(LEFT(E7,1)="2","CO",IF(LEFT(E7,1)="3","ALM",IF(LEFT(E7,1)="4","FAC","TRX")))) & "-" & B7 & "-" & TEXT(COUNTIFS($E$2:$E7,E7,$B$2:$B7,B7),"000") -> SOL-26-006 | B7: 26 | C7: 38887 | D7: Lerma - Tres Marías | E7: 1. Solicitud | F7: Tandem Hamm | G7: 50 | H7: 27 | I7: 1350 | J7: DIESEL | K7: 27
A8: =IF(LEFT(E8,1)="1","SOL",IF(LEFT(E8,1)="2","CO",IF(LEFT(E8,1)="3","ALM",IF(LEFT(E8,1)="4","FAC","TRX")))) & "-" & B8 & "-" & TEXT(COUNTIFS($E$2:$E8,E8,$B$2:$B8,B8),"000") -> SOL-26-007 | B8: 26 | C8: 38887 | D8: Lerma - Tres Marías | E8: 1. Solicitud | F8: Neuomatico Dynapac | G8: 30 | H8: 27 | I8: 810 | J8: DIESEL | K8: 27
A9: =IF(LEFT(E9,1)="1","SOL",IF(LEFT(E9,1)="2","CO",IF(LEFT(E9,1)="3","ALM",IF(LEFT(E9,1)="4","FAC","TRX")))) & "-" & B9 & "-" & TEXT(COUNTIFS($E$2:$E9,E9,$B$2:$B9,B9),"000") -> SOL-26-008 | B9: 26 | C9: 38887 | D9: Lerma - Tres Marías | E9: 1. Solicitud | F9: Barredora | G9: 50 | H9: 27 | I9: 1350 | J9: DIESEL | K9: 27
A10: =IF(LEFT(E10,1)="1","SOL",IF(LEFT(E10,1)="2","CO",IF(LEFT(E10,1)="3","ALM",IF(LEFT(E10,1)="4","FAC","TRX")))) & "-" & B10 & "-" & TEXT(COUNTIFS($E$2:$E10,E10,$B$2:$B10,B10),"000") -> SOL-26-009 | B10: 26 | C10: 38887 | D10: Lerma - Tres Marías | E10: 1. Solicitud | F10: Pipa | G10: 50 | H10: 27 | I10: 1350 | J10: DIESEL | K10: 27
A11: =IF(LEFT(E11,1)="1","SOL",IF(LEFT(E11,1)="2","CO",IF(LEFT(E11,1)="3","ALM",IF(LEFT(E11,1)="4","FAC","TRX")))) & "-" & B11 & "-" & TEXT(COUNTIFS($E$2:$E11,E11,$B$2:$B11,B11),"000") -> SOL-26-010 | B11: 26 | C11: 38887 | D11: Lerma - Tres Marías | E11: 1. Solicitud | F11: Perfiladora | G11: 200 | H11: 27 | I11: 5400 | J11: DIESEL | K11: 27
A12: =IF(LEFT(E12,1)="1","SOL",IF(LEFT(E12,1)="2","CO",IF(LEFT(E12,1)="3","ALM",IF(LEFT(E12,1)="4","FAC","TRX")))) & "-" & B12 & "-" & TEXT(COUNTIFS($E$2:$E12,E12,$B$2:$B12,B12),"000") -> SOL-26-011 | B12: 26 | C12: 38887 | D12: Lerma - Tres Marías | E12: 1. Solicitud | F12: Vogel | G12: 130 | H12: 27 | I12: 3510 | J12: DIESEL | K12: 27
A13: =IF(LEFT(E13,1)="1","SOL",IF(LEFT(E13,1)="2","CO",IF(LEFT(E13,1)="3","ALM",IF(LEFT(E13,1)="4","FAC","TRX")))) & "-" & B13 & "-" & TEXT(COUNTIFS($E$2:$E13,E13,$B$2:$B13,B13),"000") -> SOL-26-012 | B13: 26 | C13: 38887 | D13: Lerma - Tres Marías | E13: 1. Solicitud | F13: Limpieza | G13: 20 | H13: 27 | I13: 540 | J13: DIESEL | K13: 27
... A15: =IF(LEFT(E15,1)="1","SOL",IF(LEFT(E15,1)="2","CO",IF(LEFT(E15,1)="3","ALM",IF(LEFT(E15,1)="4","FAC","TRX")))) & "-" & B15 & "-" & TEXT(COUNTIFS($E$2:$E15,E15,$B$2:$B15,B15),"000") -> SOL-26-014 | B15: 26 | C15: 38887 | D15: Lerma - Tres Marías | E15: 1. Solicitud | F15: Petrolizadora | G15: 80 | H15: 27 | I15: 2160 | J15: DIESEL | K15: 27
A16: =IF(LEFT(E16,1)="1","SOL",IF(LEFT(E16,1)="2","CO",IF(LEFT(E16,1)="3","ALM",IF(LEFT(E16,1)="4","FAC","TRX")))) & "-" & B16 & "-" & TEXT(COUNTIFS($E$2:$E16,E16,$B$2:$B16,B16),"000") -> CO-22-001 | B16: 22 | C16: 46168 | D16: Jalisco | E16: 2. Consumo Real | F16: (Captura_Jalisco) Motoconformadora Rentada | G16: 89 | H16: 27 | I16: 2403 | J16: DIESEL
A17: =IF(LEFT(E17,1)="1","SOL",IF(LEFT(E17,1)="2","CO",IF(LEFT(E17,1)="3","ALM",IF(LEFT(E17,1)="4","FAC","TRX")))) & "-" & B17 & "-" & TEXT(COUNTIFS($E$2:$E17,E17,$B$2:$B17,B17),"000") -> CO-22-002 | B17: 22 | C17: 46169 | D17: Jalisco | E17: 2. Consumo Real | F17: (Captura_Jalisco) Motoconformadora Rentada | G17: 89 | H17: 27 | I17: 2403 | J17: DIESEL
A18: =IF(LEFT(E18,1)="1","SOL",IF(LEFT(E18,1)="2","CO",IF(LEFT(E18,1)="3","ALM",IF(LEFT(E18,1)="4","FAC","TRX")))) & "-" & B18 & "-" & TEXT(COUNTIFS($E$2:$E18,E18,$B$2:$B18,B18),"000") -> CO-22-003 | B18: 22 | C18: 46171 | D18: Jalisco | E18: 2. Consumo Real | F18: (Captura_Jalisco) Motoconformadora Rentada | G18: 99 | H18: 27 | I18: 2673 | J18: DIESEL
A19: =IF(LEFT(E19,1)="1","SOL",IF(LEFT(E19,1)="2","CO",IF(LEFT(E19,1)="3","ALM",IF(LEFT(E19,1)="4","FAC","TRX")))) & "-" & B19 & "-" & TEXT(COUNTIFS($E$2:$E19,E19,$B$2:$B19,B19),"000") -> CO-22-004 | B19: 22 | C19: 46171 | D19: Jalisco | E19: 2. Consumo Real | F19: (Captura_Jalisco) Motoconformadora | G19: 99 | H19: 27 | I19: 2673 | J19: DIESEL
A20: =IF(LEFT(E20,1)="1","SOL",IF(LEFT(E20,1)="2","CO",IF(LEFT(E20,1)="3","ALM",IF(LEFT(E20,1)="4","FAC","TRX")))) & "-" & B20 & "-" & TEXT(COUNTIFS($E$2:$E20,E20,$B$2:$B20,B20),"000") -> CO-22-005 | B20: 22 | C20: 46172 | D20: Jalisco | E20: 2. Consumo Real | F20: (Captura_Jalisco) Motoconformadora Rentada | G20: 90 | H20: 27 | I20: 2430 | J20: DIESEL
A21: =IF(LEFT(E21,1)="1","SOL",IF(LEFT(E21,1)="2","CO",IF(LEFT(E21,1)="3","ALM",IF(LEFT(E21,1)="4","FAC","TRX")))) & "-" & B21 & "-" & TEXT(COUNTIFS($E$2:$E21,E21,$B$2:$B21,B21),"000") -> CO-22-006 | B21: 22 | C21: 46172 | D21: Jalisco | E21: 2. Consumo Real | F21: (Captura_Jalisco) Motoconformadora | G21: 90 | H21: 27 | I21: 2430 | J21: DIESEL
A22: =IF(LEFT(E22,1)="1","SOL",IF(LEFT(E22,1)="2","CO",IF(LEFT(E22,1)="3","ALM",IF(LEFT(E22,1)="4","FAC","TRX")))) & "-" & B22 & "-" & TEXT(COUNTIFS($E$2:$E22,E22,$B$2:$B22,B22),"000") -> CO-23-001 | B22: 23 | C22: 46174 | D22: Jalisco | E22: 2. Consumo Real | F22: (Captura_Jalisco) Retroexcavadora | G22: 50 | H22: 27 | I22: 1350 | J22: DIESEL
A23: =IF(LEFT(E23,1)="1","SOL",IF(LEFT(E23,1)="2","CO",IF(LEFT(E23,1)="3","ALM",IF(LEFT(E23,1)="4","FAC","TRX")))) & "-" & B23 & "-" & TEXT(COUNTIFS($E$2:$E23,E23,$B$2:$B23,B23),"000") -> CO-23-002 | B23: 23 | C23: 46175 | D23: Jalisco | E23: 2. Consumo Real | F23: (Captura_Jalisco) Motoconformadora Rentada | G23: 74 | H23: 27 | I23: 1998 | J23: DIESEL
A24: =IF(LEFT(E24,1)="1","SOL",IF(LEFT(E24,1)="2","CO",IF(LEFT(E24,1)="3","ALM",IF(LEFT(E24,1)="4","FAC","TRX")))) & "-" & B24 & "-" & TEXT(COUNTIFS($E$2:$E24,E24,$B$2:$B24,B24),"000") -> CO-23-003 | B24: 23 | C24: 46175 | D24: Jalisco | E24: 2. Consumo Real | F24: (Captura_Jalisco) Motoconformadora | G24: 80 | H24: 27 | I24: 2160 | J24: DIESEL
A25: =IF(LEFT(E25,1)="1","SOL",IF(LEFT(E25,1)="2","CO",IF(LEFT(E25,1)="3","ALM",IF(LEFT(E25,1)="4","FAC","TRX")))) & "-" & B25 & "-" & TEXT(COUNTIFS($E$2:$E25,E25,$B$2:$B25,B25),"000") -> CO-23-004 | B25: 23 | C25: 46175 | D25: Jalisco | E25: 2. Consumo Real | F25: (Captura_Jalisco) Vibro Compactador | G25: 40 | H25: 27 | I25: 1080 | J25: DIESEL
A26: =IF(LEFT(E26,1)="1","SOL",IF(LEFT(E26,1)="2","CO",IF(LEFT(E26,1)="3","ALM",IF(LEFT(E26,1)="4","FAC","TRX")))) & "-" & B26 & "-" & TEXT(COUNTIFS($E$2:$E26,E26,$B$2:$B26,B26),"000") -> CO-23-005 | B26: 23 | C26: 46177 | D26: Jalisco | E26: 2. Consumo Real | F26: (Captura_Jalisco) Motoconformadora Rentada | G26: 70 | H26: 27 | I26: 1890 | J26: DIESEL
A27: =IF(LEFT(E27,1)="1","SOL",IF(LEFT(E27,1)="2","CO",IF(LEFT(E27,1)="3","ALM",IF(LEFT(E27,1)="4","FAC","TRX")))) & "-" & B27 & "-" & TEXT(COUNTIFS($E$2:$E27,E27,$B$2:$B27,B27),"000") -> CO-23-006 | B27: 23 | C27: 46177 | D27: Jalisco | E27: 2. Consumo Real | F27: (Captura_Jalisco) Pipa | G27: 100 | H27: 27 | I27: 2700 | J27: DIESEL
... A33: =IF(LEFT(E33,1)="1","SOL",IF(LEFT(E33,1)="2","CO",IF(LEFT(E33,1)="3","ALM",IF(LEFT(E33,1)="4","FAC","TRX")))) & "-" & B33 & "-" & TEXT(COUNTIFS($E$2:$E33,E33,$B$2:$B33,B33),"000") -> CO-23-012 | B33: 23 | C33: 46179 | D33: Jalisco | E33: 2. Consumo Real | F33: (Captura_Jalisco) Retroexcavadora | G33: 40 | H33: 27 | I33: 1080 | J33: DIESEL
A34: =IF(LEFT(E34,1)="1","SOL",IF(LEFT(E34,1)="2","CO",IF(LEFT(E34,1)="3","ALM",IF(LEFT(E34,1)="4","FAC","TRX")))) & "-" & B34 & "-" & TEXT(COUNTIFS($E$2:$E34,E34,$B$2:$B34,B34),"000") -> SOL-24-001 | B34: 24 | C34: 46181 | D34: México-Toluca | E34: 1. Solicitud | F34: Vogel | G34: 200 | H34: 27 | I34: 5400 | J34: DIESEL | K34: 27
A35: =IF(LEFT(E35,1)="1","SOL",IF(LEFT(E35,1)="2","CO",IF(LEFT(E35,1)="3","ALM",IF(LEFT(E35,1)="4","FAC","TRX")))) & "-" & B35 & "-" & TEXT(COUNTIFS($E$2:$E35,E35,$B$2:$B35,B35),"000") -> SOL-24-002 | B35: 24 | C35: 46181 | D35: México-Toluca | E35: 1. Solicitud | F35: Perfiladora | G35: 300 | H35: 27 | I35: 8100 | J35: DIESEL | K35: 27
A36: =IF(LEFT(E36,1)="1","SOL",IF(LEFT(E36,1)="2","CO",IF(LEFT(E36,1)="3","ALM",IF(LEFT(E36,1)="4","FAC","TRX")))) & "-" & B36 & "-" & TEXT(COUNTIFS($E$2:$E36,E36,$B$2:$B36,B36),"000") -> SOL-24-003 | B36: 24 | C36: 46181 | D36: México-Toluca | E36: 1. Solicitud | F36: Retroexcavadora | G36: 30 | H36: 27 | I36: 810 | J36: DIESEL | K36: 27
A37: =IF(LEFT(E37,1)="1","SOL",IF(LEFT(E37,1)="2","CO",IF(LEFT(E37,1)="3","ALM",IF(LEFT(E37,1)="4","FAC","TRX")))) & "-" & B37 & "-" & TEXT(COUNTIFS($E$2:$E37,E37,$B$2:$B37,B37),"000") -> SOL-24-004 | B37: 24 | C37: 46181 | D37: México-Toluca | E37: 1. Solicitud | F37: Barredora | G37: 20 | H37: 27 | I37: 540 | J37: DIESEL | K37: 27
A38: =IF(LEFT(E38,1)="1","SOL",IF(LEFT(E38,1)="2","CO",IF(LEFT(E38,1)="3","ALM",IF(LEFT(E38,1)="4","FAC","TRX")))) & "-" & B38 & "-" & TEXT(COUNTIFS($E$2:$E38,E38,$B$2:$B38,B38),"000") -> SOL-24-005 | B38: 24 | C38: 46181 | D38: México-Toluca | E38: 1. Solicitud | F38: Neuomatico | G38: 30 | H38: 27 | I38: 810 | J38: DIESEL | K38: 27
A39: =IF(LEFT(E39,1)="1","SOL",IF(LEFT(E39,1)="2","CO",IF(LEFT(E39,1)="3","ALM",IF(LEFT(E39,1)="4","FAC","TRX")))) & "-" & B39 & "-" & TEXT(COUNTIFS($E$2:$E39,E39,$B$2:$B39,B39),"000") -> SOL-24-006 | B39: 24 | C39: 46181 | D39: México-Toluca | E39: 1. Solicitud | F39: Compactador | G39: 30 | H39: 27 | I39: 810 | J39: DIESEL | K39: 27
A40: =IF(LEFT(E40,1)="1","SOL",IF(LEFT(E40,1)="2","CO",IF(LEFT(E40,1)="3","ALM",IF(LEFT(E40,1)="4","FAC","TRX")))) & "-" & B40 & "-" & TEXT(COUNTIFS($E$2:$E40,E40,$B$2:$B40,B40),"000") -> SOL-24-007 | B40: 24 | C40: 46181 | D40: México-Toluca | E40: 1. Solicitud | F40: Limpieza | G40: 30 | H40: 27 | I40: 810 | J40: DIESEL | K40: 27
A41: =IF(LEFT(E41,1)="1","SOL",IF(LEFT(E41,1)="2","CO",IF(LEFT(E41,1)="3","ALM",IF(LEFT(E41,1)="4","FAC","TRX")))) & "-" & B41 & "-" & TEXT(COUNTIFS($E$2:$E41,E41,$B$2:$B41,B41),"000") -> SOL-24-008 | B41: 24 | C41: 46181 | D41: Lerma - Tres Marías | E41: 1. Solicitud | F41: Retroexcavadora | G41: 50 | H41: 27 | I41: 1350 | J41: DIESEL | K41: 27
A42: =IF(LEFT(E42,1)="1","SOL",IF(LEFT(E42,1)="2","CO",IF(LEFT(E42,1)="3","ALM",IF(LEFT(E42,1)="4","FAC","TRX")))) & "-" & B42 & "-" & TEXT(COUNTIFS($E$2:$E42,E42,$B$2:$B42,B42),"000") -> SOL-24-009 | B42: 24 | C42: 46181 | D42: Lerma - Tres Marías | E42: 1. Solicitud | F42: Neuomatico | G42: 50 | H42: 27 | I42: 1350 | J42: DIESEL | K42: 27
A43: =IF(LEFT(E43,1)="1","SOL",IF(LEFT(E43,1)="2","CO",IF(LEFT(E43,1)="3","ALM",IF(LEFT(E43,1)="4","FAC","TRX")))) & "-" & B43 & "-" & TEXT(COUNTIFS($E$2:$E43,E43,$B$2:$B43,B43),"000") -> SOL-24-010 | B43: 24 | C43: 46181 | D43: Lerma - Tres Marías | E43: 1. Solicitud | F43: Petrolizadora | G43: 60 | H43: 27 | I43: 1620 | J43: DIESEL | K43: 27
A44: =IF(LEFT(E44,1)="1","SOL",IF(LEFT(E44,1)="2","CO",IF(LEFT(E44,1)="3","ALM",IF(LEFT(E44,1)="4","FAC","TRX")))) & "-" & B44 & "-" & TEXT(COUNTIFS($E$2:$E44,E44,$B$2:$B44,B44),"000") -> SOL-24-011 | B44: 24 | C44: 46181 | D44: Chamapa-Lechería | E44: 1. Solicitud | F44: Perfiladora Wirgent | G44: 250 | H44: 27 | I44: 6750 | J44: DIESEL | K44: 27
A45: =IF(LEFT(E45,1)="1","SOL",IF(LEFT(E45,1)="2","CO",IF(LEFT(E45,1)="3","ALM",IF(LEFT(E45,1)="4","FAC","TRX")))) & "-" & B45 & "-" & TEXT(COUNTIFS($E$2:$E45,E45,$B$2:$B45,B45),"000") -> SOL-24-012 | B45: 24 | C45: 46181 | D45: Chamapa-Lechería | E45: 1. Solicitud | F45: Perfiladora Cat-PM | G45: 150 | H45: 27 | I45: 4050 | J45: DIESEL | K45: 27
... A57: =IF(LEFT(E57,1)="1","SOL",IF(LEFT(E57,1)="2","CO",IF(LEFT(E57,1)="3","ALM",IF(LEFT(E57,1)="4","FAC","TRX")))) & "-" & B57 & "-" & TEXT(COUNTIFS($E$2:$E57,E57,$B$2:$B57,B57),"000") -> SOL-24-024 | B57: 24 | C57: 46181 | D57: Chamapa-Lechería | E57: 1. Solicitud | F57: Rastrillador | G57: 10 | H57: 27 | I57: 270 | J57: DIESEL | K57: 27
...

Sheet Dashboard_Ejecutivo
B2: Peticiones por Día y Obra | G2: Salidas Marimba por Día y Obra | L2: Salidas Pegaso a Obra | Q2: Consumo Total en Obra | V2: Resumen Semanal por Obra
B4: Fecha | C4: Obra | D4: Litros Solicitados | E4: Costo Estimado ($) | G4: Fecha | H4: Obra | I4: Salida (L) | J4: Costo Surtido ($) | L4: Fecha | M4: Obra | N4: Salida (L) | O4: Costo Surtido ($) | Q4: Fecha | R4: Obra | S4: Litros Recibidos | T4: Costo Surtido ($) | V4: Obra | W4: Litros Recibidos | X4: Costo Surtido ($)
B5: 2026-06-07 | C5: Lerma - Tres Marías | D5: 160 | E5: 4528 | G5: 2026-06-08 | H5: Chamapa-Lechería | I5: 455 | J5: 12876.5 | L5: 2026-06-08 | M5: Bacheo Toluca | N5: 180 | O5: 5094 | Q5: 2026-06-08 | R5: Bacheo Toluca | S5: 100 | T5: 2830 | V5: Bacheo Toluca | W5: 200 | X5: 5660
B6: 2026-06-07 | C6: México-Toluca | D6: 640 | E6: 18112 | G6: 2026-06-08 | H6: Lerma - Tres Marías | I6: 97 | J6: 2745.1 | L6: 2026-06-08 | M6: Planta Asfalto Pegaso | N6: 409 | O6: 11574.7 | Q6: 2026-06-08 | R6: Chamapa-Lechería | S6: 455 | T6: 12876.5 | V6: Chamapa-Lechería | W6: 1693 | X6: 47911.9
B7: 2026-06-08 | C7: Bacheo Toluca | D7: 100 | E7: 2830 | G7: 2026-06-08 | H7: México-Toluca | I7: 369 | J7: 10442.7 | L7: 2026-06-09 | M7: Lerma - Tres Marías | N7: 180 | O7: 5094 | Q7: 2026-06-08 | R7: Lerma - Tres Marías | S7: 97 | T7: 2745.1 | V7: Lerma - Tres Marías | W7: 872 | X7: 24677.6
B8: 2026-06-08 | C8: Chamapa-Lechería | D8: 990 | E8: 28017 | G8: 2026-06-09 | H8: Chamapa-Lechería | I8: 736 | J8: 20828.8 | L8: 2026-06-10 | M8: Bacheo Toluca | N8: 100 | O8: 2830 | Q8: 2026-06-08 | R8: México-Toluca | S8: 369 | T8: 10442.7 | V8: México-Toluca | W8: 1285 | X8: 36365.5
B9: 2026-06-09 | C9: Bacheo Toluca | D9: 100 | E9: 2830 | G9: 2026-06-10 | H9: México-Toluca | I9: 300 | J9: 8490 | L9: 2026-06-11 | M9: Lerma - Tres Marías | N9: 595 | O9: 16838.5 | Q9: 2026-06-08 | R9: Planta Asfalto Pegaso | S9: 409 | T9: 11574.7 | V9: Planta Asfalto Pegaso | W9: 647 | X9: 18310.1
B10: 2026-06-09 | C10: Chamapa-Lechería | D10: 790 | E10: 22357 | G10: 2026-06-11 | H10: México-Toluca | I10: 256 | J10: 7244.8 | L10: 2026-06-11 | M10: Planta Asfalto Pegaso | N10: 238 | O10: 6735.4 | Q10: 2026-06-09 | R10: Chamapa-Lechería | S10: 736 | T10: 20828.8 | X10: =SUM(X5:X9) -> 132925.1
B11: 2026-06-09 | C11: Lerma - Tres Marías | D11: 210 | E11: 5943 | G11: 2026-06-12 | H11: Chamapa-Lechería | I11: 502 | J11: 14206.6 | L11: 2026-06-12 | M11: Bacheo Toluca | N11: 70 | O11: 1981 | Q11: 2026-06-09 | R11: Lerma - Tres Marías | S11: 180 | T11: 5094
B12: 2026-06-10 | C12: México-Toluca | D12: 320 | E12: 9056 | G12: 2026-06-12 | H12: México-Toluca | I12: 360 | J12: 10188 | Q12: 2026-06-10 | R12: Bacheo Toluca | S12: 100 | T12: 2830
B13: 2026-06-11 | C13: Bacheo Toluca | D13: 70 | E13: 1981 | Q13: 2026-06-10 | R13: México-Toluca | S13: 300 | T13: 8490
B14: 2026-06-11 | C14: Lerma - Tres Marías | D14: 460 | E14: 13018 | Q14: 2026-06-11 | R14: Lerma - Tres Marías | S14: 595 | T14: 16838.5
B15: 2026-06-12 | C15: Chamapa-Lechería | D15: 620 | E15: 17546 | Q15: 2026-06-11 | R15: México-Toluca | S15: 256 | T15: 7244.8
B16: 2026-06-12 | C16: México-Toluca | D16: 540 | E16: 15282 | Q16: 2026-06-11 | R16: Planta Asfalto Pegaso | S16: 238 | T16: 6735.4
Q17: 2026-06-12 | R17: Chamapa-Lechería | S17: 502 | T17: 14206.6
Q18: 2026-06-12 | R18: México-Toluca | S18: 360 | T18: 10188
B35: Costos por Día (Petición vs Surtido) | G35: Costos por Obra (Petición vs Surtido) | L35: Totales Generales por Día | Q35: Totales Generales por Obra | V35: Reporte de Discrepancias (Faltantes/Sobrantes)
B37: Fecha | C37: Costo Solicitado ($) | D37: Costo Surtido ($) | G37: Obra | H37: Costo Solicitado ($) | I37: Costo Surtido ($) | L37: Fecha | M37: Litros Totales | N37: Costo Total ($) | Q37: Obra | R37: Litros Totales | S37: Costo Total ($) | V37: Fecha | W37: Obra | X37: Litros Surtidos | Y37: Litros Recibidos | Z37: Discrepancia (L)
B38: 2026-06-07 | C38: 22640 | D38: 0 | G38: Bacheo Toluca | H38: 7641 | I38: 9905 | L38: 2026-06-08 | M38: 1510 | N38: 42733 | Q38: Bacheo Toluca | R38: 350 | S38: 9905 | V38: 2026-06-08 | W38: Bacheo Toluca | X38: 180 | Y38: 100 | Z38: 80
B39: 2026-06-08 | C39: 30847 | D39: 42733 | G39: Chamapa-Lechería | H39: 67920 | I39: 47911.9 | L39: 2026-06-09 | M39: 916 | N39: 25922.8 | Q39: Chamapa-Lechería | R39: 1693 | S39: 47911.9 | V39: 2026-06-12 | W39: Bacheo Toluca | X39: 70 | Y39: 0 | Z39: 70
B40: 2026-06-09 | C40: 31130 | D40: 25922.8 | G40: Lerma - Tres Marías | H40: 23489 | I40: 24677.6 | L40: 2026-06-10 | M40: 400 | N40: 11320 | Q40: Lerma - Tres Marías | R40: 872 | S40: 24677.6
B41: 2026-06-10 | C41: 9056 | D41: 11320 | G41: México-Toluca | H41: 42450 | I41: 36365.5 | L41: 2026-06-11 | M41: 1089 | N41: 30818.7 | Q41: México-Toluca | R41: 1285 | S41: 36365.5
B42: 2026-06-11 | C42: 14999 | D42: 30818.7 | G42: Planta Asfalto Pegaso | H42: 0 | I42: 18310.1 | L42: 2026-06-12 | M42: 932 | N42: 26375.6 | Q42: Planta Asfalto Pegaso | R42: 647 | S42: 18310.1
B43: 2026-06-12 | C43: 32828 | D43: 26375.6

Sheet Captura_Pegaso
A1: GC-COMB-001 | BITÁCORA DE INVENTARIO PEGASO
A2: Responsable: | C2: Semana: | F2: Fecha entrega: | H2: Tanque: | I2: Pegaso | J2: Costo por litro base:
A4: Fecha | B4: Tipo Movimiento | C4: Origen/Destino | D4: Obra | E4: Equipo | F4: Economico | G4: Entrada (L) | H4: Salida (L) | I4: Existencia Teórica | J4: Costo/L | K4: Importe | L4: Observaciones
A5: 46181 | B5: Salida Directa Máquina | C5: Otro | D5: Bacheo Toluca | E5: Bidones | F5: =VLOOKUP(TablaPegaso[[#This Row],[Equipo]],Catalogos!$I$4:$J$34,2,FALSE) -> BD-01 | H5: 100 | I5: =IF(ROW()=5,G5-H5,I4+G5-H5) -> -100 | J5: 28.3 | K5: =IFERROR((G5+H5)*J5,0) -> 2830
A6: 46181 | B6: Salida Directa Máquina | C6: Planta Asfalto Pegaso | D6: Planta Asfalto Pegaso | E6: Bidones | F6: =VLOOKUP(TablaPegaso[[#This Row],[Equipo]],Catalogos!$I$4:$J$34,2,FALSE) -> BD-01 | H6: 200 | I6: =IF(ROW()=5,G6-H6,I5+G6-H6) -> -300 | J6: 28.3 | K6: =IFERROR((G6+H6)*J6,0) -> 5660
A7: 46181 | B7: Salida Directa Máquina | C7: Planta Asfaltos | D7: Planta Asfalto Pegaso | E7: Bidones | F7: =VLOOKUP(TablaPegaso[[#This Row],[Equipo]],Catalogos!$I$4:$J$34,2,FALSE) -> BD-01 | H7: 209 | I7: =IF(ROW()=5,G7-H7,I6+G7-H7) -> -509 | J7: 28.3 | K7: =IFERROR((G7+H7)*J7,0) -> 5914.7
A8: 46181 | B8: Entrada | F8: =VLOOKUP(TablaPegaso[[#This Row],[Equipo]],Catalogos!$I$4:$J$34,2,FALSE) -> #N/A | G8: 2800 | I8: =IF(ROW()=5,G8-H8,I7+G8-H8) -> 2291 | J8: 28.3 | K8: =IFERROR((G8+H8)*J8,0) -> 79240
A9: 46181 | B9: Salida Directa Máquina | C9: Carga directa | D9: Bacheo Toluca | E9: Bidones | F9: =VLOOKUP(TablaPegaso[[#This Row],[Equipo]],Catalogos!$I$4:$J$34,2,FALSE) -> BD-01 | H9: 80 | I9: =IF(ROW()=5,G9-H9,I8+G9-H9) -> 2211 | J9: 28.3 | K9: =IFERROR((G9+H9)*J9,0) -> 2264
A10: 46182 | B10: Salida Directa Máquina | C10: Carga directa | D10: Lerma - Tres Marías | E10: Retroexcavadora | F10: =VLOOKUP(TablaPegaso[[#This Row],[Equipo]],Catalogos!$I$4:$J$34,2,FALSE) -> RT-01 | H10: 70 | I10: =IF(ROW()=5,G10-H10,I9+G10-H10) -> 2141 | J10: 28.3 | K10: =IFERROR((G10+H10)*J10,0) -> 1981
A11: 46182 | B11: Salida Directa Máquina | C11: Carga directa | D11: Lerma - Tres Marías | E11: Doble Rodillo | F11: =VLOOKUP(TablaPegaso[[#This Row],[Equipo]],Catalogos!$I$4:$J$34,2,FALSE) -> DR-01 | H11: 50 | I11: =IF(ROW()=5,G11-H11,I10+G11-H11) -> 2091 | J11: 28.3 | K11: =IFERROR((G11+H11)*J11,0) -> 1415
A12: 46182 | B12: Salida Directa Máquina | C12: Carga directa | D12: Lerma - Tres Marías | E12: Petrolizadora | F12: =VLOOKUP(TablaPegaso[[#This Row],[Equipo]],Catalogos!$I$4:$J$34,2,FALSE) -> PT-01 | H12: 60 | I12: =IF(ROW()=5,G12-H12,I11+G12-H12) -> 2031 | J12: 28.3 | K12: =IFERROR((G12+H12)*J12,0) -> 1698
A13: 46183 | B13: Salida Directa Máquina | C13: Otro | D13: Bacheo Toluca | E13: Bidones | F13: =VLOOKUP(TablaPegaso[[#This Row],[Equipo]],Catalogos!$I$4:$J$34,2,FALSE) -> BD-01 | H13: 100 | I13: =IF(ROW()=5,G13-H13,I12+G13-H13) -> 1931 | J13: 28.3 | K13: =IFERROR((G13+H13)*J13,0) -> 2830
A14: 46184 | B14: Salida Directa Máquina | C14: Planta Asfalto Pegaso | D14: Planta Asfalto Pegaso | E14: PayLoder | F14: =VLOOKUP(TablaPegaso[[#This Row],[Equipo]],Catalogos!$I$4:$J$34,2,FALSE) -> PL-01 | H14: 238 | I14: =IF(ROW()=5,G14-H14,I13+G14-H14) -> 1693 | J14: 28.3 | K14: =IFERROR((G14+H14)*J14,0) -> 6735.4
A15: 46184 | B15: Salida Directa Máquina | C15: Carga directa | D15: Lerma - Tres Marías | E15: Petrolizadora | F15: =VLOOKUP(TablaPegaso[[#This Row],[Equipo]],Catalogos!$I$4:$J$34,2,FALSE) -> PT-01 | H15: 80 | I15: =IF(ROW()=5,G15-H15,I14+G15-H15) -> 1613 | J15: 28.3 | K15: =IFERROR((G15+H15)*J15,0) -> 2264
A16: 46184 | B16: Salida Directa Máquina | C16: Carga directa | D16: Lerma - Tres Marías | E16: Compresor | F16: =VLOOKUP(TablaPegaso[[#This Row],[Equipo]],Catalogos!$I$4:$J$34,2,FALSE) -> CPR-01 | H16: 50 | I16: =IF(ROW()=5,G16-H16,I15+G16-H16) -> 1563 | J16: 28.3 | K16: =IFERROR((G16+H16)*J16,0) -> 1415
A17: 46184 | B17: Salida Directa Máquina | C17: Carga directa | D17: Lerma - Tres Marías | E17: Retroexcavadora | F17: =VLOOKUP(TablaPegaso[[#This Row],[Equipo]],Catalogos!$I$4:$J$34,2,FALSE) -> RT-01 | H17: 70 | I17: =IF(ROW()=5,G17-H17,I16+G17-H17) -> 1493 | J17: 28.3 | K17: =IFERROR((G17+H17)*J17,0) -> 1981
A18: 46184 | B18: Salida Directa Máquina | C18: Carga directa | D18: Lerma - Tres Marías | E18: Camion de Impacto | F18: =VLOOKUP(TablaPegaso[[#This Row],[Equipo]],Catalogos!$I$4:$J$34,2,FALSE) -> CI-01 | H18: 80 | I18: =IF(ROW()=5,G18-H18,I17+G18-H18) -> 1413 | J18: 28.3 | K18: =IFERROR((G18+H18)*J18,0) -> 2264
A19: 46184 | B19: Salida Directa Máquina | C19: Carga directa | D19: Lerma - Tres Marías | E19: Vogel | F19: =VLOOKUP(TablaPegaso[[#This Row],[Equipo]],Catalogos!$I$4:$J$34,2,FALSE) -> VG-01 | H19: 185 | I19: =IF(ROW()=5,G19-H19,I18+G19-H19) -> 1228 | J19: 28.3 | K19: =IFERROR((G19+H19)*J19,0) -> 5235.5
A20: 46184 | B20: Salida Directa Máquina | C20: Carga directa | D20: Lerma - Tres Marías | E20: Doble Rodillo | F20: =VLOOKUP(TablaPegaso[[#This Row],[Equipo]],Catalogos!$I$4:$J$34,2,FALSE) -> DR-01 | H20: 50 | I20: =IF(ROW()=5,G20-H20,I19+G20-H20) -> 1178 | J20: 28.3 | K20: =IFERROR((G20+H20)*J20,0) -> 1415
... A23: 46185 | B23: Salida Directa Máquina | C23: Carga directa | D23: Bacheo Toluca | E23: Barredora Broce | F23: =VLOOKUP(TablaPegaso[[#This Row],[Equipo]],Catalogos!$I$4:$J$34,2,FALSE) -> BR-02 | H23: 70 | I23: =IF(ROW()=5,G23-H23,I22+G23-H23) -> 1028 | J23: 28.3 | K23: =IFERROR((G23+H23)*J23,0) -> 1981
F24: =VLOOKUP(TablaPegaso[[#This Row],[Equipo]],Catalogos!$I$4:$J$34,2,FALSE) -> #N/A | I24: =IF(ROW()=5,G24-H24,I23+G24-H24) -> 1028 | K24: =IFERROR((G24+H24)*J24,0) -> 0
F25: =VLOOKUP(TablaPegaso[[#This Row],[Equipo]],Catalogos!$I$4:$J$34,2,FALSE) -> #N/A | I25: =IF(ROW()=5,G25-H25,I24+G25-H25) -> 1028 | K25: =IFERROR((G25+H25)*J25,0) -> 0
F26: =VLOOKUP(TablaPegaso[[#This Row],[Equipo]],Catalogos!$I$4:$J$34,2,FALSE) -> #N/A | I26: =IF(ROW()=5,G26-H26,I25+G26-H26) -> 1028 | K26: =IFERROR((G26+H26)*J26,0) -> 0
F27: =VLOOKUP(TablaPegaso[[#This Row],[Equipo]],Catalogos!$I$4:$J$34,2,FALSE) -> #N/A | I27: =IF(ROW()=5,G27-H27,I26+G27-H27) -> 1028 | K27: =IFERROR((G27+H27)*J27,0) -> 0
F28: =VLOOKUP(TablaPegaso[[#This Row],[Equipo]],Catalogos!$I$4:$J$34,2,FALSE) -> #N/A | I28: =IF(ROW()=5,G28-H28,I27+G28-H28) -> 1028 | K28: =IFERROR((G28+H28)*J28,0) -> 0
F29: =VLOOKUP(TablaPegaso[[#This Row],[Equipo]],Catalogos!$I$4:$J$34,2,FALSE) -> #N/A | I29: =IF(ROW()=5,G29-H29,I28+G29-H29) -> 1028 | K29: =IFERROR((G29+H29)*J29,0) -> 0
F30: =VLOOKUP(TablaPegaso[[#This Row],[Equipo]],Catalogos!$I$4:$J$34,2,FALSE) -> #N/A | I30: =IF(ROW()=5,G30-H30,I29+G30-H30) -> 1028 | K30: =IFERROR((G30+H30)*J30,0) -> 0
F31: =VLOOKUP(TablaPegaso[[#This Row],[Equipo]],Catalogos!$I$4:$J$34,2,FALSE) -> #N/A | I31: =IF(ROW()=5,G31-H31,I30+G31-H31) -> 1028 | K31: =IFERROR((G31+H31)*J31,0) -> 0
F32: =VLOOKUP(TablaPegaso[[#This Row],[Equipo]],Catalogos!$I$4:$J$34,2,FALSE) -> #N/A | I32: =IF(ROW()=5,G32-H32,I31+G32-H32) -> 1028 | K32: =IFERROR((G32+H32)*J32,0) -> 0
F33: =VLOOKUP(TablaPegaso[[#This Row],[Equipo]],Catalogos!$I$4:$J$34,2,FALSE) -> #N/A | I33: =IF(ROW()=5,G33-H33,I32+G33-H33) -> 1028 | K33: =IFERROR((G33+H33)*J33,0) -> 0
F34: =VLOOKUP(TablaPegaso[[#This Row],[Equipo]],Catalogos!$I$4:$J$34,2,FALSE) -> #N/A | I34: =IF(ROW()=5,G34-H34,I33+G34-H34) -> 1028 | K34: =IFERROR((G34+H34)*J34,0) -> 0
F35: =VLOOKUP(TablaPegaso[[#This Row],[Equipo]],Catalogos!$I$4:$J$34,2,FALSE) -> #N/A | I35: =IF(ROW()=5,G35-H35,I34+G35-H35) -> 1028 | K35: =IFERROR((G35+H35)*J35,0) -> 0
... F206: =VLOOKUP(TablaPegaso[[#This Row],[Equipo]],Catalogos!$I$4:$J$34,2,FALSE) -> #N/A | I206: =IF(ROW()=5,G206-H206,I205+G206-H206) -> 1028 | K206: =IFERROR((G206+H206)*J206,0) -> 0

Sheet Captura_Marimba_M01
A1: GC-COMB-002 | BITÁCORA DE SUMINISTRO DE MARIMBA M-01
A2: Operador: | C2: Semana: | E2: Fecha entrega: | G2: Marimba: | H2: M-01 | I2: Costo/L base:
A4: Fecha | B4: Movimiento | C4: Origen/Obra | D4: Equipo | E4: Económico | F4: Entrada (L) | G4: Salida (L) | H4: Existencia Teórica | I4: Costo/L | J4: Importe | K4: Firma/Validación | L4: Observaciones
A5: 46181 | B5: Salida a Obra | C5: México-Toluca | D5: Neuomatico | E5: =VLOOKUP(TablaMarimba[[#This Row],[Equipo]],Catalogos!$I$4:$J$34,2,FALSE) -> NM-01 | F5: 0 | G5: 30 | H5: =IF(ROW()=5,F5-G5,H4+F5-G5) -> -30 | I5: 28.3 | J5: =IFERROR((F5+G5)*I5,0) -> 849
A6: 46181 | B6: Salida a Obra | C6: México-Toluca | D6: Compactador | E6: =VLOOKUP(TablaMarimba[[#This Row],[Equipo]],Catalogos!$I$4:$J$34,2,FALSE) -> CP-01 | G6: 32 | H6: =IF(ROW()=5,F6-G6,H5+F6-G6) -> -62 | I6: 28.3 | J6: =IFERROR((F6+G6)*I6,0) -> 905.6
A7: 46181 | B7: Salida a Obra | C7: México-Toluca | D7: Perfiladora | E7: =VLOOKUP(TablaMarimba[[#This Row],[Equipo]],Catalogos!$I$4:$J$34,2,FALSE) -> PR-01 | G7: 277 | H7: =IF(ROW()=5,F7-G7,H6+F7-G7) -> -339 | I7: 28.3 | J7: =IFERROR((F7+G7)*I7,0) -> 7839.1
A8: 46181 | B8: Salida a Obra | C8: México-Toluca | D8: Retroexcavadora | E8: =VLOOKUP(TablaMarimba[[#This Row],[Equipo]],Catalogos!$I$4:$J$34,2,FALSE) -> RT-01 | G8: 30 | H8: =IF(ROW()=5,F8-G8,H7+F8-G8) -> -369 | I8: 28.3 | J8: =IFERROR((F8+G8)*I8,0) -> 849
A9: 46181 | B9: Salida a Obra | C9: Lerma - Tres Marías | D9: Vogel | E9: =VLOOKUP(TablaMarimba[[#This Row],[Equipo]],Catalogos!$I$4:$J$34,2,FALSE) -> VG-01 | G9: 97 | H9: =IF(ROW()=5,F9-G9,H8+F9-G9) -> -466 | I9: 28.3 | J9: =IFERROR((F9+G9)*I9,0) -> 2745.1
A10: 46181 | B10: Salida a Obra | C10: Chamapa-Lechería | D10: Perfiladora Wirgent | E10: =VLOOKUP(TablaMarimba[[#This Row],[Equipo]],Catalogos!$I$4:$J$34,2,FALSE) -> PR-02 | G10: 198 | H10: =IF(ROW()=5,F10-G10,H9+F10-G10) -> -664 | I10: 28.3 | J10: =IFERROR((F10+G10)*I10,0) -> 5603.4
A11: 46181 | B11: Salida a Obra | C11: Chamapa-Lechería | D11: Maxilihgs | E11: =VLOOKUP(TablaMarimba[[#This Row],[Equipo]],Catalogos!$I$4:$J$34,2,FALSE) -> MX-01 | G11: 10 | H11: =IF(ROW()=5,F11-G11,H10+F11-G11) -> -674 | I11: 28.3 | J11: =IFERROR((F11+G11)*I11,0) -> 283
A12: 46181 | B12: Salida a Obra | C12: Chamapa-Lechería | D12: Neuomatico Dynapac | E12: =VLOOKUP(TablaMarimba[[#This Row],[Equipo]],Catalogos!$I$4:$J$34,2,FALSE) -> NM-02 | G12: 27 | H12: =IF(ROW()=5,F12-G12,H11+F12-G12) -> -701 | I12: 28.3 | J12: =IFERROR((F12+G12)*I12,0) -> 764.1
A13: 46181 | B13: Salida a Obra | C13: Chamapa-Lechería | D13: Compresor | E13: =VLOOKUP(TablaMarimba[[#This Row],[Equipo]],Catalogos!$I$4:$J$34,2,FALSE) -> CPR-01 | G13: 30 | H13: =IF(ROW()=5,F13-G13,H12+F13-G13) -> -731 | I13: 28.3 | J13: =IFERROR((F13+G13)*I13,0) -> 849
A14: 46181 | B14: Salida a Obra | C14: Chamapa-Lechería | D14: Retroexcavadora Jonh Deere | E14: =VLOOKUP(TablaMarimba[[#This Row],[Equipo]],Catalogos!$I$4:$J$34,2,FALSE) -> RT-02 | G14: 40 | H14: =IF(ROW()=5,F14-G14,H13+F14-G14) -> -771 | I14: 28.3 | J14: =IFERROR((F14+G14)*I14,0) -> 1132
A15: 46181 | B15: Salida a Obra | C15: Chamapa-Lechería | D15: Vogele Guion | E15: =VLOOKUP(TablaMarimba[[#This Row],[Equipo]],Catalogos!$I$4:$J$34,2,FALSE) -> VG-02 | G15: 120 | H15: =IF(ROW()=5,F15-G15,H14+F15-G15) -> -891 | I15: 28.3 | J15: =IFERROR((F15+G15)*I15,0) -> 3396
A16: 46181 | B16: Salida a Obra | C16: Chamapa-Lechería | D16: Petrolizadora Elton | E16: =VLOOKUP(TablaMarimba[[#This Row],[Equipo]],Catalogos!$I$4:$J$34,2,FALSE) -> PT-02 | G16: 30 | H16: =IF(ROW()=5,F16-G16,H15+F16-G16) -> -921 | I16: 28.3 | J16: =IFERROR((F16+G16)*I16,0) -> 849
A17: 46182 | B17: Salida a Obra | C17: Chamapa-Lechería | D17: Barredora Broce | E17: =VLOOKUP(TablaMarimba[[#This Row],[Equipo]],Catalogos!$I$4:$J$34,2,FALSE) -> BR-02 | G17: 30 | H17: =IF(ROW()=5,F17-G17,H16+F17-G17) -> -951 | I17: 28.3 | J17: =IFERROR((F17+G17)*I17,0) -> 849
... A42: 46185 | B42: Salida a Obra | C42: Chamapa-Lechería | D42: Petrolizadora Elton | E42: =VLOOKUP(TablaMarimba[[#This Row],[Equipo]],Catalogos!$I$4:$J$34,2,FALSE) -> PT-02 | G42: 40 | H42: =IF(ROW()=5,F42-G42,H41+F42-G42) -> -2515 | I42: 28.3 | J42: =IFERROR((F42+G42)*I42,0) -> 1132
A43: 46185 | B43: Salida a Obra | C43: Chamapa-Lechería | D43: Perfiladora Wirgent | E43: =VLOOKUP(TablaMarimba[[#This Row],[Equipo]],Catalogos!$I$4:$J$34,2,FALSE) -> PR-02 | G43: 200 | H43: =IF(ROW()=5,F43-G43,H42+F43-G43) -> -2715 | I43: 28.3 | J43: =IFERROR((F43+G43)*I43,0) -> 5660 | N43: =SUM(G5:G48) -> 3075
A44: 46185 | B44: Salida a Obra | C44: México-Toluca | D44: Barredora | E44: =VLOOKUP(TablaMarimba[[#This Row],[Equipo]],Catalogos!$I$4:$J$34,2,FALSE) -> BR-01 | G44: 20 | H44: =IF(ROW()=5,F44-G44,H43+F44-G44) -> -2735 | I44: 28.3 | J44: =IFERROR((F44+G44)*I44,0) -> 566
A45: 46185 | B45: Salida a Obra | C45: México-Toluca | D45: Neuomatico | E45: =VLOOKUP(TablaMarimba[[#This Row],[Equipo]],Catalogos!$I$4:$J$34,2,FALSE) -> NM-01 | G45: 30 | H45: =IF(ROW()=5,F45-G45,H44+F45-G45) -> -2765 | I45: 28.3 | J45: =IFERROR((F45+G45)*I45,0) -> 849
A46: 46185 | B46: Salida a Obra | C46: México-Toluca | D46: Maxilihgs | E46: =VLOOKUP(TablaMarimba[[#This Row],[Equipo]],Catalogos!$I$4:$J$34,2,FALSE) -> MX-01 | G46: 20 | H46: =IF(ROW()=5,F46-G46,H45+F46-G46) -> -2785 | I46: 28.3 | J46: =IFERROR((F46+G46)*I46,0) -> 566
A47: 46185 | B47: Salida a Obra | C47: México-Toluca | D47: Compactador | E47: =VLOOKUP(TablaMarimba[[#This Row],[Equipo]],Catalogos!$I$4:$J$34,2,FALSE) -> CP-01 | G47: 40 | H47: =IF(ROW()=5,F47-G47,H46+F47-G47) -> -2825 | I47: 28.3 | J47: =IFERROR((F47+G47)*I47,0) -> 1132
A48: 46185 | B48: Salida a Obra | C48: México-Toluca | D48: Perfiladora | E48: =VLOOKUP(TablaMarimba[[#This Row],[Equipo]],Catalogos!$I$4:$J$34,2,FALSE) -> PR-01 | G48: 250 | H48: =IF(ROW()=5,F48-G48,H47+F48-G48) -> -3075 | I48: 28.3 | J48: =IFERROR((F48+G48)*I48,0) -> 7075
E49: =VLOOKUP(TablaMarimba[[#This Row],[Equipo]],Catalogos!$I$4:$J$34,2,FALSE) -> #N/A | H49: =IF(ROW()=5,F49-G49,H48+F49-G49) -> -3075 | I49: 28.3 | J49: =IFERROR((F49+G49)*I49,0) -> 0
E50: =VLOOKUP(TablaMarimba[[#This Row],[Equipo]],Catalogos!$I$4:$J$34,2,FALSE) -> #N/A | H50: =IF(ROW()=5,F50-G50,H49+F50-G50) -> -3075 | I50: 28.3 | J50: =IFERROR((F50+G50)*I50,0) -> 0
E51: =VLOOKUP(TablaMarimba[[#This Row],[Equipo]],Catalogos!$I$4:$J$34,2,FALSE) -> #N/A | H51: =IF(ROW()=5,F51-G51,H50+F51-G51) -> -3075 | I51: 28.3 | J51: =IFERROR((F51+G51)*I51,0) -> 0
E52: =VLOOKUP(TablaMarimba[[#This Row],[Equipo]],Catalogos!$I$4:$J$34,2,FALSE) -> #N/A | H52: =IF(ROW()=5,F52-G52,H51+F52-G52) -> -3075 | I52: 28.3 | J52: =IFERROR((F52+G52)*I52,0) -> 0
E53: =VLOOKUP(TablaMarimba[[#This Row],[Equipo]],Catalogos!$I$4:$J$34,2,FALSE) -> #N/A | H53: =IF(ROW()=5,F53-G53,H52+F53-G53) -> -3075 | I53: 28.3 | J53: =IFERROR((F53+G53)*I53,0) -> 0
E54: =VLOOKUP(TablaMarimba[[#This Row],[Equipo]],Catalogos!$I$4:$J$34,2,FALSE) -> #N/A | H54: =IF(ROW()=5,F54-G54,H53+F54-G54) -> -3075 | I54: 28.3 | J54: =IFERROR((F54+G54)*I54,0) -> 0
E55: =VLOOKUP(TablaMarimba[[#This Row],[Equipo]],Catalogos!$I$4:$J$34,2,FALSE) -> #N/A | H55: =IF(ROW()=5,F55-G55,H54+F55-G55) -> -3075 | I55: 28.3 | J55: =IFERROR((F55+G55)*I55,0) -> 0
E56: =VLOOKUP(TablaMarimba[[#This Row],[Equipo]],Catalogos!$I$4:$J$34,2,FALSE) -> #N/A | H56: =IF(ROW()=5,F56-G56,H55+F56-G56) -> -3075 | I56: 28.3 | J56: =IFERROR((F56+G56)*I56,0) -> 0
E57: =VLOOKUP(TablaMarimba[[#This Row],[Equipo]],Catalogos!$I$4:$J$34,2,FALSE) -> #N/A | H57: =IF(ROW()=5,F57-G57,H56+F57-G57) -> -3075 | I57: 28.3 | J57: =IFERROR((F57+G57)*I57,0) -> 0
E58: =VLOOKUP(TablaMarimba[[#This Row],[Equipo]],Catalogos!$I$4:$J$34,2,FALSE) -> #N/A | H58: =IF(ROW()=5,F58-G58,H57+F58-G58) -> -3075 | I58: 28.3 | J58: =IFERROR((F58+G58)*I58,0) -> 0
E59: =VLOOKUP(TablaMarimba[[#This Row],[Equipo]],Catalogos!$I$4:$J$34,2,FALSE) -> #N/A | H59: =IF(ROW()=5,F59-G59,H58+F59-G59) -> -3075 | I59: 28.3 | J59: =IFERROR((F59+G59)*I59,0) -> 0
E60: =VLOOKUP(TablaMarimba[[#This Row],[Equipo]],Catalogos!$I$4:$J$34,2,FALSE) -> #N/A | H60: =IF(ROW()=5,F60-G60,H59+F60-G60) -> -3075 | I60: 28.3 | J60: =IFERROR((F60+G60)*I60,0) -> 0
... E204: =VLOOKUP(TablaMarimba[[#This Row],[Equipo]],Catalogos!$I$4:$J$34,2,FALSE) -> #N/A | H204: =IF(ROW()=5,F204-G204,H203+F204-G204) -> -3075 | I204: 28.3 | J204: =IFERROR((F204+G204)*I204,0) -> 0

Sheet Solicitudes
A1: GC-COMB-003 | BITÁCORA DE SOLICITUDES DE COMBUSTIBLE DE OBRA
A2: Ingeniero: | C2: Semana: | E2: Fecha entrega: | G2: Obra: | I2: Costo/L base:
A4: Fecha de Solicitud | B4: Obra | C4: Fecha de Trabajo | D4: Equipo | E4: Económico | F4: Litros Solicitados | G4: Costo/L | H4: Importe | I4: Solicitante | J4: Incidencia | K4: Observaciones
A5: 46180 | B5: México-Toluca | C5: 46181 | D5: Vogel | E5: =VLOOKUP(TablaObra5[[#This Row],[Equipo]],Catalogos!$I$3:$J$34,2,FALSE) -> VG-01 | F5: 200 | G5: 28.3 | H5: =IFERROR(F5*G5,0) -> 5660 | I5: =VLOOKUP(TablaObra5[[#This Row],[Obra]],Catalogos!$B$3:$C$8,2,FALSE) -> Samuel Ortega
A6: 46180 | B6: México-Toluca | C6: 46181 | D6: Perfiladora | E6: =VLOOKUP(TablaObra5[[#This Row],[Equipo]],Catalogos!$I$3:$J$34,2,FALSE) -> PR-01 | F6: 300 | G6: 28.3 | H6: =IFERROR(F6*G6,0) -> 8490 | I6: =VLOOKUP(TablaObra5[[#This Row],[Obra]],Catalogos!$B$3:$C$8,2,FALSE) -> Samuel Ortega
A7: 46180 | B7: México-Toluca | C7: 46181 | D7: Retroexcavadora | E7: =VLOOKUP(TablaObra5[[#This Row],[Equipo]],Catalogos!$I$3:$J$34,2,FALSE) -> RT-01 | F7: 30 | G7: 28.3 | H7: =IFERROR(F7*G7,0) -> 849 | I7: =VLOOKUP(TablaObra5[[#This Row],[Obra]],Catalogos!$B$3:$C$8,2,FALSE) -> Samuel Ortega
A8: 46180 | B8: México-Toluca | C8: 46181 | D8: Barredora | E8: =VLOOKUP(TablaObra5[[#This Row],[Equipo]],Catalogos!$I$3:$J$34,2,FALSE) -> BR-01 | F8: 20 | G8: 28.3 | H8: =IFERROR(F8*G8,0) -> 566 | I8: =VLOOKUP(TablaObra5[[#This Row],[Obra]],Catalogos!$B$3:$C$8,2,FALSE) -> Samuel Ortega
A9: 46180 | B9: México-Toluca | C9: 46181 | D9: Neuomatico | E9: =VLOOKUP(TablaObra5[[#This Row],[Equipo]],Catalogos!$I$3:$J$34,2,FALSE) -> NM-01 | F9: 30 | G9: 28.3 | H9: =IFERROR(F9*G9,0) -> 849 | I9: =VLOOKUP(TablaObra5[[#This Row],[Obra]],Catalogos!$B$3:$C$8,2,FALSE) -> Samuel Ortega
A10: 46180 | B10: México-Toluca | C10: 46181 | D10: Compactador | E10: =VLOOKUP(TablaObra5[[#This Row],[Equipo]],Catalogos!$I$3:$J$34,2,FALSE) -> CP-01 | F10: 30 | G10: 28.3 | H10: =IFERROR(F10*G10,0) -> 849 | I10: =VLOOKUP(TablaObra5[[#This Row],[Obra]],Catalogos!$B$3:$C$8,2,FALSE) -> Samuel Ortega
A11: 46180 | B11: México-Toluca | C11: 46181 | D11: Limpieza | E11: =VLOOKUP(TablaObra5[[#This Row],[Equipo]],Catalogos!$I$3:$J$34,2,FALSE) -> LP-01 | F11: 30 | G11: 28.3 | H11: =IFERROR(F11*G11,0) -> 849 | I11: =VLOOKUP(TablaObra5[[#This Row],[Obra]],Catalogos!$B$3:$C$8,2,FALSE) -> Samuel Ortega
A12: 46180 | B12: Lerma - Tres Marías | C12: 46181 | D12: Retroexcavadora | E12: =VLOOKUP(TablaObra5[[#This Row],[Equipo]],Catalogos!$I$3:$J$34,2,FALSE) -> RT-01 | F12: 50 | G12: 28.3 | H12: =IFERROR(F12*G12,0) -> 1415 | I12: =VLOOKUP(TablaObra5[[#This Row],[Obra]],Catalogos!$B$3:$C$8,2,FALSE) -> Apolinar
A13: 46180 | B13: Lerma - Tres Marías | C13: 46181 | D13: Neuomatico | E13: =VLOOKUP(TablaObra5[[#This Row],[Equipo]],Catalogos!$I$3:$J$34,2,FALSE) -> NM-01 | F13: 50 | G13: 28.3 | H13: =IFERROR(F13*G13,0) -> 1415 | I13: =VLOOKUP(TablaObra5[[#This Row],[Obra]],Catalogos!$B$3:$C$8,2,FALSE) -> Apolinar
A14: 46180 | B14: Lerma - Tres Marías | C14: 46181 | D14: Petrolizadora | E14: =VLOOKUP(TablaObra5[[#This Row],[Equipo]],Catalogos!$I$3:$J$34,2,FALSE) -> PT-01 | F14: 60 | G14: 28.3 | H14: =IFERROR(F14*G14,0) -> 1698 | I14: =VLOOKUP(TablaObra5[[#This Row],[Obra]],Catalogos!$B$3:$C$8,2,FALSE) -> Apolinar
A15: 46181 | B15: Bacheo Toluca | D15: Retroexcavadora | E15: =VLOOKUP(TablaObra5[[#This Row],[Equipo]],Catalogos!$I$3:$J$34,2,FALSE) -> RT-01 | F15: 100 | G15: 28.3 | H15: =IFERROR(F15*G15,0) -> 2830 | I15: =VLOOKUP(TablaObra5[[#This Row],[Obra]],Catalogos!$B$3:$C$8,2,FALSE) -> Diego Carreola
A16: 46181 | B16: Chamapa-Lechería | C16: 46181 | D16: Perfiladora Wirgent | E16: =VLOOKUP(TablaObra5[[#This Row],[Equipo]],Catalogos!$I$3:$J$34,2,FALSE) -> PR-02 | F16: 250 | G16: 28.3 | H16: =IFERROR(F16*G16,0) -> 7075 | I16: =VLOOKUP(TablaObra5[[#This Row],[Obra]],Catalogos!$B$3:$C$8,2,FALSE) -> Francisco Javier
A17: 46181 | B17: Chamapa-Lechería | C17: 46181 | D17: Perfiladora Cat-PM | E17: =VLOOKUP(TablaObra5[[#This Row],[Equipo]],Catalogos!$I$3:$J$34,2,FALSE) -> PR-03 | F17: 150 | G17: 28.3 | H17: =IFERROR(F17*G17,0) -> 4245 | I17: =VLOOKUP(TablaObra5[[#This Row],[Obra]],Catalogos!$B$3:$C$8,2,FALSE) -> Francisco Javier
A18: 46181 | B18: Chamapa-Lechería | C18: 46181 | D18: Barredora Broce | E18: =VLOOKUP(TablaObra5[[#This Row],[Equipo]],Catalogos!$I$3:$J$34,2,FALSE) -> BR-02 | F18: 40 | G18: 28.3 | H18: =IFERROR(F18*G18,0) -> 1132 | I18: =VLOOKUP(TablaObra5[[#This Row],[Obra]],Catalogos!$B$3:$C$8,2,FALSE) -> Francisco Javier
A19: 46181 | B19: Chamapa-Lechería | C19: 46181 | D19: Retroexcavadora Jonh Deere | E19: =VLOOKUP(TablaObra5[[#This Row],[Equipo]],Catalogos!$I$3:$J$34,2,FALSE) -> RT-02 | F19: 60 | G19: 28.3 | H19: =IFERROR(F19*G19,0) -> 1698 | I19: =VLOOKUP(TablaObra5[[#This Row],[Obra]],Catalogos!$B$3:$C$8,2,FALSE) -> Francisco Javier
A20: 46181 | B20: Chamapa-Lechería | C20: 46181 | D20: Buggy Trasnfer | E20: =VLOOKUP(TablaObra5[[#This Row],[Equipo]],Catalogos!$I$3:$J$34,2,FALSE) -> BG-01 | F20: 100 | G20: 28.3 | H20: =IFERROR(F20*G20,0) -> 2830 | I20: =VLOOKUP(TablaObra5[[#This Row],[Obra]],Catalogos!$B$3:$C$8,2,FALSE) -> Francisco Javier
A21: 46181 | B21: Chamapa-Lechería | C21: 46181 | D21: Vogele Guion | E21: =VLOOKUP(TablaObra5[[#This Row],[Equipo]],Catalogos!$I$3:$J$34,2,FALSE) -> VG-02 | F21: 100 | G21: 28.3 | H21: =IFERROR(F21*G21,0) -> 2830 | I21: =VLOOKUP(TablaObra5[[#This Row],[Obra]],Catalogos!$B$3:$C$8,2,FALSE) -> Francisco Javier
A22: 46181 | B22: Chamapa-Lechería | C22: 46181 | D22: Limpieza | E22: =VLOOKUP(TablaObra5[[#This Row],[Equipo]],Catalogos!$I$3:$J$34,2,FALSE) -> LP-01 | F22: 20 | G22: 28.3 | H22: =IFERROR(F22*G22,0) -> 566 | I22: =VLOOKUP(TablaObra5[[#This Row],[Obra]],Catalogos!$B$3:$C$8,2,FALSE) -> Francisco Javier
A23: 46181 | B23: Chamapa-Lechería | C23: 46181 | D23: Tandem Hamm | E23: =VLOOKUP(TablaObra5[[#This Row],[Equipo]],Catalogos!$I$3:$J$34,2,FALSE) -> TD-01 | F23: 50 | G23: 28.3 | H23: =IFERROR(F23*G23,0) -> 1415 | I23: =VLOOKUP(TablaObra5[[#This Row],[Obra]],Catalogos!$B$3:$C$8,2,FALSE) -> Francisco Javier
A24: 46181 | B24: Chamapa-Lechería | C24: 46181 | D24: Neuomatico Dynapac | E24: =VLOOKUP(TablaObra5[[#This Row],[Equipo]],Catalogos!$I$3:$J$34,2,FALSE) -> NM-02 | F24: 50 | G24: 28.3 | H24: =IFERROR(F24*G24,0) -> 1415 | I24: =VLOOKUP(TablaObra5[[#This Row],[Obra]],Catalogos!$B$3:$C$8,2,FALSE) -> Francisco Javier
A25: 46181 | B25: Chamapa-Lechería | C25: 46181 | D25: Petrolizadora Elton | E25: =VLOOKUP(TablaObra5[[#This Row],[Equipo]],Catalogos!$I$3:$J$34,2,FALSE) -> PT-02 | F25: 50 | G25: 28.3 | H25: =IFERROR(F25*G25,0) -> 1415 | I25: =VLOOKUP(TablaObra5[[#This Row],[Obra]],Catalogos!$B$3:$C$8,2,FALSE) -> Francisco Javier
A26: 46181 | B26: Chamapa-Lechería | C26: 46181 | D26: Camion de Impacto | E26: =VLOOKUP(TablaObra5[[#This Row],[Equipo]],Catalogos!$I$3:$J$34,2,FALSE) -> CI-01 | F26: 20 | G26: 28.3 | H26: =IFERROR(F26*G26,0) -> 566 | I26: =VLOOKUP(TablaObra5[[#This Row],[Obra]],Catalogos!$B$3:$C$8,2,FALSE) -> Francisco Javier
A27: 46181 | B27: Chamapa-Lechería | C27: 46181 | D27: Maxilihgs | E27: =VLOOKUP(TablaObra5[[#This Row],[Equipo]],Catalogos!$I$3:$J$34,2,FALSE) -> MX-01 | F27: 50 | G27: 28.3 | H27: =IFERROR(F27*G27,0) -> 1415 | I27: =VLOOKUP(TablaObra5[[#This Row],[Obra]],Catalogos!$B$3:$C$8,2,FALSE) -> Francisco Javier
... A40: 46182 | B40: Chamapa-Lechería | C40: 46182 | D40: Compresor | E40: =VLOOKUP(TablaObra5[[#This Row],[Equipo]],Catalogos!$I$3:$J$34,2,FALSE) -> CPR-01 | F40: 30 | G40: 28.3 | H40: =IFERROR(F40*G40,0) -> 849 | I40: =VLOOKUP(TablaObra5[[#This Row],[Obra]],Catalogos!$B$3:$C$8,2,FALSE) -> Francisco Javier
A41: 46182 | B41: Lerma - Tres Marías | C41: 46182 | D41: Retroexcavadora | E41: =VLOOKUP(TablaObra5[[#This Row],[Equipo]],Catalogos!$I$3:$J$34,2,FALSE) -> RT-01 | F41: 50 | G41: 28.3 | H41: =IFERROR(F41*G41,0) -> 1415 | I41: =VLOOKUP(TablaObra5[[#This Row],[Obra]],Catalogos!$B$3:$C$8,2,FALSE) -> Apolinar | K41: Segunda solicitud, el dia 7/06/2026, no se relizo la carga
A42: 46182 | B42: Lerma - Tres Marías | C42: 46182 | D42: Neuomatico | E42: =VLOOKUP(TablaObra5[[#This Row],[Equipo]],Catalogos!$I$3:$J$34,2,FALSE) -> NM-01 | F42: 50 | G42: 28.3 | H42: =IFERROR(F42*G42,0) -> 1415 | I42: =VLOOKUP(TablaObra5[[#This Row],[Obra]],Catalogos!$B$3:$C$8,2,FALSE) -> Apolinar
A43: 46182 | B43: Lerma - Tres Marías | C43: 46182 | D43: Petrolizadora | E43: =VLOOKUP(TablaObra5[[#This Row],[Equipo]],Catalogos!$I$3:$J$34,2,FALSE) -> PT-01 | F43: 60 | G43: 28.3 | H43: =IFERROR(F43*G43,0) -> 1698 | I43: =VLOOKUP(TablaObra5[[#This Row],[Obra]],Catalogos!$B$3:$C$8,2,FALSE) -> Apolinar
A44: 46182 | B44: Lerma - Tres Marías | C44: 46182 | D44: Doble Rodillo | E44: =VLOOKUP(TablaObra5[[#This Row],[Equipo]],Catalogos!$I$3:$J$34,2,FALSE) -> DR-01 | F44: 50 | G44: 28.3 | H44: =IFERROR(F44*G44,0) -> 1415 | I44: =VLOOKUP(TablaObra5[[#This Row],[Obra]],Catalogos!$B$3:$C$8,2,FALSE) -> Apolinar
A45: 46182 | B45: Bacheo Toluca | D45: Retroexcavadora | E45: =VLOOKUP(TablaObra5[[#This Row],[Equipo]],Catalogos!$I$3:$J$34,2,FALSE) -> RT-01 | F45: 100 | G45: 28.3 | H45: =IFERROR(F45*G45,0) -> 2830 | I45: =VLOOKUP(TablaObra5[[#This Row],[Obra]],Catalogos!$B$3:$C$8,2,FALSE) -> Diego Carreola
A46: 46183 | B46: México-Toluca | C46: 46183 | D46: Perfiladora | E46: =VLOOKUP(TablaObra5[[#This Row],[Equipo]],Catalogos!$I$3:$J$34,2,FALSE) -> PR-01 | F46: 250 | G46: 28.3 | H46: =IFERROR(F46*G46,0) -> 7075 | I46: =VLOOKUP(TablaObra5[[#This Row],[Obra]],Catalogos!$B$3:$C$8,2,FALSE) -> Samuel Ortega
A47: 46183 | B47: México-Toluca | C47: 46183 | D47: Retroexcavadora | E47: =VLOOKUP(TablaObra5[[#This Row],[Equipo]],Catalogos!$I$3:$J$34,2,FALSE) -> RT-01 | F47: 30 | G47: 28.3 | H47: =IFERROR(F47*G47,0) -> 849 | I47: =VLOOKUP(TablaObra5[[#This Row],[Obra]],Catalogos!$B$3:$C$8,2,FALSE) -> Samuel Ortega
A48: 46183 | B48: México-Toluca | C48: 46183 | D48: Barredora | E48: =VLOOKUP(TablaObra5[[#This Row],[Equipo]],Catalogos!$I$3:$J$34,2,FALSE) -> BR-01 | F48: 20 | G48: 28.3 | H48: =IFERROR(F48*G48,0) -> 566 | I48: =VLOOKUP(TablaObra5[[#This Row],[Obra]],Catalogos!$B$3:$C$8,2,FALSE) -> Samuel Ortega
A49: 46183 | B49: México-Toluca | C49: 46183 | D49: Maxilihgs | E49: =VLOOKUP(TablaObra5[[#This Row],[Equipo]],Catalogos!$I$3:$J$34,2,FALSE) -> MX-01 | F49: 20 | G49: 28.3 | H49: =IFERROR(F49*G49,0) -> 566 | I49: =VLOOKUP(TablaObra5[[#This Row],[Obra]],Catalogos!$B$3:$C$8,2,FALSE) -> Samuel Ortega
A50: 46184 | B50: Lerma - Tres Marías | C50: 46184 | D50: Petrolizadora | E50: =VLOOKUP(TablaObra5[[#This Row],[Equipo]],Catalogos!$I$3:$J$34,2,FALSE) -> PT-01 | F50: 80 | G50: 28.3 | H50: =IFERROR(F50*G50,0) -> 2264 | I50: =VLOOKUP(TablaObra5[[#This Row],[Obra]],Catalogos!$B$3:$C$8,2,FALSE) -> Apolinar
