Workbook

Sheet FRESADO
A1: SEM | B1: NO | C1: FOLIO | D1: FECHA | E1: VIAJES | F1: MATERIAL | G1: PLACAS | H1: CAPACIDAD | I1: UNIDAD | J1: OPERADOR | K1: SINDICATO | L1: KM INICIA | M1: KM TERMINA | N1: TIRO | O1: CPO | P1: CARRIL | Q1: OBSERVACIONES | R1: PU | S1: IMPORTE | T1: IVA | U1: TOTAL | V1: CONCILIACION | W1: ESTATUS | X1: FACTURA | Z1: TIRO
A2: 23 | B2: 1 | C2: 1 | D2: 46175 | E2: 1 | F2: TIRO LIBRE | G2: NR0950C | H2: 14 | I2: M3 | J2: ALEJANDRO FLORES | K2: COSUM TOLUCA | Q2: APOYO AL DERRUMBRE 22+400 CUERPO B A SOLICITUD DE SICT | R2: 5600 | S2: =FRESADO!$R2*FRESADO!$E2 -> 5600 | T2: =FRESADO!$S2*16% -> 896 | U2: =FRESADO!$S2+FRESADO!$T2 -> 6496 | V2: CUAJIMALPA 1 | W2: PAGADA | X2: A-1183 | Z2: APOYO AL DERRUMBRE 22+400 CUERPO B A SOLICITUD DE SICT
A3: 23 | B3: 2 | C3: 2 | D3: 46175 | E3: 1 | F3: TIRO LIBRE | G3: 95AX5D | H3: 14 | I3: M3 | J3: CESAR HERNANDEZ | K3: COSUM TOLUCA | Q3: APOYO AL DERRUMBRE 22+400 CUERPO B A SOLICITUD DE SICT | R3: 5600 | S3: =FRESADO!$R3*FRESADO!$E3 -> 5600 | T3: =FRESADO!$S3*16% -> 896 | U3: =FRESADO!$S3+FRESADO!$T3 -> 6496 | V3: CUAJIMALPA 1 | W3: PAGADA | X3: A-1183 | Z3: APOYO AL DERRUMBRE 22+400 CUERPO B A SOLICITUD DE SICT
A4: 23 | B4: 3 | C4: 3 | D4: 46175 | E4: 1 | F4: TIRO LIBRE | G4: MY7968B | H4: 14 | I4: M3 | J4: JORGE GARCIA | K4: COSUM TOLUCA | Q4: APOYO AL DERRUMBRE 22+400 CUERPO B A SOLICITUD DE SICT | R4: 5600 | S4: =FRESADO!$R4*FRESADO!$E4 -> 5600 | T4: =FRESADO!$S4*16% -> 896 | U4: =FRESADO!$S4+FRESADO!$T4 -> 6496 | V4: CUAJIMALPA 1 | W4: PAGADA | X4: A-1183 | Z4: APOYO AL DERRUMBRE 22+400 CUERPO B A SOLICITUD DE SICT
A5: 23 | C5: 5761 | D5: 46174 | E5: 1 | F5: FRESADO | G5: 95AX5D | H5: 14 | I5: M3 | J5: CESAR HERNANDEZ | K5: COSUM TOLUCA | R5: 2500 | S5: =FRESADO!$R5*FRESADO!$E5 -> 2500 | T5: =FRESADO!$S5*16% -> 400 | U5: =FRESADO!$S5+FRESADO!$T5 -> 2900 | V5: CUAJIMALPA 1 | W5: PAGADA | X5: A-1183 | Z5: BANCO ASIGNADO POR LA SICT
A6: 23 | C6: 5761 | D6: 46174 | E6: 1 | F6: FRESADO | G6: 95AX5D | H6: 14 | I6: M3 | J6: CESAR HERNANDEZ | K6: COSUM TOLUCA | R6: 2500 | S6: =FRESADO!$R6*FRESADO!$E6 -> 2500 | T6: =FRESADO!$S6*16% -> 400 | U6: =FRESADO!$S6+FRESADO!$T6 -> 2900 | V6: CUAJIMALPA 1 | W6: PAGADA | X6: A-1183 | Z6: BANCO ASIGNADO POR LA SICT
A7: 23 | C7: 5761 | D7: 46174 | E7: 1 | F7: FRESADO | G7: 95AX5D | H7: 14 | I7: M3 | J7: CESAR HERNANDEZ | K7: COSUM TOLUCA | R7: 2500 | S7: =FRESADO!$R7*FRESADO!$E7 -> 2500 | T7: =FRESADO!$S7*16% -> 400 | U7: =FRESADO!$S7+FRESADO!$T7 -> 2900 | V7: CUAJIMALPA 1 | W7: PAGADA | X7: A-1183 | Z7: BANCO ASIGNADO POR LA SICT
A8: 23 | C8: 5761 | D8: 46174 | E8: 1 | F8: FRESADO | G8: 95AX5D | H8: 14 | I8: M3 | J8: CESAR HERNANDEZ | K8: COSUM TOLUCA | R8: 2500 | S8: =FRESADO!$R8*FRESADO!$E8 -> 2500 | T8: =FRESADO!$S8*16% -> 400 | U8: =FRESADO!$S8+FRESADO!$T8 -> 2900 | V8: CUAJIMALPA 1 | W8: PAGADA | X8: A-1183 | Z8: BANCO ASIGNADO POR LA SICT
A9: 23 | C9: 5761 | D9: 46174 | E9: 1 | F9: FRESADO | G9: 95AX5D | H9: 14 | I9: M3 | J9: CESAR HERNANDEZ | K9: COSUM TOLUCA | R9: 2500 | S9: =FRESADO!$R9*FRESADO!$E9 -> 2500 | T9: =FRESADO!$S9*16% -> 400 | U9: =FRESADO!$S9+FRESADO!$T9 -> 2900 | V9: CUAJIMALPA 1 | W9: PAGADA | X9: A-1183 | Z9: BANCO ASIGNADO POR LA SICT
A10: 23 | C10: 2 | D10: 46174 | E10: 1 | F10: FRESADO | G10: MY7968B | H10: 14 | I10: M3 | J10: JORGE GARCIA | K10: COSUM TOLUCA | R10: 2500 | S10: =FRESADO!$R10*FRESADO!$E10 -> 2500 | T10: =FRESADO!$S10*16% -> 400 | U10: =FRESADO!$S10+FRESADO!$T10 -> 2900 | V10: CUAJIMALPA 1 | W10: PAGADA | X10: A-1183 | Z10: BANCO ASIGNADO POR LA SICT
A11: 23 | C11: 4 | D11: 46174 | E11: 1 | F11: FRESADO | G11: MY7968B | H11: 14 | I11: M3 | J11: JORGE GARCIA | K11: COSUM TOLUCA | R11: 2500 | S11: =FRESADO!$R11*FRESADO!$E11 -> 2500 | T11: =FRESADO!$S11*16% -> 400 | U11: =FRESADO!$S11+FRESADO!$T11 -> 2900 | V11: CUAJIMALPA 1 | W11: PAGADA | X11: A-1183 | Z11: BANCO ASIGNADO POR LA SICT
A12: 23 | C12: 5751 | D12: 46176 | E12: 1 | F12: FRESADO | G12: MY7967B | H12: 14 | I12: M3 | J12: ENRIQUE TORRES | K12: COSUM TOLUCA | R12: 2500 | S12: =FRESADO!$R12*FRESADO!$E12 -> 2500 | T12: =FRESADO!$S12*16% -> 400 | U12: =FRESADO!$S12+FRESADO!$T12 -> 2900 | V12: CUAJIMALPA 1 | W12: PAGADA | X12: A-1183 | Z12: BANCO ASIGNADO POR LA SICT
A13: 23 | C13: 5752 | D13: 46176 | E13: 1 | F13: FRESADO | G13: 95AX5D | H13: 14 | I13: M3 | J13: CESAR HERNANDEZ | K13: COSUM TOLUCA | R13: 2500 | S13: =FRESADO!$R13*FRESADO!$E13 -> 2500 | T13: =FRESADO!$S13*16% -> 400 | U13: =FRESADO!$S13+FRESADO!$T13 -> 2900 | V13: CUAJIMALPA 1 | W13: PAGADA | X13: A-1183 | Z13: BANCO ASIGNADO POR LA SICT
A14: 23 | C14: 5753 | D14: 46176 | E14: 1 | F14: FRESADO | G14: NB1258D | H14: 14 | I14: M3 | J14: SANTOS SOTERO | K14: COSUM TOLUCA | R14: 2500 | S14: =FRESADO!$R14*FRESADO!$E14 -> 2500 | T14: =FRESADO!$S14*16% -> 400 | U14: =FRESADO!$S14+FRESADO!$T14 -> 2900 | V14: CUAJIMALPA 1 | W14: PAGADA | X14: A-1183 | Z14: BANCO ASIGNADO POR LA SICT
A15: 23 | C15: 5754 | D15: 46176 | E15: 1 | F15: FRESADO | G15: 95AX5D | H15: 14 | I15: M3 | J15: CESAR HERNANDEZ | K15: COSUM TOLUCA | R15: 2500 | S15: =FRESADO!$R15*FRESADO!$E15 -> 2500 | T15: =FRESADO!$S15*16% -> 400 | U15: =FRESADO!$S15+FRESADO!$T15 -> 2900 | V15: CUAJIMALPA 1 | W15: PAGADA | X15: A-1183 | Z15: BANCO ASIGNADO POR LA SICT
A16: 23 | C16: 5755 | D16: 46176 | E16: 1 | F16: FRESADO | G16: MY7967B | H16: 14 | I16: M3 | J16: ENRIQUE TORRES | K16: COSUM TOLUCA | R16: 2500 | S16: =FRESADO!$R16*FRESADO!$E16 -> 2500 | T16: =FRESADO!$S16*16% -> 400 | U16: =FRESADO!$S16+FRESADO!$T16 -> 2900 | V16: CUAJIMALPA 1 | W16: PAGADA | X16: A-1183 | Z16: BANCO ASIGNADO POR LA SICT
... A18: 23 | C18: 5757 | D18: 46176 | E18: 1 | F18: FRESADO | G18: 95AX5D | H18: 14 | I18: M3 | J18: CESAR HERNANDEZ | K18: COSUM TOLUCA | R18: 2500 | S18: =FRESADO!$R18*FRESADO!$E18 -> 2500 | T18: =FRESADO!$S18*16% -> 400 | U18: =FRESADO!$S18+FRESADO!$T18 -> 2900 | V18: CUAJIMALPA 1 | W18: PAGADA | X18: A-1183 | Z18: BANCO ASIGNADO POR LA SICT
A19: 23 | C19: 5758 | D19: 46176 | E19: 1 | F19: FRESADO | G19: MY7967B | H19: 14 | I19: M3 | J19: ENRIQUE TORRES | K19: COSUM TOLUCA | L19: 680 | M19: 750 | R19: 2500 | S19: =FRESADO!$R19*FRESADO!$E19 -> 2500 | T19: =FRESADO!$S19*16% -> 400 | U19: =FRESADO!$S19+FRESADO!$T19 -> 2900 | V19: CUAJIMALPA 1 | W19: PAGADA | X19: A-1183 | Z19: BANCO ASIGNADO POR LA SICT
A20: 23 | C20: 5759 | D20: 46176 | E20: 1 | F20: FRESADO | G20: NB1258D | H20: 14 | I20: M3 | J20: SANTOS SOTERO | K20: COSUM TOLUCA | L20: 750 | M20: 810 | R20: 2500 | S20: =FRESADO!$R20*FRESADO!$E20 -> 2500 | T20: =FRESADO!$S20*16% -> 400 | U20: =FRESADO!$S20+FRESADO!$T20 -> 2900 | V20: CUAJIMALPA 1 | W20: PAGADA | X20: A-1183 | Z20: BANCO ASIGNADO POR LA SICT
A21: 23 | C21: 5760 | D21: 46176 | E21: 1 | F21: FRESADO | G21: 95AX5D | H21: 14 | I21: M3 | J21: CESAR HERNANDEZ | K21: COSUM TOLUCA | L21: 810 | M21: 870 | R21: 2500 | S21: =FRESADO!$R21*FRESADO!$E21 -> 2500 | T21: =FRESADO!$S21*16% -> 400 | U21: =FRESADO!$S21+FRESADO!$T21 -> 2900 | V21: CUAJIMALPA 1 | W21: PAGADA | X21: A-1183 | Z21: BANCO ASIGNADO POR LA SICT
A22: 23 | C22: 5762 | D22: 46177 | E22: 1 | F22: FRESADO | G22: 95AX5D | H22: 14 | I22: M3 | J22: CESAR HERNANDEZ | K22: COSUM TOLUCA | L22: 680 | M22: 770 | R22: 2500 | S22: =FRESADO!$R22*FRESADO!$E22 -> 2500 | T22: =FRESADO!$S22*16% -> 400 | U22: =FRESADO!$S22+FRESADO!$T22 -> 2900 | V22: CUAJIMALPA 1 | W22: PAGADA | X22: A-1183 | Z22: BANCO ASIGNADO POR LA SICT
A23: 23 | C23: 5763 | D23: 46177 | E23: 1 | F23: FRESADO | G23: MY7968B | H23: 14 | I23: M3 | J23: JORGE GARCIA | K23: COSUM TOLUCA | L23: 770 | M23: 860 | R23: 2500 | S23: =FRESADO!$R23*FRESADO!$E23 -> 2500 | T23: =FRESADO!$S23*16% -> 400 | U23: =FRESADO!$S23+FRESADO!$T23 -> 2900 | V23: CUAJIMALPA 1 | W23: PAGADA | X23: A-1183 | Z23: BANCO ASIGNADO POR LA SICT
A24: 23 | C24: 5764 | D24: 46177 | E24: 1 | F24: FRESADO | G24: NB1258D | H24: 14 | I24: M3 | J24: SANTOS SOTERO | K24: COSUM TOLUCA | L24: 860 | M24: 930 | R24: 2500 | S24: =FRESADO!$R24*FRESADO!$E24 -> 2500 | T24: =FRESADO!$S24*16% -> 400 | U24: =FRESADO!$S24+FRESADO!$T24 -> 2900 | V24: CUAJIMALPA 1 | W24: PAGADA | X24: A-1183 | Z24: BANCO ASIGNADO POR LA SICT
A25: 23 | C25: 5765 | D25: 46177 | E25: 1 | F25: FRESADO | G25: MY7967B | H25: 14 | I25: M3 | J25: ENRIQUE TORRES | K25: COSUM TOLUCA | R25: 2500 | S25: =FRESADO!$R25*FRESADO!$E25 -> 2500 | T25: =FRESADO!$S25*16% -> 400 | U25: =FRESADO!$S25+FRESADO!$T25 -> 2900 | V25: CUAJIMALPA 1 | W25: PAGADA | X25: A-1183 | Z25: BANCO ASIGNADO POR LA SICT
A26: 23 | C26: 5766 | D26: 46177 | E26: 1 | F26: FRESADO | G26: 95AX5D | H26: 14 | I26: M3 | J26: CESAR HERNANDEZ | K26: COSUM TOLUCA | R26: 2500 | S26: =FRESADO!$R26*FRESADO!$E26 -> 2500 | T26: =FRESADO!$S26*16% -> 400 | U26: =FRESADO!$S26+FRESADO!$T26 -> 2900 | V26: CUAJIMALPA 1 | W26: PAGADA | X26: A-1183 | Z26: BANCO ASIGNADO POR LA SICT
A27: 23 | C27: 5767 | D27: 46177 | E27: 1 | F27: FRESADO | G27: NB1258D | H27: 14 | I27: M3 | J27: SANTOS SOTERO | K27: COSUM TOLUCA | R27: 2500 | S27: =FRESADO!$R27*FRESADO!$E27 -> 2500 | T27: =FRESADO!$S27*16% -> 400 | U27: =FRESADO!$S27+FRESADO!$T27 -> 2900 | V27: CUAJIMALPA 1 | W27: PAGADA | X27: A-1183 | Z27: BANCO ASIGNADO POR LA SICT
A28: 23 | C28: 5768 | D28: 46177 | E28: 1 | F28: FRESADO | G28: MY7968B | H28: 14 | I28: M3 | J28: JORGE GARCIA | K28: COSUM TOLUCA | R28: 2500 | S28: =FRESADO!$R28*FRESADO!$E28 -> 2500 | T28: =FRESADO!$S28*16% -> 400 | U28: =FRESADO!$S28+FRESADO!$T28 -> 2900 | V28: CUAJIMALPA 1 | W28: PAGADA | X28: A-1183 | Z28: BANCO ASIGNADO POR LA SICT
A29: 23 | C29: 5769 | D29: 46177 | E29: 1 | F29: FRESADO | G29: MY7967B | H29: 14 | I29: M3 | J29: ENRIQUE TORRES | K29: COSUM TOLUCA | R29: 2500 | S29: =FRESADO!$R29*FRESADO!$E29 -> 2500 | T29: =FRESADO!$S29*16% -> 400 | U29: =FRESADO!$S29+FRESADO!$T29 -> 2900 | V29: CUAJIMALPA 1 | W29: PAGADA | X29: A-1183 | Z29: BANCO ASIGNADO POR LA SICT
A30: 23 | C30: 5770 | D30: 46177 | E30: 1 | F30: FRESADO | G30: 95AX5D | H30: 14 | I30: M3 | J30: CESAR HERNANDEZ | K30: COSUM TOLUCA | R30: 2500 | S30: =FRESADO!$R30*FRESADO!$E30 -> 2500 | T30: =FRESADO!$S30*16% -> 400 | U30: =FRESADO!$S30+FRESADO!$T30 -> 2900 | V30: CUAJIMALPA 1 | W30: PAGADA | X30: A-1183 | Z30: BANCO ASIGNADO POR LA SICT
A31: 23 | C31: 5771 | D31: 46177 | E31: 1 | F31: FRESADO | G31: NB1258D | H31: 14 | I31: M3 | J31: SANTOS SOTERO | K31: COSUM TOLUCA | R31: 2500 | S31: =FRESADO!$R31*FRESADO!$E31 -> 2500 | T31: =FRESADO!$S31*16% -> 400 | U31: =FRESADO!$S31+FRESADO!$T31 -> 2900 | V31: CUAJIMALPA 1 | W31: PAGADA | X31: A-1183 | Z31: BANCO ASIGNADO POR LA SICT
A32: 23 | C32: 5772 | D32: 46177 | E32: 1 | F32: FRESADO | G32: MY7968B | H32: 14 | I32: M3 | J32: JORGE GARCIA | K32: COSUM TOLUCA | R32: 2500 | S32: =FRESADO!$R32*FRESADO!$E32 -> 2500 | T32: =FRESADO!$S32*16% -> 400 | U32: =FRESADO!$S32+FRESADO!$T32 -> 2900 | V32: CUAJIMALPA 1 | W32: PAGADA | X32: A-1183 | Z32: BANCO ASIGNADO POR LA SICT
A33: 23 | C33: 5773 | D33: 46178 | E33: 1 | F33: FRESADO | G33: MY7967B | H33: 14 | I33: M3 | J33: ENRIQUE TORRES | K33: COSUM TOLUCA | R33: 2500 | S33: =FRESADO!$R33*FRESADO!$E33 -> 2500 | T33: =FRESADO!$S33*16% -> 400 | U33: =FRESADO!$S33+FRESADO!$T33 -> 2900 | V33: CUAJIMALPA 1 | W33: PAGADA | X33: A-1183 | Z33: BANCO ASIGNADO POR LA SICT
A34: 23 | C34: 5774 | D34: 46178 | E34: 1 | F34: FRESADO | G34: 95AX5D | H34: 14 | I34: M3 | J34: CESAR HERNANDEZ | K34: COSUM TOLUCA | R34: 2500 | S34: =FRESADO!$R34*FRESADO!$E34 -> 2500 | T34: =FRESADO!$S34*16% -> 400 | U34: =FRESADO!$S34+FRESADO!$T34 -> 2900 | V34: CUAJIMALPA 1 | W34: PAGADA | X34: A-1183 | Z34: BANCO ASIGNADO POR LA SICT
A35: 23 | C35: 5775 | D35: 46178 | E35: 1 | F35: FRESADO | G35: HC1139G | H35: 14 | I35: M3 | J35: VICTOR LEON | K35: COSUM TOLUCA | Q35: TRABAJOS DE NOCHE | R35: 3000 | S35: =FRESADO!$R35*FRESADO!$E35 -> 3000 | T35: =FRESADO!$S35*16% -> 480 | U35: =FRESADO!$S35+FRESADO!$T35 -> 3480 | V35: CUAJIMALPA 2 | W35: PAGADA | X35: A-1196 | Z35: BANCO ASIGNADO POR LA SICT
A36: 23 | C36: 5776 | D36: 46178 | E36: 1 | F36: FRESADO | G36: MY7967B | H36: 14 | I36: M3 | J36: ENRIQUE TORRES | K36: COSUM TOLUCA | R36: 2500 | S36: =FRESADO!$R36*FRESADO!$E36 -> 2500 | T36: =FRESADO!$S36*16% -> 400 | U36: =FRESADO!$S36+FRESADO!$T36 -> 2900 | V36: CUAJIMALPA 1 | W36: PAGADA | X36: A-1183 | Z36: BANCO ASIGNADO POR LA SICT
A37: 23 | C37: 5777 | D37: 46178 | E37: 1 | F37: FRESADO | G37: HC1139G | H37: 14 | I37: M3 | J37: VICTOR LEON | K37: COSUM TOLUCA | Q37: TRABAJOS DE NOCHE | R37: 3000 | S37: =FRESADO!$R37*FRESADO!$E37 -> 3000 | T37: =FRESADO!$S37*16% -> 480 | U37: =FRESADO!$S37+FRESADO!$T37 -> 3480 | V37: CUAJIMALPA 2 | W37: PAGADA | X37: A-1196 | Z37: BANCO ASIGNADO POR LA SICT
A38: 23 | C38: 5778 | D38: 46178 | E38: 1 | F38: FRESADO | G38: MY7967B | H38: 14 | I38: M3 | J38: ENRIQUE TORRES | K38: COSUM TOLUCA | R38: 2500 | S38: =FRESADO!$R38*FRESADO!$E38 -> 2500 | T38: =FRESADO!$S38*16% -> 400 | U38: =FRESADO!$S38+FRESADO!$T38 -> 2900 | V38: CUAJIMALPA 1 | W38: PAGADA | X38: A-1183 | Z38: BANCO ASIGNADO POR LA SICT
A39: 23 | C39: 5779 | D39: 46178 | E39: 1 | F39: FRESADO | G39: NE4904D | H39: 14 | I39: M3 | J39: JONATHAN GUTIERREZ | K39: COSUM TOLUCA | R39: 2500 | S39: =FRESADO!$R39*FRESADO!$E39 -> 2500 | T39: =FRESADO!$S39*16% -> 400 | U39: =FRESADO!$S39+FRESADO!$T39 -> 2900 | V39: CUAJIMALPA 1 | W39: PAGADA | X39: A-1183 | Z39: BANCO ASIGNADO POR LA SICT
A40: 23 | C40: 5780 | D40: 46178 | E40: 1 | F40: FRESADO | G40: HC1139G | H40: 14 | I40: M3 | J40: VICTOR LEON | K40: COSUM TOLUCA | Q40: TRABAJOS DE NOCHE | R40: 3000 | S40: =FRESADO!$R40*FRESADO!$E40 -> 3000 | T40: =FRESADO!$S40*16% -> 480 | U40: =FRESADO!$S40+FRESADO!$T40 -> 3480 | V40: CUAJIMALPA 2 | W40: PAGADA | X40: A-1196 | Z40: BANCO ASIGNADO POR LA SICT
A41: 23 | C41: 5781 | D41: 46178 | E41: 1 | F41: FRESADO | G41: 95AX5D | H41: 14 | I41: M3 | J41: CESAR HERNANDEZ | K41: COSUM TOLUCA | R41: 2500 | S41: =FRESADO!$R41*FRESADO!$E41 -> 2500 | T41: =FRESADO!$S41*16% -> 400 | U41: =FRESADO!$S41+FRESADO!$T41 -> 2900 | V41: CUAJIMALPA 1 | W41: PAGADA | X41: A-1183 | Z41: BANCO ASIGNADO POR LA SICT
...

Sheet Tabla dinámica 3

Sheet CARPETA
A1: SEM | B1: NO | C1: FOLIO | D1: FECHA | E1: VIAJES | F1: MATERIAL | G1: PLACAS | H1: CAPACIDAD (M3) | I1: PESO TOTAL (KG) | J1: OPERADOR | K1: SINDICATO | L1: KM INICIO | M1: KM FINAL | N1: CUERPO | O1: KM ACARREO POR VIAJE | P1: OBSERVACIONES | Q1: PU | R1: IMPORTE | S1: IVA | T1: TOTAL | U1: CONCILIACION | V1: ESTATUS | W1: FACTURA
A2: 23 | C2: 4979 | D2: 46174 | E2: 1 | F2: CARPETA DENSA | G2: LD69570 | H2: 14 | I2: M3 | J2: HUMBERTO COLIN | K2: COSUM TOLUCA | Q2: 3350 | R2: =CARPETA!$Q2*CARPETA!$E2 -> 3350 | S2: =CARPETA!$R2*16% -> 536 | T2: =CARPETA!$R2+CARPETA!$S2 -> 3886 | U2: CUAJIMALPA 1 | V2: PAGADA | W2: A-1183
A3: 23 | C3: 4980 | D3: 46174 | E3: 1 | F3: CARPETA DENSA | G3: NR0950C | H3: 14 | I3: M3 | J3: ALEJANDRO FLORES | K3: COSUM TOLUCA | Q3: 3350 | R3: =CARPETA!$Q3*CARPETA!$E3 -> 3350 | S3: =CARPETA!$R3*16% -> 536 | T3: =CARPETA!$R3+CARPETA!$S3 -> 3886 | U3: CUAJIMALPA 1 | V3: PAGADA | W3: A-1183
A4: 23 | C4: 4981 | D4: 46174 | E4: 1 | F4: CARPETA DENSA | G4: LF64430 | H4: 14 | I4: M3 | J4: CARLOS JOAQUIN | K4: COSUM TOLUCA | Q4: 3350 | R4: =CARPETA!$Q4*CARPETA!$E4 -> 3350 | S4: =CARPETA!$R4*16% -> 536 | T4: =CARPETA!$R4+CARPETA!$S4 -> 3886 | U4: CUAJIMALPA 2 | V4: PAGADA | W4: A-1196
A5: 23 | C5: 4982 | D5: 46174 | E5: 1 | F5: CARPETA DENSA | G5: 32AH5L | H5: 14 | I5: M3 | J5: GUSTAVO JOAQUIN | K5: COSUM TOLUCA | Q5: 3350 | R5: =CARPETA!$Q5*CARPETA!$E5 -> 3350 | S5: =CARPETA!$R5*16% -> 536 | T5: =CARPETA!$R5+CARPETA!$S5 -> 3886 | U5: CUAJIMALPA 2 | V5: PAGADA | W5: A-1196
A6: 23 | C6: 4983 | D6: 46174 | E6: 1 | F6: CARPETA DENSA | G6: MY7967B | H6: 14 | I6: M3 | J6: JORGE GARCIA | K6: COSUM TOLUCA | Q6: 3350 | R6: =CARPETA!$Q6*CARPETA!$E6 -> 3350 | S6: =CARPETA!$R6*16% -> 536 | T6: =CARPETA!$R6+CARPETA!$S6 -> 3886 | U6: CUAJIMALPA 1 | V6: PAGADA | W6: A-1183
A7: 23 | C7: S/F | D7: 46174 | E7: 1 | F7: PIPA DE AGUA | H7: 10 | I7: M3 | K7: COSUM TOLUCA | Q7: 4700 | R7: =CARPETA!$Q7*CARPETA!$E7 -> 4700 | S7: =CARPETA!$R7*16% -> 752 | T7: =CARPETA!$R7+CARPETA!$S7 -> 5452 | U7: CUAJIMALPA 1 | V7: PAGADA | W7: A-1183
A8: 23 | C8: S/F | D8: 46175 | E8: 1 | F8: REGRESO PIPA | H8: 0 | I8: M3 | K8: COSUM TOLUCA | P8: SE CANCELARON LABORES | Q8: 1000 | R8: =CARPETA!$Q8*CARPETA!$E8 -> 1000 | S8: =CARPETA!$R8*16% -> 160 | T8: =CARPETA!$R8+CARPETA!$S8 -> 1160 | U8: CUAJIMALPA 1 | V8: PAGADA | W8: A-1183
A9: 23 | C9: 5568 | D9: 46176 | E9: 1 | F9: CARPETA DENSA | G9: LD69570 | H9: 15 | I9: M3 | J9: HUMBERTO COLIN | K9: COSUM TOLUCA | Q9: 3350 | R9: =CARPETA!$Q9*CARPETA!$E9 -> 3350 | S9: =CARPETA!$R9*16% -> 536 | T9: =CARPETA!$R9+CARPETA!$S9 -> 3886 | U9: CUAJIMALPA 1 | V9: PAGADA | W9: A-1183
A10: 23 | C10: 5569 | D10: 46176 | E10: 1 | F10: CARPETA DENSA | G10: HE4281J | H10: 15 | I10: M3 | J10: ANASIEL BENITES | K10: COSUM TOLUCA | Q10: 3350 | R10: =CARPETA!$Q10*CARPETA!$E10 -> 3350 | S10: =CARPETA!$R10*16% -> 536 | T10: =CARPETA!$R10+CARPETA!$S10 -> 3886 | U10: CUAJIMALPA 1 | V10: PAGADA | W10: A-1183
A11: 23 | C11: 5570 | D11: 46176 | E11: 1 | F11: CARPETA DENSA | G11: 22BC9R | H11: 15 | I11: M3 | J11: REY DAVID | K11: COSUM TOLUCA | Q11: 3350 | R11: =CARPETA!$Q11*CARPETA!$E11 -> 3350 | S11: =CARPETA!$R11*16% -> 536 | T11: =CARPETA!$R11+CARPETA!$S11 -> 3886 | U11: CUAJIMALPA 1 | V11: PAGADA | W11: A-1183
A12: 23 | C12: 5571 | D12: 46176 | E12: 1 | F12: CARPETA DENSA | G12: MY6927D | H12: 15 | I12: M3 | J12: DANIEL CRUZ | K12: COSUM TOLUCA | Q12: 3350 | R12: =CARPETA!$Q12*CARPETA!$E12 -> 3350 | S12: =CARPETA!$R12*16% -> 536 | T12: =CARPETA!$R12+CARPETA!$S12 -> 3886 | U12: CUAJIMALPA 1 | V12: PAGADA | W12: A-1183
A13: 23 | C13: 5572 | D13: 46176 | E13: 1 | F13: CARPETA DENSA | G13: GZ9775J | H13: 15 | I13: M3 | J13: OMERO BENITEZ | K13: COSUM TOLUCA | Q13: 3350 | R13: =CARPETA!$Q13*CARPETA!$E13 -> 3350 | S13: =CARPETA!$R13*16% -> 536 | T13: =CARPETA!$R13+CARPETA!$S13 -> 3886 | U13: CUAJIMALPA 1 | V13: PAGADA | W13: A-1183
A14: 23 | C14: 5573 | D14: 46176 | E14: 1 | F14: CARPETA DENSA | G14: LD58235 | H14: 15 | I14: M3 | J14: CARLOS GUADARRAMA | K14: COSUM TOLUCA | Q14: 3350 | R14: =CARPETA!$Q14*CARPETA!$E14 -> 3350 | S14: =CARPETA!$R14*16% -> 536 | T14: =CARPETA!$R14+CARPETA!$S14 -> 3886 | U14: CUAJIMALPA 1 | V14: PAGADA | W14: A-1183
A15: 23 | C15: 5574 | D15: 46176 | E15: 1 | F15: CARPETA DENSA | G15: MY7968B | H15: 15 | I15: M3 | J15: JORGE GARCIA | K15: COSUM TOLUCA | Q15: 3350 | R15: =CARPETA!$Q15*CARPETA!$E15 -> 3350 | S15: =CARPETA!$R15*16% -> 536 | T15: =CARPETA!$R15+CARPETA!$S15 -> 3886 | U15: CUAJIMALPA 1 | V15: PAGADA | W15: A-1183
A16: 23 | C16: 5575 | D16: 46176 | E16: 1 | F16: CARPETA DENSA | G16: NR0950C | H16: 15 | I16: M3 | J16: ALEJANDRO FLORES | K16: COSUM TOLUCA | Q16: 3350 | R16: =CARPETA!$Q16*CARPETA!$E16 -> 3350 | S16: =CARPETA!$R16*16% -> 536 | T16: =CARPETA!$R16+CARPETA!$S16 -> 3886 | U16: CUAJIMALPA 1 | V16: PAGADA | W16: A-1183
A17: 23 | C17: S/F | D17: 46176 | E17: 1 | F17: PIPA DE AGUA | H17: 10 | I17: M3 | K17: COSUM TOLUCA | Q17: 4700 | R17: =CARPETA!$Q17*CARPETA!$E17 -> 4700 | S17: =CARPETA!$R17*16% -> 752 | T17: =CARPETA!$R17+CARPETA!$S17 -> 5452 | U17: CUAJIMALPA 1 | V17: PAGADA | W17: A-1183
A18: 23 | C18: 5585 | D18: 46177 | E18: 1 | F18: CARPETA DENSA | G18: LD69570 | H18: 15 | I18: M3 | J18: HUMBERTO COLIN | K18: COSUM TOLUCA | Q18: 3350 | R18: =CARPETA!$Q18*CARPETA!$E18 -> 3350 | S18: =CARPETA!$R18*16% -> 536 | T18: =CARPETA!$R18+CARPETA!$S18 -> 3886 | U18: CUAJIMALPA 1 | V18: PAGADA | W18: A-1183
A19: 23 | C19: 5586 | D19: 46177 | E19: 1 | F19: CARPETA DENSA | G19: 22BC9R | H19: 15 | I19: M3 | J19: REY DAVID | K19: COSUM TOLUCA | Q19: 3350 | R19: =CARPETA!$Q19*CARPETA!$E19 -> 3350 | S19: =CARPETA!$R19*16% -> 536 | T19: =CARPETA!$R19+CARPETA!$S19 -> 3886 | U19: CUAJIMALPA 1 | V19: PAGADA | W19: A-1183
A20: 23 | C20: 5587 | D20: 46177 | E20: 1 | F20: CARPETA DENSA | G20: MY6927D | H20: 15 | I20: M3 | J20: DANIEL CRUZ | K20: COSUM TOLUCA | Q20: 3350 | R20: =CARPETA!$Q20*CARPETA!$E20 -> 3350 | S20: =CARPETA!$R20*16% -> 536 | T20: =CARPETA!$R20+CARPETA!$S20 -> 3886 | U20: CUAJIMALPA 1 | V20: PAGADA | W20: A-1183
A21: 23 | C21: 5588 | D21: 46177 | E21: 1 | F21: CARPETA DENSA | G21: HE4281J | H21: 15 | I21: M3 | J21: ANASIEL BENITES | K21: COSUM TOLUCA | Q21: 3350 | R21: =CARPETA!$Q21*CARPETA!$E21 -> 3350 | S21: =CARPETA!$R21*16% -> 536 | T21: =CARPETA!$R21+CARPETA!$S21 -> 3886 | U21: CUAJIMALPA 1 | V21: PAGADA | W21: A-1183
A22: 23 | C22: 5589 | D22: 46177 | E22: 1 | F22: CARPETA DENSA | G22: LD58235 | H22: 15 | I22: M3 | J22: CARLOS GUADARRAMA | K22: COSUM TOLUCA | Q22: 3350 | R22: =CARPETA!$Q22*CARPETA!$E22 -> 3350 | S22: =CARPETA!$R22*16% -> 536 | T22: =CARPETA!$R22+CARPETA!$S22 -> 3886 | U22: CUAJIMALPA 1 | V22: PAGADA | W22: A-1183
A23: 23 | C23: 5590 | D23: 46177 | E23: 1 | F23: CARPETA DENSA | G23: LF6443G | H23: 15 | I23: M3 | J23: CARLOS JOAQUIN | K23: COSUM TOLUCA | Q23: 3350 | R23: =CARPETA!$Q23*CARPETA!$E23 -> 3350 | S23: =CARPETA!$R23*16% -> 536 | T23: =CARPETA!$R23+CARPETA!$S23 -> 3886 | U23: CUAJIMALPA 2 | V23: PAGADA | W23: A-1196
A24: 23 | C24: 5591 | D24: 46177 | E24: 1 | F24: CARPETA DENSA | G24: NR0950C | H24: 15 | I24: M3 | J24: ALEJANDRO FLORES | K24: COSUM TOLUCA | Q24: 3350 | R24: =CARPETA!$Q24*CARPETA!$E24 -> 3350 | S24: =CARPETA!$R24*16% -> 536 | T24: =CARPETA!$R24+CARPETA!$S24 -> 3886 | U24: CUAJIMALPA 1 | V24: PAGADA | W24: A-1183
A25: 23 | C25: 5592 | D25: 46177 | E25: 1 | F25: CARPETA DENSA | G25: NE4904D | H25: 15 | I25: M3 | J25: JONATHAN GUTIERREZ | K25: COSUM TOLUCA | Q25: 3350 | R25: =CARPETA!$Q25*CARPETA!$E25 -> 3350 | S25: =CARPETA!$R25*16% -> 536 | T25: =CARPETA!$R25+CARPETA!$S25 -> 3886 | U25: CUAJIMALPA 1 | V25: PAGADA | W25: A-1183
A26: 23 | C26: 5593 | D26: 46177 | E26: 1 | F26: CARPETA DENSA | G26: HB9249J | H26: 15 | I26: M3 | J26: DANIEL SANCHEZ | K26: COSUM TOLUCA | Q26: 3350 | R26: =CARPETA!$Q26*CARPETA!$E26 -> 3350 | S26: =CARPETA!$R26*16% -> 536 | T26: =CARPETA!$R26+CARPETA!$S26 -> 3886 | U26: CUAJIMALPA 1 | V26: PAGADA | W26: A-1183
A27: 23 | C27: 5594 | D27: 46177 | E27: 1 | F27: CARPETA DENSA | G27: LD69570 | H27: 15 | I27: M3 | J27: HUMBERTO COLIN | K27: COSUM TOLUCA | Q27: 3350 | R27: =CARPETA!$Q27*CARPETA!$E27 -> 3350 | S27: =CARPETA!$R27*16% -> 536 | T27: =CARPETA!$R27+CARPETA!$S27 -> 3886 | U27: CUAJIMALPA 1 | V27: PAGADA | W27: A-1183
A28: 23 | C28: S/F | D28: 46177 | E28: 1 | F28: PIPA DE AGUA | H28: 10 | I28: M3 | K28: COSUM TOLUCA | Q28: 4700 | R28: =CARPETA!$Q28*CARPETA!$E28 -> 4700 | S28: =CARPETA!$R28*16% -> 752 | T28: =CARPETA!$R28+CARPETA!$S28 -> 5452 | U28: CUAJIMALPA 1 | V28: PAGADA | W28: A-1183
A29: 23 | C29: 5604 | D29: 46178 | E29: 1 | F29: CARPETA DENSA | G29: 22BC9R | H29: 15 | I29: M3 | J29: REY DAVID | K29: COSUM TOLUCA | Q29: 3350 | R29: =CARPETA!$Q29*CARPETA!$E29 -> 3350 | S29: =CARPETA!$R29*16% -> 536 | T29: =CARPETA!$R29+CARPETA!$S29 -> 3886 | U29: CUAJIMALPA 1 | V29: PAGADA | W29: A-1183
A30: 23 | C30: 5605 | D30: 46178 | E30: 1 | F30: CARPETA DENSA | G30: LD58235 | H30: 15 | I30: M3 | J30: CARLOS GUADARRAMA | K30: COSUM TOLUCA | Q30: 3350 | R30: =CARPETA!$Q30*CARPETA!$E30 -> 3350 | S30: =CARPETA!$R30*16% -> 536 | T30: =CARPETA!$R30+CARPETA!$S30 -> 3886 | U30: CUAJIMALPA 1 | V30: PAGADA | W30: A-1183
A31: 23 | C31: 5606 | D31: 46178 | E31: 1 | F31: CARPETA DENSA | G31: MY6927D | H31: 15 | I31: M3 | J31: DANIEL CRUZ | K31: COSUM TOLUCA | Q31: 3350 | R31: =CARPETA!$Q31*CARPETA!$E31 -> 3350 | S31: =CARPETA!$R31*16% -> 536 | T31: =CARPETA!$R31+CARPETA!$S31 -> 3886 | U31: CUAJIMALPA 1 | V31: PAGADA | W31: A-1183
A32: 23 | C32: 5607 | D32: 46178 | E32: 1 | F32: CARPETA DENSA | G32: HE4281J | H32: 15 | I32: M3 | J32: ANASIEL BENITES | K32: COSUM TOLUCA | Q32: 3350 | R32: =CARPETA!$Q32*CARPETA!$E32 -> 3350 | S32: =CARPETA!$R32*16% -> 536 | T32: =CARPETA!$R32+CARPETA!$S32 -> 3886 | U32: CUAJIMALPA 1 | V32: PAGADA | W32: A-1183
A33: 23 | C33: 5608 | D33: 46178 | E33: 1 | F33: CARPETA DENSA | G33: NR0950C | H33: 15 | I33: M3 | J33: ALEJANDRO FLORES | K33: COSUM TOLUCA | Q33: 3350 | R33: =CARPETA!$Q33*CARPETA!$E33 -> 3350 | S33: =CARPETA!$R33*16% -> 536 | T33: =CARPETA!$R33+CARPETA!$S33 -> 3886 | U33: CUAJIMALPA 1 | V33: PAGADA | W33: A-1183
A34: 23 | C34: 5609 | D34: 46178 | E34: 1 | F34: CARPETA DENSA | G34: HB9249J | H34: 15 | I34: M3 | J34: DANIEL SANCHEZ | K34: COSUM TOLUCA | Q34: 3350 | R34: =CARPETA!$Q34*CARPETA!$E34 -> 3350 | S34: =CARPETA!$R34*16% -> 536 | T34: =CARPETA!$R34+CARPETA!$S34 -> 3886 | U34: CUAJIMALPA 1 | V34: PAGADA | W34: A-1183
A35: 23 | C35: 5610 | D35: 46178 | E35: 1 | F35: CARPETA DENSA | G35: LD69570 | H35: 15 | I35: M3 | J35: HUMBERTO COLIN | K35: COSUM TOLUCA | Q35: 3350 | R35: =CARPETA!$Q35*CARPETA!$E35 -> 3350 | S35: =CARPETA!$R35*16% -> 536 | T35: =CARPETA!$R35+CARPETA!$S35 -> 3886 | U35: CUAJIMALPA 1 | V35: PAGADA | W35: A-1183
A36: 23 | C36: 5611 | D36: 46178 | E36: 1 | F36: CARPETA DENSA | G36: MY7968B | H36: 15 | I36: M3 | J36: JORGE GARCIA | K36: COSUM TOLUCA | Q36: 3350 | R36: =CARPETA!$Q36*CARPETA!$E36 -> 3350 | S36: =CARPETA!$R36*16% -> 536 | T36: =CARPETA!$R36+CARPETA!$S36 -> 3886 | U36: CUAJIMALPA 1 | V36: PAGADA | W36: A-1183
A37: 23 | C37: 5612 | D37: 46178 | E37: 1 | F37: CARPETA DENSA | G37: LF6443G | H37: 15 | I37: M3 | J37: CARLOS JOAQUIN | K37: COSUM TOLUCA | Q37: 3350 | R37: =CARPETA!$Q37*CARPETA!$E37 -> 3350 | S37: =CARPETA!$R37*16% -> 536 | T37: =CARPETA!$R37+CARPETA!$S37 -> 3886 | U37: CUAJIMALPA 2 | V37: PAGADA | W37: A-1196
A38: 23 | C38: 5613 | D38: 46178 | E38: 1 | F38: CARPETA DENSA | G38: NB1258D | H38: 15 | I38: M3 | J38: SANTOS SOTERO | K38: COSUM TOLUCA | Q38: 3350 | R38: =CARPETA!$Q38*CARPETA!$E38 -> 3350 | S38: =CARPETA!$R38*16% -> 536 | T38: =CARPETA!$R38+CARPETA!$S38 -> 3886 | U38: CUAJIMALPA 1 | V38: PAGADA | W38: A-1183
A39: 23 | C39: s/f | D39: 46178 | E39: 1 | F39: PIPA DE AGUA | G39: KR-9352-A | H39: 10 | I39: M3 | J39: ROBERTO ONOFRE | K39: COSUM TOLUCA | Q39: 4500 | R39: =CARPETA!$Q39*CARPETA!$E39 -> 4500 | S39: =CARPETA!$R39*16% -> 720 | T39: =CARPETA!$R39+CARPETA!$S39 -> 5220 | U39: CUAJIMALPA 2 | V39: PAGADA | W39: A-1196
A40: 24 | C40: 5626 | D40: 46181 | E40: 1 | F40: CARPETA DENSA | G40: LD5835 | H40: 15 | I40: M3 | J40: CARLOS GUADARRAMA | K40: COSUM TOLUCA | Q40: 3350 | R40: =CARPETA!$Q40*CARPETA!$E40 -> 3350 | S40: =CARPETA!$R40*16% -> 536 | T40: =CARPETA!$R40+CARPETA!$S40 -> 3886 | U40: CUAJIMALPA 2 | V40: PAGADA | W40: A-1196
...

Sheet Tabla dinámica 4

Sheet VICENTE LOMBARDO
A1: SEM | B1: NO | C1: FOLIO | D1: FECHA | E1: VIAJES | F1: MATERIAL | G1: PLACAS | H1: CAPACIDAD (M3) | I1: PESO TOTAL (KG) | J1: OPERADOR | K1: SINDICATO | L1: KM INICIO | M1: KM FINAL | N1: CUERPO | O1: KM ACARREO POR VIAJE | P1: OBSERVACIONES | Q1: PU | R1: IMPORTE | S1: IVA | T1: TOTAL | U1: CONCILIACION | V1: ESTATUS | W1: FACTURA
A2: 23 | C2: 4979 | D2: 46174 | E2: 1 | F2: CARPETA DENSA | G2: LD69570 | H2: 14 | I2: M3 | J2: HUMBERTO COLIN | Q2: 3350 | R2: ='VICENTE LOMBARDO'!$Q2*'VICENTE LOMBARDO'!$E2 -> 3350 | S2: ='VICENTE LOMBARDO'!$R2*16% -> 536 | T2: ='VICENTE LOMBARDO'!$R2+'VICENTE LOMBARDO'!$S2 -> 3886 | U2: CUAJIMALPA 1 | V2: PAGADA | W2: A-1183
A3: 23 | C3: 4980 | D3: 46174 | E3: 1 | F3: CARPETA DENSA | G3: NR0950C | H3: 14 | I3: M3 | J3: ALEJANDRO FLORES | Q3: 3350 | R3: ='VICENTE LOMBARDO'!$Q3*'VICENTE LOMBARDO'!$E3 -> 3350 | S3: ='VICENTE LOMBARDO'!$R3*16% -> 536 | T3: ='VICENTE LOMBARDO'!$R3+'VICENTE LOMBARDO'!$S3 -> 3886 | U3: CUAJIMALPA 1 | V3: PAGADA | W3: A-1183
A4: 23 | C4: 4981 | D4: 46174 | E4: 1 | F4: CARPETA DENSA | G4: LF64430 | H4: 14 | I4: M3 | J4: CARLOS JOAQUIN | Q4: 3350 | R4: ='VICENTE LOMBARDO'!$Q4*'VICENTE LOMBARDO'!$E4 -> 3350 | S4: ='VICENTE LOMBARDO'!$R4*16% -> 536 | T4: ='VICENTE LOMBARDO'!$R4+'VICENTE LOMBARDO'!$S4 -> 3886 | U4: CUAJIMALPA 2 | V4: PAGADA | W4: A-1196
A5: 23 | C5: 4982 | D5: 46174 | E5: 1 | F5: CARPETA DENSA | G5: 32AH5L | H5: 14 | I5: M3 | J5: GUSTAVO JOAQUIN | Q5: 3350 | R5: ='VICENTE LOMBARDO'!$Q5*'VICENTE LOMBARDO'!$E5 -> 3350 | S5: ='VICENTE LOMBARDO'!$R5*16% -> 536 | T5: ='VICENTE LOMBARDO'!$R5+'VICENTE LOMBARDO'!$S5 -> 3886 | U5: CUAJIMALPA 2 | V5: PAGADA | W5: A-1196
A6: 23 | C6: 4983 | D6: 46174 | E6: 1 | F6: CARPETA DENSA | G6: MY7967B | H6: 14 | I6: M3 | J6: JORGE GARCIA | Q6: 3350 | R6: ='VICENTE LOMBARDO'!$Q6*'VICENTE LOMBARDO'!$E6 -> 3350 | S6: ='VICENTE LOMBARDO'!$R6*16% -> 536 | T6: ='VICENTE LOMBARDO'!$R6+'VICENTE LOMBARDO'!$S6 -> 3886 | U6: CUAJIMALPA 1 | V6: PAGADA | W6: A-1183
A7: 23 | C7: S/F | D7: 46174 | E7: 1 | F7: PIPA DE AGUA | H7: 10 | I7: M3 | Q7: 4700 | R7: ='VICENTE LOMBARDO'!$Q7*'VICENTE LOMBARDO'!$E7 -> 4700 | S7: ='VICENTE LOMBARDO'!$R7*16% -> 752 | T7: ='VICENTE LOMBARDO'!$R7+'VICENTE LOMBARDO'!$S7 -> 5452 | U7: CUAJIMALPA 1 | V7: PAGADA | W7: A-1183
A8: 23 | C8: S/F | D8: 46175 | E8: 1 | F8: REGRESO PIPA | H8: 0 | I8: M3 | P8: SE CANCELARON LABORES | Q8: 1000 | R8: ='VICENTE LOMBARDO'!$Q8*'VICENTE LOMBARDO'!$E8 -> 1000 | S8: ='VICENTE LOMBARDO'!$R8*16% -> 160 | T8: ='VICENTE LOMBARDO'!$R8+'VICENTE LOMBARDO'!$S8 -> 1160 | U8: CUAJIMALPA 1 | V8: PAGADA | W8: A-1183
A9: 23 | C9: 5568 | D9: 46176 | E9: 1 | F9: CARPETA DENSA | G9: LD69570 | H9: 15 | I9: M3 | J9: HUMBERTO COLIN | Q9: 3350 | R9: ='VICENTE LOMBARDO'!$Q9*'VICENTE LOMBARDO'!$E9 -> 3350 | S9: ='VICENTE LOMBARDO'!$R9*16% -> 536 | T9: ='VICENTE LOMBARDO'!$R9+'VICENTE LOMBARDO'!$S9 -> 3886 | U9: CUAJIMALPA 1 | V9: PAGADA | W9: A-1183
A10: 23 | C10: 5569 | D10: 46176 | E10: 1 | F10: CARPETA DENSA | G10: HE4281J | H10: 15 | I10: M3 | J10: ANASIEL BENITES | Q10: 3350 | R10: ='VICENTE LOMBARDO'!$Q10*'VICENTE LOMBARDO'!$E10 -> 3350 | S10: ='VICENTE LOMBARDO'!$R10*16% -> 536 | T10: ='VICENTE LOMBARDO'!$R10+'VICENTE LOMBARDO'!$S10 -> 3886 | U10: CUAJIMALPA 1 | V10: PAGADA | W10: A-1183
A11: 23 | C11: 5570 | D11: 46176 | E11: 1 | F11: CARPETA DENSA | G11: 22BC9R | H11: 15 | I11: M3 | J11: REY DAVID | Q11: 3350 | R11: ='VICENTE LOMBARDO'!$Q11*'VICENTE LOMBARDO'!$E11 -> 3350 | S11: ='VICENTE LOMBARDO'!$R11*16% -> 536 | T11: ='VICENTE LOMBARDO'!$R11+'VICENTE LOMBARDO'!$S11 -> 3886 | U11: CUAJIMALPA 1 | V11: PAGADA | W11: A-1183
A12: 23 | C12: 5571 | D12: 46176 | E12: 1 | F12: CARPETA DENSA | G12: MY6927D | H12: 15 | I12: M3 | J12: DANIEL CRUZ | Q12: 3350 | R12: ='VICENTE LOMBARDO'!$Q12*'VICENTE LOMBARDO'!$E12 -> 3350 | S12: ='VICENTE LOMBARDO'!$R12*16% -> 536 | T12: ='VICENTE LOMBARDO'!$R12+'VICENTE LOMBARDO'!$S12 -> 3886 | U12: CUAJIMALPA 1 | V12: PAGADA | W12: A-1183
A13: 23 | C13: 5572 | D13: 46176 | E13: 1 | F13: CARPETA DENSA | G13: GZ9775J | H13: 15 | I13: M3 | J13: OMERO BENITEZ | Q13: 3350 | R13: ='VICENTE LOMBARDO'!$Q13*'VICENTE LOMBARDO'!$E13 -> 3350 | S13: ='VICENTE LOMBARDO'!$R13*16% -> 536 | T13: ='VICENTE LOMBARDO'!$R13+'VICENTE LOMBARDO'!$S13 -> 3886 | U13: CUAJIMALPA 1 | V13: PAGADA | W13: A-1183
A14: 23 | C14: 5573 | D14: 46176 | E14: 1 | F14: CARPETA DENSA | G14: LD58235 | H14: 15 | I14: M3 | J14: CARLOS GUADARRAMA | Q14: 3350 | R14: ='VICENTE LOMBARDO'!$Q14*'VICENTE LOMBARDO'!$E14 -> 3350 | S14: ='VICENTE LOMBARDO'!$R14*16% -> 536 | T14: ='VICENTE LOMBARDO'!$R14+'VICENTE LOMBARDO'!$S14 -> 3886 | U14: CUAJIMALPA 1 | V14: PAGADA | W14: A-1183
A15: 23 | C15: 5574 | D15: 46176 | E15: 1 | F15: CARPETA DENSA | G15: MY7968B | H15: 15 | I15: M3 | J15: JORGE GARCIA | Q15: 3350 | R15: ='VICENTE LOMBARDO'!$Q15*'VICENTE LOMBARDO'!$E15 -> 3350 | S15: ='VICENTE LOMBARDO'!$R15*16% -> 536 | T15: ='VICENTE LOMBARDO'!$R15+'VICENTE LOMBARDO'!$S15 -> 3886 | U15: CUAJIMALPA 1 | V15: PAGADA | W15: A-1183
A16: 23 | C16: 5575 | D16: 46176 | E16: 1 | F16: CARPETA DENSA | G16: NR0950C | H16: 15 | I16: M3 | J16: ALEJANDRO FLORES | Q16: 3350 | R16: ='VICENTE LOMBARDO'!$Q16*'VICENTE LOMBARDO'!$E16 -> 3350 | S16: ='VICENTE LOMBARDO'!$R16*16% -> 536 | T16: ='VICENTE LOMBARDO'!$R16+'VICENTE LOMBARDO'!$S16 -> 3886 | U16: CUAJIMALPA 1 | V16: PAGADA | W16: A-1183
A17: 23 | C17: S/F | D17: 46176 | E17: 1 | F17: PIPA DE AGUA | H17: 10 | I17: M3 | Q17: 4700 | R17: ='VICENTE LOMBARDO'!$Q17*'VICENTE LOMBARDO'!$E17 -> 4700 | S17: ='VICENTE LOMBARDO'!$R17*16% -> 752 | T17: ='VICENTE LOMBARDO'!$R17+'VICENTE LOMBARDO'!$S17 -> 5452 | U17: CUAJIMALPA 1 | V17: PAGADA | W17: A-1183
A18: 23 | C18: 5585 | D18: 46177 | E18: 1 | F18: CARPETA DENSA | G18: LD69570 | H18: 15 | I18: M3 | J18: HUMBERTO COLIN | Q18: 3350 | R18: ='VICENTE LOMBARDO'!$Q18*'VICENTE LOMBARDO'!$E18 -> 3350 | S18: ='VICENTE LOMBARDO'!$R18*16% -> 536 | T18: ='VICENTE LOMBARDO'!$R18+'VICENTE LOMBARDO'!$S18 -> 3886 | U18: CUAJIMALPA 1 | V18: PAGADA | W18: A-1183
A19: 23 | C19: 5586 | D19: 46177 | E19: 1 | F19: CARPETA DENSA | G19: 22BC9R | H19: 15 | I19: M3 | J19: REY DAVID | Q19: 3350 | R19: ='VICENTE LOMBARDO'!$Q19*'VICENTE LOMBARDO'!$E19 -> 3350 | S19: ='VICENTE LOMBARDO'!$R19*16% -> 536 | T19: ='VICENTE LOMBARDO'!$R19+'VICENTE LOMBARDO'!$S19 -> 3886 | U19: CUAJIMALPA 1 | V19: PAGADA | W19: A-1183
A20: 23 | C20: 5587 | D20: 46177 | E20: 1 | F20: CARPETA DENSA | G20: MY6927D | H20: 15 | I20: M3 | J20: DANIEL CRUZ | Q20: 3350 | R20: ='VICENTE LOMBARDO'!$Q20*'VICENTE LOMBARDO'!$E20 -> 3350 | S20: ='VICENTE LOMBARDO'!$R20*16% -> 536 | T20: ='VICENTE LOMBARDO'!$R20+'VICENTE LOMBARDO'!$S20 -> 3886 | U20: CUAJIMALPA 1 | V20: PAGADA | W20: A-1183
A21: 23 | C21: 5588 | D21: 46177 | E21: 1 | F21: CARPETA DENSA | G21: HE4281J | H21: 15 | I21: M3 | J21: ANASIEL BENITES | Q21: 3350 | R21: ='VICENTE LOMBARDO'!$Q21*'VICENTE LOMBARDO'!$E21 -> 3350 | S21: ='VICENTE LOMBARDO'!$R21*16% -> 536 | T21: ='VICENTE LOMBARDO'!$R21+'VICENTE LOMBARDO'!$S21 -> 3886 | U21: CUAJIMALPA 1 | V21: PAGADA | W21: A-1183
A22: 23 | C22: 5589 | D22: 46177 | E22: 1 | F22: CARPETA DENSA | G22: LD58235 | H22: 15 | I22: M3 | J22: CARLOS GUADARRAMA | Q22: 3350 | R22: ='VICENTE LOMBARDO'!$Q22*'VICENTE LOMBARDO'!$E22 -> 3350 | S22: ='VICENTE LOMBARDO'!$R22*16% -> 536 | T22: ='VICENTE LOMBARDO'!$R22+'VICENTE LOMBARDO'!$S22 -> 3886 | U22: CUAJIMALPA 1 | V22: PAGADA | W22: A-1183
A23: 23 | C23: 5590 | D23: 46177 | E23: 1 | F23: CARPETA DENSA | G23: LF6443G | H23: 15 | I23: M3 | J23: CARLOS JOAQUIN | Q23: 3350 | R23: ='VICENTE LOMBARDO'!$Q23*'VICENTE LOMBARDO'!$E23 -> 3350 | S23: ='VICENTE LOMBARDO'!$R23*16% -> 536 | T23: ='VICENTE LOMBARDO'!$R23+'VICENTE LOMBARDO'!$S23 -> 3886 | U23: CUAJIMALPA 2 | V23: PAGADA | W23: A-1196
A24: 23 | C24: 5591 | D24: 46177 | E24: 1 | F24: CARPETA DENSA | G24: NR0950C | H24: 15 | I24: M3 | J24: ALEJANDRO FLORES | Q24: 3350 | R24: ='VICENTE LOMBARDO'!$Q24*'VICENTE LOMBARDO'!$E24 -> 3350 | S24: ='VICENTE LOMBARDO'!$R24*16% -> 536 | T24: ='VICENTE LOMBARDO'!$R24+'VICENTE LOMBARDO'!$S24 -> 3886 | U24: CUAJIMALPA 1 | V24: PAGADA | W24: A-1183
A25: 23 | C25: 5592 | D25: 46177 | E25: 1 | F25: CARPETA DENSA | G25: NE4904D | H25: 15 | I25: M3 | J25: JONATHAN GUTIERREZ | Q25: 3350 | R25: ='VICENTE LOMBARDO'!$Q25*'VICENTE LOMBARDO'!$E25 -> 3350 | S25: ='VICENTE LOMBARDO'!$R25*16% -> 536 | T25: ='VICENTE LOMBARDO'!$R25+'VICENTE LOMBARDO'!$S25 -> 3886 | U25: CUAJIMALPA 1 | V25: PAGADA | W25: A-1183
A26: 23 | C26: 5593 | D26: 46177 | E26: 1 | F26: CARPETA DENSA | G26: HB9249J | H26: 15 | I26: M3 | J26: DANIEL SANCHEZ | Q26: 3350 | R26: ='VICENTE LOMBARDO'!$Q26*'VICENTE LOMBARDO'!$E26 -> 3350 | S26: ='VICENTE LOMBARDO'!$R26*16% -> 536 | T26: ='VICENTE LOMBARDO'!$R26+'VICENTE LOMBARDO'!$S26 -> 3886 | U26: CUAJIMALPA 1 | V26: PAGADA | W26: A-1183
A27: 23 | C27: 5594 | D27: 46177 | E27: 1 | F27: CARPETA DENSA | G27: LD69570 | H27: 15 | I27: M3 | J27: HUMBERTO COLIN | Q27: 3350 | R27: ='VICENTE LOMBARDO'!$Q27*'VICENTE LOMBARDO'!$E27 -> 3350 | S27: ='VICENTE LOMBARDO'!$R27*16% -> 536 | T27: ='VICENTE LOMBARDO'!$R27+'VICENTE LOMBARDO'!$S27 -> 3886 | U27: CUAJIMALPA 1 | V27: PAGADA | W27: A-1183
A28: 23 | C28: S/F | D28: 46177 | E28: 1 | F28: PIPA DE AGUA | H28: 10 | I28: M3 | Q28: 4700 | R28: ='VICENTE LOMBARDO'!$Q28*'VICENTE LOMBARDO'!$E28 -> 4700 | S28: ='VICENTE LOMBARDO'!$R28*16% -> 752 | T28: ='VICENTE LOMBARDO'!$R28+'VICENTE LOMBARDO'!$S28 -> 5452 | U28: CUAJIMALPA 1 | V28: PAGADA | W28: A-1183
A29: 23 | C29: 5604 | D29: 46178 | E29: 1 | F29: CARPETA DENSA | G29: 22BC9R | H29: 15 | I29: M3 | J29: REY DAVID | Q29: 3350 | R29: ='VICENTE LOMBARDO'!$Q29*'VICENTE LOMBARDO'!$E29 -> 3350 | S29: ='VICENTE LOMBARDO'!$R29*16% -> 536 | T29: ='VICENTE LOMBARDO'!$R29+'VICENTE LOMBARDO'!$S29 -> 3886 | U29: CUAJIMALPA 1 | V29: PAGADA | W29: A-1183
A30: 23 | C30: 5605 | D30: 46178 | E30: 1 | F30: CARPETA DENSA | G30: LD58235 | H30: 15 | I30: M3 | J30: CARLOS GUADARRAMA | Q30: 3350 | R30: ='VICENTE LOMBARDO'!$Q30*'VICENTE LOMBARDO'!$E30 -> 3350 | S30: ='VICENTE LOMBARDO'!$R30*16% -> 536 | T30: ='VICENTE LOMBARDO'!$R30+'VICENTE LOMBARDO'!$S30 -> 3886 | U30: CUAJIMALPA 1 | V30: PAGADA | W30: A-1183
A31: 23 | C31: 5606 | D31: 46178 | E31: 1 | F31: CARPETA DENSA | G31: MY6927D | H31: 15 | I31: M3 | J31: DANIEL CRUZ | Q31: 3350 | R31: ='VICENTE LOMBARDO'!$Q31*'VICENTE LOMBARDO'!$E31 -> 3350 | S31: ='VICENTE LOMBARDO'!$R31*16% -> 536 | T31: ='VICENTE LOMBARDO'!$R31+'VICENTE LOMBARDO'!$S31 -> 3886 | U31: CUAJIMALPA 1 | V31: PAGADA | W31: A-1183
A32: 23 | C32: 5607 | D32: 46178 | E32: 1 | F32: CARPETA DENSA | G32: HE4281J | H32: 15 | I32: M3 | J32: ANASIEL BENITES | Q32: 3350 | R32: ='VICENTE LOMBARDO'!$Q32*'VICENTE LOMBARDO'!$E32 -> 3350 | S32: ='VICENTE LOMBARDO'!$R32*16% -> 536 | T32: ='VICENTE LOMBARDO'!$R32+'VICENTE LOMBARDO'!$S32 -> 3886 | U32: CUAJIMALPA 1 | V32: PAGADA | W32: A-1183
A33: 23 | C33: 5608 | D33: 46178 | E33: 1 | F33: CARPETA DENSA | G33: NR0950C | H33: 15 | I33: M3 | J33: ALEJANDRO FLORES | Q33: 3350 | R33: ='VICENTE LOMBARDO'!$Q33*'VICENTE LOMBARDO'!$E33 -> 3350 | S33: ='VICENTE LOMBARDO'!$R33*16% -> 536 | T33: ='VICENTE LOMBARDO'!$R33+'VICENTE LOMBARDO'!$S33 -> 3886 | U33: CUAJIMALPA 1 | V33: PAGADA | W33: A-1183
A34: 23 | C34: 5609 | D34: 46178 | E34: 1 | F34: CARPETA DENSA | G34: HB9249J | H34: 15 | I34: M3 | J34: DANIEL SANCHEZ | Q34: 3350 | R34: ='VICENTE LOMBARDO'!$Q34*'VICENTE LOMBARDO'!$E34 -> 3350 | S34: ='VICENTE LOMBARDO'!$R34*16% -> 536 | T34: ='VICENTE LOMBARDO'!$R34+'VICENTE LOMBARDO'!$S34 -> 3886 | U34: CUAJIMALPA 1 | V34: PAGADA | W34: A-1183
A35: 23 | C35: 5610 | D35: 46178 | E35: 1 | F35: CARPETA DENSA | G35: LD69570 | H35: 15 | I35: M3 | J35: HUMBERTO COLIN | Q35: 3350 | R35: ='VICENTE LOMBARDO'!$Q35*'VICENTE LOMBARDO'!$E35 -> 3350 | S35: ='VICENTE LOMBARDO'!$R35*16% -> 536 | T35: ='VICENTE LOMBARDO'!$R35+'VICENTE LOMBARDO'!$S35 -> 3886 | U35: CUAJIMALPA 1 | V35: PAGADA | W35: A-1183
A36: 23 | C36: 5611 | D36: 46178 | E36: 1 | F36: CARPETA DENSA | G36: MY7968B | H36: 15 | I36: M3 | J36: JORGE GARCIA | Q36: 3350 | R36: ='VICENTE LOMBARDO'!$Q36*'VICENTE LOMBARDO'!$E36 -> 3350 | S36: ='VICENTE LOMBARDO'!$R36*16% -> 536 | T36: ='VICENTE LOMBARDO'!$R36+'VICENTE LOMBARDO'!$S36 -> 3886 | U36: CUAJIMALPA 1 | V36: PAGADA | W36: A-1183
A37: 23 | C37: 5612 | D37: 46178 | E37: 1 | F37: CARPETA DENSA | G37: LF6443G | H37: 15 | I37: M3 | J37: CARLOS JOAQUIN | Q37: 3350 | R37: ='VICENTE LOMBARDO'!$Q37*'VICENTE LOMBARDO'!$E37 -> 3350 | S37: ='VICENTE LOMBARDO'!$R37*16% -> 536 | T37: ='VICENTE LOMBARDO'!$R37+'VICENTE LOMBARDO'!$S37 -> 3886 | U37: CUAJIMALPA 2 | V37: PAGADA | W37: A-1196
A38: 23 | C38: 5613 | D38: 46178 | E38: 1 | F38: CARPETA DENSA | G38: NB1258D | H38: 15 | I38: M3 | J38: SANTOS SOTERO | Q38: 3350 | R38: ='VICENTE LOMBARDO'!$Q38*'VICENTE LOMBARDO'!$E38 -> 3350 | S38: ='VICENTE LOMBARDO'!$R38*16% -> 536 | T38: ='VICENTE LOMBARDO'!$R38+'VICENTE LOMBARDO'!$S38 -> 3886 | U38: CUAJIMALPA 1 | V38: PAGADA | W38: A-1183
A39: 24 | C39: 5626 | D39: 46181 | E39: 1 | F39: CARPETA DENSA | G39: LD5835 | H39: 15 | I39: M3 | J39: CARLOS GUADARRAMA | Q39: 3350 | R39: ='VICENTE LOMBARDO'!$Q39*'VICENTE LOMBARDO'!$E39 -> 3350 | S39: ='VICENTE LOMBARDO'!$R39*16% -> 536 | T39: ='VICENTE LOMBARDO'!$R39+'VICENTE LOMBARDO'!$S39 -> 3886 | U39: CUAJIMALPA 2 | V39: PAGADA | W39: A-1196
A40: 24 | C40: 5627 | D40: 46181 | E40: 1 | F40: CARPETA DENSA | G40: 22BC9R | H40: 15 | I40: M3 | J40: REY DAVID | Q40: 3350 | R40: ='VICENTE LOMBARDO'!$Q40*'VICENTE LOMBARDO'!$E40 -> 3350 | S40: ='VICENTE LOMBARDO'!$R40*16% -> 536 | T40: ='VICENTE LOMBARDO'!$R40+'VICENTE LOMBARDO'!$S40 -> 3886 | U40: CUAJIMALPA 2 | V40: PAGADA | W40: A-1196
...
