Workbook

Sheet FRESADO
A1: SEM | B1: NO | C1: FOLIO | D1: FECHA | E1: VIAJES | F1: MATERIAL | G1: PLACAS | H1: CAPACIDAD | I1: UNIDAD | J1: OPERADOR | K1: SINDICATO | L1: KM INICIA | M1: KM TERMINA | N1: TIRO | O1: CPO | P1: CARRIL | Q1: OBSERVACIONES | R1: PU | S1: IMPORTE | T1: IVA | U1: TOTAL | V1: CONCILIACION | W1: ESTATUS | X1: FACTURA
A2: 28 | B2: 1 | C2: 1917 | D2: 46212 | E2: 1 | F2: FRESADO | G2: MY-7968-B | H2: 14 | I2: M³ | J2: JORGE GARCIA | K2: COSUM TOLUCA | L2: NA | M2: NA | N2: PEGASSO | O2: 1 | P2: BAJA | R2: 2000 | S2: =FRESADO!$R2*FRESADO!$E2 -> 2000 | T2: =FRESADO!$S2*16% -> 320 | U2: =FRESADO!$S2+FRESADO!$T2 -> 2320 | V2: A DEL M 1
A3: 28 | B3: 2 | C3: 1918 | D3: 46212 | E3: 1 | F3: FRESADO | G3: LD-5752-26 | H3: 14 | I3: M³ | J3: ARTURO HERNANDEZ | K3: COSUM TOLUCA | L3: NA | M3: NA | N3: PEGASSO | O3: 1 | P3: BAJA | R3: 2000 | S3: =FRESADO!$R3*FRESADO!$E3 -> 2000 | T3: =FRESADO!$S3*16% -> 320 | U3: =FRESADO!$S3+FRESADO!$T3 -> 2320 | V3: A DEL M 1
A4: 28 | B4: 3 | C4: 1919 | D4: 46212 | E4: 1 | F4: FRESADO | G4: LH-1606-2 | H4: 14 | I4: M³ | J4: JULIO CESAR | K4: COSUM TOLUCA | L4: NA | M4: NA | N4: PEGASSO | O4: 1 | P4: BAJA | R4: 2000 | S4: =FRESADO!$R4*FRESADO!$E4 -> 2000 | T4: =FRESADO!$S4*16% -> 320 | U4: =FRESADO!$S4+FRESADO!$T4 -> 2320 | V4: A DEL M 1
A5: 28 | B5: 4 | C5: 1920 | D5: 46212 | E5: 1 | F5: FRESADO | G5: HG-6103-D | H5: 14 | I5: M³ | J5: ENRIQUE COLIN | K5: COSUM TOLUCA | L5: NA | M5: NA | N5: PEGASSO | O5: 1 | P5: BAJA | R5: 2000 | S5: =FRESADO!$R5*FRESADO!$E5 -> 2000 | T5: =FRESADO!$S5*16% -> 320 | U5: =FRESADO!$S5+FRESADO!$T5 -> 2320 | V5: A DEL M 1
A6: 28 | B6: 5 | C6: 1921 | D6: 46212 | E6: 1 | F6: FRESADO | G6: NR-0950-C | H6: 14 | I6: M³ | J6: ALEJANDRO FLORES | K6: COSUM TOLUCA | L6: NA | M6: NA | N6: PEGASSO | O6: 1 | P6: BAJA | R6: 2000 | S6: =FRESADO!$R6*FRESADO!$E6 -> 2000 | T6: =FRESADO!$S6*16% -> 320 | U6: =FRESADO!$S6+FRESADO!$T6 -> 2320 | V6: A DEL M 1
A7: 28 | B7: 6 | C7: 1922 | D7: 46212 | E7: 1 | F7: FRESADO | G7: HC-8639-C | H7: 14 | I7: M³ | J7: JORGE HERNANDEZ | K7: COSUM TOLUCA | L7: NA | M7: NA | N7: PEGASSO | O7: 1 | P7: BAJA | R7: 2000 | S7: =FRESADO!$R7*FRESADO!$E7 -> 2000 | T7: =FRESADO!$S7*16% -> 320 | U7: =FRESADO!$S7+FRESADO!$T7 -> 2320 | V7: A DEL M 1
A8: 28 | B8: 7 | C8: 1923 | D8: 46212 | E8: 1 | F8: FRESADO | G8: GX-0733-H | H8: 14 | I8: M³ | J8: MIGUEL ANGEL | K8: COSUM TOLUCA | L8: NA | M8: NA | N8: PEGASSO | O8: 1 | P8: BAJA | R8: 2000 | S8: =FRESADO!$R8*FRESADO!$E8 -> 2000 | T8: =FRESADO!$S8*16% -> 320 | U8: =FRESADO!$S8+FRESADO!$T8 -> 2320 | V8: A DEL M 1
A9: 28 | B9: 8 | C9: 1924 | D9: 46212 | E9: 1 | F9: CAMION DE LIMPIEZA | G9: MU-3175-9 | H9: 7 | I9: M³ | J9: DIEGO HERNANDEZ | K9: COSUM TOLUCA | L9: NA | M9: NA | N9: PEGASSO | O9: 1 | P9: BAJA | R9: 3200 | S9: =FRESADO!$R9*FRESADO!$E9 -> 3200 | T9: =FRESADO!$S9*16% -> 512 | U9: =FRESADO!$S9+FRESADO!$T9 -> 3712 | V9: A DEL M 1
A10: 28 | B10: 1 | C10: 1300 | D10: 46213 | E10: 1 | F10: FRESADO | G10: MY-7968-B | H10: 14 | I10: M3 | J10: JORGE GARCIA | K10: COSUM TOLUCA | N10: KM | O10: B | P10: ACOTAMIENTO | Q10: BANCO PEGASO | R10: 2000 | S10: =FRESADO!$R10*FRESADO!$E10 -> 2000 | T10: =FRESADO!$S10*16% -> 320 | U10: =FRESADO!$S10+FRESADO!$T10 -> 2320 | V10: A DEL M 1
A11: 28 | B11: 2 | C11: 1348 | D11: 46213 | E11: 1 | F11: FRESADO | G11: LH-16-062 | H11: 14 | I11: M3 | J11: CESAR HERNANDEZ | K11: COSUM TOLUCA | N11: KM | O11: B | P11: ACOTAMIENTO | Q11: BANCO PEGASO | R11: 2000 | S11: =FRESADO!$R11*FRESADO!$E11 -> 2000 | T11: =FRESADO!$S11*16% -> 320 | U11: =FRESADO!$S11+FRESADO!$T11 -> 2320 | V11: A DEL M 1
A12: 28 | B12: 3 | C12: 1349 | D12: 46213 | E12: 1 | F12: FRESADO | G12: GX-0733-H | H12: 14 | I12: M3 | J12: MIGUEL ANGEL | K12: COSUM TOLUCA | N12: KM | O12: B | P12: ACOTAMIENTO | Q12: BANCO PEGASO | R12: 2000 | S12: =FRESADO!$R12*FRESADO!$E12 -> 2000 | T12: =FRESADO!$S12*16% -> 320 | U12: =FRESADO!$S12+FRESADO!$T12 -> 2320 | V12: A DEL M 1
A13: 28 | B13: 4 | C13: 1350 | D13: 46213 | E13: 1 | F13: FRESADO | G13: LD-57-526 | H13: 14 | I13: M3 | J13: ARTURO HERNANDEZ | K13: COSUM TOLUCA | N13: KM | O13: B | P13: ACOTAMIENTO | Q13: BANCO PEGASO | R13: 2000 | S13: =FRESADO!$R13*FRESADO!$E13 -> 2000 | T13: =FRESADO!$S13*16% -> 320 | U13: =FRESADO!$S13+FRESADO!$T13 -> 2320 | V13: A DEL M 1
A14: 28 | B14: 5 | C14: 1351 | D14: 46213 | E14: 1 | F14: FRESADO | G14: HC-8639-C | H14: 14 | I14: M3 | J14: OSCAR HERNANDEZ | K14: COSUM TOLUCA | N14: KM | O14: B | P14: ACOTAMIENTO | Q14: BANCO PEGASO | R14: 2000 | S14: =FRESADO!$R14*FRESADO!$E14 -> 2000 | T14: =FRESADO!$S14*16% -> 320 | U14: =FRESADO!$S14+FRESADO!$T14 -> 2320 | V14: A DEL M 1
A15: 28 | B15: 6 | C15: 1352 | D15: 46213 | E15: 1 | F15: FRESADO | G15: NR-0950-C | H15: 14 | I15: M3 | J15: ALEJANDRO FLORES | K15: COSUM TOLUCA | N15: KM | O15: B | P15: ACOTAMIENTO | Q15: BANCO PEGASO | R15: 2000 | S15: =FRESADO!$R15*FRESADO!$E15 -> 2000 | T15: =FRESADO!$S15*16% -> 320 | U15: =FRESADO!$S15+FRESADO!$T15 -> 2320 | V15: A DEL M 1
A16: 28 | B16: 7 | C16: 1353 | D16: 46213 | E16: 1 | F16: FRESADO | G16: MY-7968-B | H16: 14 | I16: M3 | J16: JORGE GARCIA | K16: COSUM TOLUCA | N16: KM | O16: B | P16: ACOTAMIENTO | Q16: BANCO ZINACANTEPEC | R16: 2855 | S16: =FRESADO!$R16*FRESADO!$E16 -> 2855 | T16: =FRESADO!$S16*16% -> 456.8 | U16: =FRESADO!$S16+FRESADO!$T16 -> 3311.8 | V16: A DEL M 1
A17: 28 | B17: 8 | C17: 1354 | D17: 46213 | E17: 1 | F17: FRESADO | G17: LH-16-062 | H17: 14 | I17: M3 | J17: CESAR HERNANDEZ | K17: COSUM TOLUCA | N17: KM | O17: B | P17: ACOTAMIENTO | Q17: BANCO PEGASO | R17: 2000 | S17: =FRESADO!$R17*FRESADO!$E17 -> 2000 | T17: =FRESADO!$S17*16% -> 320 | U17: =FRESADO!$S17+FRESADO!$T17 -> 2320 | V17: A DEL M 1
A18: 28 | B18: 9 | C18: 1355 | D18: 46213 | E18: 1 | F18: FRESADO | G18: GX-0733-H | H18: 14 | I18: M3 | J18: MIGUEL ANGEL | K18: COSUM TOLUCA | N18: KM | O18: B | P18: ACOTAMIENTO | Q18: BANCO PEGASO | R18: 2000 | S18: =FRESADO!$R18*FRESADO!$E18 -> 2000 | T18: =FRESADO!$S18*16% -> 320 | U18: =FRESADO!$S18+FRESADO!$T18 -> 2320 | V18: A DEL M 1
A19: 28 | B19: 10 | C19: 1356 | D19: 46213 | E19: 1 | F19: FRESADO | G19: HC-8639-C | H19: 14 | I19: M3 | J19: JORGE HERNANDEZ | K19: COSUM TOLUCA | N19: KM | O19: B | P19: ACOTAMIENTO | Q19: BANCO PEGASO | R19: 2000 | S19: =FRESADO!$R19*FRESADO!$E19 -> 2000 | T19: =FRESADO!$S19*16% -> 320 | U19: =FRESADO!$S19+FRESADO!$T19 -> 2320 | V19: A DEL M 1
A20: 28 | B20: 11 | C20: 1357 | D20: 46213 | E20: 1 | F20: VIAJE EN FALSO | H20: 0 | K20: COSUM TOLUCA | Q20: VIAJE EN FALSO | R20: 1000 | S20: =FRESADO!$R20*FRESADO!$E20 -> 1000 | T20: =FRESADO!$S20*16% -> 160 | U20: =FRESADO!$S20+FRESADO!$T20 -> 1160 | V20: A DEL M 1
A21: 28 | B21: 12 | C21: 1358 | D21: 46213 | E21: 1 | F21: CAMION DE LIMPIEZA | G21: MU-31-759 | H21: 7 | I21: M3 | J21: DIEGO HERNANDEZ | K21: COSUM TOLUCA | N21: KM | O21: B | P21: ACOTAMIENTO | Q21: SE UTILIZO PARA LIMPIEZA O RETIRO DE ESCOMBRO | R21: 3400 | S21: =FRESADO!$R21*FRESADO!$E21 -> 3400 | T21: =FRESADO!$S21*16% -> 544 | U21: =FRESADO!$S21+FRESADO!$T21 -> 3944 | V21: A DEL M 1
A22: 28 | B22: 13 | C22: 1359 | D22: 46213 | E22: 1 | F22: PIPA DE AGUA | G22: HB-0596-D | H22: 10 | I22: M3 | J22: FRANCISCO ALBARRAN | K22: COSUM TOLUCA | N22: KM | O22: B | P22: ACOTAMIENTO | R22: 4700 | S22: =FRESADO!$R22*FRESADO!$E22 -> 4700 | T22: =FRESADO!$S22*16% -> 752 | U22: =FRESADO!$S22+FRESADO!$T22 -> 5452 | V22: A DEL M 2
A23: 28 | B23: 14 | C23: 1361 | D23: 46214 | E23: 1 | F23: VIAJE EN FALSO | H23: 0 | Q23: VIAJE EN FALSO | S23: =FRESADO!$R23*FRESADO!$E23 -> 0 | T23: =FRESADO!$S23*16% -> 0 | U23: =FRESADO!$S23+FRESADO!$T23 -> 0
A24: 28 | B24: 15 | C24: 1362 | D24: 46214 | E24: 1 | F24: VIAJE EN FALSO | H24: 0 | K24: COSUM TOLUCA | Q24: VIAJE EN FALSO | R24: 1000 | S24: =FRESADO!$R24*FRESADO!$E24 -> 1000 | T24: =FRESADO!$S24*16% -> 160 | U24: =FRESADO!$S24+FRESADO!$T24 -> 1160 | V24: A DEL M 1
A25: 28 | B25: 16 | C25: 1363 | D25: 46214 | E25: 1 | F25: VIAJE EN FALSO | H25: 0 | K25: COSUM TOLUCA | Q25: VIAJE EN FALSO | R25: 1000 | S25: =FRESADO!$R25*FRESADO!$E25 -> 1000 | T25: =FRESADO!$S25*16% -> 160 | U25: =FRESADO!$S25+FRESADO!$T25 -> 1160 | V25: A DEL M 1
A26: 28 | B26: 17 | C26: 1360 | D26: 46214 | E26: 1 | F26: CAMION DE LIMPIEZA | G26: HG-5430-G | H26: 7 | I26: M3 | J26: ONESIMO HERNANDEZ | K26: COSUM TOLUCA | N26: KM | O26: B | P26: ACOTAMIENTO | Q26: SE UTILIZO PARA LIMPIEZA O RETIRO DE ESCOMBRO | R26: 3200 | S26: =FRESADO!$R26*FRESADO!$E26 -> 3200 | T26: =FRESADO!$S26*16% -> 512 | U26: =FRESADO!$S26+FRESADO!$T26 -> 3712 | V26: A DEL M 1
A27: 28 | B27: 18 | C27: 1365 | D27: 46214 | E27: 1 | F27: CAMION DE LIMPIEZA | G27: HG-9585-H | H27: 7 | I27: M3 | J27: JUAN GUADARRAMA | K27: COSUM TOLUCA | N27: KM | O27: B | P27: ACOTAMIENTO | Q27: SE UTILIZO PARA LIMPIEZA O RETIRO DE ESCOMBRO | R27: 3200 | S27: =FRESADO!$R27*FRESADO!$E27 -> 3200 | T27: =FRESADO!$S27*16% -> 512 | U27: =FRESADO!$S27+FRESADO!$T27 -> 3712 | V27: A DEL M 1
A28: 28 | B28: 19 | C28: 1364 | D28: 46214 | E28: 1 | F28: PIPA DE AGUA | G28: KR-9352-A | H28: 0 | I28: M3 | J28: ROBERTO ONOFRE | K28: COSUM TOLUCA | N28: KM | O28: B | P28: ACOTAMIENTO | R28: 4500 | S28: =FRESADO!$R28*FRESADO!$E28 -> 4500 | T28: =FRESADO!$S28*16% -> 720 | U28: =FRESADO!$S28+FRESADO!$T28 -> 5220 | V28: A DEL M 2
A29: 29 | B29: 20 | C29: 1366 | D29: 46216 | E29: 1 | F29: FRESADO | G29: HG-5430-G | H29: 7 | I29: M3 | J29: ALEJANDRO HERNANDEZ | K29: COSUM TOLUCA | N29: KM | O29: B | P29: CARRIL DE ALTA | Q29: PEGASO | R29: 1000 | S29: =FRESADO!$R29*FRESADO!$E29 -> 1000 | T29: =FRESADO!$S29*16% -> 160 | U29: =FRESADO!$S29+FRESADO!$T29 -> 1160 | V29: A DEL M 2
A30: 29 | B30: 21 | C30: 1367 | D30: 46216 | E30: 1 | F30: FRESADO | G30: MX-3669-D | H30: 14 | I30: M3 | J30: SIGFRIADO CALDERA | K30: COSUM TOLUCA | N30: KM | O30: B | P30: CARRIL DE ALTA | Q30: BANCO ZINACANTEPEC | R30: 2855 | S30: =FRESADO!$R30*FRESADO!$E30 -> 2855 | T30: =FRESADO!$S30*16% -> 456.8 | U30: =FRESADO!$S30+FRESADO!$T30 -> 3311.8 | V30: A DEL M 2
A31: 29 | B31: 22 | C31: 1368 | D31: 46216 | E31: 1 | F31: FRESADO | G31: HB-9249-J | H31: 14 | I31: M3 | J31: DANIEL SANCHEZ | K31: COSUM TOLUCA | N31: KM | O31: B | P31: CARRIL DE ALTA | Q31: BANCO ZINACANTEPEC | R31: 2855 | S31: =FRESADO!$R31*FRESADO!$E31 -> 2855 | T31: =FRESADO!$S31*16% -> 456.8 | U31: =FRESADO!$S31+FRESADO!$T31 -> 3311.8 | V31: A DEL M 2
A32: 29 | B32: 23 | C32: 1369 | D32: 46216 | E32: 1 | F32: FRESADO | G32: LD-57-526 | H32: 14 | I32: M3 | J32: ARTURO HERNANDEZ | K32: COSUM TOLUCA | N32: KM | O32: B | P32: CARRIL DE ALTA | Q32: PLANTA PEGASO | R32: 2000 | S32: =FRESADO!$R32*FRESADO!$E32 -> 2000 | T32: =FRESADO!$S32*16% -> 320 | U32: =FRESADO!$S32+FRESADO!$T32 -> 2320 | V32: A DEL M 1
A33: 29 | B33: 24 | C33: 1370 | D33: 46216 | E33: 1 | F33: FRESADO | G33: HE-4281-J | H33: 14 | I33: M3 | J33: DANIEL CRUZ | K33: COSUM TOLUCA | N33: KM | O33: B | P33: CARRIL DE ALTA | Q33: PLANTA PEGASO | R33: 2000 | S33: =FRESADO!$R33*FRESADO!$E33 -> 2000 | T33: =FRESADO!$S33*16% -> 320 | U33: =FRESADO!$S33+FRESADO!$T33 -> 2320 | V33: A DEL M 2
A34: 29 | B34: 25 | C34: 1371 | D34: 46216 | E34: 1 | F34: FRESADO | G34: HE-4251-J | H34: 14 | I34: M3 | J34: REY DAVID | K34: COSUM TOLUCA | N34: KM | O34: B | P34: CARRIL DE ALTA | Q34: PLANTA PEGASO | R34: 2000 | S34: =FRESADO!$R34*FRESADO!$E34 -> 2000 | T34: =FRESADO!$S34*16% -> 320 | U34: =FRESADO!$S34+FRESADO!$T34 -> 2320 | V34: A DEL M 2
A35: 29 | B35: 26 | C35: 1372 | D35: 46216 | E35: 1 | F35: FRESADO | G35: HC-8639-C | H35: 14 | I35: M3 | J35: JORGE HERNANDEZ | K35: COSUM TOLUCA | N35: KM | O35: B | P35: CARRIL DE ALTA | Q35: PLANTA PEGASO | R35: 2000 | S35: =FRESADO!$R35*FRESADO!$E35 -> 2000 | T35: =FRESADO!$S35*16% -> 320 | U35: =FRESADO!$S35+FRESADO!$T35 -> 2320 | V35: A DEL M 2
A36: 29 | B36: 27 | C36: 1373 | D36: 46216 | E36: 1 | F36: FRESADO | G36: HG-5430-G | H36: 7 | I36: M3 | J36: ALEJANDRO HERNANDEZ | K36: COSUM TOLUCA | N36: KM | O36: B | P36: CARRIL DE ALTA | Q36: PLANTA PEGASO | R36: 1000 | S36: =FRESADO!$R36*FRESADO!$E36 -> 1000 | T36: =FRESADO!$S36*16% -> 160 | U36: =FRESADO!$S36+FRESADO!$T36 -> 1160 | V36: A DEL M 2
A37: 29 | B37: 28 | C37: 1374 | D37: 46216 | E37: 1 | F37: FRESADO | G37: NR-0950-C | H37: 14 | I37: M3 | J37: ALEJANDRO FLORES | K37: COSUM TOLUCA | N37: KM | O37: B | P37: CARRIL DE ALTA | Q37: PLANTA PEGASO | R37: 2000 | S37: =FRESADO!$R37*FRESADO!$E37 -> 2000 | T37: =FRESADO!$S37*16% -> 320 | U37: =FRESADO!$S37+FRESADO!$T37 -> 2320 | V37: A DEL M 2
A38: 29 | B38: 29 | C38: 1375 | D38: 46216 | E38: 1 | F38: FRESADO | G38: MX-3669-D | H38: 14 | I38: M3 | J38: SIGFRIADO CALDERA | K38: COSUM TOLUCA | N38: KM | O38: B | P38: CARRIL DE ALTA | Q38: BANCO ZINACANTEPEC | R38: 2855 | S38: =FRESADO!$R38*FRESADO!$E38 -> 2855 | T38: =FRESADO!$S38*16% -> 456.8 | U38: =FRESADO!$S38+FRESADO!$T38 -> 3311.8 | V38: A DEL M 2
A39: 29 | B39: 30 | C39: 1376 | D39: 46216 | E39: 1 | F39: FRESADO | G39: HB-9249-J | H39: 14 | I39: M3 | J39: DANIEL SANCHEZ | K39: COSUM TOLUCA | N39: KM | O39: B | P39: CARRIL DE ALTA | Q39: BANCO ZINACANTEPEC | R39: 2855 | S39: =FRESADO!$R39*FRESADO!$E39 -> 2855 | T39: =FRESADO!$S39*16% -> 456.8 | U39: =FRESADO!$S39+FRESADO!$T39 -> 3311.8 | V39: A DEL M 2
A40: 29 | B40: 31 | C40: 1377 | D40: 46216 | E40: 1 | F40: FRESADO | G40: LD-57-526 | H40: 14 | I40: M3 | J40: ARTURO HERNANDEZ | K40: COSUM TOLUCA | N40: KM | O40: B | P40: CARRIL DE ALTA | Q40: PLANTA PEGASO | R40: 2000 | S40: =FRESADO!$R40*FRESADO!$E40 -> 2000 | T40: =FRESADO!$S40*16% -> 320 | U40: =FRESADO!$S40+FRESADO!$T40 -> 2320 | V40: A DEL M 1
...

Sheet Tabla dinámica 9

Sheet CARPETA
A1: SEM | B1: NO | C1: FOLIO | D1: FECHA | E1: VIAJES | F1: MATERIAL | G1: PLACAS | H1: CAPACIDAD (M3) | I1: PESO TOTAL (KG) | J1: OPERADOR | K1: SINDICATO | L1: KM INICIO | M1: KM FINAL | N1: CUERPO | O1: KM ACARREO POR VIAJE | P1: OBSERVACIONES | Q1: PU | R1: IMPORTE | S1: IVA | T1: TOTAL | U1: CONCILIACION | V1: ESTATUS | W1: FACTURA
A2: 28 | B2: 1 | C2: 486 | D2: 46213 | E2: 1 | F2: CARPETA | G2: HC-1139-G | H2: 14 | I2: 25240 | J2: VICTOR DE LEON | K2: COSUM TOLUCA | L2: 0+000.00 | M2: 0+035.00 | N2: B | P2: CARRIL DE ALTA | Q2: 2881.92 | R2: =Q2*E2 -> 2881.92 | S2: =R2*16% -> 461.1072 | T2: =R2+S2 -> 3343.0272 | U2: A DEL M 1
A3: 28 | B3: 2 | C3: 487 | D3: 46213 | E3: 1 | F3: CARPETA | G3: 412-AT-3 | H3: 14 | I3: 23160 | J3: JUAN GONZALES | K3: COSUM TOLUCA | L3: 0+035.00 | M3: 0+070.00 | N3: B | P3: CARRIL DE ALTA | Q3: 2850 | R3: =Q3*E3 -> 2850 | S3: =R3*16% -> 456 | T3: =R3+S3 -> 3306 | U3: A DEL M 1
A4: 28 | B4: 3 | C4: 488 | D4: 46213 | E4: 1 | F4: CARPETA | G4: HC-4281-J | H4: 14 | I4: 23070 | J4: DANIEL CRUZ | K4: COSUM TOLUCA | L4: 0+070.00 | M4: 0+110.00 | N4: B | P4: CARRIL DE ALTA | Q4: 2850 | R4: =Q4*E4 -> 2850 | S4: =R4*16% -> 456 | T4: =R4+S4 -> 3306 | U4: A DEL M 1
A5: 28 | B5: 4 | C5: 489 | D5: 46213 | E5: 1 | F5: CARPETA | G5: HE-4251-J | H5: 14 | I5: 25110 | J5: REY DAVID | K5: COSUM TOLUCA | L5: 0+110.00 | M5: 0+145.00 | N5: B | P5: CARRIL DE ALTA | Q5: 2862.54 | R5: =Q5*E5 -> 2862.54 | S5: =R5*16% -> 458.0064 | T5: =R5+S5 -> 3320.5464 | U5: A DEL M 1
A6: 28 | B6: 5 | C6: 491 | D6: 46213 | E6: 1 | F6: CARPETA | G6: NE-4904-D | H6: 14 | I6: 25120 | J6: GERARDO ENRIQUE | K6: COSUM TOLUCA | L6: 0+145.00 | M6: 0+180.00 | N6: B | P6: CARRIL DE ALTA | Q6: 2863.68 | R6: =Q6*E6 -> 2863.68 | S6: =R6*16% -> 458.1888 | T6: =R6+S6 -> 3321.8688 | U6: A DEL M 1
A7: 28 | B7: 6 | C7: 492 | D7: 46213 | E7: 1 | F7: CARPETA | G7: HF-0627-G | H7: 14 | I7: 22420 | J7: JOSE MIGUEL | K7: COSUM TOLUCA | L7: 0+180.00 | M7: 0+215.00 | N7: B | P7: CARRIL DE ALTA | Q7: 2850 | R7: =Q7*E7 -> 2850 | S7: =R7*16% -> 456 | T7: =R7+S7 -> 3306 | U7: A DEL M 1
A8: 28 | B8: 7 | C8: 490 | D8: 46213 | E8: 1 | F8: CARPETA | G8: 22-BC-9R | H8: 14 | I8: 24380 | J8: JUAN MANUEL | K8: COSUM TOLUCA | L8: 0+215.00 | M8: 0+250.00 | N8: B | P8: CARRIL DE ALTA | Q8: 2850 | R8: =Q8*E8 -> 2850 | S8: =R8*16% -> 456 | T8: =R8+S8 -> 3306 | U8: A DEL M 1
A9: 28 | B9: 8 | C9: 493 | D9: 46213 | E9: 1 | F9: CARPETA | G9: LD-5753-6 | H9: 14 | I9: 24450 | J9: ARTURO HERNANDEZ | K9: COSUM TOLUCA | L9: 0+250.00 | M9: 0+285.00 | N9: B | P9: CARRIL DE ALTA | Q9: 2850 | R9: =Q9*E9 -> 2850 | S9: =R9*16% -> 456 | T9: =R9+S9 -> 3306 | U9: A DEL M 1
A10: 28 | B10: 1 | C10: 494 | D10: 46214 | E10: 1 | F10: CARPETA | G10: HC-4281-J | H10: 14 | I10: 26210 | J10: DANIEL CRUZ | K10: COSUM TOLUCA | L10: 0 | M10: 0+040.00 | N10: B | P10: CARRIL CENTRAL | Q10: 2987.94 | R10: =Q10*E10 -> 2987.94 | S10: =R10*16% -> 478.0704 | T10: =R10+S10 -> 3466.0104 | U10: A DEL M 1
A11: 28 | B11: 2 | C11: 495 | D11: 46214 | E11: 1 | F11: CARPETA | G11: HE-4251-J | H11: 14 | I11: 26580 | J11: REY DAVID | K11: COSUM TOLUCA | L11: 0+040.00 | M11: 0+080.00 | N11: B | P11: CARRIL CENTRAL | Q11: 3030.12 | R11: =Q11*E11 -> 3030.12 | S11: =R11*16% -> 484.8192 | T11: =R11+S11 -> 3514.9392 | U11: A DEL M 1
A12: 28 | B12: 3 | C12: 496 | D12: 46214 | E12: 1 | F12: CARPETA | G12: 22-BC-9R | H12: 14 | I12: 24860 | J12: JUAN MANUEL | K12: COSUM TOLUCA | L12: 0+080.00 | M12: 0+130.00 | N12: B | P12: CARRIL CENTRAL | Q12: 2850 | R12: =Q12*E12 -> 2850 | S12: =R12*16% -> 456 | T12: =R12+S12 -> 3306 | U12: A DEL M 1
A13: 28 | B13: 4 | C13: 497 | D13: 46214 | E13: 1 | F13: CARPETA | G13: HC-1139-G | H13: 14 | I13: 26860 | J13: VICTOR DE LEON | K13: COSUM TOLUCA | L13: 0+130.00 | M13: 0+170.00 | N13: B | P13: CARRIL CENTRAL | Q13: 3062.04 | R13: =Q13*E13 -> 3062.04 | S13: =R13*16% -> 489.9264 | T13: =R13+S13 -> 3551.9664 | U13: A DEL M 1
A14: 28 | B14: 5 | C14: 498 | D14: 46214 | E14: 1 | F14: CARPETA | G14: 412-AT-3 | H14: 14 | I14: 24610 | J14: JUAN GONZALES | K14: COSUM TOLUCA | L14: 0+170.00 | M14: 0+215.00 | N14: B | P14: CARRIL CENTRAL | Q14: 2850 | R14: =Q14*E14 -> 2850 | S14: =R14*16% -> 456 | T14: =R14+S14 -> 3306 | U14: A DEL M 1
A15: 28 | B15: 6 | C15: 500 | D15: 46214 | E15: 1 | F15: CARPETA | G15: HG-610-3D | H15: 14 | I15: 24880 | J15: ENRIQUE COLIN | K15: COSUM TOLUCA | L15: 0+000.00 | M15: 0+050.00 | N15: B | P15: ACOTAMIENTO | Q15: 2850 | R15: =Q15*E15 -> 2850 | S15: =R15*16% -> 456 | T15: =R15+S15 -> 3306 | U15: A DEL M 1
A16: 28 | B16: 7 | C16: 601 | D16: 46214 | E16: 1 | F16: CARPETA | G16: LD-5752-6 | H16: 14 | I16: 25670 | J16: ARTURO HERNANDEZ | K16: COSUM TOLUCA | L16: 0+050.00 | M16: 0+100.00 | N16: B | P16: ACOTAMIENTO | Q16: 2926.38 | R16: =Q16*E16 -> 2926.38 | S16: =R16*16% -> 468.2208 | T16: =R16+S16 -> 3394.6008 | U16: A DEL M 1
A17: 28 | B17: 8 | C17: 602 | D17: 46214 | E17: 1 | F17: CARPETA | G17: LH-160-62 | H17: 14 | I17: 26980 | J17: JULIO CESAR | K17: COSUM TOLUCA | L17: 0+100.00 | M17: 0+145.00 | N17: B | P17: ACOTAMIENTO | Q17: 3075.72 | R17: =Q17*E17 -> 3075.72 | S17: =R17*16% -> 492.1152 | T17: =R17+S17 -> 3567.8352 | U17: A DEL M 1
A18: 28 | B18: 9 | C18: 499 | D18: 46214 | E18: 1 | F18: CARPETA | G18: NB-1258-D | H18: 14 | I18: 26200 | J18: SANTOS OTERO | K18: COSUM TOLUCA | L18: 0+145.00 | M18: 0+185.00 | N18: B | P18: ACOTAMIENTO | Q18: 2986.8 | R18: =Q18*E18 -> 2986.8 | S18: =R18*16% -> 477.888 | T18: =R18+S18 -> 3464.688 | U18: A DEL M 1
A19: 28 | B19: 10 | C19: 603 | D19: 46214 | E19: 1 | F19: CARPETA | G19: MY-7968-B | H19: 14 | I19: 22430 | J19: JORGE GARCIA | K19: COSUM TOLUCA | L19: 0+185.00 | M19: 0+220.00 | N19: B | P19: ACOTAMIENTO | Q19: 2850 | R19: =Q19*E19 -> 2850 | S19: =R19*16% -> 456 | T19: =R19+S19 -> 3306 | U19: A DEL M 1
A20: 28 | B20: 11 | C20: 604 | D20: 46214 | E20: 1 | F20: CARPETA | G20: GX-0733-H | H20: 8 | I20: 16050 | J20: MIGUEL ANGEL | K20: COSUM TOLUCA | L20: 0+220.00 | M20: 0+230.00 | N20: B | P20: ACOTAMIENTO | Q20: 2850 | R20: =Q20*E20 -> 2850 | S20: =R20*16% -> 456 | T20: =R20+S20 -> 3306 | U20: A DEL M 1
A21: 29 | B21: 1 | C21: 628 | D21: 46216 | E21: 1 | F21: CARPETA | G21: HC1139G | H21: 14 | I21: 59130 | J21: VICTOR DE LEON | K21: COSUM TOLUCA | L21: 0+320.00 | M21: 0+355.00 | N21: B | Q21: 2850 | R21: =Q21*E21 -> 2850 | S21: =R21*16% -> 456 | T21: =R21+S21 -> 3306 | U21: A DEL M 2
A22: 29 | B22: 2 | C22: 629 | D22: 46216 | E22: 1 | F22: CARPETA | G22: NE4904D | H22: 14 | I22: 59133 | J22: GERARDO ENRIQUE | K22: COSUM TOLUCA | L22: 0+390.00 | M22: 0+430.00 | N22: B | Q22: 2850 | R22: =Q22*E22 -> 2850 | S22: =R22*16% -> 456 | T22: =R22+S22 -> 3306 | U22: A DEL M 2
A23: 29 | B23: 3 | C23: 627 | D23: 46216 | E23: 1 | F23: CARPETA | G23: MY-7968-B | H23: 14 | I23: 59143 | J23: JORGE GARCIA | K23: COSUM TOLUCA | L23: 0+290.00 | M23: 0+320.00 | N23: B | Q23: 2850 | R23: =Q23*E23 -> 2850 | S23: =R23*16% -> 456 | T23: =R23+S23 -> 3306 | U23: A DEL M 2
A24: 29 | B24: 4 | C24: 630 | D24: 46216 | E24: 1 | F24: CARPETA | G24: NB1258D | H24: 14 | I24: 59149 | J24: SANTOS OTERO | K24: COSUM TOLUCA | L24: 0+355.00 | M24: 0+390.00 | N24: B | Q24: 2850 | R24: =Q24*E24 -> 2850 | S24: =R24*16% -> 456 | T24: =R24+S24 -> 3306 | U24: A DEL M 2
A25: 29 | B25: 5 | C25: 632 | D25: 46216 | E25: 1 | F25: CARPETA | G25: HB73236 | H25: 14 | I25: 59161 | J25: MARTIN | K25: COSUM TOLUCA | L25: 0+465.00 | M25: 0+495.00 | N25: B | Q25: 2850 | R25: =Q25*E25 -> 2850 | S25: =R25*16% -> 456 | T25: =R25+S25 -> 3306 | U25: A DEL M 2
A26: 29 | B26: 6 | C26: 633 | D26: 46216 | E26: 1 | F26: CARPETA | G26: HJ6103D | H26: 14 | I26: 59167 | J26: ENRIQUE COLIN | K26: COSUM TOLUCA | L26: 0+430.00 | M26: 0+465.00 | N26: B | Q26: 2850 | R26: =Q26*E26 -> 2850 | S26: =R26*16% -> 456 | T26: =R26+S26 -> 3306 | U26: A DEL M 2
A27: 29 | B27: 7 | C27: 634 | D27: 46216 | E27: 1 | F27: CARPETA | G27: 258ET7 | H27: 14 | I27: 59162 | J27: ELISEO REYES | K27: COSUM TOLUCA | L27: 0+495.00 | M27: 0+525.00 | N27: B | Q27: 2850 | R27: =Q27*E27 -> 2850 | S27: =R27*16% -> 456 | T27: =R27+S27 -> 3306 | U27: A DEL M 2
A28: 29 | B28: 8 | C28: 635 | D28: 46216 | E28: 1 | F28: CARPETA | G28: NJ6644D | H28: 14 | I28: 59184 | J28: RAMIRO HDEZ | K28: COSUM TOLUCA | L28: 0+525.00 | M28: 0+555.00 | N28: B | Q28: 2850 | R28: =Q28*E28 -> 2850 | S28: =R28*16% -> 456 | T28: =R28+S28 -> 3306 | U28: A DEL M 2
A29: 29 | B29: 9 | C29: 636 | D29: 46216 | E29: 1 | F29: CARPETA | G29: HD57440 | H29: 14 | I29: 59183 | J29: RAMIRO HDEZ ESQUIVEL | K29: COSUM TOLUCA | L29: 0+555.00 | M29: 0+585.00 | N29: B | Q29: 2850 | R29: =Q29*E29 -> 2850 | S29: =R29*16% -> 456 | T29: =R29+S29 -> 3306 | U29: A DEL M 2
A30: 29 | B30: 10 | C30: 637 | D30: 46216 | E30: 1 | F30: CARPETA | G30: 22BC9R | H30: 14 | I30: 59187 | J30: JUAN MANUEL | K30: COSUM TOLUCA | L30: 0+585.00 | M30: 0+615.00 | N30: B | Q30: 2850 | R30: =Q30*E30 -> 2850 | S30: =R30*16% -> 456 | T30: =R30+S30 -> 3306 | U30: A DEL M 2
A31: 29 | B31: 1 | C31: 815 | D31: 46221 | E31: 1 | F31: CARPETA | G31: 6X0733H | H31: 14 | I31: 23010 | J31: MIGUEL ANGEL | K31: COSUM TOLUCA | L31: 0+203 | M31: 0+240 | Q31: 3420 | R31: =Q31*E31 -> 3420 | S31: =R31*16% -> 547.2 | T31: =R31+S31 -> 3967.2 | U31: A DEL M 2
A32: 29 | B32: 2 | C32: 816 | D32: 46221 | E32: 1 | F32: CARPETA | G32: HG6103D | H32: 14 | I32: 23520 | J32: ENRIQUE GODIN | K32: COSUM TOLUCA | L32: 0+240 | M32: 0+260 | Q32: 3420 | R32: =Q32*E32 -> 3420 | S32: =R32*16% -> 547.2 | T32: =R32+S32 -> 3967.2 | U32: A DEL M 2
A33: 29 | B33: 3 | C33: 817 | D33: 46221 | E33: 1 | F33: CARPETA | G33: LG5557526 | H33: 14 | I33: 25720 | J33: ARTURO HERNANDEZ | K33: COSUM TOLUCA | L33: 0+260 | M33: 0+310 | Q33: 3420 | R33: =Q33*E33 -> 3420 | S33: =R33*16% -> 547.2 | T33: =R33+S33 -> 3967.2 | U33: A DEL M 2
A34: 29 | B34: 4 | C34: 818 | D34: 46221 | E34: 1 | F34: CARPETA | G34: MY7967B | H34: 14 | I34: 24990 | J34: ENRIQUE TORRES | K34: COSUM TOLUCA | L34: 0+310 | M34: 0+350 | Q34: 3420 | R34: =Q34*E34 -> 3420 | S34: =R34*16% -> 547.2 | T34: =R34+S34 -> 3967.2 | U34: A DEL M 2
A35: 29 | B35: 5 | C35: 819 | D35: 46221 | E35: 1 | F35: CARPETA | G35: LH16O62 | H35: 14 | I35: 25970 | J35: JULIO CESAR HERNANDEZ | K35: COSUM TOLUCA | L35: 0+350 | M35: 0+390 | Q35: 3420 | R35: =Q35*E35 -> 3420 | S35: =R35*16% -> 547.2 | T35: =R35+S35 -> 3967.2 | U35: A DEL M 2
A36: 29 | B36: 6 | C36: 820 | D36: 46221 | E36: 1 | F36: CARPETA | G36: MY7968B | H36: 14 | I36: 22410 | J36: JORGE GARCIA | K36: COSUM TOLUCA | L36: 0+203 | M36: 0+240 | Q36: 3420 | R36: =Q36*E36 -> 3420 | S36: =R36*16% -> 547.2 | T36: =R36+S36 -> 3967.2 | U36: A DEL M 2
A37: 29 | B37: 7 | C37: 821 | D37: 46221 | E37: 1 | F37: CARPETA | G37: MX3669D | H37: 14 | I37: 25090 | J37: SIGFRIDO CALDERA | K37: COSUM TOLUCA | L37: 0+240 | M37: 0+260 | Q37: 3420 | R37: =Q37*E37 -> 3420 | S37: =R37*16% -> 547.2 | T37: =R37+S37 -> 3967.2 | U37: A DEL M 2
A38: 29 | B38: 8 | C38: 822 | D38: 46221 | E38: 1 | F38: CARPETA | G38: 1A86899 | H38: 14 | I38: 24830 | J38: JOSUE MORALES | K38: COSUM TOLUCA | L38: 0+260 | M38: 0+330 | Q38: 3420 | R38: =Q38*E38 -> 3420 | S38: =R38*16% -> 547.2 | T38: =R38+S38 -> 3967.2 | U38: A DEL M 2
A39: 29 | B39: 9 | C39: 823 | D39: 46221 | E39: 1 | F39: CARPETA | G39: HB7323G | H39: 14 | I39: 24960 | J39: MARTIN CALDERA | K39: COSUM TOLUCA | L39: 0+330 | M39: 0+203 | Q39: 3420 | R39: =Q39*E39 -> 3420 | S39: =R39*16% -> 547.2 | T39: =R39+S39 -> 3967.2 | U39: A DEL M 2
A40: 29 | B40: 10 | C40: 824 | D40: 46221 | E40: 1 | F40: CARPETA | G40: HF8029G | H40: 14 | I40: 25400 | J40: ALEJANDRO NAVARRO | K40: COSUM TOLUCA | L40: 0+203 | M40: 0+240 | Q40: 3420 | R40: =Q40*E40 -> 3420 | S40: =R40*16% -> 547.2 | T40: =R40+S40 -> 3967.2 | U40: A DEL M 2
...

Sheet Tabla dinámica 8
