Workbook

Sheet CATALOGOS
A1: OBRAS | B1: CODIGO_OBRA | C1: SINDICATOS | D1: MATERIALES | E1: CAMIONES | F1: PLACA_CAMION | G1: ORIGEN

Sheet BD_ACARREOS
A1: FOLIO_CONCILIACION | B1: FECHA | C1: SEMANA | D1: FOLIO | E1: SINDICATO | F1: MATERIAL | G1: ORIGEN | H1: OBRA_DESTINO | I1: PLACA_CAMION | J1: CAPACIDAD_M3 | K1: PRECIO_UNITARIO | L1: SUBTOTAL | M1: IVA | N1: IMPORTE_TOTAL | O1: ESTATUS_CONCILIACION | P1: OBSERVACIONES
B2: 15/06/2026 | D2: 5704 | E2: COSUM-TOLUCA | F2: CARPETA DENSA | H2: MEXICO-TOLUCA | I2: 22-BC-9R | J2: 14 M3 | K2: 2850 | L2: 2850 | M2: 456 | N2: =L2+M2 -> 3306 | O2: =IF(A2="", "", IF(SUMIFS(BD_FACTURAS!I:I, BD_FACTURAS!A:A, A2) = N2, "✅ Cuadrado", "⚠️ Diferencia"))
B3: 15/06/2026 | D3: 5705 | E3: COSUM-TOLUCA | F3: CARPETA DENSA | H3: MEXICO-TOLUCA | I3: HE-4281-J | J3: 14 M3 | K3: 2850 | L3: 2850 | M3: 456 | N3: =L3+M3 -> 3306 | O3: =IF(A3="", "", IF(SUMIFS(BD_FACTURAS!I:I, BD_FACTURAS!A:A, A3) = N3, "✅ Cuadrado", "⚠️ Diferencia"))
B4: 15/06/2026 | D4: 5706 | E4: COSUM-TOLUCA | F4: CARPETA DENSA | H4: MEXICO-TOLUCA | I4: NJ-66-440 | J4: 14 M3 | K4: 2850 | L4: 2850 | M4: 456 | N4: =L4+M4 -> 3306 | O4: =IF(A4="", "", IF(SUMIFS(BD_FACTURAS!I:I, BD_FACTURAS!A:A, A4) = N4, "✅ Cuadrado", "⚠️ Diferencia"))
B5: 15/06/2026 | D5: 5707 | E5: COSUM-TOLUCA | F5: CARPETA DENSA | H5: MEXICO-TOLUCA | I5: HD-57-440 | J5: 14 M3 | K5: 2850 | L5: 2850 | M5: 456 | N5: =L5+M5 -> 3306 | O5: =IF(A5="", "", IF(SUMIFS(BD_FACTURAS!I:I, BD_FACTURAS!A:A, A5) = N5, "✅ Cuadrado", "⚠️ Diferencia"))
B6: 15/06/2026 | D6: 5708 | E6: COSUM-TOLUCA | F6: CARPETA DENSA | H6: MEXICO-TOLUCA | I6: MY-7967-B | J6: 14 M3 | K6: 2850 | L6: 2850 | M6: 456 | N6: =L6+M6 -> 3306 | O6: =IF(A6="", "", IF(SUMIFS(BD_FACTURAS!I:I, BD_FACTURAS!A:A, A6) = N6, "✅ Cuadrado", "⚠️ Diferencia"))
B7: 15/06/2026 | D7: 5709 | E7: COSUM-TOLUCA | F7: CARPETA DENSA | H7: MEXICO-TOLUCA | I7: LD-58-235 | J7: 14 M3 | K7: 2850 | L7: 2850 | M7: 456 | N7: =L7+M7 -> 3306 | O7: =IF(A7="", "", IF(SUMIFS(BD_FACTURAS!I:I, BD_FACTURAS!A:A, A7) = N7, "✅ Cuadrado", "⚠️ Diferencia"))
B8: 15/06/2026 | D8: 5710 | E8: COSUM-TOLUCA | F8: CARPETA DENSA | H8: MEXICO-TOLUCA | I8: NB-1258-D | J8: 14 M3 | K8: 2850 | L8: 2850 | M8: 456 | N8: =L8+M8 -> 3306 | O8: =IF(A8="", "", IF(SUMIFS(BD_FACTURAS!I:I, BD_FACTURAS!A:A, A8) = N8, "✅ Cuadrado", "⚠️ Diferencia"))
B9: 15/06/2026 | D9: 5711 | E9: COSUM-TOLUCA | F9: CARPETA DENSA | H9: MEXICO-TOLUCA | I9: NR-0950-C | J9: 14 M3 | K9: 2850 | L9: 2850 | M9: 456 | N9: =L9+M9 -> 3306 | O9: =IF(A9="", "", IF(SUMIFS(BD_FACTURAS!I:I, BD_FACTURAS!A:A, A9) = N9, "✅ Cuadrado", "⚠️ Diferencia"))
B10: 15/06/2026 | D10: 5712 | E10: COSUM-TOLUCA | F10: CARPETA DENSA | H10: MEXICO-TOLUCA | I10: LF-544-30 | J10: 14 M3 | K10: 2850 | L10: 2850 | M10: 456 | N10: =L10+M10 -> 3306 | O10: =IF(A10="", "", IF(SUMIFS(BD_FACTURAS!I:I, BD_FACTURAS!A:A, A10) = N10, "✅ Cuadrado", "⚠️ Diferencia"))
B11: 15/06/2026 | D11: 5713 | E11: COSUM-TOLUCA | F11: CARPETA DENSA | H11: MEXICO-TOLUCA | I11: HE-4281-J | J11: 14 M3 | K11: 2850 | L11: 2850 | M11: 456 | N11: =L11+M11 -> 3306 | O11: =IF(A11="", "", IF(SUMIFS(BD_FACTURAS!I:I, BD_FACTURAS!A:A, A11) = N11, "✅ Cuadrado", "⚠️ Diferencia"))
B12: 15/06/2026 | D12: 5714 | E12: COSUM-TOLUCA | F12: CARPETA DENSA | H12: MEXICO-TOLUCA | I12: 22-BC-9R | J12: 14 M3 | K12: 2850 | L12: 2850 | M12: 456 | N12: =L12+M12 -> 3306 | O12: =IF(A12="", "", IF(SUMIFS(BD_FACTURAS!I:I, BD_FACTURAS!A:A, A12) = N12, "✅ Cuadrado", "⚠️ Diferencia"))
B13: 15/06/2026 | D13: 5715 | E13: COSUM-TOLUCA | F13: CARPETA DENSA | H13: MEXICO-TOLUCA | I13: MY-7967-B | J13: 8 M3 | K13: 2850 | L13: 2850 | M13: 456 | N13: =L13+M13 -> 3306 | O13: =IF(A13="", "", IF(SUMIFS(BD_FACTURAS!I:I, BD_FACTURAS!A:A, A13) = N13, "✅ Cuadrado", "⚠️ Diferencia"))
... B70: 19/06/2026 | D70: 278 | E70: COSUM-HUIXQUILUCAN | F70: CARPETA DENSA | H70: MEXICO-TOLUCA | I70: 12-AN-1U | J70: 14 M3 | K70: 2850 | L70: 2850 | M70: 456 | N70: =L70+M70 -> 3306 | O70: =IF(A70="", "", IF(SUMIFS(BD_FACTURAS!I:I, BD_FACTURAS!A:A, A70) = N70, "✅ Cuadrado", "⚠️ Diferencia"))
B71: 15/06/2026 | D71: 532 | E71: COSUM-TOLUCA | F71: FRESADO | H71: MEXICO-TOLUCA | I71: 95AX5D | J71: 14 | K71: 2000 | L71: 2000 | M71: 320 | N71: =L71+M71 -> 2320 | O71: =IF(A71="", "", IF(SUMIFS(BD_FACTURAS!I:I, BD_FACTURAS!A:A, A71) = N71, "✅ Cuadrado", "⚠️ Diferencia"))
B72: 15/06/2026 | D72: 533 | E72: COSUM-TOLUCA | F72: FRESADO | H72: MEXICO-TOLUCA | I72: HC-1139-G | J72: 14 | K72: 2000 | L72: 2000 | M72: 320 | N72: =L72+M72 -> 2320 | O72: =IF(A72="", "", IF(SUMIFS(BD_FACTURAS!I:I, BD_FACTURAS!A:A, A72) = N72, "✅ Cuadrado", "⚠️ Diferencia"))
B73: 15/06/2026 | D73: 534 | E73: COSUM-TOLUCA | F73: FRESADO | H73: MEXICO-TOLUCA | I73: LH-16-062 | J73: 14 | K73: 2000 | L73: 2000 | M73: 320 | N73: =L73+M73 -> 2320 | O73: =IF(A73="", "", IF(SUMIFS(BD_FACTURAS!I:I, BD_FACTURAS!A:A, A73) = N73, "✅ Cuadrado", "⚠️ Diferencia"))
B74: 15/06/2026 | D74: 535 | E74: COSUM-TOLUCA | F74: FRESADO | H74: MEXICO-TOLUCA | I74: 95AX5D | J74: 14 | K74: 2000 | L74: 2000 | M74: 320 | N74: =L74+M74 -> 2320 | O74: =IF(A74="", "", IF(SUMIFS(BD_FACTURAS!I:I, BD_FACTURAS!A:A, A74) = N74, "✅ Cuadrado", "⚠️ Diferencia"))
B75: 15/06/2026 | D75: 536 | E75: COSUM-TOLUCA | F75: FRESADO | H75: MEXICO-TOLUCA | I75: HC-1139-G | J75: 14 | K75: 2000 | L75: 2000 | M75: 320 | N75: =L75+M75 -> 2320 | O75: =IF(A75="", "", IF(SUMIFS(BD_FACTURAS!I:I, BD_FACTURAS!A:A, A75) = N75, "✅ Cuadrado", "⚠️ Diferencia"))
B76: 15/06/2026 | D76: 537 | E76: COSUM-TOLUCA | F76: FRESADO | H76: MEXICO-TOLUCA | I76: LH-16-062 | J76: 14 | K76: 2000 | L76: 2000 | M76: 320 | N76: =L76+M76 -> 2320 | O76: =IF(A76="", "", IF(SUMIFS(BD_FACTURAS!I:I, BD_FACTURAS!A:A, A76) = N76, "✅ Cuadrado", "⚠️ Diferencia"))
B77: 15/06/2026 | D77: 538 | E77: COSUM-TOLUCA | F77: FRESADO | H77: MEXICO-TOLUCA | I77: 95AX5D | J77: 14 | K77: 2000 | L77: 2000 | M77: 320 | N77: =L77+M77 -> 2320 | O77: =IF(A77="", "", IF(SUMIFS(BD_FACTURAS!I:I, BD_FACTURAS!A:A, A77) = N77, "✅ Cuadrado", "⚠️ Diferencia"))
B78: 15/06/2026 | D78: 539 | E78: COSUM-TOLUCA | F78: FRESADO | H78: MEXICO-TOLUCA | I78: HC-1139-G | J78: 14 | K78: 2000 | L78: 2000 | M78: 320 | N78: =L78+M78 -> 2320 | O78: =IF(A78="", "", IF(SUMIFS(BD_FACTURAS!I:I, BD_FACTURAS!A:A, A78) = N78, "✅ Cuadrado", "⚠️ Diferencia"))
B79: 15/06/2026 | D79: 540 | E79: COSUM-TOLUCA | F79: FRESADO | H79: MEXICO-TOLUCA | I79: 95AX5D | J79: 14 | K79: 2000 | L79: 2000 | M79: 320 | N79: =L79+M79 -> 2320 | O79: =IF(A79="", "", IF(SUMIFS(BD_FACTURAS!I:I, BD_FACTURAS!A:A, A79) = N79, "✅ Cuadrado", "⚠️ Diferencia"))
B80: 15/06/2026 | D80: 541 | E80: COSUM-TOLUCA | F80: FRESADO | H80: MEXICO-TOLUCA | I80: LH-16-062 | J80: 14 | K80: 2000 | L80: 2000 | M80: 320 | N80: =L80+M80 -> 2320 | O80: =IF(A80="", "", IF(SUMIFS(BD_FACTURAS!I:I, BD_FACTURAS!A:A, A80) = N80, "✅ Cuadrado", "⚠️ Diferencia"))
B81: 15/06/2026 | D81: 542 | E81: COSUM-TOLUCA | F81: FRESADO | H81: MEXICO-TOLUCA | I81: HC-1139-G | J81: 14 | K81: 2000 | L81: 2000 | M81: 320 | N81: =L81+M81 -> 2320 | O81: =IF(A81="", "", IF(SUMIFS(BD_FACTURAS!I:I, BD_FACTURAS!A:A, A81) = N81, "✅ Cuadrado", "⚠️ Diferencia"))
B82: 15/06/2026 | D82: 543 | E82: COSUM-TOLUCA | F82: FRESADO | H82: MEXICO-TOLUCA | I82: 95AX5D | J82: 14 | K82: 2000 | L82: 2000 | M82: 320 | N82: =L82+M82 -> 2320 | O82: =IF(A82="", "", IF(SUMIFS(BD_FACTURAS!I:I, BD_FACTURAS!A:A, A82) = N82, "✅ Cuadrado", "⚠️ Diferencia"))
... B86: 15/06/2026 | D86: 547 | E86: COSUM-TOLUCA | F86: FRESADO | H86: MEXICO-TOLUCA | I86: LH-16-062 | J86: 14 | K86: 2000 | L86: 2000 | M86: 320 | N86: =L86+M86 -> 2320 | O86: =IF(A86="", "", IF(SUMIFS(BD_FACTURAS!I:I, BD_FACTURAS!A:A, A86) = N86, "✅ Cuadrado", "⚠️ Diferencia"))
B87: 15/06/2026 | D87: 548 | E87: CANCELADAS | F87: CANCELADO | H87: MEXICO-TOLUCA | I87: - | J87: - | K87: 0 | L87: 0 | M87: 0 | N87: =L87+M87 -> 0 | O87: =IF(A87="", "", IF(SUMIFS(BD_FACTURAS!I:I, BD_FACTURAS!A:A, A87) = N87, "✅ Cuadrado", "⚠️ Diferencia"))
B88: 15/06/2026 | D88: 549 | E88: COSUM-TOLUCA | F88: FRESADO | H88: MEXICO-TOLUCA | I88: HC-1139-G | J88: 14 | K88: 2000 | L88: 2000 | M88: 320 | N88: =L88+M88 -> 2320 | O88: =IF(A88="", "", IF(SUMIFS(BD_FACTURAS!I:I, BD_FACTURAS!A:A, A88) = N88, "✅ Cuadrado", "⚠️ Diferencia"))
B89: 16/06/2026 | D89: 550 | E89: COSUM-TOLUCA | F89: FRESADO | H89: MEXICO-TOLUCA | I89: 95-AX5D | J89: 14 | K89: 2000 | L89: 2000 | M89: 320 | N89: =L89+M89 -> 2320 | O89: =IF(A89="", "", IF(SUMIFS(BD_FACTURAS!I:I, BD_FACTURAS!A:A, A89) = N89, "✅ Cuadrado", "⚠️ Diferencia"))
B90: 16/06/2026 | D90: 351 | E90: COSUM-TOLUCA | F90: FRESADO | H90: MEXICO-TOLUCA | I90: MY-7968-B | J90: 14 | K90: 2000 | L90: 2000 | M90: 320 | N90: =L90+M90 -> 2320 | O90: =IF(A90="", "", IF(SUMIFS(BD_FACTURAS!I:I, BD_FACTURAS!A:A, A90) = N90, "✅ Cuadrado", "⚠️ Diferencia"))
B91: 16/06/2026 | D91: 352 | E91: COSUM-TOLUCA | F91: FRESADO | H91: MEXICO-TOLUCA | I91: HC-1139-G | J91: 14 | K91: 2000 | L91: 2000 | M91: 320 | N91: =L91+M91 -> 2320 | O91: =IF(A91="", "", IF(SUMIFS(BD_FACTURAS!I:I, BD_FACTURAS!A:A, A91) = N91, "✅ Cuadrado", "⚠️ Diferencia"))
B92: 16/06/2026 | D92: 353 | E92: COSUM-TOLUCA | F92: FRESADO | H92: MEXICO-TOLUCA | I92: LH-16-062 | J92: 14 | K92: 2000 | L92: 2000 | M92: 320 | N92: =L92+M92 -> 2320 | O92: =IF(A92="", "", IF(SUMIFS(BD_FACTURAS!I:I, BD_FACTURAS!A:A, A92) = N92, "✅ Cuadrado", "⚠️ Diferencia"))
B93: 16/06/2026 | D93: 354 | E93: COSUM-TOLUCA | F93: FRESADO | H93: MEXICO-TOLUCA | I93: 95-AX5D | J93: 14 | K93: 2000 | L93: 2000 | M93: 320 | N93: =L93+M93 -> 2320 | O93: =IF(A93="", "", IF(SUMIFS(BD_FACTURAS!I:I, BD_FACTURAS!A:A, A93) = N93, "✅ Cuadrado", "⚠️ Diferencia"))
B94: 16/06/2026 | D94: 355 | E94: COSUM-TOLUCA | F94: FRESADO | H94: MEXICO-TOLUCA | I94: MY-7968-B | J94: 14 | K94: 2000 | L94: 2000 | M94: 320 | N94: =L94+M94 -> 2320 | O94: =IF(A94="", "", IF(SUMIFS(BD_FACTURAS!I:I, BD_FACTURAS!A:A, A94) = N94, "✅ Cuadrado", "⚠️ Diferencia"))
B95: 16/06/2026 | D95: 356 | E95: COSUM-TOLUCA | F95: FRESADO | H95: MEXICO-TOLUCA | I95: LH-16-062 | J95: 14 | K95: 2000 | L95: 2000 | M95: 320 | N95: =L95+M95 -> 2320 | O95: =IF(A95="", "", IF(SUMIFS(BD_FACTURAS!I:I, BD_FACTURAS!A:A, A95) = N95, "✅ Cuadrado", "⚠️ Diferencia"))
B96: 16/06/2026 | D96: 357 | E96: COSUM-TOLUCA | F96: FRESADO | H96: MEXICO-TOLUCA | I96: HC-1139-G | J96: 14 | K96: 2000 | L96: 2000 | M96: 320 | N96: =L96+M96 -> 2320 | O96: =IF(A96="", "", IF(SUMIFS(BD_FACTURAS!I:I, BD_FACTURAS!A:A, A96) = N96, "✅ Cuadrado", "⚠️ Diferencia"))
B97: 16/06/2026 | D97: 358 | E97: COSUM-TOLUCA | F97: FRESADO | H97: MEXICO-TOLUCA | I97: 95-AX5D | J97: 14 | K97: 2000 | L97: 2000 | M97: 320 | N97: =L97+M97 -> 2320 | O97: =IF(A97="", "", IF(SUMIFS(BD_FACTURAS!I:I, BD_FACTURAS!A:A, A97) = N97, "✅ Cuadrado", "⚠️ Diferencia"))
B98: 16/06/2026 | D98: 359 | E98: COSUM-TOLUCA | F98: FRESADO | H98: MEXICO-TOLUCA | I98: MY-7968-B | J98: 14 | K98: 2000 | L98: 2000 | M98: 320 | N98: =L98+M98 -> 2320 | O98: =IF(A98="", "", IF(SUMIFS(BD_FACTURAS!I:I, BD_FACTURAS!A:A, A98) = N98, "✅ Cuadrado", "⚠️ Diferencia"))
B99: 16/06/2026 | D99: 360 | E99: COSUM-TOLUCA | F99: FRESADO | H99: MEXICO-TOLUCA | I99: LH-16-062 | J99: 14 | K99: 2000 | L99: 2000 | M99: 320 | N99: =L99+M99 -> 2320 | O99: =IF(A99="", "", IF(SUMIFS(BD_FACTURAS!I:I, BD_FACTURAS!A:A, A99) = N99, "✅ Cuadrado", "⚠️ Diferencia"))
...

Sheet BD_FACTURAS
A1: FOLIO_CONCILIACION | B1: FOLIO_FACTURA | C1: FECHA_FACTURA | D1: SEMANA | E1: SINDICATO_PROVEEDOR | F1: VIAJES_AMPARADOS | G1: IMPORTE | H1: I.V.A | I1: IMPORTE_TOTAL | J1: ESTATUS_CONCILIACION | K1: OBSERVACIONES

Sheet TABLAS_DINAMICAS
A1: Aquí puedes insertar tus tablas dinámicas de resumen
